File: data/ac dwie rel do testu programu.zip/Yb0.1Lu0.9/ac_800_Oe.dat
[Header]
; MPMS3 Data File (default extension .dat)
; Copyright (c) 2007, Quantum Design, Inc. All rights reserved.
TITLE,
FILEOPENTIME,3823556302.49429,02/27/2021,2:58 am
BYAPP,SQUID AC,0.9.1.0
INFO,MPMS3 Measurement Release 1.1.16 Build 347, MultiVu Release 2.3.3.2,APPNAME
INFO,0,MOMENT_UNITS
INFO,MLKS329,SAMPLE_MATERIAL
INFO,capsule, dry,SAMPLE_COMMENT
INFO,1,SAMPLE_MASS
INFO,,SAMPLE_VOLUME
INFO,,SAMPLE_MOLECULAR_WEIGHT
INFO,,SAMPLE_SIZE
INFO,,SAMPLE_SHAPE
INFO,Standard,SAMPLE_HOLDER
INFO,Standard,SAMPLE_HOLDER_DETAIL
INFO,66.06,SAMPLE_OFFSET
DATATYPE,COMMENT,1
DATATYPE,TIME,2
STARTUPAXIS,X,2
STARTUPAXIS,Y1,5
FIELDGROUP, VSM,2,3,4,5,6,8,9,10,11,14,15
FIELDGROUP, DC, 2,3,4,14,56,57,58,59,60,61,62,63,64,65,66,67,68,69
FIELDGROUP, AC, 2,3,4,11,16,17,18,19,20,21,22,23,24,25,26,27,28,29,30
STARTUPGROUP, All
[Data]
Comment,Time Stamp (sec),Temperature (K),Magnetic Field (Oe),Moment (emu),M. Std. Err. (emu),Transport Action,Averaging Time (sec),Frequency (Hz),Peak Amplitude (mm),Center Position (mm),Lockin Signal' (V),Lockin Signal (V),Range,M. Quad. Signal (emu),AC Moment (emu),AC M. Std Err. (emu),AC Phase (deg),AC Phase Std. Err. (deg),AC Susceptibility (emu/Oe),AC Suscept. Std Err. (emu/Oe),AC X' (emu/Oe),AC X' Std Err. (emu/Oe),AC X'' (emu/Oe),AC X'' Std Err. (emu/Oe),AC Drive (Oe),AC Frequency (Hz),AC Averaging Time (sec),AC Cycles,AC Range,AC Measure Type,AC Signal' (V),AC Signal'' (V),AC Trim Coil Ratio,AC Trim Coil Phase,Min. Temperature (K),Max. Temperature (K),Min. Field (Oe),Max. Field (Oe),Mass (grams),Motor Lag (deg),Pressure (Torr),Measure Count,Measurement Number,SQUID Status (code),Motor Status (code),Measure Status (code),Motor Current (amps),Motor Temp. (C),Temp. Status (code),Field Status (code),Chamber Status (code),Chamber Temp (K),Redirection State,Evercool Status,Average Temp (K),Rotation Angle (deg),Rotator state,DC Moment Fixed Ctr (emu),DC Moment Err Fixed Ctr (emu),DC Moment Free Ctr (emu),DC Moment Err Free Ctr (emu),DC Fixed Fit,DC Free Fit,DC Calculated Center (mm),DC Calculated Center Err (mm),DC Scan Length (mm),DC Scan Time (s),DC Number of Points,DC Squid Drift,DC Min V (V),DC Max V (V),DC Scans per Measure,Map 01,Map 02,Map 03,Map 04,Map 05,Map 06,Map 07,Map 08,Map 09,Map 10,Map 11,Map 12,Map 13,Map 14,Map 15,Map 16
,3823556496.52329,1.79996824264526,800.057006835938,,,5,,,,26.7500001937151,,,,,3.17877815783072E-6,5.50828846754639E-8,2.90997871993018,0.0140320689540592,1.05959361267636E-6,1.83609770395994E-8,1.05822729923629E-6,1.07484655027457E-8,5.37922594394264E-8,1.48860997976295E-8,2.99999747054123,1.99984133243561,17.5013884513395,33,1,3,0.0105129669287544,0.000801294528674942,0.0261473692953587,176.502304077148,1.79845678806305,1.8025130033493,800.057006835938,800.057006835938,,,2.29067134857178,0,1,,,,,,1,1,1,1.79999542236328,0,0,1.80001026073485,,,,,,,,,,,,,,,,,,,,,,,,,,,,,,,,,
,3823556974.38768,1.79998201131821,800.057006835938,,,5,,,,26.7500001937151,,,,,3.16617462096765E-6,6.48633152288044E-8,5.89206959867128,0.0116589941940367,1.05538599961687E-6,2.16209915675133E-8,1.04981043260428E-6,1.79429006006182E-8,1.08340499272037E-7,1.20631502684338E-8,3.00001574979869,6.93581342697144,13,90,1,3,0.0103348942495173,0.00184732463440321,0.0255140624940395,168.457397460938,1.79898762702942,1.80128467082977,800.057006835938,800.057006835938,,,2.2913875579834,0,1,,,,,,1,1,1,1.79991912841797,0,0,1.79999112241408,,,,,,,,,,,,,,,,,,,,,,,,,,,,,,,,,
,3823557343.50847,1.79973196983337,800.057006835938,,,5,,,,26.7500001937151,,,,,2.81130295808978E-6,1.22621700857097E-8,13.4597946607795,0.00316231162947957,9.37103385237831E-7,4.08740049328886E-9,9.11364428758792E-7,3.07412082588333E-9,2.18122975904332E-7,2.69381215759532E-9,2.99999231928534,24.0295906066895,13,312,1,3,0.00859675272257579,0.00356942572131297,0.0204198900610209,147.447692871094,1.79855024814606,1.8026202917099,800.057006835938,800.057006835938,,,2.2919750213623,0,1,,,,,,1,1,1,1.79987978935242,0,0,1.80000738054514,,,,,,,,,,,,,,,,,,,,,,,,,,,,,,,,,
,3823557672.47381,1.79952126741409,800.057006835938,,,5,,,,26.7500001937151,,,,,2.18544809825694E-6,5.45740933649977E-9,17.3855760405626,0.00189725266693346,7.28480784626937E-7,1.81913166396153E-9,6.95200562847075E-7,1.35060405514149E-9,2.17670464206304E-7,1.21865035882439E-9,3.00000788541888,83.3244476318359,13,1083,1,3,0.00656436926525932,0.00302057468702295,0.00998664833605289,128.859970092773,1.79854452610016,1.80227494239807,800.057006835938,800.057006835938,,,2.292888879776,0,1,,,,,,1,1,1,1.80004417896271,0,0,1.79999860506209,,,,,,,,,,,,,,,,,,,,,,,,,,,,,,,,,
,3823557988.35557,1.79957050085068,800.057006835938,,,5,,,,26.7500001937151,,,,,1.68907303674914E-6,7.83277088189497E-9,17.0566273169922,0.00373259264693384,5.63016907556261E-7,2.61088913479364E-9,5.38252793720493E-7,1.59383560386058E-9,1.65142266686332E-7,2.06795312859114E-9,3.00003963305552,288.071533203125,13,3744,1,3,0.00512179627208493,0.00222825856942408,0.00555827002972364,127.987091064453,1.79875648021698,1.80222189426422,800.057006835938,800.057006835938,,,2.29296088218689,0,1,,,,,,1,1,1,1.80004918575287,0,0,1.80000317664374,,,,,,,,,,,,,,,,,,,,,,,,,,,,,,,,,
,3823558316.75988,1.7999182343483,800.057006835938,,,5,,,,26.7500001937151,,,,,2.02891580976937E-6,2.99734538097045E-6,-11.4692647341302,1.04377131561904,6.76287216386166E-7,9.99088456250366E-7,6.62782782465076E-7,7.07005991062571E-7,-1.34474467149718E-7,7.05918034912249E-7,3.00008008522054,999.040954589844,13,12987,1000,3,0.00669902258475649,0.000544120492596396,0.00722349062561989,89.2833557128906,1.79485416412354,1.8061226606369,800.057006835938,800.057006835938,,,2.29088354110718,0,1,,,,,,1,1,1,1.80008018016815,0,0,1.80002737646343,,,,,,,,,,,,,,,,,,,,,,,,,,,,,,,,,
,3823558928.77458,2.00009906291962,800.057006835938,,,5,,,,26.7500001937151,,,,,2.85740223496603E-6,4.13952423653856E-8,4.46329150012751,0.00925300485355966,9.5246309412162E-7,1.37983515735992E-8,9.49574651328932E-7,1.06515036672222E-8,7.41210308702448E-8,8.77154352299534E-9,3.00001359905833,5.41091823577881,13,70,1,3,0.00938613659109629,0.00130140024687214,0.0257990900427103,170.990188598633,1.99845039844513,2.00182723999023,800.057006835938,800.057006835938,,,2.44413065910339,0,1,,,,,,1,1,1,2.00013661384583,0,0,1.99998244538027,,,,,,,,,,,,,,,,,,,,,,,,,,,,,,,,,
,3823559311.67262,1.99996310472488,800.057006835938,,,5,,,,26.7500001937151,,,,,2.67367559664967E-6,2.6131058610647E-8,10.3657353753246,0.00417702878496084,8.91240678160595E-7,8.71050415629719E-9,8.76694962648866E-7,8.48218241574682E-9,1.60361743799015E-7,1.98127840619787E-9,2.99994789529556,18.75119972229,13,243,1,3,0.00838770855220696,0.00284194189650345,0.0221190415322781,152.606399536133,1.99820017814636,2.00258135795593,800.057006835938,800.057006835938,,,2.44480109214783,0,1,,,,,,1,1,1,1.99989354610443,0,0,2.00001280382276,,,,,,,,,,,,,,,,,,,,,,,,,,,,,,,,,
,3823559636.83304,1.9996845126152,800.057006835938,,,5,,,,26.7500001937151,,,,,2.15221148806023E-6,9.73959521838121E-9,16.2565319515841,0.00318943030593891,7.17411768726288E-7,3.24656766821487E-9,6.88728173009669E-7,2.71542620410372E-9,2.00831147010978E-7,1.77951177415745E-9,2.99996679993322,64.9310150146484,13,844,1,3,0.00648300001232273,0.00293691847792054,0.0118006728589535,130.501937866211,1.99908220767975,2.00182485580444,800.057006835938,800.057006835938,,,2.44551062583923,0,1,,,,,,1,1,1,2.00005555152893,0,0,1.99999836702195,,,,,,,,,,,,,,,,,,,,,,,,,,,,,,,,,
,3823559959.66852,1.99963063001633,800.057006835938,,,5,,,,26.7500001937151,,,,,1.64705253371577E-6,4.82946606667996E-9,17.1578819370557,0.00203483027517225,5.49043148628131E-7,1.60989719584758E-9,5.24608246100702E-7,1.31535300205026E-9,1.61970883737286E-7,9.28232439206516E-10,2.99985991598508,225.014404296875,13,2925,1,3,0.00500631339605316,0.00214312782808514,0.00590644730255008,129.155090332031,1.99768543243408,2.00319290161133,800.057006835938,800.057006835938,,,2.44599199295044,0,1,,,,,,1,1,1,2.00014066696167,0,0,2.00000366710481,,,,,,,,,,,,,,,,,,,,,,,,,,,,,,,,,
,3823560280.46984,2.00258779525757,800.057006835938,,,5,,,,26.7500001937151,,,,,1.25160420920468E-6,8.15101948437686E-9,14.0422887366039,0.00491540853319942,4.17220144864884E-7,2.71712854995045E-9,4.04752315577301E-7,2.37753194373958E-9,1.01233454529061E-7,1.31534383849006E-9,2.99986523807477,779.690673828125,13,10135,10,3,0.00369586311388671,0.00187475584693125,0.00620225304737687,101.959259033203,1.99573588371277,2.00607824325562,800.057006835938,800.057006835938,,,2.44457101821899,0,1,,,,,,1,1,1,2.00007939338684,0,0,1.9999942939306,,,,,,,,,,,,,,,,,,,,,,,,,,,,,,,,,
,3823560956.62486,2.19992411136627,800.057006835938,,,5,,,,26.7500001937151,,,,,2.61391945402311E-6,8.59398174096516E-8,2.51480026252384,0.0149182640319953,8.71306794740098E-7,2.86466159974839E-8,8.70467657273992E-7,2.55905040994798E-8,3.82307232496476E-8,1.2874576033478E-8,2.99999893241142,4.21513509750366,13,54,1,3,0.00863243642856987,0.000796660370726462,0.0259441919624805,172.906890869141,2.19792890548706,2.2014172077179,800.057006835938,800.057006835938,,,2.570237159729,0,1,,,,,,1,1,1,2.20009446144104,0,0,2.19997786404042,,,,,,,,,,,,,,,,,,,,,,,,,,,,,,,,,
,3823561362.79608,2.20011603832245,800.057006835938,,,5,,,,26.7500001937151,,,,,2.56741399342208E-6,1.36613480841851E-8,7.44957233369507,0.00282364022854956,8.55827952047308E-7,4.55390660915957E-9,8.48604214024256E-7,3.97065892845389E-9,1.10961125831371E-7,2.22978319099337E-9,2.99991836826587,14.6017122268677,13,189,1,3,0.00822503250978357,0.00217292572104299,0.0234566293656826,157.469741821289,2.19866108894348,2.20233488082886,800.057006835938,800.057006835938,,,2.5706102848053,0,1,,,,,,1,1,1,2.20001864433289,0,0,2.20001299564655,,,,,,,,,,,,,,,,,,,,,,,,,,,,,,,,,
,3823561689.02559,2.19969713687897,800.057006835938,,,5,,,,26.7500001937151,,,,,2.1957106613937E-6,7.4886582384209E-9,14.8927432858326,0.00280464088160743,7.31867767320969E-7,2.49609735997915E-9,7.07283332470924E-7,1.4254873176468E-9,1.88097624791502E-7,2.04902121456148E-9,3.00014669238841,50.6515846252441,13,658,1,3,0.00664837686360978,0.00292331285513322,0.0139095261693001,133.399917602539,2.19796013832092,2.2032630443573,800.057006835938,800.057006835938,,,2.572434425354,0,1,,,,,,1,1,1,2.19985485076904,0,0,2.19999431806897,,,,,,,,,,,,,,,,,,,,,,,,,,,,,,,,,
,3823562012.51545,2.19968092441559,800.057006835938,,,5,,,,26.7500001937151,,,,,1.68640805305384E-6,4.09712357175332E-9,18.1652681328738,0.00194118083618238,5.62161361122241E-7,1.36576942906079E-9,5.34143919016689E-7,8.65570156502759E-10,1.75258864872231E-7,1.05646317376841E-9,2.99986475357764,175.640731811523,13,2283,1,3,0.00508984718764385,0.00227561307605355,0.00646407203748822,129.150924682617,2.19827699661255,2.20269274711609,800.057006835938,800.057006835938,,,2.57276892662048,0,1,,,,,,1,1,1,2.20003795623779,0,0,2.20001815235804,,,,,,,,,,,,,,,,,,,,,,,,,,,,,,,,,
,3823562336.3506,2.19934594631195,800.057006835938,,,5,,,,26.7500001937151,,,,,1.29390376116989E-6,7.27593891865511E-9,14.0459150809294,0.00461397175722803,4.31320121502309E-7,2.42541907104453E-9,4.1842431666823E-7,1.42381226457096E-9,1.04681127398837E-7,1.96352140437629E-9,2.99986876722366,608.450134277344,13,7909,1,3,0.00389869535366739,0.00177179200471999,0.00564009044319391,112.168151855469,2.19734907150269,2.20383787155151,800.057006835938,800.057006835938,,,2.57222127914429,0,1,,,,,,1,1,1,2.1998565196991,0,0,2.20000455871461,,,,,,,,,,,,,,,,,,,,,,,,,,,,,,,,,
,3823562901.79462,2.40004253387451,800.057006835938,,,5,,,,26.7500001937151,,,,,2.42310288677402E-6,4.69030042857433E-8,1.78846167278115,0.0100097261778896,8.07701311565621E-7,1.5634341523318E-8,8.07307852515114E-7,1.33968217611953E-8,2.52079347083162E-8,8.0596402876624E-9,2.99999870258618,3.30276823043823,13,42,1,3,0.00801691188025124,0.000562781098193681,0.0260533876717091,174.390869140625,2.39804768562317,2.40256524085999,800.057006835938,800.057006835938,,,2.69051313400269,0,1,,,,,,1,1,1,2.40004706382751,0,0,2.40000328966366,,,,,,,,,,,,,,,,,,,,,,,,,,,,,,,,,
,3823563329.40031,2.40011155605316,800.057006835938,,,5,,,,26.7500001937151,,,,,2.41037655782719E-6,2.3773662284968E-8,4.77260929087426,0.00338811195965052,8.03479047579203E-7,7.92475327897092E-9,8.00693183442446E-7,7.55181427470899E-9,6.68506236888238E-8,2.40246034157942E-9,2.99992459677623,11.4084405899048,13,148,1,3,0.00784159013983663,0.00152916842045028,0.0244085937738419,161.719390869141,2.39868187904358,2.40198111534119,800.057006835938,800.057006835938,,,2.69150447845459,0,1,,,,,,1,1,1,2.40003657341003,0,0,2.39999922807666,,,,,,,,,,,,,,,,,,,,,,,,,,,,,,,,,
,3823563658.68288,2.3998441696167,800.057006835938,,,5,,,,26.7500001937151,,,,,2.20091016225456E-6,9.04315077467788E-9,11.9227285852361,0.00276651697560037,7.33609966857492E-7,3.01427366453835E-9,7.1778387919279E-7,2.41743242874291E-9,1.51558194247623E-7,1.80051830793014E-9,3.00010940647716,39.504955291748,13,513,1,3,0.00678666852301584,0.00263979258661431,0.0161689873784781,137.420455932617,2.39906454086304,2.40176343917847,800.057006835938,800.057006835938,,,2.69271016120911,0,1,,,,,,1,1,1,2.39995837211609,0,0,2.40000247582793,,,,,,,,,,,,,,,,,,,,,,,,,,,,,,,,,
,3823563979.88618,2.39966630935669,800.057006835938,,,5,,,,26.7500001937151,,,,,1.72915046900005E-6,5.33983464753373E-9,18.0163598223057,0.00232496994501811,5.7637225943758E-7,1.77991020214794E-9,5.48111714900354E-7,1.31775889915235E-9,1.78265334370352E-7,1.19649145898126E-9,3.00005845299937,136.773452758789,13,1778,1,3,0.00521579234876553,0.00233974574650574,0.00730631360784173,128.645889282227,2.39783954620361,2.40198945999146,800.057006835938,800.057006835938,,,2.69332313537598,0,1,,,,,,1,1,1,2.39975094795227,0,0,2.39998949141729,,,,,,,,,,,,,,,,,,,,,,,,,,,,,,,,,
,3823564295.76044,2.39955604076386,800.057006835938,,,5,,,,26.7500001937151,,,,,1.28383350285006E-6,8.66161983864915E-9,15.9848652043904,0.00542819882908781,4.2795407266837E-7,2.8872711902487E-9,4.11407002730171E-7,1.81953990143531E-9,1.1785145912555E-7,2.24178711592447E-9,2.99993290131609,474.059478759766,13,6162,1,3,0.0038634509959899,0.00176509518865799,0.00543398596346378,119.821380615234,2.39786720275879,2.40267300605774,800.057006835938,800.057006835938,,,2.69323658943176,0,1,,,,,,1,1,1,2.39982628822327,0,0,2.40004344909422,,,,,,,,,,,,,,,,,,,,,,,,,,,,,,,,,
,3823564867.52458,2.60005629062653,800.057006835938,,,5,,,,26.7500001937151,,,,,2.22790274273643E-6,5.25803878576859E-8,2.0275510444968,0.0104739152394939,7.42634292251921E-7,1.75267970068852E-8,7.42169351075075E-7,1.57277150201839E-8,2.62744429686522E-8,7.73482989886914E-9,2.99999981953522,2.59945297241211,13.4643713009828,33,1,3,0.00737286999946576,0.000494480529584445,0.0261108800768852,175.519958496094,2.59816932678223,2.60108613967896,800.057006835938,800.057006835938,,,2.80513429641724,0,1,,,,,,1,1,1,2.5999608039856,0,0,2.59997109820445,,,,,,,,,,,,,,,,,,,,,,,,,,,,,,,,,
,3823565316.23611,2.60006380081177,800.057006835938,,,5,,,,26.7500001937151,,,,,2.26923043025712E-6,7.07682187379784E-8,3.46358720308887,0.0142169477354362,7.56408752152411E-7,2.35893628579526E-8,7.55027091851725E-7,2.11365224353136E-8,4.56978216405792E-8,1.04740373966125E-8,3.00000551791591,8.89725303649902,13,115,1,3,0.00743743952263049,0.00113301615049752,0.0250667911022902,165.430236816406,2.59908032417297,2.60280609130859,800.057006835938,800.057006835938,,,2.80592894554138,0,1,,,,,,1,1,1,2.59986233711243,0,0,2.59999301634639,,,,,,,,,,,,,,,,,,,,,,,,,,,,,,,,,
,3823565659.90669,2.59977471828461,800.057006835938,,,5,,,,26.7500001937151,,,,,2.15564557870684E-6,1.00236549057586E-8,8.3287491878032,0.00309905351584785,7.18583569777357E-7,3.34138125281117E-9,7.11004834992651E-7,2.57961681764502E-9,1.0408876678606E-7,2.12377158629662E-9,2.99985369742693,30.8258380889893,13,400,1,3,0.00679456715628375,0.00217659548376187,0.0184177160263062,142.227233886719,2.59847688674927,2.60203003883362,800.057006835938,800.057006835938,,,2.80689001083374,0,1,,,,,,1,1,1,2.60001873970032,0,0,2.60000025480986,,,,,,,,,,,,,,,,,,,,,,,,,,,,,,,,,
,3823565981.88745,2.59959781169891,800.057006835938,,,5,,,,26.7500001937151,,,,,1.80518760095787E-6,5.77505122351884E-9,16.5746411172193,0.00234252180641636,6.01693817714116E-7,1.92490388053287E-9,5.76692792843015E-7,1.45286375686681E-9,1.71641699357445E-7,1.26271210229147E-9,3.00017641500111,106.844917297363,13,1388,1,3,0.00548530594854944,0.00235157346277082,0.0084829879924655,128.347030639648,2.59798192977905,2.60231757164001,800.057006835938,800.057006835938,,,2.80787301063538,0,1,,,,,,1,1,1,2.60006642341614,0,0,2.60000774973915,,,,,,,,,,,,,,,,,,,,,,,,,,,,,,,,,
,3823566302.18619,2.59969282150269,800.057006835938,,,5,,,,26.7500001937151,,,,,1.31875430348463E-6,5.36270412231016E-9,17.8610445560382,0.00329325426253167,4.39604397788133E-7,1.78764786584947E-9,4.18416853169548E-7,1.1222345626878E-9,1.3483087012387E-7,1.39150080078492E-9,2.99986603892029,369.910034179687,13,4808,1,3,0.00394833348229028,0.00185377999302831,0.00541515927761793,124.991973876953,2.59770703315735,2.60272622108459,800.057006835938,800.057006835938,,,2.80768728256226,0,1,,,,,,1,1,1,2.59999394416809,0,0,2.60003955023629,,,,,,,,,,,,,,,,,,,,,,,,,,,,,,,,,
,3823566797.26186,2.7999963760376,800.057006835938,,,5,,,,26.7500001937151,,,,,2.09697201589057E-6,6.26029286668164E-8,0.245347898988871,0.019868003899321,6.9899238638454E-7,2.08676940712034E-8,6.98985977813427E-7,1.55758826266959E-8,2.99316617656571E-9,1.38871356387388E-8,2.99999264188974,1.99984133243561,17.5013884513395,33,1,3,0.00695225545505222,0.000205608644065311,0.0261570699512959,176.482543945313,2.79843616485596,2.80319452285767,800.057006835938,800.057006835938,,,2.91244339942932,0,1,,,,,,1,1,1,2.79998922348022,0,0,2.80000578789484,,,,,,,,,,,,,,,,,,,,,,,,,,,,,,,,,
,3823567275.018,2.79989051818848,800.057006835938,,,5,,,,26.7500001937151,,,,,2.06943974974226E-6,6.95481946897764E-8,2.32512655292553,0.0282737588244626,6.89808789258759E-7,2.31825816528663E-8,6.89240869402342E-7,1.24664283399131E-8,2.79855263330703E-8,1.9545338486136E-8,3.00001939952953,6.93581342697144,13,90,1,3,0.00681701283317117,0.00078482482841571,0.0255304016172886,168.460052490234,2.7981173992157,2.80315971374512,800.057006835938,800.057006835938,,,2.91369318962097,0,1,,,,,,1,1,1,2.79995679855347,0,0,2.80001571092261,,,,,,,,,,,,,,,,,,,,,,,,,,,,,,,,,
,3823567637.4109,2.79985642433166,800.057006835938,,,5,,,,26.7500001937151,,,,,2.08841973455706E-6,7.73842999773474E-9,5.48983286098189,0.00270588787782524,6.96119328622812E-7,2.57940039805276E-9,6.92926361893353E-7,1.77499560383389E-9,6.65971221263778E-8,1.87154936345401E-9,3.00008870417196,24.0295906066895,13,312,1,3,0.00669220447349069,0.00174049813689442,0.0204211454838514,147.439849853516,2.79842066764832,2.80181002616882,800.057006835938,800.057006835938,,,2.91460394859314,0,1,,,,,,1,1,1,2.80010509490967,0,0,2.79997685179114,,,,,,,,,,,,,,,,,,,,,,,,,,,,,,,,,
,3823567960.99992,2.79974615573883,800.057006835938,,,5,,,,26.7500001937151,,,,,1.88428272535942E-6,5.17147999655191E-9,13.728415580525,0.00224605826022267,6.28122308342883E-7,1.72390369516529E-9,6.10177822383578E-7,9.71038469484983E-10,1.49065956238257E-7,1.42440452154042E-9,2.99986595020093,83.3244476318359,13,1083,1,3,0.00581438061474905,0.00223795574073751,0.00998637825250626,128.848129272461,2.79636764526367,2.80162787437439,800.057006835938,800.057006835938,,,2.91580533981323,0,1,,,,,,1,1,1,2.8000659942627,0,0,2.79996031017627,,,,,,,,,,,,,,,,,,,,,,,,,,,,,,,,,
,3823568281.38721,2.79951798915863,800.057006835938,,,5,,,,26.7500001937151,,,,,1.40880622792544E-6,6.2991316719069E-9,18.7269384640264,0.00362993541524209,4.69610041561257E-7,2.09974617346778E-9,4.44748619263109E-7,1.30582682638886E-9,1.50772201677641E-7,1.64430845417635E-9,2.99994911361297,288.071533203125,13,3744,1,3,0.00421600806251661,0.00198212657235048,0.00553933484479785,127.975524902344,2.79896712303162,2.80181312561035,800.057006835938,800.057006835938,,,2.91579008102417,0,1,,,,,,1,1,1,2.80006885528564,0,0,2.79999992539806,,,,,,,,,,,,,,,,,,,,,,,,,,,,,,,,,
,3823568656.66488,2.80004477500916,800.057006835938,,,5,,,,26.7500001937151,,,,,2.84639172232239E-5,4.67763719455437E-7,57.5012879379,1.78045358845683,9.48757827797131E-6,1.559147628601E-7,5.09749222240448E-6,1.11458312440849E-7,8.00185694843134E-6,1.09025033205954E-7,3.00012462498599,999.040954589844,13,12987,1000,3,0.0266090900760437,0.0904575060328666,0.0072113717906177,89.3004150390625,2.796217918396,2.8046715259552,800.057006835938,800.057006835938,,,2.9155490398407,0,1,,,,,,1,1,1,2.79996871948242,0,0,2.80001059689916,,,,,,,,,,,,,,,,,,,,,,,,,,,,,,,,,
,3823569272.83402,2.99986231327057,800.057006835938,,,5,,,,26.7500001937151,,,,,1.92482405680686E-6,3.3202370704911E-8,1.30324866318363,0.0102982177491532,6.41608833009084E-7,1.10674709440472E-8,6.41442862500304E-7,8.88600092255191E-9,1.45927633673313E-8,6.59756778682383E-9,2.99999619359917,5.41091823577881,13,70,1,3,0.00636146974774486,0.000526778822969845,0.0257899761199951,170.964172363281,2.99864220619202,3.00221920013428,800.057006835938,800.057006835938,,,3.01501250267029,0,1,,,,,,1,1,1,2.99982404708862,0,0,3.00002845498018,,,,,,,,,,,,,,,,,,,,,,,,,,,,,,,,,
,3823569654.40255,3.0000878572464,800.057006835938,,,5,,,,26.7500001937151,,,,,1.9350772739302E-6,9.24150989204035E-9,2.95204978455463,0.00234765005687561,6.45043022471017E-7,3.08058574883173E-9,6.44187040337475E-7,2.70909897873429E-9,3.32198419591304E-8,1.46655762905041E-9,2.99991970538235,18.75119972229,13,243,1,3,0.0062852744569444,0.0012563464533478,0.0221234206110239,152.609405517578,2.99822950363159,3.0016667842865,800.057006835938,800.057006835938,,,3.0162570476532,0,1,,,,,,1,1,1,2.99987816810608,0,0,2.99998947657072,,,,,,,,,,,,,,,,,,,,,,,,,,,,,,,,,
,3823569978.65486,2.99952006340027,800.057006835938,,,5,,,,26.7500001937151,,,,,1.84699908935091E-6,8.45055061981662E-9,8.47662386158343,0.00263440093323781,6.15685875791071E-7,2.81693948268649E-9,6.089601761676E-7,2.39181718099533E-9,9.07557242852711E-8,1.48807211579735E-9,2.99990492225889,64.9310150146484,13,844,1,3,0.00585360953213592,0.00174404705378165,0.0118046253919601,130.497344970703,2.99795699119568,3.00305438041687,800.057006835938,800.057006835938,,,3.01712560653687,0,1,,,,,,1,1,1,2.99997544288635,0,0,2.9999961625962,,,,,,,,,,,,,,,,,,,,,,,,,,,,,,,,,
,3823570298.83417,2.9998277425766,800.057006835938,,,5,,,,26.7500001937151,,,,,1.49192013731693E-6,6.16350545730051E-9,17.0393283049077,0.00325454603957762,4.97331226828732E-7,2.05460309434358E-9,4.75500297860029E-7,1.32243789990162E-9,1.45732000308771E-7,1.57243501493384E-9,2.99985212436842,225.014404296875,13,2925,1,3,0.00453882983522045,0.00193177532306867,0.00591074302792549,129.160140991211,2.99899625778198,3.0015013217926,800.057006835938,800.057006835938,,,3.01746153831482,0,1,,,,,,1,1,1,2.99997472763062,0,0,3.00001653035482,,,,,,,,,,,,,,,,,,,,,,,,,,,,,,,,,
,3823570617.74467,2.99961864948273,800.057006835938,,,5,,,,26.7500001937151,,,,,1.0624098865281E-6,1.80615713059177E-8,17.3144628515289,0.0151668429643375,3.54148466331141E-7,6.02072501266404E-9,3.38100478047933E-7,5.25815938378295E-9,1.05400203740117E-7,2.93272732671378E-9,2.99989972435659,779.690673828125,13,10135,1,3,0.00304136897885313,0.0017675781716411,0.00620784936472774,101.978454589844,2.99710750579834,3.003830909729,800.057006835938,800.057006835938,,,3.01711583137512,0,1,,,,,,1,1,1,3.00015091896057,0,0,3.00004174595787,,,,,,,,,,,,,,,,,,,,,,,,,,,,,,,,,
,3823571214.99422,3.20002222061157,800.057006835938,,,5,,,,26.7500001937151,,,,,1.84460334612539E-6,7.99869653987664E-8,0.990669588699038,0.0151266160101291,6.14867988919181E-7,2.66623307703489E-8,6.14776080887348E-7,2.50096581074587E-8,1.06308121190883E-8,9.24104341811667E-9,2.99999899062537,4.21513509750366,13,54,1,3,0.00610457768322791,0.00039996060537066,0.0259485505521297,172.899337768555,3.19799733161926,3.2021312713623,800.057006835938,800.057006835938,,,3.11121940612793,0,1,,,,,,1,1,1,3.20003914833069,0,0,3.19998637478003,,,,,,,,,,,,,,,,,,,,,,,,,,,,,,,,,
,3823571620.08108,3.20001935958862,800.057006835938,,,5,,,,26.7500001937151,,,,,1.84170705391931E-6,1.21396976605005E-8,1.61025250921608,0.00332438449921151,6.1392479403357E-7,4.04671381911268E-9,6.13682356813109E-7,3.50840647423061E-9,1.72515989250103E-8,2.01667467514576E-9,2.99989033154867,14.6017122268677,13,189,1,3,0.00602810890473404,0.000950353320271242,0.0234586969017982,157.464370727539,3.19841647148132,3.2012300491333,800.057006835938,800.057006835938,,,3.11214208602905,0,1,,,,,,1,1,1,3.20003962516785,0,0,3.19999658511235,,,,,,,,,,,,,,,,,,,,,,,,,,,,,,,,,
,3823571947.09754,3.19990658760071,800.057006835938,,,5,,,,26.7500001937151,,,,,1.81174628450495E-6,8.38224009845099E-9,5.88945759235229,0.00380634188688948,6.03871268341809E-7,2.79387572260443E-9,6.00683863126963E-7,1.56325626441519E-9,6.19629349499649E-8,2.31559310007719E-9,3.00021938364428,50.6515846252441,13,658,1,3,0.00579566782536333,0.00152388776786745,0.0139068309217691,133.392929077148,3.19908618927002,3.20241498947144,800.057006835938,800.057006835938,,,3.11314153671265,0,1,,,,,,1,1,1,3.20011234283447,0,0,3.20001286552066,,,,,,,,,,,,,,,,,,,,,,,,,,,,,,,,,
,3823572267.25397,3.19963920116425,800.057006835938,,,5,,,,26.7500001937151,,,,,1.61125591895506E-6,6.1820290884192E-9,14.8956800687499,0.00295562014020449,5.37100130941531E-7,2.06073324157446E-9,5.19051130052594E-7,1.34849011529501E-9,1.38066922354828E-7,1.55826695462672E-9,2.99991719631598,175.640731811523,13,2283,1,3,0.00497914773938924,0.00189321304022932,0.00649302965030074,129.142913818359,3.19833731651306,3.20236968994141,800.057006835938,800.057006835938,,,3.11378502845764,0,1,,,,,,1,1,1,3.2001211643219,0,0,3.1999678725288,,,,,,,,,,,,,,,,,,,,,,,,,,,,,,,,,
,3823572586.02493,3.19961726665497,800.057006835938,,,5,,,,26.7500001937151,,,,,1.17773680620005E-6,9.63827431992154E-9,17.9292117754342,0.00667941574068612,3.92590064516664E-7,3.21284918427232E-9,3.73524939737798E-7,2.69990311793612E-9,1.20855608686868E-7,1.74152893591755E-9,2.9999149562025,608.450134277344,13,7909,1,3,0.00343140798847688,0.00184912042818959,0.00566673604771495,112.179016113281,3.19844675064087,3.20256447792053,800.057006835938,800.057006835938,,,3.11375737190247,0,1,,,,,,1,1,1,3.20003795623779,0,0,3.20004659985739,,,,,,,,,,,,,,,,,,,,,,,,,,,,,,,,,
,3823573231.44606,3.40000891685486,800.057006835938,,,5,,,,26.7500001937151,,,,,1.72121366943354E-6,6.92347555663636E-8,0.256782378716472,0.0158812055984783,5.73738142836103E-7,2.30782620332257E-8,5.73732380903538E-7,2.12067387412223E-8,2.57131246213821E-9,9.10386788325536E-9,2.99999867696652,3.30276823043823,13,42,1,3,0.0057033402893222,0.000247400873090147,0.0260544680058956,174.381118774414,3.39808320999146,3.40144443511963,800.057006835938,800.057006835938,,,3.20182514190674,0,1,,,,,,1,1,1,3.40009546279907,0,0,3.39999693251671,,,,,,,,,,,,,,,,,,,,,,,,,,,,,,,,,
,3823573662.39935,3.40023255348206,800.057006835938,,,5,,,,26.7500001937151,,,,,1.72399731168778E-6,1.69004027096353E-8,0.806904309090836,0.00456321888164889,5.74683731498245E-7,5.63364364152513E-9,5.74626742564165E-7,4.99452573275928E-9,8.09308215970126E-9,2.60627193218627E-9,2.99990623919906,11.4084405899048,13,148,1,3,0.00567083041302838,0.000703208060661353,0.0244186539202929,161.730575561523,3.39851117134094,3.40150260925293,800.057006835938,800.057006835938,,,3.20297908782959,0,1,,,,,,1,1,1,3.40006470680237,0,0,3.40003665855953,,,,,,,,,,,,,,,,,,,,,,,,,,,,,,,,,
,3823573990.55811,3.39983701705933,800.057006835938,,,5,,,,26.7500001937151,,,,,1.70472967840366E-6,9.00468323443441E-9,3.1826652695265,0.00440039059421104,5.68224892408312E-7,3.00146423616487E-9,5.67348466412349E-7,1.64443062516516E-9,3.1547519902419E-8,2.51090331952381E-9,3.00009679473648,39.504955291748,13,513,1,3,0.00550631506659242,0.00122214297094378,0.0161657799035311,137.419555664062,3.39909553527832,3.40220475196838,800.057006835938,800.057006835938,,,3.20397567749023,0,1,,,,,,1,1,1,3.4000403881073,0,0,3.40004043653607,,,,,,,,,,,,,,,,,,,,,,,,,,,,,,,,,
,3823574311.67398,3.39957070350647,800.057006835938,,,5,,,,26.7500001937151,,,,,1.64021519678509E-6,4.50779550899221E-9,10.0668625112935,0.00205094593293994,5.46750314646886E-7,1.50263125090911E-9,5.38332787432971E-7,1.00759345420725E-9,9.55704794437899E-8,1.11474486195155E-9,2.99993461886604,136.773452758789,13,1778,1,3,0.00520695026240934,0.00151375739723166,0.00733918929472566,128.633514404297,3.39876556396484,3.4029233455658,800.057006835938,800.057006835938,,,3.20478129386902,0,1,,,,,,1,1,1,3.40013289451599,0,0,3.40001156216576,,,,,,,,,,,,,,,,,,,,,,,,,,,,,,,,,
,3823574630.39288,3.39945673942566,800.057006835938,,,5,,,,26.7500001937151,,,,,1.28823881652386E-6,4.96675984064444E-9,17.9099359212388,0.00303105370674064,4.29431954999296E-7,1.65565992968232E-9,4.08622150311031E-7,1.25107024163731E-9,1.32059616271239E-7,1.08445057667245E-9,2.99986715363549,474.059478759766,13,6162,1,3,0.00381511002069566,0.00190018266398233,0.0054319896735251,119.841659545898,3.39850521087646,3.40172433853149,800.057006835938,800.057006835938,,,3.20491456985474,0,1,,,,,,1,1,1,3.39992523193359,0,0,3.40002864126175,,,,,,,,,,,,,,,,,,,,,,,,,,,,,,,,,
,3823575163.68067,3.5995934009552,800.057006835938,,,5,,,,26.7500001937151,,,,,1.62695989838475E-6,5.1248146622964E-8,0.590275668900268,0.0150126110418783,5.42320380052707E-7,1.7082728579331E-8,5.42291600331166E-7,1.5021879377062E-8,5.58702342716662E-9,8.13404915746715E-9,2.9999977102587,2.59945297241211,13.4643713009828,33,1,3,0.0053915140496777,0.000225938554218551,0.0261097531765699,175.514709472656,3.59825468063354,3.60175538063049,800.057006835938,800.057006835938,,,3.28852725028992,0,1,,,,,,1,1,1,3.59923005104065,0,0,3.6000106408424,,,,,,,,,,,,,,,,,,,,,,,,,,,,,,,,,
,3823575610.74655,3.60001790523529,800.057006835938,,,5,,,,26.7500001937151,,,,,1.64187949930332E-6,2.8864133121519E-8,0.242681178654769,0.0118311007298486,5.47282945374292E-7,9.62119802161091E-9,5.47278036202884E-7,7.11801217315078E-9,2.31805683155696E-9,6.47312552588986E-9,3.00005602802116,8.89725303649902,13,115,1,3,0.00541884666729623,0.000516130618358456,0.0250957682728767,165.394561767578,3.59918022155762,3.602534532547,800.057006835938,800.057006835938,,,3.29002952575684,0,1,,,,,,1,1,1,3.59996175765991,0,0,3.60003300992454,,,,,,,,,,,,,,,,,,,,,,,,,,,,,,,,,
,3823575955.89009,3.59975457191467,800.057006835938,,,5,,,,26.7500001937151,,,,,1.63696196716346E-6,8.70683718690643E-9,2.39982715512042,0.00430888642012976,5.45674949088362E-7,2.90239054662862E-9,5.45196368378102E-7,1.69547243619943E-9,2.28488505162671E-8,2.35568336226394E-9,2.99988476637653,30.8258380889893,13,400,1,3,0.00530281925873825,0.00111104423313912,0.0184197872877121,142.229782104492,3.59858274459839,3.60202145576477,800.057006835938,800.057006835938,,,3.29072260856628,0,1,,,,,,1,1,1,3.60009384155273,0,0,3.5999951327025,,,,,,,,,,,,,,,,,,,,,,,,,,,,,,,,,
,3823576278.26115,3.59931290149689,800.057006835938,,,5,,,,26.7500001937151,,,,,1.62215301733201E-6,7.95632015580896E-9,6.86944050569331,0.00393842002283278,5.40698620751098E-7,2.65201327404711E-9,5.36817095319931E-7,1.56217634261392E-9,6.46715134693229E-8,2.14307710554229E-9,3.00010570598208,106.844917297363,13,1388,1,3,0.00521483011456136,0.001251888540076,0.00844134297221899,128.356079101562,3.59791445732117,3.60273337364197,800.057006835938,800.057006835938,,,3.2915952205658,0,1,,,,,,1,1,1,3.59989666938782,0,0,3.5999863223424,,,,,,,,,,,,,,,,,,,,,,,,,,,,,,,,,
,3823576596.88986,3.59950292110443,800.057006835938,,,5,,,,26.7500001937151,,,,,1.40117736212448E-6,5.779171431576E-9,15.3876495020608,0.00305155425575538,4.67070680209034E-7,1.92643815448042E-9,4.50327422046149E-7,1.40718843137026E-9,1.23936408146272E-7,1.31566891034774E-9,2.99992575320162,369.910034179687,13,4808,1,3,0.00427626473747618,0.00178659255455286,0.00540850218385458,125.011016845703,3.59819078445435,3.60149765014648,800.057006835938,800.057006835938,,,3.29188680648804,0,1,,,,,,1,1,1,3.59997630119324,0,0,3.59999127615066,,,,,,,,,,,,,,,,,,,,,,,,,,,,,,,,,
,3823577105.9428,3.79995000362396,800.057006835938,,,5,,,,26.7500001937151,,,,,1.54611462166684E-6,4.63783433240744E-8,-1.24457811597701,0.0243165725403968,5.15372819364106E-7,1.54594861347319E-8,5.15251236185359E-7,9.05478993545457E-9,-1.11940407702975E-8,1.25302230935749E-8,2.99999255601899,1.99984133243561,17.5013884513395,33,1,3,0.00512816350024223,1.82636733934207E-5,0.0261466801166534,176.477844238281,3.79866528511047,3.80224609375,800.057006835938,800.057006835938,,,3.37137532234192,0,1,,,,,,1,1,1,3.79993033409119,0,0,3.79999127463689,,,,,,,,,,,,,,,,,,,,,,,,,,,,,,,,,
,3823577583.41089,3.79997599124908,800.057006835938,,,5,,,,26.7500001937151,,,,,1.54725547209564E-6,5.62646582048128E-8,0.121105580504911,0.016132300524989,5.157476574992E-7,1.87547345557758E-8,5.15746505399262E-7,1.68113434159101E-8,1.09013043330081E-9,8.31377175594491E-9,3.00002423587943,6.93581342697144,13,90,1,3,0.00511566402461545,0.000390336052167198,0.0255185440182686,168.464370727539,3.79817676544189,3.8015296459198,800.057006835938,800.057006835938,,,3.37257623672485,0,1,,,,,,1,1,1,3.79998993873596,0,0,3.80001166604814,,,,,,,,,,,,,,,,,,,,,,,,,,,,,,,,,
,3823577944.66804,3.79985654354095,800.057006835938,,,5,,,,26.7500001937151,,,,,1.51936040980238E-6,1.4203513613872E-8,0.525790433533906,0.00465984125402152,5.06460727582437E-7,4.7345723849974E-9,5.06439402396502E-7,4.11577083782898E-9,4.64761052645983E-9,2.34021496432625E-9,2.99995700960855,24.0295906066895,13,312,1,3,0.00496000031621105,0.000840188780025898,0.0204258989542723,147.45051574707,3.79887843132019,3.80169606208801,800.057006835938,800.057006835938,,,3.37343430519104,0,1,,,,,,1,1,1,3.80015897750854,0,0,3.79998336732388,,,,,,,,,,,,,,,,,,,,,,,,,,,,,,,,,
,3823578267.64625,3.799635887146,800.057006835938,,,5,,,,26.7500001937151,,,,,1.52610180469081E-6,7.55508139342658E-9,3.06079075879164,0.0019271597136939,5.08719069759213E-7,2.51845189266242E-9,5.07993353663079E-7,2.34192776181965E-9,2.71632945501176E-8,9.2626901819792E-10,2.99989109001388,83.3244476318359,13,1083,1,3,0.00496327765502721,0.0009094614396971,0.00995662901550531,128.850448608398,3.79875564575195,3.80227494239807,800.057006835938,800.057006835938,,,3.37434363365173,0,1,,,,,,1,1,1,3.80008125305176,0,0,3.79998969274854,,,,,,,,,,,,,,,,,,,,,,,,,,,,,,,,,
,3823578582.68848,3.79959344863892,800.057006835938,,,5,,,,26.7500001937151,,,,,1.43338796593629E-6,5.96598605964912E-9,10.8053913879097,0.00342578648500314,4.77800820518735E-7,1.98868213089936E-9,4.69329227669919E-7,1.09636364356801E-9,8.95751089484877E-8,1.65916948465812E-9,2.9999696617936,288.071533203125,13,3744,1,3,0.00452661655234755,0.00140614887977349,0.0055376784875989,127.978256225586,3.79880475997925,3.80238628387451,800.057006835938,800.057006835938,,,3.37504649162292,0,1,,,,,,1,1,1,3.80013346672058,0,0,3.80002551987058,,,,,,,,,,,,,,,,,,,,,,,,,,,,,,,,,
,3823578919.6119,3.79998099803925,800.057006835938,,,5,,,,26.7500001937151,,,,,1.92950620010322E-6,1.65467593428222E-6,7.22174134444212,0.570844420926963,6.43183464835691E-7,5.51571277944037E-7,6.38081136194431E-7,4.65371774083743E-7,8.08543942582484E-8,2.96074292262884E-7,2.99993128802858,999.040954589844,13,12987,1000,3,0.00586939304478349,0.00253047999294774,0.00723950983956456,89.3362121582031,3.79746580123901,3.80402374267578,800.057006835938,800.057006835938,,,3.37397503852844,0,1,,,,,,1,1,1,3.79997682571411,0,0,3.80003795586526,,,,,,,,,,,,,,,,,,,,,,,,,,,,,,,,,
,3823579538.47851,4.00007581710815,800.057006835938,,,5,,,,26.7500001937151,,,,,1.44383385715576E-6,4.14052009651608E-8,-0.180185324565708,0.019425057241935,4.81277845161194E-7,1.38017305801613E-8,4.81275465259137E-7,1.01530928879943E-8,-1.5135331525713E-9,9.34892891272139E-9,3.00000066837104,5.41091823577881,13,70,1,3,0.00478044589656822,0.00027147555912729,0.0258068218827248,170.913848876953,3.99929046630859,4.0019211769104,800.057006835938,800.057006835938,,,3.45109939575195,0,1,,,,,,1,1,1,4.00004577636719,0,0,4.00001926754796,,,,,,,,,,,,,,,,,,,,,,,,,,,,,,,,,
,3823579923.27984,3.99977469444275,800.057006835938,,,5,,,,26.7500001937151,,,,,1.44026073261409E-6,8.64609833250048E-9,-0.124344936168638,0.00329823949239326,4.80099348432567E-7,2.8821074420208E-9,4.80098217824986E-7,2.40984987736758E-9,-1.04192449218774E-9,1.58087535115932E-9,2.99992228132836,18.75119972229,13,243,1,3,0.00472151702719776,0.000682670005097173,0.0221253074705601,152.609130859375,3.99834632873535,4.00201177597046,800.057006835938,800.057006835938,,,3.4521062374115,0,1,,,,,,1,1,1,3.99989247322082,0,0,4.00000493709858,,,,,,,,,,,,,,,,,,,,,,,,,,,,,,,,,
,3823580247.02394,3.99957263469696,800.057006835938,,,5,,,,26.7500001937151,,,,,1.46961511464981E-6,7.18726724006317E-9,2.29500031443608,0.0022300402625114,4.89872835561837E-7,2.39576127635938E-9,4.89479905253596E-7,2.14806855523395E-9,1.96167625852379E-8,1.06088339383659E-9,2.99999307568116,64.9310150146484,13,844,1,3,0.00477993661775381,0.000878064837307312,0.0118006663396955,130.503799438477,3.99853253364563,4.00194406509399,800.057006835938,800.057006835938,,,3.45315289497375,0,1,,,,,,1,1,1,4.00007104873657,0,0,3.9999905427297,,,,,,,,,,,,,,,,,,,,,,,,,,,,,,,,,
,3823580568.30268,3.99944460391998,800.057006835938,,,5,,,,26.7500001937151,,,,,1.42815313940366E-6,4.5826923428364E-9,6.81130449493507,0.00212886699182526,4.76074561744489E-7,1.52763957066722E-9,4.72714488234385E-7,1.1551604551058E-9,5.64623852977428E-8,9.99643426841846E-10,2.99985181768683,225.014404296875,13,2925,1,3,0.00460416888815095,0.00104821307627089,0.00592434220016003,129.161224365234,3.99826908111572,4.00216102600098,800.057006835938,800.057006835938,,,3.45357966423035,0,1,,,,,,1,1,1,4.00002384185791,0,0,4.00001248859224,,,,,,,,,,,,,,,,,,,,,,,,,,,,,,,,,
,3823580887.30543,3.99949288368225,800.057006835938,,,5,,,,26.7500001937151,,,,,1.23091033078001E-6,2.44570825095663E-8,14.1882266805595,0.015196821767563,4.10284547516029E-7,8.15198538844091E-9,3.97769119351948E-7,7.01051641300713E-9,1.00564097074493E-7,4.16023141138949E-9,3.00013816808911,779.690673828125,13,10135,1,3,0.00363031235395024,0.00185237915949541,0.00621212832629681,102.015258789062,3.99785971641541,4.00274229049683,800.057006835938,800.057006835938,,,3.45351147651672,0,1,,,,,,1,1,1,4.00010347366333,0,0,4.00005707665095,,,,,,,,,,,,,,,,,,,,,,,,,,,,,,,,,
,3823581478.02606,4.20004749298096,800.057006835938,,,5,,,,26.7500001937151,,,,,1.35957420618886E-6,7.5364187916436E-8,0.31733388917208,0.0329967096422244,4.53191444375343E-7,2.51213983176141E-8,4.53184493520157E-7,2.0188745426696E-8,2.50999758720882E-9,1.4949890017264E-8,2.99999971990387,4.21513509750366,13,54,1,3,0.00450256351086134,0.000241895021155255,0.0259508155286312,172.890411376953,4.19831514358521,4.20206212997437,800.057006835938,800.057006835938,,,3.52658224105835,0,1,,,,,,1,1,1,4.19998931884766,0,0,4.20001017645504,,,,,,,,,,,,,,,,,,,,,,,,,,,,,,,,,
,3823581880.03292,4.19996118545532,800.057006835938,,,5,,,,26.7500001937151,,,,,1.40629234234425E-6,9.73083931581138E-9,0.42079879424464,0.00306910020415822,4.68783504952645E-7,3.24374728016573E-9,4.68770862128923E-7,2.91147117138621E-9,3.44286720518325E-9,1.4301160917106E-9,2.99987590750726,14.6017122268677,13,189,1,3,0.0046170218089899,0.000629958015961272,0.0234633218497038,157.460220336914,4.19898700714111,4.20113897323608,800.057006835938,800.057006835938,,,3.52745866775513,0,1,,,,,,1,1,1,4.20004034042358,0,0,4.19998737481924,,,,,,,,,,,,,,,,,,,,,,,,,,,,,,,,,
,3823582205.95626,4.19959092140198,800.057006835938,,,5,,,,26.7500001937151,,,,,1.39751248995817E-6,6.21708755909695E-9,1.60838185613283,0.00341710867538814,4.65817423786703E-7,2.07227322191703E-9,4.65633900879668E-7,1.32715805172126E-9,1.30745040006924E-8,1.59153002234511E-9,3.00012927510863,50.6515846252441,13,658,1,3,0.00454583777400435,0.000838439775377282,0.0139132644981146,133.401290893555,4.1988959312439,4.20111703872681,800.057006835938,800.057006835938,,,3.52836489677429,0,1,,,,,,1,1,1,4.20000314712524,0,0,4.19998864522056,,,,,,,,,,,,,,,,,,,,,,,,,,,,,,,,,
,3823582530.70854,4.19948196411133,800.057006835938,,,5,,,,26.7500001937151,,,,,1.38253216514578E-6,6.43815432179913E-9,4.13630418538287,0.00239820180688465,4.60866474248623E-7,2.14615584198234E-9,4.59666046104648E-7,1.85598725350677E-9,3.32420388194854E-8,1.07763454514753E-9,2.99985406271913,175.640731811523,13,2283,1,3,0.00450050771871188,0.000798237744809372,0.00646582012996078,129.153411865234,4.19873332977295,4.20237731933594,800.057006835938,800.057006835938,,,3.52858066558838,0,1,,,,,,1,1,1,4.19992828369141,0,0,4.20000556915525,,,,,,,,,,,,,,,,,,,,,,,,,,,,,,,,,
,3823582854.37594,4.19942927360535,800.057006835938,,,5,,,,26.7500001937151,,,,,1.29607320213582E-6,8.13634119091195E-9,10.2738359800883,0.00388334956609889,4.32008925853427E-7,2.71201658399425E-9,4.25082347493225E-7,2.31217632350836E-9,7.70500478045326E-8,1.41734773463226E-9,3.00010746207488,608.450134277344,13,7909,1,3,0.00401369749599295,0.00151346104582361,0.00563515350222588,112.206527709961,4.19874572753906,4.20217847824097,800.057006835938,800.057006835938,,,3.5287184715271,0,1,,,,,,1,1,1,4.19989442825317,0,0,4.20004538884239,,,,,,,,,,,,,,,,,,,,,,,,,,,,,,,,,
,3823583468.4437,4.40013432502747,800.057006835938,,,5,,,,26.7500001937151,,,,,1.37164413183233E-6,9.13240724275683E-8,-0.845785513300975,0.041516205927778,4.57214951864812E-7,3.04413735385509E-8,4.57165137136979E-7,2.37944629187797E-8,-6.74904402635517E-9,1.89868574893374E-8,2.99999841702004,3.30276823043823,13,42,1,3,0.004547973801012,0.000109660416080398,0.0260635688900948,174.388809204102,4.39922046661377,4.40220737457275,800.057006835938,800.057006835938,,,3.59788298606873,0,1,,,,,,1,1,1,4.40001344680786,0,0,4.40001641323692,,,,,,,,,,,,,,,,,,,,,,,,,,,,,,,,,
,3823583899.13996,4.39994645118713,800.057006835938,,,5,,,,26.7500001937151,,,,,1.31841918594391E-6,1.61228229638077E-8,0.0520163795261883,0.00626088873731777,4.39486794581602E-7,5.37444225593359E-9,4.3948661346812E-7,4.61835526849817E-9,3.98991146602614E-10,2.74871318552878E-9,2.99990625929742,11.4084405899048,13,148,1,3,0.0043434513794361,0.000480586868433914,0.0244212169200182,161.730880737305,4.39840316772461,4.40145254135132,800.057006835938,800.057006835938,,,3.59864854812622,0,1,,,,,,1,1,1,4.40013265609741,0,0,4.39999345370701,,,,,,,,,,,,,,,,,,,,,,,,,,,,,,,,,
,3823584227.73602,4.39971542358398,800.057006835938,,,5,,,,26.7500001937151,,,,,1.31549528813662E-6,7.74218197683872E-9,0.413953308543988,0.00277304102199585,4.38478278220262E-7,2.58060872850472E-9,4.38466834330906E-7,2.28237258711676E-9,3.16791143178595E-9,1.20429098776528E-9,3.00013787108469,39.504955291748,13,513,1,3,0.00428967794079304,0.00073672701098385,0.0161791238933802,137.422592163086,4.39880132675171,4.40215063095093,800.057006835938,800.057006835938,,,3.60009336471558,0,1,,,,,,1,1,1,4.39995956420898,0,0,4.40002925055368,,,,,,,,,,,,,,,,,,,,,,,,,,,,,,,,,
,3823584549.77227,4.39970278739929,800.057006835938,,,5,,,,26.7500001937151,,,,,1.33607249256109E-6,5.11179760245756E-9,2.66839133447275,0.00261834681954213,4.453483398273E-7,1.70389749692684E-9,4.4486545326359E-7,1.24481630397964E-9,2.07333615102103E-8,1.16348573234914E-9,3.00006168896735,136.773452758789,13,1778,1,3,0.00436491139017619,0.000676565534753879,0.0073124342598021,128.646194458008,4.39895582199097,4.40145206451416,800.057006835938,800.057006835938,,,3.60079717636108,0,1,,,,,,1,1,1,4.40003347396851,0,0,4.40001380254352,,,,,,,,,,,,,,,,,,,,,,,,,,,,,,,,,
,3823584864.59559,4.39949655532837,800.057006835938,,,5,,,,26.7500001937151,,,,,1.29503478026932E-6,5.6896238688828E-9,8.07926384114603,0.00320439612428,4.31693624462068E-7,1.89660879167517E-9,4.27408886967511E-7,1.31655981150875E-9,6.06714821179622E-8,1.36520883800963E-9,2.99989322724665,474.059478759766,13,6162,1,3,0.0041051195965872,0.00122712211247789,0.00544252479448914,119.828308105469,4.3982663154602,4.4020791053772,800.057006835938,800.057006835938,,,3.60093283653259,0,1,,,,,,1,1,1,4.4000244140625,0,0,4.40000752479799,,,,,,,,,,,,,,,,,,,,,,,,,,,,,,,,,
,3823585388.36538,4.60004615783691,800.057006835938,,,5,,,,26.7500001937151,,,,,1.29952227407527E-6,6.35609600980593E-8,2.27461383121349,0.0353814881178378,4.33173529443701E-7,2.11869592155307E-8,4.32832222628323E-7,1.46262586930977E-8,1.7192255970032E-8,1.53283983978479E-8,3.000003891614,2.59945297241211,13.4643713009828,33,1,3,0.00429926722016908,0.000306966549742967,0.0261018835008144,175.529281616211,4.59836483001709,4.60169553756714,800.057006835938,800.057006835938,,,3.66759157180786,0,1,,,,,,1,1,1,4.59993696212769,0,0,4.60000625099103,,,,,,,,,,,,,,,,,,,,,,,,,,,,,,,,,
,3823585838.36097,4.60003328323364,800.057006835938,,,5,,,,26.7500001937151,,,,,1.27558128996426E-6,5.84628122186863E-8,-0.661408240071161,0.0255078447382882,4.25184873292131E-7,1.94871966224907E-8,4.25156543921617E-7,1.61827360039803E-8,-4.90811950463781E-9,1.08567899320697E-8,3.00006272586242,8.89725303649902,13,115,1,3,0.00421572205456083,0.000334502379869308,0.0250550713390112,165.398727416992,4.59885454177856,4.60196113586426,800.057006835938,800.057006835938,,,3.66833662986755,0,1,,,,,,1,1,1,4.60003042221069,0,0,4.60002169957975,,,,,,,,,,,,,,,,,,,,,,,,,,,,,,,,,
,3823586185.91811,4.59957957267761,800.057006835938,,,5,,,,26.7500001937151,,,,,1.27737621162237E-6,9.26218133574553E-9,0.334059922804681,0.00393847823927756,4.2580007251149E-7,3.08745180041049E-9,4.25792835187863E-7,2.59856667529158E-9,2.48259007315016E-9,1.66727617805871E-9,2.99994362163454,30.8258380889893,13,400,1,3,0.00416653244832744,0.000717247355840669,0.0183785334229469,142.234176635742,4.59875965118408,4.60168600082397,800.057006835938,800.057006835938,,,3.66918540000916,0,1,,,,,,1,1,1,4.59985542297363,0,0,4.59997709095478,,,,,,,,,,,,,,,,,,,,,,,,,,,,,,,,,
,3823586506.93181,4.59953927993774,800.057006835938,,,5,,,,26.7500001937151,,,,,1.27703805670023E-6,6.02123150241361E-9,1.57259772593463,0.0036435551849577,4.25660843173432E-7,2.00698989729594E-9,4.25500519940178E-7,1.27270423768598E-9,1.16816497873696E-8,1.55184805030136E-9,3.00013044934912,106.844917297363,13,1388,1,3,0.0041788263216027,0.000602298980999793,0.00846786890178919,128.353454589844,4.59898138046265,4.6021032333374,800.057006835938,800.057006835938,,,3.66981506347656,0,1,,,,,,1,1,1,4.60008239746094,0,0,4.60001355882675,,,,,,,,,,,,,,,,,,,,,,,,,,,,,,,,,
,3823586824.97225,4.59958624839783,800.057006835938,,,5,,,,26.7500001937151,,,,,1.2535575911413E-6,5.37978534132057E-9,4.53249881513291,0.00306521972029637,4.17864582874143E-7,1.79331350509125E-9,4.16557782628448E-7,1.25964353181367E-9,3.30215589010047E-8,1.27642919909513E-9,2.9999134708166,369.910034179687,13,4808,1,3,0.00405833095460932,0.000849107659856533,0.00541043048724532,125.009017944336,4.5988450050354,4.60163068771362,800.057006835938,800.057006835938,,,3.67022728919983,0,1,,,,,,1,1,1,4.60008955001831,0,0,4.60002118065244,,,,,,,,,,,,,,,,,,,,,,,,,,,,,,,,,
,3823587305.23286,4.80019187927246,800.057006835938,,,5,,,,26.7500001937151,,,,,1.21642234653918E-6,6.55441028511629E-8,-0.822747798825121,0.0444037162854833,4.05473349593133E-7,2.18479930138984E-8,4.05431546054135E-7,1.23798561346304E-8,-5.82225853328572E-9,1.80020543500237E-8,3.00000566685771,1.99984133243561,17.5013884513395,33,1,3,0.00403442279257559,4.40718977761342E-5,0.0261537935584784,176.517044067383,4.79886054992676,4.80195045471191,800.057006835938,800.057006835938,,,3.73397827148438,0,1,,,,,,1,1,1,4.80018520355225,0,0,4.79998060256716,,,,,,,,,,,,,,,,,,,,,,,,,,,,,,,,,
,3823587781.39542,4.800133228302,800.057006835938,,,5,,,,26.7500001937151,,,,,1.1927379836626E-6,4.05778844559174E-8,-0.468572967848546,0.0264623943511308,3.97575601691717E-7,1.3525834717193E-8,3.97562306441824E-7,8.50356303225569E-9,-3.25139311497561E-9,1.05184419261257E-8,3.00002811688493,6.93581342697144,13,90,1,3,0.00394641708545355,0.00026029519582859,0.0255262907594442,168.469390869141,4.79896211624146,4.80207252502441,800.057006835938,800.057006835938,,,3.734530210495,0,1,,,,,,1,1,1,4.80023622512817,0,0,4.80000505677189,,,,,,,,,,,,,,,,,,,,,,,,,,,,,,,,,
,3823588143.93262,4.79981470108032,800.057006835938,,,5,,,,26.7500001937151,,,,,1.20959718104397E-6,8.65630301237267E-9,-0.0225489450197198,0.0045453122291701,4.03205536310956E-7,2.88548068172705E-9,4.03205505085868E-7,2.23163851630868E-9,-1.58682878782526E-10,1.82914961037844E-9,2.99995181641334,24.0295906066895,13,312,1,3,0.00395499070313887,0.000631061462725563,0.0204260218888521,147.450958251953,4.79875183105469,4.80181550979614,800.057006835938,800.057006835938,,,3.73548007011414,0,1,,,,,,1,1,1,4.79994916915894,0,0,4.80000066757202,,,,,,,,,,,,,,,,,,,,,,,,,,,,,,,,,
,3823588466.76444,4.79951405525207,800.057006835938,,,5,,,,26.7500001937151,,,,,1.23233268730329E-6,9.29900589222855E-9,1.89140999918737,0.0043697373731104,4.10779206914823E-7,3.09968103975628E-9,4.105554043222E-7,2.5369102487382E-9,1.35579060110945E-8,1.78104153182111E-9,2.99998799004161,83.3244476318359,13,1083,1,3,0.0040220232513115,0.000652409420784424,0.00994808971881866,128.858413696289,4.79897785186768,4.80200719833374,800.057006835938,800.057006835938,,,3.73586654663086,0,1,,,,,,1,1,1,4.80005788803101,0,0,4.80001998326135,,,,,,,,,,,,,,,,,,,,,,,,,,,,,,,,,
,3823588786.32943,4.79951667785645,800.057006835938,,,5,,,,26.7500001937151,,,,,1.20710421346947E-6,5.43533640069703E-9,1.75841085048748,0.00259318224937371,4.02377959395946E-7,1.81182332489497E-9,4.02188478449544E-7,1.48554189237663E-9,1.23470648368832E-8,1.03724107449885E-9,2.9999262764829,288.071533203125,13,3744,1,3,0.00395081162326401,0.000569886830050149,0.00554587738588452,127.972305297852,4.79885005950928,4.80202293395996,800.057006835938,800.057006835938,,,3.73659753799438,0,1,,,,,,1,1,1,4.79995393753052,0,0,4.7999978292556,,,,,,,,,,,,,,,,,,,,,,,,,,,,,,,,,
,3823589042.73304,4.79957437515259,800.057006835938,,,5,,,,26.7500001937151,,,,,1.24014015695864E-6,2.29335157020197E-8,4.52267279169327,0.0101068878137492,4.13384857858172E-7,7.64459410129702E-9,4.12097663498051E-7,6.64389512180281E-9,3.25968778546092E-8,3.78133264657713E-9,2.99996512543795,779.690673828125,13,10135,1,3,0.00391901913694952,0.00122540375981444,0.00621919147670269,101.98779296875,4.79853630065918,4.80186080932617,800.057006835938,800.057006835938,,,3.73643231391907,0,1,,,,,,1,1,1,4.80007123947144,0,0,4.79999584621853,,,,,,,,,,,,,,,,,,,,,,,,,,,,,,,,,