File: data/ac dwie rel do testu programu.zip/Yb0.1Lu0.9/acdc_1_8K.csv
[Data]

Comment,Time Stamp (sec),Temperature (K),Magnetic Field (Oe),Moment (emu),M. Std. Err. (emu),Transport Action,Averaging Time (sec),Frequency (Hz),Peak Amplitude (mm),Center Position (mm),Lockin Signal' (V),Lockin Signal (V),Range,M. Quad. Signal (emu),AC Moment (emu),AC M. Std Err. (emu),AC Phase (deg),AC Phase Std. Err. (deg),AC Susceptibility (emu/Oe),AC Suscept. Std Err. (emu/Oe),AC X' (emu/Oe),AC X' Std Err. (emu/Oe),AC X'' (emu/Oe),AC X'' Std Err. (emu/Oe),AC Drive (Oe),AC Frequency (Hz),AC Averaging Time (sec),AC Cycles,AC Range,AC Measure Type,AC Signal' (V),AC Signal'' (V),AC Trim Coil Ratio,AC Trim Coil Phase,Min. Temperature (K),Max. Temperature (K),Min. Field (Oe),Max. Field (Oe),Mass (grams),Motor Lag (deg),Pressure (Torr),Measure Count,Measurement Number,SQUID Status (code),Motor Status (code),Measure Status (code),Motor Current (amps),Motor Temp. (C),Temp. Status (code),Field Status (code),Chamber Status (code),Chamber Temp (K),Redirection State,Evercool Status,Average Temp (K),Rotation Angle (deg),Rotator state,DC Moment Fixed Ctr (emu),DC Moment Err Fixed Ctr (emu),DC Moment Free Ctr (emu),DC Moment Err Free Ctr (emu),DC Fixed Fit,DC Free Fit,DC Calculated Center (mm),DC Calculated Center Err (mm),DC Scan Length (mm),DC Scan Time (s),DC Number of Points,DC Squid Drift,DC Min V (V),DC Max V (V),DC Scans per Measure,Map 01,Map 02,Map 03,Map 04,Map 05,Map 06,Map 07,Map 08,Map 09,Map 10,Map 11,Map 12,Map 13,Map 14,Map 15,Map 16

,3823515138.7955,1.7995423078537,-0.252101629972458,,,5,,,,26.7500001937151,,,,,3.32849546287524E-6,1.00256787362661E-7,-0.345193638699572,0.028125450480089,1.10949387291731E-6,3.34187901224171E-8,1.10947373688489E-6,1.19655144547545E-8,-6.68440002764114E-9,3.12032369647642E-8,3.00001247787272,1.00057637691498,33.9804144735361,34,1,3,0.0110393843096612,8.91199921418959E-5,0.0261649210005999,178.077026367187,1.79851424694061,1.80163812637329,-0.252101629972458,-0.252101629972458,,,2.37605786323547,0,1,,,,,,1,1,1,1.79995286464691,0,0,1.79977442515202,,,,,,,,,,,,,,,,,,,,,,,,,,,,,,,,,

,3823515328.82482,1.80003583431244,-0.252101629972458,,,5,,,,26.7500001937151,,,,,3.33660850585723E-6,8.31001001077129E-8,0.142670461861707,0.0200783703261563,1.11220485865814E-6,2.77000837624584E-8,1.11220141057732E-6,1.63886572526676E-8,2.76946431723764E-9,2.2331738712017E-8,2.99999454226696,1.32110726833344,25.7359873910093,34,1,3,0.0110643890066494,0.000221366384833993,0.0261142551898956,177.559661865234,1.79871332645416,1.80127942562103,-0.252101629972458,-0.252101629972458,,,2.35971999168396,0,1,,,,,,1,1,1,1.80001270771027,0,0,1.79998534732724,,,,,,,,,,,,,,,,,,,,,,,,,,,,,,,,,

,3823515479.79505,1.80042481422424,-0.252101629972458,,,5,,,,26.7500001937151,,,,,3.25249154188864E-6,9.60682583587809E-8,-0.530936024314756,0.0185943427717587,1.08416189005651E-6,3.20226949756229E-8,1.08411534214974E-6,2.4879474948067E-8,-1.00463309950834E-8,2.01609702100442E-8,3.0000054159062,1.73988473415375,19.541524408246,33,1,3,0.0107866529529968,0.000136943413277552,0.0260875206440687,176.882446289062,1.79575145244598,1.80176961421967,-0.252101629972458,-0.252101629972458,,,2.35317015647888,0,1,,,,,,1,1,1,1.80095052719116,0,0,1.79990063607693,,,,,,,,,,,,,,,,,,,,,,,,,,,,,,,,,

,3823515605.96736,1.79988521337509,-0.252101629972458,,,5,,,,26.7500001937151,,,,,3.28776477140956E-6,6.40315797422686E-8,0.873713396965458,0.0119915327585794,1.09591829725576E-6,2.13437957763803E-8,1.09579087875478E-6,1.68218861898107E-8,1.67112027632312E-8,1.31370378381462E-8,3.00000901494419,2.30147647857666,14.7731251292332,34,1,3,0.0108942057036423,0.000470211629840506,0.0260533038526773,175.993713378906,1.79912996292114,1.80114686489105,-0.252101629972458,-0.252101629972458,,,2.34651470184326,0,1,,,,,,1,1,1,1.79988813400269,0,0,1.79998662235501,,,,,,,,,,,,,,,,,,,,,,,,,,,,,,,,,

,3823515714.37817,1.79979103803635,-0.252101629972458,,,5,,,,26.7500001937151,,,,,3.27384923385451E-6,8.45785293012756E-8,0.227490463423604,0.0179036537125214,1.09128225416609E-6,2.81928218182727E-8,1.09127365239952E-6,2.03252905051224E-8,4.33287853943735E-9,1.9537598827882E-8,3.00000226463523,3.0215425491333,12,36,1,3,0.0108495028379949,0.000427317875321069,0.0259655434638262,174.799911499023,1.79862666130066,1.80131185054779,-0.252101629972458,-0.252101629972458,,,2.34196519851685,0,1,,,,,,1,1,1,1.79979753494263,0,0,1.79996720260503,,,,,,,,,,,,,,,,,,,,,,,,,,,,,,,,,

,3823515808.36398,1.79990047216415,-0.252101629972458,,,5,,,,26.7500001937151,,,,,3.29860849817398E-6,4.7162785073702E-8,0.398509388014037,0.00903886191247331,1.09953489310343E-6,1.57209101574738E-8,1.0995082975447E-6,1.21823907286028E-8,7.64753439448429E-9,9.9366177502718E-9,3.00000347316281,3.9944474697113,12,47,1,3,0.010924571528379,0.000571850843742482,0.0258713252842426,173.191055297852,1.79869997501373,1.80169153213501,-0.252101629972458,-0.252101629972458,,,2.33859801292419,0,1,,,,,,1,1,1,1.79992127418518,0,0,1.79998540216022,,,,,,,,,,,,,,,,,,,,,,,,,,,,,,,,,

,3823515898.12762,1.80001670122147,-0.252101629972458,,,5,,,,26.7500001937151,,,,,3.34264095573177E-6,3.93307125767715E-8,-0.563232849105427,0.00639343339239937,1.11421257000917E-6,1.31102247955503E-8,1.11415873494342E-6,1.10027684379443E-8,-1.095283140207E-8,7.12861002516187E-9,3.00000291300273,5.2525954246521,12,63,1,3,0.0110719777498811,0.000531255182314936,0.025730200111866,171.129699707031,1.79838597774506,1.80116188526154,-0.252101629972458,-0.252101629972458,,,2.33587861061096,0,1,,,,,,1,1,1,1.80000948905945,0,0,1.79999635274383,,,,,,,,,,,,,,,,,,,,,,,,,,,,,,,,,

,3823515988.38572,1.79995065927506,-0.252101629972458,,,5,,,,26.7500001937151,,,,,3.34541877853336E-6,6.78975798331679E-8,0.638298668530941,0.0164486215664766,1.11514578454324E-6,2.26326522758504E-8,1.11507658555067E-6,1.32490155441879E-8,1.24229280458631E-8,1.83494015201974E-8,2.99998334289863,6.92008590698242,12,83,1,3,0.0110530021631337,0.000935853211481658,0.0254090391099453,168.435729980469,1.79877781867981,1.80131113529205,-0.252101629972458,-0.252101629972458,,,2.33280825614929,0,1,,,,,,1,1,1,1.80008685588837,0,0,1.80000437796116,,,,,,,,,,,,,,,,,,,,,,,,,,,,,,,,,

,3823516073.30476,1.79992085695267,-0.252101629972458,,,5,,,,26.7500001937151,,,,,3.32061133885309E-6,3.0080751051319E-8,-0.155883892391283,0.00564554729131903,1.10686451612081E-6,1.0026863296946E-8,1.106860419541E-6,7.84183680027995E-9,-3.01142837614514E-9,6.24848647061174E-9,3.00001607287107,9.10972499847412,12,109,1,3,0.0109644996846747,0.000979838264729556,0.0249395314604044,164.988830566406,1.7987025976181,1.80153024196625,-0.252101629972458,-0.252101629972458,,,2.33061790466309,0,1,,,,,,1,1,1,1.79992723464966,0,0,1.79999478897416,,,,,,,,,,,,,,,,,,,,,,,,,,,,,,,,,

,3823516153.8142,1.80014038085938,-0.252101629972458,,,5,,,,26.7500001937151,,,,,3.34835745050415E-6,1.38381355279293E-8,0.199046964267005,0.00209587008718276,1.11612138237315E-6,4.61272106792958E-9,1.11611464722973E-6,3.97812095324291E-9,3.87742566612629E-9,2.33489814165225E-9,2.99999400010124,12.0147953033447,12,144,1,3,0.0110222898498347,0.00128649835030417,0.0241429787129164,160.770034790039,1.79908728599548,1.80148148536682,-0.252101629972458,-0.252101629972458,,,2.32840490341187,0,1,,,,,,1,1,1,1.80004143714905,0,0,1.79999546265938,,,,,,,,,,,,,,,,,,,,,,,,,,,,,,,,,

,3823516221.41778,1.80019342899322,-0.252101629972458,,,5,,,,26.7500001937151,,,,,3.3492010525601E-6,8.35363157389796E-9,0.0516609055835584,0.00102336308608571,1.11637997303359E-6,2.78449303127746E-9,1.11637951923747E-6,2.54133424476854E-9,1.00658710044409E-9,1.13799020101205E-9,3.00005476044072,15.8532876968384,12,190,1,3,0.0109954384749249,0.00148980044955289,0.0229456964880228,155.774826049805,1.7984094619751,1.80129873752594,-0.252101629972458,-0.252101629972458,,,2.32693648338318,0,1,,,,,,1,1,1,1.80006396770477,0,0,1.79997728810166,,,,,,,,,,,,,,,,,,,,,,,,,,,,,,,,,

,3823516288.16613,1.80003172159195,-0.252101629972458,,,5,,,,26.7500001937151,,,,,3.34311401787778E-6,5.02678189594639E-9,0.109783351319468,0.000857936284561372,1.11444328329293E-6,1.67570214194255E-9,1.11444123752887E-6,1.37799175122863E-9,2.13536223211367E-9,9.53475957775924E-10,2.99980633200069,20.9024505615234,12,250,1,3,0.0109410006741239,0.00169225062274774,0.0212982594966888,150.214004516602,1.798623919487,1.8013710975647,-0.252101629972458,-0.252101629972458,,,2.32515716552734,0,1,,,,,,1,1,1,1.79990518093109,0,0,1.79998010672056,,,,,,,,,,,,,,,,,,,,,,,,,,,,,,,,,

,3823516353.9979,1.80003267526627,-0.252101629972458,,,5,,,,26.7500001937151,,,,,3.33735160240655E-6,5.22697630314173E-9,0.0911955354917673,0.000852435291623206,1.11249350913161E-6,1.74239274202837E-9,1.11249209994246E-6,1.46420350995387E-9,1.77071329374183E-9,9.44478982779337E-10,2.99988411169394,27.5553760528564,12,330,1,3,0.0108991359163006,0.001802723420397,0.0192036218941212,144.385498046875,1.79883110523224,1.80133545398712,-0.252101629972458,-0.252101629972458,,,2.32350969314575,0,1,,,,,,1,1,1,1.80003154277802,0,0,1.79999076575041,,,,,,,,,,,,,,,,,,,,,,,,,,,,,,,,,

,3823516419.40156,1.79998058080673,-0.252101629972458,,,5,,,,26.7500001937151,,,,,3.33235960310406E-6,6.75773529435664E-9,0.106111497708365,0.00118517389925421,1.11087877165168E-6,2.25276548063701E-9,1.11087686655872E-6,1.83121530031275E-9,2.05734076488788E-9,1.31209863754605E-9,2.99975090724746,36.330451965332,12,435,1,3,0.0108754052738832,0.00181757183631004,0.016818106174469,138.806442260742,1.79891955852509,1.80134403705597,-0.252101629972458,-0.252101629972458,,,2.32213759422302,0,1,,,,,,1,1,1,1.79992318153381,0,0,1.7999842441999,,,,,,,,,,,,,,,,,,,,,,,,,,,,,,,,,

,3823516484.74117,1.79996013641357,-0.252101629972458,,,5,,,,26.7500001937151,,,,,3.32902536774916E-6,4.72917846251218E-9,0.227918251367598,0.0011731070097524,1.10975885811737E-6,1.57651177465772E-9,1.1097500777842E-6,8.89652929623557E-10,4.41452465547919E-9,1.30150184035469E-9,2.9997736385692,47.8707122802734,12,574,1,3,0.0108705562278422,0.00175600278255621,0.0143110547214746,134.086669921875,1.79873085021973,1.80152142047882,-0.252101629972458,-0.252101629972458,,,2.3207266330719,0,1,,,,,,1,1,1,1.80000352859497,0,0,1.79999499768019,,,,,,,,,,,,,,,,,,,,,,,,,,,,,,,,,

,3823516549.67637,1.79992818832397,-0.252101629972458,,,5,,,,26.7500001937151,,,,,3.35482800364777E-6,6.10029132897342E-9,-0.106219861166191,0.00115255813195026,1.11836483635351E-6,2.03359197741821E-9,1.11836291450311E-6,1.57405557854821E-9,-2.07332007023764E-9,1.28757344111354E-9,2.99976170082957,63.0854339599609,12,757,1,3,0.0109841478077779,0.00155680139263215,0.0119266603142023,130.692031860352,1.7986935377121,1.80146980285645,-0.252101629972458,-0.252101629972458,,,2.3191876411438,0,1,,,,,,1,1,1,1.79993462562561,0,0,1.79997718706727,,,,,,,,,,,,,,,,,,,,,,,,,,,,,,,,,

,3823516614.52337,1.79990327358246,-0.252101629972458,,,5,,,,26.7500001937151,,,,,3.35356922400878E-6,5.82098290673596E-9,-0.018555022378977,0.00125244884029557,1.11793300526391E-6,1.9404605898483E-9,1.11793294664153E-6,1.34421161982396E-9,-3.62038386501971E-10,1.39945790286263E-9,2.99979444941524,83.1824951171875,12,998,1,3,0.0109984344110887,0.00140459166950336,0.00987737998366356,128.838516235352,1.79886484146118,1.80132651329041,-0.252101629972458,-0.252101629972458,,,2.31790399551392,0,1,,,,,,1,1,1,1.7999769449234,0,0,1.79999123490046,,,,,,,,,,,,,,,,,,,,,,,,,,,,,,,,,

,3823516679.08916,1.79978483915329,-0.252101629972458,,,5,,,,26.7500001937151,,,,,3.36087153902017E-6,7.58594139952764E-9,-0.120970639500402,0.00187607987877229,1.12027704578521E-6,2.52861673583637E-9,1.12027454883451E-6,1.40679462060805E-9,-2.36527945185547E-9,2.1011500403779E-9,3.00003606399389,109.726127624512,12,1316,1,3,0.0110412343931626,0.00124114601955124,0.00821865163743496,128.423965454102,1.79899132251739,1.80109965801239,-0.252101629972458,-0.252101629972458,,,2.31635737419128,0,1,,,,,,1,1,1,1.79977941513062,0,0,1.79999847639175,,,,,,,,,,,,,,,,,,,,,,,,,,,,,,,,,

,3823516743.48376,1.79999315738678,-0.252101629972458,,,5,,,,26.7500001937151,,,,,3.37356640815583E-6,9.48848588833934E-9,-0.249167144074659,0.00167091601110944,1.12454461870416E-6,3.16289186410748E-9,1.12453398505578E-6,2.54425874762902E-9,-4.89038966259706E-9,1.87899770333827E-9,2.99994002198265,144.4619140625,12,1733,1,3,0.0110955656760588,0.00112498722472893,0.00704175978899002,128.920379638672,1.79846322536469,1.80124855041504,-0.252101629972458,-0.252101629972458,,,2.31529641151428,0,1,,,,,,1,1,1,1.80001544952393,0,0,1.80000276863575,,,,,,,,,,,,,,,,,,,,,,,,,,,,,,,,,

,3823516808.24709,1.79998058080673,-0.252101629972458,,,5,,,,26.7500001937151,,,,,3.35415920683797E-6,5.15210657215804E-9,-0.433968047283488,0.00113131877314209,1.1180644785097E-6,1.71738638287736E-9,1.11803240806211E-6,1.16202581699826E-9,-8.46833088592602E-9,1.26455999807131E-9,2.99996938576283,190.73486328125,12,2288,1,3,0.0110386556296449,0.00105364636112301,0.00617410102859139,129.513824462891,1.79878783226013,1.80161476135254,-0.252101629972458,-0.252101629972458,,,2.31433343887329,0,1,,,,,,1,1,1,1.80008578300476,0,0,1.79999945126474,,,,,,,,,,,,,,,,,,,,,,,,,,,,,,,,,

,3823516872.63001,1.79984772205353,-0.252101629972458,,,5,,,,26.7500001937151,,,,,3.34780391610035E-6,7.73400735132586E-9,-0.0391856088463101,0.00144211924715147,1.11590786435041E-6,2.57794059705309E-9,1.11590760337099E-6,2.01443148749846E-9,-7.63189296728093E-10,1.60867756374893E-9,3.00007198000094,251.044357299805,12,3012,1,3,0.0110065981440289,0.00117530277895667,0.00564070791006088,129.197708129883,1.79898905754089,1.80107390880585,-0.252101629972458,-0.252101629972458,,,2.3134593963623,0,1,,,,,,1,1,1,1.79993200302124,0,0,1.79999903459398,,,,,,,,,,,,,,,,,,,,,,,,,,,,,,,,,

,3823516937.17329,1.79997485876083,-0.252101629972458,,,5,,,,26.7500001937151,,,,,3.34094785575809E-6,4.83056074076316E-9,-0.193424421592098,0.000981053384926902,1.11365478311417E-6,1.61019486275512E-9,1.11364843715129E-6,1.18318331059554E-9,-3.75957225737821E-9,1.09215600972167E-9,2.99998518967936,331.038146972656,12,3972,1,3,0.0109745782971815,0.0012779593799704,0.00535668432712555,127.051895141602,1.79893290996552,1.80142939090729,-0.252101629972458,-0.252101629972458,,,2.31232833862305,0,1,,,,,,1,1,1,1.79998433589935,0,0,1.80001297640422,,,,,,,,,,,,,,,,,,,,,,,,,,,,,,,,,

,3823517001.69732,1.79999315738678,-0.252101629972458,,,5,,,,26.7500001937151,,,,,3.3794729655923E-6,6.12196409216068E-9,0.507846287756071,0.00100432801129826,1.12648991593711E-6,2.04065275436799E-9,1.12644566588678E-6,1.70137762455311E-9,9.98461380758084E-9,1.12675544932327E-9,3.00000285646673,436.940734863281,12,5243,1,3,0.0110544716249432,0.00166633003749176,0.00531558133661747,122.3896484375,1.79798316955566,1.80266010761261,-0.252101629972458,-0.252101629972458,,,2.31099939346313,0,1,,,,,,1,1,1,1.80003428459167,0,0,1.80001392250969,,,,,,,,,,,,,,,,,,,,,,,,,,,,,,,,,

,3823517065.85662,1.79987049102783,-0.252101629972458,,,5,,,,26.7500001937151,,,,,3.35193843360694E-6,8.35611809880194E-9,-0.657048636711693,0.0018670739604409,1.11733280023163E-6,2.78542253067391E-9,1.11725933234195E-6,1.84928460552489E-9,-1.28129141213337E-8,2.08296066265172E-9,2.99994633014627,574.448547363281,12,6893,1,3,0.0109486690353608,0.00177974700912063,0.00547532085329294,114.815353393555,1.79664874076843,1.80395579338074,-0.252101629972458,-0.252101629972458,,,2.30995631217957,0,1,,,,,,1,1,1,1.80005633831024,0,0,1.80002207793887,,,,,,,,,,,,,,,,,,,,,,,,,,,,,,,,,

,3823517130.18417,1.79992789030075,-0.252101629972458,,,5,,,,26.7500001937151,,,,,3.39312531312494E-6,1.69680788844205E-8,-1.05491895652625,0.00209257562795243,1.13101072514788E-6,5.65587104290018E-9,1.13081902723383E-6,5.13859819321966E-9,-2.08227770837999E-8,2.36298240843144E-9,3.00008234906992,758.4951171875,12,9101,1,3,0.0110099207753687,0.00223183845221113,0.00601686723530292,103.900115966797,1.79504787921906,1.80662381649017,-0.252101629972458,-0.252101629972458,,,2.30833387374878,0,1,,,,,,1,1,1,1.80018353462219,0,0,1.80004188938746,,,,,,,,,,,,,,,,,,,,,,,,,,,,,,,,,

,3823517200.9797,1.80001211166382,-0.252101629972458,,,5,,,,26.7500001937151,,,,,2.77564864261873E-6,1.76757321976804E-8,6.45433095010697,0.00475444360825383,9.2519479182006E-7,5.89177431170508E-9,9.1933069584898E-7,4.14844254480636E-9,1.04002281132643E-7,4.18370995559066E-9,3.00006946338124,941.265075683594,12,11295,100,3,0.00854350296159567,0.003394769355348,0.00707000680267811,89.8638916015625,1.79378545284271,1.80877447128296,-0.252101629972458,-0.252101629972458,,,2.30726218223572,0,1,,,,,,1,1,1,1.79994225502014,0,0,1.80001729053,,,,,,,,,,,,,,,,,,,,,,,,,,,,,,,,,

,3823517413.14242,1.80011385679245,199.853546142578,,,5,,,,26.7500001937151,,,,,3.30260136929873E-6,3.2588340189096E-8,1.182126043681,0.00764501398612205,1.10086610548116E-6,1.08627700217066E-8,1.10063180595784E-6,6.86619760259394E-9,2.27114489022987E-8,8.41754732844557E-9,3.00000277313946,1.00057637691498,33.9804144735361,34,1,3,0.010947327257435,0.000381917525239912,0.0261928290128708,178.09358215332,1.79891073703766,1.80137968063354,199.853546142578,199.853546142578,,,2.30509328842163,0,1,,,,,,1,1,1,1.80009353160858,0,0,1.80000494065145,,,,,,,,,,,,,,,,,,,,,,,,,,,,,,,,,

,3823517613.43823,1.79992711544037,199.853546142578,,,5,,,,26.7500001937151,,,,,3.3529804948147E-6,3.3416602548774E-8,0.300151530147899,0.00652431838155917,1.11766354509368E-6,1.11389012036926E-8,1.11764820895753E-6,8.42055866543379E-9,5.85500174204189E-9,7.29172899850317E-9,2.99999092708501,1.32110726833344,25.7359873910093,34,1,3,0.0111181186609502,0.000254607006961741,0.0261377189308405,177.579971313477,1.79923415184021,1.80162727832794,199.853546142578,199.853546142578,,,2.30224442481995,0,1,,,,,,1,1,1,1.7999472618103,0,0,1.79999784845294,,,,,,,,,,,,,,,,,,,,,,,,,,,,,,,,,

,3823517769.65621,1.79991960525513,199.853546142578,,,5,,,,26.7500001937151,,,,,3.33070646188275E-6,6.20050274275252E-8,0.451710690470015,0.0129923589593363,1.11023804016896E-6,2.0668390000614E-8,1.11020353697246E-6,1.4802641340819E-8,8.75284708241533E-9,1.44244290893108E-8,2.99999310181795,1.73988473415375,19.541524408246,33,1,3,0.0110420983443945,0.000331235912794067,0.0260952450335026,176.908355712891,1.79871356487274,1.80131828784943,199.853546142578,199.853546142578,,,2.30137395858765,0,1,,,,,,1,1,1,1.79991149902344,0,0,1.80000268875208,,,,,,,,,,,,,,,,,,,,,,,,,,,,,,,,,

,3823517895.92407,1.80004775524139,199.853546142578,,,5,,,,26.7500001937151,,,,,3.3228352271664E-6,5.89220098048746E-8,1.47706009930617,0.0109361018787125,1.10760804839616E-6,1.96406044314181E-8,1.10724001847979E-6,1.54672035255776E-8,2.85504877161215E-8,1.21045015399148E-8,3.00001000532448,2.30147647857666,14.7731251292332,34,1,3,0.0110048419444679,0.000592725315579595,0.0260590240359306,175.987167358398,1.79860603809357,1.80167710781097,199.853546142578,199.853546142578,,,2.30055141448975,0,1,,,,,,1,1,1,1.79988563060761,0,0,1.79999660578641,,,,,,,,,,,,,,,,,,,,,,,,,,,,,,,,,

,3823518005.48837,1.80009263753891,199.853546142578,,,5,,,,26.7500001937151,,,,,3.26941242993991E-6,7.25098672505355E-8,1.34071185163513,0.0103338988645653,1.08980503356184E-6,2.41699754943387E-8,1.08950668453246E-6,2.14035874652718E-8,2.54989320520704E-8,1.12282749794167E-8,2.99999754933633,3.0215425491333,12,36,1,3,0.0108244977647108,0.000638715579596469,0.026000389829278,174.824310302734,1.79870116710663,1.80174899101257,199.853546142578,199.853546142578,,,2.29972171783447,0,1,,,,,,1,1,1,1.80004894733429,0,0,1.79999882591014,,,,,,,,,,,,,,,,,,,,,,,,,,,,,,,,,

,3823518099.13821,1.79990541934967,199.853546142578,,,5,,,,26.7500001937151,,,,,3.26487996930231E-6,4.84821342997143E-8,1.33958340278168,0.00819368241849419,1.0882931000099E-6,1.61607081204298E-8,1.0879956661905E-6,1.34886986417982E-8,2.54421280526068E-8,8.90075816458783E-9,3.0000006149746,3.9944474697113,12,47,1,3,0.010802131065644,0.000745074045386408,0.0259312577545643,173.212326049805,1.79875659942627,1.80152869224548,199.853546142578,199.853546142578,,,2.2987790107727,0,1,,,,,,1,1,1,1.79991352558136,0,0,1.80001069439782,,,,,,,,,,,,,,,,,,,,,,,,,,,,,,,,,

,3823518188.83009,1.79997456073761,199.853546142578,,,5,,,,26.7500001937151,,,,,3.31360066385461E-6,5.77472112550305E-8,1.66920755401664,0.00427792536412001,1.10453431977178E-6,1.92490837529272E-8,1.10406562088728E-6,1.86996060739115E-8,3.21740318969751E-8,4.56639442095601E-9,2.99999792178414,5.2525954246521,12,63,1,3,0.0109469317224441,0.000955364369804224,0.0257549379020929,171.13720703125,1.79877436161041,1.80181193351746,199.853546142578,199.853546142578,,,2.2972366809845,0,1,,,,,,1,1,1,1.79998970031738,0,0,1.80001963144061,,,,,,,,,,,,,,,,,,,,,,,,,,,,,,,,,

,3823518274.86725,1.79997986555099,199.853546142578,,,5,,,,26.7500001937151,,,,,3.29115094100006E-6,5.17385091912021E-8,3.59701986787922,0.0116975665719823,1.09704830501223E-6,1.72461381533661E-8,1.09488711218182E-6,1.15112775378862E-8,6.88272846214159E-8,1.28421092757673E-8,3.00000549288791,6.92008590698242,12,83,1,3,0.0108116020799085,0.00148227216463612,0.0254366137087345,168.450866699219,1.79857981204987,1.80140244960785,199.853546142578,199.853546142578,,,2.29705166816711,0,1,,,,,,1,1,1,1.80009043216705,0,0,1.8000083845782,,,,,,,,,,,,,,,,,,,,,,,,,,,,,,,,,

,3823518359.49033,1.79993689060211,199.853546142578,,,5,,,,26.7500001937151,,,,,3.24514689788905E-6,3.97210513728799E-8,2.87135579134695,0.00690669839364603,1.08173220019216E-6,1.32405532469058E-8,1.08037411310161E-6,1.09760743074052E-8,5.41879015322703E-8,7.40527130377189E-9,2.99995405268752,9.10972499847412,12,109,1,3,0.0106497024792441,0.00152365984082593,0.024969719350338,165.031616210938,1.7988029718399,1.80147671699524,199.853546142578,199.853546142578,,,2.29829168319702,0,1,,,,,,1,1,1,1.80017280578613,0,0,1.79997032299274,,,,,,,,,,,,,,,,,,,,,,,,,,,,,,,,,

,3823518439.8239,1.80012577772141,199.853546142578,,,5,,,,26.7500001937151,,,,,3.27172380203307E-6,6.32739185016592E-9,3.48309191672129,0.0012834610203217,1.09053727689784E-6,2.10905843392332E-9,1.08852280425769E-6,1.58391502215012E-9,6.62544859969692E-8,1.3926021256304E-9,3.00010267538939,12.0147953033447,12,144,1,3,0.0106801811686872,0.0018735119040255,0.024180393666029,160.802093505859,1.79886865615845,1.80145621299744,199.853546142578,199.853546142578,,,2.29817414283752,0,1,,,,,,1,1,1,1.80008256435394,0,0,1.79998547090611,,,,,,,,,,,,,,,,,,,,,,,,,,,,,,,,,

,3823518507.25994,1.80009835958481,199.853546142578,,,5,,,,26.7500001937151,,,,,3.24106310452223E-6,7.27659625465624E-9,4.3591375972377,0.00139723600757058,1.08038638593365E-6,2.42560396880186E-9,1.0772610586726E-6,1.91704409264266E-9,8.21179297009715E-8,1.48610112722224E-9,2.99991109358654,15.8532876968384,12,190,1,3,0.0105018830144681,0.00223834430058304,0.022979874163866,155.824981689453,1.79862570762634,1.80135917663574,199.853546142578,199.853546142578,,,2.29809951782227,0,1,,,,,,1,1,1,1.79993081092834,0,0,1.79999488050287,,,,,,,,,,,,,,,,,,,,,,,,,,,,,,,,,

,3823518573.90335,1.80003696680069,199.853546142578,,,5,,,,26.7500001937151,,,,,3.20414709416118E-6,8.12754589279499E-9,5.44283818586626,0.00106510299730679,1.06798303359166E-6,2.70901455618567E-9,1.06316784479246E-6,2.52193806251495E-9,1.01301006110532E-7,9.89236207618877E-10,3.00018539001085,20.9024505615234,12,250,1,3,0.0102898123995922,0.00259102847365253,0.021327581256628,150.264663696289,1.79900407791138,1.80144655704498,199.853546142578,199.853546142578,,,2.29822325706482,0,1,,,,,,1,1,1,1.79994666576386,0,0,1.80000654917497,,,,,,,,,,,,,,,,,,,,,,,,,,,,,,,,,

,3823518639.77361,1.80009013414383,199.853546142578,,,5,,,,26.7500001937151,,,,,3.15310682820747E-6,6.81866121350757E-9,6.56030290802452,0.0010955284935052,1.05097637242679E-6,2.27275896993741E-9,1.04409474812965E-6,2.02753185165432E-9,1.20072862577101E-7,1.02691183942836E-9,3.00016909126767,27.5553760528564,12,330,1,3,0.0100396754089481,0.00285401002075097,0.0192724820226431,144.445175170898,1.79878568649292,1.80143868923187,199.853546142578,199.853546142578,,,2.29821586608887,0,1,,,,,,1,1,1,1.80013287067413,0,0,1.80000715516508,,,,,,,,,,,,,,,,,,,,,,,,,,,,,,,,,

,3823518705.22747,1.8000510931015,199.853546142578,,,5,,,,26.7500001937151,,,,,3.07591524110385E-6,9.96930402668362E-9,7.53070064464063,0.00182830642900772,1.02523097273244E-6,3.32286115305127E-9,1.01638812957899E-6,2.85464528874978E-9,1.34364122818672E-7,1.70070765208953E-9,3.00021685153144,36.330451965332,12,435,1,3,0.00973721064589651,0.00296224314257898,0.0168566033244133,138.876312255859,1.79862201213837,1.80154228210449,199.853546142578,199.853546142578,,,2.29799604415894,0,1,,,,,,1,1,1,1.80003774166107,0,0,1.8000052664429,,,,,,,,,,,,,,,,,,,,,,,,,,,,,,,,,

,3823518770.62594,1.80000567436218,199.853546142578,,,5,,,,26.7500001937151,,,,,3.00507677557147E-6,7.37053878055497E-9,8.58676296000645,0.00210986702329504,1.00162068863321E-6,2.45667072102454E-9,9.90393423974611E-7,1.18231421334236E-9,1.49548887143693E-7,2.15345400054607E-9,3.00021436225736,47.8707122802734,12,574,1,3,0.00947774662161355,0.00299617666545896,0.0143491374328732,134.139862060547,1.79858887195587,1.80143809318542,199.853546142578,199.853546142578,,,2.29803323745728,0,1,,,,,,1,1,1,1.80001366138458,0,0,1.79998548701406,,,,,,,,,,,,,,,,,,,,,,,,,,,,,,,,,

,3823518835.42627,1.80004370212555,199.853546142578,,,5,,,,26.7500001937151,,,,,2.91234475543673E-6,4.89987693908317E-9,9.61182006199384,0.0013016105537291,9.70816893167916E-7,1.63335171704028E-9,9.57188188812154E-7,1.03942465331036E-9,1.62099386978213E-7,1.25993421322268E-9,2.99989089181723,63.0854339599609,12,757,1,3,0.00917012907209749,0.00294299054011803,0.011960313655436,130.715606689453,1.79855227470398,1.80142498016357,199.853546142578,199.853546142578,,,2.29786562919617,0,1,,,,,,1,1,1,1.800013422966,0,0,1.79999322630465,,,,,,,,,,,,,,,,,,,,,,,,,,,,,,,,,

,3823518900.31565,1.79996490478516,199.853546142578,,,5,,,,26.7500001937151,,,,,2.81558340844358E-6,4.86767863154981E-9,10.5626468942853,0.00115987486259058,9.38567957167894E-7,1.62262896409416E-9,9.22663983692954E-7,1.2483284511113E-9,1.72049363318093E-7,1.03662955450024E-9,2.99987165227709,83.1824951171875,12,998,1,3,0.00886017483969419,0.00285614520632131,0.00988724455237389,128.848556518555,1.79878997802734,1.80112898349762,199.853546142578,199.853546142578,,,2.29772210121155,0,1,,,,,,1,1,1,1.79998981952667,0,0,1.79999602027237,,,,,,,,,,,,,,,,,,,,,,,,,,,,,,,,,

,3823518969.65196,1.80012148618698,199.853546142578,,,5,,,,26.7500001937151,,,,,2.72324182170236E-6,6.0016654695874E-9,11.2052692587098,0.00139967010317038,9.07803395924391E-7,2.00067884206028E-9,8.90498201472492E-7,1.6134221780539E-9,1.76408499869234E-7,1.18304044919499E-9,2.99981453465412,109.726127624512,12,1316,1,3,0.00857443951316761,0.00274438547848894,0.00826602336019278,128.387634277344,1.79927289485931,1.80126333236694,199.853546142578,199.853546142578,,,2.29048299789429,0,1,,,,,,1,1,1,1.80022406578064,0,0,1.800090475994,,,,,,,,,,,,,,,,,,,,,,,,,,,,,,,,,

,3823519034.41023,1.79992240667343,199.853546142578,,,5,,,,26.7500001937151,,,,,2.62860034330073E-6,8.28701593538029E-9,11.9257149589331,0.00262693766756244,8.76203337715688E-7,2.76234880695692E-9,8.57291662703807E-7,1.46413083197294E-9,1.81061575389849E-7,2.34241154329519E-9,2.99998896392433,144.4619140625,12,1733,1,3,0.00826579590747711,0.00268133422776045,0.00706140836700797,128.858245849609,1.79897177219391,1.80107438564301,199.853546142578,199.853546142578,,,2.28960704803467,0,1,,,,,,1,1,1,1.79986202716827,0,0,1.80001154967717,,,,,,,,,,,,,,,,,,,,,,,,,,,,,,,,,

,3823519099.04688,1.80005502700806,199.853546142578,,,5,,,,26.7500001937151,,,,,2.52252342103592E-6,4.89287748012281E-9,12.4418163415103,0.00123385764327156,8.40822935896273E-7,1.63092384931281E-9,8.21076459256325E-7,1.32263977065718E-9,1.81153684986873E-7,9.54220435399092E-10,3.00006495225661,190.73486328125,12,2288,1,3,0.00791611263829689,0.0026235695806206,0.00622052699327469,129.415191650391,1.79868912696838,1.80097663402557,199.853546142578,199.853546142578,,,2.28865027427673,0,1,,,,,,1,1,1,1.80004417896271,0,0,1.80002830331288,,,,,,,,,,,,,,,,,,,,,,,,,,,,,,,,,

,3823519163.22399,1.79990792274475,199.853546142578,,,5,,,,26.7500001937151,,,,,2.39827882640914E-6,8.4500281970111E-9,12.7377857164072,0.00270725459933434,7.99440739265926E-7,2.81672702700334E-9,7.79765980243434E-7,1.82167261948595E-9,1.76268294520163E-7,2.14836216966931E-9,2.99994572282034,251.044357299805,12,3012,1,3,0.00750311658196807,0.00256598113576329,0.00568590825423598,129.071868896484,1.7989627122879,1.8017350435257,199.853546142578,199.853546142578,,,2.28767991065979,0,1,,,,,,1,1,1,1.80002653598785,0,0,1.8000354823612,,,,,,,,,,,,,,,,,,,,,,,,,,,,,,,,,

,3823519227.36792,1.80001157522202,199.853546142578,,,5,,,,26.7500001937151,,,,,2.32016139573734E-6,7.22538666222422E-9,13.1418830585554,0.00245775246653634,7.7335305688505E-7,2.40835610517163E-9,7.53098960108226E-7,1.48487644386637E-9,1.75832041668632E-7,1.89613319040838E-9,3.00013218423498,331.038146972656,12,3972,1,3,0.00721094545153465,0.00262248722221532,0.00538242608308792,126.909805297852,1.79866182804108,1.80155301094055,199.853546142578,199.853546142578,,,2.28726077079773,0,1,,,,,,1,1,1,1.8001047372818,0,0,1.80001515895128,,,,,,,,,,,,,,,,,,,,,,,,,,,,,,,,,

,3823519291.92852,1.7997807264328,199.853546142578,,,5,,,,26.7500001937151,,,,,2.19994912627156E-6,5.12874539040498E-9,12.9802612240869,0.00173937544978101,7.33284325162691E-7,1.70950707796965E-9,7.14547080444485E-7,1.19243873928804E-9,1.64706925651494E-7,1.22495073479446E-9,3.00013112346764,436.940734863281,12,5243,1,3,0.00679178780821292,0.00261427264470867,0.00532931881025434,122.19563293457,1.79695355892181,1.80248165130615,199.853546142578,199.853546142578,,,2.28540945053101,0,1,,,,,,1,1,1,1.79999184608459,0,0,1.79987104733785,,,,,,,,,,,,,,,,,,,,,,,,,,,,,,,,,

,3823519356.5171,1.800612449646,199.853546142578,,,5,,,,26.7500001937151,,,,,2.13111817557702E-6,1.03496566624934E-8,12.9078384122004,0.00376562979234525,7.10356102491901E-7,3.44980482694609E-9,6.92405860605989E-7,2.30369251720876E-9,1.58681809121163E-7,2.56790851281289E-9,3.00007020155263,574.448547363281,12,6893,1,3,0.00650113856779821,0.00273359103231657,0.00550281815230846,114.612884521484,1.78998458385468,1.80614638328552,199.853546142578,199.853546142578,,,2.2852795124054,0,1,,,,,,5,1,1,1.80143237113953,0,0,1.80031251150464,,,,,,,,,,,,,,,,,,,,,,,,,,,,,,,,,

,3823519420.67079,1.79992741346359,199.853546142578,,,5,,,,26.7500001937151,,,,,2.03093527204063E-6,1.72774515262731E-8,13.0337583041966,0.0062964597644303,6.77005560370248E-7,5.75938136155444E-9,6.59564107101927E-7,4.69821192151935E-9,1.52681752004196E-7,3.33125778172662E-9,2.99987975125334,758.4951171875,12,9101,1,3,0.00606619333191733,0.00290068014088555,0.0060406532138586,103.709869384766,1.79534804821014,1.8061637878418,199.853546142578,199.853546142578,,,2.28444910049438,0,1,,,,,,1,1,1,1.79996931552887,0,0,1.80004689428541,,,,,,,,,,,,,,,,,,,,,,,,,,,,,,,,,

,3823519495.06872,1.80003613233566,199.853546142578,,,5,,,,26.7500001937151,,,,,1.74187243066433E-6,2.35324093538256E-8,20.016918567895,0.0153665674928003,5.80642190947445E-7,7.84438026857465E-9,5.45566517380952E-7,6.08368732737818E-9,1.98752431484671E-7,4.95207535289009E-9,2.99990675466088,941.265075683594,12,11295,100,3,0.00471201540743001,0.00332899246278423,0.00710670463740826,89.6949157714844,1.79371821880341,1.80638635158539,199.853546142578,199.853546142578,,,2.2843770980835,0,1,,,,,,1,1,1,1.79997396469116,0,0,1.79987445974772,,,,,,,,,,,,,,,,,,,,,,,,,,,,,,,,,

,3823519696.99357,1.79999941587448,399.744903564453,,,5,,,,26.7500001937151,,,,,3.35643872161418E-6,4.72694768625784E-8,1.19295987451217,0.0107117541167598,1.11881572372737E-6,1.57565319532442E-8,1.11857321951666E-6,1.02274568912472E-8,2.32932659740531E-8,1.1986134686849E-8,2.99999244775725,1.00057637691498,33.9804144735361,34,1,3,0.0111257846542237,0.000391847028015132,0.0262266732752323,178.111907958984,1.7986843585968,1.8014155626297,399.744903564453,399.744903564453,,,2.29454255104065,0,1,,,,,,1,1,1,1.80009698867798,0,0,1.80000737017774,,,,,,,,,,,,,,,,,,,,,,,,,,,,,,,,,

,3823519887.56303,1.7999062538147,399.744903564453,,,5,,,,26.7500001937151,,,,,3.32904234191345E-6,4.72998296099655E-8,1.06784021124227,0.0094363555968913,1.10968404965638E-6,1.5766656316986E-8,1.10949133086921E-6,1.17884878729076E-8,2.06803478659188E-8,1.04699095071669E-8,2.99999116229912,1.32110726833344,25.7359873910093,34,1,3,0.0110344351464247,0.000402253847583603,0.0261953603476286,177.571350097656,1.79881608486176,1.80166232585907,399.744903564453,399.744903564453,,,2.2873203754425,0,1,,,,,,1,1,1,1.8000351190567,0,0,1.8000246330818,,,,,,,,,,,,,,,,,,,,,,,,,,,,,,,,,

,3823520043.79938,1.79999208450317,399.744903564453,,,5,,,,26.7500001937151,,,,,3.3271400412871E-6,4.80515923223691E-8,0.321839005706418,0.0103162411715311,1.1090473664244E-6,1.60172073481484E-8,1.10902986992976E-6,1.12093128785364E-8,6.22965299895661E-9,1.14412515060485E-8,2.99999814436591,1.73988473415375,19.541524408246,33,1,3,0.0110310806114981,0.000307463537624311,0.0261236615478992,176.893676757813,1.79767978191376,1.80334544181824,399.744903564453,399.744903564453,,,2.28157711029053,0,1,,,,,,1,1,1,1.79986453056335,0,0,1.80011997187048,,,,,,,,,,,,,,,,,,,,,,,,,,,,,,,,,

,3823520169.70083,1.79943042993546,399.744903564453,,,5,,,,26.7500001937151,,,,,3.23160335877823E-6,4.10213813514307E-8,1.96935638787841,0.00862580385597018,1.07719877524757E-6,1.36737640251219E-8,1.07656252719613E-6,1.00342987376568E-8,3.70179204164168E-8,9.28895427150862E-9,3.00000652900436,2.30147647857666,14.7731251292332,34,1,3,0.0106973729697105,0.000669930248565611,0.0260743089020252,176.000549316406,1.79570353031158,1.80099034309387,399.744903564453,399.744903564453,,,2.29057216644287,0,1,,,,,,1,1,1,1.79924261569977,0,0,1.79985378561793,,,,,,,,,,,,,,,,,,,,,,,,,,,,,,,,,

,3823520278.41356,1.80002248287201,399.744903564453,,,5,,,,26.7500001937151,,,,,3.30185865022212E-6,7.38568337327857E-8,1.16739969613135,0.013936495906554,1.10062054210353E-6,2.46189667675692E-8,1.10039209456594E-6,1.92635485459952E-8,2.24235571898522E-8,1.5330010506153E-8,2.99999729599043,3.0215425491333,12,36,1,3,0.0109338622921113,0.000613558624980442,0.0260224882513285,174.841217041016,1.79891192913055,1.80153357982635,399.744903564453,399.744903564453,,,2.29331707954407,0,1,,,,,,1,1,1,1.8000408411026,0,0,1.80002035799715,,,,,,,,,,,,,,,,,,,,,,,,,,,,,,,,,

,3823520372.18657,1.79995256662369,399.744903564453,,,5,,,,26.7500001937151,,,,,3.29919022770354E-6,4.11110878205168E-8,2.64601665574857,0.00592480400478774,1.09972993424421E-6,1.370369417499E-8,1.09855741833238E-6,1.20847719041219E-8,5.07693500024934E-8,6.46138700798834E-9,3.00000038643207,3.9944474697113,12,47,1,3,0.0108956289271467,0.00100315432535822,0.0259429421275854,173.247192382813,1.79872298240662,1.80168962478638,399.744903564453,399.744903564453,,,2.29435300827026,0,1,,,,,,1,1,1,1.79997062683105,0,0,1.79998075432248,,,,,,,,,,,,,,,,,,,,,,,,,,,,,,,,,

,3823520460.6271,1.79995334148407,399.744903564453,,,5,,,,26.7500001937151,,,,,3.29540489081765E-6,8.35762668362651E-8,3.79431801611581,0.0202722515775758,1.09847175264008E-6,2.78588432536946E-8,1.09606394179973E-6,1.66684778356541E-8,7.26913119610392E-8,2.23221189423458E-8,2.99999056224925,5.2525954246521,12,63,1,3,0.0108440318350664,0.00135473663144779,0.0257555022835732,171.158020019531,1.79874730110168,1.80100417137146,399.744903564453,399.744903564453,,,2.29499411582947,0,1,,,,,,1,1,1,1.80000793933868,0,0,1.7999908522118,,,,,,,,,,,,,,,,,,,,,,,,,,,,,,,,,

,3823520546.72745,1.80004286766052,399.744903564453,,,5,,,,26.7500001937151,,,,,3.26283121898288E-6,3.68232909771231E-8,4.57437120863487,0.00591985493046449,1.08759961370864E-6,1.22743085235909E-8,1.08413523073625E-6,1.05237113495385E-8,8.67393867608051E-8,6.31744799455361E-9,3.00002977001513,6.92008590698242,12,83,1,3,0.010691832358632,0.0016536841089204,0.0254982765763998,168.476104736328,1.79900455474854,1.80092406272888,399.744903564453,399.744903564453,,,2.29549241065979,0,1,,,,,,1,1,1,1.800137758255,0,0,1.79998666331882,,,,,,,,,,,,,,,,,,,,,,,,,,,,,,,,,

,3823520631.86654,1.80014216899872,399.744903564453,,,5,,,,26.7500001937151,,,,,3.24058506904386E-6,2.32359466702947E-8,4.89539108365807,0.00534554676537653,1.08017063721922E-6,7.74514070345006E-9,1.07623035185024E-6,5.15771470138189E-9,9.21782797999752E-8,5.77799130973628E-9,3.00006772761976,9.10972499847412,12,109,1,3,0.0105742095875001,0.00189771165782652,0.024994196370244,165.07878112793,1.79874277114868,1.80168211460114,399.744903564453,399.744903564453,,,2.29571223258972,0,1,,,,,,1,1,1,1.80022120475769,0,0,1.80000657058624,,,,,,,,,,,,,,,,,,,,,,,,,,,,,,,,,

,3823520712.48004,1.80007535219193,399.744903564453,,,5,,,,26.7500001937151,,,,,3.19347136669448E-6,9.24177385643077E-9,6.52302813646938,0.0016539428788486,1.06450267370276E-6,3.08062664426201E-9,1.05761137842523E-6,2.57165735278259E-9,1.2093020526656E-7,1.69612469506703E-9,2.99996556663059,12.0147953033447,12,144,1,3,0.0103128641977092,0.00238047853272563,0.024210412055254,160.87483215332,1.79891300201416,1.80170893669128,399.744903564453,399.744903564453,,,2.29570031166077,0,1,,,,,,1,1,1,1.80000030994415,0,0,1.80000059201684,,,,,,,,,,,,,,,,,,,,,,,,,,,,,,,,,

,3823520779.97814,1.80003952980042,399.744903564453,,,5,,,,26.7500001937151,,,,,3.13585661541044E-6,1.23547568470496E-8,8.05630825214221,0.00184563119128553,1.04533629584582E-6,4.1184522580221E-9,1.03501967979036E-6,3.7805212972008E-9,1.46499944912326E-7,1.63380161678782E-9,2.99985433192397,15.8532876968384,12,190,1,3,0.00999990222765663,0.00281785611993562,0.0230153426527977,155.921081542969,1.79859161376953,1.80123233795166,399.744903564453,399.744903564453,,,2.29620242118835,0,1,,,,,,1,1,1,1.79989039897919,0,0,1.79998355742657,,,,,,,,,,,,,,,,,,,,,,,,,,,,,,,,,

,3823520846.45011,1.800053358078,399.744903564453,,,5,,,,26.7500001937151,,,,,3.06479901479664E-6,5.90631427993054E-9,9.44150022279811,0.0011491451573777,1.02153347512844E-6,1.96864385639934E-9,1.00769537742443E-6,1.66201744506974E-9,1.67572871090187E-7,1.05510977894374E-9,3.00019440323413,20.9024505615234,12,250,1,3,0.00964518660478912,0.00316006565516026,0.0213759783655405,150.377075195313,1.79897248744965,1.80150580406189,399.744903564453,399.744903564453,,,2.29631614685059,0,1,,,,,,1,1,1,1.79995679855347,0,0,1.79997683855203,,,,,,,,,,,,,,,,,,,,,,,,,,,,,,,,,

,3823520912.36088,1.80003321170807,399.744903564453,,,5,,,,26.7500001937151,,,,,2.97010428039234E-6,5.20037590501753E-9,11.0877979819105,0.00116201544857545,9.89963361449491E-7,1.73333362256629E-9,9.71484351190155E-7,1.38851385045131E-9,1.90382804909004E-7,1.03753300392019E-9,3.00021636764774,27.5553760528564,12,330,1,3,0.00921487814622426,0.00342784779359033,0.0193252433091402,144.560806274414,1.79877173900604,1.8011109828949,399.744903564453,399.744903564453,,,2.29661107063293,0,1,,,,,,1,1,1,1.80010652542114,0,0,1.79998077979455,,,,,,,,,,,,,,,,,,,,,,,,,,,,,,,,,

,3823520977.87172,1.80002844333649,399.744903564453,,,5,,,,26.7500001937151,,,,,2.8527914358993E-6,7.07744390396467E-9,12.2754301668921,0.001614326234356,9.50848352621683E-7,2.35894422290138E-9,9.29108951978802E-7,1.97438165354541E-9,2.02161185780605E-7,1.29090469551516E-9,3.00025911390977,36.330451965332,12,435,1,3,0.00877228584530065,0.00348624954847458,0.0169147718697786,138.978164672852,1.79853951931,1.80149483680725,399.744903564453,399.744903564453,,,2.29663825035095,0,1,,,,,,1,1,1,1.79986250400543,0,0,1.80000037327409,,,,,,,,,,,,,,,,,,,,,,,,,,,,,,,,,

,3823521042.94366,1.80001455545425,399.744903564453,,,5,,,,26.7500001937151,,,,,2.71548956455957E-6,6.33038112489475E-9,13.4877450619141,0.00147689303206989,9.05171570172515E-7,2.11014658181564E-9,8.80206783985167E-7,1.84791333178434E-9,2.11119844815846E-7,1.01879090836242E-9,2.99997221967768,47.8707122802734,12,574,1,3,0.0083013989756123,0.00343046771957855,0.0144196506589651,134.23095703125,1.79883825778961,1.80115687847137,399.744903564453,399.744903564453,,,2.29575133323669,0,1,,,,,,1,1,1,1.79983103275299,0,0,1.79999171942472,,,,,,,,,,,,,,,,,,,,,,,,,,,,,,,,,

[...]

,3823553492.37667,1.79948502779007,149.69792175293,,,5,,,,26.7500001937151,,,,,2.89993239105206E-6,8.09193730482509E-9,8.48372558264044,0.00242211451357267,9.6667633054522E-7,2.69740228598656E-9,9.56098772118754E-7,1.2650187437988E-9,1.42612292560573E-7,2.38237416672597E-9,2.99990006936081,109.726127624512,12,1316,1,3,0.00925929708398343,0.00248526564750049,0.00829064659774303,128.301742553711,1.79879665374756,1.8013870716095,149.69792175293,149.69792175293,,,2.29337501525879,0,1,,,,,,1,1,1,1.79981660842896,0,0,1.80001830259959,,,,,,,,,,,,,,,,,,,,,,,,,,,,,,,,,

,3823553553.25838,1.79957604408264,149.69792175293,,,5,,,,26.7500001937151,,,,,2.82787590945283E-6,6.80008307143989E-9,9.67691959032187,0.00196346211691473,9.42678789567893E-7,2.26682297385051E-9,9.292656596226E-7,1.27902004246697E-9,1.58457041962045E-7,1.87152187423611E-9,2.99982978374753,144.4619140625,12,1733,1,3,0.0089988346080443,0.00253312895879713,0.00707160728052258,128.725555419922,1.79835200309753,1.80217981338501,149.69792175293,149.69792175293,,,2.2934787273407,0,1,,,,,,1,1,1,1.80001962184906,0,0,1.79999073418704,,,,,,,,,,,,,,,,,,,,,,,,,,,,,,,,,

,3823553614.09613,1.79954820871353,149.69792175293,,,5,,,,26.7500001937151,,,,,2.73669146284481E-6,7.51821766651791E-9,10.0938030429963,0.00160619538957354,9.12189111707151E-7,2.50595888793142E-9,8.98070377627191E-7,2.104961564653E-9,1.59870486161877E-7,1.35976717100248E-9,3.00013607674304,190.73486328125,12,2288,1,3,0.00869767269295055,0.0024917587844879,0.00619857851415873,129.224319458008,1.79798221588135,1.80237603187561,149.69792175293,149.69792175293,,,2.29366731643677,0,1,,,,,,1,1,1,1.79993891716003,0,0,1.80000985662142,,,,,,,,,,,,,,,,,,,,,,,,,,,,,,,,,

,3823553675.0593,1.79967480897903,149.69792175293,,,5,,,,26.7500001937151,,,,,2.63928307861013E-6,6.9400169790106E-9,10.560148840859,0.00219891367606137,8.79722229287077E-7,2.31323697618691E-9,8.64822422969719E-7,1.21871265144813E-9,1.61224617942201E-7,1.96616499338144E-9,3.00013230397621,251.044357299805,12,3012,1,3,0.00835850973982713,0.00250774265226254,0.00568972853943706,128.783721923828,1.79853618144989,1.80202567577362,149.69792175293,149.69792175293,,,2.29349517822266,0,1,,,,,,1,1,1,1.80019962787628,0,0,1.8000038365523,,,,,,,,,,,,,,,,,,,,,,,,,,,,,,,,,

,3823553736.1468,1.79952937364578,149.69792175293,,,5,,,,26.7500001937151,,,,,2.5363519493006E-6,7.18632184613891E-9,10.9410227708773,0.00196690946559231,8.45481291046931E-7,2.395527432235E-9,8.30113038497578E-7,1.77836431521512E-9,1.60471046692866E-7,1.60498350177186E-9,2.99989127631661,331.038146972656,12,3972,1,3,0.00798720231302765,0.00256171987987535,0.00540838716551662,126.51789855957,1.79827618598938,1.80172991752625,149.69792175293,149.69792175293,,,2.29339218139648,0,1,,,,,,1,1,1,1.80002748966217,0,0,1.79999032020569,,,,,,,,,,,,,,,,,,,,,,,,,,,,,,,,,

,3823553796.75514,1.79960769414902,149.69792175293,,,5,,,,26.7500001937151,,,,,2.43145571121831E-6,6.30554380675544E-9,11.358955811118,0.0022278152705601,8.10516892015594E-7,2.10193002699555E-9,7.94640905488528E-7,9.94340796949723E-10,1.5963540824952E-7,1.85186290472781E-9,2.99988283423898,436.940734863281,12,5243,1,3,0.00758532298475882,0.00267556434854134,0.00537946540862322,121.712463378906,1.79814207553864,1.80271136760712,149.69792175293,149.69792175293,,,2.29312086105347,0,1,,,,,,1,1,1,1.80001401901245,0,0,1.80001883109411,,,,,,,,,,,,,,,,,,,,,,,,,,,,,,,,,

,3823553857.43977,1.79958486557007,149.69792175293,,,5,,,,26.7500001937151,,,,,2.35669024793966E-6,6.72259776002594E-9,11.3372467280666,0.00223994561433334,7.85566013362226E-7,2.24087332919477E-9,7.70237319570158E-7,1.41928272119968E-9,1.54429378329382E-7,1.73411355879611E-9,2.99999008085014,574.448547363281,12,6893,1,3,0.00726949386457777,0.00282448872337537,0.00557915773242712,114.053649902344,1.79672491550446,1.80361926555634,149.69792175293,149.69792175293,,,2.29294466972351,0,1,,,,,,1,1,1,1.79993963241577,0,0,1.80000309014724,,,,,,,,,,,,,,,,,,,,,,,,,,,,,,,,,

,3823553925.11406,1.80258500576019,149.69792175293,,,5,,,,26.7500001937151,,,,,2.91114249015941E-6,1.02598964244259E-8,7.8253820182582,0.00297956761028506,9.70352863183899E-7,3.41986690966363E-9,9.61316569836551E-7,1.76732867074578E-9,1.32117870278318E-7,2.92780447594647E-9,3.00008646401829,758.4951171875,12,9101,10,3,0.00903690951868161,0.00335100413394572,0.0061050090007484,103.132141113281,1.79585790634155,1.80545330047607,149.69792175293,149.69792175293,,,2.29179453849792,0,1,,,,,,1,1,1,1.79986941814423,0,0,1.80000810365419,,,,,,,,,,,,,,,,,,,,,,,,,,,,,,,,,

,3823554039.23927,1.79996794462204,149.69792175293,,,5,,,,26.7500001937151,,,,,2.0044897047825E-6,9.16814763689119E-9,15.3919831152516,0.00406892283277642,6.6814341436627E-7,3.05595855688927E-9,6.44178814983288E-7,2.00458708936979E-9,1.77339438613479E-7,2.30662378869132E-9,3.00008899538993,941.265075683594,12,11295,100,3,0.00571377126294074,0.00338099087209001,0.00719499262049794,89.1754455566406,1.79378592967987,1.80730581283569,149.69792175293,149.69792175293,,,2.29160976409912,0,1,,,,,,1,1,1,1.80001282691956,0,0,1.80001821495452,,,,,,,,,,,,,,,,,,,,,,,,,,,,,,,,,

,3823554240.67545,1.79999315738678,299.698394775391,,,5,,,,26.7500001937151,,,,,3.26192759284448E-6,6.06796407496336E-8,0.367554716344127,0.00953507518512535,1.08730794105946E-6,2.02265235416148E-8,1.08728556828679E-6,1.73686436684418E-8,6.975076073223E-9,1.03654460443433E-8,3.00000346697193,1.00057637691498,33.9804144735361,34,1,3,0.0108168201643571,0.000224236239298485,0.0262021999806166,178.0927734375,1.79848718643188,1.80180656909943,299.698394775391,299.698394775391,,,2.29177451133728,0,1,,,,,,1,1,1,1.80000340938568,0,0,1.79999865115957,,,,,,,,,,,,,,,,,,,,,,,,,,,,,,,,,

,3823554427.19042,1.80000555515289,299.698394775391,,,5,,,,26.7500001937151,,,,,3.3162704502147E-6,6.6326010262021E-8,1.46036902943703,0.0166138504003162,1.1054261145396E-6,2.21087227105113E-8,1.10506706351024E-6,1.22971926064441E-8,2.81723242026326E-8,1.83732053243384E-8,2.99999285940147,1.32110726833344,25.7359873910093,34,1,3,0.010989068549084,0.000475215164056412,0.0261446218937635,177.589370727539,1.798748254776,1.80222463607788,299.698394775391,299.698394775391,,,2.29097747802734,0,1,,,,,,1,1,1,1.80011558532715,0,0,1.80000263870142,,,,,,,,,,,,,,,,,,,,,,,,,,,,,,,,,

,3823554577.02247,1.79984420537949,299.698394775391,,,5,,,,26.7500001937151,,,,,3.28041543424464E-6,6.27423581883628E-8,0.853433879906017,0.0154908821562905,1.09347005554708E-6,2.09140858127872E-8,1.09334875483131E-6,1.22619726134251E-8,1.62868869637798E-8,1.69423437874528E-8,3.00000481732752,1.73988473415375,19.541524408246,33,1,3,0.0108728509818879,0.000403258456620507,0.026125879958272,176.883255004883,1.79853081703186,1.80146586894989,299.698394775391,299.698394775391,,,2.29100251197815,0,1,,,,,,1,1,1,1.79983389377594,0,0,1.79999247967728,,,,,,,,,,,,,,,,,,,,,,,,,,,,,,,,,

,3823554699.32444,1.79992926120758,299.698394775391,,,5,,,,26.7500001937151,,,,,3.27323135312906E-6,9.40476063065755E-8,0.91569982521357,0.0108388799873634,1.09107392274831E-6,3.13491103034655E-8,1.0909345827073E-6,2.90471736769072E-8,1.74367759242793E-8,1.17910312611932E-8,3.00000878481642,2.30147647857666,14.7731251292332,34,1,3,0.0108457885849121,0.000478418941879559,0.0261020213365555,175.994247436523,1.79904246330261,1.80216228961945,299.698394775391,299.698394775391,,,2.2909152507782,0,1,,,,,,1,1,1,1.80002868175507,0,0,1.80000217607088,,,,,,,,,,,,,,,,,,,,,,,,,,,,,,,,,

,3823554805.3864,1.80001139640808,299.698394775391,,,5,,,,26.7500001937151,,,,,3.32437686349097E-6,5.31440934188835E-8,1.14619034765775,0.00834422322193642,1.10812662080333E-6,1.77147137867161E-8,1.10790489658225E-6,1.51190226356814E-8,2.21663678143455E-8,9.23180584105965E-9,2.99999729370367,3.0215425491333,12,36,1,3,0.0110086376338477,0.000612874358813084,0.0260302126407623,174.838577270508,1.79859304428101,1.80170977115631,299.698394775391,299.698394775391,,,2.29065847396851,0,1,,,,,,1,1,1,1.79992485046387,0,0,1.8000057220459,,,,,,,,,,,,,,,,,,,,,,,,,,,,,,,,,

,3823554895.55776,1.79988646507263,299.698394775391,,,5,,,,26.7500001937151,,,,,3.30564372572815E-6,6.41674780330206E-8,2.22780478966287,0.0111103381810074,1.10188110498317E-6,2.13891566863982E-8,1.101048269873E-6,1.75639823650544E-8,4.28331288678683E-8,1.22066599541132E-8,3.00000037279759,3.9944474697113,12,47,1,3,0.0109239902252713,0.000924616575052153,0.0259279441088438,173.239303588867,1.79860031604767,1.80243229866028,299.698394775391,299.698394775391,,,2.29047846794128,0,1,,,,,,1,1,1,1.79986429214478,0,0,1.80000685952431,,,,,,,,,,,,,,,,,,,,,,,,,,,,,,,,,

,3823554981.34238,1.80003136396408,299.698394775391,,,5,,,,26.7500001937151,,,,,3.28648704109997E-6,6.26004942112127E-8,2.7150142431017,0.00857251015257954,1.09549834107248E-6,2.08668820844484E-8,1.09426864036742E-6,1.86936517616862E-8,5.18917912679319E-8,9.27222474593227E-9,2.99999271371104,5.2525954246521,12,63,1,3,0.0108382360009311,0.00114633787483825,0.0257651805877686,171.14826965332,1.79871010780334,1.80176627635956,299.698394775391,299.698394775391,,,2.29057431221008,0,1,,,,,,1,1,1,1.79992079734802,0,0,1.79999325814701,,,,,,,,,,,,,,,,,,,,,,,,,,,,,,,,,

,3823555063.65703,1.80001980066299,299.698394775391,,,5,,,,26.7500001937151,,,,,3.26457356280555E-6,3.62038928386119E-8,3.39376880321487,0.00967024904634566,1.08819346467558E-6,1.2067989532126E-8,1.08628506919559E-6,5.83025173565445E-9,6.44186696958301E-8,1.05661978046221E-8,2.99999372242031,6.92008590698242,12,83,1,3,0.0107294019353553,0.00143302626324515,0.0254810098558664,168.443420410156,1.79903507232666,1.80166471004486,299.698394775391,299.698394775391,,,2.29151463508606,0,1,,,,,,1,1,1,1.80003833770752,0,0,1.80001239329577,,,,,,,,,,,,,,,,,,,,,,,,,,,,,,,,,

,3823555144.92497,1.79996526241302,299.698394775391,,,5,,,,26.7500001937151,,,,,3.29388142339474E-6,1.55187424711987E-8,3.84644617893149,0.00321243260095187,1.09795187829941E-6,5.17287365722377E-9,1.09547864975228E-6,3.79359415421221E-9,7.36536149696935E-8,3.51671228091333E-9,3.00002348782039,9.10972499847412,12,109,1,3,0.0107816908031135,0.00173105498325765,0.0249732304364443,165.054077148438,1.79871475696564,1.80191779136658,299.698394775391,299.698394775391,,,2.29117321968079,0,1,,,,,,1,1,1,1.79997003078461,0,0,1.79999833921843,,,,,,,,,,,,,,,,,,,,,,,,,,,,,,,,,

,3823555221.70814,1.80003768205643,299.698394775391,,,5,,,,26.7500001937151,,,,,3.24724145054428E-6,1.39160274797265E-8,5.06651752690957,0.00246442866265688,1.08244330697502E-6,4.63880220628051E-9,1.07821403138803E-6,3.83798011065572E-9,9.55929669640079E-8,2.60545477397019E-9,2.99991826788507,12.0147953033447,12,144,1,3,0.010544738275331,0.00215246110300818,0.0241735558956862,160.842132568359,1.79769647121429,1.80137062072754,299.698394775391,299.698394775391,,,2.29133129119873,0,1,,,,,,1,1,1,1.80007219314575,0,0,1.79998323276861,,,,,,,,,,,,,,,,,,,,,,,,,,,,,,,,,

,3823555285.51954,1.79991322755814,299.698394775391,,,5,,,,26.7500001937151,,,,,3.19455613163407E-6,1.22711399238804E-8,6.21017056949151,0.00211838756578622,1.06483034572315E-6,4.09029662624175E-9,1.05858168417233E-6,3.48472197351671E-9,1.15188901842883E-7,2.14178412962988E-9,3.00006113130121,15.8532876968384,12,190,1,3,0.0102744015387122,0.0025401782143013,0.0230123773217201,155.883682250977,1.79907047748566,1.80196464061737,299.698394775391,299.698394775391,,,2.2915563583374,0,1,,,,,,1,1,1,1.80008542537689,0,0,1.80002477055504,,,,,,,,,,,,,,,,,,,,,,,,,,,,,,,,,

,3823555348.57902,1.80012238025665,299.698394775391,,,5,,,,26.7500001937151,,,,,3.13938940217635E-6,7.40563196874195E-9,7.58273262118114,0.00185675841477434,1.04652829253557E-6,2.46869769453309E-9,1.03737677276513E-6,1.51667815340316E-9,1.38097423599544E-7,1.94785925723153E-9,2.99981321534088,20.9024505615234,12,250,1,3,0.00997987553232179,0.00291407430331631,0.0213832911103964,150.331115722656,1.79846322536469,1.80195796489716,299.698394775391,299.698394775391,,,2.29190397262573,0,1,,,,,,1,1,1,1.79992020130157,0,0,1.80000815083904,,,,,,,,,,,,,,,,,,,,,,,,,,,,,,,,,

,3823555410.87293,1.79975467920303,299.698394775391,,,5,,,,26.7500001937151,,,,,3.02861171763107E-6,1.37766860959431E-8,9.2132571623197,0.00225059544063478,1.00961107587646E-6,4.59256457021728E-9,9.96586330901678E-7,4.25631562913322E-9,1.61648413516336E-7,1.72494249087072E-9,2.99978059868439,27.5553760528564,12,330,1,3,0.00950588197730188,0.0031854355503977,0.0193044692277908,144.520370483398,1.79858863353729,1.80129289627075,299.698394775391,299.698394775391,,,2.292072057724,0,1,,,,,,1,1,1,1.79991781711578,0,0,1.79999724763339,,,,,,,,,,,,,,,,,,,,,,,,,,,,,,,,,

,3823555472.64664,1.79981189966202,299.698394775391,,,5,,,,26.7500001937151,,,,,2.9455839840764E-6,6.28867736999463E-9,10.0291437018294,0.00125084223195101,9.81941182161318E-7,2.09639627466263E-9,9.66936432414318E-7,1.81810260479185E-9,1.71004154611044E-7,1.04373380651794E-9,2.99975603181544,36.330451965332,12,435,1,3,0.00919192842175962,0.00324118923373734,0.0169033389538527,138.927017211914,1.79838979244232,1.80221843719482,299.698394775391,299.698394775391,,,2.29209494590759,0,1,,,,,,1,1,1,1.80010664463043,0,0,1.79999212225278,,,,,,,,,,,,,,,,,,,,,,,,,,,,,,,,,

,3823555534.13942,1.79974919557571,299.698394775391,,,5,,,,26.7500001937151,,,,,2.84485083414356E-6,7.23789452540246E-9,11.3976441073147,0.00187986795012441,9.48324610636529E-7,2.4127358191337E-9,9.29622986515732E-7,1.69382216918984E-9,1.87405096196702E-7,1.71821436150784E-9,2.99987029993248,47.8707122802734,12,574,1,3,0.00882233349981613,0.00327366392916537,0.0144002623856068,134.186981201172,1.79890954494476,1.80153322219849,299.698394775391,299.698394775391,,,2.29223346710205,0,1,,,,,,1,1,1,1.80003297328949,0,0,1.80000165303548,,,,,,,,,,,,,,,,,,,,,,,,,,,,,,,,,

,3823555597.34347,1.79959708452225,299.698394775391,,,5,,,,26.7500001937151,,,,,2.72250188030671E-6,8.11258001760673E-9,12.1379415569387,0.00185470102690299,9.07495762367814E-7,2.70417884413674E-9,8.87207979404896E-7,2.2895177599133E-9,1.90815512985244E-7,1.43898980125584E-9,3.00001608073985,63.0854339599609,12,757,1,3,0.00844260778698804,0.00312692329882247,0.0120035707950592,130.724761962891,1.79846036434174,1.80225682258606,299.698394775391,299.698394775391,,,2.29224133491516,0,1,,,,,,1,1,1,1.80006766319275,0,0,1.80000971594164,,,,,,,,,,,,,,,,,,,,,,,,,,,,,,,,,

,3823555658.84988,1.79962664842606,299.698394775391,,,5,,,,26.7500001937151,,,,,2.59651448821802E-6,5.25039975141881E-9,12.8960322812478,0.00144865403893311,8.65548904555674E-7,1.75022237462607E-9,8.43716863212549E-7,1.28281454290972E-9,1.93175466631516E-7,1.1906574692753E-9,2.9998472351495,83.1824951171875,12,998,1,3,0.00805662420665901,0.0029649941666368,0.00993167888373137,128.817718505859,1.79860365390778,1.802170753479,299.698394775391,299.698394775391,,,2.29231977462769,0,1,,,,,,1,1,1,1.79997038841248,0,0,1.79999505281448,,,,,,,,,,,,,,,,,,,,,,,,,,,,,,,,,

,3823555719.8,1.79956752061844,299.698394775391,,,5,,,,26.7500001937151,,,,,2.49468277596486E-6,6.43103003224273E-9,13.5284191088754,0.00203625404379003,8.31594803135094E-7,2.14376401085719E-9,8.08521382251503E-7,1.31941239487296E-9,1.94533007593608E-7,1.68963755477383E-9,2.99987778490193,109.726127624512,12,1316,1,3,0.00774627424346349,0.00283095173045758,0.00829850323498249,128.299346923828,1.79876387119293,1.80167937278748,299.698394775391,299.698394775391,,,2.29241824150085,0,1,,,,,,1,1,1,1.79997551441193,0,0,1.80001945098241,,,,,,,,,,,,,,,,,,,,,,,,,,,,,,,,,

,3823555780.59575,1.79956465959549,299.698394775391,,,5,,,,26.7500001937151,,,,,2.37556482309424E-6,9.55004432152676E-9,13.4573776617841,0.00269342755560474,7.91894519024124E-7,3.18350721526679E-9,7.70151717788373E-7,2.5004418454499E-9,1.84291239205955E-7,1.97040827423629E-9,2.99985006339193,144.4619140625,12,1733,1,3,0.00740252642630205,0.00262256935068235,0.0070846495218575,128.713012695312,1.79820489883423,1.80179703235626,299.698394775391,299.698394775391,,,2.29264378547668,0,1,,,,,,1,1,1,1.80000400543213,0,0,1.80000463922818,,,,,,,,,,,,,,,,,,,,,,,,,,,,,,,,,

,3823555841.12328,1.79959976673126,299.698394775391,,,5,,,,26.7500001937151,,,,,2.277030132409E-6,8.32999816916538E-9,13.5198381879547,0.00230769234200418,7.59016666764835E-7,2.77669028377241E-9,7.37983581411119E-7,2.29898166759881E-9,1.77444453264733E-7,1.55714232619908E-9,2.99997382417756,190.73486328125,12,2288,1,3,0.0070997554974737,0.00250278005322792,0.00624996889382601,129.185409545898,1.79897117614746,1.80163478851318,299.698394775391,299.698394775391,,,2.29267930984497,0,1,,,,,,1,1,1,1.79998481273651,0,0,1.80000397364298,,,,,,,,,,,,,,,,,,,,,,,,,,,,,,,,,

,3823555901.88954,1.79958254098892,299.698394775391,,,5,,,,26.7500001937151,,,,,2.1678145220032E-6,1.07968870664742E-8,13.756983354728,0.00348606616286231,7.22577657572746E-7,3.59882696899789E-9,7.01849139394025E-7,2.70777451231958E-9,1.71832059742015E-7,2.37055114756442E-9,3.00011285885206,251.044357299805,12,3012,1,3,0.00673963678791272,0.00244016091939272,0.00570180034264922,128.765579223633,1.79842364788055,1.80230987071991,299.698394775391,299.698394775391,,,2.29270911216736,0,1,,,,,,1,1,1,1.79998898506165,0,0,1.80002351999283,,,,,,,,,,,,,,,,,,,,,,,,,,,,,,,,,

,3823555962.6373,1.79954290390015,299.698394775391,,,5,,,,26.7500001937151,,,,,2.07347150247398E-6,9.8492849738387E-9,13.5116176306785,0.00305281794930207,6.91155796745291E-7,3.28308848004065E-9,6.72026377553964E-7,2.71462747801444E-9,1.61483383808722E-7,1.84647437658489E-9,3.00000594979906,331.038146972656,12,3972,1,3,0.00642885718480422,0.00238565513173056,0.00544506870210171,126.500823974609,1.79821026325226,1.80159401893616,299.698394775391,299.698394775391,,,2.29262685775757,0,1,,,,,,1,1,1,1.80006730556488,0,0,1.79999718666077,,,,,,,,,,,,,,,,,,,,,,,,,,,,,,,,,

,3823556023.30394,1.79962092638016,299.698394775391,,,5,,,,26.7500001937151,,,,,1.97709958935194E-6,8.05905354585153E-9,12.9607230734518,0.00279321855464742,6.59062306033754E-7,2.68646983843611E-9,6.42272062675526E-7,2.10771759001106E-9,1.47816510380453E-7,1.66572709457008E-9,2.99986749545753,436.940734863281,12,5243,1,3,0.00610446808255585,0.00234781229267336,0.00538501469418406,121.702774047852,1.79782819747925,1.80265319347382,299.698394775391,299.698394775391,,,2.29226994514465,0,1,,,,,,1,1,1,1.80003488063812,0,0,1.80003406802813,,,,,,,,,,,,,,,,,,,,,,,,,,,,,,,,,

,3823556083.82609,1.79948949813843,299.698394775391,,,5,,,,26.7500001937151,,,,,1.90333491212291E-6,8.92149998596889E-9,12.5560385383326,0.00370687593027692,6.3443610303224E-7,2.97379176320955E-9,6.19262833971912E-7,1.88221157628391E-9,1.37922845431097E-7,2.30232861100143E-9,3.00004193176597,574.448547363281,12,6893,1,3,0.00582101575132576,0.00240613487265562,0.00557281635701656,114.060440063477,1.79631114006042,1.80412769317627,299.698394775391,299.698394775391,,,2.29198479652405,0,1,,,,,,1,1,1,1.79993140697479,0,0,1.80003110433029,,,,,,,,,,,,,,,,,,,,,,,,,,,,,,,,,

,3823556144.3923,1.79944431781769,299.698394775391,,,5,,,,26.7500001937151,,,,,1.82248939102713E-6,1.53734539288405E-8,12.6652215846421,0.00579041843157476,6.07496059701426E-7,5.12448123525618E-9,5.92714350393332E-7,4.59602187440338E-9,1.33195951104262E-7,2.26647101470511E-9,3.00000199494768,758.4951171875,12,9101,1,3,0.00546007224017109,0.00256829015309229,0.00612214580178261,103.143310546875,1.79448711872101,1.80653250217438,299.698394775391,299.698394775391,,,2.29154920578003,0,1,,,,,,1,1,1,1.79994404315948,0,0,1.80004351536433,,,,,,,,,,,,,,,,,,,,,,,,,,,,,,,,,

,3823556214.16663,1.80013525485992,299.698394775391,,,5,,,,26.7500001937151,,,,,1.52205758681518E-6,1.56939141546996E-8,19.8989400753971,0.0114703445488937,5.07336425886263E-7,5.23113867989145E-9,4.77045612144985E-7,3.93838836999804E-9,1.72678119529556E-7,3.44295061470836E-9,3.000095221147,941.265075683594,12,11295,100,3,0.00412319225559428,0.00290070466898768,0.00721287727355957,89.2013549804687,1.79244923591614,1.80610764026642,299.698394775391,299.698394775391,,,2.29077482223511,0,1,,,,,,1,1,1,1.80019950866699,0,0,1.80003749312095,,,,,,,,,,,,,,,,,,,,,,,,,,,,,,,,,