File: data/AP498/ac_1000.dat
[Header]
; MPMS3 Data File (default extension .dat)
; Copyright (c) 2007, Quantum Design, Inc. All rights reserved.
TITLE,
FILEOPENTIME,3825414583.90006,03/20/2021,3:09 pm
BYAPP,SQUID AC,0.9.1.0
INFO,MPMS3 Measurement Release 1.1.16 Build 347, MultiVu Release 2.3.3.2,APPNAME
INFO,0,MOMENT_UNITS
INFO,SC_AP498,SAMPLE_MATERIAL
INFO,crystals, nujol, capsule,SAMPLE_COMMENT
INFO,1,SAMPLE_MASS
INFO,,SAMPLE_VOLUME
INFO,,SAMPLE_MOLECULAR_WEIGHT
INFO,,SAMPLE_SIZE
INFO,,SAMPLE_SHAPE
INFO,Standard,SAMPLE_HOLDER
INFO,Standard,SAMPLE_HOLDER_DETAIL
INFO,64.87,SAMPLE_OFFSET
DATATYPE,COMMENT,1
DATATYPE,TIME,2
STARTUPAXIS,X,2
STARTUPAXIS,Y1,5
FIELDGROUP, VSM,2,3,4,5,6,8,9,10,11,14,15
FIELDGROUP, DC, 2,3,4,14,56,57,58,59,60,61,62,63,64,65,66,67,68,69
FIELDGROUP, AC, 2,3,4,11,16,17,18,19,20,21,22,23,24,25,26,27,28,29,30
STARTUPGROUP, All
[Data]
Comment,Time Stamp (sec),Temperature (K),Magnetic Field (Oe),Moment (emu),M. Std. Err. (emu),Transport Action,Averaging Time (sec),Frequency (Hz),Peak Amplitude (mm),Center Position (mm),Lockin Signal' (V),Lockin Signal (V),Range,M. Quad. Signal (emu),AC Moment (emu),AC M. Std Err. (emu),AC Phase (deg),AC Phase Std. Err. (deg),AC Susceptibility (emu/Oe),AC Suscept. Std Err. (emu/Oe),AC X' (emu/Oe),AC X' Std Err. (emu/Oe),AC X'' (emu/Oe),AC X'' Std Err. (emu/Oe),AC Drive (Oe),AC Frequency (Hz),AC Averaging Time (sec),AC Cycles,AC Range,AC Measure Type,AC Signal' (V),AC Signal'' (V),AC Trim Coil Ratio,AC Trim Coil Phase,Min. Temperature (K),Max. Temperature (K),Min. Field (Oe),Max. Field (Oe),Mass (grams),Motor Lag (deg),Pressure (Torr),Measure Count,Measurement Number,SQUID Status (code),Motor Status (code),Measure Status (code),Motor Current (amps),Motor Temp. (C),Temp. Status (code),Field Status (code),Chamber Status (code),Chamber Temp (K),Redirection State,Evercool Status,Average Temp (K),Rotation Angle (deg),Rotator state,DC Moment Fixed Ctr (emu),DC Moment Err Fixed Ctr (emu),DC Moment Free Ctr (emu),DC Moment Err Free Ctr (emu),DC Fixed Fit,DC Free Fit,DC Calculated Center (mm),DC Calculated Center Err (mm),DC Scan Length (mm),DC Scan Time (s),DC Number of Points,DC Squid Drift,DC Min V (V),DC Max V (V),DC Scans per Measure,Map 01,Map 02,Map 03,Map 04,Map 05,Map 06,Map 07,Map 08,Map 09,Map 10,Map 11,Map 12,Map 13,Map 14,Map 15,Map 16
,3825415486.16565,1.9999566078186,1000.06182861328,,,5,,,,24.2400001734495,,,,,0.000201282117794986,9.58452187942367E-7,14.5995069822629,0.00227412340781048,6.70942595128238E-5,3.19485111409341E-7,6.49278757424412E-5,2.92613910722383E-7,1.69118482475532E-5,1.28249115646042E-7,2.99999015201165,0.800566077232361,39.971716151935,32,1,3,0.643897333737815,0.176463448911347,0.0262706521898508,178.450180053711,1.99855697154999,2.0018482208252,1000.06182861328,1000.06182861328,,,2.51295471191406,0,1,,,,,,1,1,1,1.99957180023193,0,0,2.00000441175396,,,,,,,,,,,,,,,,,,,,,,,,,,,,,,,,,
,3825416360.919,2.00000929832458,1000.06182861328,,,5,,,,24.2400001734495,,,,,9.85061911849369E-5,3.33047167658817E-7,44.96626370805,0.00881944093472271,3.28355546542306E-5,1.11016255369845E-7,2.32319104536869E-5,7.11440399738774E-8,2.3204568216686E-5,8.52240255593343E-8,2.99998560165163,6.14035797119141,12,73,1,3,0.215166496285551,0.245784917401218,0.0257305223494768,169.394897460938,1.99661934375763,2.00308442115784,1000.06182861328,1000.06182861328,,,2.51119565963745,0,1,,,,,,1,1,1,2.00006890296936,0,0,1.99998519390444,,,,,,,,,,,,,,,,,,,,,,,,,,,,,,,,,
,3825416905.99645,1.99996316432953,1000.06182861328,,,5,,,,24.2400001734495,,,,,2.94164317180855E-5,2.99918358056494E-8,40.3114068471217,0.00418685444627282,9.80629822960385E-6,9.99811565121572E-9,7.47769021092284E-6,9.63802324338687E-9,6.34410230666249E-6,2.65910220469601E-9,2.99974883787252,47.1313934326172,12,565,1,3,0.0634080483815724,0.0738130888902426,0.0145851410925388,134.529067993164,1.99747323989868,2.00228881835938,1000.06182861328,1000.06182861328,,,2.51182675361633,0,1,,,,,,1,1,1,2.00042772293091,0,0,1.99999884953575,,,,,,,,,,,,,,,,,,,,,,,,,,,,,,,,,
,3825417422.16325,1.99985808134079,1000.06182861328,,,5,,,,24.2400001734495,,,,,1.54370557571669E-5,1.30383625896503E-8,19.3774107768558,0.000613912177353342,5.14590968667784E-6,4.34631042369266E-9,4.85441212594788E-6,4.03498103202124E-9,1.70735743618465E-6,1.61534589804421E-9,2.99986915765965,361.021270751953,12,4332,1,3,0.0456636599598311,0.0228427885847519,0.00539505342021585,125.647705078125,1.99867737293243,2.00257325172424,1000.06182861328,1000.06182861328,,,2.51144099235535,0,1,,,,,,1,1,1,2.00022864341736,0,0,2.00001713018569,,,,,,,,,,,,,,,,,,,,,,,,,,,,,,,,,
,3825418618.90838,3.0000284910202,1000.06182861328,,,5,,,,24.2400001734495,,,,,0.000149516025357355,2.82819744959136E-7,3.96909333942747,0.000941616458123821,4.98386479677681E-5,9.42731969610834E-8,4.97191116336987E-5,8.19941970432441E-8,3.4497492098585E-6,4.65229762213993E-8,3.00000163435515,1.72026944160461,18.6017371616806,30,1,3,0.493842409640662,0.0454348639370341,0.0261842552572489,176.998382568359,2.99877619743347,3.00182199478149,1000.06182861328,1000.06182861328,,,3.09499979019165,0,1,,,,,,1,1,1,3.00002384185791,0,0,2.99999772912205,,,,,,,,,,,,,,,,,,,,,,,,,,,,,,,,,
,3825419278.91941,2.99962830543518,1000.06182861328,,,5,,,,24.2400001734495,,,,,0.000132804251840136,1.16709683425795E-7,22.3034547863741,0.000744099402733136,4.42667762427192E-5,3.89020785854605E-8,4.09550386733954E-5,3.54012997214688E-8,1.67997704205641E-5,1.61282266942179E-8,3.00008862429821,13.2110729217529,12,158,1,3,0.384098801417237,0.214869444971981,0.0240228958427906,159.360046386719,2.99902296066284,3.00197291374207,1000.06182861328,1000.06182861328,,,3.09549689292908,0,1,,,,,,1,1,1,2.99978399276733,0,0,2.99999116697619,,,,,,,,,,,,,,,,,,,,,,,,,,,,,,,,,
,3825419797.17126,2.99970030784607,1000.06182861328,,,5,,,,24.2400001734495,,,,,4.69297863058956E-5,8.10981119940462E-9,54.8957679066803,0.00262854593587258,1.5643070221753E-5,2.70323724149385E-9,8.99579284963271E-6,2.35601228477991E-9,1.27977090515917E-5,1.32540472979594E-9,3.00003679844356,101.09342956543,12,1213,1,3,0.0736215293125862,0.136579828547076,0.00879037007689476,128.472381591797,2.99895572662354,3.00226974487305,1000.06182861328,1000.06182861328,,,3.09607839584351,0,1,,,,,,1,1,1,2.99983549118042,0,0,2.99999790721469,,,,,,,,,,,,,,,,,,,,,,,,,,,,,,,,,
,3825420312.41483,2.99996626377106,1000.06182861328,,,5,,,,24.2400001734495,,,,,1.26600952769802E-5,2.61486961629656E-8,37.2147425263502,0.00873819944791901,4.21990976077886E-6,8.71598007405037E-9,3.36062778690139E-6,8.02606799595945E-9,2.55221849907545E-6,3.39860871173463E-9,3.00008673044317,775.049621582031,12,9300,1,3,0.0269421021368047,0.0321134929810045,0.0061534377746284,102.693359375,2.99733018875122,3.00382733345032,1000.06182861328,1000.06182861328,,,3.09528803825378,0,1,,,,,,1,1,1,2.99987030029297,0,0,3.00003335967896,,,,,,,,,,,,,,,,,,,,,,,,,,,,,,,,,
,3825421492.0853,3.99988830089569,1000.06182861328,,,5,,,,24.2400001734495,,,,,0.000116626636921158,1.94541358807355E-7,1.3693680139508,0.00100292756543492,3.88755245680612E-5,6.48470844523451E-8,3.88644220704734E-5,5.18486548191523E-8,9.29035828175138E-7,3.89469043110485E-8,3.00000162613818,3.70358967781067,12,44,1,3,0.385941472627285,0.0259014842296402,0.0261374060064554,173.258087158203,3.99893760681152,4.00170278549194,1000.06182861328,1000.06182861328,,,3.53818368911743,0,1,,,,,,1,1,1,3.99965786933899,0,0,3.99999493728449,,,,,,,,,,,,,,,,,,,,,,,,,,,,,,,,,
,3825422069.60975,3.99954771995544,1000.06182861328,,,5,,,,24.2400001734495,,,,,0.000114689771365813,3.2667209566487E-8,9.25284001319927,0.000137038374548536,3.82272388366849E-5,1.08883050977846E-8,3.7729841208969E-5,1.02035529034996E-8,6.14661463107419E-6,3.80035472659178E-9,3.00021070984993,28.3225784301758,12,339,1,3,0.359762046633409,0.12126325886258,0.019147852435708,144.011138916016,3.99841642379761,4.001389503479,1000.06182861328,1000.06182861328,,,3.53808069229126,0,1,,,,,,1,1,1,3.99974942207336,0,0,4.00004364952208,,,,,,,,,,,,,,,,,,,,,,,,,,,,,,,,,
,3825422591.97272,3.9997535943985,1000.06182861328,,,5,,,,24.2400001734495,,,,,7.23649886598543E-5,7.92696298260965E-9,42.915726415661,0.000352108075666216,2.41228623487022E-5,2.64245238497265E-9,1.76665236651389E-5,2.08300824916617E-9,1.64257855058296E-5,1.62592473403701E-9,2.99985083087569,217.013900756836,12,2604,1,3,0.157273211493703,0.180310997176517,0.00598745234310627,129.379089355469,3.99903678894043,4.00114059448242,1000.06182861328,1000.06182861328,,,3.5380802154541,0,1,,,,,,1,1,1,4.00013065338135,0,0,3.9999998448387,,,,,,,,,,,,,,,,,,,,,,,,,,,,,,,,,
,3825423606.58556,4.99991750717163,1000.06182861328,,,5,,,,24.2400001734495,,,,,9.56931348851575E-5,7.84121651194241E-8,-0.0124084775510839,0.000426039683943835,3.18977398772767E-5,2.61374115206398E-8,3.18977391292421E-5,2.23267173644299E-8,-6.90805482475611E-9,1.35897745650227E-8,2.99999734317626,1.03099930286407,31.0378483390874,31,1,3,0.317371945517099,0.00473634271174075,0.026240648701787,178.101760864258,4.99900531768799,5.00152015686035,1000.06182861328,1000.06182861328,,,3.88754320144653,0,1,,,,,,1,1,1,4.99969387054443,0,0,5.0000098904237,,,,,,,,,,,,,,,,,,,,,,,,,,,,,,,,,
,3825424378.5239,5.00004410743713,1000.06182861328,,,5,,,,24.2400001734495,,,,,9.58581189803462E-5,1.05088438199409E-7,0.729720401756585,0.00053160119584794,3.19521570058817E-5,3.50288771839854E-8,3.19495656203614E-5,3.066469073868E-8,4.06932425269277E-7,1.69321876516842E-8,3.00005157594527,7.92664384841919,12,95,1,3,0.316381888468769,0.0303311610723537,0.0252680461853743,167.043655395508,4.998854637146,5.00190401077271,1000.06182861328,1000.06182861328,,,3.88640093803406,0,1,,,,,,1,1,1,5.00014209747314,0,0,4.99999527991573,,,,,,,,,,,,,,,,,,,,,,,,,,,,,,,,,
,3825424904.32754,4.99954533576965,1000.06182861328,,,5,,,,24.2400001734495,,,,,9.47401158527795E-5,1.58194839215631E-8,5.45760548803823,0.000144987121160538,3.15776849985479E-5,5.27276830536047E-9,3.14345384399895E-5,2.52347209241003E-9,3.00332864208122E-6,4.62970562788193E-9,3.00022360274783,60.7314987182617,12,728,1,3,0.304290075046229,0.0746772933271332,0.0123805766925216,131.181396484375,4.99863862991333,5.00132608413696,1000.06182861328,1000.06182861328,,,3.88567137718201,0,1,,,,,,1,1,1,4.99975776672363,0,0,4.99999851650662,,,,,,,,,,,,,,,,,,,,,,,,,,,,,,,,,
,3825425422.00907,4.9996931552887,1000.06182861328,,,5,,,,24.2400001734495,,,,,7.42337633715975E-5,6.42282832163514E-9,31.2119213079613,0.000120687664532309,2.47455996317169E-5,2.14103032005576E-9,2.11638338871509E-5,1.51060972252598E-9,1.28232927257514E-5,1.51725709674005E-9,2.99987733077403,466.139617919922,12,5593,1,3,0.189020914136094,0.156811248216612,0.0053822286427021,120.710098266602,4.99894189834595,5.00163316726685,1000.06182861328,1000.06182861328,,,3.88515090942383,0,1,,,,,,1,1,1,5.00012683868408,0,0,5.00005131676084,,,,,,,,,,,,,,,,,,,,,,,,,,,,,,,,,
,3825427213.97471,1.80028694868088,1000.30139160156,,,5,,,,24.2400001734495,,,,,0.000152766521597961,1.1735475487228E-6,36.4249563433417,0.0122346427549933,5.09222452376986E-5,3.91183064516149E-7,4.09738332897344E-5,3.89123642414395E-7,3.02360719273084E-5,4.00871660060836E-8,2.99999579525345,2.22107553482056,14.4074343705674,31,1,3,0.399203650083394,0.3120646884291,0.0262279193848372,176.134536743164,1.79684603214264,1.8019345998764,1000.30139160156,1000.30139160156,,,2.3398756980896,0,1,,,,,,1,1,1,1.79999136924744,0,0,1.80000660714415,,,,,,,,,,,,,,,,,,,,,,,,,,,,,,,,,
,3825427831.96349,1.79981845617294,1000.30139160156,,,5,,,,24.2400001734495,,,,,4.63937690276238E-5,1.53406100432657E-7,44.8002110948714,0.0193316870924871,1.54653198586672E-5,5.1137781240607E-8,1.09736982535404E-5,4.97300390741338E-8,1.08974338709226E-5,1.19162025787292E-8,2.99985835738297,17.0014362335205,12,204,1,3,0.0929468929059602,0.122406293129361,0.0227553695440292,154.391784667969,1.79728102684021,1.801100730896,1000.30139160156,1000.30139160156,,,2.34031200408936,0,1,,,,,,1,1,1,1.8004823923111,0,0,1.79992490344577,,,,,,,,,,,,,,,,,,,,,,,,,,,,,,,,,
,3825428347.0887,1.79997736215591,1000.30139160156,,,5,,,,24.2400001734495,,,,,2.06069205915484E-5,8.45815566364855E-9,24.3649159321302,0.000374368748285201,6.86936601271073E-6,2.81954631639207E-9,6.25755587101067E-6,2.46027813784432E-9,2.83393435664364E-6,1.37727009505229E-9,2.99982859457749,130.20832824707,12,1562,1,3,0.0586429480298916,0.0346743023761244,0.00753173278644681,128.618774414062,1.79886651039124,1.80167543888092,1000.30139160156,1000.30139160156,,,2.34197950363159,0,1,,,,,,1,1,1,1.80053699016571,0,0,1.79999262378329,,,,,,,,,,,,,,,,,,,,,,,,,,,,,,,,,
,3825428871.22544,1.79984587430954,1000.30139160156,,,5,,,,24.2400001734495,,,,,7.97607867526017E-5,1.01693596464767E-6,83.7412308442713,10.6965766980556,2.65870371973171E-5,3.38980035430697E-7,2.89849259466068E-6,2.47073034998696E-7,2.64285695339385E-5,2.32082700340051E-7,2.99998778204027,999.040954589844,12,11988,100,3,-0.0452543408447228,0.260318206440907,0.00714710773900151,89.5985412597656,1.79466676712036,1.80634963512421,1000.30139160156,1000.30139160156,,,2.34145832061768,0,1,,,,,,1,1,1,1.80044686794281,0,0,1.8000108251969,,,,,,,,,,,,,,,,,,,,,,,,,,,,,,,,,
,3825430034.33605,2.19989788532257,1000.30139160156,,,5,,,,24.2400001734495,,,,,0.000129802500700281,3.79917649060985E-7,36.4205817918023,0.00366009406195311,4.32674709792911E-5,1.26639130730022E-7,3.48164935335924E-5,7.68841097210958E-8,2.56882428937658E-5,1.00629533957233E-7,3.00000202836926,4.79836130142212,12,57,1,3,0.332083442309001,0.273927192859662,0.0259335841983557,172.445266723633,2.19664812088013,2.20189070701599,1000.30139160156,1000.30139160156,,,2.63048887252808,0,1,,,,,,1,1,1,2.19982814788818,0,0,2.20000080519085,,,,,,,,,,,,,,,,,,,,,,,,,,,,,,,,,
,3825430590.12754,2.19956290721893,1000.30139160156,,,5,,,,24.2400001734495,,,,,3.7918199624069E-5,3.54247657309101E-8,47.6940152807444,0.00747800653899581,1.26385525772292E-5,1.1807463662962E-8,8.50688040394245E-6,9.7031805115237E-9,9.34697796297851E-6,6.72788868167079E-9,3.00020112211157,36.4388999938965,12,437,1,3,0.068126184707179,0.105366250437128,0.0169061496853828,138.963531494141,2.19871854782104,2.20185947418213,1000.30139160156,1000.30139160156,,,2.63204765319824,0,1,,,,,,1,1,1,2.19980525970459,0,0,2.19998817216782,,,,,,,,,,,,,,,,,,,,,,,,,,,,,,,,,
,3825431103.73204,2.19981169700623,1000.30139160156,,,5,,,,24.2400001734495,,,,,1.56913425439554E-5,7.07596074145899E-9,25.7474863573004,0.000430418729698135,5.23022009615438E-6,2.35855102684217E-9,4.71094971374832E-6,1.74463678664531E-9,2.27203764245924E-6,1.58713749527323E-9,3.00013044489136,279.817321777344,12,3357,1,3,0.0439368772097257,0.0276036145503307,0.00557330390438437,128.44189453125,2.19703650474548,2.20231533050537,1000.30139160156,1000.30139160156,,,2.63335132598877,0,1,,,,,,1,1,1,2.20035409927368,0,0,2.19998361193945,,,,,,,,,,,,,,,,,,,,,,,,,,,,,,,,,
,3825432178.53543,2.3987592458725,1000.30139160156,,,5,,,,24.2400001734495,,,,,0.000175273031330401,2.68637318226034E-6,10.8823196353933,0.00357214090844198,5.84244536608361E-5,8.95459411589804E-7,5.73738077111188E-5,8.9362559918586E-7,1.10300940292798E-5,5.72786721605056E-8,2.99999435763475,1.33032166957855,24.0543326713889,31,1,3,0.568803324309966,0.120203062316108,0.0262028519064188,177.594360351562,2.39590263366699,2.40235376358032,1000.30139160156,1000.30139160156,,,2.75470733642578,0,1,,,,,,1,1,1,2.40001559257507,0,0,2.40001286859587,,,,,,,,,,,,,,,,,,,,,,,,,,,,,,,,,
,3825432886.57001,2.39996683597565,1000.30139160156,,,5,,,,24.2400001734495,,,,,0.000105326065816376,1.36215187272349E-7,41.9603945037596,0.00424146728430236,3.51078727584844E-5,4.54040073125679E-8,2.61064663265014E-5,4.08126262859391E-8,2.34737117978641E-5,1.98960653317181E-8,3.00006971487391,10.2065477371216,12,122,1,3,0.234782798941636,0.258426341422114,0.0248164553195238,163.530227661133,2.39665937423706,2.40323686599731,1000.30139160156,1000.30139160156,,,2.75548362731934,0,1,,,,,,1,1,1,2.40013527870178,0,0,2.39997078715891,,,,,,,,,,,,,,,,,,,,,,,,,,,,,,,,,
,3825433406.93406,2.4001282453537,1000.30139160156,,,5,,,,24.2400001734495,,,,,2.82289730502553E-5,1.38373458761082E-8,46.7140577681175,0.0029941790225983,9.41034096172809E-6,4.61278355637392E-9,6.45210401339689E-6,4.02267834716877E-9,6.85017305009773E-6,2.25739474907982E-9,2.99978217208736,78.3758010864258,12,940,1,3,0.0545522697058181,0.0757398529001548,0.0104106236249208,129.155395507812,2.39619755744934,2.40211319923401,1000.30139160156,1000.30139160156,,,2.75751900672913,0,1,,,,,,1,1,1,2.3993935585022,0,0,2.39999351080726,,,,,,,,,,,,,,,,,,,,,,,,,,,,,,,,,
,3825433922.77056,2.40007507801056,1000.30139160156,,,5,,,,24.2400001734495,,,,,1.27072793681627E-5,7.79132636641389E-9,22.1029455710403,0.000601427087984575,4.23571251806231E-6,2.59707980491972E-9,3.92442698924367E-6,2.04052231931853E-9,1.59377957753437E-6,1.60657778444891E-9,3.00003348054788,600.961547851562,12,7211,1,3,0.0355099770058677,0.0225346607696176,0.00560011714696884,113.008819580078,2.39358115196228,2.40363907814026,1000.30139160156,1000.30139160156,,,2.75722241401672,0,1,,,,,,1,1,1,2.40001606941223,0,0,2.40009036518279,,,,,,,,,,,,,,,,,,,,,,,,,,,,,,,,,
,3825435080.47339,2.60012769699097,1000.30139160156,,,5,,,,24.2400001734495,,,,,0.000159772622847446,3.21925746349834E-7,13.6779275914293,0.00106474793028895,5.32574965726233E-5,1.07308492702382E-7,5.17471292297629E-5,9.48628518568934E-8,1.2593472819727E-5,5.0161259390432E-8,3.00000249973401,2.90091037750244,12,34,1,3,0.510219586577554,0.143179651178834,0.026085814461112,175.239105224609,2.59657406806946,2.60242867469788,1000.30139160156,1000.30139160156,,,2.87350463867187,0,1,,,,,,1,1,1,2.60036110877991,0,0,2.59999332945031,,,,,,,,,,,,,,,,,,,,,,,,,,,,,,,,,
,3825435674.98112,2.59967958927155,1000.30139160156,,,5,,,,24.2400001734495,,,,,8.3055978313979E-5,6.34864363388409E-8,47.3108568705241,0.00643491272692564,2.76868896785126E-5,2.11633406128882E-8,1.87722760172505E-5,2.03605218249719E-8,2.03510568079962E-5,5.77374548382317E-9,2.99983057968544,21.9156761169434,12,262,1,3,0.153110175038639,0.22848814273306,0.0211255419999361,149.437973022461,2.59864044189453,2.60228896141052,1000.30139160156,1000.30139160156,,,2.87428951263428,0,1,,,,,,1,1,1,2.59981107711792,0,0,2.59998714356195,,,,,,,,,,,,,,,,,,,,,,,,,,,,,,,,,
,3825436187.72552,2.60016393661499,1000.30139160156,,,5,,,,24.2400001734495,,,,,2.151448505427E-5,8.94408294603026E-9,45.1535607653859,0.00130389963095165,7.17186840131505E-6,2.98151620629396E-9,5.05766684613755E-6,1.85097355907368E-9,5.08485028680907E-6,2.33737796943576E-9,2.99984381340922,168.083053588867,12,2016,1,3,0.0446643809843864,0.0553568116959213,0.00661102775484323,129.166244506836,2.59642195701599,2.60181856155396,1000.30139160156,1000.30139160156,,,2.87452411651611,0,1,,,,,,1,1,1,2.59960031509399,0,0,2.59997429544964,,,,,,,,,,,,,,,,,,,,,,,,,,,,,,,,,
,3825436987.43366,2.80033755302429,1000.30139160156,,,5,,,,24.2400001734495,,,,,0.000160512281768359,4.63364960759362E-7,3.122554878147,0.00147679126697574,5.35040859670109E-5,1.54454963953149E-7,5.34246486892121E-5,1.3290742456277E-7,2.91446866505092E-6,7.8688959745699E-8,3.00000044608418,0.800566077232361,39.971716151935,32,1,3,0.53120815535506,0.0357388428415128,0.0263121351599693,178.372268676758,2.79707813262939,2.80253028869629,1000.30139160156,1000.30139160156,,,2.98453688621521,0,1,,,,,,1,1,1,2.80016183853149,0,0,2.80001319720682,,,,,,,,,,,,,,,,,,,,,,,,,,,,,,,,,
,3825437866.71275,2.80014407634735,1000.30139160156,,,5,,,,24.2400001734495,,,,,0.000146115690609985,1.75663578588304E-7,17.0573145213047,0.000756468501099215,4.87049455720436E-5,5.85541840059516E-8,4.65625031822828E-5,4.99413150564415E-8,1.42865328395534E-5,3.05688978380983E-8,3.00001753197429,6.14035797119141,12,73,1,3,0.452685554298147,0.17278492373653,0.0255065970122814,170.020355224609,2.79844260215759,2.80250597000122,1000.30139160156,1000.30139160156,,,2.98415279388428,0,1,,,,,,1,1,1,2.80021715164185,0,0,2.80002454817295,,,,,,,,,,,,,,,,,,,,,,,,,,,,,,,,,
,3825438404.81611,2.79996454715729,1000.30139160156,,,5,,,,24.2400001734495,,,,,6.30411019733288E-5,1.88188773293035E-8,51.8079554951274,0.0043139046332975,2.10155024775687E-5,6.27349698465549E-9,1.29938699139985E-5,5.79523633887087E-9,1.65169818381804E-5,2.40249873946107E-9,2.99974278705051,47.1313934326172,12,565,1,3,0.101633618225757,0.182095083894795,0.0146018648520112,134.4208984375,2.79865646362305,2.80192089080811,1000.30139160156,1000.30139160156,,,2.98505806922913,0,1,,,,,,1,1,1,2.79998779296875,0,0,2.80000081285834,,,,,,,,,,,,,,,,,,,,,,,,,,,,,,,,,
,3825438920.68998,2.79987680912018,1000.30139160156,,,5,,,,24.2400001734495,,,,,1.63531472174495E-5,5.22018605915526E-9,42.178612973029,0.000921232860453692,5.45114374087579E-6,1.74009223938297E-9,4.03959885409406E-6,1.17428950043951E-9,3.66013786375476E-6,1.28412038793813E-9,2.99994789989196,361.021270751953,12,4332,1,3,0.0352168509418376,0.0410527039247276,0.00537138665094972,125.672164916992,2.79855728149414,2.80202507972717,1000.30139160156,1000.30139160156,,,2.98532056808472,0,1,,,,,,1,1,1,2.79992389678955,0,0,2.80001163482666,,,,,,,,,,,,,,,,,,,,,,,,,,,,,,,,,
,3825439989.1087,3.20024049282074,1000.30139160156,,,5,,,,24.2400001734495,,,,,0.000142080667154421,6.8471286462013E-7,2.7007783956862,0.00139565352604278,4.73600323090671E-5,2.28236705530096E-7,4.73074264381341E-5,2.18900153063597E-7,2.23160572602029E-6,6.46120479474665E-8,3.00001204026247,1.72026944160461,18.6017371616806,30,1,3,0.470124563591839,0.0327775496109675,0.0262899380177259,176.867370605469,3.19632697105408,3.20249891281128,1000.30139160156,1000.30139160156,,,3.18545818328857,0,1,,,,,,1,1,1,3.20015740394592,0,0,3.19997352783126,,,,,,,,,,,,,,,,,,,,,,,,,,,,,,,,,
,3825440634.16738,3.19983911514282,1000.30139160156,,,5,,,,24.2400001734495,,,,,0.00013353530871856,8.01799621415006E-8,15.9148576741957,0.000371287174169049,4.45103441654799E-5,2.67257981753355E-8,4.28042731508116E-5,2.42627266382575E-8,1.22051193259295E-5,1.12066223361884E-8,3.00009607254673,13.2110729217529,12,158,1,3,0.407855233654296,0.171736156171863,0.0238918885588646,159.164581298828,3.19856452941895,3.20174717903137,1000.30139160156,1000.30139160156,,,3.18576788902283,0,1,,,,,,1,1,1,3.20021867752075,0,0,3.20001811451382,,,,,,,,,,,,,,,,,,,,,,,,,,,,,,,,,
,3825441148.79098,3.19974064826965,1000.30139160156,,,5,,,,24.2400001734495,,,,,5.95773001683092E-5,1.48278823597276E-8,52.3198841978336,0.0029832207384874,1.98595676848682E-5,4.94274383891791E-9,1.21392086767478E-5,4.77172579124014E-9,1.57175711015484E-5,1.28893352442035E-9,2.99992935967602,101.09342956543,12,1213,1,3,0.101160821255932,0.16901207127779,0.00878389645367861,128.371978759766,3.19904088973999,3.20194697380066,1000.30139160156,1000.30139160156,,,3.18673610687256,0,1,,,,,,1,1,1,3.19982147216797,0,0,3.20009807177952,,,,,,,,,,,,,,,,,,,,,,,,,,,,,,,,,
,3825441659.97037,3.1996591091156,1000.30139160156,,,5,,,,24.2400001734495,,,,,1.41435800847801E-5,2.18498761215682E-8,44.8333667515687,0.0142860023395511,4.71439567026584E-6,7.28308962553364E-9,3.34326208607894E-6,6.43150588226637E-9,3.3238720131209E-6,3.41747371312916E-9,3.00008337738494,775.049621582031,12,9300,1,3,0.0250775925498357,0.0395498237752951,0.00615777214989066,102.693878173828,3.1977481842041,3.20337963104248,1000.30139160156,1000.30139160156,,,3.18585681915283,0,1,,,,,,1,1,1,3.19966983795166,0,0,3.20002431339688,,,,,,,,,,,,,,,,,,,,,,,,,,,,,,,,,
,3825442744.92063,3.40012168884277,1000.30139160156,,,5,,,,24.2400001734495,,,,,0.000133895467062012,2.55039201342163E-7,3.60821981828335,0.00167941562666421,4.46318216966505E-5,8.5013065861951E-8,4.45433484849719E-5,3.96404967745506E-8,2.8088456183915E-6,7.52054012868442E-8,3.00000004418508,3.70358967781067,12,44,1,3,0.441587657593037,0.0470235755496283,0.0261265430599451,173.612121582031,3.39905142784119,3.40240740776062,1000.30139160156,1000.30139160156,,,3.27751803398132,0,1,,,,,,1,1,1,3.40027260780334,0,0,3.40000355685199,,,,,,,,,,,,,,,,,,,,,,,,,,,,,,,,,
,3825443316.61499,3.39950430393219,1000.30139160156,,,5,,,,24.2400001734495,,,,,0.000120227732304557,3.99255036613422E-8,22.077046577931,0.000322941542441764,4.00744085110008E-5,1.33080023474038E-8,3.71361238959536E-5,1.24583656249908E-8,1.50620888156643E-5,4.67889436005498E-9,3.00011246008918,28.3225784301758,12,339,1,3,0.339510598497593,0.20765720557594,0.0191317051649094,144.001190185547,3.39887547492981,3.40164732933044,1000.30139160156,1000.30139160156,,,3.27785730361938,0,1,,,,,,1,1,1,3.39957141876221,0,0,3.40001513466002,,,,,,,,,,,,,,,,,,,,,,,,,,,,,,,,,
,3825443847.40853,3.39997565746307,1000.30139160156,,,5,,,,24.2400001734495,,,,,4.28491613802911E-5,6.59885471230105E-9,55.9457445221692,0.00188940280387473,1.42828030011914E-5,2.19957961493805E-9,7.9980511565426E-6,1.49903789710507E-9,1.18334119875955E-5,1.60966948952071E-9,3.00005267710525,217.013900756836,12,2604,1,3,0.0666541132111197,0.125014957254363,0.00594406435266137,129.414001464844,3.39856576919556,3.40128374099731,1000.30139160156,1000.30139160156,,,3.27878785133362,0,1,,,,,,1,1,1,3.4001579284668,0,0,3.39999984559559,,,,,,,,,,,,,,,,,,,,,,,,,,,,,,,,,
,3825444731.57746,3.59986233711243,1000.30139160156,,,5,,,,24.2400001734495,,,,,0.000129049088160254,3.64768743548762E-7,0.839238639403842,0.00265346552716439,4.30164867057402E-5,1.21589931639421E-7,4.30118722248263E-5,4.1810495860873E-8,6.30060489426154E-7,1.14175277148544E-7,2.99999135315329,1.03099930286407,31.0378483390874,31,1,3,0.427856722676684,0.0127482992477904,0.0262568648904562,178.00505065918,3.596843957901,3.60130620002747,1000.30139160156,1000.30139160156,,,3.36561512947082,0,1,,,,,,1,1,1,3.60008835792542,0,0,3.59999594467365,,,,,,,,,,,,,,,,,,,,,,,,,,,,,,,,,
,3825445492.73214,3.59983515739441,1000.30139160156,,,5,,,,24.2400001734495,,,,,0.00012751002236975,8.93398896848519E-8,5.086596730888,0.000402765648897996,4.25039646569332E-5,2.97804003406726E-8,4.23365769588929E-5,2.4561351742817E-8,3.76845631015814E-6,1.68407911042312E-8,2.99995596643595,7.92664384841919,12,95,1,3,0.416568391707304,0.072201725376354,0.025353129953146,166.675048828125,3.59914326667786,3.60222816467285,1000.30139160156,1000.30139160156,,,3.36504817008972,0,1,,,,,,1,1,1,3.59983158111572,0,0,3.60000240802765,,,,,,,,,,,,,,,,,,,,,,,,,,,,,,,,,
,3825446018.59962,3.59858345985413,1000.30139160156,,,5,,,,24.2400001734495,,,,,0.000103291153127038,1.28464563996932E-8,29.990944710692,0.000186346959776216,3.44287005991911E-5,4.28194271973735E-9,2.98188496011352E-5,3.77532469062334E-9,1.72096378059975E-5,2.02038534331485E-9,3.00014671856263,60.7314987182617,12,728,1,3,0.267995318975661,0.211821800193943,0.012385887093842,131.206207275391,3.59576654434204,3.6016092300415,1000.30139160156,1000.30139160156,,,3.36577177047729,0,1,,,,,,1,1,1,3.60018563270569,0,0,3.59998908118596,,,,,,,,,,,,,,,,,,,,,,,,,,,,,,,,,
,3825446532.98523,3.59964954853058,1000.30139160156,,,5,,,,24.2400001734495,,,,,2.97415143259002E-5,8.8653684961397E-9,57.3631912260681,0.00708820487269071,9.91340047155799E-6,2.95499238092365E-9,5.34641478532044E-6,2.15977172617296E-9,8.34813499248744E-6,2.0167711972707E-9,3.00013243802971,466.139617919922,12,5593,1,3,0.0402817707803354,0.0897756490605241,0.00540306605398655,120.660614013672,3.59858798980713,3.60165214538574,1000.30139160156,1000.30139160156,,,3.36535286903381,0,1,,,,,,1,1,1,3.59974050521851,0,0,3.59999019002158,,,,,,,,,,,,,,,,,,,,,,,,,,,,,,,,,
,3825447553.73537,3.79991495609283,1000.30139160156,,,5,,,,24.2400001734495,,,,,0.000122381822318109,1.49970262025541E-7,1.15924753061743,0.00100589690334877,4.07939532298062E-5,4.99901026071454E-8,4.07856037757996E-5,2.85282413878966E-8,8.25314945399075E-7,4.10505761468317E-8,2.99999908390075,2.22107553482056,14.4074343705674,31,1,3,0.405454287849895,0.0194728470113134,0.0260889418423176,176.344985961914,3.79867458343506,3.80235409736633,1000.30139160156,1000.30139160156,,,3.44721746444702,0,1,,,,,,1,1,1,3.79999709129334,0,0,3.79999646206492,,,,,,,,,,,,,,,,,,,,,,,,,,,,,,,,,
,3825448167.72866,3.79962289333343,1000.30139160156,,,5,,,,24.2400001734495,,,,,0.000120820014889995,4.49461013577925E-8,7.6244766079734,0.000170766682754033,4.02750723541462E-5,1.49826788704674E-8,3.99189984345751E-5,1.38126831859022E-8,5.34368946628658E-6,5.80434745181967E-9,2.99987083393921,17.0014362335205,12,204,1,3,0.385489382951786,0.107728693849851,0.0227452889084816,154.613632202148,3.79877758026123,3.80189347267151,1000.30139160156,1000.30139160156,,,3.44752836227417,0,1,,,,,,1,1,1,3.79984164237976,0,0,3.80000414545574,,,,,,,,,,,,,,,,,,,,,,,,,,,,,,,,,
,3825448687.39971,3.79961585998535,1000.30139160156,,,5,,,,24.2400001734495,,,,,8.37884128334515E-5,8.95555028233341E-9,39.0018342299546,0.000247248027180108,2.79311689186369E-5,2.98536491188118E-9,2.17060323931396E-5,2.34504059556717E-9,1.75783490382175E-5,1.84748159997152E-9,2.99981762587617,130.20832824707,12,1562,1,3,0.195084830438411,0.196658983866397,0.00753101753070951,128.613830566406,3.79902672767639,3.80133843421936,1000.30139160156,1000.30139160156,,,3.44865441322327,0,1,,,,,,1,1,1,3.79992508888245,0,0,3.80001229331607,,,,,,,,,,,,,,,,,,,,,,,,,,,,,,,,,
,3825449233.95524,3.79996705055237,1000.30139160156,,,5,,,,24.2400001734495,,,,,5.57014033439376E-5,1.30712804942727E-6,-75.3800429250601,0.214463677439006,1.85674866803992E-5,4.35717615541161E-7,4.68655269615989E-6,3.14413290271208E-7,-1.79662958189193E-5,3.01652322042626E-7,2.99994308883705,999.040954589844,12,11988,1000,3,0.0942827413214274,-0.158611062432842,0.00715677021071315,89.7015380859375,3.79667592048645,3.80395293235779,1000.30139160156,1000.30139160156,,,3.44918131828308,0,1,,,,,,1,1,1,3.79984474182129,0,0,3.80005516269343,,,,,,,,,,,,,,,,,,,,,,,,,,,,,,,,,
,3825450288.8927,4.20000243186951,1000.30139160156,,,5,,,,24.2400001734495,,,,,0.000111683688116438,1.80870942507978E-7,1.24404185479114,0.00136126634695002,3.72277864630252E-5,6.02901367121139E-8,3.7219011508472E-5,3.259787381422E-8,8.08249509021755E-7,5.07176419755254E-8,3.00000883016137,4.79836130142212,12,57,1,3,0.369329896676278,0.0280407511749318,0.0260781813412905,172.97590637207,4.19908714294434,4.20138168334961,1000.30139160156,1000.30139160156,,,3.60506558418274,0,1,,,,,,1,1,1,4.19988441467285,0,0,4.20002321653728,,,,,,,,,,,,,,,,,,,,,,,,,,,,,,,,,
,3825450846.92868,4.19950294494629,1000.30139160156,,,5,,,,24.2400001734495,,,,,0.000109673010070973,2.80888681893318E-8,8.90786788966298,0.000126300233327328,3.65608308165926E-5,9.36376558859066E-9,3.61198564334943E-5,8.66216521756074E-9,5.66130031205419E-6,3.5562620462721E-9,2.9997406410469,36.4388999938965,12,437,1,3,0.344500056732851,0.11411986414007,0.0169330183416605,138.922958374023,4.1989917755127,4.20129299163818,1000.30139160156,1000.30139160156,,,3.60614347457886,0,1,,,,,,1,1,1,4.1999077796936,0,0,4.19999582048446,,,,,,,,,,,,,,,,,,,,,,,,,,,,,,,,,
,3825451362.07564,4.19964528083801,1000.30139160156,,,5,,,,24.2400001734495,,,,,7.06207051619996E-5,7.83349991234606E-9,41.9888951039208,0.000357185739046213,2.35391883750259E-5,2.6110505360924E-9,1.74960784793858E-5,2.16747682907604E-9,1.57474006489365E-5,1.45589460382506E-9,3.00013339614229,279.817321777344,12,3357,1,3,0.155115572174448,0.174571415068915,0.00559159042313695,128.453521728516,4.1986985206604,4.2018575668335,1000.30139160156,1000.30139160156,,,3.60702753067017,0,1,,,,,,1,1,1,4.19985055923462,0,0,4.20001557516673,,,,,,,,,,,,,,,,,,,,,,,,,,,,,,,,,
,3825452353.63494,4.39991617202759,1000.30139160156,,,5,,,,24.2400001734495,,,,,0.000107463198403353,1.02424654974207E-7,0.293652897389025,0.000446318008254829,3.58211106954265E-5,3.41415941297486E-8,3.58206402259879E-5,3.01692930980989E-8,1.83589908038368E-7,1.59831850293202E-8,2.99999626804073,1.33032166957855,24.0543326713889,31,1,3,0.356348184348444,0.00835956571368868,0.0262308493256569,177.817657470703,4.39721250534058,4.40200757980347,1000.30139160156,1000.30139160156,,,3.67938232421875,0,1,,,,,,1,1,1,4.3998384475708,0,0,4.39999144846999,,,,,,,,,,,,,,,,,,,,,,,,,,,,,,,,,
,3825453058.89956,4.39969182014465,1000.30139160156,,,5,,,,24.2400001734495,,,,,0.000107491481242671,1.25818305162122E-7,2.01694115269756,0.000345022718977959,3.58314125654665E-5,4.19405105263553E-8,3.58092137257815E-5,4.02618094970366E-8,1.26108634834316E-6,1.17470472560406E-8,2.99992307158633,10.2065477371216,12,122,1,3,0.353032650917127,0.0483655627052489,0.0247994754463434,163.489288330078,4.39902925491333,4.40147066116333,1000.30139160156,1000.30139160156,,,3.67914700508118,0,1,,,,,,1,1,1,4.39992189407349,0,0,4.4000153613813,,,,,,,,,,,,,,,,,,,,,,,,,,,,,,,,,
,3825453576.455,4.39968991279602,1000.30139160156,,,5,,,,24.2400001734495,,,,,0.000102511086524539,8.72010430787864E-9,13.9479762401737,6.32247820795442E-5,3.41677642366343E-5,2.90648044237767E-9,3.31603272960879E-5,2.05412018589348E-9,8.23582458206533E-6,2.05626331578152E-9,3.00022810432025,78.3758010864258,12,940,1,3,0.315439431299944,0.124059686942869,0.0104177063331008,129.217926025391,4.39899396896362,4.40143013000488,1000.30139160156,1000.30139160156,,,3.68061208724976,0,1,,,,,,1,1,1,4.40011930465698,0,0,4.39999365428137,,,,,,,,,,,,,,,,,,,,,,,,,,,,,,,,,
,3825454083.2154,4.39971280097961,1000.30139160156,,,5,,,,24.2400001734495,,,,,5.04988892284433E-5,9.13397513639855E-9,50.0978197397837,0.00222580552243346,1.68331947020631E-5,3.04470027408443E-9,1.07981379386956E-5,2.54447323876626E-9,1.2913429479982E-5,1.67208124689326E-9,2.99995871979393,600.961547851562,12,7211,1,3,0.0825878290114077,0.14530174563986,0.00560942944139242,113.062591552734,4.39649772644043,4.40158081054687,1000.30139160156,1000.30139160156,,,3.68134450912476,0,1,,,,,,1,1,1,4.4000186920166,0,0,4.4000190023392,,,,,,,,,,,,,,,,,,,,,,,,,,,,,,,,,
,3825455198.1036,4.60045838356018,1000.30139160156,,,5,,,,24.2400001734495,,,,,0.000102775573987553,1.08090490267011E-7,0.432169026050133,0.00057015083714529,3.42584432358233E-5,3.6030077784758E-8,3.42574687005137E-5,3.02815674969082E-8,2.58401190886685E-7,1.95241689991125E-8,3.0000071305074,2.90091037750244,12,34,1,3,0.340576301180007,0.0144505023347178,0.0260683204978704,175.224563598633,4.59708833694458,4.60171556472778,1000.30139160156,1000.30139160156,,,3.75015783309937,0,1,,,,,,1,1,1,4.60044384002686,0,0,4.59999766945839,,,,,,,,,,,,,,,,,,,,,,,,,,,,,,,,,
,3825455788.86783,4.59986662864685,1000.30139160156,,,5,,,,24.2400001734495,,,,,0.000103165541109618,3.89094090651512E-8,3.30179643438919,0.000130328315083278,3.43861695561302E-5,1.29689189147129E-8,3.43290889024873E-5,1.23472285090052E-8,1.98048273611783E-6,3.96721639979562E-9,3.0002045136553,21.9156761169434,12,262,1,3,0.333967584242278,0.0719902487030704,0.0211408101022243,149.396301269531,4.59893655776978,4.6013331413269,1000.30139160156,1000.30139160156,,,3.75110363960266,0,1,,,,,,1,1,1,4.60023927688599,0,0,4.59999714957343,,,,,,,,,,,,,,,,,,,,,,,,,,,,,,,,,
,3825456304.35988,4.59959506988525,1000.30139160156,,,5,,,,24.2400001734495,,,,,9.28521428304188E-5,7.79380459463975E-9,21.4648820164494,7.0797969416354E-5,3.09490307847776E-5,2.59779355626271E-9,2.88024688595691E-5,1.48122991329066E-9,1.13252061398751E-5,2.13412495063738E-9,3.00016318689012,168.083053588867,12,2016,1,3,0.272511285286684,0.141323064632044,0.00659360317513347,129.216751098633,4.59869718551636,4.60140419006348,1000.30139160156,1000.30139160156,,,3.75237631797791,0,1,,,,,,1,1,1,4.599853515625,0,0,4.60000355281527,,,,,,,,,,,,,,,,,,,,,,,,,,,,,,,,,
,3825457040.86338,4.80000638961792,1000.30139160156,,,5,,,,24.2400001734495,,,,,9.94321250129425E-5,1.66548413360412E-7,0.0187779401920415,0.000504564800802311,3.31441056620024E-5,5.55162449715102E-8,3.3144103881974E-5,5.29377427976006E-8,1.08625456881326E-8,1.67227044233826E-8,2.99999420792744,0.800566077232361,39.971716151935,32,1,3,0.329782137494523,0.00428934751145564,0.0263225212693214,178.435852050781,4.798828125,4.80191659927368,1000.30139160156,1000.30139160156,,,3.81971025466919,0,1,,,,,,1,1,1,4.79999494552612,0,0,4.8000050561618,,,,,,,,,,,,,,,,,,,,,,,,,,,,,,,,,
,3825457912.29271,4.80003690719604,1000.30139160156,,,5,,,,24.2400001734495,,,,,9.87404556406399E-5,1.78226026158708E-7,0.716173061864493,0.000853341452585843,3.29136445563035E-5,5.94089629991113E-8,3.29110733849391E-5,5.23890840640499E-8,4.11395952632181E-7,2.80144383409643E-8,2.99998547628873,6.14035797119141,12,73,1,3,0.32640504433492,0.0259756431399197,0.0256140138953924,169.834777832031,4.79879236221313,4.80174589157105,1000.30139160156,1000.30139160156,,,3.81917238235474,0,1,,,,,,1,1,1,4.80002593994141,0,0,4.79999933967108,,,,,,,,,,,,,,,,,,,,,,,,,,,,,,,,,
,3825458457.22361,4.79978823661804,1000.30139160156,,,5,,,,24.2400001734495,,,,,9.82420113736698E-5,1.18701816594914E-8,5.37529327348933,7.43531467230429E-5,3.27488903863758E-5,3.95691489412278E-9,3.26048755964032E-5,3.17626670305168E-9,3.06788345312055E-6,2.35976806284345E-9,2.99985771165366,47.1313934326172,12,565,1,3,0.314772241653941,0.080815841784996,0.014562526717782,134.442169189453,4.79915380477905,4.80136060714722,1000.30139160156,1000.30139160156,,,3.82005906105041,0,1,,,,,,1,1,1,4.8002028465271,0,0,4.80000481238732,,,,,,,,,,,,,,,,,,,,,,,,,,,,,,,,,
,3825458968.01652,4.7995982170105,1000.30139160156,,,5,,,,24.2400001734495,,,,,7.76942408658738E-5,5.26402582822661E-9,30.9510367500628,8.29271170544984E-5,2.58971589804421E-5,1.75461285458825E-9,2.22095880253942E-5,1.16955293214492E-9,1.33190481266703E-5,1.307980201837E-9,3.00010672694057,361.021270751953,12,4332,1,3,0.2021022020448,0.158715491892322,0.0053746928460896,125.717956542969,4.79721832275391,4.8014121055603,1000.30139160156,1000.30139160156,,,3.82106137275696,0,1,,,,,,1,1,1,4.80021715164185,0,0,4.80006958189465,,,,,,,,,,,,,,,,,,,,,,,,,,,,,,,,,
,3825460047.48276,5.19995045661926,1000.30139160156,,,5,,,,24.2400001734495,,,,,9.20045480115229E-5,9.52576737653031E-8,0.0182103930244824,0.000612179144778721,3.06682082661275E-5,3.17525844224055E-8,3.06682067171262E-5,2.56076587651015E-8,9.74731683950126E-9,1.87743023857641E-8,2.99999749620654,1.72026944160461,18.6017371616806,30,1,3,0.305089650075375,0.0069536824206796,0.0261920522898436,176.895629882813,5.19750070571899,5.20177221298218,1000.30139160156,1000.30139160156,,,3.94638991355896,0,1,,,,,,1,1,1,5.19994878768921,0,0,5.20001766941335,,,,,,,,,,,,,,,,,,,,,,,,,,,,,,,,,
,3825460704.44357,5.19975090026855,1000.30139160156,,,5,,,,24.2400001734495,,,,,9.23781131213939E-5,5.32235373094686E-8,0.996446069068612,0.000239298971932712,3.07921240677455E-5,1.77408447605312E-8,3.07874675524092E-5,1.61802426575527E-8,5.35486986567863E-7,7.27580376040874E-9,3.00005653777419,13.2110729217529,12,158,1,3,0.303224706107107,0.0421621237027337,0.0239077210426331,159.281921386719,5.19912481307983,5.20167255401611,1000.30139160156,1000.30139160156,,,3.94756078720093,0,1,,,,,,1,1,1,5.20014715194702,0,0,5.19999977142092,,,,,,,,,,,,,,,,,,,,,,,,,,,,,,,,,
,3825461220.50406,5.1996431350708,1000.30139160156,,,5,,,,24.2400001734495,,,,,9.13231920028426E-5,1.08109137087565E-8,7.20556851475183,6.60816119310673E-5,3.04390325077642E-5,3.60339741310432E-9,3.01986407242255E-5,3.05771368615992E-9,3.81795736197685E-6,1.90653086265007E-9,3.00020021922669,101.09342956543,12,1213,1,3,0.292985480493129,0.0729521901775876,0.00878495816141367,128.451950073242,5.19901323318481,5.2020206451416,1000.30139160156,1000.30139160156,,,3.94860029220581,0,1,,,,,,1,1,1,5.19990301132202,0,0,5.1999934590052,,,,,,,,,,,,,,,,,,,,,,,,,,,,,,,,,
,3825461733.49565,5.19989228248596,1000.30139160156,,,5,,,,24.2400001734495,,,,,6.44794087470065E-5,3.43444148953199E-8,35.803580949574,0.00183387108899513,2.14931425822385E-5,1.14481416717851E-8,1.74315244926579E-5,9.85132492225983E-9,1.25736681967636E-5,5.83192464057315E-9,2.99999911601065,775.049621582031,12,9300,1,3,0.141234273568341,0.16009962727724,0.006133824121207,102.759643554688,5.19652938842773,5.20226335525513,1000.30139160156,1000.30139160156,,,3.94920825958252,0,1,,,,,,1,1,1,5.20000791549683,0,0,5.20003399016365,,,,,,,,,,,,,,,,,,,,,,,,,,,,,,,,,
,3825462859.30225,5.40000534057617,1000.30139160156,,,5,,,,24.2400001734495,,,,,8.85972323679416E-5,1.5570825655694E-7,0.20296408558294,0.00136200022442957,2.95324099283055E-5,5.19027506724378E-8,2.9532224634216E-5,3.28000219538003E-8,1.04615140784847E-7,4.02250430353463E-8,3.00000008746409,3.70358967781067,12,44,1,3,0.293526218314524,0.0137041057321019,0.0259839948266745,173.820739746094,5.39892148971558,5.40148448944092,1000.30139160156,1000.30139160156,,,4.00770616531372,0,1,,,,,,1,1,1,5.39991617202759,0,0,5.39998928512015,,,,,,,,,,,,,,,,,,,,,,,,,,,,,,,,,
,3825463434.30083,5.39987421035767,1000.30139160156,,,5,,,,24.2400001734495,,,,,8.8994668456486E-5,2.92453237824904E-8,1.72394403087815,0.000133136226702591,2.96624953046598E-5,9.74765448792626E-9,2.96490693251125E-5,8.98086853856415E-9,8.92365314001543E-7,3.78956043744096E-9,3.00024214222145,28.3225784301758,12,339,1,3,0.289083480314365,0.056705560799616,0.0191403329372406,144.020660400391,5.39878463745117,5.40157747268677,1000.30139160156,1000.30139160156,,,4.00884056091309,0,1,,,,,,1,1,1,5.40022230148315,0,0,5.39999752196055,,,,,,,,,,,,,,,,,,,,,,,,,,,,,,,,,
,3825463949.47884,5.39971351623535,1000.30139160156,,,5,,,,24.2400001734495,,,,,8.62298529199778E-5,6.64596341833788E-9,12.1495194431035,5.93129501824259E-5,2.87420438911733E-5,2.21522553733528E-9,2.80982710562928E-5,1.42251177630913E-9,6.04915289021796E-6,1.69814146275398E-9,3.00012947048831,217.013900756836,12,2604,1,3,0.270941438538414,0.0887446532829967,0.00595419574528933,129.444076538086,5.39888668060303,5.40151977539063,1000.30139160156,1000.30139160156,,,4.01000261306763,0,1,,,,,,1,1,1,5.39997529983521,0,0,5.39998956710573,,,,,,,,,,,,,,,,,,,,,,,,,,,,,,,,,
,3825464946.71866,5.59986519813538,1000.30139160156,,,5,,,,24.2400001734495,,,,,8.59902947820759E-5,7.29905119727851E-8,-0.0357160871965173,0.000669430114410126,2.86635295764198E-5,2.43302538272731E-8,2.86635240073566E-5,1.49591375201704E-8,-1.78677917310802E-8,1.91881592643007E-8,2.99998974490623,1.03099930286407,31.0378483390874,31,1,3,0.28519361336477,0.00414011289548449,0.0263671893626451,177.902572631836,5.59906435012817,5.60142517089844,1000.30139160156,1000.30139160156,,,4.06584405899048,0,1,,,,,,1,1,1,5.59976863861084,0,0,5.60001462300618,,,,,,,,,,,,,,,,,,,,,,,,,,,,,,,,,
,3825465717.72989,5.60012888908386,1000.30139160156,,,5,,,,24.2400001734495,,,,,8.60556101344341E-5,1.13375990178944E-7,0.360544775394457,0.000474106666658897,2.86856614427952E-5,3.77926002143758E-8,2.86850934973929E-5,3.52817012410175E-8,1.80508882035542E-7,1.35455597338469E-8,2.99995209474412,7.92664384841919,12,95,1,3,0.284198051571749,0.025398725898321,0.0253797266632318,166.988235473633,5.59905242919922,5.6015625,1000.30139160156,1000.30139160156,,,4.06642866134644,0,1,,,,,,1,1,1,5.60012769699097,0,0,5.60000661015511,,,,,,,,,,,,,,,,,,,,,,,,,,,,,,,,,
,3825466245.93981,5.59968662261963,1000.30139160156,,,5,,,,24.2400001734495,,,,,8.5673229435948E-5,8.03822698467199E-9,2.87243842220728,6.04034932154317E-5,2.85600258303549E-5,2.67962316611542E-9,2.85241424105306E-5,2.06263582306773E-9,1.43121458010661E-6,1.71053026099515E-9,2.99976022237664,60.7314987182617,12,728,1,3,0.277934787153403,0.0550492860049861,0.0123708294704556,131.239364624023,5.59894514083862,5.60149908065796,1000.30139160156,1000.30139160156,,,4.06749153137207,0,1,,,,,,1,1,1,5.60003280639648,0,0,5.59999910233513,,,,,,,,,,,,,,,,,,,,,,,,,,,,,,,,,
,3825466759.35082,5.59965443611145,1000.30139160156,,,5,,,,24.2400001734495,,,,,7.78547105962436E-5,7.42639882713215E-9,19.524802425615,7.74472598699222E-5,2.59526271637274E-5,2.47556709740056E-9,2.44602707299434E-5,1.99383205267966E-9,8.67375423431624E-6,1.46733302267735E-9,2.99987781988626,466.139617919922,12,5593,1,3,0.227448884201746,0.1208858428707,0.00536501500755548,120.723785400391,5.59915399551392,5.60169124603271,1000.30139160156,1000.30139160156,,,4.06826782226562,0,1,,,,,,1,1,1,5.60002088546753,0,0,5.60004107426789,,,,,,,,,,,,,,,,,,,,,,,,,,,,,,,,,
,3825467797.4988,5.79985046386719,1000.30139160156,,,5,,,,24.2400001734495,,,,,8.29915365780087E-5,9.31257712988493E-8,-0.0207844414804996,0.000543755389936022,2.76638704424958E-5,3.10419517253705E-8,2.76638686223156E-5,2.71536561182445E-8,-1.00352606878211E-8,1.50426635384946E-8,2.99999729793852,2.22107553482056,14.4074343705674,31,1,3,0.275166846369997,0.00753991654354635,0.0261694267392158,176.129486083984,5.79901456832886,5.80181503295898,1000.30139160156,1000.30139160156,,,4.12138414382935,0,1,,,,,,1,1,1,5.79990720748901,0,0,5.80001054639402,,,,,,,,,,,,,,,,,,,,,,,,,,,,,,,,,
,3825468416.75674,5.79962944984436,1000.30139160156,,,5,,,,24.2400001734495,,,,,8.3366882697091E-5,4.09998004372767E-8,0.700333378312621,0.000173174929430791,2.77896286632825E-5,1.3666928551958E-8,2.77875527379571E-5,1.28262892293777E-8,3.3966759983931E-7,4.71924153319945E-9,2.99992791221572,17.0014362335205,12,204,1,3,0.273012604262963,0.0417239393001174,0.022682199254632,154.583282470703,5.79899454116821,5.80161428451538,1000.30139160156,1000.30139160156,,,4.12229061126709,0,1,,,,,,1,1,1,5.79994344711304,0,0,5.79999834393698,,,,,,,,,,,,,,,,,,,,,,,,,,,,,,,,,
,3825468932.64578,5.79984784126282,1000.30139160156,,,5,,,,24.2400001734495,,,,,8.32468824756888E-5,1.05847323936687E-8,5.06610866827048,9.93149234637773E-5,2.77473325246564E-5,3.52803709493144E-9,2.76389368346823E-5,2.19246081870286E-9,2.45023118956051E-6,2.7640841705102E-9,3.00017604941719,130.20832824707,12,1562,1,3,0.269888145982263,0.0538936052813507,0.00751894852146506,128.672058105469,5.7990894317627,5.80146217346191,1000.30139160156,1000.30139160156,,,4.12343835830688,0,1,,,,,,1,1,1,5.80023622512817,0,0,5.80000953825693,,,,,,,,,,,,,,,,,,,,,,,,,,,,,,,,,
,3825469488.64659,5.80028986930847,1000.30139160156,,,5,,,,24.2400001734495,,,,,6.86682554467763E-5,1.83045004750344E-6,33.8732045478685,0.113286956663613,2.28903464727983E-5,6.10174752742621E-7,1.90052374230595E-5,5.58878577503202E-7,1.27580920257649E-5,2.4488357334153E-7,2.999878377917,999.040954589844,12,11988,1000,3,0.146308621402293,0.174168699288129,0.00715141277760267,89.7952880859375,5.79828214645386,5.8018913269043,1000.30139160156,1000.30139160156,,,4.1237621307373,0,1,,,,,,1,1,1,5.79987144470215,0,0,5.80001414031313,,,,,,,,,,,,,,,,,,,,,,,,,,,,,,,,,
,3825470569.02906,6.00015473365784,1000.30139160156,,,5,,,,24.2400001734495,,,,,8.01704323365775E-5,9.92291601594457E-8,0.0825737311306809,0.000813870802549628,2.67235137716598E-5,3.30764316816753E-8,2.67234860191641E-5,2.49210217089547E-8,3.85134733469937E-8,2.17484024648787E-8,2.99999592200327,4.79836130142212,12,57,1,3,0.265471386425088,0.0147502683231958,0.0258304439485073,172.354629516602,5.9990086555481,6.00136661529541,1000.30139160156,1000.30139160156,,,4.17618846893311,0,1,,,,,,1,1,1,6.00012874603271,0,0,6.00002353619306,,,,,,,,,,,,,,,,,,,,,,,,,,,,,,,,,
,3825471131.07585,5.99970936775208,1000.30139160156,,,5,,,,24.2400001734495,,,,,8.05545846999501E-5,2.14484879465398E-8,1.20352324227018,0.000116031112912859,2.6849185026557E-5,7.14887207924345E-9,2.68432619295961E-5,6.47030523647398E-9,5.63937558056867E-7,3.03998719606579E-9,3.00026181875808,36.4388999938965,12,437,1,3,0.261987897258329,0.04913998083621,0.0169135797768831,138.974746704102,5.99909400939941,6.00128507614136,1000.30139160156,1000.30139160156,,,4.17719411849976,0,1,,,,,,1,1,1,6.00005769729614,0,0,6.00001644709754,,,,,,,,,,,,,,,,,,,,,,,,,,,,,,,,,
,3825471641.84375,5.99959945678711,1000.30139160156,,,5,,,,24.2400001734495,,,,,7.93960188815905E-5,6.66887008205587E-9,8.89881763346413,6.22983851743011E-5,2.64665378410797E-5,2.22305733801599E-9,2.61479616652221E-5,1.49982438068272E-9,4.0941086999954E-6,1.64088718540199E-9,2.99986418164438,279.817321777344,12,3357,1,3,0.253261553562491,0.0692076744552275,0.00559259857982397,128.498794555664,5.99892044067383,6.00159645080566,1000.30139160156,1000.30139160156,,,4.17824935913086,0,1,,,,,,1,1,1,5.99990367889404,0,0,6.0000313425821,,,,,,,,,,,,,,,,,,,,,,,,,,,,,,,,,
,3825472033.05697,6.00014805793762,1000.30139160156,,,5,,,,24.2400001734495,,,,,0.000313453627797441,1.03112776610991E-6,62.9159944607784,1.88421530021198,0.000104488839716474,3.43723391039802E-7,4.75733906027537E-5,2.61672125914348E-7,9.30305870767934E-5,2.22875454160763E-7,2.99987662460397,999.040954589844,12,11988,1000,3,0.197947317625589,1.01928209009721,0.00715712644159794,89.793701171875,5.99840974807739,6.00202178955078,1000.30139160156,1000.30139160156,,,4.17838621139526,0,1,,,,,,1,1,1,6.00008201599121,0,0,5.99999814973751,,,,,,,,,,,,,,,,,,,,,,,,,,,,,,,,,