File: data/AP498/ac_4000.csv
[Data]

Comment,Time Stamp (sec),Temperature (K),Magnetic Field (Oe),Moment (emu),M. Std. Err. (emu),Transport Action,Averaging Time (sec),Frequency (Hz),Peak Amplitude (mm),Center Position (mm),Lockin Signal' (V),Lockin Signal (V),Range,M. Quad. Signal (emu),AC Moment (emu),AC M. Std Err. (emu),AC Phase (deg),AC Phase Std. Err. (deg),AC Susceptibility (emu/Oe),AC Suscept. Std Err. (emu/Oe),AC X' (emu/Oe),AC X' Std Err. (emu/Oe),AC X'' (emu/Oe),AC X'' Std Err. (emu/Oe),AC Drive (Oe),AC Frequency (Hz),AC Averaging Time (sec),AC Cycles,AC Range,AC Measure Type,AC Signal' (V),AC Signal'' (V),AC Trim Coil Ratio,AC Trim Coil Phase,Min. Temperature (K),Max. Temperature (K),Min. Field (Oe),Max. Field (Oe),Mass (grams),Motor Lag (deg),Pressure (Torr),Measure Count,Measurement Number,SQUID Status (code),Motor Status (code),Measure Status (code),Motor Current (amps),Motor Temp. (C),Temp. Status (code),Field Status (code),Chamber Status (code),Chamber Temp (K),Redirection State,Evercool Status,Average Temp (K),Rotation Angle (deg),Rotator state,DC Moment Fixed Ctr (emu),DC Moment Err Fixed Ctr (emu),DC Moment Free Ctr (emu),DC Moment Err Free Ctr (emu),DC Fixed Fit,DC Free Fit,DC Calculated Center (mm),DC Calculated Center Err (mm),DC Scan Length (mm),DC Scan Time (s),DC Number of Points,DC Squid Drift,DC Min V (V),DC Max V (V),DC Scans per Measure,Map 01,Map 02,Map 03,Map 04,Map 05,Map 06,Map 07,Map 08,Map 09,Map 10,Map 11,Map 12,Map 13,Map 14,Map 15,Map 16

,3825482774.81998,1.80000019073486,4000.47412109375,,,5,,,,24.2400001734495,,,,,7.74748536829874E-5,2.86322681039923E-6,17.442913523405,0.0201149610925303,2.58250204493364E-5,9.54411495015001E-7,2.46374848946042E-5,8.54613243144271E-7,7.74118978431577E-6,4.24897053954483E-7,2.99999195876641,0.600503325462341,53.288630792115,32,1,3,0.2442078352858,0.0801500463052006,0.0264395363628864,177.69905090332,1.79880225658417,1.80255496501923,4000.47412109375,4000.47412109375,,,2.34304761886597,0,1,,,,,,1,1,1,1.79999446868896,0,0,1.8000024146721,,,,,,,,,,,,,,,,,,,,,,,,,,,,,,,,,

,3825482994.96119,1.80034345388412,4000.47412109375,,,5,,,,24.2400001734495,,,,,7.19758999701438E-5,4.47574900741339E-6,19.6806490401037,0.0325617807767769,2.39920451019108E-5,1.49192121384016E-6,2.25905339760612E-5,1.41595367926791E-6,8.07997542375895E-6,4.70004347292608E-7,2.99999019109928,0.800566077232361,39.971716151935,32,1,3,0.223615234368807,0.0837415003937102,0.027147863060236,178.997253417969,1.79809904098511,1.80180084705353,4000.47412109375,4000.47412109375,,,2.34206008911133,0,1,,,,,,1,1,1,1.80032217502594,0,0,1.79999088062035,,,,,,,,,,,,,,,,,,,,,,,,,,,,,,,,,

,3825483173.4674,1.80007112026215,4000.47412109375,,,5,,,,24.2400001734495,,,,,6.83611252237717E-5,2.99248090515919E-6,20.1872030988047,0.0227203023996659,2.27870031248896E-5,9.97491944637021E-7,2.13872002809228E-5,9.64752183855208E-7,7.86353454608208E-6,2.53462824418797E-7,3.00000508399908,1.02065479755402,31.3524220693299,31,1,3,0.211480918794054,0.0819075959301893,0.0269244778901339,179.7353515625,1.79769098758698,1.8015501499176,4000.47412109375,4000.47412109375,,,2.34103155136108,0,1,,,,,,1,1,1,1.80020880699158,0,0,1.8000065569846,,,,,,,,,,,,,,,,,,,,,,,,,,,,,,,,,

,3825483314.23948,1.79998004436493,4000.47412109375,,,5,,,,24.2400001734495,,,,,6.36677234233743E-5,1.52911559334386E-6,21.3107189481686,0.0134594490006816,2.12225731055945E-5,5.0970516490512E-7,1.97714426127815E-5,4.92230589494751E-7,7.71282478938749E-6,1.3231931792677E-7,3.00000019350108,1.33032166957855,24.0543326713889,31,1,3,0.195161450289442,0.0807756943459059,0.0264182295650244,178.920654296875,1.79830265045166,1.8016574382782,4000.47412109375,4000.47412109375,,,2.34110260009766,0,1,,,,,,1,1,1,1.79977309703827,0,0,1.80001524657257,,,,,,,,,,,,,,,,,,,,,,,,,,,,,,,,,

,3825483432.01367,1.79994636774063,4000.47412109375,,,5,,,,24.2400001734495,,,,,6.02671950383265E-5,4.98853161245399E-7,21.8987562639293,0.00509475920894791,2.00891033202494E-5,1.66284704166483E-7,1.86395610169621E-5,1.55094600538538E-7,7.49258548877503E-6,5.99688896305913E-8,2.9999942793653,1.73002147674561,18.4968802006991,31,1,3,0.183607648535484,0.079132787550177,0.0268196482211351,177.153305053711,1.79878401756287,1.80168175697327,4000.47412109375,4000.47412109375,,,2.34084010124207,0,1,,,,,,1,1,1,1.80007421970367,0,0,1.79999437869764,,,,,,,,,,,,,,,,,,,,,,,,,,,,,,,,,

,3825483537.40648,1.80001294612885,4000.47412109375,,,5,,,,24.2400001734495,,,,,5.5424432523968E-5,5.45546761912331E-7,22.2202854090081,0.00815422351674507,1.84748317659353E-5,1.81849126599943E-7,1.71028307771317E-5,9.97078923522838E-8,6.98660061749696E-6,1.52077089161476E-7,2.99999660219706,2.30147647857666,13.9041177686901,32,1,3,0.167992781753995,0.0747334723447359,0.0266353413462639,176.023010253906,1.79867386817932,1.80222690105438,4000.47412109375,4000.47412109375,,,2.3407461643219,0,1,,,,,,1,1,1,1.79998314380646,0,0,1.80001006227859,,,,,,,,,,,,,,,,,,,,,,,,,,,,,,,,,

,3825483624.98154,1.79984557628632,4000.47412109375,,,5,,,,24.2400001734495,,,,,5.18150602847575E-5,4.17818848802825E-7,22.2762745439686,0.0061302509682604,1.72717056649152E-5,1.39273102030897E-7,1.59826624324954E-5,1.0208499169523E-7,6.54723744371345E-6,9.47399146078011E-8,2.99999671659596,2.94003653526306,12,35,1,3,0.156510638518457,0.0710632182791141,0.0276710633188486,174.392272949219,1.79898250102997,1.80234658718109,4000.47412109375,4000.47412109375,,,2.34046864509583,0,1,,,,,,1,1,1,1.79990494251251,0,0,1.79999831576406,,,,,,,,,,,,,,,,,,,,,,,,,,,,,,,,,

,3825483711.46007,1.80005049705505,4000.47412109375,,,5,,,,24.2400001734495,,,,,4.82537117948287E-5,1.12723705758114E-6,22.4926748303972,0.0163663254999839,1.60845665976478E-5,3.75745592403183E-7,1.48609886918813E-5,3.32719943886225E-7,6.1533972514329E-6,1.74591492206139E-7,3.000000746174,3.82425808906555,12,45,1,3,0.144885305901369,0.0680431726857787,0.0272642206400633,173.449478149414,1.79877436161041,1.80189430713654,4000.47412109375,4000.47412109375,,,2.3404393196106,0,1,,,,,,1,1,1,1.80001485347748,0,0,1.79999397642472,,,,,,,,,,,,,,,,,,,,,,,,,,,,,,,,,

,3825483800.04791,1.79994648694992,4000.47412109375,,,5,,,,24.2400001734495,,,,,4.53835337146812E-5,9.99087312882338E-7,23.5074576525539,0.0179122822229108,1.51278881056386E-5,3.33030062666933E-7,1.38723969151369E-5,2.27075978103145E-7,6.03403698742575E-6,2.43609365190342E-7,2.99999136679002,5.00288152694702,12,60,10,3,0.134315289526723,0.0679748298054975,0.0409845449030399,156.281036376953,1.79872155189514,1.80182886123657,4000.47412109375,4000.47412109375,,,2.3407998085022,0,1,,,,,,1,1,1,1.79991137981415,0,0,1.80000902829545,,,,,,,,,,,,,,,,,,,,,,,,,,,,,,,,,

,3825483894.96663,1.79991298913956,4000.47412109375,,,5,,,,24.2400001734495,,,,,4.1997486202479E-5,7.65894074435846E-7,22.3736046596941,0.0138343027168579,1.39991270692247E-5,2.55297386560264E-7,1.2945293629982E-5,2.15463418819085E-7,5.32868947620768E-6,1.36938930678213E-7,3.00000750009658,6.5069465637207,12,78,1,3,0.124628345059502,0.0622047741819902,0.0253859404474497,171.676940917969,1.79911553859711,1.80205178260803,4000.47412109375,4000.47412109375,,,2.34085369110107,0,1,,,,,,1,1,1,1.79994690418243,0,0,1.80001096315281,,,,,,,,,,,,,,,,,,,,,,,,,,,,,,,,,

,3825483975.29498,1.79996913671494,4000.47412109375,,,5,,,,24.2400001734495,,,,,3.966714677193E-5,6.96406457753639E-7,22.2902880048712,0.0137562614239325,1.32221885143201E-5,2.32132084516966E-7,1.22341475899242E-5,1.98531891021217E-7,5.01516718127827E-6,1.20292946217688E-7,3.00004395860556,8.50071811676025,12,102,1,3,0.116744821883993,0.0606061928975692,0.0262742936611176,170.653854370117,1.7989274263382,1.802090883255,4000.47412109375,4000.47412109375,,,2.34087038040161,0,1,,,,,,1,1,1,1.80001103878021,0,0,1.79999840259552,,,,,,,,,,,,,,,,,,,,,,,,,,,,,,,,,

,3825484051.55222,1.79969030618668,4000.47412109375,,,5,,,,24.2400001734495,,,,,3.70602247185037E-5,1.14872342867509E-6,22.2111183890872,0.0248673014173175,1.23530657539188E-5,3.82897193831786E-7,1.14364342599444E-5,3.73200590368156E-7,4.66971144061516E-6,8.56246482802461E-8,3.00008317423121,11.0973014831543,12,133,1,3,0.107992700318111,0.0585935184975461,0.0246412809938192,162.232482910156,1.79911744594574,1.80221402645111,4000.47412109375,4000.47412109375,,,2.34005856513977,0,1,,,,,,1,1,1,1.80001902580261,0,0,1.79999861966318,,,,,,,,,,,,,,,,,,,,,,,,,,,,,,,,,

,3825484114.64616,1.7996027469635,4000.47412109375,,,5,,,,24.2400001734495,,,,,3.48697362098104E-5,3.99645430766027E-7,22.066756365725,0.00986276302847992,1.16233059178553E-5,1.33215837152209E-7,1.07718611499862E-5,1.17549680752101E-7,4.36672048858946E-6,6.26780011107815E-8,2.99998438105675,14.4291152954102,12,173,1,3,0.100587165539162,0.0568999105874854,0.0237887110561132,158.356475830078,1.79887175559998,1.80209100246429,4000.47412109375,4000.47412109375,,,2.34069514274597,0,1,,,,,,1,1,1,1.7998913526535,0,0,1.79998264774199,,,,,,,,,,,,,,,,,,,,,,,,,,,,,,,,,

,3825484178.6876,1.79968470335007,4000.47412109375,,,5,,,,24.2400001734495,,,,,3.28602592366555E-5,3.60356918757029E-7,22.2968091032386,0.0101965689895635,1.09528322518635E-5,1.20112530260911E-7,1.01338982887388E-5,1.10916199806644E-7,4.15555529513918E-6,4.60935629576502E-8,3.00016091555356,18.8089847564697,12,225,1,3,0.0935181787871359,0.0557283015725378,0.0227132737636566,153.113082885742,1.79890513420105,1.801913022995,4000.47412109375,4000.47412109375,,,2.34082698822021,0,1,,,,,,1,1,1,1.80001175403595,0,0,1.80000214160435,,,,,,,,,,,,,,,,,,,,,,,,,,,,,,,,,

,3825484242.95433,1.79968494176865,4000.47412109375,,,5,,,,24.2400001734495,,,,,3.07971195460585E-5,2.09604826495378E-7,22.5984175408967,0.00682512882551686,1.02658155662701E-5,6.98690176976954E-8,9.4776147744955E-6,6.63429744276968E-8,3.94484314351523E-6,2.19155054271363E-8,2.99996813183036,24.5121116638184,12,294,1,3,0.0866190946395843,0.05383594160254,0.0207290444523096,146.841522216797,1.79892587661743,1.8016951084137,4000.47412109375,4000.47412109375,,,2.34112071990967,0,1,,,,,,1,1,1,1.79989242553711,0,0,1.80001208138844,,,,,,,,,,,,,,,,,,,,,,,,,,,,,,,,,

,3825484307.23656,1.79967784881592,4000.47412109375,,,5,,,,24.2400001734495,,,,,2.88943164487398E-5,1.2004893135946E-7,23.0071641591508,0.00429966070218631,9.6320908144887E-6,4.00190193489444E-8,8.86591568597021E-6,3.61891852696955E-8,3.76466632091411E-6,1.7084050432109E-8,2.99979692937245,31.9555797576904,12,383,1,3,0.0805908005664639,0.0515103106960459,0.0185276810079813,141.760406494141,1.79876792430878,1.80150723457336,4000.47412109375,4000.47412109375,,,2.34097242355347,0,1,,,,,,1,1,1,1.79989945888519,0,0,1.80000822506254,,,,,,,,,,,,,,,,,,,,,,,,,,,,,,,,,

,3825484371.44942,1.79966539144516,4000.47412109375,,,5,,,,24.2400001734495,,,,,2.71017791758772E-5,9.09881351201469E-8,23.4739554545552,0.0034891024346533,9.03326916823617E-6,3.03271718923792E-8,8.2856869791159E-6,2.64574212051655E-8,3.59824167475109E-6,1.48237046031812E-8,3.00021826773142,41.5912475585937,12,499,1,3,0.0753284518851938,0.0486643764441788,0.016047915443778,137.122512817383,1.79893577098846,1.80197155475616,4000.47412109375,4000.47412109375,,,2.34087085723877,0,1,,,,,,1,1,1,1.79993212223053,0,0,1.79999974038866,,,,,,,,,,,,,,,,,,,,,,,,,,,,,,,,,

,3825484435.43879,1.79962402582169,4000.47412109375,,,5,,,,24.2400001734495,,,,,2.53528227241675E-5,1.30999193483921E-7,24.2739226601638,0.00566991736185278,8.45062131105055E-6,4.36647464556438E-8,7.70350591188668E-6,4.23816844665339E-8,3.47404623001893E-6,1.05072786588547E-8,3.00011345805007,54.253475189209,12,651,1,3,0.0702881178237719,0.0457551573679689,0.0136543717235327,133.363235473633,1.79881882667542,1.80175828933716,4000.47412109375,4000.47412109375,,,2.34125852584839,0,1,,,,,,1,1,1,1.80010640621185,0,0,1.80000073569162,,,,,,,,,,,,,,,,,,,,,,,,,,,,,,,,,

,3825484498.32669,1.79970419406891,4000.47412109375,,,5,,,,24.2400001734495,,,,,2.37770541327734E-5,6.91075422166602E-8,24.8252315496934,0.00309945150750862,7.92505696227436E-6,2.30340228663949E-8,7.19272364701291E-6,2.18479950436568E-8,3.32734945459515E-6,7.29597985070899E-9,3.00023763185038,70.7653961181641,12,849,1,3,0.0661039146199809,0.0425950619916805,0.0114155262708664,130.527557373047,1.79881644248962,1.80203247070313,4000.47412109375,4000.47412109375,,,2.34125304222107,0,1,,,,,,1,1,1,1.80005192756653,0,0,1.80000083484957,,,,,,,,,,,,,,,,,,,,,,,,,,,,,,,,,

,3825484562.27556,1.79989337921143,4000.47412109375,,,5,,,,24.2400001734495,,,,,2.22417845549551E-5,4.23885771045144E-8,25.9615434830548,0.00207213816929227,7.41435799485664E-6,1.41303448367158E-8,6.66616085991179E-6,1.33474875591135E-8,3.24576706891833E-6,4.63801908834026E-9,2.99982609018667,92.1285400390625,12,1105,1,3,0.0616024790347883,0.0401851109869084,0.00960513856261969,128.624130249023,1.79860389232635,1.80182361602783,4000.47412109375,4000.47412109375,,,2.34123110771179,0,1,,,,,,1,1,1,1.8000739812851,0,0,1.80000980695089,,,,,,,,,,,,,,,,,,,,,,,,,,,,,,,,,

,3825484626.51821,1.79945880174637,4000.47412109375,,,5,,,,24.2400001734495,,,,,2.07083644572296E-5,4.60617106339686E-8,27.0544323676998,0.00235898877930743,6.90322890495747E-6,1.53548839125819E-8,6.14784184137978E-6,1.27511791996002E-8,3.13984235394396E-6,8.55452447471811E-9,2.99980845809099,119.970825195313,12,1439,1,3,0.0570620186612227,0.0378516828128017,0.0081162927672267,128.725540161133,1.79899621009827,1.80169725418091,4000.47412109375,4000.47412109375,,,2.34153032302856,0,1,,,,,,1,1,1,1.79971861839294,0,0,1.80000084165543,,,,,,,,,,,,,,,,,,,,,,,,,,,,,,,,,

,3825484690.84489,1.79974371194839,4000.47412109375,,,5,,,,24.2400001734495,,,,,1.92314960519526E-5,3.25631783280861E-8,28.4112753475701,0.00199650905345952,6.41075328046346E-6,1.08548238642048E-8,5.6386098248047E-6,9.96941828379528E-9,3.05021915058393E-6,4.29393761082268E-9,2.9998808580826,156.500396728516,12,1878,1,3,0.0523881143941578,0.0360463586981555,0.00700872857123613,129.256423950195,1.79905581474304,1.80204033851624,4000.47412109375,4000.47412109375,,,2.34149122238159,0,1,,,,,,1,1,1,1.80008018016815,0,0,1.80002066067287,,,,,,,,,,,,,,,,,,,,,,,,,,,,,,,,,

,3825484754.73288,1.79984831809998,4000.47412109375,,,5,,,,24.2400001734495,,,,,1.77094262928226E-5,1.99772446295041E-8,29.7853938917351,0.00141774485972188,5.90289021504865E-6,6.65879740525113E-9,5.1230718798389E-6,5.85012229046536E-9,2.93227682951678E-6,3.18051129078006E-9,3.00012801316797,203.875274658203,12,2446,1,3,0.0474639725723645,0.0343030649310584,0.00629463093355298,129.643585205078,1.79899108409882,1.80186700820923,4000.47412109375,4000.47412109375,,,2.34135675430298,0,1,,,,,,1,1,1,1.80016541481018,0,0,1.80000410571931,,,,,,,,,,,,,,,,,,,,,,,,,,,,,,,,,

,3825484819.12624,1.79975324869156,4000.47412109375,,,5,,,,24.2400001734495,,,,,1.62352905720964E-5,1.31920509053146E-8,31.2313962462559,0.00117034236073008,5.41201801930861E-6,4.39755709293598E-9,4.62770982702087E-6,3.94241709148686E-9,2.80610776667888E-6,1.94829563013006E-9,2.99985892770004,266.093322753906,12,3193,1,3,0.0425213425036046,0.0327880901039688,0.00578700378537178,128.836074829102,1.79886376857758,1.80192887783051,4000.47412109375,4000.47412109375,,,2.3412880897522,0,1,,,,,,1,1,1,1.80002987384796,0,0,1.80001526976389,,,,,,,,,,,,,,,,,,,,,,,,,,,,,,,,,

,3825484883.33141,1.79968070983887,4000.47412109375,,,5,,,,24.2400001734495,,,,,1.47827904670368E-5,1.65508796447592E-8,32.871871543974,0.00192827813474716,4.92777676990498E-6,5.51716135169478E-9,4.13877282058901E-6,4.95536777994921E-9,2.67461089386265E-6,2.42557200389432E-9,2.99989044903954,346.298767089844,12,4155,1,3,0.0374437626367856,0.0314527366438864,0.00552289327606559,126.298355102539,1.79870331287384,1.80165565013886,4000.47412109375,4000.47412109375,,,2.34128522872925,0,1,,,,,,1,1,1,1.7999609708786,0,0,1.80000275468069,,,,,,,,,,,,,,,,,,,,,,,,,,,,,,,,,

,3825484947.62852,1.79979252815247,4000.47412109375,,,5,,,,24.2400001734495,,,,,1.35259471131279E-5,7.36777068546186E-9,34.7806143045118,0.00103937905324124,4.50884807878759E-6,2.45603198225208E-9,3.70330746995613E-6,1.87023052855501E-9,2.57200792777816E-6,1.59195818660728E-9,2.99986756634412,451.068145751953,12,5412,1,3,0.0326343839547513,0.0306286521009265,0.00549684232100844,121.488433837891,1.79815900325775,1.80285251140594,4000.47412109375,4000.47412109375,,,2.34091186523438,0,1,,,,,,1,1,1,1.80001282691956,0,0,1.80000329017639,,,,,,,,,,,,,,,,,,,,,,,,,,,,,,,,,

,3825485014.06906,1.79965764284134,4000.47412109375,,,5,,,,24.2400001734495,,,,,1.21230613235338E-5,8.94213597012787E-9,36.2482497558279,0.00142558150506781,4.04108303074187E-6,2.9807581569617E-9,3.25898259828433E-6,1.73333995176775E-9,2.38943183318332E-6,2.42496428878849E-9,2.99995353505721,589.177978515625,12,7070,1,3,0.0276220818405976,0.0291094387606433,0.00570749351754785,113.786727905273,1.79454708099365,1.80359923839569,4000.47412109375,4000.47412109375,,,2.34036302566528,0,1,,,,,,1,1,1,1.80000483989716,0,0,1.79998170045706,,,,,,,,,,,,,,,,,,,,,,,,,,,,,,,,,

,3825485077.92592,1.79965573549271,4000.47412109375,,,5,,,,24.2400001734495,,,,,1.08655544685631E-5,4.26336525978082E-8,37.7421724421004,0.0158951755684755,3.62198606520563E-6,1.42117455731184E-8,2.8641695308541E-6,1.19316515796443E-8,2.21705118458523E-6,7.72071258479567E-9,2.99988853434373,767.436157226563,12,9209,1,3,0.0228660573135596,0.0277827424567746,0.0062297023832798,103.159057617187,1.79561269283295,1.80626022815704,4000.47412109375,4000.47412109375,,,2.34004735946655,0,1,,,,,,1,1,1,1.80003976821899,0,0,1.80000092869713,,,,,,,,,,,,,,,,,,,,,,,,,,,,,,,,,

,3825485168.48683,1.8000425696373,4000.47412109375,,,5,,,,24.2400001734495,,,,,7.77817379063379E-5,1.10117340690592E-6,-83.1974024863522,0.418888428066079,2.59281672301366E-5,3.67070844804426E-7,3.07116507681247E-6,2.7426130749815E-7,-2.5745636542624E-5,2.43970777583793E-7,2.99989340611516,999.040954589844,12,11988,1000,3,0.100861546237397,-0.237154239914232,0.00726823695003986,89.6922912597656,1.79488301277161,1.80661737918854,4000.47412109375,4000.47412109375,,,2.33962488174438,0,1,,,,,,1,1,1,1.80004787445068,0,0,1.79999834020561,,,,,,,,,,,,,,,,,,,,,,,,,,,,,,,,,

,3825485606.22916,2.19991040229797,4000.47412109375,,,5,,,,24.2400001734495,,,,,8.916914740428E-5,1.79034597677093E-6,14.7992369044882,0.0174115898201878,2.97230237935636E-5,5.96781483454211E-7,2.87370157036511E-5,2.74810958613201E-7,7.59223760698138E-6,5.29742461975535E-7,3.00000255773402,0.600503325462341,53.288630792115,32,1,3,0.285025078533053,0.0791857757143424,0.0279297307133675,178.484832763672,2.19900107383728,2.20186495780945,4000.47412109375,4000.47412109375,,,2.62762069702148,0,1,,,,,,1,1,1,2.19986057281494,0,0,2.20000759840814,,,,,,,,,,,,,,,,,,,,,,,,,,,,,,,,,

,3825485827.19166,2.19992208480835,4000.47412109375,,,5,,,,24.2400001734495,,,,,8.3131493460951E-5,1.42028797960163E-6,15.7037741282013,0.00736400851250626,2.7710579632101E-5,4.73430724274835E-7,2.66762523095385E-5,4.51749007765314E-7,7.50025241340903E-6,1.4163151016087E-7,2.99999114290083,0.800566077232361,39.971716151935,32,1,3,0.264359571717697,0.0785754917695514,0.0264882743358612,179.560531616211,2.19882869720459,2.20241928100586,4000.47412109375,4000.47412109375,,,2.62779903411865,0,1,,,,,,1,1,1,2.19988465309143,0,0,2.19999836838764,,,,,,,,,,,,,,,,,,,,,,,,,,,,,,,,,

,3825486005.99136,2.19980335235596,4000.47412109375,,,5,,,,24.2400001734495,,,,,7.96242161963389E-5,1.17147527954177E-6,16.3523997749672,0.00693031664490683,2.65413707019186E-5,3.90491249367945E-7,2.54677246756469E-5,3.66481369489773E-7,7.47257375889377E-6,1.34814026161373E-7,3.00000392182395,1.02065479755402,31.3524220693299,31,1,3,0.252153256280056,0.0787148098453245,0.0263785161077976,178.596939086914,2.19901299476624,2.20199728012085,4000.47412109375,4000.47412109375,,,2.62758636474609,0,1,,,,,,1,1,1,2.19967722892761,0,0,2.2000062983287,,,,,,,,,,,,,,,,,,,,,,,,,,,,,,,,,

,3825486149.78391,2.19997894763947,4000.47412109375,,,5,,,,24.2400001734495,,,,,7.53952068041299E-5,9.26266921972077E-7,17.0287455691394,0.00597949451062948,2.51316949298944E-5,3.08755140988344E-7,2.40298699373431E-5,2.89776584801406E-7,7.35985331672114E-6,1.06579866708331E-7,3.0000048550027,1.33032166957855,24.0543326713889,31,1,3,0.237606786794027,0.0781316069844938,0.0281242039054632,177.391738891602,2.19883346557617,2.20249009132385,4000.47412109375,4000.47412109375,,,2.62784957885742,0,1,,,,,,1,1,1,2.20004105567932,0,0,2.19999902616671,,,,,,,,,,,,,,,,,,,,,,,,,,,,,,,,,

,3825486272.18131,2.20006716251373,4000.47412109375,,,5,,,,24.2400001734495,,,,,7.09034437940684E-5,4.52961332641513E-7,17.5937841873488,0.00425444439880979,2.36344834907243E-5,1.50987125101361E-7,2.25289442513239E-5,1.18769625719575E-7,7.14391214910003E-6,9.3224932034333E-8,2.99999971744234,1.73002147674561,18.4968802006991,31,1,3,0.222390643212454,0.076620877323504,0.0267151184380054,175.52001953125,2.19803810119629,2.20290184020996,4000.47412109375,4000.47412109375,,,2.62804388999939,0,1,,,,,,1,1,1,2.2000253200531,0,0,2.19998934112977,,,,,,,,,,,,,,,,,,,,,,,,,,,,,,,,,

,3825486377.39759,2.19994330406189,4000.47412109375,,,5,,,,24.2400001734495,,,,,6.67328863194033E-5,4.97102040731329E-7,17.4712173564777,0.0043096791612594,2.22443422088753E-5,1.65701028632757E-7,2.12181637790492E-5,1.45695749726291E-7,6.67834456665675E-6,7.89276846337687E-8,2.99999369245351,2.30147647857666,13.9041177686901,32,1,3,0.209024321184931,0.0729264286299442,0.0267813540995121,176.586822509766,2.19912576675415,2.20184731483459,4000.47412109375,4000.47412109375,,,2.6282696723938,0,1,,,,,,1,1,1,2.19999766349792,0,0,2.20000614914843,,,,,,,,,,,,,,,,,,,,,,,,,,,,,,,,,

,3825486462.63658,2.20008826255798,4000.47412109375,,,5,,,,24.2400001734495,,,,,6.32662538279146E-5,5.8456643571768E-7,17.5617415416052,0.00672961393686538,2.10887096393996E-5,1.94855093859685E-7,2.01058146220719E-5,1.38722318740953E-7,6.36316687175399E-6,1.36837954845138E-7,3.0000059230611,2.94003653526306,12,35,1,3,0.197584720841548,0.0707679486280409,0.0261931642889977,176.544036865234,2.19872570037842,2.20171117782593,4000.47412109375,4000.47412109375,,,2.62840104103088,0,1,,,,,,1,1,1,2.20015525817871,0,0,2.2000121617619,,,,,,,,,,,,,,,,,,,,,,,,,,,,,,,,,

,3825486542.12366,2.19976854324341,4000.47412109375,,,5,,,,24.2400001734495,,,,,6.01078957267604E-5,1.14799805768652E-6,17.5779713338048,0.0155777320406758,2.00359652707354E-5,3.82666019772818E-7,1.91004229454659E-5,2.15310675126328E-7,6.05092948516482E-6,3.16345690448622E-7,2.99999999573537,3.82425808906555,12,45,1,3,0.187076332406734,0.068985197520469,0.0259270556271076,174.042114257813,2.19755148887634,2.20219540596008,4000.47412109375,4000.47412109375,,,2.62837815284729,0,1,,,,,,1,1,1,2.19960904121399,0,0,2.20001224982433,,,,,,,,,,,,,,,,,,,,,,,,,,,,,,,,,

,3825486625.88428,2.19994902610779,4000.47412109375,,,5,,,,24.2400001734495,,,,,5.68175098031307E-5,1.08980122388302E-6,17.1881139121804,0.0157333366250577,1.89391068762349E-5,3.63265865126578E-7,1.80932804277321E-5,2.01094714864905E-7,5.59669300863429E-6,3.02527691987963E-7,3.00000998856109,5.00288152694702,12,60,1,3,0.176500106890169,0.066074580206631,0.0248097144067287,182.517044067383,2.19883298873901,2.20222616195679,4000.47412109375,4000.47412109375,,,2.62873291969299,0,1,,,,,,1,1,1,2.20001721382141,0,0,2.20000828030598,,,,,,,,,,,,,,,,,,,,,,,,,,,,,,,,,

,3825486705.69221,2.20012366771698,4000.47412109375,,,5,,,,24.2400001734495,,,,,5.38320445251797E-5,7.97640894538937E-7,16.8392145800691,0.0116013737784504,1.79439590458933E-5,2.65879471440873E-7,1.71745481574757E-5,1.68016868553549E-7,5.19813060890563E-6,2.0606364360347E-7,3.00000932834831,6.5069465637207,12,78,1,3,0.166692737303436,0.0639552914361588,0.0248874705284834,173.210586547852,2.1986608505249,2.20215463638306,4000.47412109375,4000.47412109375,,,2.62892723083496,0,1,,,,,,1,1,1,2.2000687122345,0,0,2.2000002861023,,,,,,,,,,,,,,,,,,,,,,,,,,,,,,,,,

,3825486789.56364,2.19985890388489,4000.47412109375,,,5,,,,24.2400001734495,,,,,5.14747700617861E-5,5.38325498051871E-7,16.520714831046,0.00666099876868798,1.7158193664812E-5,1.79441173592294E-7,1.64498517623425E-5,1.53981470334127E-7,4.87913791936154E-6,9.21349096375536E-8,3.00001101907076,8.50071811676025,12,102,1,3,0.158634739528548,0.0630186500164078,0.0251372680068016,169.047348022461,2.19846892356873,2.20182228088379,4000.47412109375,4000.47412109375,,,2.62853837013245,0,1,,,,,,1,1,1,2.20001912117004,0,0,2.20000688713717,,,,,,,,,,,,,,,,,,,,,,,,,,,,,,,,,

,3825486865.38084,2.19978427886963,4000.47412109375,,,5,,,,24.2400001734495,,,,,4.9442913749912E-5,6.19622067965254E-7,16.5307426428544,0.00733382261109194,1.64814530419454E-5,2.06546727172619E-7,1.58002285300595E-5,1.95232219776508E-7,4.68946401753376E-6,6.74235186478565E-8,2.99991230288249,11.0973014831543,12,133,1,3,0.151105421237572,0.0635266119120259,0.0248420275747776,162.822174072266,2.19860124588013,2.20181655883789,4000.47412109375,4000.47412109375,,,2.62853121757507,0,1,,,,,,1,1,1,2.19993925094604,0,0,2.2000003359211,,,,,,,,,,,,,,,,,,,,,,,,,,,,,,,,,

,3825486929.57319,2.19987547397614,4000.47412109375,,,5,,,,24.2400001734495,,,,,4.73481921666674E-5,3.50534619876669E-7,16.5337627228177,0.0045235066252536,1.57831485962595E-5,1.16847966954516E-7,1.51305502272113E-5,1.11883598131915E-7,4.4915731579756E-6,3.36972973761961E-8,2.99992057211503,14.4291152954102,12,173,1,3,0.143396409349372,0.063732798079683,0.0238070581108332,158.534118652344,2.19882607460022,2.20230889320374,4000.47412109375,4000.47412109375,,,2.62901067733765,0,1,,,,,,1,1,1,2.19997358322144,0,0,2.20000262487502,,,,,,,,,,,,,,,,,,,,,,,,,,,,,,,,,

,3825486993.43506,2.1998291015625,4000.47412109375,,,5,,,,24.2400001734495,,,,,4.54124998618508E-5,2.42456172286452E-7,16.7465203385268,0.00354242656002255,1.51383965104983E-5,8.08235107879044E-8,1.44963598816161E-5,7.66048125591673E-8,4.36194900150578E-6,2.57709640653456E-8,2.99982232796966,18.8089847564697,12,225,1,3,0.136084101070048,0.0641545772321216,0.0225946195423603,153.180694580078,2.19896411895752,2.20248413085938,4000.47412109375,4000.47412109375,,,2.62917995452881,0,1,,,,,,1,1,1,2.19987821578979,0,0,2.1999940985725,,,,,,,,,,,,,,,,,,,,,,,,,,,,,,,,,

,3825487057.43985,2.19978153705597,4000.47412109375,,,5,,,,24.2400001734495,,,,,4.34813206320477E-5,1.72045847488315E-7,17.2425612338254,0.00307576247318664,1.44935592407E-5,5.73477678792136E-8,1.38421960304403E-5,4.49621678606766E-8,4.29614577482479E-6,3.55973305459342E-8,3.00004435832062,24.5121116638184,12,294,1,3,0.128855237785336,0.0642619092887278,0.0206933487206697,147.88232421875,2.19898247718811,2.20185136795044,4000.47412109375,4000.47412109375,,,2.62946748733521,0,1,,,,,,1,1,1,2.19992303848267,0,0,2.20000847801566,,,,,,,,,,,,,,,,,,,,,,,,,,,,,,,,,

,3825487122.00908,2.19993054866791,4000.47412109375,,,5,,,,24.2400001734495,,,,,4.15406176053877E-5,1.07484575098247E-7,17.9922616563331,0.00206800558355075,1.38463269541267E-5,3.58267800318571E-8,1.31692172425735E-5,2.88356730003018E-8,4.27697174861851E-6,2.12617527516134E-8,3.00011820773934,31.9555797576904,12,383,1,3,0.121893396158408,0.0636432329764929,0.0183935575187206,142.136810302734,2.19894552230835,2.20213723182678,4000.47412109375,4000.47412109375,,,2.62971258163452,0,1,,,,,,1,1,1,2.20009899139404,0,0,2.19999630110604,,,,,,,,,,,,,,,,,,,,,,,,,,,,,,,,,

,3825487186.91141,2.19989991188049,4000.47412109375,,,5,,,,24.2400001734495,,,,,3.95139161627722E-5,8.62635597728007E-8,18.9911657292537,0.00178009465795687,1.31724578290609E-5,2.87570358405137E-8,1.24554646521078E-5,2.4754221000983E-8,4.28661236391639E-6,1.46354245912814E-8,2.99973753384103,41.5912475585937,12,499,1,3,0.115037249927313,0.062150470353488,0.0161493066698313,136.622497558594,2.19886803627014,2.20223784446716,4000.47412109375,4000.47412109375,,,2.63008642196655,0,1,,,,,,1,1,1,2.20021462440491,0,0,2.19998717680573,,,,,,,,,,,,,,,,,,,,,,,,,,,,,,,,,

,3825487250.87565,2.19966888427734,4000.47412109375,,,5,,,,24.2400001734495,,,,,3.76287620709194E-5,6.33609902307574E-8,20.07786971007,0.00143258613623777,1.2541811812628E-5,2.11184628991571E-8,1.17796072720855E-5,1.43850416480788E-8,4.30556570717542E-6,1.54615669324332E-8,3.00026524341818,54.253475189209,12,651,1,3,0.109011349022058,0.0600945321897707,0.0136958053335547,133.272109985352,2.19890880584717,2.20202612876892,4000.47412109375,4000.47412109375,,,2.62990808486938,0,1,,,,,,1,1,1,2.19994115829468,0,0,2.20000676503257,,,,,,,,,,,,,,,,,,,,,,,,,,,,,,,,,

,3825487313.90323,2.2000424861908,4000.47412109375,,,5,,,,24.2400001734495,,,,,3.56425473479201E-5,6.61827166676519E-8,21.491158069609,0.00159339008150103,1.18817510953482E-5,2.20625803925566E-8,1.10556618429899E-5,2.01536646138041E-8,4.35297028536433E-6,8.97704050410396E-9,2.99977226099901,70.7653961181641,12,849,1,3,0.102637727633162,0.0579799981724185,0.0112899113446474,129.922668457031,2.19877290725708,2.20244288444519,4000.47412109375,4000.47412109375,,,2.63005590438843,0,1,,,,,,1,1,1,2.19995594024658,0,0,2.20005178451538,,,,,,,,,,,,,,,,,,,,,,,,,,,,,,,,,

,3825487376.92534,2.19980800151825,4000.47412109375,,,5,,,,24.2400001734495,,,,,3.37172322554668E-5,2.6679313754843E-8,23.0613877339888,0.000701776318697527,1.12389901602755E-5,8.89303554045324E-9,1.03408340030004E-5,6.79454319237983E-9,4.40250518967993E-6,5.73761831517655E-9,3.00002329165136,92.1285400390625,12,1105,1,3,0.0963485240366141,0.0561149526530816,0.00950661394745111,128.203247070312,2.19887351989746,2.20154428482056,4000.47412109375,4000.47412109375,,,2.63016080856323,0,1,,,,,,1,1,1,2.19988512992859,0,0,2.2000165254839,,,,,,,,,,,,,,,,,,,,,,,,,,,,,,,,,

,3825487441.09231,2.19973480701447,4000.47412109375,,,5,,,,24.2400001734495,,,,,3.17217941383666E-5,3.67135891670335E-8,24.785811141661,0.00112145995205635,1.05744037015656E-5,1.22384097031918E-8,9.60030364125908E-6,1.18954757713044E-8,4.43307834797808E-6,2.87686083039978E-9,2.99986600035612,119.970825195313,12,1439,1,3,0.0896365569401535,0.0544765627903674,0.00811137724667788,128.92741394043,2.19887733459473,2.20218849182129,4000.47412109375,4000.47412109375,,,2.63016319274902,0,1,,,,,,1,1,1,2.20007467269897,0,0,2.19999977142092,,,,,,,,,,,,,,,,,,,,,,,,,,,,,,,,,

,3825487505.13312,2.1999933719635,4000.47412109375,,,5,,,,24.2400001734495,,,,,2.96067195187299E-5,3.83514561685115E-8,26.7627110968039,0.00139978111850733,9.86834406097535E-6,1.27830901519117E-8,8.81123783678249E-6,1.24003955691693E-8,4.44368116424211E-6,3.10444577340737E-9,3.00017098469545,156.500396728516,12,1878,1,3,0.0822144705596226,0.0531493049162529,0.00700946757569909,129.437652587891,2.19896817207336,2.20205640792847,4000.47412109375,4000.47412109375,,,2.63040494918823,0,1,,,,,,1,1,1,2.20016741752625,0,0,2.20001593468681,,,,,,,,,,,,,,,,,,,,,,,,,,,,,,,,,

,3825487569.07674,2.19977486133575,4000.47412109375,,,5,,,,24.2400001734495,,,,,2.74268169398069E-5,1.36805100895193E-8,28.8248285943725,0.000606821916574131,9.14185407247698E-6,4.55996141112229E-9,8.00915855427331E-6,4.23913157114709E-9,4.40759289578504E-6,1.68018201199405E-9,3.00013725031772,203.875274658203,12,2446,1,3,0.0743887715694323,0.0518851916658931,0.00626948848366737,129.553558349609,2.19914317131042,2.20205497741699,4000.47412109375,4000.47412109375,,,2.63035678863525,0,1,,,,,,1,1,1,2.19990706443787,0,0,2.19999272861178,,,,,,,,,,,,,,,,,,,,,,,,,,,,,,,,,

,3825487632.94048,2.19963335990906,4000.47412109375,,,5,,,,24.2400001734495,,,,,2.52141235437095E-5,8.69948886584589E-9,31.0411632757268,0.00046716044221806,8.40442877966228E-6,2.89973333658499E-9,7.20088985510897E-6,2.42249636500536E-9,4.33377530647406E-6,1.59372669703375E-9,3.00009961470846,266.093322753906,12,3193,1,3,0.0662067665216134,0.0507010735159488,0.00576472142711282,128.872634887695,2.19881224632263,2.20241379737854,4000.47412109375,4000.47412109375,,,2.63032937049866,0,1,,,,,,1,1,1,2.19972634315491,0,0,2.20001269143725,,,,,,,,,,,,,,,,,,,,,,,,,,,,,,,,,

,3825487696.98921,2.19983720779419,4000.47412109375,,,5,,,,24.2400001734495,,,,,2.30016082000893E-5,8.14278361324403E-9,33.4150399268568,0.000576896012712067,7.66736330035647E-6,2.71431804662637E-9,6.39997372035248E-6,2.16647398368092E-9,4.22241593858905E-6,1.63521036453274E-9,2.99993717514597,346.298767089844,12,4155,1,3,0.0577955654577833,0.0494888431917176,0.00551077257841825,126.290542602539,2.19900679588318,2.20188641548157,4000.47412109375,4000.47412109375,,,2.63042736053467,0,1,,,,,,1,1,1,2.19991517066956,0,0,2.20002988785032,,,,,,,,,,,,,,,,,,,,,,,,,,,,,,,,,

,3825487763.62663,2.19987905025482,4000.47412109375,,,5,,,,24.2400001734495,,,,,2.09726677455024E-5,1.00378612003186E-8,36.2248161246014,0.000815222076345383,6.99094865678091E-6,3.34598216721233E-9,5.63962926191034E-6,1.97736747486505E-9,4.13133693977524E-6,2.69918775424178E-9,2.99997450634398,451.068145751953,12,5412,1,3,0.0493891226507989,0.0487505590260358,0.00550058810040355,121.508712768555,2.1976113319397,2.2025043964386,4000.47412109375,4000.47412109375,,,2.63005352020264,0,1,,,,,,1,1,1,2.20007491111755,0,0,2.19999399690917,,,,,,,,,,,,,,,,,,,,,,,,,,,,,,,,,

,3825487827.6413,2.19969761371613,4000.47412109375,,,5,,,,24.2400001734495,,,,,1.88319841320643E-5,7.89726620242935E-9,38.9588022181088,0.00129522147719408,6.27756745362268E-6,2.63252246482913E-9,4.88142556115848E-6,1.93112538682756E-9,3.94709230011807E-6,1.78911410149832E-9,2.99988558803883,589.177978515625,12,7070,1,3,0.0407228671117361,0.0471961508465244,0.00569108314812183,113.818649291992,2.1970386505127,2.20309615135193,4000.47412109375,4000.47412109375,,,2.62991118431091,0,1,,,,,,1,1,1,2.20003294944763,0,0,2.20004004145425,,,,,,,,,,,,,,,,,,,,,,,,,,,,,,,,,

,3825487891.54743,2.19981467723846,4000.47412109375,,,5,,,,24.2400001734495,,,,,1.66972744932495E-5,2.99882590918509E-8,41.6884649915023,0.0114985858299972,5.56591323921491E-6,9.996364877862E-9,4.15646868415781E-6,8.77662855764895E-9,3.7017777167306E-6,4.78519612266978E-9,2.99991641544249,767.436157226563,12,9209,1,3,0.0321184094262775,0.0450101315605427,0.00621714862063527,103.1875,2.19505906105042,2.2050507068634,4000.47412109375,4000.47412109375,,,2.62919902801514,0,1,,,,,,1,1,1,2.19992423057556,0,0,2.20007869175502,,,,,,,,,,,,,,,,,,,,,,,,,,,,,,,,,

,3825487982.44663,2.2001074552536,4000.47412109375,,,5,,,,24.2400001734495,,,,,1.59208075418297E-5,5.7960146780457E-7,50.0841862600667,0.933883219300386,5.30689253115726E-6,1.93198912332707E-7,3.40522780525428E-6,1.40168664344362E-7,4.07032332027516E-6,1.32960765876474E-7,3.00002448671367,999.040954589844,12,11988,1000,3,0.0211863774633222,0.0483079824546515,0.00726814055815339,89.7133178710937,2.19641852378845,2.20502066612244,4000.47412109375,4000.47412109375,,,2.62970423698425,0,1,,,,,,1,1,1,2.2004599571228,0,0,2.19997550975317,,,,,,,,,,,,,,,,,,,,,,,,,,,,,,,,,

,3825488361.81653,2.60014629364014,4000.47412109375,,,5,,,,24.2400001734495,,,,,9.19113933499092E-5,3.41526831273334E-6,10.5189735084645,0.019315774837581,3.06372139146531E-5,1.13842584754212E-6,3.01223404099438E-5,9.88417389126173E-7,5.59316410269551E-6,5.64840220969613E-7,2.99999189240736,0.600503325462341,53.288630792115,32,1,3,0.299062934077708,0.0594662208197264,0.0270030815154314,179.783355712891,2.59633111953735,2.60179591178894,4000.47412109375,4000.47412109375,,,2.86768913269043,0,1,,,,,,1,1,1,2.60038590431213,0,0,2.59999783080921,,,,,,,,,,,,,,,,,,,,,,,,,,,,,,,,,

,3825488603.09665,2.59983801841736,4000.47412109375,,,5,,,,24.2400001734495,,,,,9.04975076996125E-5,1.72618577310328E-6,10.6412946390921,0.00831253701215028,3.01658063120257E-5,5.75394693330663E-7,2.96470303131048E-5,5.2831667616611E-7,5.5704096858752E-6,2.27948552962904E-7,3.00000294252156,0.800566077232361,39.971716151935,32,1,3,0.294209028713512,0.059809519532488,0.0264047849923372,180.021087646484,2.59902167320251,2.60162448883057,4000.47412109375,4000.47412109375,,,2.8676483631134,0,1,,,,,,1,1,1,2.59987092018127,0,0,2.59999825801755,,,,,,,,,,,,,,,,,,,,,,,,,,,,,,,,,

,3825488778.27728,2.60014355182648,4000.47412109375,,,5,,,,24.2400001734495,,,,,8.68989634676935E-5,1.4160420301027E-6,12.198253932874,0.00693676295501666,2.89664159496921E-5,4.7201555472466E-7,2.83124218815469E-5,4.39653337758457E-7,6.12045914714609E-6,1.71766197198044E-7,2.99999018237591,1.02065479755402,31.3524220693299,31,1,3,0.280690940467593,0.0657459319047189,0.0274107474833727,179.008285522461,2.59880614280701,2.60159039497375,4000.47412109375,4000.47412109375,,,2.86769509315491,0,1,,,,,,1,1,1,2.60031247138977,0,0,2.60000384015006,,,,,,,,,,,,,,,,,,,,,,,,,,,,,,,,,

,3825488925.75846,2.60008680820465,4000.47412109375,,,5,,,,24.2400001734495,,,,,8.3120041720685E-5,1.2689928789866E-6,12.2409902676042,0.00776166968412319,2.77067650653385E-5,4.22998916264012E-7,2.70768367780962E-5,3.74090014694016E-7,5.87449916828682E-6,1.97445547092761E-7,2.99999085150035,1.33032166957855,24.0543326713889,31,1,3,0.268226860024542,0.0639724882156039,0.028064139187336,176.692321777344,2.59886837005615,2.60172891616821,4000.47412109375,4000.47412109375,,,2.86738848686218,0,1,,,,,,1,1,1,2.60019779205322,0,0,2.60001463589706,,,,,,,,,,,,,,,,,,,,,,,,,,,,,,,,,

,3825489053.46245,2.60003077983856,4000.47412109375,,,5,,,,24.2400001734495,,,,,7.94573653915785E-5,8.39266434335039E-7,12.4110797507229,0.00495315094718356,2.648579611631E-5,2.79755558940497E-7,2.58668425269916E-5,2.54873498113786E-7,5.69243828236703E-6,1.15337213063917E-7,2.99999913322026,1.73002147674561,18.4968802006991,31,1,3,0.255957692502334,0.0630009500409275,0.0266985632479191,175.028839111328,2.59855103492737,2.60222625732422,4000.47412109375,4000.47412109375,,,2.86782503128052,0,1,,,,,,1,1,1,2.60027647018433,0,0,2.59999907442502,,,,,,,,,,,,,,,,,,,,,,,,,,,,,,,,,

,3825489158.51916,2.59970080852509,4000.47412109375,,,5,,,,24.2400001734495,,,,,7.62468089958302E-5,1.09281196949846E-6,12.3788288567988,0.00483380588153148,2.54155152393878E-5,3.64269398685162E-7,2.48246440993786E-5,3.56137215730956E-7,5.44843649341159E-6,7.65406976049459E-8,3.00001035893486,2.30147647857666,13.9041177686901,32,1,3,0.245277618664691,0.0617959150177687,0.0268945693969727,176.423904418945,2.5987331867218,2.60192584991455,4000.47412109375,4000.47412109375,,,2.86743354797363,0,1,,,,,,1,1,1,2.59978437423706,0,0,2.6000195614835,,,,,,,,,,,,,,,,,,,,,,,,,,,,,,,,,

,3825489246.16485,2.59968793392181,4000.47412109375,,,5,,,,24.2400001734495,,,,,7.33727103881844E-5,8.58305443846777E-7,12.3648986568481,0.00417652314718964,2.44575881477184E-5,2.86102025391849E-7,2.38902613535167E-5,2.78101891822484E-7,5.23727318975099E-6,6.71841253427739E-8,2.99999778984867,2.94003653526306,12,35,1,3,0.235639889944513,0.0609796770522885,0.0265129134058952,174.743591308594,2.59883189201355,2.6025242805481,4000.47412109375,4000.47412109375,,,2.86802887916565,0,1,,,,,,1,1,1,2.60004425048828,0,0,2.59999480365235,,,,,,,,,,,,,,,,,,,,,,,,,,,,,,,,,

,3825489328.94675,2.60017323493958,4000.47412109375,,,5,,,,24.2400001734495,,,,,7.05228605307274E-5,9.45260013313441E-7,12.014590807544,0.00907797801375541,2.35076063362183E-5,3.15086485589436E-7,2.29926633504458E-5,2.35717017128692E-7,4.8933615962527E-6,2.09086061795266E-7,3.00000176632498,3.82425808906555,12,45,1,3,0.226304088945721,0.0592780757539831,0.026764877140522,173.467666625977,2.59637904167175,2.60238242149353,4000.47412109375,4000.47412109375,,,2.86804127693176,0,1,,,,,,1,1,1,2.60014486312866,0,0,2.59998352439315,,,,,,,,,,,,,,,,,,,,,,,,,,,,,,,,,

,3825489409.80297,2.59998655319214,4000.47412109375,,,5,,,,24.2400001734495,,,,,6.77170333677544E-5,8.40137860297676E-7,11.8529434100799,0.00943262175012282,2.25723739727305E-5,2.80046319635718E-7,2.20910860181813E-5,1.81725392042807E-7,4.63637631152957E-6,2.13077035431787E-7,2.99999607704369,5.00288152694702,12,60,1,3,0.216769814403954,0.0588491805732845,0.0224572997540236,187.957443237305,2.59868454933166,2.60220408439636,4000.47412109375,4000.47412109375,,,2.86818361282349,0,1,,,,,,1,1,1,2.60000038146973,0,0,2.600031670928,,,,,,,,,,,,,,,,,,,,,,,,,,,,,,,,,

[...]

,3825496818.43658,3.49953353404999,4000.22216796875,,,5,,,,24.2400001734495,,,,,5.74642621907365E-5,1.62074088338956E-8,29.9624460259962,0.000386631415940744,1.91549050945335E-5,5.40251220856394E-9,1.65949083054641E-5,5.14852140750578E-9,9.56657762806649E-6,1.63702946831665E-9,2.99997634585702,266.093322753906,12,3193,1,3,0.153041217876473,0.112683404084626,0.0057743526995182,128.807388305664,3.49871778488159,3.50211882591248,4000.22216796875,4000.22216796875,,,3.32238936424255,0,1,,,,,,1,1,1,3.50005698204041,0,0,3.49999887660398,,,,,,,,,,,,,,,,,,,,,,,,,,,,,,,,,

,3825496878.62769,3.49944937229156,4000.22216796875,,,5,,,,24.2400001734495,,,,,5.25563392385057E-5,6.30611092315501E-9,34.5393577177984,0.000214342717586952,1.75182533790113E-5,2.10197381683392E-9,1.44304320374618E-5,1.69503447274901E-9,9.93236289426832E-6,1.2430414566087E-9,3.0000901403489,346.298767089844,12,4155,1,3,0.129818169147735,0.115639954592906,0.00554403616115451,126.269897460938,3.49846744537354,3.5018298625946,4000.22216796875,4000.22216796875,,,3.32266139984131,0,1,,,,,,1,1,1,3.4998676776886,0,0,3.50001374341674,,,,,,,,,,,,,,,,,,,,,,,,,,,,,,,,,

,3825496938.86324,3.49946570396423,4000.22216796875,,,5,,,,24.2299996316433,,,,,4.72760969135909E-5,1.26747523055569E-8,39.4183852236853,0.000912016769707568,1.57592336818969E-5,4.22506079147179E-9,1.21744785850301E-5,3.89771198690646E-9,1.00067735770965E-5,1.63063789933815E-9,2.99989821001882,451.068145751953,12,5412,1,3,0.105043854633495,0.11591702785328,0.00549004971981049,121.471984863281,3.4985203742981,3.50175380706787,4000.22216796875,4000.22216796875,,,3.32250452041626,0,1,,,,,,1,1,1,3.4999041557312,0,0,3.5000105914423,,,,,,,,,,,,,,,,,,,,,,,,,,,,,,,,,

,3825496999.03554,3.49955308437347,4000.22216796875,,,5,,,,24.2400001734495,,,,,4.15871563651735E-5,9.45424755610648E-9,44.2173013091489,0.00120169656968201,1.3861757991499E-5,3.15127320713414E-9,9.93472272379265E-6,2.32309168466084E-9,9.66693431322696E-6,2.12926462673411E-9,3.00013579739868,589.177978515625,12,7070,1,3,0.0800075774330035,0.112020716596228,0.00568762514740229,113.750244140625,3.49857234954834,3.50220632553101,4000.22216796875,4000.22216796875,,,3.32259702682495,0,1,,,,,,1,1,1,3.49990367889404,0,0,3.50005983498137,,,,,,,,,,,,,,,,,,,,,,,,,,,,,,,,,

,3825497059.27284,3.49932837486267,4000.22216796875,,,5,,,,24.2299996316433,,,,,3.58860121303492E-5,2.97948774860011E-8,48.8098818769246,0.0135163424499806,1.19614495330161E-5,9.9311654384076E-9,7.87732838102899E-6,9.19365617398938E-9,9.00133170749343E-6,3.75562686105644E-9,3.0001390743903,767.436157226563,12,9209,1,3,0.056514875827424,0.104541008518241,0.00623140996322036,103.111511230469,3.49693703651428,3.50314617156982,4000.22216796875,4000.22216796875,,,3.32226300239563,0,1,,,,,,1,1,1,3.49996852874756,0,0,3.5000459945808,,,,,,,,,,,,,,,,,,,,,,,,,,,,,,,,,

,3825497125.43401,3.49966478347778,4000.22216796875,,,5,,,,24.2400001734495,,,,,0.000257624884911959,2.31716597569493E-6,68.0120433207882,60.00450725957,8.58750235695613E-5,7.72389215604653E-7,3.21526131478445E-5,5.28988998429338E-7,7.96286954611072E-5,5.62810571971687E-7,2.99999783642884,999.040954589844,12,11988,1000,3,0.0856778437430389,0.849253551438599,0.00724606076255441,89.7096252441406,3.49637341499329,3.50345921516418,4000.22216796875,4000.22216796875,,,3.32279014587402,0,1,,,,,,1,1,1,3.49959993362427,0,0,3.49999764376673,,,,,,,,,,,,,,,,,,,,,,,,,,,,,,,,,

,3825497505.06985,4.00011014938354,4000.22216796875,,,5,,,,24.2299996316433,,,,,8.96381666224205E-5,7.50410894097289E-7,2.59504937311356,0.00437499199737493,2.98793244217593E-5,2.50136425132408E-7,2.98486827454625E-5,2.13479544334673E-7,1.35283637645932E-6,1.3036378073944E-7,3.00000647126889,0.600503325462341,53.288630792115,32,1,3,0.296876579782749,0.0172330666232294,0.0265834927558899,178.81901550293,3.99673438072205,4.00272417068481,4000.22216796875,4000.22216796875,,,3.53013467788696,0,1,,,,,,1,1,1,4.00021648406982,0,0,3.99999624978605,,,,,,,,,,,,,,,,,,,,,,,,,,,,,,,,,

,3825497722.84858,4.00029826164246,4000.22216796875,,,5,,,,24.2400001734495,,,,,8.87655101556977E-5,1.26709479043006E-6,2.83435441797275,0.00357551868789352,2.95884144286116E-5,4.22363660320527E-7,2.95522179622562E-5,4.09664778470285E-7,1.46310693750354E-6,1.02790227357691E-7,3.00000901940398,0.800566077232361,39.971716151935,32,1,3,0.293872330238042,0.0189218199331967,0.0266681965440512,178.633773803711,3.99752879142761,4.0019793510437,4000.22216796875,4000.22216796875,,,3.52995228767395,0,1,,,,,,1,1,1,4.00021123886108,0,0,3.99999753369225,,,,,,,,,,,,,,,,,,,,,,,,,,,,,,,,,

,3825497893.5744,4.00001299381256,4000.22216796875,,,5,,,,24.2400001734495,,,,,8.80166802292441E-5,5.53272166940182E-7,2.84685435263452,0.00380733635463234,2.93389917780081E-5,1.84424673988845E-7,2.93027832331269E-5,1.46883175415748E-7,1.45716620273946E-6,1.11524854430205E-7,2.99998994155005,1.02065479755402,31.3524220693299,31,1,3,0.291343398070608,0.0195106524700452,0.026844572275877,177.243133544922,3.9970920085907,4.00259971618652,4000.22216796875,4000.22216796875,,,3.53025507926941,0,1,,,,,,1,1,1,3.99988055229187,0,0,4.00001005166107,,,,,,,,,,,,,,,,,,,,,,,,,,,,,,,,,

,3825498036.93783,3.99983298778534,4000.22216796875,,,5,,,,24.2400001734495,,,,,8.70201430608349E-5,4.23028088721642E-7,2.666285433031,0.00170199416201202,2.9006758381384E-5,1.4100957693794E-7,2.89753562705869E-5,1.32322984505385E-7,1.34935569385969E-6,4.87270824060357E-8,2.99999544646405,1.33032166957855,24.0543326713889,31,1,3,0.288040622433077,0.0193325794366618,0.0264484137296677,177.706298828125,3.99884057044983,4.00277376174927,4000.22216796875,4000.22216796875,,,3.53014469146729,0,1,,,,,,1,1,1,3.99970269203186,0,0,4.00000373009712,,,,,,,,,,,,,,,,,,,,,,,,,,,,,,,,,

,3825498151.37563,3.99993288516998,4000.22216796875,,,5,,,,24.2400001734495,,,,,8.59151723138958E-5,4.45318835770655E-7,2.55751008514358,0.00213063789968756,2.86383034179045E-5,1.48439159150069E-7,2.86097778286263E-5,1.3555252278927E-7,1.27790267728196E-6,6.0495433998311E-8,3.0000091506881,1.73002147674561,18.4968802006991,31,1,3,0.28433533469727,0.0197540431755065,0.026582607999444,177.205368041992,3.9989914894104,4.0021915435791,4000.22216796875,4000.22216796875,,,3.53013253211975,0,1,,,,,,1,1,1,4.00000429153442,0,0,4.0000117186344,,,,,,,,,,,,,,,,,,,,,,,,,,,,,,,,,

,3825498253.1783,4.00033271312714,4000.22216796875,,,5,,,,24.2299996316433,,,,,8.53837186002322E-5,4.62693307793172E-7,2.52932516218025,0.00229894293528607,2.84612423248237E-5,1.54231117724356E-7,2.84335143984987E-5,1.39929357839712E-7,1.25601497710138E-6,6.48614869477266E-8,2.99999970576692,2.30147647857666,13.9041177686901,32,1,3,0.282459155780773,0.0211956957624849,0.0266219936311245,176.343719482422,3.99689030647278,4.00326204299927,4000.22216796875,4000.22216796875,,,3.53000926971436,0,1,,,,,,1,1,1,3.99997639656067,0,0,4.00000902811686,,,,,,,,,,,,,,,,,,,,,,,,,,,,,,,,,

,3825498335.1018,3.99989175796509,4000.22216796875,,,5,,,,24.2400001734495,,,,,8.48339992148451E-5,3.8626930097981E-7,2.45246627438022,0.00124346555684762,2.82779584223618E-5,1.28756245538763E-7,2.82520576586442E-5,1.24161732062377E-7,1.21002916884973E-6,3.40886352984225E-8,3.00000438319336,2.94003653526306,12,35,1,3,0.280518202957721,0.0225523810427668,0.0272664222866297,176.550842285156,3.99907970428467,4.00251626968384,4000.22216796875,4000.22216796875,,,3.53028178215027,0,1,,,,,,1,1,1,3.9997239112854,0,0,4.00002167065938,,,,,,,,,,,,,,,,,,,,,,,,,,,,,,,,,

,3825498414.0817,3.99995183944702,4000.22216796875,,,5,,,,24.2400001734495,,,,,8.41782776976123E-5,3.68043300240191E-7,2.50057715831318,0.00380387520968736,2.80594206879811E-5,1.22681077295614E-7,2.80327020064448E-5,6.01053049869986E-8,1.22421712247598E-6,1.06948581284804E-7,3.00000055716293,3.82425808906555,12,45,1,3,0.278103314509645,0.0251342914392807,0.0263787545263767,173.811553955078,3.99879217147827,4.00275421142578,4000.22216796875,4000.22216796875,,,3.53045964241028,0,1,,,,,,1,1,1,4.0000057220459,0,0,3.99999709253187,,,,,,,,,,,,,,,,,,,,,,,,,,,,,,,,,

,3825498490.93535,3.99986636638641,4000.22216796875,,,5,,,,24.2400001734495,,,,,8.32773508151682E-5,3.92554741268167E-7,2.384888200656,0.00364933663655341,2.77590310187538E-5,1.30851175412717E-7,2.7734987258615E-5,8.27042355321198E-8,1.15511249002089E-6,1.01400392168557E-7,3.00000928558733,5.00288152694702,12,60,1,3,0.274853654643323,0.0275338423635352,0.0229155402630568,173.300247192383,3.99890089035034,4.00193881988525,4000.22216796875,4000.22216796875,,,3.53088688850403,0,1,,,,,,1,1,1,4.00016450881958,0,0,3.99999204748555,,,,,,,,,,,,,,,,,,,,,,,,,,,,,,,,,

,3825498567.57237,4.00002753734589,4000.22216796875,,,5,,,,24.2400001734495,,,,,8.30706754134383E-5,4.48783436718254E-7,2.57701564874874,0.00432031924097676,2.76902050394556E-5,1.49594370326135E-7,2.76622015721428E-5,8.95481143951206E-8,1.245013778733E-6,1.19831593670247E-7,3.00000217748736,6.5069465637207,12,78,1,3,0.273616733742269,0.0322787015138707,0.0267019849270582,171.022903442383,3.99869203567505,4.00240421295166,4000.22216796875,4000.22216796875,,,3.53101968765259,0,1,,,,,,1,1,1,4.00014543533325,0,0,4.00000431060791,,,,,,,,,,,,,,,,,,,,,,,,,,,,,,,,,

,3825498644.27471,4.00011456012726,4000.22216796875,,,5,,,,24.2400001734495,,,,,8.32093150076967E-5,3.29662227599138E-7,2.70889855879025,0.00151391853350033,2.7736893386553E-5,1.09889212038881E-7,2.77058987077259E-5,1.02090412989407E-7,1.31088959651134E-6,4.06593961856121E-8,2.99995078208856,8.50071811676025,12,102,1,3,0.273339244494722,0.0377045300934107,0.0272524077445269,168.737243652344,3.99891233444214,4.00266313552856,4000.22216796875,4000.22216796875,,,3.53116464614868,0,1,,,,,,1,1,1,3.99997925758362,0,0,3.99999889574553,,,,,,,,,,,,,,,,,,,,,,,,,,,,,,,,,

,3825498717.54304,3.99957180023193,4000.22216796875,,,5,,,,24.2400001734495,,,,,8.27177237334449E-5,3.05742352899139E-7,3.11099489018938,0.00130140656723851,2.75720836506638E-5,1.01912303061567E-7,2.75314499645119E-5,9.61691628878882E-8,1.49634878647271E-6,3.37284690544291E-8,3.00005341567479,11.0973014831543,12,133,1,3,0.270561939778936,0.0447068880850061,0.0248726364225149,162.42658996582,3.9988386631012,4.00266313552856,4000.22216796875,4000.22216796875,,,3.53091287612915,0,1,,,,,,1,1,1,4.00012111663818,0,0,4.00001779198647,,,,,,,,,,,,,,,,,,,,,,,,,,,,,,,,,

,3825498777.9484,3.99933362007141,4000.22216796875,,,5,,,,24.2400001734495,,,,,8.22765323838684E-5,2.06832060985757E-7,3.5017580446208,0.00178753084922304,2.74266746335062E-5,6.89469460619379E-8,2.73754669683534E-5,4.86104723889842E-8,1.67519841117496E-6,4.88948192080467E-8,2.99987269631858,14.4291152954102,12,173,1,3,0.267734166343894,0.0517061070856482,0.0238540880382061,158.116790771484,3.99851822853088,4.00182199478149,4000.22216796875,4000.22216796875,,,3.53123950958252,0,1,,,,,,1,1,1,3.99978756904602,0,0,3.99999724404287,,,,,,,,,,,,,,,,,,,,,,,,,,,,,,,,,

,3825498837.13866,3.99932825565338,4000.22216796875,,,5,,,,24.2299996316433,,,,,8.18884280063643E-5,1.46261272595596E-7,4.00038852465188,0.000541215280021928,2.72962519423653E-5,4.87539527058705E-8,2.72297467322108E-5,4.72867418414434E-8,1.90427492782372E-6,1.18706339538773E-8,2.99998799026575,18.8089847564697,12,225,1,3,0.264865464608207,0.0586920991292314,0.0225463174283504,153.312927246094,3.99861550331116,4.00192022323608,4000.22216796875,4000.22216796875,,,3.53163981437683,0,1,,,,,,1,1,1,3.99963617324829,0,0,3.99999177455902,,,,,,,,,,,,,,,,,,,,,,,,,,,,,,,,,

,3825498897.52233,3.99938654899597,4000.22216796875,,,5,,,,24.2400001734495,,,,,8.12435129223335E-5,8.68141035825346E-8,4.68055382173638,0.000468619264121281,2.70805114397981E-5,2.89373297711794E-8,2.69902017073167E-5,2.65940298325027E-8,2.20977637768918E-6,1.14073060603256E-8,3.00007306372126,24.5121116638184,12,294,1,3,0.261113872956333,0.0648309473696062,0.0205509830266237,147.441329956055,3.99843263626099,4.00216007232666,4000.22216796875,4000.22216796875,,,3.53205561637878,0,1,,,,,,1,1,1,4.00000238418579,0,0,4.0000222881635,,,,,,,,,,,,,,,,,,,,,,,,,,,,,,,,,

,3825498958.07299,3.99959754943848,4000.22216796875,,,5,,,,24.2400001734495,,,,,8.0451713777672E-5,8.25814622526344E-8,5.51442961638119,0.000447875954104539,2.68186712240059E-5,2.75286253251416E-8,2.66945551803995E-5,2.55215815815185E-8,2.57717867869679E-6,1.03186281001846E-8,2.9998396678825,31.9555797576904,12,383,1,3,0.257126621826162,0.0693388867602878,0.0184801500290632,142.116775512695,3.99863600730896,4.00160789489746,4000.22216796875,4000.22216796875,,,3.53223848342895,0,1,,,,,,1,1,1,4.00035762786865,0,0,3.99999308188756,,,,,,,,,,,,,,,,,,,,,,,,,,,,,,,,,

,3825499017.6858,3.9996132850647,4000.22216796875,,,5,,,,24.2400001734495,,,,,7.96970445131995E-5,4.2062304333682E-8,6.51224568060399,0.000288064476793545,2.65657086634299E-5,1.40207824451514E-8,2.6394297103649E-5,1.21301772579083E-8,3.01296485119515E-6,7.03143940214173E-9,2.99999693299768,41.5912475585937,12,499,1,3,0.253628403962897,0.0722544486000581,0.0162025094032288,137.522491455078,3.99846816062927,4.00193214416504,4000.22216796875,4000.22216796875,,,3.53235411643982,0,1,,,,,,1,1,1,4.0000262260437,0,0,4.00000977105108,,,,,,,,,,,,,,,,,,,,,,,,,,,,,,,,,

,3825499077.92561,3.9994056224823,4000.22216796875,,,5,,,,24.2400001734495,,,,,7.8818565790813E-5,3.37233111924269E-8,7.78600934011284,0.000223001872503799,2.62707944698566E-5,1.12402219996057E-8,2.60286027121E-5,9.99131003253905E-9,3.55900027158025E-6,5.14939942460325E-9,3.00023533286175,54.253475189209,12,651,1,3,0.249903387045322,0.074376415772033,0.0136261126026511,132.936050415039,3.99849677085876,4.00142478942871,4000.22216796875,4000.22216796875,,,3.53231835365295,0,1,,,,,,1,1,1,3.99979615211487,0,0,3.9999854403027,,,,,,,,,,,,,,,,,,,,,,,,,,,,,,,,,

,3825499138.31102,3.9994752407074,4000.22216796875,,,5,,,,24.2400001734495,,,,,7.78948443414768E-5,2.64868543592708E-8,9.41796168997826,0.000215137526338136,2.59659258998255E-5,8.82928393305855E-9,2.56159288988608E-5,7.10590577838977E-9,4.24894039540908E-6,5.24045397262611E-9,2.99988703048714,70.7653961181641,12,849,1,3,0.245852002622642,0.076989218571317,0.0114429080858827,130.276596069336,3.99849224090576,4.00162410736084,4000.22216796875,4000.22216796875,,,3.53280925750732,0,1,,,,,,1,1,1,3.99998211860657,0,0,4.00001311706284,,,,,,,,,,,,,,,,,,,,,,,,,,,,,,,,,

,3825499198.87812,3.99916839599609,4000.22216796875,,,5,,,,24.2299996316433,,,,,7.69075088183013E-5,4.31130115750016E-8,11.4719575310354,0.000252396794121164,2.56367912423457E-5,1.43715391976672E-8,2.51246236461483E-5,1.38189153489457E-8,5.09885789594334E-6,3.94698840747709E-9,2.99988825010475,92.1285400390625,12,1105,1,3,0.241001577881237,0.0812312945267428,0.00961974635720253,128.959747314453,3.99890661239624,4.00186109542847,4000.22216796875,4000.22216796875,,,3.53270411491394,0,1,,,,,,1,1,1,3.99972319602966,0,0,3.9999894045167,,,,,,,,,,,,,,,,,,,,,,,,,,,,,,,,,

,3825499259.23084,3.99962329864502,4000.22216796875,,,5,,,,24.2299996316433,,,,,7.55145714588246E-5,2.65110217038798E-8,14.0195597548607,0.000248164071844183,2.51721144912815E-5,8.83721460267821E-9,2.44223147792118E-5,6.62582840836084E-9,6.09802335083077E-6,5.84762856521748E-9,2.99992960404575,119.970825195313,12,1439,1,3,0.233853230509732,0.0875342694645402,0.00806012190878391,128.591674804688,3.99916863441467,4.00233697891235,4000.22216796875,4000.22216796875,,,3.53283953666687,0,1,,,,,,1,1,1,3.9998733997345,0,0,4.00004422462593,,,,,,,,,,,,,,,,,,,,,,,,,,,,,,,,,

,3825499319.53421,3.99951839447022,4000.22216796875,,,5,,,,24.2299996316433,,,,,7.34982094617507E-5,1.34089100287369E-8,17.1714532185395,0.000139939793622955,2.45005943963515E-5,4.46985400484106E-9,2.34084945072277E-5,3.08902097142202E-9,7.23336095322366E-6,3.23071884612521E-9,2.99985413711823,156.500396728516,12,1878,1,3,0.223229981897785,0.0960849268967658,0.00697410898283124,129.17073059082,3.99849605560303,4.00131845474243,4000.22216796875,4000.22216796875,,,3.5330708026886,0,1,,,,,,1,1,1,4.00013446807861,0,0,3.99996988773346,,,,,,,,,,,,,,,,,,,,,,,,,,,,,,,,,

,3825499379.939,3.99928772449493,4000.22216796875,,,5,,,,24.2400001734495,,,,,7.07272527332494E-5,1.42618963260196E-8,20.9044684699642,0.000156746749665639,2.35745442022176E-5,4.75372211350061E-9,2.20227887200183E-5,3.9226019230152E-9,8.41165330572683E-6,2.68534319704989E-9,3.00015356083094,203.875274658203,12,2446,1,3,0.208442198126786,0.106081210193899,0.00621052924543619,129.656890869141,3.99882388114929,4.00196599960327,4000.22216796875,4000.22216796875,,,3.53309655189514,0,1,,,,,,1,1,1,3.99972152709961,0,0,4.00002618563377,,,,,,,,,,,,,,,,,,,,,,,,,,,,,,,,,

,3825499440.28092,3.99940752983093,4000.22216796875,,,5,,,,24.2299996316433,,,,,6.6945484869339E-5,2.09264502279897E-8,25.2081374143232,0.000308551082637877,2.23160135702954E-5,6.97574971900477E-9,2.01907831026321E-5,6.69393471261231E-9,9.50456413372405E-6,1.96273335058002E-9,2.99988547051474,266.093322753906,12,3193,1,3,0.188560706276411,0.116043512523935,0.00578685011714697,128.820388793945,3.99880361557007,4.00161552429199,4000.22216796875,4000.22216796875,,,3.53321552276611,0,1,,,,,,1,1,1,3.99999284744263,0,0,3.99998094671864,,,,,,,,,,,,,,,,,,,,,,,,,,,,,,,,,

,3825499500.65158,3.99943709373474,4000.22216796875,,,5,,,,24.2400001734495,,,,,6.23361306465862E-5,9.59618867970159E-9,29.9342198813617,0.000184106001593249,2.07786480392697E-5,3.19871998832291E-9,1.8006752967816E-5,2.26625228329645E-9,1.03686576708799E-5,2.25741226898192E-9,3.00000897694483,346.298767089844,12,4155,1,3,0.164492416971754,0.124350056670582,0.00554623641073704,126.281112670898,3.99852347373962,4.00212812423706,4000.22216796875,4000.22216796875,,,3.5335419178009,0,1,,,,,,1,1,1,3.99996519088745,0,0,4.00001277761944,,,,,,,,,,,,,,,,,,,,,,,,,,,,,,,,,

,3825499561.11213,3.99948382377625,4000.22216796875,,,5,,,,24.2400001734495,,,,,5.70281502452063E-5,9.02323643144782E-9,35.0693621562617,0.000242896932628852,1.90102438465652E-5,3.00788161827944E-9,1.55590685493083E-5,1.73578184859207E-9,1.09226716962379E-5,2.4565042649427E-9,2.99986421560342,451.068145751953,12,5412,1,3,0.13695384394299,0.129813237901376,0.00550551479682326,121.484359741211,3.99889588356018,4.0016016960144,4000.22216796875,4000.22216796875,,,3.53330063819885,0,1,,,,,,1,1,1,3.99987173080444,0,0,3.99999741376457,,,,,,,,,,,,,,,,,,,,,,,,,,,,,,,,,

,3825499624.05272,3.99963581562042,4000.22216796875,,,5,,,,24.2400001734495,,,,,5.09585568177055E-5,1.04136595955268E-8,40.3701507092335,0.000788472408722119,1.69864354690758E-5,3.47127092608079E-9,1.29415550322653E-5,2.77519150573972E-9,1.10025062277613E-5,2.08519398347586E-9,2.99995587128781,589.177978515625,12,7070,1,3,0.107029626670548,0.130373041255623,0.0056682052090764,113.78645324707,3.99838256835937,4.00177717208862,4000.22216796875,4000.22216796875,,,3.53312706947327,0,1,,,,,,1,1,1,4.00021743774414,0,0,3.99998350681797,,,,,,,,,,,,,,,,,,,,,,,,,,,,,,,,,

,3825499684.52944,3.99949705600738,4000.22216796875,,,5,,,,24.2400001734495,,,,,4.45355558783796E-5,3.3707089905605E-8,45.0628189833585,0.00758083111024317,1.48458128772409E-5,1.12361716274856E-8,1.04860591293636E-5,1.04168117754838E-8,1.05090781670679E-5,4.21207612424731E-9,2.99987317950464,767.436157226563,12,9209,1,3,0.0784703348904315,0.124873703174586,0.00622344063594937,103.162445068359,3.9983344078064,4.00268173217773,4000.22216796875,4000.22216796875,,,3.53329038619995,0,1,,,,,,1,1,1,4.00011682510376,0,0,4.00005830748607,,,,,,,,,,,,,,,,,,,,,,,,,,,,,,,,,

,3825499751.25585,4.00021123886108,4000.22216796875,,,5,,,,24.2400001734495,,,,,3.53507510927919E-5,5.26577117101602E-7,54.567574520267,0.865500052061698,1.1783174562675E-5,1.75519611315514E-7,6.83120573506723E-6,1.26162433172008E-7,9.60092865194066E-6,1.22025302345323E-7,3.00010416588166,999.040954589844,12,11988,1000,3,0.0385344730129772,0.110603142899765,0.00723981531336904,89.7269897460937,3.99699926376343,4.00398635864258,4000.22216796875,4000.22216796875,,,3.53390979766846,0,1,,,,,,1,1,1,4.00008535385132,0,0,4.00000483135007,,,,,,,,,,,,,,,,,,,,,,,,,,,,,,,,,