File: data/AP498/ac_dc.dat
[Header]
; MPMS3 Data File (default extension .dat)
; Copyright (c) 2007, Quantum Design, Inc. All rights reserved.
TITLE,
FILEOPENTIME,3825362206.66378,03/20/2021,12:36 am
BYAPP,SQUID AC,0.9.1.0
INFO,MPMS3 Measurement Release 1.1.16 Build 347, MultiVu Release 2.3.3.2,APPNAME
INFO,0,MOMENT_UNITS
INFO,SC_AP498,SAMPLE_MATERIAL
INFO,crystals, nujol, capsule,SAMPLE_COMMENT
INFO,1,SAMPLE_MASS
INFO,,SAMPLE_VOLUME
INFO,,SAMPLE_MOLECULAR_WEIGHT
INFO,,SAMPLE_SIZE
INFO,,SAMPLE_SHAPE
INFO,Straw,SAMPLE_HOLDER
INFO,Standard,SAMPLE_HOLDER_DETAIL
INFO,64.87,SAMPLE_OFFSET
DATATYPE,COMMENT,1
DATATYPE,TIME,2
STARTUPAXIS,X,2
STARTUPAXIS,Y1,5
FIELDGROUP, VSM,2,3,4,5,6,8,9,10,11,14,15
FIELDGROUP, DC, 2,3,4,14,56,57,58,59,60,61,62,63,64,65,66,67,68,69
FIELDGROUP, AC, 2,3,4,11,16,17,18,19,20,21,22,23,24,25,26,27,28,29,30
STARTUPGROUP, All
[Data]
Comment,Time Stamp (sec),Temperature (K),Magnetic Field (Oe),Moment (emu),M. Std. Err. (emu),Transport Action,Averaging Time (sec),Frequency (Hz),Peak Amplitude (mm),Center Position (mm),Lockin Signal' (V),Lockin Signal (V),Range,M. Quad. Signal (emu),AC Moment (emu),AC M. Std Err. (emu),AC Phase (deg),AC Phase Std. Err. (deg),AC Susceptibility (emu/Oe),AC Suscept. Std Err. (emu/Oe),AC X' (emu/Oe),AC X' Std Err. (emu/Oe),AC X'' (emu/Oe),AC X'' Std Err. (emu/Oe),AC Drive (Oe),AC Frequency (Hz),AC Averaging Time (sec),AC Cycles,AC Range,AC Measure Type,AC Signal' (V),AC Signal'' (V),AC Trim Coil Ratio,AC Trim Coil Phase,Min. Temperature (K),Max. Temperature (K),Min. Field (Oe),Max. Field (Oe),Mass (grams),Motor Lag (deg),Pressure (Torr),Measure Count,Measurement Number,SQUID Status (code),Motor Status (code),Measure Status (code),Motor Current (amps),Motor Temp. (C),Temp. Status (code),Field Status (code),Chamber Status (code),Chamber Temp (K),Redirection State,Evercool Status,Average Temp (K),Rotation Angle (deg),Rotator state,DC Moment Fixed Ctr (emu),DC Moment Err Fixed Ctr (emu),DC Moment Free Ctr (emu),DC Moment Err Free Ctr (emu),DC Fixed Fit,DC Free Fit,DC Calculated Center (mm),DC Calculated Center Err (mm),DC Scan Length (mm),DC Scan Time (s),DC Number of Points,DC Squid Drift,DC Min V (V),DC Max V (V),DC Scans per Measure,Map 01,Map 02,Map 03,Map 04,Map 05,Map 06,Map 07,Map 08,Map 09,Map 10,Map 11,Map 12,Map 13,Map 14,Map 15,Map 16
,3825364151.32922,1.79994511604309,-0.516808271408081,,,5,,,,24.2400001734495,,,,,0.000256732293943719,6.08298919857319E-8,-0.0978175287601245,0.000154711767147008,8.55774420447483E-5,2.02766332043076E-8,8.55773173301454E-5,1.53572733921453E-8,-1.46100985153602E-7,1.32399398813188E-8,2.99999962384332,1.00057637691498,31.9815665633281,32,1,3,0.85144814693833,0.0105503702224455,0.0261857341974974,178.098388671875,1.79865443706512,1.8043714761734,-0.516808271408081,-0.516808271408081,,,2.30345845222473,0,1,,,,,,1,1,1,1.7998560667038,0,0,1.80012532327541,,,,,,,,,,,,,,,,,,,,,,,,,,,,,,,,,
,3825364868.59539,1.80003529787064,-0.516808271408081,,,5,,,,24.2400001734495,,,,,0.000255664217767996,5.97388990484486E-8,0.0133585640454723,0.000137952581703565,8.52216398427208E-5,1.99130210076071E-8,8.52216375264242E-5,1.60725573129225E-8,1.98695040587604E-8,1.17559052000356E-8,2.99999176546981,5.2525954246521,12,63,1,3,0.846396135636064,0.0491535671934643,0.0257562901824713,171.151016235352,1.79860901832581,1.80174374580383,-0.516808271408081,-0.516808271408081,,,2.3141143321991,0,1,,,,,,1,1,1,1.80001950263977,0,0,1.79999344607434,,,,,,,,,,,,,,,,,,,,,,,,,,,,,,,,,
,3825365299.39337,1.79957872629166,-0.516808271408081,,,5,,,,24.2400001734495,,,,,0.000256855411033612,8.92926057329826E-9,0.0797324272020568,1.54684019912226E-5,8.5621562467312E-5,2.97652768492199E-9,8.56214795628724E-5,2.67023073967E-9,1.1915036065443E-7,1.31513682026946E-9,2.99989165850218,27.5553760528564,12,330,1,3,0.838867134323725,0.138576858143538,0.0192990060895681,144.532775878906,1.79853975772858,1.80166113376617,-0.516808271408081,-0.516808271408081,,,2.33049654960632,0,1,,,,,,1,1,1,1.80012631416321,0,0,1.79998199079858,,,,,,,,,,,,,,,,,,,,,,,,,,,,,,,,,
,3825365668.73815,1.79947382211685,-0.516808271408081,,,5,,,,24.2299996316433,,,,,0.000259053947463881,8.41231854557912E-9,-0.0425270539141041,2.10985610539958E-5,8.63469056394669E-5,2.80396296900874E-9,8.63468818545251E-5,2.13197263793438E-9,-6.40898719850627E-8,1.82123611941765E-9,3.00015322547325,144.4619140625,12,1733,1,3,0.851704093026408,0.0894594812309214,0.00706409802660346,129.097640991211,1.79848027229309,1.80196392536163,-0.516808271408081,-0.516808271408081,,,2.33562636375427,0,1,,,,,,1,1,1,1.79992270469666,0,0,1.79998976389567,,,,,,,,,,,,,,,,,,,,,,,,,,,,,,,,,
,3825366032.88966,1.80002242326736,-0.516808271408081,,,5,,,,24.2299996316433,,,,,0.000262766648779019,1.71127771757458E-8,-0.461132253409144,3.09637592837233E-5,8.75850827698721E-5,5.70401157195771E-9,8.75822461343371E-5,5.03365766201543E-9,-7.04901319147871E-7,2.68291605434476E-9,3.00013016451023,758.4951171875,12,9101,1,3,0.850781119435036,0.18166239838134,0.00594703899696469,104.53596496582,1.79519951343536,1.80590057373047,-0.516808271408081,-0.516808271408081,,,2.33688521385193,0,1,,,,,,1,1,1,1.80040109157562,0,0,1.79993605411659,,,,,,,,,,,,,,,,,,,,,,,,,,,,,,,,,
,3825366847.09447,1.80007642507553,199.777908325195,,,5,,,,24.2400001734495,,,,,0.000247194130696665,1.18647630756073E-7,5.00860175048034,0.000295838943408757,8.23978682123706E-5,3.95491260864342E-8,8.20832403796294E-5,3.12442248920679E-8,7.19377054979945E-6,2.42473046975237E-8,3.00000638438305,3.0215425491333,12,36,1,3,0.81365411837369,0.100549930890359,0.0260549895465374,174.892181396484,1.79596042633057,1.80342948436737,199.777908325195,199.777908325195,,,2.34260535240173,0,1,,,,,,1,1,1,1.79995548725128,0,0,1.80002235362404,,,,,,,,,,,,,,,,,,,,,,,,,,,,,,,,,
,3825367341.7127,1.79947340488434,199.777908325195,,,5,,,,24.2299996316433,,,,,0.000206321830801287,1.86421471499475E-8,10.6482580094782,6.59839669919746E-5,6.87705421716648E-5,6.21374171490655E-9,6.7586317935926E-5,4.34953800615943E-9,1.27073639457071E-5,4.43757875789765E-9,3.0001483816467,15.8532876968384,12,190,1,3,0.648903565199186,0.214867662368215,0.0230478644371033,155.976165771484,1.79851019382477,1.80236983299255,199.777908325195,199.777908325195,,,2.33882570266724,0,1,,,,,,1,1,1,1.79996478557587,0,0,1.80000030225323,,,,,,,,,,,,,,,,,,,,,,,,,,,,,,,,,
,3825367714.52725,1.79942601919174,199.777908325195,,,5,,,,24.2400001734495,,,,,0.000171739399606989,8.98032052227003E-9,4.8131416585344,3.63338703500632E-5,5.72427199435366E-5,2.99324426331916E-9,5.70408615200369E-5,2.16483590080412E-9,4.80303066679128E-6,2.06712281746458E-9,3.00019635294044,83.1824951171875,12,998,1,3,0.555169354766593,0.119196538477022,0.00997588597238064,128.895462036133,1.79851865768433,1.80248594284058,199.777908325195,199.777908325195,,,2.34854340553284,0,1,,,,,,1,1,1,1.80002057552338,0,0,1.80000856518745,,,,,,,,,,,,,,,,,,,,,,,,,,,,,,,,,
,3825368078.84975,1.79973179101944,199.777908325195,,,5,,,,24.2400001734495,,,,,0.000167294438850461,1.00083643074879E-8,1.10621417138565,5.2713220980871E-5,5.57641257077814E-5,3.33608032165911E-9,5.57537326203246E-5,1.56784551791456E-9,1.07657552201204E-6,2.94470581629412E-9,3.00003697228443,436.940734863281,12,5243,1,3,0.546333483316975,0.0882763274429315,0.00533745205029845,122.548828125,1.79721534252167,1.80269026756287,199.777908325195,199.777908325195,,,2.34288954734802,0,1,,,,,,1,1,1,1.80033433437347,0,0,1.80010738968849,,,,,,,,,,,,,,,,,,,,,,,,,,,,,,,,,
,3825368837.8726,1.79995620250702,399.606262207031,,,5,,,,24.2400001734495,,,,,0.000225751989157919,9.55268525735946E-8,13.6415291701613,0.000224102261315024,7.52506797579935E-5,3.18422912600612E-8,7.31278813640042E-5,2.79664926323965E-8,1.77476131142252E-5,1.52252028732848E-8,2.99999933401184,1.73988473415375,18.3920229724668,31,1,3,0.723536719410286,0.192737938102856,0.0261124577373266,176.892761230469,1.79846143722534,1.80313158035278,399.606262207031,399.606262207031,,,2.3517119884491,0,1,,,,,,1,1,1,1.7999781370163,0,0,1.80001482096585,,,,,,,,,,,,,,,,,,,,,,,,,,,,,,,,,
,3825369404.43726,1.7999415397644,399.606262207031,,,5,,,,24.2400001734495,,,,,0.000146308977392661,1.28379786143048E-7,22.5213713899301,0.000689389740119321,4.87685776213327E-5,4.2792313069925E-8,4.50493262673089E-5,3.85493901714246E-8,1.86797314239125E-5,1.85775826006976E-8,3.00006652908124,9.10972499847412,12,109,1,3,0.429057430342665,0.226219313918589,0.0248424187302589,165.299057006836,1.79804277420044,1.80243492126465,399.606262207031,399.606262207031,,,2.35275721549988,0,1,,,,,,1,1,1,1.79996025562286,0,0,1.80000066906214,,,,,,,,,,,,,,,,,,,,,,,,,,,,,,,,,
,3825369792.52534,1.79955041408539,399.606262207031,,,5,,,,24.2400001734495,,,,,9.84803150418267E-5,9.14510015896891E-9,11.9548589379286,5.29276639742938E-5,3.28296219992189E-5,3.04863140655503E-9,3.21175836919068E-5,2.76537585912984E-9,6.80036016729716E-6,1.28329646254309E-9,2.99973953535529,47.8707122802734,12,574,1,3,0.304279990356533,0.116311694548482,0.014458891004324,134.317611694336,1.79842531681061,1.80261087417603,399.606262207031,399.606262207031,,,2.34796380996704,0,1,,,,,,1,1,1,1.80011868476868,0,0,1.80000320076942,,,,,,,,,,,,,,,,,,,,,,,,,,,,,,,,,
,3825370158.5124,1.79953616857529,399.606262207031,,,5,,,,24.2400001734495,,,,,9.09830428823247E-5,4.79622244232024E-9,3.94699991612334,3.66782026167437E-5,3.03270907263277E-5,1.59870969956483E-9,3.02551594163684E-5,1.15146909151987E-9,2.087524996987E-6,1.10904987929176E-9,3.00005838685146,251.044357299805,12,3012,1,3,0.296173506256912,0.0527427972447851,0.00569423567503691,129.086029052734,1.79822993278503,1.80183935165405,399.606262207031,399.606262207031,,,2.3550705909729,0,1,,,,,,1,1,1,1.80024468898773,0,0,1.7999910334746,,,,,,,,,,,,,,,,,,,,,,,,,,,,,,,,,
,3825370717.57573,1.80000829696655,599.5732421875,,,5,,,,24.2400001734495,,,,,0.000214516817423211,3.83194360006825E-7,18.3592990567036,0.00104849487790404,7.15055687801267E-5,1.27731387192675E-7,6.78659352141944E-5,1.11275156821301E-7,2.25224599915775E-5,6.27148048594582E-8,3.00000155348504,1.00057637691498,31.9815665633281,32,1,3,0.671977332514286,0.233897599845754,0.0263204351067543,178.095443725586,1.79581487178802,1.80225825309753,599.5732421875,599.5732421875,,,2.35769653320313,0,1,,,,,,1,1,1,1.80018198490143,0,0,1.79995216672116,,,,,,,,,,,,,,,,,,,,,,,,,,,,,,,,,
,3825371440.53636,1.80038106441498,599.5732421875,,,5,,,,24.2400001734495,,,,,0.000119493509726595,1.39916401383172E-7,31.1923361733638,0.00128552358195297,3.98309853285704E-5,4.66385843337492E-8,3.40727609122467E-5,3.70123770623013E-8,2.06289688559963E-5,2.83767773514588E-8,3.00001390226426,5.2525954246521,12,63,1,3,0.326471995928644,0.224606709208054,0.027585731819272,171.001342773438,1.79567408561707,1.80255353450775,599.5732421875,599.5732421875,,,2.35644745826721,0,1,,,,,,1,1,1,1.80086219310761,0,0,1.79999733106657,,,,,,,,,,,,,,,,,,,,,,,,,,,,,,,,,
,3825371870.51361,1.79956543445587,599.5732421875,,,5,,,,24.2400001734495,,,,,6.75791146793535E-5,3.95997029534102E-8,21.1049095936875,0.000534805615418584,2.25253012231969E-5,1.31992737934936E-8,2.10143644702553E-5,1.25802179508603E-8,8.11083726300982E-6,3.99486482680679E-9,3.0001425512463,27.5553760528564,12,330,1,3,0.192890486636601,0.113304161215456,0.0194361601024866,144.771484375,1.79838752746582,1.80293238162994,599.5732421875,599.5732421875,,,2.34876370429993,0,1,,,,,,1,1,1,1.80005371570587,0,0,1.80011193087844,,,,,,,,,,,,,,,,,,,,,,,,,,,,,,,,,
,3825372237.77164,1.79998391866684,599.5732421875,,,5,,,,24.2400001734495,,,,,5.35414083044251E-5,6.79586034281708E-9,11.1759236499462,7.62290693978489E-5,1.78480796245699E-5,2.26540653967131E-9,1.75096209267429E-5,1.89230766408931E-9,3.45935272655957E-6,1.24548725180725E-9,2.99984140762793,144.4619140625,12,1733,1,3,0.169053547752582,0.0524569739578715,0.00712516810745001,128.824432373047,1.79721224308014,1.80288767814636,599.5732421875,599.5732421875,,,2.35100388526917,0,1,,,,,,1,1,1,1.80073177814484,0,0,1.80007498264313,,,,,,,,,,,,,,,,,,,,,,,,,,,,,,,,,
,3825372596.95718,1.79956239461899,599.5732421875,,,5,,,,24.2400001734495,,,,,4.61548083614335E-5,2.20074671531258E-8,7.3346394858996,0.000320302819866619,1.53845288397446E-5,7.33562818538111E-9,1.52586440322097E-5,5.73489273570333E-9,1.96405445933717E-6,4.57410605300478E-9,3.00007942018976,758.4951171875,12,9101,1,3,0.143713456050501,0.0519453778811977,0.00604260759428143,103.791015625,1.7949606180191,1.80641233921051,599.5732421875,599.5732421875,,,2.35689568519592,0,1,,,,,,1,1,1,1.79993569850922,0,0,1.7999112383794,,,,,,,,,,,,,,,,,,,,,,,,,,,,,,,,,
,3825373417.6136,1.79992932081223,799.615844726563,,,5,,,,24.2400001734495,,,,,0.000133627497453299,1.40445866586884E-7,37.1122286740615,0.00138670657011115,4.4542429636514E-5,4.68152158007138E-8,3.55205906911882E-5,3.18869460543907E-8,2.68759311442949E-5,3.42766261728278E-8,3.00000468191247,3.0215425491333,12,36,1,3,0.343590172519263,0.279956527469736,0.0260972250252962,174.902084350586,1.79816949367523,1.80232727527618,799.615844726563,799.615844726563,,,2.34950304031372,0,1,,,,,,1,1,1,1.79991400241852,0,0,1.79999094511333,,,,,,,,,,,,,,,,,,,,,,,,,,,,,,,,,
,3825373902.6082,1.79971081018448,799.615844726563,,,5,,,,24.2400001734495,,,,,5.80374190496826E-5,5.99078724299299E-8,35.4474633640504,0.00236146736121839,1.93464559734133E-5,1.99699613698249E-8,1.57605447828263E-5,1.8677763373409E-8,1.12200974541108E-5,7.06686015704546E-9,2.99989926472528,15.8532876968384,12,190,1,3,0.140297935795218,0.131494385458478,0.0230584628880024,156.042572021484,1.79824841022491,1.80342769622803,799.615844726563,799.615844726563,,,2.35825610160828,0,1,,,,,,1,1,1,1.80019116401672,0,0,1.8000120789774,,,,,,,,,,,,,,,,,,,,,,,,,,,,,,,,,
,3825374273.01463,1.7995907664299,799.615844726563,,,5,,,,24.2400001734495,,,,,3.40249530355951E-5,9.9373325793151E-9,22.3526073147302,0.00025380349278611,1.13419865369848E-5,3.31254218661881E-9,1.04897601356147E-5,2.52930637253672E-9,4.31341986159644E-6,2.13905236307448E-9,2.99991125228759,83.1824951171875,12,998,1,3,0.0977393072122306,0.0557079881615681,0.0100258262827992,129.071594238281,1.79888916015625,1.80308890342712,799.615844726563,799.615844726563,,,2.34731698036194,0,1,,,,,,1,1,1,1.80012822151184,0,0,1.80030393997828,,,,,,,,,,,,,,,,,,,,,,,,,,,,,,,,,
,3825374636.84121,1.7994499206543,799.615844726563,,,5,,,,24.2400001734495,,,,,2.53467905666371E-5,4.95281536926351E-9,13.4391387334772,0.000152852870423807,8.44888318142402E-6,1.65092927106711E-9,8.21753032240822E-6,1.05607328077559E-9,1.96362481488983E-6,1.26896677801196E-9,3.00001669124333,436.940734863281,12,5243,1,3,0.0779978696376338,0.0307800294872969,0.00540036801248789,122.17219543457,1.79785561561584,1.80289328098297,799.615844726563,799.615844726563,,,2.35865449905396,0,1,,,,,,1,1,1,1.79985344409943,0,0,1.8000322163105,,,,,,,,,,,,,,,,,,,,,,,,,,,,,,,,,
,3825375366.02712,1.80016934871674,999.532470703125,,,5,,,,24.2400001734495,,,,,0.000168370289464192,9.91731190253155E-7,32.452452826471,0.00680832567723066,5.61232264751748E-5,3.30575865672011E-7,4.73588570783121E-5,3.26598648847851E-7,3.0115697007039E-5,5.11246079257152E-8,3.00001086962932,1.73988473415375,18.3920229724668,31,1,3,0.464337037358277,0.310281515004685,0.0262898094952106,176.966415405273,1.79673063755035,1.80313420295715,999.532470703125,999.532470703125,,,2.35933876037598,0,1,,,,,,1,1,1,1.80045354366302,0,0,1.80004273170282,,,,,,,,,,,,,,,,,,,,,,,,,,,,,,,,,
,3825375926.70422,1.8004692196846,999.532470703125,,,5,,,,24.2400001734495,,,,,6.71186176648919E-5,2.11931588730715E-7,48.0347600587335,0.0181122087228815,2.2368242962161E-5,7.06292446568826E-8,1.49571885176614E-5,6.39160213245808E-8,1.66319212618809E-5,3.00538253611335E-8,3.00062091503711,9.10972499847412,12,109,1,3,0.132863246025046,0.178498934011159,0.0255170445889235,164.877807617187,1.7964334487915,1.8025062084198,999.532470703125,999.532470703125,,,2.35967898368835,0,1,,,,,,1,1,1,1.80058085918427,0,0,1.800037753582,,,,,,,,,,,,,,,,,,,,,,,,,,,,,,,,,
,3825376315.2969,1.79960525035858,999.532470703125,,,5,,,,24.2400001734495,,,,,2.75028621593401E-5,3.04285613324231E-8,35.656997185944,0.00280948051699226,9.16817429430615E-6,1.01434662401454E-8,7.44933661704585E-6,9.2408228682935E-9,5.34441800916768E-6,4.18295351178966E-9,2.99981885994692,47.8707122802734,12,574,1,3,0.0647264343824323,0.0639319641895476,0.0145048908889294,134.329284667969,1.79792952537537,1.80341482162476,999.532470703125,999.532470703125,,,2.35878372192383,0,1,,,,,,1,1,1,1.80002987384796,0,0,1.8000090777874,,,,,,,,,,,,,,,,,,,,,,,,,,,,,,,,,
,3825376680.317,1.79958695173264,999.532470703125,,,5,,,,24.2400001734495,,,,,1.7379951648444E-5,1.09006559312933E-8,19.3395971247425,0.000450199134747535,5.79335517022224E-6,3.63357578178451E-9,5.46644950699857E-6,3.15866334997443E-9,1.9185655880829E-6,1.7960286198998E-9,2.99998034606556,251.044357299805,12,3012,1,3,0.05186390272156,0.0247537614996736,0.00575431808829308,128.96662902832,1.79773771762848,1.80225467681885,999.532470703125,999.532470703125,,,2.35920071601868,0,1,,,,,,1,1,1,1.80011212825775,0,0,1.8000279823939,,,,,,,,,,,,,,,,,,,,,,,,,,,,,,,,,
,3825377219.82194,1.80086386203766,1499.66418457031,,,5,,,,24.2400001734495,,,,,0.000181226082907059,1.84834302258754E-6,19.0632078510956,0.00505774660413634,6.04087559508117E-5,6.16114969621335E-7,5.70958696020949E-5,5.90919245452349E-7,1.97301664946167E-5,1.74390656703634E-7,2.99999693843429,1.00057637691498,31.9815665633281,32,1,3,0.565120539124434,0.204934143186081,0.0264323465526104,177.928466796875,1.79595053195953,1.80201470851898,1499.66418457031,1499.66418457031,,,2.35875988006592,0,1,,,,,,1,1,1,1.80023443698883,0,0,1.80001133925294,,,,,,,,,,,,,,,,,,,,,,,,,,,,,,,,,
,3825377938.61837,1.79996818304062,1499.66418457031,,,5,,,,24.2400001734495,,,,,0.000103091102980968,3.29389895867924E-7,42.6589886451618,0.00759087431082607,3.43636677411364E-5,1.09796525709716E-7,2.52710351443412E-5,8.25992884138839E-8,2.328597095585E-5,7.23369519087195E-8,3.00000290299509,5.2525954246521,12,63,1,3,0.237368179408935,0.246067333153236,0.0278921313583851,181.282028198242,1.79809248447418,1.80221390724182,1499.66418457031,1499.66418457031,,,2.35221290588379,0,1,,,,,,1,1,1,1.79998767375946,0,0,1.79998434308064,,,,,,,,,,,,,,,,,,,,,,,,,,,,,,,,,
,3825378366.57507,1.79955732822418,1499.66418457031,,,5,,,,24.2400001734495,,,,,3.64340682831321E-5,9.84141410195756E-8,55.1406222789437,0.0685828076514814,1.21440221080484E-5,3.28029111379701E-8,6.94108886571406E-6,3.12926058946962E-8,9.96486619674487E-6,9.83889198257557E-9,3.00016485139513,27.5553760528564,12,330,1,3,0.0519203805820338,0.10886652818912,0.0194914601743221,144.883209228516,1.79819679260254,1.80129146575928,1499.66418457031,1499.66418457031,,,2.35970211029053,0,1,,,,,,1,1,1,1.80006146430969,0,0,1.79994931768198,,,,,,,,,,,,,,,,,,,,,,,,,,,,,,,,,
,3825378734.3559,1.79975819587708,1499.66418457031,,,5,,,,24.2299996316433,,,,,1.29223693189204E-5,9.83138021685674E-9,40.6240824557521,0.00196404059033116,4.30761141880697E-6,3.27724464760176E-9,3.2694671940962E-6,2.52474824060303E-9,2.80465691345036E-6,2.08949247469483E-9,2.99989206605347,144.4619140625,12,1733,1,3,0.0292872080108637,0.0311047983509721,0.0072008678689599,128.847885131836,1.79666328430176,1.8028576374054,1499.66418457031,1499.66418457031,,,2.35927987098694,0,1,,,,,,1,1,1,1.80012047290802,0,0,1.79998063842456,,,,,,,,,,,,,,,,,,,,,,,,,,,,,,,,,
,3825379099.74999,1.8010870218277,1499.66418457031,,,5,,,,24.2299996316433,,,,,7.71700749487279E-6,6.62524923835199E-9,21.195811541099,0.000872477269283928,2.57235065175709E-6,2.20842913624886E-9,2.39833173299027E-6,1.58229430598393E-9,9.30049877225423E-7,1.54061805100541E-9,2.99998271604283,758.4951171875,12,9101,10,3,0.02124051848187,0.0142027157554127,0.00609494373202324,103.803680419922,1.7938334941864,1.80733668804169,1499.66418457031,1499.66418457031,,,2.35835027694702,0,1,,,,,,1,1,1,1.799973487854,0,0,1.79997410440958,,,,,,,,,,,,,,,,,,,,,,,,,,,,,,,,,
,3825379941.20083,1.80011343955994,2000.04809570313,,,5,,,,24.2400001734495,,,,,0.000121998278406561,4.65089945615874E-7,26.5930417687499,0.00314780253257254,4.06660871071427E-5,1.55029960160932E-7,3.636396514165E-5,1.37671103803117E-7,1.82041940162861E-5,7.12808229829842E-8,3.0000004201322,3.0215425491333,12,36,1,3,0.354936376618713,0.194347933947144,0.0260537397116423,175.522384643555,1.79697751998901,1.8018182516098,2000.04809570313,2000.04809570313,,,2.3582067489624,0,1,,,,,,1,1,1,1.80028331279755,0,0,1.79996732828465,,,,,,,,,,,,,,,,,,,,,,,,,,,,,,,,,
,3825380441.33807,1.79968929290771,2000.04809570313,,,5,,,,24.2400001734495,,,,,6.37552407323363E-5,2.09469433158815E-7,43.6275362545411,0.0165294715558445,2.1252777802528E-5,6.9826531406819E-8,1.53836180770085E-5,6.76598396130422E-8,1.46637259652642E-5,1.72595072885895E-8,2.9998544813635,15.8532876968384,12,190,1,3,0.13186632051601,0.165033450295196,0.023423558101058,156.251663208008,1.79597330093384,1.80184996128082,2000.04809570313,2000.04809570313,,,2.35884881019592,0,1,,,,,,1,1,1,1.8001856803894,0,0,1.79993502820124,,,,,,,,,,,,,,,,,,,,,,,,,,,,,,,,,
,3825380811.90156,1.79956245422363,2000.04809570313,,,5,,,,24.2400001734495,,,,,2.32618102150503E-5,2.75387750482947E-8,54.9306583680639,0.0187623118159163,7.75452464331326E-6,9.18028768115801E-9,4.45549695747682E-6,7.62598969703297E-9,6.34674714366875E-6,5.11096498222875E-9,2.99977255667231,83.1824951171875,12,998,1,3,0.0357444645644159,0.0681086015109093,0.0101716415956616,129.050323486328,1.79713606834412,1.80186784267426,2000.04809570313,2000.04809570313,,,2.35898494720459,0,1,,,,,,1,1,1,1.79984211921692,0,0,1.79997553626696,,,,,,,,,,,,,,,,,,,,,,,,,,,,,,,,,
,3825381176.32331,1.7997710108757,2000.04809570313,,,5,,,,24.2400001734495,,,,,8.25180641636148E-6,8.55393936252622E-9,41.5920295573086,0.00359745344861195,2.75064719557006E-6,2.85135982734115E-9,2.05718274784003E-6,2.23883892253394E-9,1.8259406169114E-6,1.76574435973105E-9,2.99995085871103,436.940734863281,12,5243,1,3,0.0176442477816667,0.0208323423458335,0.0054511409252882,122.273071289062,1.79772555828094,1.80269777774811,2000.04809570313,2000.04809570313,,,2.35901403427124,0,1,,,,,,1,1,1,1.80001246929169,0,0,1.8000489850839,,,,,,,,,,,,,,,,,,,,,,,,,,,,,,,,,
,3825381927.3268,1.79999107122421,2499.86474609375,,,5,,,,24.2400001734495,,,,,0.000115016746782748,7.23355956206019E-7,20.1510462489296,0.0032975563275131,3.83387863333904E-5,2.4111783912956E-7,3.59919812106606E-5,2.34153997405689E-7,1.32075669995961E-5,5.7530147274665E-8,3.00001011462839,1.73988473415375,18.3920229724668,31,1,3,0.35495351595676,0.139906411754019,0.0263663697987795,176.965194702148,1.7962783575058,1.8025838136673,2499.86474609375,2499.86474609375,,,2.35837626457214,0,1,,,,,,1,1,1,1.79974973201752,0,0,1.79998090838598,,,,,,,,,,,,,,,,,,,,,,,,,,,,,,,,,
,3825382511.74909,1.79882079362869,2499.86474609375,,,5,,,,24.2400001734495,,,,,7.3461835706982E-5,1.10437154488143E-6,29.8050008636853,0.0193048728307493,2.45247511095526E-5,3.68687183079951E-7,2.12806678827088E-5,3.64299390480799E-7,1.21900201579551E-5,5.67114896890158E-8,2.99541615647091,9.10972499847412,12,109,1,3,0.199104482644359,0.140297895732149,0.0256871562451124,165.956146240234,1.79645276069641,1.80266165733337,2499.86474609375,2499.86474609375,,,2.35841608047485,0,1,,,,,,1,1,1,1.80019795894623,0,0,1.80003501946413,,,,,,,,,,,,,,,,,,,,,,,,,,,,,,,,,
,3825382898.42351,1.80012357234955,2499.86474609375,,,5,,,,24.2299996316433,,,,,3.867305472741E-5,7.26989921328223E-8,42.4415346683061,0.00888830258055348,1.28916237135392E-5,2.42341355637891E-8,9.51358428559073E-6,2.17570500351967E-8,8.69975149141895E-6,1.06735233306559E-8,2.99985910128562,47.8707122802734,12,574,1,3,0.0796568722659466,0.100114623336791,0.0146759124472737,134.990753173828,1.79790508747101,1.80261492729187,2499.86474609375,2499.86474609375,,,2.35939931869507,0,1,,,,,,1,1,1,1.80054473876953,0,0,1.80001491611287,,,,,,,,,,,,,,,,,,,,,,,,,,,,,,,,,
,3825383262.8735,1.79940360784531,2499.86474609375,,,5,,,,24.2400001734495,,,,,1.47989110182159E-5,1.90414046904446E-8,52.4502495740479,0.0144387338238544,4.93275574223142E-6,6.34685877976624E-9,3.00626835739642E-6,6.04949928560081E-9,3.91080935048413E-6,1.9199413438465E-9,3.00013051356184,251.044357299805,12,3012,1,3,0.0254346492129498,0.0418093895852579,0.00582468509674072,129.098022460938,1.7961140871048,1.80282771587372,2499.86474609375,2499.86474609375,,,2.35920739173889,0,1,,,,,,1,1,1,1.79991102218628,0,0,1.80010343988736,,,,,,,,,,,,,,,,,,,,,,,,,,,,,,,,,
,3825383826.01108,1.80017602443695,2999.94604492188,,,5,,,,24.2400001734495,,,,,0.000103991913663032,9.78313197122479E-7,17.9645444199194,0.0051208253434961,3.46640802097812E-5,3.26105424362399E-7,3.29741216857859E-5,2.94970607716644E-7,1.06913869933292E-5,1.39057859834869E-7,2.99999056757574,1.00057637691498,31.9815665633281,32,1,3,0.32638344191307,0.111717821690141,0.0271840058267117,176.924789428711,1.79627895355225,1.80311143398285,2999.94604492188,2999.94604492188,,,2.35919427871704,0,1,,,,,,1,1,1,1.80014395713806,0,0,1.79999845736736,,,,,,,,,,,,,,,,,,,,,,,,,,,,,,,,,
,3825384548.7017,1.80095851421356,2999.94604492188,,,5,,,,24.2400001734495,,,,,6.91785060887664E-5,1.13120118087157E-6,23.9210292558712,0.0122921113360541,2.30594617321407E-5,3.7706640135E-7,2.10787737549667E-5,3.60760324417097E-7,9.35008408320417E-6,1.09686185791604E-7,3.00000524263514,5.2525954246521,12,63,1,3,0.203789884692905,0.105429801718906,0.0240038260817528,163.778762817383,1.79674458503723,1.80273175239563,2999.94604492188,2999.94604492188,,,2.35938215255737,0,1,,,,,,1,1,1,1.80060994625092,0,0,1.79999005514033,,,,,,,,,,,,,,,,,,,,,,,,,,,,,,,,,
,3825384975.89461,1.79971611499786,2999.94604492188,,,5,,,,24.2400001734495,,,,,4.37347014760442E-5,1.25789464805456E-7,29.9056179455861,0.0048026425515059,1.45778851544264E-5,4.19288187567747E-8,1.26368086547542E-5,3.85219096789182E-8,7.2681361158673E-6,1.65556128556975E-8,3.00007175339591,27.5553760528564,12,330,1,3,0.112001109971924,0.0917674375804339,0.0197998713701963,145.423583984375,1.79599940776825,1.8021103143692,2999.94604492188,2999.94604492188,,,2.35956978797913,0,1,,,,,,1,1,1,1.80030715465546,0,0,1.79995302294121,,,,,,,,,,,,,,,,,,,,,,,,,,,,,,,,,
,3825385341.31007,1.7978709936142,2999.94604492188,,,5,,,,24.2400001734495,,,,,2.34096648969089E-5,3.93237726387108E-8,41.7936785360087,0.00532606665208789,7.80281850492598E-6,1.31072470357895E-8,5.81738769955511E-6,1.11491889020958E-8,5.20019009016788E-6,6.89169875158493E-9,3.00015499298493,144.4619140625,12,1733,1,3,0.0518375075614645,0.0574798785765777,0.0072258934378624,128.987670898438,1.79521644115448,1.80248069763184,2999.94604492188,2999.94604492188,,,2.35948920249939,0,1,,,,,,1,1,1,1.80021154880524,0,0,1.80005188385646,,,,,,,,,,,,,,,,,,,,,,,,,,,,,,,,,
,3825385705.12547,1.79995334148407,2999.94604492188,,,5,,,,24.2299996316433,,,,,9.18165220729787E-6,1.71615548782774E-8,49.8649461777845,0.0312130398621139,3.06049946977945E-6,5.72042247078496E-9,1.97277191834144E-6,4.82208546449492E-9,2.33983502895476E-6,3.07745430792536E-9,3.00005025256859,758.4951171875,12,9101,1,3,0.0140400403886905,0.0269677159512343,0.00616783555597067,103.7529296875,1.79407358169556,1.80708694458008,2999.94604492188,2999.94604492188,,,2.36001992225647,0,1,,,,,,1,1,1,1.80096399784088,0,0,1.80006912401167,,,,,,,,,,,,,,,,,,,,,,,,,,,,,,,,,
,3825386520.83411,1.80015629529953,3499.85083007812,,,5,,,,24.2299996316433,,,,,6.38954631872952E-5,4.73903592224249E-7,22.3607343361252,0.00553853453268452,2.12984541575551E-5,1.57967615079372E-7,1.96969588502762E-5,1.20976815006466E-7,8.10271322163157E-6,1.01579415457838E-7,3.00000472872956,3.0215425491333,12,36,1,3,0.192821939965059,0.0880063654633075,0.0284766033291817,173.699340820313,1.79629015922546,1.80340135097504,3499.85083007812,3499.85083007812,,,2.35894417762756,0,1,,,,,,1,1,1,1.79979240894318,0,0,1.79996868183738,,,,,,,,,,,,,,,,,,,,,,,,,,,,,,,,,
,3825387002.86655,1.79987901449203,3499.85083007812,,,5,,,,24.2400001734495,,,,,4.19408552981542E-5,3.38534438839049E-7,24.0121187922023,0.00802844585682095,1.39803184309406E-5,1.12845081989017E-7,1.27704533862791E-5,1.05471852442025E-7,5.68900902964393E-6,4.01210776469884E-8,2.99999284746852,15.8532876968384,12,190,1,3,0.118090679303985,0.0732774082015367,0.0235162191092968,156.383758544922,1.79756987094879,1.80166113376617,3499.85083007812,3499.85083007812,,,2.35945773124695,0,1,,,,,,1,1,1,1.80027031898499,0,0,1.79998508576424,,,,,,,,,,,,,,,,,,,,,,,,,,,,,,,,,
,3825387370.65112,1.79962658882141,3499.85083007812,,,5,,,,24.2400001734495,,,,,2.66221881885596E-5,4.38206107295958E-8,30.034021223347,0.00246868572598087,8.87348823000601E-6,1.46059246064469E-8,7.68203041239763E-6,1.4053051235696E-8,4.44130635185788E-6,3.98055078803355E-9,3.00019423010398,83.1824951171875,12,998,1,3,0.0698697313085571,0.0535616922316676,0.0103027727454901,129.445037841797,1.79578936100006,1.80315709114075,3499.85083007812,3499.85083007812,,,2.35936737060547,0,1,,,,,,1,1,1,1.79993748664856,0,0,1.79998366711503,,,,,,,,,,,,,,,,,,,,,,,,,,,,,,,,,
,3825387734.96644,1.79944521188736,3499.85083007812,,,5,,,,24.2299996316433,,,,,1.40265111585944E-5,1.68886366057226E-8,41.5223257180752,0.00476002750517089,4.67551248557551E-6,5.62955609000607E-9,3.50054436519313E-6,5.04068464539916E-9,3.09945255651495E-6,2.50667111447863E-9,2.99999437534769,436.940734863281,12,5243,1,3,0.0300003624383465,0.0354091633963241,0.00545342080295086,122.335113525391,1.79601633548737,1.80268692970276,3499.85083007812,3499.85083007812,,,2.35936665534973,0,1,,,,,,1,1,1,1.7997944355011,0,0,1.79994252125422,,,,,,,,,,,,,,,,,,,,,,,,,,,,,,,,,
,3825388436.73991,1.80009186267853,4000.23486328125,,,5,,,,24.2400001734495,,,,,5.89078987732559E-5,9.58568666716703E-7,21.5057545204146,0.00915839253864182,1.96360111761182E-5,3.19523619831968E-7,1.82689668760971E-5,3.12571761069541E-7,7.198457070005E-6,6.62890474543868E-8,2.99999313734865,1.73988473415375,18.3920229724668,31,1,3,0.179984804679954,0.076133941937533,0.0269610416144133,176.710922241211,1.79610693454742,1.80275762081146,4000.23486328125,4000.23486328125,,,2.35964417457581,0,1,,,,,,1,1,1,1.8001800775528,0,0,1.80000707579822,,,,,,,,,,,,,,,,,,,,,,,,,,,,,,,,,
,3825389023.72398,1.8000927567482,4000.23486328125,,,5,,,,24.2299996316433,,,,,3.86443237338317E-5,1.01977564889424E-6,21.9911764301093,0.0197774335407016,1.28716787749918E-5,3.39667596864528E-7,1.19351551611143E-5,3.29844828303767E-7,4.81997777657759E-6,8.10954104803851E-8,3.00227533714663,9.10972499847412,12,109,1,3,0.113746067275284,0.0590058301206014,0.0258511006832123,166.451263427734,1.79735791683197,1.80239903926849,4000.23486328125,4000.23486328125,,,2.35911798477173,0,1,,,,,,1,1,1,1.79995656013489,0,0,1.79998114441015,,,,,,,,,,,,,,,,,,,,,,,,,,,,,,,,,
,3825389426.96889,1.79953843355179,4000.23486328125,,,5,,,,24.2400001734495,,,,,2.61001047211311E-5,1.14315736470668E-7,23.9051950534241,0.0044854403512298,8.69972946081669E-6,3.8103907667606E-8,7.95344245605661E-6,3.11073941518095E-8,3.52534335768845E-6,2.2005404077758E-8,3.00010532956055,47.8707122802734,12,574,1,3,0.0724064199072134,0.0470525990519855,0.0147882085293531,135.377243041992,1.79740583896637,1.80273270606995,4000.23486328125,4000.23486328125,,,2.35950970649719,0,1,,,,,,1,1,1,1.80018663406372,0,0,1.80001181070922,,,,,,,,,,,,,,,,,,,,,,,,,,,,,,,,,
,3825389792.08143,1.79994976520538,4000.23486328125,,,5,,,,24.2299996316433,,,,,1.64675847413018E-5,2.4054495668066E-8,30.8487058182686,0.00176945179704546,5.48906888657729E-6,8.01798113251742E-9,4.71249908289066E-6,5.77603023602396E-9,2.81464556122888E-6,5.56106969511643E-9,3.00006887899892,251.044357299805,12,3012,1,3,0.0434113427151995,0.0328855569120945,0.00590087100863457,129.234664916992,1.79592847824097,1.80169951915741,4000.23486328125,4000.23486328125,,,2.36030149459839,0,1,,,,,,1,1,1,1.80077481269836,0,0,1.79992916186651,,,,,,,,,,,,,,,,,,,,,,,,,,,,,,,,,
,3825390320.51053,1.80021017789841,4500.126953125,,,5,,,,24.2400001734495,,,,,5.3286939062907E-5,8.14655930522715E-7,19.2146172070745,0.00872976562506077,1.77622624409356E-5,2.71551203568413E-7,1.67727701327421E-5,2.44792580610758E-7,5.84569491975656E-6,1.17544241191898E-7,3.00000854283629,1.00057637691498,31.9815665633281,32,1,3,0.165903683053617,0.0610646773710664,0.0269226413220167,180.278961181641,1.79665374755859,1.80189049243927,4500.126953125,4500.126953125,,,2.36014151573181,0,1,,,,,,1,1,1,1.80012106895447,0,0,1.79998591671819,,,,,,,,,,,,,,,,,,,,,,,,,,,,,,,,,
,3825391033.48078,1.80023103952408,4500.126953125,,,5,,,,24.2400001734495,,,,,3.61856636662076E-5,1.04919133661398E-6,23.7823234977955,0.02276513514102,1.20619084331185E-5,3.49731041215564E-7,1.10376609043375E-5,2.90702056338829E-7,4.86412138107114E-6,1.94432804922673E-7,2.99999489026565,5.2525954246521,12,63,10,3,0.106681107101034,0.0550092501818516,0.0380698144435883,161.883255004883,1.79678022861481,1.80185973644257,4500.126953125,4500.126953125,,,2.35966897010803,0,1,,,,,,1,1,1,1.80038237571716,0,0,1.80002559894739,,,,,,,,,,,,,,,,,,,,,,,,,,,,,,,,,
,3825391484.81055,1.7993215918541,4500.126953125,,,5,,,,24.2299996316433,,,,,2.45032701937943E-5,2.44335743577721E-7,21.0960189244781,0.00913769382298937,8.16779210407043E-6,8.14456005811713E-8,7.62037480281186E-6,7.40520194282764E-8,2.93984960839588E-6,3.39069944498455E-8,2.99998700769857,27.5553760528564,12,330,1,3,0.0698466373351897,0.0412763351537849,0.019787210971117,145.198104858398,1.79582703113556,1.80288827419281,4500.126953125,4500.126953125,,,2.35910129547119,0,1,,,,,,1,1,1,1.80001223087311,0,0,1.7999977450217,,,,,,,,,,,,,,,,,,,,,,,,,,,,,,,,,
,3825391852.16201,1.79968774318695,4500.126953125,,,5,,,,24.2400001734495,,,,,1.68596951330255E-5,3.2310339223296E-8,24.3059853819207,0.00175082574380254,5.61989949002678E-6,1.07701152061703E-8,5.12175318949827E-6,9.86595660086347E-9,2.3132043886928E-6,4.3195233422288E-9,2.99999940620738,144.4619140625,12,1733,1,3,0.0480218470326201,0.0283188457972109,0.00731167802587151,129.188262939453,1.79781293869019,1.80303359031677,4500.126953125,4500.126953125,,,2.35995316505432,0,1,,,,,,1,1,1,1.80016505718231,0,0,1.80009113152822,,,,,,,,,,,,,,,,,,,,,,,,,,,,,,,,,
,3825392218.34383,1.79937833547592,4500.126953125,,,5,,,,24.2299996316433,,,,,1.03061844566296E-5,1.7430468655179E-8,31.5677144335015,0.00404592420132056,3.43546484751077E-6,5.81027465523245E-9,2.92709183447508E-6,5.0976938606893E-9,1.79848606083881E-6,2.78797576602223E-9,2.99993884789628,758.4951171875,12,9101,1,3,0.024443710763532,0.023819811231621,0.00619358150288463,103.699493408203,1.7946971654892,1.80370473861694,4500.126953125,4500.126953125,,,2.35893607139587,0,1,,,,,,1,1,1,1.8001594543457,0,0,1.80002163302514,,,,,,,,,,,,,,,,,,,,,,,,,,,,,,,,,
,3825393053.84154,1.80012208223343,4999.93115234375,,,5,,,,24.2400001734495,,,,,3.36746911018184E-5,5.75913725886543E-7,21.8054870038849,0.013908629053651,1.12248883050237E-5,1.91971092677889E-7,1.04217504440075E-5,1.13894547729604E-7,4.16956054555952E-6,1.54534567076145E-7,3.0000023329183,3.0215425491333,12,36,1,3,0.102027228388401,0.0455085979421717,0.0264669321477413,174.361892700195,1.79796385765076,1.8031325340271,4999.93115234375,4999.93115234375,,,2.35955262184143,0,1,,,,,,1,1,1,1.80029237270355,0,0,1.80005763423058,,,,,,,,,,,,,,,,,,,,,,,,,,,,,,,,,
,3825393545.83778,1.80040150880814,4999.93115234375,,,5,,,,24.2400001734495,,,,,2.27747563494717E-5,5.6845898760824E-7,20.2400380465765,0.0199216634095556,7.59124932457571E-6,1.89477939500773E-7,7.1225010711895E-6,1.70240000357876E-7,2.62622253413064E-6,8.31879308289912E-8,3.00013283396466,15.8532876968384,12,190,1,3,0.0665721476103062,0.035560969952592,0.0239215418696403,156.750579833984,1.79576373100281,1.80374872684479,4999.93115234375,4999.93115234375,,,2.35987138748169,0,1,,,,,,1,1,1,1.80105757713318,0,0,1.80001839724454,,,,,,,,,,,,,,,,,,,,,,,,,,,,,,,,,
,3825393915.58031,1.7994636297226,4999.93115234375,,,5,,,,24.2400001734495,,,,,1.61268790057577E-5,4.37793760725453E-8,20.8867317876453,0.00218282066900426,5.37596413921834E-6,1.45940423884453E-8,5.02269373305698E-6,1.36252010413223E-8,1.91664761760521E-6,5.22876369893378E-9,2.99981149206523,83.1824951171875,12,998,1,3,0.0469216069580301,0.0253573418734736,0.0103448620066047,129.28141784668,1.7984356880188,1.80262339115143,4999.93115234375,4999.93115234375,,,2.35989499092102,0,1,,,,,,1,1,1,1.79996085166931,0,0,1.79999515811602,,,,,,,,,,,,,,,,,,,,,,,,,,,,,,,,,
,3825394280.78196,1.7996768951416,4999.93115234375,,,5,,,,24.2299996316433,,,,,1.08433146515025E-5,6.37818881416975E-9,26.0242338706477,0.000643342305191616,3.614273129879E-6,2.12596583141247E-9,3.24781674407626E-6,1.71740883110934E-9,1.58576689783311E-6,1.25309122699065E-9,3.00013702945177,436.940734863281,12,5243,1,3,0.0296444457430581,0.0202139176180796,0.00554107083007693,122.086730957031,1.7955082654953,1.80273747444153,4999.93115234375,4999.93115234375,,,2.35953617095947,0,1,,,,,,1,1,1,1.79983758926392,0,0,1.80005212961617,,,,,,,,,,,,,,,,,,,,,,,,,,,,,,,,,
,3825405417.16339,1.80000394582748,99.9204711914062,,,5,,,,24.2400001734495,,,,,0.000255067098381105,9.90135018011598E-8,0.587959455959502,0.000248715151360099,8.50221811714107E-5,3.30044288031844E-8,8.50177045751318E-5,2.53424108100348E-8,8.72467718484716E-7,2.11436641800776E-8,3.00000652614254,1.73988473415375,18.3920229724668,31,1,3,0.845543526650108,0.0273162077878142,0.026124756783247,176.880615234375,1.79728627204895,1.80259692668915,99.9204711914062,99.9204711914062,,,2.35580110549927,0,1,,,,,,1,1,1,1.80004668235779,0,0,1.80001961994171,,,,,,,,,,,,,,,,,,,,,,,,,,,,,,,,,
,3825406004.55539,1.80013889074326,99.9204711914062,,,5,,,,24.2400001734495,,,,,0.000250448411219638,7.31263939361889E-8,2.37206016592876,0.000238325160903531,8.34845964358573E-5,2.43759880801095E-8,8.34130611263348E-5,1.40244565508071E-8,3.45529674446266E-6,1.99374876385207E-8,2.99993557987744,9.10972499847412,12,109,1,3,0.822901206406445,0.110364070410233,0.0248976498842239,165.023834228516,1.79641032218933,1.80175495147705,99.9204711914062,99.9204711914062,,,2.35382533073425,0,1,,,,,,1,1,1,1.79996848106384,0,0,1.80004722526275,,,,,,,,,,,,,,,,,,,,,,,,,,,,,,,,,
,3825406415.93577,1.7998833656311,99.9204711914062,,,5,,,,24.2400001734495,,,,,0.000233529333111072,1.0537313394538E-8,2.19729205659527,3.52737366177052E-5,7.78461188039109E-5,3.51257351467321E-9,7.77888808569595E-5,2.18835701215821E-9,2.9846654509954E-6,2.74759281614319E-9,2.99988408798281,47.8707122802734,12,574,1,3,0.757873767097833,0.149370526762205,0.0143108079209924,134.115112304688,1.7967734336853,1.80204689502716,99.9204711914062,99.9204711914062,,,2.35471940040588,0,1,,,,,,1,1,1,1.80010426044464,0,0,1.79993388988078,,,,,,,,,,,,,,,,,,,,,,,,,,,,,,,,,
,3825406809.29923,1.7998104095459,99.9204711914062,,,5,,,,24.2400001734495,,,,,0.000231353187614272,5.88181573271611E-9,0.611968818684118,1.59950427970766E-5,7.71167084079031E-5,1.96057929197473E-9,7.71123096740701E-5,1.52518975519526E-9,8.23657938627434E-7,1.23193643130136E-9,3.00003971111613,251.044357299805,12,3012,1,3,0.759647384460103,0.0899133992350536,0.00568873062729836,129.083633422852,1.79600119590759,1.80241370201111,99.9204711914062,99.9204711914062,,,2.35521912574768,0,1,,,,,,1,1,1,1.80026483535767,0,0,1.79999103243389,,,,,,,,,,,,,,,,,,,,,,,,,,,,,,,,,
,3825407333.71237,1.79995930194855,299.660552978516,,,5,,,,24.2400001734495,,,,,0.000250139136690127,2.82319719989743E-7,3.9957956924771,0.000474304622538195,8.33793497233941E-5,9.41061641865201E-8,8.31766683847874E-5,8.56344043456911E-8,5.81014601392856E-6,3.90220313446001E-8,3.00001304303702,1.00057637691498,31.9815665633281,32,1,3,0.826731214642263,0.0696525849037201,0.0262337494641542,178.074981689453,1.79583263397217,1.80246293544769,299.660552978516,299.660552978516,,,2.35476088523865,0,1,,,,,,1,1,1,1.79978597164154,0,0,1.79998588983991,,,,,,,,,,,,,,,,,,,,,,,,,,,,,,,,,
,3825408078.05862,1.79967224597931,299.660552978516,,,5,,,,24.2400001734495,,,,,0.000217464323569314,1.34643027967331E-7,13.7818756908227,0.000511911592350774,7.24883258337767E-5,4.48811442831049E-8,7.04013641963089E-5,2.42809206880169E-8,1.72686218756001E-5,3.77459137219264E-8,2.99999097879543,5.2525954246521,12,63,1,3,0.689261203436127,0.212103286917494,0.0327995382249355,167.0078125,1.79631721973419,1.80199265480042,299.660552978516,299.660552978516,,,2.35417437553406,0,1,,,,,,1,1,1,1.7998149394989,0,0,1.80000193913778,,,,,,,,,,,,,,,,,,,,,,,,,,,,,,,,,
,3825408539.66201,1.79987055063248,299.660552978516,,,5,,,,24.2400001734495,,,,,0.00014916517964387,2.39785128428735E-8,13.6665587209756,9.19312143543956E-5,4.97245960182712E-5,7.99329888568813E-9,4.83167528575058E-5,7.66419779228914E-9,1.17484825610363E-5,2.26999984066375E-9,2.99982687821253,27.5553760528564,12,330,1,3,0.45458832541909,0.192768241727943,0.0192972533404827,144.50048828125,1.79825270175934,1.8023247718811,299.660552978516,299.660552978516,,,2.35504364967346,0,1,,,,,,1,1,1,1.79985427856445,0,0,1.80000677922877,,,,,,,,,,,,,,,,,,,,,,,,,,,,,,,,,
,3825408937.54457,1.79970514774322,299.660552978516,,,5,,,,24.2400001734495,,,,,0.000130392780856934,4.68279961940544E-9,4.13625761644723,2.57781227156018E-5,4.34620600270834E-5,1.56085418852066E-9,4.33488560760619E-5,1.08842821102041E-9,3.13485864030164E-6,1.11874475519549E-9,3.00015187443208,144.4619140625,12,1733,1,3,0.424268872371063,0.0762395013295699,0.00708042504265904,128.768295288086,1.79837012290955,1.80140161514282,299.660552978516,299.660552978516,,,2.3554220199585,0,1,,,,,,1,1,1,1.79996728897095,0,0,1.80000536025517,,,,,,,,,,,,,,,,,,,,,,,,,,,,,,,,,
,3825409329.25666,1.80034005641937,299.660552978516,,,5,,,,24.2400001734495,,,,,0.000130177156708557,1.60057241181837E-8,0.680607697509956,8.12196856291412E-5,4.33911313586801E-5,5.33508716323998E-9,4.33880699992703E-5,4.03386473918274E-9,5.15424412161351E-7,3.49157418728948E-9,3.00008671432154,758.4951171875,12,9101,1,3,0.419595323634205,0.0984660219112865,0.00602895673364401,103.538940429688,1.7953794002533,1.80638599395752,299.660552978516,299.660552978516,,,2.35488200187683,0,1,,,,,,1,1,1,1.80020642280579,0,0,1.80006152947744,,,,,,,,,,,,,,,,,,,,,,,,,,,,,,,,,
,3825410195.33279,1.80070108175278,1249.755859375,,,5,,,,24.2400001734495,,,,,0.000132333865297586,8.75212035613427E-7,39.4440535110391,0.0135634590166231,4.41112769603912E-5,2.91737269331586E-7,3.40647269400353E-5,2.82194325224986E-7,2.80249733911947E-5,7.40067370437672E-8,3.000000780218,3.0215425491333,12,36,1,3,0.328616561864,0.290974701057816,0.0261565744876862,174.645431518555,1.79592537879944,1.80187928676605,1249.755859375,1249.755859375,,,2.35503482818604,0,1,,,,,,1,1,1,1.80010592937469,0,0,1.79999742243025,,,,,,,,,,,,,,,,,,,,,,,,,,,,,,,,,
,3825410708.6098,1.79977971315384,1249.755859375,,,5,,,,24.2400001734495,,,,,4.71554881603056E-5,2.35937637417319E-7,52.8114890446143,0.0730446815602769,1.57188286595822E-5,7.86475432997712E-8,9.5010790683399E-6,7.66071951066597E-8,1.25224227275099E-5,1.7798138244759E-8,2.99993652081445,15.8532876968384,12,190,1,3,0.076870222836068,0.136018890767989,0.0229305159300566,155.938186645508,1.7980682849884,1.80179333686829,1249.755859375,1249.755859375,,,2.35566139221191,0,1,,,,,,1,1,1,1.80033898353577,0,0,1.80000265439351,,,,,,,,,,,,,,,,,,,,,,,,,,,,,,,,,
,3825411100.7563,1.799496114254,1249.755859375,,,5,,,,24.2400001734495,,,,,1.77918989296237E-5,2.21701354880218E-8,38.1746158004119,0.00355866005133397,5.93038740498191E-6,7.38973916078153E-9,4.66206016162413E-6,7.05779344212515E-9,3.66533624959093E-6,2.18993072782754E-9,3.0001242270745,83.1824951171875,12,998,1,3,0.041217532808451,0.041975579363414,0.0100412759929895,128.90397644043,1.79668056964874,1.80234062671661,1249.755859375,1249.755859375,,,2.3555018901825,0,1,,,,,,1,1,1,1.79915022850037,0,0,1.79998864978552,,,,,,,,,,,,,,,,,,,,,,,,,,,,,,,,,
,3825411487.13606,1.79977780580521,1249.755859375,,,5,,,,24.2400001734495,,,,,1.11838903550993E-5,8.625103711999E-9,19.399146566008,0.000659821086941494,3.72781698157235E-6,2.87492161175853E-9,3.51617988512331E-6,1.43369154317716E-9,1.23818353387268E-6,2.491927533613E-9,3.00011787337854,436.940734863281,12,5243,1,3,0.0328146312828376,0.017092108233849,0.00539561873301864,122.079299926758,1.79425442218781,1.80395972728729,1249.755859375,1249.755859375,,,2.3561327457428,0,1,,,,,,1,1,1,1.80011963844299,0,0,1.79996289525713,,,,,,,,,,,,,,,,,,,,,,,,,,,,,,,,,
,3825412227.00595,1.79994517564774,1749.74914550781,,,5,,,,24.2400001734495,,,,,0.000152698289308137,1.00149890388887E-6,23.7007329292843,0.00432699722231489,5.08995670277799E-5,3.33833868196604E-7,4.6606567828991E-5,3.17247010966107E-7,2.04595639938175E-5,1.03920092321833E-7,2.99999191004509,1.73988473415375,18.3920229724668,31,1,3,0.45893387049591,0.214306194767711,0.0259942449629307,176.920364379883,1.79855334758759,1.8021799325943,1749.74914550781,1749.74914550781,,,2.3560619354248,0,1,,,,,,1,1,1,1.79988765716553,0,0,1.79998657780309,,,,,,,,,,,,,,,,,,,,,,,,,,,,,,,,,
,3825412805.84916,1.79987210035324,1749.74914550781,,,5,,,,24.2400001734495,,,,,8.10923267254965E-5,4.04171686645096E-7,44.2242893772526,0.0191686800104157,2.70301700178092E-5,1.34720877394269E-7,1.93702251335507E-5,1.1979611419985E-7,1.88527045663807E-5,6.16328307681723E-8,3.00006720905077,9.10972499847412,12,109,1,3,0.174399342766687,0.204619529812135,0.0250275488942862,166.401443481445,1.79815757274628,1.80219209194183,1749.74914550781,1749.74914550781,,,2.35616636276245,0,1,,,,,,1,1,1,1.79985857009888,0,0,1.79999292174051,,,,,,,,,,,,,,,,,,,,,,,,,,,,,,,,,
,3825413216.83769,1.7997664809227,1749.74914550781,,,5,,,,24.2400001734495,,,,,2.86466017069842E-5,5.04262004170768E-8,55.4236980706628,0.0434401553618334,9.54823683551685E-6,1.68076237880635E-8,5.41865533648455E-6,1.57491507617713E-8,7.86174287365775E-6,5.87030388345222E-9,3.00019806802725,47.8707122802734,12,574,1,3,0.0408812439302463,0.085492865443358,0.0145726967602968,134.492309570312,1.79850685596466,1.80271601676941,1749.74914550781,1749.74914550781,,,2.35634636878967,0,1,,,,,,1,1,1,1.80008089542389,0,0,1.80000685341656,,,,,,,,,,,,,,,,,,,,,,,,,,,,,,,,,
,3825413604.74776,1.79958868026733,1749.74914550781,,,5,,,,24.2400001734495,,,,,1.01457064496595E-5,1.21507910926913E-8,40.7123182992567,0.00366818438988157,3.38178313892494E-6,4.0501211665987E-9,2.56337173732496E-6,3.66409480760163E-9,2.20580654976829E-6,1.72565660113407E-9,3.00010557533408,251.044357299805,12,3012,1,3,0.0229157708624268,0.0245033232289756,0.00576085550710559,129.009521484375,1.79821193218231,1.8017725944519,1749.74914550781,1749.74914550781,,,2.35682344436646,0,1,,,,,,1,1,1,1.79991126060486,0,0,1.80000229487343,,,,,,,,,,,,,,,,,,,,,,,,,,,,,,,,,
,3825413961.88068,1.8030002117157,1749.74914550781,,,5,,,,24.2400001734495,,,,,6.1119938153252E-6,1.74910449916428E-8,19.9485038380016,0.00320980835048874,2.03728657149695E-6,5.83022040918525E-9,1.91504864630726E-6,4.40926547604239E-9,6.95072123364567E-7,3.81442629781477E-9,3.00006582325541,941.265075683594,12,11295,100,3,0.0165369210240127,0.0116797552994528,0.00718002952635288,89.7551574707031,1.79507970809937,1.80885243415833,1749.74914550781,1749.74914550781,,,2.35587358474731,0,1,,,,,,5,1,1,1.80035674571991,0,0,1.80003569950567,,,,,,,,,,,,,,,,,,,,,,,,,,,,,,,,,