File: data/AP498/chiT1000.dat
[Header]
; MPMS3 Data File (default extension .dat)
; Copyright (c) 2007, Quantum Design, Inc. All rights reserved.
TITLE,
FILEOPENTIME,3825501413.7209,03/21/2021,3:17 pm
BYAPP,SQUID AC,0.9.1.0
INFO,MPMS3 Measurement Release 1.1.16 Build 347, MultiVu Release 2.3.3.2,APPNAME
INFO,0,MOMENT_UNITS
INFO,SC_AZV129,SAMPLE_MATERIAL
INFO,capsule nujol,SAMPLE_COMMENT
INFO,22,SAMPLE_MASS
INFO,,SAMPLE_VOLUME
INFO,,SAMPLE_MOLECULAR_WEIGHT
INFO,,SAMPLE_SIZE
INFO,,SAMPLE_SHAPE
INFO,Standard,SAMPLE_HOLDER
INFO,Standard,SAMPLE_HOLDER_DETAIL
INFO,64.87,SAMPLE_OFFSET
DATATYPE,COMMENT,1
DATATYPE,TIME,2
STARTUPAXIS,X,2
STARTUPAXIS,Y1,5
FIELDGROUP, VSM,2,3,4,5,6,8,9,10,11,14,15
FIELDGROUP, DC, 2,3,4,14,56,57,58,59,60,61,62,63,64,65,66,67,68,69
FIELDGROUP, AC, 2,3,4,11,16,17,18,19,20,21,22,23,24,25,26,27,28,29,30
STARTUPGROUP, All
[Data]
Comment,Time Stamp (sec),Temperature (K),Magnetic Field (Oe),Moment (emu),M. Std. Err. (emu),Transport Action,Averaging Time (sec),Frequency (Hz),Peak Amplitude (mm),Center Position (mm),Lockin Signal' (V),Lockin Signal (V),Range,M. Quad. Signal (emu),AC Moment (emu),AC M. Std Err. (emu),AC Phase (deg),AC Phase Std. Err. (deg),AC Susceptibility (emu/Oe),AC Suscept. Std Err. (emu/Oe),AC X' (emu/Oe),AC X' Std Err. (emu/Oe),AC X'' (emu/Oe),AC X'' Std Err. (emu/Oe),AC Drive (Oe),AC Frequency (Hz),AC Averaging Time (sec),AC Cycles,AC Range,AC Measure Type,AC Signal' (V),AC Signal'' (V),AC Trim Coil Ratio,AC Trim Coil Phase,Min. Temperature (K),Max. Temperature (K),Min. Field (Oe),Max. Field (Oe),Mass (grams),Motor Lag (deg),Pressure (Torr),Measure Count,Measurement Number,SQUID Status (code),Motor Status (code),Measure Status (code),Motor Current (amps),Motor Temp. (C),Temp. Status (code),Field Status (code),Chamber Status (code),Chamber Temp (K),Redirection State,Evercool Status,Average Temp (K),Rotation Angle (deg),Rotator state,DC Moment Fixed Ctr (emu),DC Moment Err Fixed Ctr (emu),DC Moment Free Ctr (emu),DC Moment Err Free Ctr (emu),DC Fixed Fit,DC Free Fit,DC Calculated Center (mm),DC Calculated Center Err (mm),DC Scan Length (mm),DC Scan Time (s),DC Number of Points,DC Squid Drift,DC Min V (V),DC Max V (V),DC Scans per Measure,Map 01,Map 02,Map 03,Map 04,Map 05,Map 06,Map 07,Map 08,Map 09,Map 10,Map 11,Map 12,Map 13,Map 14,Map 15,Map 16
,3825502934.56509,1.80056637525558,1000.03662109375,,,6,,,,24.2439994812012,,,100,,,,,,,,,,,,,,,,,,,,,,1.79830026626587,1.80192089080811,1000.03662109375,1000.03662109375,,,2.3663477897644,-99999999,1,0,0,0,0.0138092041015625,33.2355842590332,1,1,1,1.80130457878113,0,1816138816,1.80016654067569,,,0.0772646308672635,0.00380730865701928,0.0772744610239754,0.00380734694490035,0.980110466480255,0.987298309803009,24.1862773895264,0.186506778001785,30,3,200,0.000983946840278804,-3.16095781326294,0.479100733995438,1,,,,,,,,,,,,,,,,
,3825503040.16591,4.48563623428345,1000.03662109375,,,6,,,,24.2439994812012,,,100,,,,,,,,,,,,,,,,,,,,,,4.35782527923584,4.59015703201294,1000.03662109375,1000.03662109375,,,3.78140997886658,-99999999,1,0,0,0,0,32.7468223571777,6,1,1,4.61344718933105,0,1816138848,4.47515255212784,,,0.0329304274685468,0.00162288474890599,0.0329346820404999,0.00162289578109982,0.974711179733276,0.980128765106201,24.1850109100342,0.186515375971794,30,3,200,-0.00135194789618254,-1.37232577800751,0.203701004385948,1,,,,,,,,,,,,,,,,
,3825503140.10352,7.53463912010193,1000.03662109375,,,6,,,,24.2439994812012,,,100,,,,,,,,,,,,,,,,,,,,,,7.39645671844482,7.64815998077393,1000.03662109375,1000.03662109375,,,4.5748782157898,-99999999,1,0,0,0,0,33.2355842590332,6,1,1,7.67282152175903,0,1816139168,7.52016343010796,,,0.0199960680060377,0.000985377390216853,0.019998517900588,0.00098538671045883,0.977856755256653,0.983742594718933,24.1873149871826,0.186487272381783,30,3,200,-0.000411544227972627,-0.8285973072052,0.123509205877781,1,,,,,,,,,,,,,,,,
,3825503239.86802,10.6834931373596,1000.03662109375,,,6,,,,24.2439994812012,,,100,,,,,,,,,,,,,,,,,,,,,,10.5381660461426,10.8042793273926,1000.03662109375,1000.03662109375,,,5.0796332359314,-99999999,1,0,0,0,0.0138092041015625,33.7243423461914,6,1,1,10.8288202285767,0,1816138752,10.6782782077789,,,0.0142723527933332,0.00070329715495968,0.0142738863332582,0.000703302447558691,0.979434490203857,0.985061109066009,24.190710067749,0.186490193009377,30,3,200,-0.000154146429849789,-0.590784549713135,0.0911836549639702,1,,,,,,,,,,,,,,,,
,3825503339.96411,13.8894534111023,1000.03662109375,,,6,,,,24.2439994812012,,,100,,,,,,,,,,,,,,,,,,,,,,13.7452144622803,14.0134315490723,1000.03662109375,1000.03662109375,,,5.42244291305542,-99999999,1,0,0,0,0.0138092041015625,34.2131004333496,6,1,1,14.0336923599243,0,1816139040,13.8769149780273,,,0.0110786040434675,0.000545907417849931,0.0110795851206352,0.000545909791188804,0.980504333972931,0.985449314117432,24.1950645446777,0.186552867293358,30,3,200,-6.50771762593649E-5,-0.451003611087799,0.0723633468151092,1,,,,,,,,,,,,,,,,
,3825503439.93748,17.2143573760986,1000.03662109375,,,6,,,,24.2439994812012,,,100,,,,,,,,,,,,,,,,,,,,,,17.0676937103271,17.341796875,1000.03662109375,1000.03662109375,,,5.65412044525146,-99999999,1,0,0,0,0.013885498046875,33.2355842590332,2,1,1,17.3610210418701,0,1816138880,17.2029783460829,,,0.00900460330140298,0.00044370128268964,0.00900527709336866,0.000443704121711173,0.981439411640167,0.985588908195496,24.1999053955078,0.186490580439568,30,3,200,-2.52680019912077E-5,-0.371491491794586,0.0534300431609154,1,,,,,,,,,,,,,,,,
,3825503540.27753,20.5068216323853,1000.03662109375,,,6,,,,24.2439994812012,,,100,,,,,,,,,,,,,,,,,,,,,,20.3637523651123,20.6291351318359,1000.03662109375,1000.03662109375,,,5.83759450912476,-99999999,1,0,0,0,0.0138092041015625,33.2355842590332,2,1,1,20.6498908996582,0,1816138816,20.4977073669434,,,0.00761072513003877,0.000375012873375094,0.00761116270379706,0.00037501439985684,0.982211172580719,0.985521495342255,24.2050380706787,0.186496660113335,30,3,200,8.14412487670779E-6,-0.314791828393936,0.0441785790026188,1,,,,,,,,,,,,,,,,
,3825503640.233,23.7767820358276,1000.03662109375,,,6,,,,24.2439994812012,,,100,,,,,,,,,,,,,,,,,,,,,,23.630952835083,23.9111289978027,1000.03662109375,1000.03662109375,,,5.97408151626587,-99999999,1,0,0,0,0,33.2355842590332,2,1,1,23.9226112365723,0,1816138848,23.7707481384277,,,0.00660067200538655,0.000325239053596959,0.00660094233248958,0.000325239913680182,0.982946336269379,0.985363483428955,24.2110214233398,0.186422303318977,30,3,200,1.11610788735561E-5,-0.270511716604233,0.0407292321324348,1,,,,,,,,,,,,,,,,
,3825503739.7487,27.028094291687,1000.03662109375,,,6,,,,24.2439994812012,,,100,,,,,,,,,,,,,,,,,,,,,,26.8804702758789,27.1568183898926,1000.03662109375,1000.03662109375,,,6.08945751190186,-99999999,1,0,0,0,0,33.2355842590332,2,1,1,27.1757183074951,0,1816138848,27.0189993116591,,,0.00583483706342282,0.000287500622649031,0.00583499225249427,0.000287501340706548,0.98357218503952,0.985110819339752,24.2178401947021,0.186459109187126,30,3,200,2.20154615817592E-5,-0.234800100326538,0.04028045758605,1,,,,,,,,,,,,,,,,
,3825503839.24645,30.2739038467407,1000.03662109375,,,6,,,,24.2439994812012,,,100,,,,,,,,,,,,,,,,,,,,,,30.1239929199219,30.3970775604248,1000.03662109375,1000.03662109375,,,6.18573045730591,-99999999,1,0,0,0,0,33.2355842590332,2,1,1,30.4238147735596,0,1816138944,30.2690124511719,,,0.00523175846757832,0.000257783091724054,0.0052318308006575,0.000257783431207934,0.98404586315155,0.984849989414215,24.2251510620117,0.186485469341278,30,3,200,2.33149676205358E-5,-0.215428039431572,0.0311990901827812,1,,,,,,,,,,,,,,,,
,3825503939.63192,33.5666217803955,1000.03662109375,,,6,,,,24.2439994812012,,,100,,,,,,,,,,,,,,,,,,,,,,33.4284286499023,33.6844444274902,1000.03662109375,1000.03662109375,,,6.27281618118286,-99999999,1,0,0,0,0.0138092041015625,33.2355842590332,2,1,1,33.7048149108887,0,1816138880,33.5559819539388,,,0.00473742063864293,0.000233424649156823,0.00473744050150576,0.000233424679419319,0.984333276748657,0.984594702720642,24.2332553863525,0.186537384986877,30,3,200,2.69231750280596E-5,-0.199600011110306,0.0338017717003822,1,,,,,,,,,,,,,,,,
,3825504039.44529,36.831371307373,1000.03662109375,,,6,,,,24.2439994812012,,,100,,,,,,,,,,,,,,,,,,,,,,36.6799240112305,36.9669914245605,1000.03662109375,1000.03662109375,,,6.34012651443481,-99999999,1,0,0,0,0,33.2355842590332,2,1,1,36.9828186035156,0,1816139008,36.8210377163357,,,0.00433041518675481,0.000213370499120092,0.00433041656824415,0.000213370533511147,0.984315693378449,0.984325766563416,24.2418823242187,0.186437517404556,30,3,200,2.22523303818889E-5,-0.176426202058792,0.0277332179248333,1,,,,,,,,,,,,,,,,
,3825504138.78036,40.0881195068359,1000.03662109375,,,6,,,,24.2439994812012,,,100,,,,,,,,,,,,,,,,,,,,,,39.946964263916,40.2087936401367,1000.03662109375,1000.03662109375,,,6.40252161026001,-99999999,1,0,0,0,0.0138092041015625,34.2131004333496,2,1,1,40.2292747497559,0,1816138752,40.0815997123718,,,0.00398903256007454,0.000196551034564782,0.00398903917050557,0.000196551029300741,0.983886420726776,0.983991205692291,24.2509155273438,0.186530396342278,30,3,200,1.10407245301758E-5,-0.166024267673492,0.0220739170908928,1,,,,,,,,,,,,,,,,
,3825504238.4793,43.370719909668,1000.03662109375,,,6,,,,24.2439994812012,,,100,,,,,,,,,,,,,,,,,,,,,,43.2212295532227,43.5009727478027,1000.03662109375,1000.03662109375,,,6.45804309844971,-99999999,1,0,0,0,0.0145721435546875,33.2355842590332,2,1,1,43.5202102661133,0,1816139008,43.3608101738824,,,0.00369453577002794,0.000182042635782537,0.00369457125243208,0.000182042611975951,0.983136713504791,0.983724057674408,24.2606258392334,0.186520665884018,30,3,200,2.37870808632579E-5,-0.157027095556259,0.017195001244545,1,,,,,,,,,,,,,,,,
,3825504338.44572,46.646427154541,1000.03662109375,,,6,,,,24.2439994812012,,,100,,,,,,,,,,,,,,,,,,,,,,46.4946975708008,46.7834892272949,1000.03662109375,1000.03662109375,,,6.51058626174927,-99999999,1,0,0,0,0.0145721435546875,33.2355842590332,2,1,1,46.7981567382812,0,1816138720,46.6365720960829,,,0.00343918331150865,0.000169463906463397,0.0034392722952444,0.000169464024194987,0.981970131397247,0.983424842357635,24.2707386016846,0.186537727713585,30,3,200,2.54868427873589E-5,-0.138586893677711,0.0236254949122667,1,,,,,,,,,,,,,,,,
,3825504438.46402,49.9375267028809,1000.03662109375,,,6,,,,24.2439994812012,,,100,,,,,,,,,,,,,,,,,,,,,,49.7890853881836,50.0601654052734,1000.03662109375,1000.03662109375,,,6.56338500976563,-99999999,1,0,0,0,0.0138092041015625,33.2355842590332,2,1,1,50.0859680175781,0,1816138816,49.9343438148499,,,0.00321597905045907,0.000158470252215056,0.00321614663944537,0.000158470734301596,0.980440080165863,0.983133256435394,24.2813186645508,0.186519980430603,30,3,200,2.26412321353564E-5,-0.131702095270157,0.0200297757983208,1,,,,,,,,,,,,,,,,
,3825504537.78815,53.2131214141846,1000.03662109375,,,6,,,,24.2439994812012,,,100,,,,,,,,,,,,,,,,,,,,,,53.0734901428223,53.3395462036133,1000.03662109375,1000.03662109375,,,6.60579109191895,-99999999,1,0,0,0,0.0145721435546875,33.2355842590332,2,1,1,53.3527526855469,0,1816139040,53.2043647766113,,,0.00302032555806376,0.00014883462892772,0.00302058378889201,0.000148835365461509,0.978673279285431,0.982859432697296,24.2917900085449,0.186449646949768,30,3,200,2.85562637145631E-5,-0.126019015908241,0.016492011025548,1,,,,,,,,,,,,,,,,
,3825504637.77082,56.5007762908936,1000.03662109375,,,6,,,,24.2439994812012,,,100,,,,,,,,,,,,,,,,,,,,,,56.352897644043,56.6315727233887,1000.03662109375,1000.03662109375,,,6.65134477615356,-99999999,1,0,0,0,0.0145721435546875,32.7468223571777,2,1,1,56.6486549377441,0,1816139040,56.4921179877387,,,0.00284493425628527,0.000140197967735676,0.00284529554452791,0.000140198829145888,0.976680815219879,0.982615947723389,24.3025665283203,0.186564028263092,30,3,200,1.60443250933895E-5,-0.120765194296837,0.0134904347360134,1,,,,,,,,,,,,,,,,
,3825504737.40901,59.78759765625,1000.03662109375,,,6,,,,24.2439994812012,,,100,,,,,,,,,,,,,,,,,,,,,,59.6411933898926,59.9179840087891,1000.03662109375,1000.03662109375,,,6.68306684494019,-99999999,1,0,0,0,0.0145721435546875,33.2355842590332,2,1,1,59.9340019226074,0,1816139104,59.781087398529,,,0.00268789096759682,0.000132466653111295,0.0026883725833677,0.000132467389715035,0.974287629127502,0.982277393341064,24.3141784667969,0.186541825532913,30,3,200,1.74189099197974E-5,-0.105861827731133,0.0210200846195221,1,,,,,,,,,,,,,,,,
,3825504837.31574,63.0794563293457,1000.03662109375,,,6,,,,24.2439994812012,,,100,,,,,,,,,,,,,,,,,,,,,,62.9335250854492,63.2049713134766,1000.03662109375,1000.03662109375,,,6.71250677108765,-99999999,1,0,0,0,0.0145721435546875,33.7243423461914,2,1,1,63.2253875732422,0,1816139200,63.0770220756531,,,0.00254549435845237,0.000125458224332003,0.00254612812964113,0.000125459339049253,0.971568048000336,0.981874704360962,24.3265209197998,0.186564818024635,30,3,200,1.36366315928171E-5,-0.101991303265095,0.0182068608701229,1,,,,,,,,,,,,,,,,
,3825504945.81709,66.6538429260254,1000.03662109375,,,6,,,,24.2439994812012,,,10,,,,,,,,,,,,,,,,,,,,,,66.5137405395508,66.7792434692383,1000.03662109375,1000.03662109375,,,6.74055814743042,-99999999,1,0,0,0,0.0138092041015625,33.7243423461914,2,1,1,66.8052978515625,0,1816139008,66.6597766876221,,,0.0024066687672114,0.000118627093734922,0.00240748632240149,0.000118628780220343,0.968457162380218,0.98143857717514,24.3400726318359,0.186588123440742,30,3,200,0.000168016544193961,-0.98228645324707,0.154491171240807,1,,,,,,,,,,,,,,,,
,3825505045.51734,69.9349899291992,1000.03662109375,,,6,,,,24.2439994812012,,,10,,,,,,,,,,,,,,,,,,,,,,69.7791137695313,70.0709915161133,1000.03662109375,1000.03662109375,,,6.76342058181763,-99999999,1,0,0,0,0.0138092041015625,33.7243423461914,2,1,1,70.0908660888672,0,1816138848,69.9290050930447,,,0.00229032009330741,0.000112903098956156,0.00229130393328316,0.000112904641352133,0.96551650762558,0.981075584888458,24.3525772094727,0.18658971786499,30,3,200,0.000142510471050628,-0.951470494270325,0.130745142698288,1,,,,,,,,,,,,,,,,
,3825505144.94659,73.2082710266113,1000.03662109375,,,6,,,,24.2439994812012,,,10,,,,,,,,,,,,,,,,,,,,,,73.0615539550781,73.329475402832,1000.03662109375,1000.03662109375,,,6.78508996963501,-99999999,1,0,0,0,0.0164031982421875,33.7243423461914,2,1,1,73.3549880981445,0,1816138848,73.1962492201063,,,0.00218460180145628,0.000107703410012288,0.00218579768706218,0.000107706554482903,0.962489902973175,0.98071813583374,24.3651428222656,0.186546385288239,30,3,200,0.000193938700249419,-0.922984004020691,0.109734587371349,1,,,,,,,,,,,,,,,,
,3825505244.47816,76.5158386230469,1000.03662109375,,,6,,,,24.2439994812012,,,10,,,,,,,,,,,,,,,,,,,,,,76.3703842163086,76.6381759643555,1000.03662109375,1000.03662109375,,,6.80512809753418,-99999999,1,0,0,0,0.0145721435546875,33.2355842590332,2,1,1,76.6612930297852,0,1816138816,76.5104913711548,,,0.00208747569402894,0.000102927644220737,0.00208884944405483,0.000102930105565065,0.959344685077667,0.980347394943237,24.3780193328857,0.186601638793945,30,3,200,0.00016467590467073,-0.896001696586609,0.0910743474960327,1,,,,,,,,,,,,,,,,
,3825505344.08197,79.7877426147461,1000.03662109375,,,6,,,,24.2439994812012,,,10,,,,,,,,,,,,,,,,,,,,,,79.6340026855469,79.9229431152344,1000.03662109375,1000.03662109375,,,6.82374238967896,-99999999,1,0,0,0,0.0138092041015625,32.2580642700195,2,1,1,79.9414825439453,0,1816138880,79.7779973347982,,,0.00199812052730305,9.85351169495742E-5,0.00199971064170107,9.85384513592137E-5,0.956152081489563,0.979972302913666,24.390905380249,0.186658665537834,30,3,200,0.000165214500157163,-0.870068252086639,0.179353177547455,1,,,,,,,,,,,,,,,,
,3825505443.55159,83.0744438171387,1000.03662109375,,,6,,,,24.2439994812012,,,10,,,,,,,,,,,,,,,,,,,,,,82.9372940063477,83.1985626220703,1000.03662109375,1000.03662109375,,,6.84129190444946,-99999999,1,0,0,0,0.013885498046875,33.7243423461914,2,1,1,83.2115936279297,0,1816138880,83.0659951104058,,,0.00191550764449007,9.44753060659436E-5,0.0019173165157008,9.44790651079179E-5,0.952863574028015,0.979603052139282,24.4040012359619,0.186645001173019,30,3,200,0.000145358557347208,-0.74273419380188,0.163928881287575,1,,,,,,,,,,,,,,,,
,3825505543.28603,86.3827667236328,1000.03662109375,,,6,,,,24.2439994812012,,,10,,,,,,,,,,,,,,,,,,,,,,86.2380676269531,86.5094146728516,1000.03662109375,1000.03662109375,,,6.85800409317017,-99999999,1,0,0,0,0.000457763671875,33.2355842590332,2,1,1,86.5274658203125,0,1816139136,86.3739276462131,,,0.00183897521262394,9.07154052621353E-5,0.0018410202277838,9.07201510721347E-5,0.949534475803375,0.979222416877747,24.4171772003174,0.186698198318481,30,3,200,0.000144150064443238,-0.721535444259644,0.149191156029701,1,,,,,,,,,,,,,,,,
,3825505643.33732,89.7023086547852,1000.03662109375,,,6,,,,24.2439994812012,,,10,,,,,,,,,,,,,,,,,,,,,,89.5569152832031,89.8226013183594,1000.03662109375,1000.03662109375,,,6.87296056747437,-99999999,1,0,0,0,0.013885498046875,33.2355842590332,2,1,1,89.8477020263672,0,1816139168,89.7006483078003,,,0.00176764072023333,8.72125162144756E-5,0.00176993170146046,8.72178743922794E-5,0.946029901504517,0.978802442550659,24.4308452606201,0.186684966087341,30,3,200,8.50411815918051E-5,-0.706955254077911,0.13052824139595,1,,,,,,,,,,,,,,,,
,3825505743.51281,93.0379638671875,1000.03662109375,,,6,,,,24.2439994812012,,,10,,,,,,,,,,,,,,,,,,,,,,92.8915863037109,93.1587142944336,1000.03662109375,1000.03662109375,,,6.88739585876465,-99999999,1,0,0,0,0.0138092041015625,34.2131004333496,2,1,1,93.1843414306641,0,1816138880,93.0301751030816,,,0.00170131460535402,8.39562264106953E-5,0.00170385396823367,8.39623920704512E-5,0.94259238243103,0.97843873500824,24.4442882537842,0.186723187565804,30,3,200,0.000118452655442525,-0.692709088325501,0.113636627793312,1,,,,,,,,,,,,,,,,
,3825505843.02692,96.3400421142578,1000.03662109375,,,6,,,,24.2439994812012,,,10,,,,,,,,,,,,,,,,,,,,,,96.1844329833984,96.4756927490234,1000.03662109375,1000.03662109375,,,6.90261077880859,-99999999,1,0,0,0,0.0138092041015625,32.7468223571777,2,1,1,96.4956512451172,0,1816138976,96.3327941894531,,,0.00163995489262125,8.09450413004792E-5,0.00164273083546148,8.09510498993853E-5,0.939093887805939,0.978039503097534,24.4578590393066,0.186764299869537,30,3,200,0.00013397927978076,-0.678910136222839,0.0986389815807343,1,,,,,,,,,,,,,,,,
,3825505943.45528,99.6860122680664,1000.03662109375,,,6,,,,24.2439994812012,,,10,,,,,,,,,,,,,,,,,,,,,,99.5362167358398,99.8154296875,1000.03662109375,1000.03662109375,,,6.91546297073364,-99999999,1,0,0,0,0.0145721435546875,33.2355842590332,2,1,1,99.835807800293,0,1816138976,99.683126449585,,,0.00158213115581818,7.81087843541792E-5,0.00158516813028836,7.81152008732962E-5,0.935480654239655,0.977635085582733,24.4718418121338,0.186821341514587,30,3,200,0.00010619121894706,-0.667057752609253,0.0833980664610863,1,,,,,,,,,,,,,,,,
,3825506043.1314,103.00553894043,1000.03662109375,,,6,,,,24.2439994812012,,,10,,,,,,,,,,,,,,,,,,,,,,102.852684020996,103.142181396484,1000.03662109375,1000.03662109375,,,6.92689895629883,-99999999,1,0,0,0,0.0138092041015625,33.7243423461914,2,1,1,103.158393859863,0,1816138880,102.992042541504,,,0.0015283952914062,7.5473741172924E-5,0.00153174003649603,7.54828913960906E-5,0.93191921710968,0.977282881736755,24.4856033325195,0.186854764819145,30,3,200,0.000106238658190705,-0.657235562801361,0.0682049840688705,1,,,,,,,,,,,,,,,,
,3825506142.99471,106.316467285156,1000.03662109375,,,6,,,,24.2439994812012,,,10,,,,,,,,,,,,,,,,,,,,,,106.172660827637,106.441032409668,1000.03662109375,1000.03662109375,,,6.93939638137817,-99999999,1,0,0,0,0,32.7468223571777,2,1,1,106.460273742676,0,1816138848,106.307572258843,,,0.00147787798965158,7.29980797669834E-5,0.00148146396855115,7.30060432873841E-5,0.928230345249176,0.97686505317688,24.499792098999,0.186927646398544,30,3,200,9.2628804850392E-5,-0.648604273796082,0.053222481161356,1,,,,,,,,,,,,,,,,
,3825506242.81969,109.638481140137,1000.03662109375,,,6,,,,24.2439994812012,,,10,,,,,,,,,,,,,,,,,,,,,,109.48770904541,109.770683288574,1000.03662109375,1000.03662109375,,,6.95041704177856,-99999999,1,0,0,0,0.0145721435546875,33.7243423461914,2,1,1,109.789253234863,0,1816139136,109.627250671387,,,0.00143060713380909,7.06823874612621E-5,0.0014344789546007,7.06913071194793E-5,0.924557328224182,0.97645115852356,24.5138168334961,0.186953544616699,30,3,200,0.000100728204415645,-0.641571581363678,0.143191829323769,1,,,,,,,,,,,,,,,,
,3825506342.54506,112.948226928711,1000.03662109375,,,6,,,,24.2439994812012,,,10,,,,,,,,,,,,,,,,,,,,,,112.806632995605,113.07349395752,1000.03662109375,1000.03662109375,,,6.96139192581177,-99999999,1,0,0,0,0.0138092041015625,33.2355842590332,2,1,1,113.089820861816,0,1816138944,112.937661064996,,,0.001385876059933,6.84920532682723E-5,0.00139002417948999,6.8501188645723E-5,0.920855164527893,0.976065814495087,24.5280990600586,0.187075704336166,30,3,200,8.65832553245127E-5,-0.530769765377045,0.12817108631134,1,,,,,,,,,,,,,,,,
,3825506442.70403,116.278995513916,1000.03662109375,,,6,,,,24.2439994812012,,,10,,,,,,,,,,,,,,,,,,,,,,116.135917663574,116.405906677246,1000.03662109375,1000.03662109375,,,6.97158527374268,-99999999,1,0,0,0,0.0138092041015625,33.7243423461914,2,1,1,116.422073364258,0,1816139040,116.269760979546,,,0.00134357964894753,6.64221373460127E-5,0.00134802996101278,6.64323538734689E-5,0.917082905769348,0.975652456283569,24.5424709320068,0.187115862965584,30,3,200,0.000121189725177828,-0.523948848247528,0.115237474441528,1,,,,,,,,,,,,,,,,
,3825506542.74102,119.613857269287,1000.03662109375,,,6,,,,24.2439994812012,,,10,,,,,,,,,,,,,,,,,,,,,,119.465553283691,119.74267578125,1000.03662109375,1000.03662109375,,,6.9801926612854,-99999999,1,0,0,0,0.0145721435546875,33.7243423461914,2,1,1,119.762161254883,0,1816138944,119.598141140408,,,0.00130368802775397,6.44711270345709E-5,0.00130842668361343,6.44813016434737E-5,0.913250744342804,0.975243747234344,24.5570373535156,0.187145158648491,30,3,200,8.30017670523375E-5,-0.51651406288147,0.104012914001942,1,,,,,,,,,,,,,,,,
,3825506642.42729,122.936473846436,1000.03662109375,,,6,,,,24.2439994812012,,,10,,,,,,,,,,,,,,,,,,,,,,122.786964416504,123.066528320312,1000.03662109375,1000.03662109375,,,6.99036693572998,-99999999,1,0,0,0,0.0145721435546875,33.2355842590332,2,1,1,123.085983276367,0,1816139104,122.929567972819,,,0.00126608908609327,6.26332297385196E-5,0.00127113973908472,6.26444304850134E-5,0.909415423870087,0.974813401699066,24.5716037750244,0.187201589345932,30,3,200,7.2472685133107E-5,-0.510522961616516,0.0925620496273041,1,,,,,,,,,,,,,,,,
,3825506742.26164,126.263156890869,1000.03662109375,,,6,,,,24.2439994812012,,,10,,,,,,,,,,,,,,,,,,,,,,126.113479614258,126.393844604492,1000.03662109375,1000.03662109375,,,6.99924850463867,-99999999,1,0,0,0,0.016021728515625,32.2580642700195,2,1,1,126.41283416748,0,1816139104,126.249806722005,,,0.00123041114498956,6.0890142760773E-5,0.0012357672207111,6.09018270583677E-5,0.905563652515411,0.974416792392731,24.5863227844238,0.187298148870468,30,3,200,8.56714977999218E-5,-0.503717660903931,0.0827072039246559,1,,,,,,,,,,,,,,,,
,3825506841.84119,129.568580627441,1000.03662109375,,,6,,,,24.2439994812012,,,10,,,,,,,,,,,,,,,,,,,,,,129.428314208984,129.695114135742,1000.03662109375,1000.03662109375,,,7.00756072998047,-99999999,1,0,0,0,0.0138092041015625,33.2355842590332,2,1,1,129.708847045898,0,1816138784,129.559748331706,,,0.00119680654105122,5.92494913218526E-5,0.00120249634060239,5.92628055751398E-5,0.901682078838348,0.97398442029953,24.6009902954102,0.187336295843124,30,3,200,0.0001122429894167,-0.497289717197418,0.0735749527812004,1,,,,,,,,,,,,,,,,
,3825506941.46657,132.862884521484,1000.03662109375,,,6,,,,24.2439994812012,,,10,,,,,,,,,,,,,,,,,,,,,,132.717056274414,132.995407104492,1000.03662109375,1000.03662109375,,,7.01578855514526,-99999999,1,0,0,0,0.0157928466796875,33.7243423461914,2,1,1,133.014846801758,0,1816138784,132.855699327257,,,0.00116476850944224,5.76860061868933E-5,0.00117076950712209,5.76997938097044E-5,0.89781254529953,0.973596155643463,24.6157722473145,0.187445595860481,30,3,200,8.55458929436281E-5,-0.490749061107636,0.0652005150914192,1,,,,,,,,,,,,,,,,
,3825507041.55069,136.208030700684,1000.03662109375,,,6,,,,24.2439994812012,,,10,,,,,,,,,,,,,,,,,,,,,,136.061828613281,136.334289550781,1000.03662109375,1000.03662109375,,,7.02406978607178,-99999999,1,0,0,0,0.0138092041015625,33.2355842590332,2,1,1,136.354232788086,0,1816138592,136.196785820855,,,0.00113427143085613,5.61994201495409E-5,0.0011406205811939,5.62146180101982E-5,0.89379209280014,0.973151445388794,24.6309280395508,0.18748565018177,30,3,200,0.000116242947115097,-0.484483450651169,0.0571565479040146,1,,,,,,,,,,,,,,,,
,3825507141.68235,139.52579498291,1000.03662109375,,,6,,,,24.2439994812012,,,10,,,,,,,,,,,,,,,,,,,,,,139.377365112305,139.655914306641,1000.03662109375,1000.03662109375,,,7.03154230117798,-99999999,1,0,0,0,0.0145721435546875,32.7468223571777,2,1,1,139.674224853516,0,1816138816,139.5154232449,,,0.00110515965714765,5.47806817049342E-5,0.00111183072209525,5.47963597280622E-5,0.889845073223114,0.972722291946411,24.6459617614746,0.187605261802673,30,3,200,8.76410922501236E-5,-0.479705929756165,0.0485258884727955,1,,,,,,,,,,,,,,,,
,3825507242.00808,142.869834899902,1000.03662109375,,,6,,,,24.2439994812012,,,10,,,,,,,,,,,,,,,,,,,,,,142.724746704102,142.989288330078,1000.03662109375,1000.03662109375,,,7.03988122940063,-99999999,1,0,0,0,0.0145721435546875,33.2355842590332,2,1,1,143.014923095703,0,1816139168,142.858856201172,,,0.00107736225917565,5.34272113360221E-5,0.00108436665404856,5.34433297514209E-5,0.885825097560883,0.972362220287323,24.6611747741699,0.187653571367264,30,3,200,9.97185270534828E-5,-0.474150627851486,0.0411903001368046,1,,,,,,,,,,,,,,,,
,3825507342.06874,146.197982788086,1000.03662109375,,,6,,,,24.2439994812012,,,10,,,,,,,,,,,,,,,,,,,,,,146.049041748047,146.329528808594,1000.03662109375,1000.03662109375,,,7.04647159576416,-99999999,1,0,0,0,0.0145721435546875,32.7468223571777,2,1,1,146.346923828125,0,1816138976,146.189403957791,,,0.00105096423356259,5.21432528732728E-5,0.00105830515707896,5.21595729090074E-5,0.881731688976288,0.971886396408081,24.6767330169678,0.187784880399704,30,3,200,9.04879270819947E-5,-0.470155775547028,0.0328833796083927,1,,,,,,,,,,,,,,,,
,3825507442.3973,149.532485961914,1000.03662109375,,,6,,,,24.2439994812012,,,10,,,,,,,,,,,,,,,,,,,,,,149.38623046875,149.65966796875,1000.03662109375,1000.03662109375,,,7.05431461334228,-99999999,1,0,0,0,0.0145721435546875,33.2355842590332,2,1,1,149.678741455078,0,1816138848,149.52355617947,,,0.00102561463062607,5.09104675252664E-5,0.00103330805060131,5.09281821965078E-5,0.877719163894653,0.97146213054657,24.6919689178467,0.187895938754082,30,3,200,6.18600242887624E-5,-0.467469900846481,0.0239974521100521,1,,,,,,,,,,,,,,,,
,3825507542.35396,152.864814758301,1000.03662109375,,,6,,,,24.2439994812012,,,10,,,,,,,,,,,,,,,,,,,,,,152.720581054687,152.986633300781,1000.03662109375,1000.03662109375,,,7.06054639816284,-99999999,1,0,0,0,0.0146484375,33.2355842590332,2,1,1,153.009048461914,0,1816138912,152.85373433431,,,0.00100124386890686,4.97268538378077E-5,0.00100930824642974,4.97459564427627E-5,0.873557150363922,0.971007108688354,24.7075958251953,0.187948271632195,30,3,200,4.61438139609527E-5,-0.466050982475281,0.119512163102627,1,,,,,,,,,,,,,,,,
,3825507641.83584,156.201995849609,1000.03662109375,,,6,,,,24.2439994812012,,,10,,,,,,,,,,,,,,,,,,,,,,156.057006835938,156.327835083008,1000.03662109375,1000.03662109375,,,7.0667552947998,-99999999,1,0,0,0,0.0145721435546875,33.2355842590332,2,1,1,156.346984863281,0,1816138848,156.201406478882,,,0.000978289271884035,4.86131371035588E-5,0.000986695969023514,4.86320751087849E-5,0.869411110877991,0.970571219921112,24.7233028411865,0.188054591417313,30,3,200,7.02638644725084E-5,-0.358686089515686,0.110865063965321,1,,,,,,,,,,,,,,,,
,3825507742.21194,159.52360534668,1000.03662109375,,,6,,,,24.2439994812012,,,10,,,,,,,,,,,,,,,,,,,,,,159.378936767578,159.6533203125,1000.03662109375,1000.03662109375,,,7.07421159744263,-99999999,1,0,0,0,0.0138092041015625,32.7468223571777,2,1,1,159.668273925781,0,1816139008,159.522790908813,,,0.000956123462133678,4.75381105991397E-5,0.000964864457995791,4.7556668212409E-5,0.865293323993683,0.970140814781189,24.7389984130859,0.188199833035469,30,3,200,9.32293623918667E-5,-0.356046974658966,0.103264808654785,1,,,,,,,,,,,,,,,,
,3825507842.17799,162.856727600098,1000.03662109375,,,6,,,,24.2439994812012,,,10,,,,,,,,,,,,,,,,,,,,,,162.71369934082,162.982177734375,1000.03662109375,1000.03662109375,,,7.08033847808838,-99999999,1,0,0,0,0.0145721435546875,33.7243423461914,2,1,1,162.999755859375,0,1816138944,162.85333442688,,,0.000934900563330882,4.65103806750658E-5,0.00094405693684122,4.65317374251409E-5,0.86105614900589,0.969680070877075,24.7548542022705,0.188252136111259,30,3,200,8.06504831416532E-5,-0.352661341428757,0.0969033613801002,1,,,,,,,,,,,,,,,,
,3825507941.98768,166.184371948242,1000.03662109375,,,6,,,,24.2439994812012,,,10,,,,,,,,,,,,,,,,,,,,,,166.038177490234,166.315505981445,1000.03662109375,1000.03662109375,,,7.08774471282959,-99999999,1,0,0,0,0,33.7243423461914,2,1,1,166.33056640625,0,1816138976,166.187305450439,,,0.000914621646525256,4.55285937597523E-5,0.000924154524231699,4.55513616844082E-5,0.856924474239349,0.969261169433594,24.7707252502441,0.188445836305618,30,3,200,4.92559775011614E-5,-0.349832385778427,0.0903460457921028,1,,,,,,,,,,,,,,,,
,3825508042.01791,169.503753662109,1000.03662109375,,,6,,,,24.2439994812012,,,10,,,,,,,,,,,,,,,,,,,,,,169.359741210938,169.629699707031,1000.03662109375,1000.03662109375,,,7.09533786773682,-99999999,1,0,0,0,0,33.7243423461914,2,1,1,169.647766113281,0,1816139040,169.495524088542,,,0.000895200970145908,4.45900213037866E-5,0.000905076258765255,4.46115313447856E-5,0.852662801742554,0.968863070011139,24.786792755127,0.188524693250656,30,3,200,6.99535958119668E-5,-0.347657382488251,0.0835161730647087,1,,,,,,,,,,,,,,,,
,3825508142.00533,172.841011047363,1000.03662109375,,,6,,,,24.2439994812012,,,10,,,,,,,,,,,,,,,,,,,,,,172.694137573242,172.969161987305,1000.03662109375,1000.03662109375,,,7.1030740737915,-99999999,1,0,0,0,0.0138092041015625,33.7243423461914,2,1,1,172.987884521484,0,1816139040,172.83127339681,,,0.000876434716790411,4.36841681286138E-5,0.000886723090999755,4.37075386428777E-5,0.848337054252625,0.968401849269867,24.8030891418457,0.188627660274506,30,3,200,6.21999788563699E-5,-0.345425605773926,0.0771516188979149,1,,,,,,,,,,,,,,,,
,3825508242.00182,176.173706054687,1000.03662109375,,,6,,,,24.2439994812012,,,10,,,,,,,,,,,,,,,,,,,,,,176.030532836914,176.290649414062,1000.03662109375,1000.03662109375,,,7.1097092628479,-99999999,1,0,0,0,0.0138092041015625,33.7243423461914,2,1,1,176.316879272461,0,1816139008,176.168329238892,,,0.000858323645150878,4.28105509057167E-5,0.000868996543811954,4.28343458814361E-5,0.844022154808044,0.96798574924469,24.8194389343262,0.188753664493561,30,3,200,7.92730570537969E-5,-0.343577861785889,0.0706015005707741,1,,,,,,,,,,,,,,,,
,3825508342.12873,179.488128662109,1000.03662109375,,,6,,,,24.2439994812012,,,10,,,,,,,,,,,,,,,,,,,,,,179.344055175781,179.618041992187,1000.03662109375,1000.03662109375,,,7.11591148376465,-99999999,1,0,0,0,0.0138092041015625,33.2355842590332,2,1,1,179.632202148438,0,1816139008,179.481268988715,,,0.000840977774135727,4.19746516078286E-5,0.000852045178284402,4.19993590724957E-5,0.839721918106079,0.967557787895203,24.835823059082,0.188913390040398,30,3,200,6.93154870532453E-5,-0.341339319944382,0.0649808719754219,1,,,,,,,,,,,,,,,,
,3825508441.66876,182.808113098145,1000.03662109375,,,6,,,,24.2439994812012,,,10,,,,,,,,,,,,,,,,,,,,,,182.651428222656,182.951278686523,1000.03662109375,1000.03662109375,,,7.12249183654785,-99999999,1,0,0,0,0.001373291015625,33.7243423461914,2,1,1,182.964797973633,0,1816138720,182.800087822808,,,0.000824227614004495,4.11689583080337E-5,0.000835690126895215,4.11938285682473E-5,0.835305273532867,0.967076897621155,24.8525695800781,0.189062878489494,30,3,200,7.03031109878793E-5,-0.339738428592682,0.0589017495512962,1,,,,,,,,,,,,,,,,
,3825508541.79214,186.138092041016,1000.03662109375,,,6,,,,24.2439994812012,,,10,,,,,,,,,,,,,,,,,,,,,,185.988403320313,186.274230957031,1000.03662109375,1000.03662109375,,,7.12885236740112,-99999999,1,0,0,0,0,33.2355842590332,2,1,1,186.287780761719,0,1816139008,186.133022732205,,,0.000808036213020911,4.03908885725124E-5,0.000819930649919599,4.04175686455747E-5,0.830880582332611,0.966643989086151,24.8693675994873,0.18921235203743,30,3,200,7.73174833739176E-5,-0.338881373405457,0.0524605512619019,1,,,,,,,,,,,,,,,,
,3825508641.55015,189.425628662109,1000.03662109375,,,6,,,,24.2439994812012,,,10,,,,,,,,,,,,,,,,,,,,,,189.287490844727,189.555801391602,1000.03662109375,1000.03662109375,,,7.13519525527954,-99999999,1,0,0,0,0.016021728515625,33.2355842590332,2,1,1,189.563766479492,0,1816139008,189.433441162109,,,0.000792546844578232,3.96475439748802E-5,0.000804815294792829,3.96730120508967E-5,0.826463222503662,0.966250061988831,24.8861446380615,0.189351946115494,30,3,200,4.80776034237351E-5,-0.337546765804291,0.0466698929667473,1,,,,,,,,,,,,,,,,
,3825508741.26203,192.766258239746,1000.03662109375,,,6,,,,24.2439994812012,,,10,,,,,,,,,,,,,,,,,,,,,,192.619216918945,192.887634277344,1000.03662109375,1000.03662109375,,,7.14034700393677,-99999999,1,0,0,0,0.016021728515625,33.7243423461914,2,1,1,192.913299560547,0,1816138848,192.756303575304,,,0.000777535406054891,3.89285934400025E-5,0.000790236412745149,3.89550267279109E-5,0.821929275989532,0.965740025043487,24.9032688140869,0.189498603343964,30,3,200,4.91892242280301E-5,-0.336501270532608,0.0408829897642136,1,,,,,,,,,,,,,,,,
,3825508841.32951,196.092742919922,1000.03662109375,,,6,,,,24.2439994812012,,,10,,,,,,,,,,,,,,,,,,,,,,195.947311401367,196.219497680664,1000.03662109375,1000.03662109375,,,7.1453800201416,-99999999,1,0,0,0,0.0145721435546875,33.2355842590332,2,1,1,196.238174438477,0,1816139168,196.082683987088,,,0.000763096319309698,3.82372235841517E-5,0.000776217527243902,3.82643864967899E-5,0.817498624324799,0.965409219264984,24.920166015625,0.189654067158699,30,3,200,2.38639695453458E-5,-0.336987227201462,0.033741045743227,1,,,,,,,,,,,,,,,,
,3825508940.6827,199.391265869141,1000.03662109375,,,6,,,,24.2439994812012,,,10,,,,,,,,,,,,,,,,,,,,,,199.237518310547,199.511505126953,1000.03662109375,1000.03662109375,,,7.15091609954834,-99999999,1,0,0,0,0.0138092041015625,33.2355842590332,2,1,1,199.545013427734,0,1816138848,199.375284830729,,,0.000749048313634906,3.75660090893549E-5,0.000762625721949413,3.75950672676812E-5,0.812945604324341,0.964870989322662,24.9374160766602,0.189830377697945,30,3,200,5.62948916922323E-5,-0.336888372898102,0.0274539925158024,1,,,,,,,,,,,,,,,,
,3825509040.52093,202.702751159668,1000.03662109375,,,6,,,,24.2439994812012,,,10,,,,,,,,,,,,,,,,,,,,,,202.561752319336,202.829956054687,1000.03662109375,1000.03662109375,,,7.15676736831665,-99999999,1,0,0,0,0,33.2355842590332,2,1,1,202.85205078125,0,1816138880,202.702638626099,,,0.000735329534832126,3.69106952490011E-5,0.000749347530428142,3.69410741295052E-5,0.808432161808014,0.964434564113617,24.9544925689697,0.189979821443558,30,3,200,7.1458205638919E-5,-0.336435973644257,0.0217516403645277,1,,,,,,,,,,,,,,,,
,3825509140.51698,206.062652587891,1000.03662109375,,,6,,,,24.2439994812012,,,10,,,,,,,,,,,,,,,,,,,,,,205.914199829102,206.185913085938,1000.03662109375,1000.03662109375,,,7.16349601745606,-99999999,1,0,0,0,0.0138092041015625,33.2355842590332,2,1,1,206.21110534668,0,1816138848,206.05362616645,,,0.000722041185405095,3.62775500709093E-5,0.000736509450200579,3.63087247145586E-5,0.80379456281662,0.9640212059021,24.9720401763916,0.190128043293953,30,3,200,7.77636159909889E-5,-0.335734486579895,0.0163901560008526,1,,,,,,,,,,,,,,,,
,3825509240.29754,209.363540649414,1000.03662109375,,,6,,,,24.2439994812012,,,10,,,,,,,,,,,,,,,,,,,,,,209.216033935547,209.492477416992,1000.03662109375,1000.03662109375,,,7.16901350021362,-99999999,1,0,0,0,0.0145721435546875,33.2355842590332,2,1,1,209.511047363281,0,1816139040,209.353931003147,,,0.000709389301092596,3.5675687284278E-5,0.000724323577282675,3.5708614030711E-5,0.799206495285034,0.963531255722046,24.9896469116211,0.190361961722374,30,3,200,4.92101535201073E-5,-0.334740787744522,0.0116119487211108,1,,,,,,,,,,,,,,,,
,3825509340.24965,212.6748046875,1000.03662109375,,,6,,,,24.2439994812012,,,10,,,,,,,,,,,,,,,,,,,,,,212.527969360352,212.807006835938,1000.03662109375,1000.03662109375,,,7.17521524429321,-99999999,1,0,0,0,0,33.7243423461914,2,1,1,212.821640014648,0,1816138880,212.675615310669,,,0.000697111757784618,3.50930071146623E-5,0.000712490826299994,3.51258485708431E-5,0.794528424739838,0.963081896305084,25.0073051452637,0.190509185194969,30,3,200,4.10169341193978E-5,-0.33440974354744,0.00643604155629873,1,,,,,,,,,,,,,,,,
,3825509440.54026,216.020965576172,1000.03662109375,,,6,,,,24.2439994812012,,,10,,,,,,,,,,,,,,,,,,,,,,215.873107910156,216.155303955078,1000.03662109375,1000.03662109375,,,7.18185758590698,-99999999,1,0,0,0,0.0138092041015625,33.7243423461914,2,1,1,216.168823242187,0,1816138688,216.018981933594,,,0.000685085503668935,3.4522990871834E-5,0.000700967739672586,3.45583424871052E-5,0.789806962013245,0.96263176202774,25.0254135131836,0.190740585327148,30,3,200,2.50647426582873E-5,-0.335478812456131,0.1055648624897,1,,,,,,,,,,,,,,,,
,3825509540.26412,219.342597961426,1000.03662109375,,,6,,,,24.2439994812012,,,10,,,,,,,,,,,,,,,,,,,,,,219.198287963867,219.46891784668,1000.03662109375,1000.03662109375,,,7.18900108337402,-99999999,1,0,0,0,0.0145721435546875,33.7243423461914,2,1,1,219.493423461914,0,1816138944,219.332243177626,,,0.000673429519431353,3.397226540535E-5,0.000689821421433326,3.40094586699106E-5,0.784959554672241,0.962128043174744,25.0437355041504,0.190918475389481,30,3,200,5.93073054915294E-5,-0.33610212802887,0.0996510237455368,1,,,,,,,,,,,,,,,,
,3825509639.98756,222.657989501953,1000.03662109375,,,6,,,,24.2439994812012,,,10,,,,,,,,,,,,,,,,,,,,,,222.516830444336,222.779846191406,1000.03662109375,1000.03662109375,,,7.19635677337646,-99999999,1,0,0,0,0.01556396484375,33.2355842590332,2,1,1,222.79914855957,0,1816139168,222.655303955078,,,0.000662195061763668,3.34419475700553E-5,0.000679019051186087,3.347745101697E-5,0.780185282230377,0.961686670780182,25.0621318817139,0.191163882613182,30,3,200,3.42198291036766E-5,-0.336902976036072,0.093745045363903,1,,,,,,,,,,,,,,,,
,3825509739.82568,225.963768005371,1000.03662109375,,,6,,,,24.2439994812012,,,10,,,,,,,,,,,,,,,,,,,,,,225.814392089844,226.113143920898,1000.03662109375,1000.03662109375,,,7.20506763458252,-99999999,1,0,0,0,0,33.2355842590332,2,1,1,226.113143920898,0,1816138880,225.971701727973,,,0.000651182409394605,3.29232741210315E-5,0.000668572364088786,3.29629266743073E-5,0.775312066078186,0.961268603801727,25.0805892944336,0.191349282860756,30,3,200,6.98680232744664E-5,-0.230556711554527,0.0896269381046295,1,,,,,,,,,,,,,,,,
,3825509839.77084,229.291954040527,1000.03662109375,,,6,,,,24.2439994812012,,,10,,,,,,,,,,,,,,,,,,,,,,229.142486572266,229.426086425781,1000.03662109375,1000.03662109375,,,7.2146430015564,-99999999,1,0,0,0,0.015716552734375,33.2355842590332,2,1,1,229.441421508789,0,1816139040,229.281972249349,,,0.00064053752667474,3.24232947425936E-5,0.00065841211830686,3.24626310021835E-5,0.770387649536133,0.960762560367584,25.0996341705322,0.191632136702538,30,3,200,6.48235436528921E-5,-0.229874595999718,0.0855778530240059,1,,,,,,,,,,,,,,,,
,3825509939.52065,232.620941162109,1000.03662109375,,,6,,,,24.2439994812012,,,10,,,,,,,,,,,,,,,,,,,,,,232.474945068359,232.745956420898,1000.03662109375,1000.03662109375,,,7.22440910339356,-99999999,1,0,0,0,0.0145721435546875,33.2355842590332,2,1,1,232.766937255859,0,1816138752,232.617774963379,,,0.000630150131023142,3.19356718122206E-5,0.00064853853363122,3.19763630280214E-5,0.765510261058807,0.960329532623291,25.1182327270508,0.191845640540123,30,3,200,3.26836452586576E-5,-0.229940086603165,0.0808967649936676,1,,,,,,,,,,,,,,,,
,3825510039.17989,235.925994873047,1000.03662109375,,,6,,,,24.2439994812012,,,10,,,,,,,,,,,,,,,,,,,,,,235.781097412109,236.058029174805,1000.03662109375,1000.03662109375,,,7.2356276512146,-99999999,1,0,0,0,0.0138092041015625,33.2355842590332,2,1,1,236.070892333984,0,1816138560,235.921213785807,,,0.0006200500484208,3.14634084135318E-5,0.000639010824744424,3.15070891988978E-5,0.760494709014893,0.959940075874329,25.137336730957,0.192060515284538,30,3,200,5.04338495375123E-5,-0.231068775057793,0.0752827823162079,1,,,,,,,,,,,,,,,,
,3825510139.04383,239.261375427246,1000.03662109375,,,6,,,,24.2439994812012,,,10,,,,,,,,,,,,,,,,,,,,,,239.116882324219,239.393585205078,1000.03662109375,1000.03662109375,,,7.2491888999939,-99999999,1,0,0,0,0,34.2131004333496,2,1,1,239.405868530273,0,1816138816,239.251630995009,,,0.000610326488059722,3.1011178894132E-5,0.000629798257384412,3.10535080639362E-5,0.75532865524292,0.959422826766968,25.1572303771973,0.192340955138206,30,3,200,4.2700776248239E-5,-0.231171295046806,0.0709379911422729,1,,,,,,,,,,,,,,,,
,3825510238.8467,242.57935333252,1000.03662109375,,,6,,,,24.2439994812012,,,10,,,,,,,,,,,,,,,,,,,,,,242.431594848633,242.708206176758,1000.03662109375,1000.03662109375,,,7.26526165008545,-99999999,1,0,0,0,0.0138092041015625,33.7243423461914,2,1,1,242.727111816406,0,1816139008,242.573457505968,,,0.00059914914164405,3.05618235372463E-5,0.000620785105835435,3.06096673083464E-5,0.740876615047455,0.958967506885529,25.2134647369385,0.193115592002869,30,3,200,5.29188364453148E-5,-0.231547296047211,0.066261000931263,1,,,,,,,,,,,,,,,,
,3825510339.06043,245.914756774902,1000.03662109375,,,6,,,,24.2439994812012,,,10,,,,,,,,,,,,,,,,,,,,,,245.772491455078,246.035110473633,1000.03662109375,1000.03662109375,,,7.28393793106079,-99999999,1,0,0,0,0,33.7243423461914,2,1,1,246.057022094727,0,1816138688,245.904944525825,,,0.000588766408466924,3.01295806881806E-5,0.000612059421520598,3.01800646891303E-5,0.72951066493988,0.958451688289642,25.2576389312744,0.193751633167267,30,3,200,3.58320394298062E-5,-0.232465535402298,0.0612650513648987,1,,,,,,,,,,,,,,,,
,3825510438.76381,249.212089538574,1000.03662109375,,,6,,,,24.2439994812012,,,10,,,,,,,,,,,,,,,,,,,,,,249.061431884766,249.345306396484,1000.03662109375,1000.03662109375,,,7.30847644805908,-99999999,1,0,0,0,0.0006866455078125,33.2355842590332,2,1,1,249.362747192383,0,1816139040,249.208463880751,,,0.000579699783537584,2.97083503724833E-5,0.000603535797570501,2.97604310817097E-5,0.724628567695618,0.957927405834198,25.2763710021973,0.194026380777359,30,3,200,6.1003887822153E-5,-0.232869729399681,0.0568662956357002,1,,,,,,,,,,,,,,,,
,3825510538.68678,252.546417236328,1000.03662109375,,,6,,,,24.2439994812012,,,10,,,,,,,,,,,,,,,,,,,,,,252.397064208984,252.676727294922,1000.03662109375,1000.03662109375,,,7.33908653259277,-99999999,1,0,0,0,0,33.7243423461914,2,1,1,252.695770263672,0,1816138912,252.541388617622,,,0.000570943770323857,2.93021714745981E-5,0.000595281909609256,2.93539861025095E-5,0.719800710678101,0.957476913928986,25.2950038909912,0.194310203194618,30,3,200,2.74221529252827E-5,-0.232658386230469,0.0532673448324204,1,,,,,,,,,,,,,,,,
,3825510639.52195,255.920509338379,1000.03662109375,,,6,,,,24.2439994812012,,,10,,,,,,,,,,,,,,,,,,,,,,255.775100708008,256.053619384766,1000.03662109375,1000.03662109375,,,7.37487936019897,-99999999,1,0,0,0,0.001220703125,33.2355842590332,2,1,1,256.06591796875,0,1816138880,255.912190755208,,,0.00056242120958886,2.89004822968065E-5,0.000587171784266724,2.89545607121522E-5,0.715768456459045,0.957075715065002,25.3104228973389,0.194534063339233,30,3,200,5.15250576427206E-5,-0.232542738318443,0.0495576672255993,1,,,,,,,,,,,,,,,,
,3825510739.14705,259.216461181641,1000.03662109375,,,6,,,,24.2439994812012,,,10,,,,,,,,,,,,,,,,,,,,,,259.072601318359,259.347412109375,1000.03662109375,1000.03662109375,,,7.41526937484741,-99999999,1,0,0,0,0,33.7243423461914,2,1,1,259.360321044922,0,1816139136,259.209428575304,,,0.000554406816259779,2.85150582685201E-5,0.000579389774618985,2.85713364502542E-5,0.712791204452515,0.956654727458954,25.3216781616211,0.194692954421043,30,3,200,4.53369866590947E-5,-0.233451753854752,0.0449140295386314,1,,,,,,,,,,,,,,,,
,3825510839.19723,262.548843383789,1000.03662109375,,,6,,,,24.2439994812012,,,10,,,,,,,,,,,,,,,,,,,,,,262.394317626953,262.678833007813,1000.03662109375,1000.03662109375,,,7.4535813331604,-99999999,1,0,0,0,0.0145721435546875,33.2355842590332,2,1,1,262.703369140625,0,1816139040,262.553535461426,,,0.000546710811165689,2.81442058173274E-5,0.000571827551699741,2.81988420701188E-5,0.709971070289612,0.956314325332642,25.3326625823975,0.194888904690742,30,3,200,3.5265115002403E-5,-0.23410153388977,0.040673665702343,1,,,,,,,,,,,,,,,,
,3825510939.04103,265.865570068359,1000.03662109375,,,6,,,,24.2439994812012,,,10,,,,,,,,,,,,,,,,,,,,,,265.716094970703,265.995544433594,1000.03662109375,1000.03662109375,,,7.47077226638794,-99999999,1,0,0,0,0.0138092041015625,33.7243423461914,2,1,1,266.015045166016,0,1816138784,265.85693359375,,,0.000539119339835996,2.77774447577649E-5,0.000564399737940229,2.78328502618941E-5,0.707251727581024,0.956067800521851,25.3433246612549,0.195085078477859,30,3,200,3.86798055842519E-5,-0.234342366456985,0.0370102934539318,1,,,,,,,,,,,,,,,,
,3825511038.52197,269.165771484375,1000.03662109375,,,6,,,,24.2439994812012,,,10,,,,,,,,,,,,,,,,,,,,,,269.025726318359,269.296020507813,1000.03662109375,1000.03662109375,,,7.48532485961914,-99999999,1,0,0,0,0.001220703125,33.2355842590332,2,1,1,269.318481445313,0,1816138656,269.167964935303,,,0.000531964093382518,2.743750674662E-5,0.000557469634872769,2.74915197658056E-5,0.704001843929291,0.955723285675049,25.3559646606445,0.195296719670296,30,3,200,4.39211180491839E-5,-0.234710350632668,0.0332904793322086,1,,,,,,,,,,,,,,,,
,3825511139.003,272.531021118164,1000.03662109375,,,6,,,,24.2439994812012,,,10,,,,,,,,,,,,,,,,,,,,,,272.382843017578,272.662689208984,1000.03662109375,1000.03662109375,,,7.5190806388855,-99999999,1,0,0,0,0.0138092041015625,33.7243423461914,2,1,1,272.685180664062,0,1816138848,272.526664733887,,,0.000525425449575731,2.71225597026139E-5,0.000551117627688535,2.71787148986831E-5,0.701478660106659,0.955353856086731,25.3654708862305,0.195433959364891,30,3,200,2.39843720919453E-5,-0.236124366521835,0.029027946293354,1,,,,,,,,,,,,,,,,
,3825511238.51608,275.841171264648,1000.03662109375,,,6,,,,24.2439994812012,,,10,,,,,,,,,,,,,,,,,,,,,,275.693054199219,275.969879150391,1000.03662109375,1000.03662109375,,,7.57361602783203,-99999999,1,0,0,0,0.01495361328125,33.2355842590332,2,1,1,275.989288330078,0,1816138784,275.835340711806,,,0.000518569848338634,2.6798301506126E-5,0.000544565993560857,2.68560713605502E-5,0.698126494884491,0.954982876777649,25.3785629272461,0.195676550269127,30,3,200,3.23289896186907E-5,-0.238746806979179,0.023305831477046,1,,,,,,,,,,,,,,,,
,3825511338.43443,279.169143676758,1000.03662109375,,,6,,,,24.2439994812012,,,10,,,,,,,,,,,,,,,,,,,,,,279.026153564453,279.287353515625,1000.03662109375,1000.03662109375,,,7.6522421836853,-99999999,1,0,0,0,0.0138092041015625,33.7243423461914,2,1,1,279.312133789062,0,1816138784,279.165111541748,,,0.000511600154696992,2.64743211728778E-5,0.000537998563479093,2.65327571518692E-5,0.694040358066559,0.954507648944855,25.3942337036133,0.195928230881691,30,3,200,1.25633432617178E-5,-0.240949168801308,0.0180669724941254,1,,,,,,,,,,,,,,,,
,3825511437.97174,282.494888305664,1000.03662109375,,,6,,,,24.2439994812012,,,10,,,,,,,,,,,,,,,,,,,,,,282.346923828125,282.623382568359,1000.03662109375,1000.03662109375,,,7.75429677963257,-99999999,1,0,0,0,0.0138092041015625,33.2355842590332,2,1,1,282.642852783203,0,1816138976,282.487677680122,,,0.00050461123887924,2.61564710507226E-5,0.000531582002972818,2.6216858469068E-5,0.689121305942535,0.954045474529266,25.4133987426758,0.196269780397415,30,3,200,3.9061520510586E-5,-0.242377251386642,0.013476244173944,1,,,,,,,,,,,,,,,,
,3825511538.02148,285.82746887207,1000.03662109375,,,6,,,,24.2439994812012,,,10,,,,,,,,,,,,,,,,,,,,,,285.680450439453,285.954833984375,1000.03662109375,1000.03662109375,,,7.87226057052612,-99999999,1,0,0,0,0.0145721435546875,33.7243423461914,2,1,1,285.974487304687,0,1816139008,285.825080871582,,,0.000497957050256083,2.58539513696628E-5,0.000525397949290394,2.59125389293611E-5,0.684396147727966,0.953491568565369,25.4315891265869,0.196572422981262,30,3,200,3.29608956235461E-5,-0.243114948272705,0.00990457367151976,1,,,,,,,,,,,,,,,,
,3825511637.97846,289.132781982422,1000.03662109375,,,6,,,,24.2439994812012,,,10,,,,,,,,,,,,,,,,,,,,,,288.987365722656,289.257995605469,1000.03662109375,1000.03662109375,,,8.00164127349854,-99999999,1,0,0,0,0.0138092041015625,33.2355842590332,2,1,1,289.278198242188,0,1816139072,289.130641937256,,,0.000491145568722107,2.55507905607405E-5,0.000519307851445532,2.56128601419852E-5,0.678813397884369,0.952922761440277,25.453441619873,0.196992948651314,30,3,200,1.92826428246917E-5,-0.24536506831646,0.00493033649399877,1,,,,,,,,,,,,,,,,
,3825511737.72409,292.451507568359,1000.03662109375,,,6,,,,24.2439994812012,,,10,,,,,,,,,,,,,,,,,,,,,,292.300659179687,292.582946777344,1000.03662109375,1000.03662109375,,,8.1393575668335,-99999999,1,0,0,0,0.0145721435546875,33.2355842590332,2,1,1,292.602355957031,0,1816139168,292.444746229384,,,0.000484626322654063,2.52643383529074E-5,0.000513514097245586,2.53276935152019E-5,0.673047661781311,0.952438235282898,25.4756832122803,0.197361275553703,30,3,200,2.48425894824322E-5,-0.246412441134453,0.00107169162947685,1,,,,,,,,,,,,,,,,
,3825511837.84894,295.803451538086,1000.03662109375,,,6,,,,24.2439994812012,,,10,,,,,,,,,,,,,,,,,,,,,,295.656707763672,295.935516357422,1000.03662109375,1000.03662109375,,,8.27277374267578,-99999999,1,0,0,0,0.0138092041015625,33.7243423461914,2,1,1,295.9501953125,0,1816138752,295.801116943359,,,0.000478003153135366,2.49797863339388E-5,0.00050777898587772,2.50454057513568E-5,0.666480600833893,0.951948225498199,25.5018100738525,0.197910040616989,30,3,200,2.04662246687803E-5,-0.248028755187988,-0.0031947405077517,1,,,,,,,,,,,,,,,,
,3825511937.47712,299.109771728516,1000.03662109375,,,6,,,,24.2439994812012,,,10,,,,,,,,,,,,,,,,,,,,,,298.981567382812,299.218994140625,1000.03662109375,1000.03662109375,,,8.36415863037109,-99999999,1,0,0,0,0.0138092041015625,33.7243423461914,2,1,1,299.237976074219,0,1816139168,299.109239366319,,,0.000471421876363911,2.46967659578358E-5,0.000502075407888189,2.47646926562597E-5,0.659979701042175,0.951439499855042,25.5269451141357,0.198340699076653,30,3,200,8.47135452204384E-5,-0.248964071273804,-0.00684103183448315,1,,,,,,,,,,,,,,,,
,3825511973.77649,299.677963256836,1000.03662109375,,,6,,,,24.2439994812012,,,10,,,,,,,,,,,,,,,,,,,,,,299.643432617188,299.709838867188,1000.03662109375,1000.03662109375,,,8.37555503845215,-99999999,1,0,0,0,0.01556396484375,33.2355842590332,5,1,1,299.712493896484,0,1816671456,299.679229736328,,,0.000469955311204273,2.4631512824838E-5,0.000500792233820324,2.47015666087146E-5,0.658760011196136,0.951304316520691,25.5315685272217,0.198408171534538,30,3,200,6.36189070064574E-5,-0.248406559228897,0.0985349491238594,1,,,,,,,,,,,,,,,,