File: data/AP498/MH_1_8K.dat
[Header]
; MPMS3 Data File (default extension .dat)
; Copyright (c) 2007, Quantum Design, Inc. All rights reserved.
TITLE,
FILEOPENTIME,3825394583.07018,03/20/2021,9:36 am
BYAPP,SQUID AC,0.9.1.0
INFO,MPMS3 Measurement Release 1.1.16 Build 347, MultiVu Release 2.3.3.2,APPNAME
INFO,0,MOMENT_UNITS
INFO,SC_AP498,SAMPLE_MATERIAL
INFO,crystals, nujol, capsule,SAMPLE_COMMENT
INFO,1,SAMPLE_MASS
INFO,,SAMPLE_VOLUME
INFO,,SAMPLE_MOLECULAR_WEIGHT
INFO,,SAMPLE_SIZE
INFO,,SAMPLE_SHAPE
INFO,Standard,SAMPLE_HOLDER
INFO,Standard,SAMPLE_HOLDER_DETAIL
INFO,64.87,SAMPLE_OFFSET
DATATYPE,COMMENT,1
DATATYPE,TIME,2
STARTUPAXIS,X,2
STARTUPAXIS,Y1,5
FIELDGROUP, VSM,2,3,4,5,6,8,9,10,11,14,15
FIELDGROUP, DC, 2,3,4,14,56,57,58,59,60,61,62,63,64,65,66,67,68,69
FIELDGROUP, AC, 2,3,4,11,16,17,18,19,20,21,22,23,24,25,26,27,28,29,30
STARTUPGROUP, All
[Data]
Comment,Time Stamp (sec),Temperature (K),Magnetic Field (Oe),Moment (emu),M. Std. Err. (emu),Transport Action,Averaging Time (sec),Frequency (Hz),Peak Amplitude (mm),Center Position (mm),Lockin Signal' (V),Lockin Signal (V),Range,M. Quad. Signal (emu),AC Moment (emu),AC M. Std Err. (emu),AC Phase (deg),AC Phase Std. Err. (deg),AC Susceptibility (emu/Oe),AC Suscept. Std Err. (emu/Oe),AC X' (emu/Oe),AC X' Std Err. (emu/Oe),AC X'' (emu/Oe),AC X'' Std Err. (emu/Oe),AC Drive (Oe),AC Frequency (Hz),AC Averaging Time (sec),AC Cycles,AC Range,AC Measure Type,AC Signal' (V),AC Signal'' (V),AC Trim Coil Ratio,AC Trim Coil Phase,Min. Temperature (K),Max. Temperature (K),Min. Field (Oe),Max. Field (Oe),Mass (grams),Motor Lag (deg),Pressure (Torr),Measure Count,Measurement Number,SQUID Status (code),Motor Status (code),Measure Status (code),Motor Current (amps),Motor Temp. (C),Temp. Status (code),Field Status (code),Chamber Status (code),Chamber Temp (K),Redirection State,Evercool Status,Average Temp (K),Rotation Angle (deg),Rotator state,DC Moment Fixed Ctr (emu),DC Moment Err Fixed Ctr (emu),DC Moment Free Ctr (emu),DC Moment Err Free Ctr (emu),DC Fixed Fit,DC Free Fit,DC Calculated Center (mm),DC Calculated Center Err (mm),DC Scan Length (mm),DC Scan Time (s),DC Number of Points,DC Squid Drift,DC Min V (V),DC Max V (V),DC Scans per Measure,Map 01,Map 02,Map 03,Map 04,Map 05,Map 06,Map 07,Map 08,Map 09,Map 10,Map 11,Map 12,Map 13,Map 14,Map 15,Map 16
,3825394882.26883,1.802290558815,-0.352942258119583,,,6,,,,24.2439994812012,,,10,,,,,,,,,,,,,,,,,,,,,,1.79506528377533,1.80268478393555,-0.352942258119583,-0.352942258119583,,,2.40334677696228,-99999999,1,0,0,0,0.0174713134765625,33.2355842590332,1,1,1,1.80189633369446,0,1816139040,1.80006418909345,,,0.000442599052222004,2.1919197795026E-5,0.00044268729054682,2.19193412758757E-5,0.974220335483551,0.983291447162628,24.1698513031006,0.18745382130146,30,4,200,-0.000176652625668794,-0.137857988476753,0.0722562298178673,1,,,,,,,,,,,,,,,,
,3825394964.15283,1.80116921663284,251.824295043945,,,6,,,,24.2439994812012,,,100,,,,,,,,,,,,,,,,,,,,,,1.79817509651184,1.80208325386047,251.824295043945,251.824295043945,,,2.41098046302795,-99999999,1,0,0,0,0.016632080078125,33.2355842590332,1,1,1,1.80125570297241,0,1816139040,1.80007148356665,,,0.0203320414405016,0.00100677850641547,0.0203343963280418,0.00100678429653129,0.980448782444,0.98726487159729,24.1880416870117,0.187454834580421,30,4,200,0.000178475806023926,-4.82554244995117,4.80240726470947,1,,,,,,,,,,,,,,,,
,3825395042.35,1.80211710929871,1007.63745117187,,,6,,,,24.2439994812012,,,100,,,,,,,,,,,,,,,,,,,,,,1.79851222038269,1.80268275737762,1007.63745117187,1007.63745117187,,,2.41306281089783,-99999999,1,0,0,0,0.0170135498046875,33.2355842590332,1,1,1,1.80155146121979,0,1816138944,1.80037756399675,,,0.0781577481369363,0.00387013728571955,0.0781668538143672,0.00387015576221015,0.980288863182068,0.987149059772491,24.1876277923584,0.187435835599899,30,4,200,-0.00143435702193528,-3.21450710296631,0.476045936346054,1,,,,,,,,,,,,,,,,
,3825395128.0475,1.801294028759,2267.90600585938,,,6,,,,24.2439994812012,,,1000,,,,,,,,,,,,,,,,,,,,,,1.79855990409851,1.80218780040741,2267.90600585938,2267.90600585938,,,2.4154155254364,-99999999,1,0,0,0,0.0164794921875,33.7243423461914,1,1,1,1.8004002571106,0,1816138976,1.80012858997692,,,0.160585059644976,0.00795189754970285,0.160609027046185,0.00795196536266753,0.979007303714752,0.98737645149231,24.1807346343994,0.18743921816349,30,4,200,-3.82031284971163E-5,-0.660624980926514,0.0978617072105408,1,,,,,,,,,,,,,,,,
,3825395205.38662,1.80171012878418,4032.251953125,,,6,,,,24.2439994812012,,,1000,,,,,,,,,,,,,,,,,,,,,,1.79788994789124,1.8021627664566,4032.251953125,4032.251953125,,,2.41814494132996,-99999999,1,0,0,0,0.0174713134765625,33.2355842590332,1,1,1,1.80125749111176,0,1816138912,1.80014524459839,,,0.235925659313705,0.0116834008479744,0.235977090856922,0.0116835182596236,0.976090133190155,0.987510740756989,24.1670932769775,0.187459453940392,30,4,200,0.000180856484803371,-0.96885484457016,0.144768640398979,1,,,,,,,,,,,,,,,,
,3825395285.58161,1.80078893899918,6300.22119140625,,,6,,,,24.2439994812012,,,1000,,,,,,,,,,,,,,,,,,,,,,1.79898083209991,1.80165219306946,6300.22119140625,6300.22119140625,,,2.42298197746277,-99999999,1,0,0,0,0.0147247314453125,33.2355842590332,1,1,1,1.80076742172241,0,1816138912,1.80041420459747,,,0.282204550220026,0.0139764774593037,0.282293415988606,0.0139766719448063,0.972546458244324,0.987666964530945,24.1514911651611,0.187450259923935,30,4,200,0.000264359463471919,-1.15833735466003,0.173425957560539,1,,,,,,,,,,,,,,,,
,3825395368.78763,1.80149471759796,9072.41796875,,,6,,,,24.2439994812012,,,1000,,,,,,,,,,,,,,,,,,,,,,1.79790258407593,1.80213844776154,9072.41796875,9072.41796875,,,2.42543888092041,-99999999,1,0,0,0,0.01800537109375,33.2355842590332,1,1,1,1.80085098743439,0,1816138880,1.80018811225891,,,0.30403450990428,0.0150588997777045,0.304156818772123,0.0150591395508243,0.969627737998962,0.987739324569702,24.1391658782959,0.187510624527931,30,4,200,0.000255676306551322,-1.24844765663147,0.186572909355164,1,,,,,,,,,,,,,,,,
,3825395456.38969,1.80114930868149,12348.33984375,,,6,,,,24.2439994812012,,,1000,,,,,,,,,,,,,,,,,,,,,,1.79842483997345,1.80174803733826,12348.33984375,12348.33984375,,,2.42535591125488,-99999999,1,0,0,0,0.0160980224609375,33.2355842590332,1,1,1,1.80055058002472,0,1816139072,1.80012346397747,,,0.313807613081247,0.0155438386455088,0.3139522861747,0.0155441255759458,0.967829585075378,0.987730443477631,24.1318111419678,0.187507495284081,30,4,200,0.000254364509601146,-1.28880929946899,0.193077802658081,1,,,,,,,,,,,,,,,,
,3825395546.35142,1.80178505182266,16128.25,,,6,,,,24.2439994812012,,,1000,,,,,,,,,,,,,,,,,,,,,,1.79812157154083,1.80244553089142,16128.25,16128.25,,,2.42922639846802,-99999999,1,0,0,0,0.013885498046875,33.2355842590332,1,1,1,1.80112457275391,0,1816138976,1.80016624927521,,,0.318779964069135,0.0157905535962079,0.318934890965794,0.0157908285151004,0.967001497745514,0.987649261951447,24.128568649292,0.187505170702934,30,4,200,0.000255809572990984,-1.30918502807617,0.19714330136776,1,,,,,,,,,,,,,,,,
,3825395639.64199,1.80117321014404,20412.416015625,,,6,,,,24.2439994812012,,,1000,,,,,,,,,,,,,,,,,,,,,,1.79773664474487,1.80159723758698,20412.416015625,20412.416015625,,,2.43036842346191,-99999999,1,0,0,0,0.0138092041015625,33.2355842590332,1,1,1,1.80074918270111,0,1816139104,1.80004273761402,,,0.321847250945902,0.0159425682008686,0.322004552145004,0.0159428282542244,0.966857075691223,0.987573444843292,24.1281032562256,0.187499657273293,30,4,200,0.000247641815803945,-1.32095408439636,0.198757916688919,1,,,,,,,,,,,,,,,,
,3825395735.82591,1.80188119411469,25200.265625,,,6,,,,24.2439994812012,,,1000,,,,,,,,,,,,,,,,,,,,,,1.79749941825867,1.80241453647614,25200.265625,25200.265625,,,2.43185639381409,-99999999,1,0,0,0,0.015869140625,33.2355842590332,1,1,1,1.80070757865906,0,1816138880,1.80008681253953,,,0.324111240985303,0.0160545939476761,0.32426659439139,0.0160548685304698,0.967093586921692,0.987382531166077,24.1293678283691,0.187496840953827,30,4,200,0.000222174072405323,-1.33048903942108,0.200952157378197,1,,,,,,,,,,,,,,,,
,3825395833.44116,1.80166971683502,30492.431640625,,,6,,,,24.2439994812012,,,1000,,,,,,,,,,,,,,,,,,,,,,1.79788243770599,1.80236911773682,30492.431640625,30492.431640625,,,2.43194508552551,-99999999,1,0,0,0,0.0138092041015625,33.2355842590332,1,1,1,1.80097031593323,0,1816138976,1.80020916461945,,,0.326018712486108,0.016148772052716,0.326167438987456,0.0161490186889624,0.967674016952515,0.987198710441589,24.1320457458496,0.187492176890373,30,4,200,0.000221512076677755,-1.33803188800812,0.202597498893738,1,,,,,,,,,,,,,,,,
,3825395934.92047,1.80187278985977,36288.3515625,,,6,,,,24.2439994812012,,,1000,,,,,,,,,,,,,,,,,,,,,,1.7971967458725,1.80267918109894,36288.3515625,36288.3515625,,,2.43167233467102,-99999999,1,0,0,0,0,33.7243423461914,1,1,1,1.80106639862061,0,1816139008,1.80017434466969,,,0.32776683895945,0.0162349662834474,0.327907694359027,0.0162352280337706,0.968436777591705,0.986974477767944,24.1355724334717,0.187483623623848,30,4,200,0.000212808983633295,-1.34457695484161,0.204570397734642,1,,,,,,,,,,,,,,,,
,3825396039.41926,1.80159467458725,42588.1953125,,,6,,,,24.2439994812012,,,1000,,,,,,,,,,,,,,,,,,,,,,1.79786014556885,1.80251383781433,42588.1953125,42588.1953125,,,2.43278241157532,-99999999,1,0,0,0,0.0138092041015625,32.7468223571777,1,1,1,1.80091261863709,0,1816139104,1.80016182769429,,,0.329458272971023,0.0163182490956509,0.329587665399295,0.0163184563893526,0.969408869743347,0.986721634864807,24.1400661468506,0.187489852309227,30,4,200,0.000219896057387814,-1.35139083862305,0.204876497387886,1,,,,,,,,,,,,,,,,
,3825396145.29005,1.80194962024689,49392.515625,,,6,,,,24.2439994812012,,,1000,,,,,,,,,,,,,,,,,,,,,,1.79753386974335,1.80322206020355,49392.515625,49392.515625,,,2.43179869651794,-99999999,1,0,0,0,0,33.7243423461914,1,1,1,1.80067718029022,0,1816138976,1.80025852918625,,,0.331145470520785,0.0164012602185348,0.331261887250325,0.0164014255794705,0.970544219017029,0.986392080783844,24.1454811096191,0.187493145465851,30,4,200,0.00019750784849748,-1.35804438591003,0.206463411450386,1,,,,,,,,,,,,,,,,
,3825396253.59923,1.80120182037354,56700.14453125,,,6,,,,24.2439994812012,,,1000,,,,,,,,,,,,,,,,,,,,,,1.79799258708954,1.80210292339325,56700.14453125,56700.14453125,,,2.43528294563293,-99999999,1,0,0,0,0,33.2355842590332,1,1,1,1.80030071735382,0,1816138912,1.80010479146784,,,0.332863899937712,0.0164857588905842,0.332967566237995,0.0164859625073349,0.971834599971771,0.986017465591431,24.1518154144287,0.187463283538818,30,4,200,0.000197854911675677,-1.3645236492157,0.208377748727798,1,,,,,,,,,,,,,,,,
,3825396365.57063,1.80159521102905,64512.39453125,,,6,,,,24.2439994812012,,,1000,,,,,,,,,,,,,,,,,,,,,,1.79800236225128,1.8020213842392,64512.39453125,64512.39453125,,,2.43534016609192,-99999999,1,0,0,0,0.0148773193359375,33.2355842590332,1,1,1,1.80116903781891,0,1816139040,1.80010299249129,,,0.334617800837169,0.0165719500960041,0.334704943914324,0.0165720674927536,0.973319590091705,0.98566609621048,24.159158706665,0.187463596463203,30,4,200,0.000222251066588797,-1.37048470973969,0.209175497293472,1,,,,,,,,,,,,,,,,
,3825396479.09377,1.80156743526459,67228.4140625,,,6,,,,24.2439994812012,,,1000,,,,,,,,,,,,,,,,,,,,,,1.79812920093536,1.80219674110413,67228.4140625,67228.4140625,,,2.43622660636902,-99999999,1,0,0,0,0.0138092041015625,33.7243423461914,1,1,1,1.80093812942505,0,1816139040,1.80018979310989,,,0.335228985342289,0.0166019915153482,0.335310893996905,0.0166021312733965,0.97383189201355,0.985398411750793,24.1621265411377,0.187467962503433,30,4,200,8.47372973566962E-7,-1.37389945983887,0.210520550608635,1,,,,,,,,,,,,,,,,
,3825396590.77045,1.80136287212372,59248.5,,,6,,,,24.2439994812012,,,1000,,,,,,,,,,,,,,,,,,,,,,1.79805159568787,1.80166006088257,59248.5,59248.5,,,2.43359398841858,-99999999,1,0,0,0,0.0146484375,33.2355842590332,1,1,1,1.80106568336487,0,1816138944,1.80007191137834,,,0.333458575528817,0.0165151077028042,0.333558322485329,0.0165152429721649,0.972052335739136,0.985872983932495,24.1530857086182,0.187450528144836,30,4,200,0.000137162263854407,-1.36779963970184,0.208445996046066,1,,,,,,,,,,,,,,,,
,3825396700.01408,1.8016529083252,51772.45703125,,,6,,,,24.2439994812012,,,1000,,,,,,,,,,,,,,,,,,,,,,1.79851734638214,1.80218827724457,51772.45703125,51772.45703125,,,2.43375778198242,-99999999,1,0,0,0,0,33.2355842590332,1,1,1,1.80111753940582,0,1816139072,1.80034770965576,,,0.33172796144925,0.0164301092316173,0.33184435231959,0.0164303027039566,0.970548629760742,0.986227095127106,24.1458377838135,0.187473475933075,30,4,200,0.000236842810409144,-1.3602569103241,0.206979587674141,1,,,,,,,,,,,,,,,,
,3825396805.31685,1.80161213874817,44800.234375,,,6,,,,24.2439994812012,,,1000,,,,,,,,,,,,,,,,,,,,,,1.79697561264038,1.80270731449127,44800.234375,44800.234375,,,2.43380331993103,-99999999,1,0,0,0,0.0165557861328125,33.2355842590332,1,1,1,1.80051696300507,0,1816137728,1.79997994683006,,,0.330038851369945,0.016347056775917,0.330169136083988,0.0163472849327383,0.969311952590942,0.986555993556976,24.139965057373,0.18748827278614,30,4,200,0.000229031516937539,-1.35397255420685,0.205995962023735,1,,,,,,,,,,,,,,,,
,3825396909.936,1.80185371637344,38332.390625,,,6,,,,24.2439994812012,,,1000,,,,,,,,,,,,,,,,,,,,,,1.79764544963837,1.8028416633606,38332.390625,38332.390625,,,2.4347710609436,-99999999,1,0,0,0,0.0145721435546875,33.7243423461914,1,1,1,1.80086576938629,0,1816139040,1.80026082992554,,,0.328358990873257,0.0162643825691898,0.328499421618482,0.0162645581539682,0.968278706073761,0.986841022968292,24.1351337432861,0.187508270144463,30,4,200,0.000213366482057609,-1.34778237342834,0.204859927296638,1,,,,,,,,,,,,,,,,
,3825397010.25534,1.80179435014725,32368.333984375,,,6,,,,24.2439994812012,,,1000,,,,,,,,,,,,,,,,,,,,,,1.79791855812073,1.80228292942047,32368.333984375,32368.333984375,,,2.43468332290649,-99999999,1,0,0,0,0.0145721435546875,33.2355842590332,1,1,1,1.80130577087402,0,1816139104,1.80024471066215,,,0.326632057858557,0.0161792659163732,0.326784685431537,0.0161795957971491,0.967461109161377,0.987124860286713,24.1312999725342,0.187477052211761,30,4,200,0.000166535202879459,-1.34151840209961,0.203605368733406,1,,,,,,,,,,,,,,,,
,3825397108.63145,1.80181568861008,26908.291015625,,,6,,,,24.2439994812012,,,1000,,,,,,,,,,,,,,,,,,,,,,1.79840457439423,1.8027138710022,26908.291015625,26908.291015625,,,2.43590211868286,-99999999,1,0,0,0,0.0138092041015625,33.2355842590332,1,1,1,1.80091750621796,0,1816138720,1.80022912675684,,,0.324794454044058,0.0160885714194593,0.324953511030207,0.0160888905565695,0.966840982437134,0.987327456474304,24.1284294128418,0.187485814094543,30,4,200,0.000157839836901985,-1.33347725868225,0.202522277832031,1,,,,,,,,,,,,,,,,
,3825397204.57118,1.80176842212677,21952.251953125,,,6,,,,24.2439994812012,,,1000,,,,,,,,,,,,,,,,,,,,,,1.79512631893158,1.80243575572968,21952.251953125,21952.251953125,,,2.43685603141785,-99999999,1,0,0,0,0,33.2355842590332,1,1,1,1.80110108852386,0,1816139008,1.79999055645683,,,0.322681506816832,0.0159840749104562,0.322842545300595,0.0159843432893029,0.96652752161026,0.987480938434601,24.1268997192383,0.187505438923836,30,4,200,9.89863619906828E-5,-1.32530498504639,0.199263721704483,1,,,,,,,,,,,,,,,,
,3825397297.31895,1.80139660835266,17500.427734375,,,6,,,,24.2439994812012,,,1000,,,,,,,,,,,,,,,,,,,,,,1.79790329933166,1.80186080932617,17500.427734375,17500.427734375,,,2.43630814552307,-99999999,1,0,0,0,0,33.7243423461914,1,1,1,1.80093240737915,0,1816138880,1.80010762214661,,,0.319946814327205,0.0158485688544986,0.320107009461825,0.0158488698833171,0.966595530509949,0.987617671489716,24.1269664764404,0.187503203749657,30,4,200,6.589935219381E-5,-1.314657330513,0.197749063372612,1,,,,,,,,,,,,,,,,
,3825397388.26354,1.801837682724,13552.4033203125,,,6,,,,24.2439994812012,,,1000,,,,,,,,,,,,,,,,,,,,,,1.79758727550507,1.80222070217133,13552.4033203125,13552.4033203125,,,2.43347692489624,-99999999,1,0,0,0,0.015869140625,33.7243423461914,1,1,1,1.80145466327667,0,1816138976,1.8000552220778,,,0.315783200821284,0.0156419969724389,0.315935672735041,0.015642323748745,0.967229723930359,0.987720012664795,24.1293792724609,0.1875139772892,30,4,200,3.76566749764606E-5,-1.29824507236481,0.195365741848946,1,,,,,,,,,,,,,,,,
,3825397477.61062,1.80166286230087,10108.265625,,,6,,,,24.2439994812012,,,1000,,,,,,,,,,,,,,,,,,,,,,1.797886967659,1.80273842811584,10108.265625,10108.265625,,,2.43473267555237,-99999999,1,0,0,0,0.0145721435546875,33.2355842590332,1,1,1,1.8005872964859,0,1816139008,1.80024911165237,,,0.308066983641514,0.0152590582010359,0.30819796362436,0.015259221911728,0.96871292591095,0.987725973129272,24.1354312896729,0.187501072883606,30,4,200,1.2504624464782E-5,-1.26583540439606,0.190154626965523,1,,,,,,,,,,,,,,,,
,3825397562.2412,1.8021200299263,7168.3701171875,,,6,,,,24.2439994812012,,,1000,,,,,,,,,,,,,,,,,,,,,,1.79757642745972,1.80287253856659,7168.3701171875,7168.3701171875,,,2.43523740768433,-99999999,1,0,0,0,0.0145721435546875,33.2355842590332,1,1,1,1.80136752128601,0,1816138880,1.80055594444275,,,0.291196737815474,0.0144223213295666,0.291298467758975,0.0144225100845423,0.97131222486496,0.987715363502502,24.1462020874023,0.187491863965988,30,4,200,0.000138947900268249,-1.19641005992889,0.179135173559189,1,,,,,,,,,,,,,,,,
,3825397642.52119,1.80161893367767,4732.4638671875,,,6,,,,24.2439994812012,,,1000,,,,,,,,,,,,,,,,,,,,,,1.79514217376709,1.8021354675293,4732.4638671875,4732.4638671875,,,2.43640947341919,-99999999,1,0,0,0,0.0159454345703125,33.2355842590332,1,1,1,1.80110239982605,0,1816138816,1.79979668964039,,,0.253736637793045,0.0125658114671669,0.253799315636409,0.0125659076965003,0.974843561649322,0.987575352191925,24.1614952087402,0.187450215220451,30,4,200,4.44084907940123E-5,-1.04257261753082,0.155068069696426,1,,,,,,,,,,,,,,,,
,3825397723.17228,1.80031406879425,2800.38232421875,,,6,,,,24.2439994812012,,,1000,,,,,,,,,,,,,,,,,,,,,,1.79742062091827,1.80172038078308,2800.38232421875,2800.38232421875,,,2.43283772468567,-99999999,1,0,0,0,0.0138092041015625,33.7243423461914,1,1,1,1.79890775680542,0,1816139072,1.79950832236897,,,0.185628537773604,0.00919218000615453,0.185659056898294,0.00919222553846898,0.978138744831085,0.987385332584381,24.1766548156738,0.187446057796478,30,4,200,5.00667956657708E-5,-0.763754785060883,0.112704202532768,1,,,,,,,,,,,,,,,,
,3825397797.72319,1.80184882879257,1372.22692871094,,,6,,,,24.2439994812012,,,1000,,,,,,,,,,,,,,,,,,,,,,1.79487121105194,1.80234408378601,1372.22692871094,1372.22692871094,,,2.4373767375946,-99999999,1,0,0,0,0.0138092041015625,33.7243423461914,1,1,1,1.80150592327118,0,1816139040,1.79987285353921,,,0.100790460164961,0.00499087085358923,0.100802744049831,0.00499088615711174,0.979993283748627,0.987243354320526,24.1858673095703,0.187439933419228,30,4,200,2.67827053903602E-5,-0.415535271167755,0.0605195797979832,1,,,,,,,,,,,,,,,,
,3825397872.23978,1.80148065090179,448.362701416016,,,6,,,,24.2439994812012,,,1000,,,,,,,,,,,,,,,,,,,,,,1.79824995994568,1.8018844127655,448.362701416016,448.362701416016,,,2.43789958953857,-99999999,1,0,0,0,0.0147247314453125,33.2355842590332,1,1,1,1.80107688903809,0,1816139072,1.80002195184881,,,0.0324111134750523,0.00160489728665609,0.0324147621025366,0.00160490225083314,0.980393350124359,0.987133979797363,24.1881999969482,0.187442302703857,30,4,200,1.70041930687148E-5,-0.134498596191406,0.0186981651932001,1,,,,,,,,,,,,,,,,
,3825397961.55361,1.80118143558502,28.2605895996094,,,6,,,,24.2439994812012,,,10,,,,,,,,,,,,,,,,,,,,,,1.7981995344162,1.80176770687103,28.2605895996094,28.2605895996094,,,2.44213581085205,-99999999,1,0,0,0,0.0173187255859375,33.2355842590332,1,1,1,1.80059516429901,0,1816139008,1.80011097192764,,,-0.000161138535560758,8.24456739224402E-6,-0.000161138594328962,8.24456680123878E-6,0.747559249401092,0.747560918331146,24.2403659820557,0.193680807948112,30,4,200,0.0342560894787312,-0.0384332984685898,0.145293310284615,1,,,,,,,,,,,,,,,,
,3825398037.64846,1.80163478851318,-111.744033813477,,,6,,,,24.2439994812012,,,10,,,,,,,,,,,,,,,,,,,,,,1.79823052883148,1.80227279663086,-111.744033813477,-111.744033813477,,,2.4406886100769,-99999999,1,0,0,0,0.0145721435546875,33.2355842590332,1,1,1,1.80036354064941,0,1816139008,1.8000755851919,,,-0.0111633353691429,0.000552774683746814,-0.0111644431341487,0.000552776063510301,0.980313122272491,0.986065685749054,24.1915073394775,0.187463626265526,30,4,200,0.0445094481110573,-0.678713142871857,4.68121147155762,1,,,,,,,,,,,,,,,,
,3825398120.60174,1.80201518535614,-700.023132324219,,,6,,,,24.2439994812012,,,100,,,,,,,,,,,,,,,,,,,,,,1.79784882068634,1.80290377140045,-700.023132324219,-700.023132324219,,,2.43995475769043,-99999999,1,0,0,0,0.0145721435546875,33.7243423461914,1,1,1,1.80112659931183,0,1816139104,1.80010345849124,,,-0.0565944856682785,0.00280236962007477,-0.0566008020091766,0.00280237837761362,0.980634033679962,0.987424373626709,24.1884498596191,0.187421813607216,30,4,200,-0.000113210087874904,-0.345138520002365,2.3230767250061,1,,,,,,,,,,,,,,,,
,3825398199.91675,1.80109077692032,-1791.72399902344,,,6,,,,24.2439994812012,,,1000,,,,,,,,,,,,,,,,,,,,,,1.79814517498016,1.80187523365021,-1791.72399902344,-1791.72399902344,,,2.44529390335083,-99999999,1,0,0,0,0.0145721435546875,33.7243423461914,1,1,1,1.80030632019043,0,1816138848,1.80002658707755,,,-0.132658121885264,0.00656891607927707,-0.132675578175909,0.00656894418984461,0.979653596878052,0.987372756004333,24.1838226318359,0.187443301081657,30,4,200,-0.000108456624730024,-4.82709407806396,4.8803596496582,1,,,,,,,,,,,,,,,,
,3825398282.55809,1.80159741640091,-3388.17016601562,,,6,,,,24.2439994812012,,,1000,,,,,,,,,,,,,,,,,,,,,,1.79795718193054,1.80275237560272,-3388.17016601562,-3388.17016601562,,,2.44148564338684,-99999999,1,0,0,0,0.0138092041015625,33.2355842590332,1,1,1,1.8004424571991,0,1816138784,1.80010298165408,,,-0.213498061189763,0.0105724459094794,-0.21353727054353,0.0105724939620949,0.977335929870605,0.987526059150696,24.1726226806641,0.18745630979538,30,4,200,-0.000176220288267359,-0.132693365216255,0.875019550323486,1,,,,,,,,,,,,,,,,
,3825398361.07132,1.8012415766716,-5487.6845703125,,,6,,,,24.2439994812012,,,1000,,,,,,,,,,,,,,,,,,,,,,1.79824495315552,1.80180871486664,-5487.6845703125,-5487.6845703125,,,2.44397664070129,-99999999,1,0,0,0,0.0165557861328125,32.7468223571777,1,1,1,1.80067443847656,0,1816139072,1.80018023252487,,,-0.27013888305821,0.0133784567146046,-0.270212933018444,0.0133785697532074,0.973812580108643,0.987560451030731,24.1570796966553,0.187457233667374,30,4,200,-0.000208034485694952,-0.167757123708725,1.10732483863831,1,,,,,,,,,,,,,,,,
,3825398442.86525,1.80154156684875,-8092.44921875,,,6,,,,24.2439994812012,,,1000,,,,,,,,,,,,,,,,,,,,,,1.79798853397369,1.80207097530365,-8092.44921875,-8092.44921875,,,2.444331407547,-99999999,1,0,0,0,0,33.2355842590332,1,1,1,1.80101215839386,0,1816138784,1.80029889345169,,,-0.298650378459117,0.0147917975948989,-0.298760762803343,0.0147919771857315,0.970580637454987,0.987709283828735,24.1431617736816,0.187504321336746,30,4,200,-0.000231323094340041,-0.185363873839378,1.2242773771286,1,,,,,,,,,,,,,,,,
,3825398527.97859,1.80138069391251,-11200.49609375,,,6,,,,24.2439994812012,,,1000,,,,,,,,,,,,,,,,,,,,,,1.79785561561584,1.80197703838348,-11200.49609375,-11200.49609375,,,2.4443633556366,-99999999,1,0,0,0,0,33.2355842590332,1,1,1,1.80078434944153,0,1816138976,1.80022950172424,,,-0.311331625490199,0.0154209128414312,-0.311468072935562,0.0154211296226058,0.968403100967407,0.987727403640747,24.1341705322266,0.187486618757248,30,4,200,-0.00023832282749936,-0.193756371736526,1.2774510383606,1,,,,,,,,,,,,,,,,
,3825398617.81433,1.80188208818436,-14812.103515625,,,6,,,,24.2439994812012,,,1000,,,,,,,,,,,,,,,,,,,,,,1.79757082462311,1.80245339870453,-14812.103515625,-14812.103515625,,,2.44401884078979,-99999999,1,0,0,0,0,33.2355842590332,1,1,1,1.80131077766418,0,1816138048,1.80017688274384,,,-0.317430417775703,0.0157235503930565,-0.317580717943486,0.0157237811894189,0.967315018177032,0.987692832946777,24.1297721862793,0.187512561678886,30,4,200,-0.000229760276852176,-0.197967231273651,1.30189287662506,1,,,,,,,,,,,,,,,,
,3825398708.74934,1.80125910043716,-18928.16796875,,,6,,,,24.2439994812012,,,1000,,,,,,,,,,,,,,,,,,,,,,1.79790139198303,1.80195593833923,-18928.16796875,-18928.16796875,,,2.44538950920105,-99999999,1,0,0,0,0.0138092041015625,33.2355842590332,1,1,1,1.80059003829956,0,1816138944,1.80004447156733,,,-0.320957056995346,0.0158984246190127,-0.321113410230205,0.0158987110421968,0.966966152191162,0.987598717212677,24.1284999847412,0.187510296702385,30,4,200,-0.000226406133151613,-0.200904160737991,1.31667757034302,1,,,,,,,,,,,,,,,,
,3825398802.18291,1.80149382352829,-23548.33203125,,,6,,,,24.2439994812012,,,1000,,,,,,,,,,,,,,,,,,,,,,1.79829430580139,1.80208337306976,-23548.33203125,-23548.33203125,,,2.44524097442627,-99999999,1,0,0,0,0.016632080078125,33.2355842590332,1,1,1,1.80090427398682,0,1816139104,1.80010214718905,,,-0.323419274694476,0.016020306974983,-0.32357512423453,0.0160206224608183,0.967111587524414,0.987427234649658,24.1293601989746,0.187512591481209,30,4,200,-0.000193569096154533,-0.201841354370117,1.3262312412262,1,,,,,,,,,,,,,,,,
,3825398897.96072,1.80115288496017,-28672.4375,,,6,,,,24.2439994812012,,,1000,,,,,,,,,,,,,,,,,,,,,,1.79780375957489,1.80177128314972,-28672.4375,-28672.4375,,,2.44552397727966,-99999999,1,0,0,0,0.0156402587890625,33.7243423461914,1,1,1,1.80071914196014,0,1816138912,1.80007338523865,,,-0.325416119492297,0.0161189599644343,-0.325565308764764,0.0161191889204139,0.967601835727692,0.987276613712311,24.1316146850586,0.187502041459084,30,4,200,-0.000194564388948493,-0.203441545367241,1.3340961933136,1,,,,,,,,,,,,,,,,
,3825398996.39381,1.80177539587021,-34300.3515625,,,6,,,,24.2439994812012,,,1000,,,,,,,,,,,,,,,,,,,,,,1.79803395271301,1.80277287960052,-34300.3515625,-34300.3515625,,,2.44440054893494,-99999999,1,0,0,0,0.0145721435546875,33.2355842590332,1,1,1,1.80077791213989,0,1816139104,1.80031191110611,,,-0.327203062871011,0.0162071019941028,-0.327344480061895,0.0162073174840772,0.968304693698883,0.987059235572815,24.1348819732666,0.18748351931572,30,4,200,-0.000235012601478957,-0.205805584788322,1.34070777893066,1,,,,,,,,,,,,,,,,
,3825399095.87407,1.80170822143555,-40432.28515625,,,6,,,,24.2439994812012,,,1000,,,,,,,,,,,,,,,,,,,,,,1.79763627052307,1.80216681957245,-40432.28515625,-40432.28515625,,,2.44307255744934,-99999999,1,0,0,0,0.0165557861328125,33.7243423461914,1,1,1,1.80124962329865,0,1816138944,1.80025421380997,,,-0.328902996133223,0.0162908531266581,-0.329036009706666,0.0162911371503042,0.969206750392914,0.986776530742645,24.1391258239746,0.187479510903358,30,4,200,-0.000215612599276938,-0.206133618950844,1.3474839925766,1,,,,,,,,,,,,,,,,
,3825399197.8373,1.80171763896942,-47067.796875,,,6,,,,24.2439994812012,,,1000,,,,,,,,,,,,,,,,,,,,,,1.79789328575134,1.80265593528748,-47067.796875,-47067.796875,,,2.44412136077881,-99999999,1,0,0,0,0,32.7468223571777,1,1,1,1.80077934265137,0,1816138688,1.80016510053114,,,-0.330586328862632,0.0163736876390788,-0.330705816307537,0.0163738819340498,0.970303654670715,0.986463963985443,24.1443309783936,0.18746791779995,30,4,200,-0.000205265590921044,-0.207602977752686,1.35413658618927,1,,,,,,,,,,,,,,,,
,3825399304.52627,1.80186378955841,-54207.54296875,,,6,,,,24.2439994812012,,,1000,,,,,,,,,,,,,,,,,,,,,,1.79790031909943,1.80247807502747,-54207.54296875,-54207.54296875,,,2.4437735080719,-99999999,1,0,0,0,0,33.2355842590332,1,1,1,1.80124950408936,0,1816138912,1.80005513538014,,,-0.332290102271072,0.0164574745703257,-0.332395860191932,0.0164576307230804,0.971547842025757,0.986130177974701,24.1503295898438,0.187467664480209,30,4,200,-0.000180718387127854,-0.209458276629448,1.3607223033905,1,,,,,,,,,,,,,,,,
,3825399413.78522,1.80176222324371,-61851.59375,,,6,,,,24.2439994812012,,,1000,,,,,,,,,,,,,,,,,,,,,,1.7977968454361,1.80238628387451,-61851.59375,-61851.59375,,,2.44424510002136,-99999999,1,0,0,0,0,33.2355842590332,1,1,1,1.80113816261291,0,1816139040,1.80022268295288,,,-0.334032503917786,0.0165431060671192,-0.334122982330042,0.0165432300313484,0.972989022731781,0.985746443271637,24.1574974060059,0.187458276748657,30,4,200,-0.000168407263117842,-0.211570754647255,1.3671852350235,1,,,,,,,,,,,,,,,,
,3825399525.82732,1.80181908607483,-69999.640625,,,6,,,,24.2439994812012,,,1000,,,,,,,,,,,,,,,,,,,,,,1.79793047904968,1.80284202098846,-69999.640625,-69999.640625,,,2.44315075874329,-99999999,1,0,0,0,0,34.2131004333496,1,1,1,1.80079615116119,0,1816139040,1.80026106834412,,,-0.335824177657789,0.0166311057411149,-0.335897819478767,0.0166312074927036,0.974675357341766,0.985329210758209,24.1661720275879,0.187475278973579,30,4,200,-0.000223865485168062,-0.213336735963821,1.37348508834839,1,,,,,,,,,,,,,,,,
,3825399639.09114,1.80116617679596,-61851.62890625,,,6,,,,24.2439994812012,,,1000,,,,,,,,,,,,,,,,,,,,,,1.79821908473969,1.80209517478943,-61851.62890625,-61851.62890625,,,2.44091463088989,-99999999,1,0,0,0,0.0138092041015625,33.2355842590332,1,1,1,1.80023717880249,0,1816139072,1.80019359155135,,,-0.334036551039546,0.0165434128070074,-0.334129086893323,0.0165435405389247,0.972765445709229,0.985736548900604,24.156530380249,0.187454015016556,30,4,200,-0.000197097047930583,-0.211303219199181,1.36786150932312,1,,,,,,,,,,,,,,,,
,3825399749.42454,1.80145925283432,-54207.4921875,,,6,,,,24.2439994812012,,,1000,,,,,,,,,,,,,,,,,,,,,,1.7972856760025,1.80197954177856,-54207.4921875,-54207.4921875,,,2.44123148918152,-99999999,1,0,0,0,0.0138092041015625,33.7243423461914,1,1,1,1.80093896389008,0,1816139040,1.79983032941818,,,-0.332299884394988,0.0164581265405189,-0.332408688432633,0.0164582688035581,0.97119265794754,0.986117362976074,24.1488227844238,0.187469407916069,30,4,200,-0.00021407769236248,-0.210148259997368,1.36065900325775,1,,,,,,,,,,,,,,,,
,3825399854.40938,1.80136901140213,-47067.6328125,,,6,,,,24.2439994812012,,,1000,,,,,,,,,,,,,,,,,,,,,,1.79747068881989,1.80213344097137,-47067.6328125,-47067.6328125,,,2.43996500968933,-99999999,1,0,0,0,0.0138092041015625,33.7243423461914,1,1,1,1.80060458183289,0,1816139008,1.80023475885391,,,-0.330598795704508,0.0163745370491867,-0.330722964357191,0.016374725912851,0.969822704792023,0.986468553543091,24.1422672271729,0.187510132789612,30,4,200,-0.000322144187521189,-0.208826869726181,1.35407519340515,1,,,,,,,,,,,,,,,,
,3825399958.1078,1.80175888538361,-40431.765625,,,6,,,,24.2439994812012,,,1000,,,,,,,,,,,,,,,,,,,,,,1.79770720005035,1.80229723453522,-40431.765625,-40431.765625,,,2.43808794021606,-99999999,1,0,0,0,0.0154876708984375,33.7243423461914,1,1,1,1.80122053623199,0,1816139104,1.80015654997392,,,-0.328916833948535,0.0162917863283835,-0.329052715359768,0.0162919607546619,0.968709230422974,0.98677408695221,24.1370410919189,0.187504023313522,30,4,200,-0.000261287234025076,-0.207767471671104,1.34765350818634,1,,,,,,,,,,,,,,,,
,3825400061.32188,1.8011816740036,-34299.64453125,,,6,,,,24.2439994812012,,,1000,,,,,,,,,,,,,,,,,,,,,,1.79790890216827,1.80170047283173,-34299.64453125,-34299.64453125,,,2.43966889381409,-99999999,1,0,0,0,0.0138092041015625,33.2355842590332,1,1,1,1.80066287517548,0,1816138944,1.80005264282227,,,-0.327216477094347,0.0162080318953611,-0.327364496800295,0.0162083160287137,0.967801749706268,0.987046360969543,24.1328086853027,0.18751634657383,30,4,200,-0.000197497356566601,-0.205652564764023,1.34238636493683,1,,,,,,,,,,,,,,,,
,3825400159.84642,1.80162286758423,-28671.982421875,,,6,,,,24.2439994812012,,,1000,,,,,,,,,,,,,,,,,,,,,,1.79716300964355,1.8020658493042,-28671.982421875,-28671.982421875,,,2.44083595275879,-99999999,1,0,0,0,0.016632080078125,33.2355842590332,1,1,1,1.80117988586426,0,1816139104,1.80010030486367,,,-0.325431870324647,0.016120003673947,-0.325587221706577,0.0161202772533802,0.967095673084259,0.987244725227356,24.1295871734619,0.1875089854002,30,4,200,-0.000152240725583397,-0.204783245921135,1.33426463603973,1,,,,,,,,,,,,,,,,
,3825400254.63188,1.80182957649231,-23548.041015625,,,6,,,,24.2439994812012,,,1000,,,,,,,,,,,,,,,,,,,,,,1.79749250411987,1.80250883102417,-23548.041015625,-23548.041015625,,,2.43936514854431,-99999999,1,0,0,0,0.0138092041015625,33.7243423461914,1,1,1,1.80115032196045,0,1816139104,1.80001977356997,,,-0.32343323995124,0.016021232763415,-0.323593270562474,0.0160215191760106,0.966675281524658,0.987447559833527,24.1275520324707,0.1875079870224,30,4,200,-0.000109386877738871,-0.202507853507996,1.32678759098053,1,,,,,,,,,,,,,,,,
,3825400347.95164,1.80124288797379,-18928.216796875,,,6,,,,24.2439994812012,,,1000,,,,,,,,,,,,,,,,,,,,,,1.79778075218201,1.80170583724976,-18928.216796875,-18928.216796875,,,2.43915867805481,-99999999,1,0,0,0,0.016021728515625,33.2355842590332,1,1,1,1.80102789402008,0,1816139008,1.80013561248779,,,-0.320960519564035,0.0158988002382038,-0.321121829787383,0.0158991265833531,0.966574549674988,0.987590134143829,24.1269302368164,0.187492370605469,30,4,200,-6.90563465468585E-5,-0.20003741979599,1.31613647937775,1,,,,,,,,,,,,,,,,
,3825400439.60951,1.80099940299988,-14812.2431640625,,,6,,,,24.2439994812012,,,1000,,,,,,,,,,,,,,,,,,,,,,1.79931282997131,1.8020179271698,-14812.2431640625,-14812.2431640625,,,2.43860387802124,-99999999,1,0,0,0,0.015869140625,33.2355842590332,1,1,1,1.80100417137146,0,1816139072,1.80041599273682,,,-0.317409691220269,0.0157227034375332,-0.317564703843578,0.015722984521778,0.966960310935974,0.987692892551422,24.1283378601074,0.187495902180672,30,4,200,-6.78228097967804E-5,-0.197190269827843,1.30209720134735,1,,,,,,,,,,,,,,,,
,3825400528.31386,1.80124545097351,-11200.21875,,,6,,,,24.2439994812012,,,1000,,,,,,,,,,,,,,,,,,,,,,1.79792165756226,1.80212211608887,-11200.21875,-11200.21875,,,2.43917679786682,-99999999,1,0,0,0,0,33.2355842590332,1,1,1,1.80036878585815,0,1816138976,1.80015400648117,,,-0.31126987605811,0.0154179815670341,-0.31140932857421,0.0154182165807072,0.968137741088867,0.987737357616425,24.1330661773682,0.187490180134773,30,4,200,-2.31444573728368E-5,-0.193562105298042,1.27650010585785,1,,,,,,,,,,,,,,,,
,3825400614.87251,1.80200165510178,-8092.19677734375,,,6,,,,24.2439994812012,,,1000,,,,,,,,,,,,,,,,,,,,,,1.79806864261627,1.80299484729767,-8092.19677734375,-8092.19677734375,,,2.43910694122314,-99999999,1,0,0,0,0.0156402587890625,33.7243423461914,1,1,1,1.80100846290588,0,1816139072,1.80017605694858,,,-0.298424064349022,0.0147807091482167,-0.298536817608425,0.014780887938876,0.970315337181091,0.987743079662323,24.1420116424561,0.187490448355675,30,4,200,-0.000167680176673457,-0.186046063899994,1.22453629970551,1,,,,,,,,,,,,,,,,
,3825400696.78607,1.80167812108994,-5488.26416015625,,,6,,,,24.2439994812012,,,1000,,,,,,,,,,,,,,,,,,,,,,1.7978184223175,1.80193769931793,-5488.26416015625,-5488.26416015625,,,2.43942999839783,-99999999,1,0,0,0,0,33.7243423461914,1,1,1,1.80141854286194,0,1816139008,1.80007841370322,,,-0.269393234762324,0.0133415722630544,-0.269469047787856,0.0133417239024386,0.973684072494507,0.98764181137085,24.1563663482666,0.187454402446747,30,4,200,-0.000113082627649419,-0.166328698396683,1.10481953620911,1,,,,,,,,,,,,,,,,
,3825400777.27241,1.80168038606644,-3388.4345703125,,,6,,,,24.2439994812012,,,1000,,,,,,,,,,,,,,,,,,,,,,1.79791867733002,1.80232656002045,-3388.4345703125,-3388.4345703125,,,2.43835473060608,-99999999,1,0,0,0,0.01556396484375,33.7243423461914,1,1,1,1.80103421211243,0,1816138976,1.8001956820488,,,-0.211485284942903,0.0104727891256436,-0.211524519800737,0.010472838676985,0.9772589802742,0.987520754337311,24.1722869873047,0.187460780143738,30,4,200,-5.67539900657721E-5,-0.131204396486282,0.86739718914032,1,,,,,,,,,,,,,,,,
,3825400854.25436,1.80128252506256,-1792.21545410156,,,6,,,,24.2439994812012,,,1000,,,,,,,,,,,,,,,,,,,,,,1.79821598529816,1.80157852172852,-1792.21545410156,-1792.21545410156,,,2.43899321556091,-99999999,1,0,0,0,0.016632080078125,33.2355842590332,1,1,1,1.80098652839661,0,1816138976,1.79998889836398,,,-0.128730623549731,0.00637444358892292,-0.128747544601176,0.00637446463362091,0.97959166765213,0.987338960170746,24.1836280822754,0.187438920140266,30,4,200,1.57149879669305E-5,-0.080052100121975,0.528109014034271,1,,,,,,,,,,,,,,,,
,3825400928.76165,1.80148708820343,-700.287841796875,,,6,,,,24.2439994812012,,,1000,,,,,,,,,,,,,,,,,,,,,,1.79787075519562,1.80172872543335,-700.287841796875,-700.287841796875,,,2.43964195251465,-99999999,1,0,0,0,0.0145721435546875,33.2355842590332,1,1,1,1.80124688148499,0,1816138848,1.80002874677831,,,-0.0516323479769109,0.00255667434681987,-0.051638225333936,0.00255668235450329,0.980381071567535,0.987210214138031,24.1878910064697,0.187429785728455,30,4,200,4.00562203139998E-6,-0.0320270620286465,0.211201548576355,1,,,,,,,,,,,,,,,,
,3825401011.7818,1.80178445577621,-112.260848999023,,,6,,,,24.2439994812012,,,100,,,,,,,,,,,,,,,,,,,,,,1.79447019100189,1.80243217945099,-112.260848999023,-112.260848999023,,,2.44112157821655,-99999999,1,0,0,0,0.0171661376953125,33.2355842590332,1,1,1,1.80113673210144,0,1816138944,1.79974463852969,,,-0.00618830608611442,0.000306437981848628,-0.00618910437139288,0.000306439301430195,0.978434920310974,0.985310912132263,24.1844844818115,0.187441989779472,30,4,200,-0.00243119383230805,-0.0467302165925503,0.24834705889225,1,,,,,,,,,,,,,,,,
,3825401094.93506,1.80159997940063,27.9832801818848,,,6,,,,24.2439994812012,,,10,,,,,,,,,,,,,,,,,,,,,,1.79568648338318,1.80208277702332,27.9832801818848,27.9832801818848,,,2.44233703613281,-99999999,1,0,0,0,0.0157928466796875,33.2355842590332,1,1,1,1.80114579200745,0,1816138752,1.79986713149331,,,0.00472081897955265,0.000233835624021323,0.00472103595223073,0.000233835888705264,0.96793258190155,0.969360947608948,24.2082290649414,0.187496066093445,30,4,200,-0.0813424065709114,-2.17164492607117,0.227055042982101,1,,,,,,,,,,,,,,,,
,3825401176.58006,1.80204403400421,447.719848632812,,,6,,,,24.2439994812012,,,100,,,,,,,,,,,,,,,,,,,,,,1.79787826538086,1.80252230167389,447.719848632812,447.719848632812,,,2.44446086883545,-99999999,1,0,0,0,0.01556396484375,33.2355842590332,1,1,1,1.80128598213196,0,1816139008,1.80003326589411,,,0.0374585386270727,0.00185482049755083,0.037462705175442,0.0018548257106314,0.980680048465729,0.98749041557312,24.1884613037109,0.187434569001198,30,4,200,-0.000130092332256027,-1.54495143890381,0.223496153950691,1,,,,,,,,,,,,,,,,
,3825401249.71478,1.80134099721909,1371.63439941406,,,6,,,,24.2439994812012,,,100,,,,,,,,,,,,,,,,,,,,,,1.79862475395203,1.80177211761475,1371.63439941406,1371.63439941406,,,2.44395303726196,-99999999,1,0,0,0,0,33.7243423461914,1,1,1,1.80090987682343,0,1816138880,1.80020903348923,,,0.105132703500594,0.00520587590170449,0.105145454122291,0.00520589252776511,0.980092585086823,0.987342536449432,24.1860389709473,0.187453240156174,30,4,200,0.000596810830757022,-4.318687915802,0.639366447925568,1,,,,,,,,,,,,,,,,
,3825401335.73789,1.8012974858284,2799.77758789062,,,6,,,,24.2439994812012,,,1000,,,,,,,,,,,,,,,,,,,,,,1.7984459400177,1.80189418792725,2799.77758789062,2799.77758789062,,,2.44463205337524,-99999999,1,0,0,0,0.0138092041015625,33.2355842590332,1,1,1,1.80070078372955,0,1816138944,1.80015387318351,,,0.188180600908508,0.00931852828907964,0.18821106262135,0.00931857036063169,0.978263378143311,0.9874347448349,24.1771049499512,0.187432482838631,30,4,200,0.000173240929143503,-0.772862315177917,0.114929430186749,1,,,,,,,,,,,,,,,,
,3825401413.58994,1.80193102359772,4731.60693359375,,,6,,,,24.2439994812012,,,1000,,,,,,,,,,,,,,,,,,,,,,1.79827928543091,1.80253398418427,4731.60693359375,4731.60693359375,,,2.44525146484375,-99999999,1,0,0,0,0.0167083740234375,33.2355842590332,1,1,1,1.80099427700043,0,1816139040,1.80025795698166,,,0.254820590090852,0.0126194244734441,0.254882517408309,0.0126195357252453,0.975058674812317,0.987594604492188,24.162389755249,0.187447622418404,30,4,200,0.000203529605641961,-1.04578340053558,0.155426427721977,1,,,,,,,,,,,,,,,,
,3825401493.9211,1.80173093080521,7168.345703125,,,6,,,,24.2439994812012,,,1000,,,,,,,,,,,,,,,,,,,,,,1.79771161079407,1.80243039131165,7168.345703125,7168.345703125,,,2.44616222381592,-99999999,1,0,0,0,0.0138092041015625,33.7243423461914,1,1,1,1.80103147029877,0,1816138976,1.80014922618866,,,0.291564507809875,0.0144404395951667,0.291663680833582,0.0144406003654517,0.971556127071381,0.987692594528198,24.1472587585449,0.187498047947884,30,4,200,0.000218955727177672,-1.19800508022308,0.179505363106728,1,,,,,,,,,,,,,,,,
,3825401577.89585,1.80181455612183,10108.4306640625,,,6,,,,24.2439994812012,,,1000,,,,,,,,,,,,,,,,,,,,,,1.79824197292328,1.80278480052948,10108.4306640625,10108.4306640625,,,2.44529366493225,-99999999,1,0,0,0,0.000457763671875,33.2355842590332,1,1,1,1.80084431171417,0,1816139008,1.80017683722756,,,0.308164994324613,0.0152637829571171,0.308294604047288,0.0152640021797668,0.968985021114349,0.987748086452484,24.1365203857422,0.187490254640579,30,4,200,0.000235693136346526,-1.26527011394501,0.19000469148159,1,,,,,,,,,,,,,,,,
,3825401665.10417,1.80197197198868,13552.2392578125,,,6,,,,24.2439994812012,,,1000,,,,,,,,,,,,,,,,,,,,,,1.79747068881989,1.80235815048218,13552.2392578125,13552.2392578125,,,2.44529318809509,-99999999,1,0,0,0,0.0138092041015625,33.2355842590332,1,1,1,1.80158579349518,0,1816139072,1.80015808343887,,,0.315810290758049,0.0156431928096375,0.315957908553234,0.015643439387568,0.967525601387024,0.987670242786407,24.1306686401367,0.18750287592411,30,4,200,0.000245209288550541,-1.2964448928833,0.194725215435028,1,,,,,,,,,,,,,,,,
,3825401754.86222,1.80156928300858,17500.314453125,,,6,,,,24.2439994812012,,,1000,,,,,,,,,,,,,,,,,,,,,,1.79775857925415,1.80196809768677,17500.314453125,17500.314453125,,,2.44571399688721,-99999999,1,0,0,0,0.0146484375,33.7243423461914,1,1,1,1.80133509635925,0,1816138784,1.8000520251014,,,0.319951652838219,0.0158486110734037,0.320106881784764,0.015848863778417,0.966979563236237,0.98764169216156,24.1284866333008,0.187511935830116,30,4,200,0.000243784248596057,-1.31382095813751,0.197971060872078,1,,,,,,,,,,,,,,,,
,3825401847.39818,1.80184084177017,21952.2890625,,,6,,,,24.2439994812012,,,1000,,,,,,,,,,,,,,,,,,,,,,1.79790043830872,1.80255365371704,21952.2890625,21952.2890625,,,2.44651508331299,-99999999,1,0,0,0,0.0157928466796875,33.2355842590332,1,1,1,1.8011280298233,0,1816139072,1.8002678155899,,,0.322671478634903,0.0159833367909131,0.322828737979531,0.0159836494941974,0.966974258422852,0.987513363361359,24.1286602020264,0.187522172927856,30,4,200,0.000214634128496982,-1.32563400268555,0.199009358882904,1,,,,,,,,,,,,,,,,
,3825401942.69663,1.80158895254135,26908.35546875,,,6,,,,24.2439994812012,,,1000,,,,,,,,,,,,,,,,,,,,,,1.79809963703156,1.80227172374725,26908.35546875,26908.35546875,,,2.44690251350403,-99999999,1,0,0,0,0.0138092041015625,32.7468223571777,1,1,1,1.80090618133545,0,1816138592,1.80013691295277,,,0.324782860219284,0.0160877247690156,0.324936198599307,0.0160880206959684,0.967345356941223,0.987365067005158,24.1304187774658,0.187507793307304,30,4,200,0.000208445737371221,-1.33353686332703,0.201147615909576,1,,,,,,,,,,,,,,,,
,3825402042.69156,1.80170220136642,32368.548828125,,,6,,,,24.2439994812012,,,1000,,,,,,,,,,,,,,,,,,,,,,1.79727578163147,1.80234599113464,32368.548828125,32368.548828125,,,2.44275736808777,-99999999,1,0,0,0,0.0167083740234375,33.2355842590332,1,1,1,1.80105841159821,0,1816139040,1.8000630682165,,,0.326620566546175,0.0161784509795174,0.326766860302003,0.0161787113014129,0.967920899391174,0.987109541893005,24.1332092285156,0.187491998076439,30,4,200,0.000229686847887933,-1.34080064296722,0.202824473381042,1,,,,,,,,,,,,,,,,
,3825402144.5313,1.80191218852997,38332.3515625,,,6,,,,24.2439994812012,,,1000,,,,,,,,,,,,,,,,,,,,,,1.79758965969086,1.8030036687851,38332.3515625,38332.3515625,,,2.44363474845886,-99999999,1,0,0,0,0,33.7243423461914,1,1,1,1.80082070827484,0,1816138720,1.80025724172592,,,0.328341952922203,0.0162632770867744,0.32847738505623,0.0162634525512891,0.968780219554901,0.986887514591217,24.137149810791,0.187484234571457,30,4,200,0.00024009017215576,-1.34742045402527,0.203540131449699,1,,,,,,,,,,,,,,,,
,3825402248.69503,1.80135148763657,44800.3828125,,,6,,,,24.2439994812012,,,1000,,,,,,,,,,,,,,,,,,,,,,1.79753708839417,1.80195796489716,44800.3828125,44800.3828125,,,2.44081044197083,-99999999,1,0,0,0,0.0138092041015625,33.7243423461914,1,1,1,1.80074501037598,0,1816138784,1.80008927258578,,,0.330025813472678,0.0163461808280367,0.330151139942606,0.0163463865494482,0.969774425029755,0.98659074306488,24.1418514251709,0.187475562095642,30,4,200,0.000206603581318632,-1.35324776172638,0.204667985439301,1,,,,,,,,,,,,,,,,
,3825402356.11704,1.80138379335403,51772.1015625,,,6,,,,24.2439994812012,,,1000,,,,,,,,,,,,,,,,,,,,,,1.79765355587006,1.80172121524811,51772.1015625,51772.1015625,,,2.44374823570251,-99999999,1,0,0,0,0,33.2355842590332,1,1,1,1.80104637145996,0,1816138976,1.80003975738179,,,0.331713778611214,0.0164292119860633,0.331826824370862,0.0164294228849683,0.970946729183197,0.986265599727631,24.1474628448486,0.187471628189087,30,4,200,0.000173819120391272,-1.35972106456757,0.206437334418297,1,,,,,,,,,,,,,,,,
,3825402467.01706,1.80176585912704,59248.125,,,6,,,,24.2439994812012,,,1000,,,,,,,,,,,,,,,,,,,,,,1.79787862300873,1.80277907848358,59248.125,59248.125,,,2.44334363937378,-99999999,1,0,0,0,0.0145721435546875,33.2355842590332,1,1,1,1.80075263977051,0,1816139008,1.80018862811002,,,0.333443100077004,0.0165142422066186,0.333540945556775,0.0165143793506255,0.972278833389282,0.985909104347229,24.1539726257324,0.187502488493919,30,4,200,0.000190232676686719,-1.36705958843231,0.208619266748428,1,,,,,,,,,,,,,,,,
,3825402579.10879,1.801877617836,67228.3125,,,6,,,,24.2439994812012,,,1000,,,,,,,,,,,,,,,,,,,,,,1.79807686805725,1.80250084400177,67228.3125,67228.3125,,,2.44344449043274,-99999999,1,0,0,0,0.0138092041015625,33.7243423461914,1,1,1,1.80125439167023,0,1816138976,1.80023661851883,,,0.335215289500926,0.0166013186599913,0.33529734817463,0.0166014409441616,0.973825037479401,0.985489845275879,24.1618728637695,0.187455222010612,30,4,200,0.000205418618861586,-1.37356233596802,0.210063055157661,1,,,,,,,,,,,,,,,,
,3825402616.43106,1.80173110961914,70000.421875,,,6,,,,24.2439994812012,,,1000,,,,,,,,,,,,,,,,,,,,,,1.79795861244202,1.80230057239532,70000.421875,70000.421875,,,2.44375205039978,-99999999,1,0,0,0,0.0138092041015625,33.2355842590332,1,1,1,1.80116164684296,0,1816139008,1.80024551153183,,,0.335815733009761,0.0166308081334197,0.335891232695184,0.0166308853914535,0.974404633045197,0.98533684015274,24.1649188995361,0.18743884563446,30,4,200,0.00021720897348132,-1.37518227100372,0.210399553179741,1,,,,,,,,,,,,,,,,