File: data/AP424/ac_1500_Oe.csv
[Data]

Comment,Time Stamp (sec),Temperature (K),Magnetic Field (Oe),Moment (emu),M. Std. Err. (emu),Transport Action,Averaging Time (sec),Frequency (Hz),Peak Amplitude (mm),Center Position (mm),Lockin Signal' (V),Lockin Signal (V),Range,M. Quad. Signal (emu),AC Moment (emu),AC M. Std Err. (emu),AC Phase (deg),AC Phase Std. Err. (deg),AC Susceptibility (emu/Oe),AC Suscept. Std Err. (emu/Oe),AC X' (emu/Oe),AC X' Std Err. (emu/Oe),AC X'' (emu/Oe),AC X'' Std Err. (emu/Oe),AC Drive (Oe),AC Frequency (Hz),AC Averaging Time (sec),AC Cycles,AC Range,AC Measure Type,AC Signal' (V),AC Signal'' (V),AC Trim Coil Ratio,AC Trim Coil Phase,Min. Temperature (K),Max. Temperature (K),Min. Field (Oe),Max. Field (Oe),Mass (grams),Motor Lag (deg),Pressure (Torr),Measure Count,Measurement Number,SQUID Status (code),Motor Status (code),Measure Status (code),Motor Current (amps),Motor Temp. (C),Temp. Status (code),Field Status (code),Chamber Status (code),Chamber Temp (K),Redirection State,Evercool Status,Average Temp (K),Rotation Angle (deg),Rotator state,DC Moment Fixed Ctr (emu),DC Moment Err Fixed Ctr (emu),DC Moment Free Ctr (emu),DC Moment Err Free Ctr (emu),DC Fixed Fit,DC Free Fit,DC Calculated Center (mm),DC Calculated Center Err (mm),DC Scan Length (mm),DC Scan Time (s),DC Number of Points,DC Squid Drift,DC Min V (V),DC Max V (V),DC Scans per Measure,Map 01,Map 02,Map 03,Map 04,Map 05,Map 06,Map 07,Map 08,Map 09,Map 10,Map 11,Map 12,Map 13,Map 14,Map 15,Map 16

,3825921758.68392,1.99984812736511,1499.86584472656,,,5,,,,26.0400008410215,,,,,6.69558480108878E-6,2.09707178870191E-7,30.5303172831239,0.0291054545787915,2.2318680905049E-6,6.99025962293951E-8,1.92244297599345E-6,5.80212537598551E-8,1.13377607024819E-6,3.89859855812872E-8,2.99999127617532,0.500452220439911,63.9421680892357,32,1,3,0.0190186135216769,0.011469737052799,0.0263493321835995,178.881820678711,1.99717462062836,2.00280237197876,1499.86584472656,1499.86584472656,,,2.43498611450195,0,1,,,,,,1,1,1,1.99963307380676,0,0,1.99999190523743,,,,,,,,,,,,,,,,,,,,,,,,,,,,,,,,,

,3825922026.77288,2.00002861022949,1499.86584472656,,,5,,,,26.0400008410215,,,,,5.57898994322665E-6,1.44029038085275E-7,35.8491193657248,0.0341161990171828,1.85965895966699E-6,4.80095669383103E-8,1.50736895989066E-6,4.26542545730338E-8,1.08911444073974E-6,2.20348152799819E-8,3.00000702506533,0.700587213039398,45.6759692503843,32,1,3,0.0148692459880717,0.01101665458177,0.0263898782432079,178.600936889648,1.99815785884857,2.00257849693298,1499.86584472656,1499.86584472656,,,2.42861199378967,0,1,,,,,,1,1,1,2.00018548965454,0,0,2.00000727011098,,,,,,,,,,,,,,,,,,,,,,,,,,,,,,,,,

,3825922227.01078,1.99984222650528,1499.86584472656,,,5,,,,26.0400008410215,,,,,5.11182617049433E-6,9.87428086095082E-8,35.0083859341319,0.0240794101072413,1.70393790111322E-6,3.29141892623941E-8,1.39564115469451E-6,2.87549204693426E-8,9.77542908609695E-7,1.6015567539194E-8,3.00000731667197,0.900754988193512,35.52575386141,32,1,3,0.0137495741617469,0.00992259091850521,0.0263114403933287,178.416015625,1.99864292144775,2.003338098526,1499.86584472656,1499.86584472656,,,2.42451858520508,0,1,,,,,,1,1,1,2.00000429153442,0,0,2.00001548187077,,,,,,,,,,,,,,,,,,,,,,,,,,,,,,,,,

,3825922390.14304,1.99975311756134,1499.86584472656,,,5,,,,26.0400008410215,,,,,4.80380251888744E-6,1.66137570228287E-7,35.2463147166445,0.0469476138411133,1.60127221922624E-6,5.53793530708911E-8,1.3077248753377E-6,5.32710870803027E-8,9.24082447884774E-7,1.51348613417247E-8,2.9999911702763,1.13111853599548,28.290580502102,31,1,3,0.0128591000636637,0.0094098797499283,0.0263378787785769,177.898239135742,1.99889945983887,2.00304365158081,1499.86584472656,1499.86584472656,,,2.42232394218445,0,1,,,,,,1,1,1,2.00028538703918,0,0,1.99999337792397,,,,,,,,,,,,,,,,,,,,,,,,,,,,,,,,,

,3825922520.00058,1.99984818696976,1499.86584472656,,,5,,,,26.0400008410215,,,,,4.37984993053832E-6,9.55166120098398E-8,33.0033245649738,0.0248848780925275,1.45995006392069E-6,3.18388725688858E-8,1.22437100919852E-6,2.88170312377132E-8,7.9521683896671E-7,1.35385566846103E-8,2.99999982107351,1.50037264823914,21.3280347636007,31,1,3,0.0120189770007908,0.00816124675008526,0.0263272486627102,177.274871826172,1.99757552146912,2.0025794506073,1499.86584472656,1499.86584472656,,,2.42011070251465,0,1,,,,,,1,1,1,1.99976527690887,0,0,2.00000918128274,,,,,,,,,,,,,,,,,,,,,,,,,,,,,,,,,

,3825922630.33805,1.99992161989212,1499.86584472656,,,5,,,,26.0400008410215,,,,,3.98011692965547E-6,7.31275671668207E-8,32.4588180795129,0.0187039218037256,1.32670822739686E-6,2.43759032019534E-8,1.11944644181947E-6,1.72682111678256E-8,7.12035381522747E-7,1.720446279238E-8,2.99999415656362,1.941321849823,16.4836139885396,31,1,3,0.0109576479581825,0.00736346603027612,0.0262656379491091,176.602920532227,1.99749720096588,2.0025360584259,1499.86584472656,1499.86584472656,,,2.41921401023865,0,1,,,,,,1,1,1,1.99963819980621,0,0,1.99999993732295,,,,,,,,,,,,,,,,,,,,,,,,,,,,,,,,,

,3825922727.70556,1.99980968236923,1499.86584472656,,,5,,,,26.0400008410215,,,,,3.70499740628693E-6,1.22884801044526E-7,31.6332223304694,0.0346661721546996,1.23500104847285E-6,4.09616637986964E-8,1.05150825260178E-6,3.3389780797898E-8,6.47732957660333E-7,2.37272088418708E-8,2.9999953529338,2.5516369342804,12.5409691206812,30,1,3,0.0102545034250469,0.00677258518300519,0.0262135155498981,175.705459594727,1.9982088804245,2.00305724143982,1499.86584472656,1499.86584472656,,,2.41816067695618,0,1,,,,,,1,1,1,1.99988806247711,0,0,1.99999420081868,,,,,,,,,,,,,,,,,,,,,,,,,,,,,,,,,

,3825922811.72099,2.00008535385132,1499.86584472656,,,5,,,,26.0400008410215,,,,,3.40797803178435E-6,6.55851589099474E-8,29.2177606443217,0.0180148417802382,1.13599305214753E-6,2.18617268511802E-8,9.91461573728775E-7,1.69000704649811E-8,5.5451254480555E-7,1.38680466971482E-8,2.99999900997788,3.3389036655426,12,40,1,3,0.00963842431776314,0.00590524836838833,0.026135690510273,174.403121948242,1.99776041507721,2.002601146698,1499.86584472656,1499.86584472656,,,2.41781306266785,0,1,,,,,,1,1,1,2.00021815299988,0,0,1.99999492139701,,,,,,,,,,,,,,,,,,,,,,,,,,,,,,,,,

,3825922894.861,1.99992167949677,1499.86584472656,,,5,,,,26.0400008410215,,,,,3.09142877528489E-6,9.65578119780582E-8,28.5239939940544,0.0294300396911743,1.03047603706545E-6,3.21859304119631E-8,9.05393984606339E-7,2.63733507920301E-8,4.92079867099602E-7,1.84494033639102E-8,3.00000064444832,4.39734554290771,12,52,1,3,0.00875014514587071,0.00534424999999799,0.026013758033514,172.616790771484,1.99881374835968,2.00250291824341,1499.86584472656,1499.86584472656,,,2.41734600067139,0,1,,,,,,1,1,1,2.00002360343933,0,0,2.00002003010408,,,,,,,,,,,,,,,,,,,,,,,,,,,,,,,,,

,3825922975.18179,2.00008392333984,1499.86584472656,,,5,,,,26.0400008410215,,,,,2.88211933515695E-6,6.52985121956678E-8,28.2974300360203,0.0214872802691502,9.60711065646246E-7,2.17662754180156E-8,8.45904765151022E-7,1.61702110973862E-8,4.55423846488015E-7,1.45703472381024E-8,2.99998557133119,5.80182075500488,12,69,1,3,0.00810830977595231,0.00506074036476252,0.0258811488747597,170.397735595703,1.99847412109375,2.00294017791748,1499.86584472656,1499.86584472656,,,2.41696190834045,0,1,,,,,,1,1,1,2.00034928321838,0,0,1.99997811679599,,,,,,,,,,,,,,,,,,,,,,,,,,,,,,,,,

,3825923054.66355,1.99994844198227,1499.86584472656,,,5,,,,26.0400008410215,,,,,2.74587495830995E-6,4.0275296673161E-8,26.2835606561282,0.0133521654485844,9.15276968424248E-7,1.34248835074729E-8,8.20649704220515E-7,1.0279452194667E-8,4.05297411650585E-7,8.63483409028638E-9,3.00004813082677,7.55385589599609,12,90,1,3,0.00781530477090931,0.00467127183084105,0.0254886914044619,167.603317260742,1.99853622913361,2.00385499000549,1499.86584472656,1499.86584472656,,,2.41625666618347,0,1,,,,,,1,1,1,2.00009703636169,0,0,2.00001690937923,,,,,,,,,,,,,,,,,,,,,,,,,,,,,,,,,

,3825923136.67672,1.9996822476387,1499.86584472656,,,5,,,,26.0400008410215,,,,,2.54179559684771E-6,2.32480476394909E-8,25.7025793791269,0.00861524960001034,8.47285423185925E-7,7.74953419027924E-9,7.63452883218687E-7,6.38737253183662E-9,3.67467391000106E-7,4.38825162289561E-9,2.99992839165126,9.90830421447754,12,118,1,3,0.00719392084441787,0.00438775651170845,0.0249298270791769,164.039291381836,1.99796450138092,2.00290632247925,1499.86584472656,1499.86584472656,,,2.4159152507782,0,1,,,,,,1,1,1,1.99942135810852,0,0,2.00000863671303,,,,,,,,,,,,,,,,,,,,,,,,,,,,,,,,,

,3825923212.99958,1.99975645542145,1499.86584472656,,,5,,,,26.0400008410215,,,,,2.33624530707446E-6,2.55070122817138E-8,24.6783436950646,0.00976794786796935,7.78717945782953E-7,8.50200453990408E-9,7.0759456409689E-7,4.61305626403302E-9,3.25133160328125E-7,7.14169399382354E-9,3.0001174619464,12.9862041473389,12,155,1,3,0.00659873853459838,0.00405049435587589,0.0240201782435179,159.702682495117,1.99872100353241,2.00367903709412,1499.86584472656,1499.86584472656,,,2.41571807861328,0,1,,,,,,1,1,1,2.00044941902161,0,0,2.00001606300696,,,,,,,,,,,,,,,,,,,,,,,,,,,,,,,,,

,3825923277.47897,1.99965673685074,1499.86584472656,,,5,,,,26.0400008410215,,,,,2.18266397384168E-6,1.24846284696632E-8,23.0729844384541,0.00536351215394499,7.27593224361353E-7,4.16176341940879E-9,6.69390412921634E-7,3.630948966183E-9,2.85146234807957E-7,2.03383489106264E-9,2.99984098361763,17.0489253997803,12,204,1,3,0.006192101120842,0.0037343949551377,0.0227845963090658,154.714965820313,1.99876034259796,2.00220608711243,1499.86584472656,1499.86584472656,,,2.41553974151611,0,1,,,,,,1,1,1,1.99992573261261,0,0,2.00001118296669,,,,,,,,,,,,,,,,,,,,,,,,,,,,,,,,,

,3825923341.54693,1.99972397089005,1499.86584472656,,,5,,,,26.0400008410215,,,,,2.05663993871369E-6,1.5893879311218E-8,21.6106692013991,0.00691224218424742,6.85566279604653E-7,5.29811149864768E-9,6.37376400041974E-7,3.80809878912595E-9,2.52492471967974E-7,3.68352671557575E-9,2.99991408547647,22.3982219696045,12,268,1,3,0.00586497346831928,0.00346221952303712,0.0210716426372528,149.209060668945,1.99840986728668,2.00371956825256,1499.86584472656,1499.86584472656,,,2.41574263572693,0,1,,,,,,1,1,1,2.00008153915405,0,0,2.00002282574063,,,,,,,,,,,,,,,,,,,,,,,,,,,,,,,,,

,3825923405.73922,1.99965089559555,1499.86584472656,,,5,,,,26.0400008410215,,,,,1.96755726724564E-6,1.78175531673935E-8,20.6396341114112,0.00794239966592195,6.55904521217928E-7,5.93965617879789E-9,6.13805897441403E-7,3.84509844939239E-9,2.3119918083824E-7,4.52711093710019E-9,2.99976170859768,29.3438262939453,12,352,1,3,0.00563638571901138,0.00326328425126049,0.0189482718706131,143.531066894531,1.99866223335266,2.00302672386169,1499.86584472656,1499.86584472656,,,2.41559934616089,0,1,,,,,,1,1,1,2.00010561943054,0,0,2.00000462267134,,,,,,,,,,,,,,,,,,,,,,,,,,,,,,,,,

,3825923469.78584,1.99964684247971,1499.86584472656,,,5,,,,26.0400008410215,,,,,1.83923287060982E-6,1.41592160919441E-8,19.2836152292598,0.00649979140300108,6.13121244370241E-7,4.72007450950001E-9,5.78722340349153E-7,3.33539941749772E-9,2.02479907840041E-7,3.33979252364389E-9,2.99978656342101,38.507984161377,12,462,1,3,0.00533943071252227,0.0029201442045427,0.0165485162287951,138.142150878906,1.9985898733139,2.00379395484924,1499.86584472656,1499.86584472656,,,2.41523861885071,0,1,,,,,,1,1,1,1.99983954429626,0,0,2.00001166358827,,,,,,,,,,,,,,,,,,,,,,,,,,,,,,,,,

,3825923534.14724,1.99973064661026,1499.86584472656,,,5,,,,26.0400008410215,,,,,1.75455801463871E-6,1.45065595845543E-8,17.9906325315445,0.00616951510475786,5.84887344383117E-7,4.83580653404187E-9,5.56290462515719E-7,4.37444645374627E-9,1.80649181934441E-7,2.06136921922997E-9,2.99982215633209,50.5467147827148,12,606,1,3,0.00517727295463938,0.0026228547471481,0.0140556246042252,133.671524047852,1.99892747402191,2.003005027771,1499.86584472656,1499.86584472656,,,2.41498279571533,0,1,,,,,,1,1,1,2.00017499923706,0,0,2.00004404877859,,,,,,,,,,,,,,,,,,,,,,,,,,,,,,,,,

,3825923598.34505,1.99971759319305,1499.86584472656,,,5,,,,26.0400008410215,,,,,1.6783811488868E-6,7.78978553224221E-9,16.5093466794365,0.00339620044218393,5.59424286381037E-7,2.5964276441774E-9,5.36361119833946E-7,2.06609783337504E-9,1.58972580413754E-7,1.57247456398237E-9,3.00019357354754,66.1627731323242,12,793,1,3,0.00504693458917313,0.00230994035556345,0.0117982635274529,130.543426513672,1.99881172180176,2.00277757644653,1499.86584472656,1499.86584472656,,,2.4149158000946,0,1,,,,,,1,1,1,2.00013017654419,0,0,2.00000101611728,,,,,,,,,,,,,,,,,,,,,,,,,,,,,,,,,

,3825923662.65353,1.99948728084564,1499.86584472656,,,5,,,,26.0400008410215,,,,,1.58496938303844E-6,7.34873226771346E-9,15.446617584452,0.0034879568472003,5.28318060115187E-7,2.44955392673986E-9,5.09234694365755E-7,1.73548795232674E-9,1.40712468168568E-7,1.72869777790549E-9,3.00002877564487,86.8827819824219,12,1042,1,3,0.00483569256485821,0.00202005207547695,0.00979311112314463,128.861633300781,1.99819457530975,2.00243020057678,1499.86584472656,1499.86584472656,,,2.41484236717224,0,1,,,,,,1,1,1,1.99993705749512,0,0,2.00000775428045,,,,,,,,,,,,,,,,,,,,,,,,,,,,,,,,,

,3825923722.76764,1.99967080354691,1499.86584472656,,,5,,,,26.0400008410215,,,,,1.54848665354315E-6,7.02023803267127E-9,15.1221069231653,0.00303084568178066,5.16129765817752E-7,2.33993221930377E-9,4.9825724819519E-7,1.91241750129994E-9,1.34646387935377E-7,1.34831082902184E-9,3.00018862715609,114.084411621094,12,1369,1,3,0.00475909485938319,0.00188708596687067,0.00819932483136654,128.553115844727,1.99828350543976,2.00335431098938,1499.86584472656,1499.86584472656,,,2.41535329818726,0,1,,,,,,1,1,1,2.00040912628174,0,0,2.00003036806139,,,,,,,,,,,,,,,,,,,,,,,,,,,,,,,,,

,3825923786.69758,1.99964809417725,1499.86584472656,,,5,,,,26.0400008410215,,,,,1.48625108140194E-6,7.61712429537028E-9,13.9327889362779,0.00374950474778085,4.95430903354344E-7,2.53911254823643E-9,4.80854754526438E-7,1.80154320572341E-9,1.19291596719219E-7,1.78928326726751E-9,2.99991597483965,149.550155639648,12,1794,1,3,0.00461760670561995,0.00168003577086506,0.00705041736364365,129.069808959961,1.99699258804321,2.00343203544617,1499.86584472656,1499.86584472656,,,2.41452717781067,0,1,,,,,,1,1,1,2.00019264221191,0,0,1.99998684913393,,,,,,,,,,,,,,,,,,,,,,,,,,,,,,,,,

,3825923850.62774,1.99939686059952,1499.86584472656,,,5,,,,26.0400008410215,,,,,1.42638677576486E-6,6.23155069681507E-9,13.0024140175072,0.00341097515170075,4.75479238185856E-7,2.07725774550129E-9,4.63288229224746E-7,1.30190329706189E-9,1.0697907555967E-7,1.6186560926721E-9,2.99989286852376,196.096893310547,12,2353,1,3,0.00446032211343334,0.0015319638882448,0.00622228858992457,129.58544921875,1.99875962734222,2.0029194355011,1499.86584472656,1499.86584472656,,,2.41406202316284,0,1,,,,,,1,1,1,1.99975419044495,0,0,2.00000199439034,,,,,,,,,,,,,,,,,,,,,,,,,,,,,,,,,

,3825923914.82305,1.99921268224716,1499.86584472656,,,5,,,,26.0400008410215,,,,,1.39858418181744E-6,9.48618251496105E-9,12.8884182242269,0.00571108386861612,4.66174230303391E-7,3.16192181344626E-9,4.54429577567776E-7,1.61119879511095E-9,1.03981594671996E-7,2.72062272227891E-9,3.0001319054192,256.990142822266,12,3083,1,3,0.00436950747116239,0.00151513876682142,0.0057056462392211,129.208892822266,1.99811351299286,2.0038058757782,1499.86584472656,1499.86584472656,,,2.41347980499268,0,1,,,,,,1,1,1,1.99936842918396,0,0,1.99998704403166,,,,,,,,,,,,,,,,,,,,,,,,,,,,,,,,,

,3825923981.20947,1.99945676326752,1499.86584472656,,,5,,,,26.0400008410215,,,,,1.33254734575886E-6,8.57836326169087E-9,12.1046556339092,0.00525502672727244,4.44162369118056E-7,2.8593251576349E-9,4.34286952162149E-7,1.61298285206527E-9,9.31399662995208E-8,2.36093766881449E-9,3.00013562248601,337.910888671875,12,4054,1,3,0.00416536049666667,0.00144011815317428,0.00545203359797597,127.02392578125,1.99817609786987,2.001624584198,1499.86584472656,1499.86584472656,,,2.41320610046387,0,1,,,,,,1,1,1,1.99990212917328,0,0,1.99997755013979,,,,,,,,,,,,,,,,,,,,,,,,,,,,,,,,,

,3825924044.9759,1.99925112724304,1499.86584472656,,,5,,,,26.0400008410215,,,,,1.27808759542297E-6,6.36689621588635E-9,10.9413872927952,0.00411708297896577,4.26024239560634E-7,2.12227403540114E-9,4.18279913193073E-7,1.15899500301376E-9,8.08614055802387E-8,1.77785760518861E-9,3.00003491994044,442.885498046875,12,5314,1,3,0.00399462342624974,0.00138640226102804,0.005362284835428,122.393936157227,1.99731278419495,2.00348544120789,1499.86584472656,1499.86584472656,,,2.4128475189209,0,1,,,,,,1,1,1,1.99950420856476,0,0,2.00001848500872,,,,,,,,,,,,,,,,,,,,,,,,,,,,,,,,,

,3825924109.1182,1.99968671798706,1499.86584472656,,,5,,,,26.0400008410215,,,,,1.23704470767948E-6,1.06228967708337E-8,11.5356635107099,0.00513206611170305,4.12340805883568E-7,3.54090178641985E-9,4.04011694411828E-7,3.15875957834474E-9,8.24590260383548E-8,1.60006980700426E-9,3.00005405729547,581.287231445313,12,6975,1,3,0.0038071486886627,0.00150577083865118,0.00553681515157223,114.829727172852,1.9964714050293,2.00364112854004,1499.86584472656,1499.86584472656,,,2.4128053188324,0,1,,,,,,1,1,1,1.99996697902679,0,0,2.00004520113506,,,,,,,,,,,,,,,,,,,,,,,,,,,,,,,,,

,3825924175.17531,2.00278127193451,1499.86584472656,,,5,,,,26.0400008410215,,,,,1.18271103668098E-6,8.7948977752044E-9,13.0650356121968,0.0055618740346261,3.94218963018244E-7,2.93149837387351E-9,3.84014249751306E-7,2.36381071230985E-9,8.91159177202418E-8,1.73380553476802E-9,3.00013735418974,762.939453125,12,9155,10,3,0.00352860449066518,0.00169837607923291,0.00605436926707625,104.099380493164,1.99534249305725,2.00642108917236,1499.86584472656,1499.86584472656,,,2.41178393363953,0,1,,,,,,1,1,1,1.99942445755005,0,0,2.00005248437325,,,,,,,,,,,,,,,,,,,,,,,,,,,,,,,,,

,3825924272.6457,2.00218057632446,1499.86584472656,,,5,,,,26.0400008410215,,,,,0.00012834892876519,6.5534184255363E-7,240.884593466214,1.16789524829328,4.27833030665471E-5,2.18448949530817E-7,-2.08170852752469E-5,1.34375553300964E-7,-3.73772655758433E-5,1.72229945788115E-7,2.99997708371301,999.040954589844,12,11988,100,3,-0.0954772238863787,-0.414332879900087,0.00706044444814324,90.31640625,1.99477207660675,2.00636863708496,1499.86584472656,1499.86584472656,,,2.41094446182251,0,1,,,,,,1,1,1,1.99976539611816,0,0,2.00001288715162,,,,,,,,,,,,,,,,,,,,,,,,,,,,,,,,,

,3825924708.24802,3.00011229515076,1499.86584472656,,,5,,,,26.0400008410215,,,,,8.79002103388291E-6,9.88060638583295E-8,50.6930441915747,0.0469676049233157,2.93000829569723E-6,3.2935369057042E-8,1.85608645873642E-6,2.69671322293026E-8,2.267132918589E-6,1.89079960400586E-8,2.9999986849154,0.500452220439911,63.9421680892357,32,1,3,0.0182475522204107,0.0227408924347603,0.0264180768281221,178.976898193359,2.99899554252625,3.00243139266968,1499.86584472656,1499.86584472656,,,2.96571135520935,0,1,,,,,,1,1,1,3.00001764297485,0,0,2.99999364009802,,,,,,,,,,,,,,,,,,,,,,,,,,,,,,,,,

,3825924969.80968,2.99998915195465,1499.86584472656,,,5,,,,26.0400008410215,,,,,7.14194459825996E-6,1.23847324987674E-7,50.4118940276926,0.0683433807771783,2.38063716486718E-6,4.12822503141334E-8,1.51709442225742E-6,3.23569646527998E-8,1.83462743484946E-6,2.56369075642174E-8,3.00001390537747,0.700587213039398,45.6759692503843,32,1,3,0.0148772707377312,0.018436018589092,0.0263874363154173,178.614852905273,2.99906969070435,3.00251388549805,1499.86584472656,1499.86584472656,,,2.9652271270752,0,1,,,,,,1,1,1,3.00001859664917,0,0,3.00000458898998,,,,,,,,,,,,,,,,,,,,,,,,,,,,,,,,,

,3825925169.55629,2.99995195865631,1499.86584472656,,,5,,,,26.0400008410215,,,,,6.15210532891508E-6,7.36947806801329E-8,49.315214929409,0.0415816161952022,2.0506930204665E-6,2.45648220090226E-8,1.33684074649824E-6,1.86373550649725E-8,1.55505584552197E-6,1.60024834484246E-8,3.000012809092,0.900754988193512,35.52575386141,32,1,3,0.0130834575263379,0.0156606886205494,0.0263372287154198,178.282485961914,2.99918341636658,3.00300717353821,1499.86584472656,1499.86584472656,,,2.96498656272888,0,1,,,,,,1,1,1,2.99989438056946,0,0,3.00000618494045,,,,,,,,,,,,,,,,,,,,,,,,,,,,,,,,,

,3825925336.58386,3.00000667572022,1499.86584472656,,,5,,,,26.0400008410215,,,,,5.33685829160461E-6,8.70136425581744E-8,48.8251490804899,0.05926446801433,1.77895825965761E-6,2.90046371242918E-8,1.17119342280221E-6,2.38943673417866E-8,1.3390289227604E-6,1.64416600149622E-8,2.99999073200951,1.13111853599548,28.290580502102,31,1,3,0.0114322571857173,0.0135159496372765,0.0263518840074539,177.912857055664,2.99872803688049,3.00313782691956,1499.86584472656,1499.86584472656,,,2.96469664573669,0,1,,,,,,1,1,1,3.00007700920105,0,0,2.99999616377883,,,,,,,,,,,,,,,,,,,,,,,,,,,,,,,,,

,3825925469.53756,2.99987852573395,1499.86584472656,,,5,,,,26.0400008410215,,,,,4.55538553710899E-6,9.27627886004128E-8,45.6891423307571,0.0626722688470601,1.51845620656059E-6,3.09208147017907E-8,1.06071894689372E-6,2.83867839006056E-8,1.08654708454952E-6,1.2259171326105E-8,3.00001114120194,1.50037264823914,21.3280347636007,31,1,3,0.0103314423732684,0.0110263292408085,0.0262828376144171,177.311126708984,2.99888968467712,3.00212001800537,1499.86584472656,1499.86584472656,,,2.96470856666565,0,1,,,,,,1,1,1,2.99973893165588,0,0,3.00000431663112,,,,,,,,,,,,,,,,,,,,,,,,,,,,,,,,,

,3825925577.99209,3.00010085105896,1499.86584472656,,,5,,,,26.0400008410215,,,,,4.06191868631406E-6,6.49266742744199E-8,43.2170938932906,0.035643046182863,1.35397176703636E-6,2.16422067214996E-8,9.86726373633895E-7,1.72439675734383E-8,9.2715188049579E-7,1.30778703962966E-8,3.00000250020351,1.941321849823,16.4836139885396,31,1,3,0.00958354396471662,0.00947017642975956,0.0262598562985659,176.621627807617,2.99891972541809,3.0022554397583,1499.86584472656,1499.86584472656,,,2.9650559425354,0,1,,,,,,1,1,1,3.00011110305786,0,0,3.00000774985866,,,,,,,,,,,,,,,,,,,,,,,,,,,,,,,,,

,3825925672.78011,3.00003921985626,1499.86584472656,,,5,,,,26.0400008410215,,,,,3.56391714237642E-6,9.60254382441448E-8,40.2166822864907,0.0565701058607407,1.18796903528769E-6,3.20083892741425E-8,9.07142735446967E-7,3.03616919940762E-8,7.67047903541986E-7,1.01343299325554E-8,3.00000844846377,2.5516369342804,12.5409691206812,30,1,3,0.00878123100769059,0.00791393134442599,0.0261854063719511,175.651519775391,2.99876356124878,3.00195050239563,1499.86584472656,1499.86584472656,,,2.96457266807556,0,1,,,,,,1,1,1,3.00007104873657,0,0,2.99999806648347,,,,,,,,,,,,,,,,,,,,,,,,,,,,,,,,,

,3825925756.60562,3.0000239610672,1499.86584472656,,,5,,,,26.0400008410215,,,,,3.08970638222804E-6,1.25780318782528E-7,39.6019001642668,0.06472278611176,1.02990230326708E-6,4.19267800865848E-8,7.93531591265759E-7,2.88647917851134E-8,6.5651075234002E-7,3.04085297841065E-8,2.99999948774444,3.3389036655426,12,40,1,3,0.00763017391341278,0.00684111597203211,0.0261342860758305,174.373825073242,2.99913120269775,3.00295448303223,1499.86584472656,1499.86584472656,,,2.96482372283936,0,1,,,,,,1,1,1,2.99993681907654,0,0,3.00000196192638,,,,,,,,,,,,,,,,,,,,,,,,,,,,,,,,,

,3825925838.45498,3.00005948543549,1499.86584472656,,,5,,,,26.0400008410215,,,,,2.80511695788958E-6,9.67852142995229E-8,36.2049146017111,0.0524128959363418,9.35038132521361E-7,3.22617086534571E-8,7.54491291683356E-7,2.70660630668143E-8,5.52303539770492E-7,1.75569380959147E-8,3.00000273820437,4.39734554290771,12,52,1,3,0.00722038015367136,0.00586697846655087,0.026012571528554,172.659652709961,2.99900841712952,3.00200462341309,1499.86584472656,1499.86584472656,,,2.96508169174194,0,1,,,,,,1,1,1,3.00007486343384,0,0,2.99998978376389,,,,,,,,,,,,,,,,,,,,,,,,,,,,,,,,,

,3825925917.01208,3.00002884864807,1499.86584472656,,,5,,,,26.0400008410215,,,,,2.5029354948614E-6,4.83462984385696E-8,34.2725709415983,0.0264985376445145,8.34314915142848E-7,1.61154923736777E-8,6.89451127082204E-7,1.30901606831026E-8,4.6982818241874E-7,9.39982913337357E-9,2.99998891237951,5.80182075500488,12,69,1,3,0.00654579501807165,0.00510405046629007,0.0258290097117424,170.380859375,2.99861907958984,3.0024950504303,1499.86584472656,1499.86584472656,,,2.9655499458313,0,1,,,,,,1,1,1,3.00002884864807,0,0,3.00000110849158,,,,,,,,,,,,,,,,,,,,,,,,,,,,,,,,,

,3825925996.58533,3.00024175643921,1499.86584472656,,,5,,,,26.0400008410215,,,,,2.2727097139446E-6,5.3919936840584E-8,33.128282015638,0.027211394474586,7.57557637714187E-7,1.7973021247731E-8,6.34415924661357E-7,1.1106715712101E-8,4.14016918730593E-7,1.4130476243282E-8,3.0000485782206,7.55385589599609,12,90,1,3,0.00596169868276045,0.00460968314280492,0.0254744440317154,167.592315673828,2.99885368347168,3.00241684913635,1499.86584472656,1499.86584472656,,,2.9656879901886,0,1,,,,,,1,1,1,3.00021982192993,0,0,3.00000625390273,,,,,,,,,,,,,,,,,,,,,,,,,,,,,,,,,

,3825926076.01527,3.0001437664032,1499.86584472656,,,5,,,,26.0400008410215,,,,,2.10276967157422E-6,1.48609164591437E-8,30.9634759779634,0.00902965830529502,7.00931468976673E-7,4.9536970904897E-9,6.01045541889624E-7,4.10905021561918E-9,3.60623322563038E-7,2.76673475234726E-9,2.99996471073579,9.90830421447754,12,118,1,3,0.00559347295224695,0.00416028120855945,0.0249178931117058,164.014495849609,2.9988386631012,3.00338792800903,1499.86584472656,1499.86584472656,,,2.96569204330444,0,1,,,,,,1,1,1,3.00003623962402,0,0,2.99999626171895,,,,,,,,,,,,,,,,,,,,,,,,,,,,,,,,,

,3825926152.20156,2.99978840351105,1499.86584472656,,,5,,,,26.0400008410215,,,,,1.89435868653945E-6,1.735116498302E-8,30.0309863065244,0.0125863506368803,6.3146512286717E-7,5.78383365607836E-9,5.46694005745535E-7,5.22227533832094E-9,3.1602826689958E-7,2.48607563278951E-9,2.99994190959922,12.9862041473389,12,155,1,3,0.00502091683780094,0.00376917471280372,0.0240729060024023,159.738494873047,2.99911069869995,3.00330591201782,1499.86584472656,1499.86584472656,,,2.96572351455688,0,1,,,,,,1,1,1,2.99995732307434,0,0,2.9999914311651,,,,,,,,,,,,,,,,,,,,,,,,,,,,,,,,,

,3825926216.26718,2.99955224990845,1499.86584472656,,,5,,,,26.0400008410215,,,,,1.77013148435941E-6,1.12871845466223E-8,27.3064288259432,0.00720356225386925,5.90052062368889E-7,3.76244735428959E-9,5.24300061990535E-7,2.87779155223777E-9,2.70685945890254E-7,2.42370086348741E-9,2.9999581346311,17.0489253997803,12,204,1,3,0.00478450224682805,0.0033910156230345,0.022803008556366,154.689361572266,2.99897217750549,3.00342440605164,1499.86584472656,1499.86584472656,,,2.96612572669983,0,1,,,,,,1,1,1,2.9998996257782,0,0,3.00001486899361,,,,,,,,,,,,,,,,,,,,,,,,,,,,,,,,,

,3825926280.38748,2.99963772296906,1499.86584472656,,,5,,,,26.0400008410215,,,,,1.65442825935565E-6,1.42846011798057E-8,25.6259343064501,0.00925737220367875,5.51514460682299E-7,4.76186505591399E-9,4.97265763899326E-7,3.54804874917815E-9,2.38526645042659E-7,3.17595794748453E-9,2.99979126079286,22.3982219696045,12,268,1,3,0.00451138216621021,0.00310863868313751,0.0210633985698223,149.228317260742,2.99906706809998,3.00307297706604,1499.86584472656,1499.86584472656,,,2.96654033660889,0,1,,,,,,1,1,1,3.00001239776611,0,0,2.99997607110039,,,,,,,,,,,,,,,,,,,,,,,,,,,,,,,,,

,3825926344.45666,2.99960911273956,1499.86584472656,,,5,,,,26.0400008410215,,,,,1.52955996731835E-6,1.56793262262672E-8,23.6354560070766,0.00929992263295835,5.09894527554923E-7,5.22686446386188E-9,4.67121927469044E-7,2.593054059909E-9,2.04424886224898E-7,4.53830174910963E-9,2.99975756683052,29.3438262939453,12,352,1,3,0.00424310845879315,0.0027623653551009,0.0189543124288321,143.529663085938,2.99898147583008,3.00260543823242,1499.86584472656,1499.86584472656,,,2.96663045883179,0,1,,,,,,1,1,1,2.99995470046997,0,0,3.00001927406069,,,,,,,,,,,,,,,,,,,,,,,,,,,,,,,,,

,3825926408.72677,2.99977624416351,1499.86584472656,,,5,,,,26.0400008410215,,,,,1.42781652132567E-6,1.4848168255437E-8,22.0709696194165,0.00975406511641472,4.75980885015051E-7,4.94982664895449E-9,4.41100594340099E-7,3.88540651586614E-9,1.78852085737131E-7,3.06665943025388E-9,2.99973500255272,38.507984161377,12,462,1,3,0.0040299244032109,0.002465812737484,0.0165696088224649,138.153961181641,2.9988899230957,3.00223064422607,1499.86584472656,1499.86584472656,,,2.96688199043274,0,1,,,,,,1,1,1,3.0002064704895,0,0,2.9999849947672,,,,,,,,,,,,,,,,,,,,,,,,,,,,,,,,,

,3825926472.9402,2.99978756904602,1499.86584472656,,,5,,,,26.0400008410215,,,,,1.3413019563126E-6,9.88209924433077E-9,20.3085409702528,0.00630555445864196,4.47135213879837E-7,3.29428771679643E-9,4.19340040212299E-7,2.36191764961784E-9,1.55189658695788E-7,2.29644868818347E-9,2.99976811191851,50.5467147827148,12,606,1,3,0.00387353427341294,0.00216349693764694,0.0140912085771561,133.648452758789,2.99889230728149,3.00240325927734,1499.86584472656,1499.86584472656,,,2.96700978279114,0,1,,,,,,1,1,1,3.00001883506775,0,0,3.00001134191241,,,,,,,,,,,,,,,,,,,,,,,,,,,,,,,,,

,3825926537.18611,2.99984526634216,1499.86584472656,,,5,,,,26.0400008410215,,,,,1.28911423482122E-6,1.13005632833944E-8,18.5257514375815,0.00660515087223293,4.29683499316622E-7,3.76666818556327E-9,4.07417707586505E-7,3.24443066584182E-9,1.36523701714883E-7,1.91349389198912E-9,3.00014833446352,66.1627731323242,12,793,1,3,0.00381158575682341,0.00190946426485986,0.0117847956717014,130.515533447266,2.99905395507812,3.00347948074341,1499.86584472656,1499.86584472656,,,2.96686720848084,0,1,,,,,,1,1,1,3.00007843971252,0,0,3.00001845284114,,,,,,,,,,,,,,,,,,,,,,,,,,,,,,,,,

,3825926601.26398,2.999587059021,1499.86584472656,,,5,,,,26.0400008410215,,,,,1.22386060744036E-6,1.17716115894998E-8,17.0278997406657,0.00644223688791238,4.07935749063029E-7,3.92369944930649E-9,3.90052773646224E-7,3.49007771748242E-9,1.19458817734407E-7,1.79297933463294E-9,3.00013080552855,86.8827819824219,12,1042,1,3,0.00368951056335651,0.00166222802728352,0.00977937318384647,128.870376586914,2.99905562400818,3.00315284729004,1499.86584472656,1499.86584472656,,,2.96711683273315,0,1,,,,,,1,1,1,2.99994826316833,0,0,3.00000546470521,,,,,,,,,,,,,,,,,,,,,,,,,,,,,,,,,

,3825926661.24928,2.99983251094818,1499.86584472656,,,5,,,,26.0400008410215,,,,,1.18212134927164E-6,8.37101672188407E-9,15.9773990815656,0.00498803858187694,3.94016836195331E-7,2.79017169136418E-9,3.78796103396944E-7,2.18831515960951E-9,1.08456347240123E-7,1.73099244062857E-9,3.00017979101181,114.084411621094,12,1369,1,3,0.00361122197221163,0.00149463731828699,0.00819959118962288,128.550735473633,2.99900674819946,3.00258564949036,1499.86584472656,1499.86584472656,,,2.9677906036377,0,1,,,,,,1,1,1,3.00016140937805,0,0,3.00001954628249,,,,,,,,,,,,,,,,,,,,,,,,,,,,,,,,,

,3825926725.15714,2.99954521656036,1499.86584472656,,,5,,,,26.0400008410215,,,,,1.1467043758643E-6,7.42838310488565E-9,14.8026568995298,0.00476264322160103,3.82222915607386E-7,2.47605076631717E-9,3.69537526473908E-7,1.76424310054867E-9,9.76543585456222E-8,1.73731795580034E-9,3.00009321534812,149.550155639648,12,1794,1,3,0.00354260654210553,0.00135009851301845,0.00704037956893444,129.013946533203,2.99914026260376,3.003173828125,1499.86584472656,1499.86584472656,,,2.96720790863037,0,1,,,,,,1,1,1,2.99977993965149,0,0,2.99999623828464,,,,,,,,,,,,,,,,,,,,,,,,,,,,,,,,,

,3825926789.46044,2.99963474273682,1499.86584472656,,,5,,,,26.0400008410215,,,,,1.10127700635781E-6,1.16710986769007E-8,13.9115289156319,0.00694634058758078,3.67106595779876E-7,3.89051735353851E-9,3.56338670572032E-7,3.13753180840251E-9,8.82610022606021E-8,2.30043896451237E-9,2.99988346441523,196.096893310547,12,2353,1,3,0.00342452555503563,0.0012372094036096,0.00620190240442753,129.502487182617,2.99873495101929,3.00258088111877,1499.86584472656,1499.86584472656,,,2.96735072135925,0,1,,,,,,1,1,1,2.99976801872253,0,0,2.99997803899977,,,,,,,,,,,,,,,,,,,,,,,,,,,,,,,,,

,3825926849.6413,2.99982893466949,1499.86584472656,,,5,,,,26.0400008410215,,,,,1.05200018563953E-6,5.51974216289347E-9,12.9828482209637,0.00333083531524807,3.50659424399957E-7,1.83987573015469E-9,3.41695644245699E-7,1.51075625848496E-9,7.87789224604263E-8,1.05012295940084E-9,3.00006248923638,256.990142822266,12,3083,1,3,0.00328484321079357,0.00114499686892069,0.00570940738543868,129.086578369141,2.9989640712738,3.00266337394714,1499.86584472656,1499.86584472656,,,2.96786093711853,0,1,,,,,,1,1,1,3.00017023086548,0,0,3.00003061456195,,,,,,,,,,,,,,,,,,,,,,,,,,,,,,,,,

,3825926912.1779,2.99970519542694,1499.86584472656,,,5,,,,26.0400008410215,,,,,1.01090060670976E-6,4.57558287012781E-9,10.9636607657509,0.00338434888046776,3.36980425668547E-7,1.52525565127104E-9,3.30829860477897E-7,1.02816101028733E-9,6.4089084093398E-8,1.12662759537443E-9,2.99987930961924,337.910888671875,12,4054,1,3,0.00318109810609099,0.00102925202522327,0.00542873749509454,126.849822998047,2.99864554405212,3.00194072723389,1499.86584472656,1499.86584472656,,,2.96771144866943,0,1,,,,,,1,1,1,3.00008535385132,0,0,2.99999513549189,,,,,,,,,,,,,,,,,,,,,,,,,,,,,,,,,

,3825926976.51407,2.99963617324829,1499.86584472656,,,5,,,,26.0400008410215,,,,,9.78727978016139E-7,7.59654251129434E-9,10.2371246557245,0.00654046727202747,3.26231745708288E-7,2.53209612933525E-9,3.21038351553356E-7,1.30111769896033E-9,5.79786921185777E-8,2.17223468843647E-9,3.00010036083767,442.885498046875,12,5314,1,3,0.00307184417720274,0.00102384794699814,0.00536097073927522,122.184967041016,2.99889802932739,3.00288462638855,1499.86584472656,1499.86584472656,,,2.96718811988831,0,1,,,,,,1,1,1,2.99981832504272,0,0,3.00005045012822,,,,,,,,,,,,,,,,,,,,,,,,,,,,,,,,,

,3825927040.51356,2.99960720539093,1499.86584472656,,,5,,,,26.0400008410215,,,,,9.65470753953139E-7,8.37341784027713E-9,10.0349468946886,0.00697758618174223,3.21820295432332E-7,2.79111075307325E-9,3.16896977571436E-7,1.65418213810461E-9,5.60768058848074E-8,2.24810602283273E-9,3.00003066200697,581.287231445313,12,6975,1,3,0.00300116391739902,0.00109679368010141,0.00556065002456307,114.607238769531,2.99836301803589,3.00247859954834,1499.86584472656,1499.86584472656,,,2.96721720695496,0,1,,,,,,1,1,1,2.99995303153992,0,0,3.00001943300641,,,,,,,,,,,,,,,,,,,,,,,,,,,,,,,,,

,3825927104.47761,2.99959719181061,1499.86584472656,,,5,,,,26.0400008410215,,,,,9.65314990644998E-7,1.9073735414512E-8,5.57443434952867,0.0113362270194829,3.2175823143071E-7,6.35764639856056E-9,3.20236586193858E-7,5.44797530317124E-9,3.12552132663079E-8,3.27707687202578E-9,3.00012523798595,762.939453125,12,9155,1,3,0.0030362003828046,0.000998667602530893,0.00607501808553934,103.875549316406,2.99737524986267,3.00367951393127,1499.86584472656,1499.86584472656,,,2.96689701080322,0,1,,,,,,1,1,1,2.99990701675415,0,0,3.00001354444595,,,,,,,,,,,,,,,,,,,,,,,,,,,,,,,,,

,3825927209.1427,3.00042641162872,1499.86584472656,,,5,,,,26.0400008410215,,,,,8.40608997219604E-5,1.57119853195282E-6,89.6778844741491,2.4345928062478,2.80209402520211E-5,5.23744812790905E-7,1.57532237699032E-7,3.87651755447875E-7,2.80204974295857E-5,3.52185668963916E-7,2.99993144291071,999.040954589844,12,11988,100,3,-0.0758728374788068,0.267936649239355,0.0070977509021759,90.1040649414062,2.99616885185242,3.00488805770874,1499.86584472656,1499.86584472656,,,2.96708536148071,0,1,,,,,,1,1,1,3.00000405311584,0,0,2.99999673062182,,,,,,,,,,,,,,,,,,,,,,,,,,,,,,,,,

,3825927617.12477,4.00007033348084,1499.86584472656,,,5,,,,26.0400008410215,,,,,2.68793168375921E-5,8.01377682747136E-8,35.781513316707,0.00339914416545546,8.95972858234102E-6,2.67124591474659E-8,7.26860234976218E-6,1.86646132740415E-8,5.23871703284786E-6,1.9109884485143E-8,3.00001463108708,0.500452220439911,63.9421680892357,32,1,3,0.0718153267035209,0.0528395437098368,0.0264008659869432,178.946762084961,3.99897980690002,4.00248241424561,1499.86584472656,1499.86584472656,,,3.38968348503113,0,1,,,,,,1,1,1,4.00007963180542,0,0,4.0000000033022,,,,,,,,,,,,,,,,,,,,,,,,,,,,,,,,,

,3825927891.17792,3.99998497962952,1499.86584472656,,,5,,,,26.0400008410215,,,,,2.31645221681151E-5,1.14359531520732E-7,42.8683739238688,0.010532021317949,7.72150760547526E-6,3.81198449071126E-8,5.65923601057222E-6,3.19972591990286E-8,5.25306838695775E-6,2.07195072212757E-8,2.99999991603833,0.700587213039398,45.6759692503843,32,1,3,0.0556860422060223,0.0529440415607771,0.0263578593730927,178.591201782227,3.99895191192627,4.00226497650146,1499.86584472656,1499.86584472656,,,3.38915300369263,0,1,,,,,,1,1,1,3.99996471405029,0,0,4.00001487817465,,,,,,,,,,,,,,,,,,,,,,,,,,,,,,,,,

,3825928091.46045,4.00002551078796,1499.86584472656,,,5,,,,26.0400008410215,,,,,1.99102846649648E-5,7.58367241067149E-8,47.4221226633264,0.0125839680450125,6.63676461444628E-6,2.5278919688809E-8,4.49037986857258E-6,2.19365786443546E-8,4.88703726029221E-6,1.25622568837491E-8,2.9999986170409,0.900754988193512,35.52575386141,32,1,3,0.043993674652865,0.0492568252268621,0.0263575706630945,178.209503173828,3.99918150901794,4.00203990936279,1499.86584472656,1499.86584472656,,,3.38912987709045,0,1,,,,,,1,1,1,4.00005483627319,0,0,4.00000099271362,,,,,,,,,,,,,,,,,,,,,,,,,,,,,,,,,

,3825928258.57269,4.00006902217865,1499.86584472656,,,5,,,,26.0400008410215,,,,,1.733448330274E-5,7.16440301863048E-8,51.1034146938515,0.0153443131272538,5.77817900353267E-6,2.38814173875914E-8,3.62821494786243E-6,1.595556355306E-8,4.49704446152954E-6,1.77691330161214E-8,2.99999070505465,1.13111853599548,28.290580502102,31,1,3,0.0353582372977997,0.04534215905195,0.026337806135416,177.91259765625,3.99912476539612,4.00235271453857,1499.86584472656,1499.86584472656,,,3.38911724090576,0,1,,,,,,1,1,1,4.00015068054199,0,0,4.00000730984741,,,,,,,,,,,,,,,,,,,,,,,,,,,,,,,,,

,3825928394.38151,3.99989473819733,1499.86584472656,,,5,,,,26.0400008410215,,,,,1.42276413311722E-5,7.54428555340511E-8,54.6450175852799,0.0263972436381857,4.74254496895738E-6,2.51476071562814E-8,2.74422879865007E-6,1.50157780012033E-8,3.86793757488956E-6,2.0172470267799E-8,3.00000135461026,1.50037264823914,21.3280347636007,31,1,3,0.026513264555749,0.0390414515539737,0.0262619722634554,177.277435302734,3.9989070892334,4.00170660018921,1499.86584472656,1499.86584472656,,,3.3893084526062,0,1,,,,,,1,1,1,3.9999840259552,0,0,4.00000150861411,,,,,,,,,,,,,,,,,,,,,,,,,,,,,,,,,

,3825928502.74803,3.99999451637268,1499.86584472656,,,5,,,,26.0400008410215,,,,,1.18550087918215E-5,6.2116339953854E-8,56.9900996206016,0.0479090160586105,3.95165574231611E-6,2.07053740558713E-8,2.15279860184683E-6,1.66774238809831E-8,3.31376542405558E-6,1.22709432191484E-8,3.00001051834367,1.941321849823,16.4836139885396,31,1,3,0.0205857674631312,0.0335037237563769,0.02624805085361,176.636901855469,3.99891471862793,4.00165891647339,1499.86584472656,1499.86584472656,,,3.38957595825195,0,1,,,,,,1,1,1,4.00000143051147,0,0,3.99998588764921,,,,,,,,,,,,,,,,,,,,,,,,,,,,,,,,,

,3825928597.35207,4.00005435943604,1499.86584472656,,,5,,,,26.0400008410215,,,,,9.72283018176805E-6,1.13885905330817E-7,59.1199615793612,0.175340300848212,3.24093466371078E-6,3.79618661844827E-8,1.66338468035475E-6,3.62202081678076E-8,2.7815119808484E-6,1.13666091904865E-8,3.00000808119831,2.5516369342804,12.5409691206812,30,1,3,0.0156696856902253,0.0281869746881389,0.0261786319315434,175.649398803711,3.99921989440918,4.00223875045776,1499.86584472656,1499.86584472656,,,3.38949227333069,0,1,,,,,,1,1,1,4.00007915496826,0,0,4.00000509110893,,,,,,,,,,,,,,,,,,,,,,,,,,,,,,,,,

,3825928680.76138,4.00000894069672,1499.86584472656,,,5,,,,26.0400008410215,,,,,7.96906841596037E-6,7.07172894274653E-8,60.5045120267537,0.133324566278918,2.65635724270076E-6,2.35724396064399E-8,1.30787081885951E-6,1.74235481144538E-8,2.31207865826934E-6,1.58770236537763E-8,2.99999875312632,3.3389036655426,12,40,1,3,0.0120894892354371,0.0235050177788865,0.0260983016341925,174.405563354492,3.9988157749176,4.00216913223267,1499.86584472656,1499.86584472656,,,3.38987112045288,0,1,,,,,,1,1,1,4.00004386901855,0,0,4.00001963173471,,,,,,,,,,,,,,,,,,,,,,,,,,,,,,,,,

,3825928764.29371,3.99993431568146,1499.86584472656,,,5,,,,26.0400008410215,,,,,6.39663370291459E-6,9.64183550597091E-8,60.3500410027265,0.269821011585136,2.13220701275638E-6,3.21393880539185E-8,1.05480245514899E-6,2.64567762043362E-8,1.85302415684716E-6,1.82477192370453E-8,3.0000059396885,4.39734554290771,12,52,1,3,0.00955192239020068,0.0189432326039556,0.0259963870048523,172.640472412109,3.99910449981689,4.00219821929932,1499.86584472656,1499.86584472656,,,3.39039540290833,0,1,,,,,,1,1,1,3.99997282028198,0,0,4.00002563735585,,,,,,,,,,,,,,,,,,,,,,,,,,,,,,,,,

[...]

,3825987124.7711,11.9995017051697,1500.04235839844,,,5,,,,26.0400008410215,,,,,1.20433423798533E-5,4.5469730365866E-9,16.2881682376121,0.000297703554296976,4.01438272527861E-6,1.51563323823757E-9,3.85325836948872E-6,1.0142357445209E-9,1.12590790164224E-6,1.12626372017687E-9,3.0000483770559,444.903198242188,12,5338,1,3,0.036261311604527,0.0165095124912456,0.00541237602010369,121.847457885742,11.9989738464355,12.0019817352295,1500.04235839844,1500.04235839844,,,5.00951623916626,0,1,,,,,,1,1,1,11.9999923706055,0,0,12.0000126725536,,,,,,,,,,,,,,,,,,,,,,,,,,,,,,,,,

,3825987187.61605,11.9997878074646,1500.04235839844,,,5,,,,26.0400008410215,,,,,1.15913528309886E-5,7.71525768421677E-9,20.2002528815316,0.000591739065263365,3.86391332709774E-6,2.57183845774591E-9,3.62624980933777E-6,2.03529497541703E-9,1.33421831781808E-6,1.57223643762095E-9,2.9998998035743,583.022399902344,12,6996,1,3,0.0331460438141242,0.0193105822431495,0.00558249512687326,114.233978271484,11.9985179901123,12.0018262863159,1500.04235839844,1500.04235839844,,,5.00932788848877,0,1,,,,,,1,1,1,12.0006275177002,0,0,12.0000271028088,,,,,,,,,,,,,,,,,,,,,,,,,,,,,,,,,

,3825987249.66137,11.9993557929993,1500.04235839844,,,5,,,,26.0400008410215,,,,,1.06817119756881E-5,6.41782617662399E-9,25.03551861195,0.000716832094139783,3.56070308728364E-6,2.13935495852786E-9,3.22615945337198E-6,1.44002194586758E-9,1.50681838892744E-6,1.58214298784827E-9,2.99988842479897,762.939453125,12,9155,10,3,0.028013372176387,0.0215857157840257,0.00609203288331628,103.598266601562,11.9988660812378,12.0016899108887,1500.04235839844,1500.04235839844,,,5.0101375579834,0,1,,,,,,1,1,1,11.99964427948,0,0,11.9998945671579,,,,,,,,,,,,,,,,,,,,,,,,,,,,,,,,,

,3825987354.0574,11.9997901916504,1500.04235839844,,,5,,,,26.0400008410215,,,,,0.000154038568634444,5.12210823858395E-7,242.606085290031,1.53563460391364,5.13477788373649E-5,1.70742226020037E-7,-2.36253948799371E-5,1.19915063592592E-7,-4.55898575156578E-5,1.21545404149487E-7,2.99990714539639,999.040954589844,12,11988,100,3,-0.100231489173455,-0.500280057706555,0.00717023573815823,89.8892211914062,11.9991874694824,12.0017108917236,1500.04235839844,1500.04235839844,,,5.01059246063232,0,1,,,,,,1,1,1,12.0000638961792,0,0,12.0000157733615,,,,,,,,,,,,,,,,,,,,,,,,,,,,,,,,,

,3826066109.71529,1.8001606464386,1499.84069824219,,,5,,,,26.0400008410215,,,,,7.69737353702882E-6,2.56873460340373E-7,32.0548532393688,0.0344701705110552,2.56579987840191E-6,8.56247770925267E-8,2.17461900132945E-6,7.82825404108173E-8,1.36174932166833E-6,3.46907238173787E-8,2.9999898284441,0.400388091802597,79.9224568741094,32,1,3,0.0215203559831107,0.0137398158351997,0.0264210905879736,179.108825683594,1.79732167720795,1.8039767742157,1499.84069824219,1499.84069824219,,,2.30938720703125,0,1,,,,,,1,1,1,1.79991734027863,0,0,1.79999826411452,,,,,,,,,,,,,,,,,,,,,,,,,,,,,,,,,

,3826066435.12057,1.79988366365433,1499.84069824219,,,5,,,,26.0400008410215,,,,,6.90786470928642E-6,2.64083980427843E-7,35.5366491865602,0.0485144878615917,2.30262449290069E-6,8.80281052259743E-8,1.87374664840697E-6,7.66913052903096E-8,1.33833966275001E-6,4.32133197352824E-8,2.99999619155634,0.520422518253326,61.4884999738296,32,1,3,0.0185111956625085,0.0135044858384916,0.0264119226485491,178.914535522461,1.79596984386444,1.80250036716461,1499.84069824219,1499.84069824219,,,2.2957866191864,0,1,,,,,,1,1,1,1.79962193965912,0,0,1.80000882707673,,,,,,,,,,,,,,,,,,,,,,,,,,,,,,,,,

,3826066690.07907,1.79999321699142,1499.84069824219,,,5,,,,26.0400008410215,,,,,6.23298334166826E-6,2.43125743703751E-7,34.0804646856005,0.047731092944829,2.07765263006225E-6,8.10415836450384E-8,1.72081878156351E-6,7.77745866956467E-8,1.16422642652659E-6,2.27783217998406E-8,3.00001225011397,0.700587213039398,45.6759692503843,32,1,3,0.0169842450778957,0.0117894902968846,0.0263933446258306,178.627151489258,1.79538929462433,1.80242538452148,1499.84069824219,1499.84069824219,,,2.28780913352966,0,1,,,,,,1,1,1,1.7999666929245,0,0,1.80000758905546,,,,,,,,,,,,,,,,,,,,,,,,,,,,,,,,,

,3826066890.0271,1.7995348572731,1499.84069824219,,,5,,,,26.0400008410215,,,,,5.68894707894816E-6,1.77474672959487E-7,35.0244026828573,0.0410340904880666,1.89631537587802E-6,5.91582144273036E-8,1.55290722441743E-6,5.64287069809837E-8,1.08834330849395E-6,1.77621891297528E-8,3.0000005016645,0.900754988193512,35.52575386141,32,1,3,0.0152988020116201,0.0110471202797296,0.0263544283807278,178.262908935547,1.79641830921173,1.80410158634186,1499.84069824219,1499.84069824219,,,2.28179502487183,0,1,,,,,,1,1,1,1.79935419559479,0,0,1.79998592535655,,,,,,,,,,,,,,,,,,,,,,,,,,,,,,,,,

,3826067051.52253,1.80037724971771,1499.84069824219,,,5,,,,26.0400008410215,,,,,5.09975570265244E-6,1.06442131362292E-7,32.144984218615,0.0224854001055858,1.69991717362376E-6,3.54806813600437E-8,1.43932743083508E-6,3.28762244569447E-8,9.04463898686215E-7,1.33428863155444E-8,3.00000245999113,1.2005341053009,26.6548029403792,32,1,3,0.0141649366216658,0.00924688502915727,0.0263159368187189,177.766357421875,1.79590427875519,1.80413866043091,1499.84069824219,1499.84069824219,,,2.27840614318848,0,1,,,,,,1,1,1,1.79977166652679,0,0,1.80002978268792,,,,,,,,,,,,,,,,,,,,,,,,,,,,,,,,,

,3826067180.98429,1.80040323734283,1499.84069824219,,,5,,,,26.0400008410215,,,,,4.79350203114229E-6,8.45105695226238E-8,31.5212551550625,0.0179973825543563,1.59783850228549E-6,2.81702690342126E-8,1.36207147632295E-6,2.41086880092651E-8,8.35373672540228E-7,1.45717267313052E-8,2.99999156628523,1.54129183292389,20.7618046864589,32,1,3,0.0133769752488402,0.00859463117477531,0.0262888167053461,177.254196166992,1.79671573638916,1.80216217041016,1499.84069824219,1499.84069824219,,,2.27617073059082,0,1,,,,,,1,1,1,1.79993617534637,0,0,1.79999109570469,,,,,,,,,,,,,,,,,,,,,,,,,,,,,,,,,

,3826067297.79087,1.80018448829651,1499.84069824219,,,5,,,,26.0400008410215,,,,,4.3023225322121E-6,7.35280005160286E-8,31.1878618174764,0.0166294618947324,1.4341108649797E-6,2.45093908303644E-8,1.22684453750592E-6,1.78651716524438E-8,7.42648270613144E-7,1.67793289706195E-8,2.9999929832991,2.02103161811829,15.8334979587277,32,1,3,0.0120118405476707,0.00770498011649834,0.0262435767799616,176.481414794922,1.79754793643951,1.8032900094986,1499.84069824219,1499.84069824219,,,2.2738151550293,0,1,,,,,,1,1,1,1.80034625530243,0,0,1.79998951449114,,,,,,,,,,,,,,,,,,,,,,,,,,,,,,,,,

,3826067391.96048,1.8000293970108,1499.84069824219,,,5,,,,26.0400008410215,,,,,3.93835018242417E-6,8.45893148500986E-8,30.7568593882048,0.0213316995451771,1.31278531729914E-6,2.81964795896465E-8,1.12813575303361E-6,2.24220964240662E-8,6.71353120230706E-7,1.70965216696037E-8,2.99999560516622,2.63992881774902,12.12153895395,31,1,3,0.0110026770198968,0.00704171075872263,0.0261832233518362,175.500640869141,1.79761731624603,1.80362141132355,1499.84069824219,1499.84069824219,,,2.27298831939697,0,1,,,,,,1,1,1,1.80002951622009,0,0,1.80002136782902,,,,,,,,,,,,,,,,,,,,,,,,,,,,,,,,,

,3826067475.69266,1.80001974105835,1499.84069824219,,,5,,,,26.0400008410215,,,,,3.61852593509481E-6,9.68819020792105E-8,28.9624449002692,0.0245890115258157,1.20617389387683E-6,3.22939293991858E-8,1.05532652113539E-6,2.29779695006084E-8,5.84073108487502E-7,2.26916459003905E-8,3.00000352641054,3.49972248077393,12,41,1,3,0.0102513821467369,0.00624127632768522,0.0261123552918434,174.123596191406,1.79608762264252,1.80341005325317,1499.84069824219,1499.84069824219,,,2.2721095085144,0,1,,,,,,1,1,1,1.80024981498718,0,0,1.80001427342252,,,,,,,,,,,,,,,,,,,,,,,,,,,,,,,,,

,3826067559.89558,1.79992568492889,1499.84069824219,,,5,,,,26.0400008410215,,,,,3.36554656565068E-6,5.31284796982011E-8,28.274018105247,0.0150192931442829,1.12184714056597E-6,1.77094661652737E-8,9.88002079653232E-7,1.60473628018401E-8,5.31406527431616E-7,7.49048322640762E-9,3.00000458525283,4.5413064956665,12,54,1,3,0.00954296108432338,0.00579011966141092,0.0260052252560854,172.408767700195,1.79596292972565,1.8040931224823,1499.84069824219,1499.84069824219,,,2.27066159248352,0,1,,,,,,1,1,1,1.80025553703308,0,0,1.80002647853759,,,,,,,,,,,,,,,,,,,,,,,,,,,,,,,,,

,3826067639.13702,1.80000573396683,1499.84069824219,,,5,,,,26.0400008410215,,,,,3.18100092787011E-6,5.64757787953118E-8,27.4753429858224,0.0160544657391188,1.06033646212629E-6,1.88253096561477E-8,9.40740542888871E-7,1.21431827291159E-8,4.89204092255626E-7,1.43852492803271E-8,2.99999202280685,5.93727207183838,12,71,1,3,0.00902131657550415,0.00546803811651434,0.0257827062159777,170.155563354492,1.79683005809784,1.80363738536835,1499.84069824219,1499.84069824219,,,2.27038788795471,0,1,,,,,,1,1,1,1.80002653598785,0,0,1.80000596321546,,,,,,,,,,,,,,,,,,,,,,,,,,,,,,,,,

,3826067720.21123,1.80010086297989,1499.84069824219,,,5,,,,26.0400008410215,,,,,2.85312412765641E-6,3.98123505782675E-8,26.0446031554095,0.0124186322791858,9.51054603602502E-7,1.32709681049873E-8,8.54477399903168E-7,8.21400966136117E-9,4.17580210364706E-7,1.04234658212447E-8,2.99995827458177,7.80500745773315,12,93,1,3,0.0081300966202073,0.00483732959466352,0.0254309512674809,167.203262329102,1.79711079597473,1.80333197116852,1499.84069824219,1499.84069824219,,,2.26969385147095,0,1,,,,,,1,1,1,1.80015003681183,0,0,1.79999777636951,,,,,,,,,,,,,,,,,,,,,,,,,,,,,,,,,

,3826067796.73071,1.79921364784241,1499.84069824219,,,5,,,,26.0400008410215,,,,,2.68029153605457E-6,3.54063400202788E-8,25.1089557261881,0.0122825057763254,8.93451592169755E-7,1.18023918064478E-8,8.09022634835992E-7,1.04354926987955E-8,3.79128110107518E-7,5.51334240604475E-9,2.99992921781633,10.2065477371216,12,122,1,3,0.0076230968282671,0.00456480057188878,0.0248529575765133,163.586563110352,1.79786777496338,1.80337405204773,1499.84069824219,1499.84069824219,,,2.2680983543396,0,1,,,,,,1,1,1,1.7997213602066,0,0,1.80003609052345,,,,,,,,,,,,,,,,,,,,,,,,,,,,,,,,,

,3826067860.90975,1.79947036504745,1499.84069824219,,,5,,,,26.0400008410215,,,,,2.49274561183708E-6,1.96652718033922E-8,23.9717725189123,0.00726806127055171,8.30916287151906E-7,6.55509914654526E-9,7.59246209915449E-7,5.35646003219171E-9,3.37590090173474E-7,3.77857919654613E-9,2.99999608911428,13.3264532089233,12,159,1,3,0.00708484574244893,0.00424867512102161,0.0239735804498196,159.291168212891,1.79715967178345,1.80231738090515,1499.84069824219,1499.84069824219,,,2.26817393302917,0,1,,,,,,1,1,1,1.8000990152359,0,0,1.79998158651685,,,,,,,,,,,,,,,,,,,,,,,,,,,,,,,,,

,3826067925.26167,1.79938369989395,1499.84069824219,,,5,,,,26.0400008410215,,,,,2.35138220546501E-6,9.89968294057582E-9,22.5466981370672,0.00374810039677815,7.83755139358212E-7,3.29973041586351E-9,7.23850637369688E-7,2.12320600700185E-9,3.00520171119854E-7,2.52590915695835E-9,3.00014901004728,17.488582611084,12,209,1,3,0.00670027510852106,0.00397310540512172,0.0226532407104969,154.227233886719,1.79722464084625,1.80274569988251,1499.84069824219,1499.84069824219,,,2.26782917976379,0,1,,,,,,1,1,1,1.79992711544037,0,0,1.7999874391253,,,,,,,,,,,,,,,,,,,,,,,,,,,,,,,,,

,3826067989.27366,1.79900616407394,1499.84069824219,,,5,,,,26.0400008410215,,,,,2.22169340248907E-6,1.38481986856868E-8,21.1290696230699,0.00545087459770562,7.4051683778662E-7,4.61576934435537E-9,6.90732458422574E-7,2.54588501282223E-9,2.66934182762347E-7,3.85016832642132E-9,3.00019295864986,22.9024982452393,12,274,1,3,0.00636288889196742,0.00369304728602982,0.0208991691470146,148.727767944336,1.79798650741577,1.80336248874664,1499.84069824219,1499.84069824219,,,2.26760005950928,0,1,,,,,,1,1,1,1.79958832263947,0,0,1.80000251815433,,,,,,,,,,,,,,,,,,,,,,,,,,,,,,,,,

,3826068053.31009,1.79923903942108,1499.84069824219,,,5,,,,26.0400008410215,,,,,2.09306132134151E-6,1.76979897239008E-8,19.9374953141317,0.00724697245242995,6.97729298710395E-7,5.89968666122335E-9,6.55911015730718E-7,4.93118501132308E-9,2.37922074894275E-7,3.23878327226744E-9,2.99981859040475,29.9927062988281,12,359,1,3,0.00603680698554564,0.00339936077265146,0.0187647826969624,143.074859619141,1.79754042625427,1.80349445343018,1499.84069824219,1499.84069824219,,,2.26760077476501,0,1,,,,,,1,1,1,1.79999005794525,0,0,1.79994903859638,,,,,,,,,,,,,,,,,,,,,,,,,,,,,,,,,

,3826068117.56294,1.79917693138123,1499.84069824219,,,5,,,,26.0400008410215,,,,,1.98641005207187E-6,1.35667626753575E-8,18.7269622931725,0.00578430832847186,6.62102765403666E-7,4.52202256807975E-9,6.27050580577296E-7,2.70887571442671E-9,2.12573849174489E-7,3.62086736432194E-9,3.00015368590223,39.3141098022461,12,471,1,3,0.0057982134824471,0.00309511782241455,0.0163700301200151,137.786087036133,1.79799067974091,1.80273532867432,1499.84069824219,1499.84069824219,,,2.26696562767029,0,1,,,,,,1,1,1,1.80036318302155,0,0,1.80001691031078,,,,,,,,,,,,,,,,,,,,,,,,,,,,,,,,,

,3826068181.43588,1.79883825778961,1499.84069824219,,,5,,,,26.0400008410215,,,,,1.88188701489766E-6,7.97112683924709E-9,17.5502724761356,0.00323492854944165,6.27341628774181E-7,2.65723694085364E-9,5.98140593812216E-7,2.16445918381899E-9,1.8917015945178E-7,1.54143588949357E-9,2.99978022911512,51.3980293273926,12,616,1,3,0.00557644017314766,0.00276618076457847,0.0139364330098033,133.44792175293,1.79745364189148,1.80364620685577,1499.84069824219,1499.84069824219,,,2.26630592346191,0,1,,,,,,1,1,1,1.79997491836548,0,0,1.79998898127722,,,,,,,,,,,,,,,,,,,,,,,,,,,,,,,,,

,3826068245.39237,1.79955923557282,1499.84069824219,,,5,,,,26.0400008410215,,,,,1.82294362703841E-6,1.05284626172223E-8,16.5617717309809,0.00493570715798409,6.07621929923187E-7,3.50933768862286E-9,5.82413503750114E-7,1.65631353366901E-9,1.73201964114424E-7,3.09387725855013E-9,3.00012810148056,67.2563705444336,12,807,1,3,0.0054815620889649,0.00250888996449242,0.0116629041731358,130.404190063477,1.7978276014328,1.80305337905884,1499.84069824219,1499.84069824219,,,2.26611256599426,0,1,,,,,,1,1,1,1.80023992061615,0,0,1.8000215651497,,,,,,,,,,,,,,,,,,,,,,,,,,,,,,,,,

,3826068309.76573,1.79953193664551,1499.84069824219,,,5,,,,26.0400008410215,,,,,1.73954298879184E-6,6.30350595846736E-9,15.53811714089,0.00253414186375702,5.79888537325824E-7,2.10131676758329E-9,5.58695034569617E-7,1.67401652607779E-9,1.55340188197189E-7,1.27011843075563E-9,2.99978854007669,88.1374130249023,12,1057,1,3,0.00530536375154856,0.00222156985468742,0.00969625730067492,128.827011108398,1.7974865436554,1.80301833152771,1499.84069824219,1499.84069824219,,,2.26565909385681,0,1,,,,,,1,1,1,1.80003786087036,0,0,1.8000140265813,,,,,,,,,,,,,,,,,,,,,,,,,,,,,,,,,

,3826068373.99903,1.79918873310089,1499.84069824219,,,5,,,,26.0400008410215,,,,,1.6770197774478E-6,6.85763032885061E-9,14.7135070532781,0.00322100963731965,5.58970579430146E-7,2.28572951254577E-9,5.40640762725761E-7,1.4300165126403E-9,1.4197068129646E-7,1.78314670683564E-9,3.00019328236823,115.432922363281,12,1385,1,3,0.00516945090468233,0.00200461385969346,0.00813099555671215,128.555999755859,1.79766154289246,1.80375587940216,1499.84069824219,1499.84069824219,,,2.26547598838806,0,1,,,,,,1,1,1,1.79986774921417,0,0,1.80000288902767,,,,,,,,,,,,,,,,,,,,,,,,,,,,,,,,,

,3826068438.16682,1.79943829774857,1499.84069824219,,,5,,,,26.0400008410215,,,,,1.60293160177259E-6,6.78329399553831E-9,13.8643916890648,0.00243446988538354,5.34321152240964E-7,2.26114293315895E-9,5.18754021559925E-7,2.01006448244195E-9,1.28036552778949E-7,1.03557140777448E-9,2.99994038238957,151.405044555664,12,1816,1,3,0.00498267781604031,0.00180489764042075,0.00700083142146468,129.072525024414,1.79777336120605,1.80308711528778,1499.84069824219,1499.84069824219,,,2.26521348953247,0,1,,,,,,1,1,1,1.80010974407196,0,0,1.80001678542485,,,,,,,,,,,,,,,,,,,,,,,,,,,,,,,,,

,3826068498.30519,1.79925936460495,1499.84069824219,,,5,,,,26.0400008410215,,,,,1.54033677764803E-6,9.038972845211E-9,13.2345863265622,0.00392503397848641,5.1342819258142E-7,3.01288884226699E-9,4.99791992926771E-7,2.36065475565318E-9,1.17543492987536E-7,1.87211332468656E-9,3.00010166933666,198.085708618164,12,2377,1,3,0.00480981576149116,0.00167415279705742,0.00620848778635263,129.559677124023,1.79728829860687,1.80311501026154,1499.84069824219,1499.84069824219,,,2.26530885696411,0,1,,,,,,1,1,1,1.79987394809723,0,0,1.79998277405561,,,,,,,,,,,,,,,,,,,,,,,,,,,,,,,,,

,3826068565.09972,1.79921287298203,1499.84069824219,,,5,,,,26.0400008410215,,,,,1.50960754177642E-6,9.78839938468729E-9,13.5641501663621,0.00441041465537115,5.03179234112746E-7,3.26264884698496E-9,4.89144527804529E-7,2.53336372403185E-9,1.18012594926027E-7,2.0559537301437E-9,3.00013879634421,259.724060058594,12,3116,1,3,0.00469619926685676,0.00169256491072195,0.00568524049594998,129.102233886719,1.79715764522552,1.80301320552826,1499.84069824219,1499.84069824219,,,2.26427435874939,0,1,,,,,,1,1,1,1.79986786842346,0,0,1.80005558087276,,,,,,,,,,,,,,,,,,,,,,,,,,,,,,,,,

,3826068625.28907,1.79939019680023,1499.84069824219,,,5,,,,26.0400008410215,,,,,1.45700870157383E-6,8.84634504426908E-9,13.0320627771243,0.00499110644523938,4.85680730241726E-7,2.94884945877804E-9,4.73171551626276E-7,1.63135071558594E-9,1.09519196763486E-7,2.45650320034246E-9,2.99993104698362,339.673919677734,12,4076,1,3,0.00452780053112976,0.00164965093486298,0.00541511829942465,126.876083374023,1.79755890369415,1.80350482463837,1499.84069824219,1499.84069824219,,,2.26460242271423,0,1,,,,,,1,1,1,1.79989385604858,0,0,1.80002349312023,,,,,,,,,,,,,,,,,,,,,,,,,,,,,,,,,

,3826068691.8906,1.79919791221619,1499.84069824219,,,5,,,,26.0400008410215,,,,,1.36356127718595E-6,5.42155950011832E-9,11.9739989261409,0.00324899847828009,4.545003866767E-7,1.80710682418307E-9,4.44611299652262E-7,1.02188901064351E-9,9.4294187046694E-8,1.49042877184221E-9,3.00013227085743,444.903198242188,12,5338,1,3,0.00423373839744022,0.00155761587430484,0.00537946261465549,122.195541381836,1.79716014862061,1.80397796630859,1499.84069824219,1499.84069824219,,,2.26297616958618,0,1,,,,,,1,1,1,1.79983818531036,0,0,1.80002266810491,,,,,,,,,,,,,,,,,,,,,,,,,,,,,,,,,

,3826068756.02291,1.79950356483459,1499.84069824219,,,5,,,,26.0400008410215,,,,,1.33915555138373E-6,7.62426610968502E-9,12.2890529395455,0.00385440985056661,4.46379458809641E-7,2.54138944228345E-9,4.3615123535374E-7,2.07670241032009E-9,9.50090582344371E-8,1.46491207801715E-9,3.00003847613162,583.022399902344,12,6996,1,3,0.00409891041437106,0.00168589371792393,0.00557140121236444,114.608276367187,1.79655170440674,1.80401980876923,1499.84069824219,1499.84069824219,,,2.26266098022461,0,1,,,,,,1,1,1,1.80016016960144,0,0,1.80001045976366,,,,,,,,,,,,,,,,,,,,,,,,,,,,,,,,,

,3826068821.83859,1.80132085084915,1499.84069824219,,,5,,,,26.0400008410215,,,,,1.26630772894171E-6,7.45571765914112E-9,14.1309507222319,0.00497202121405537,4.22096431046246E-7,2.48520303784453E-9,4.09323909077364E-7,1.37391302066172E-9,1.03050155553516E-7,2.07089283908363E-9,3.00004367675634,762.939453125,12,9155,10,3,0.00374350774055057,0.00188844819087427,0.00606196653097868,103.971496582031,1.79581356048584,1.80574810504913,1499.84069824219,1499.84069824219,,,2.2619469165802,0,1,,,,,,1,1,1,1.80021977424622,0,0,1.80000198256109,,,,,,,,,,,,,,,,,,,,,,,,,,,,,,,,,

,3826068919.8187,1.8008279800415,1499.84069824219,,,5,,,,26.0400008410215,,,,,3.97947079790282E-5,1.11332348012992E-7,240.582819960545,0.717764936274043,1.32645468764469E-5,3.7109787307938E-8,-6.5150806821902E-6,2.70655194040488E-8,-1.15543034208908E-5,2.53888552997068E-8,3.0000804663512,999.040954589844,12,11986,100,3,-0.0302764282251939,-0.128307479217609,0.0070993504486978,90.1910095214844,1.79454791545868,1.80608713626862,1499.84069824219,1499.84069824219,,,2.26068425178528,0,1,,,,,,1,1,1,1.79982388019562,0,0,1.79999602834384,,,,,,,,,,,,,,,,,,,,,,,,,,,,,,,,,