File: data/AP424/chiTUP.dat
[Header]
; MPMS3 Data File (default extension .dat)
; Copyright (c) 2007, Quantum Design, Inc. All rights reserved.
TITLE,
FILEOPENTIME,3826051129.40718,03/27/2021,11:59 pm
BYAPP,SQUID AC,0.9.1.0
INFO,MPMS3 Measurement Release 1.1.16 Build 347, MultiVu Release 2.3.3.2,APPNAME
INFO,0,MOMENT_UNITS
INFO,SC_AP424,SAMPLE_MATERIAL
INFO,capsule nujol,SAMPLE_COMMENT
INFO,1,SAMPLE_MASS
INFO,,SAMPLE_VOLUME
INFO,,SAMPLE_MOLECULAR_WEIGHT
INFO,,SAMPLE_SIZE
INFO,,SAMPLE_SHAPE
INFO,Standard,SAMPLE_HOLDER
INFO,Standard,SAMPLE_HOLDER_DETAIL
INFO,68.35,SAMPLE_OFFSET
DATATYPE,COMMENT,1
DATATYPE,TIME,2
STARTUPAXIS,X,2
STARTUPAXIS,Y1,5
FIELDGROUP, VSM,2,3,4,5,6,8,9,10,11,14,15
FIELDGROUP, DC, 2,3,4,14,56,57,58,59,60,61,62,63,64,65,66,67,68,69
FIELDGROUP, AC, 2,3,4,11,16,17,18,19,20,21,22,23,24,25,26,27,28,29,30
STARTUPGROUP, All
[Data]
Comment,Time Stamp (sec),Temperature (K),Magnetic Field (Oe),Moment (emu),M. Std. Err. (emu),Transport Action,Averaging Time (sec),Frequency (Hz),Peak Amplitude (mm),Center Position (mm),Lockin Signal' (V),Lockin Signal (V),Range,M. Quad. Signal (emu),AC Moment (emu),AC M. Std Err. (emu),AC Phase (deg),AC Phase Std. Err. (deg),AC Susceptibility (emu/Oe),AC Suscept. Std Err. (emu/Oe),AC X' (emu/Oe),AC X' Std Err. (emu/Oe),AC X'' (emu/Oe),AC X'' Std Err. (emu/Oe),AC Drive (Oe),AC Frequency (Hz),AC Averaging Time (sec),AC Cycles,AC Range,AC Measure Type,AC Signal' (V),AC Signal'' (V),AC Trim Coil Ratio,AC Trim Coil Phase,Min. Temperature (K),Max. Temperature (K),Min. Field (Oe),Max. Field (Oe),Mass (grams),Motor Lag (deg),Pressure (Torr),Measure Count,Measurement Number,SQUID Status (code),Motor Status (code),Measure Status (code),Motor Current (amps),Motor Temp. (C),Temp. Status (code),Field Status (code),Chamber Status (code),Chamber Temp (K),Redirection State,Evercool Status,Average Temp (K),Rotation Angle (deg),Rotator state,DC Moment Fixed Ctr (emu),DC Moment Err Fixed Ctr (emu),DC Moment Free Ctr (emu),DC Moment Err Free Ctr (emu),DC Fixed Fit,DC Free Fit,DC Calculated Center (mm),DC Calculated Center Err (mm),DC Scan Length (mm),DC Scan Time (s),DC Number of Points,DC Squid Drift,DC Min V (V),DC Max V (V),DC Scans per Measure,Map 01,Map 02,Map 03,Map 04,Map 05,Map 06,Map 07,Map 08,Map 09,Map 10,Map 11,Map 12,Map 13,Map 14,Map 15,Map 16
,3826051385.1188,1.80217182636261,999.771911621094,,,6,,,,26.0463790893555,,,100,,,,,,,,,,,,,,,,,,,,,,1.79820287227631,1.80252957344055,999.771911621094,999.771911621094,,,2.31069111824036,-99999999,1,0,0,0,0.0197601318359375,33.2355842590332,1,1,1,1.80181407928467,0,1816139040,1.80022988536141,,,0.022586944348612,0.00111836900410103,0.0225877881616355,0.00111837111505853,0.983702301979065,0.986046850681305,26.0146007537842,0.1873919069767,30,4,200,0.000261996523477137,-0.927737653255463,0.140278145670891,1,,,,,,,,,,,,,,,,
,3826051491.77094,4.5034875869751,999.771911621094,,,6,,,,26.0463790893555,,,100,,,,,,,,,,,,,,,,,,,,,,4.34692478179932,4.65058517456055,999.771911621094,999.771911621094,,,3.66418719291687,-99999999,1,0,0,0,0.0201416015625,33.2355842590332,6,1,1,4.66568660736084,0,1816139008,4.49260360544378,,,0.0105312631033634,0.000521507507173761,0.0105313906357385,0.000521507879227242,0.977483749389648,0.977995455265045,26.0283699035645,0.187405988574028,30,4,200,-0.000633743416983634,-0.443514078855514,0.0648868158459663,1,,,,,,,,,,,,,,,,
,3826051590.83715,7.5323486328125,999.771911621094,,,6,,,,26.0463790893555,,,100,,,,,,,,,,,,,,,,,,,,,,7.3597264289856,7.6750602722168,999.771911621094,999.771911621094,,,4.41011333465576,-99999999,1,0,0,0,0.0191497802734375,33.2355842590332,6,1,1,7.69921207427978,0,1816138976,7.51779408888383,,,0.00634833897061705,0.000314334826655724,0.00634835648332866,0.000314334876991791,0.983026504516602,0.983180284500122,26.0377826690674,0.187385186553001,30,4,200,-0.00019931246060878,-0.261955678462982,0.0398971736431122,1,,,,,,,,,,,,,,,,
,3826051690.50284,10.6713004112244,999.771911621094,,,6,,,,26.0463790893555,,,100,,,,,,,,,,,,,,,,,,,,,,10.4953889846802,10.8304176330566,999.771911621094,999.771911621094,,,4.8782467842102,-99999999,1,0,0,0,0.02044677734375,33.7243423461914,6,1,1,10.8472118377686,0,1816138976,10.6655569076538,,,0.00450062786516376,0.000222840873992989,0.00450062872644512,0.000222840884443453,0.984558641910553,0.984567999839783,26.0484066009521,0.187390029430389,30,4,200,-0.000119674667075742,-0.182028561830521,0.0313872285187244,1,,,,,,,,,,,,,,,,
,3826051789.63347,13.8445959091187,999.771911621094,,,6,,,,26.0463790893555,,,100,,,,,,,,,,,,,,,,,,,,,,13.680326461792,14.0027675628662,999.771911621094,999.771911621094,,,5.19774913787842,-99999999,1,0,0,0,0.01800537109375,34.2131004333496,6,1,1,14.0192728042603,0,1816138848,13.8460858345032,,,0.0034817408148311,0.000172393016630276,0.00348176280645766,0.000172393042428795,0.984343588352203,0.984742403030396,26.0596179962158,0.187397658824921,30,4,200,-6.80763114360161E-5,-0.139997318387032,0.0248603839427233,1,,,,,,,,,,,,,,,,
,3826051888.66579,17.2265863418579,999.771911621094,,,6,,,,26.0463790893555,,,100,,,,,,,,,,,,,,,,,,,,,,17.0510959625244,17.3842620849609,999.771911621094,999.771911621094,,,5.42018413543701,-99999999,1,0,0,0,0.01556396484375,33.2355842590332,2,1,1,17.4020767211914,0,1816138976,17.2238021850586,,,0.00280634505534179,0.000138955062256167,0.00280641327624893,0.00013895526194023,0.982909619808197,0.984304487705231,26.0718650817871,0.187386721372604,30,4,200,-2.91062679025345E-5,-0.119543917477131,0.0132186589762568,1,,,,,,,,,,,,,,,,
,3826051998.56478,20.8324775695801,999.771911621094,,,6,,,,26.0463790893555,,,10,,,,,,,,,,,,,,,,,,,,,,20.6565971374512,20.99098777771,999.771911621094,999.771911621094,,,5.60136270523071,-99999999,1,0,0,0,0.0186920166015625,33.2355842590332,2,1,1,21.008358001709,0,1816138752,20.8210773468018,,,0.002328068323011,0.00011527871001518,0.00232820123663385,0.000115278997201221,0.980392813682556,0.983408451080322,26.0857467651367,0.187401235103607,30,4,200,-0.000331349845509976,-0.952762842178345,0.148720279335976,1,,,,,,,,,,,,,,,,
,3826052097.36174,24.0659093856812,999.771911621094,,,6,,,,26.0463790893555,,,10,,,,,,,,,,,,,,,,,,,,,,23.8911323547363,24.2224903106689,999.771911621094,999.771911621094,,,5.7340579032898,-99999999,1,0,0,0,0.0180816650390625,32.2580642700195,2,1,1,24.240686416626,0,1816139232,24.052828355269,,,0.00201942320035322,0.000100001520394683,0.00201963110031917,0.000100002056396299,0.977562606334686,0.982440233230591,26.0989990234375,0.187423959374428,30,4,200,-8.60613799886778E-5,-0.868106782436371,0.087433435022831,1,,,,,,,,,,,,,,,,
,3826052197.09249,27.3291320800781,999.771911621094,,,6,,,,26.0463790893555,,,10,,,,,,,,,,,,,,,,,,,,,,27.1544666290283,27.4832630157471,999.771911621094,999.771911621094,,,5.84229707717896,-99999999,1,0,0,0,0,33.2355842590332,2,1,1,27.5037975311279,0,1816138688,27.3160317160866,,,0.00178153162511367,8.82279528114752E-5,0.00178182415724459,8.82286568426739E-5,0.974369823932648,0.981435477733612,26.1129360198975,0.18744096159935,30,4,200,-0.000161258241860196,-0.690636873245239,0.152819842100143,1,,,,,,,,,,,,,,,,
,3826052296.154,30.5610961914063,999.771911621094,,,6,,,,26.0463790893555,,,10,,,,,,,,,,,,,,,,,,,,,,30.376558303833,30.7234477996826,999.771911621094,999.771911621094,,,5.93492937088013,-99999999,1,0,0,0,0.00030517578125,33.2355842590332,2,1,1,30.7456340789795,0,1816138976,30.5558931177313,,,0.00159586243073383,7.90406032163203E-5,0.00159624872519863,7.90414386931885E-5,0.970827162265778,0.980291604995727,26.1273670196533,0.187441423535347,30,4,200,-3.36232369591016E-5,-0.638041019439697,0.117812976241112,1,,,,,,,,,,,,,,,,
,3826052395.3547,33.811595916748,999.771911621094,,,6,,,,26.0463790893555,,,10,,,,,,,,,,,,,,,,,,,,,,33.6339263916016,33.9729614257812,999.771911621094,999.771911621094,,,6.01120328903198,-99999999,1,0,0,0,0.015716552734375,32.2580642700195,2,1,1,33.9892654418945,0,1816138848,33.8057119196111,,,0.00144486338162893,7.15703090659444E-5,0.00144536067105494,7.15715323148549E-5,0.967027246952057,0.979175865650177,26.1426162719727,0.187456160783768,30,4,200,-0.000106374820461497,-0.602953255176544,0.0818332657217979,1,,,,,,,,,,,,,,,,
,3826052494.48452,37.0597591400146,999.771911621094,,,6,,,,26.0463790893555,,,10,,,,,,,,,,,,,,,,,,,,,,36.8860054016113,37.2133445739746,999.771911621094,999.771911621094,,,6.07720470428467,-99999999,1,0,0,0,0.0145721435546875,33.7243423461914,2,1,1,37.233512878418,0,1816139008,37.0578842163086,,,0.00132015099086993,6.54019733376011E-5,0.00132076323424868,6.54033411940957E-5,0.963014185428619,0.978016376495361,26.158332824707,0.187499046325684,30,4,200,-3.03457782138139E-5,-0.572081387042999,0.0541314631700516,1,,,,,,,,,,,,,,,,
,3826052593.50987,40.3059997558594,999.771911621094,,,6,,,,26.0463790893555,,,10,,,,,,,,,,,,,,,,,,,,,,40.1257019042969,40.4686622619629,999.771911621094,999.771911621094,,,6.13994741439819,-99999999,1,0,0,0,0.0185394287109375,33.2355842590332,2,1,1,40.4862976074219,0,1816138976,40.2977464849299,,,0.00121549278928579,6.02267079516589E-5,0.00121622831551681,6.02283747182394E-5,0.958917081356049,0.976879596710205,26.1741676330566,0.187513887882233,30,4,200,-4.40328731201589E-5,-0.545897483825684,0.03114297054708,1,,,,,,,,,,,,,,,,
,3826052692.50445,43.5619220733643,999.771911621094,,,6,,,,26.0463790893555,,,10,,,,,,,,,,,,,,,,,,,,,,43.3892135620117,43.7242584228516,999.771911621094,999.771911621094,,,6.19578313827515,-99999999,1,0,0,0,0.0183868408203125,33.2355842590332,2,1,1,43.7346305847168,0,1816138944,43.5553190057928,,,0.00112583909837979,5.57944879297365E-5,0.00112670143198968,5.57963620562749E-5,0.954754531383514,0.97581422328949,26.1902599334717,0.187573313713074,30,4,200,-2.46611707552802E-5,-0.414030730724335,0.12077971547842,1,,,,,,,,,,,,,,,,
,3826052791.81194,46.8148021697998,999.771911621094,,,6,,,,26.0463790893555,,,10,,,,,,,,,,,,,,,,,,,,,,46.634635925293,46.9793357849121,999.771911621094,999.771911621094,,,6.2499418258667,-99999999,1,0,0,0,0.017547607421875,32.7468223571777,2,1,1,46.9999313354492,0,1816138944,46.8122919256037,,,0.00104861138668301,5.19787964028027E-5,0.0010496187411553,5.19807947299154E-5,0.950082302093506,0.97448194026947,26.2077770233154,0.187607049942017,30,4,200,3.43081010214519E-5,-0.390328615903854,0.108281642198563,1,,,,,,,,,,,,,,,,
,3826052890.77959,50.08571434021,999.771911621094,,,6,,,,26.0463790893555,,,10,,,,,,,,,,,,,,,,,,,,,,49.9149780273438,50.2432022094727,999.771911621094,999.771911621094,,,6.30315494537353,-99999999,1,0,0,0,0.017852783203125,33.2355842590332,2,1,1,50.2564506530762,0,1816138976,50.0772091258656,,,0.000981424463123301,4.86603020840586E-5,0.000982590139604124,4.86628955551111E-5,0.945411205291748,0.973229646682739,26.2253150939941,0.18764616549015,30,4,200,1.12381549115526E-5,-0.370342671871185,0.0969087481498718,1,,,,,,,,,,,,,,,,
,3826052989.41043,53.3202590942383,999.771911621094,,,6,,,,26.0463790893555,,,10,,,,,,,,,,,,,,,,,,,,,,53.1435585021973,53.479362487793,999.771911621094,999.771911621094,,,6.34894514083862,-99999999,1,0,0,0,0.0189208984375,32.7468223571777,2,1,1,53.4969596862793,0,1816138976,53.3140640258789,,,0.000922507771677247,4.57514279688774E-5,0.000923825942034445,4.5754175166626E-5,0.940710663795471,0.971974313259125,26.2428588867187,0.187698051333427,30,4,200,-3.0971881642472E-5,-0.353449940681458,0.0861804559826851,1,,,,,,,,,,,,,,,,
,3826053088.48438,56.5893001556396,999.771911621094,,,6,,,,26.0463790893555,,,10,,,,,,,,,,,,,,,,,,,,,,56.4118347167969,56.7474212646484,999.771911621094,999.771911621094,,,6.3933219909668,-99999999,1,0,0,0,0.019378662109375,33.2355842590332,2,1,1,56.7667655944824,0,1816139008,56.5823915654963,,,0.000869837177955842,4.31522272295029E-5,0.000871323950907566,4.31554262089251E-5,0.935856223106384,0.970755994319916,26.2610187530518,0.187738433480263,30,4,200,-2.98963168461341E-5,-0.341603845357895,0.0733351781964302,1,,,,,,,,,,,,,,,,
,3826053186.80542,59.8349266052246,999.771911621094,,,6,,,,26.0463790893555,,,10,,,,,,,,,,,,,,,,,,,,,,59.6631011962891,59.992244720459,999.771911621094,999.771911621094,,,6.42576885223389,-99999999,1,0,0,0,0.01922607421875,33.2355842590332,2,1,1,60.0067520141602,0,1816138912,59.8259249600497,,,0.000823026487226498,4.08435286932173E-5,0.000824683850430055,4.08469528824875E-5,0.930896997451782,0.969496548175812,26.2794952392578,0.187818199396133,30,4,200,-6.6579261329025E-5,-0.335822224617004,0.0572901852428913,1,,,,,,,,,,,,,,,,
,3826053286.12719,63.1026248931885,999.771911621094,,,6,,,,26.0463790893555,,,10,,,,,,,,,,,,,,,,,,,,,,62.9261474609375,63.2641181945801,999.771911621094,999.771911621094,,,6.45247077941895,-99999999,1,0,0,0,0.0193023681640625,33.7243423461914,2,1,1,63.2791023254394,0,1816138944,63.0929933027788,,,0.000780273274042024,3.87359975378105E-5,0.000782117628759076,3.87401702902641E-5,0.925821483135223,0.96820867061615,26.2983207702637,0.187892556190491,30,4,200,-5.740525375586E-5,-0.332752138376236,0.0402926914393902,1,,,,,,,,,,,,,,,,
,3826053385.00583,66.3770484924316,999.771911621094,,,6,,,,26.0463790893555,,,10,,,,,,,,,,,,,,,,,,,,,,66.1970138549805,66.5444869995117,999.771911621094,999.771911621094,,,6.47730112075806,-99999999,1,0,0,0,0.020599365234375,33.2355842590332,2,1,1,66.5570831298828,0,1816138912,66.3728145252575,,,0.000741993480162099,3.68501679732604E-5,0.000744014943211447,3.68544037069531E-5,0.920709788799286,0.966913282871246,26.3172340393066,0.18797804415226,30,4,200,2.39764403886511E-6,-0.329026788473129,0.0261569041758776,1,,,,,,,,,,,,,,,,
,3826053484.7795,69.6547317504883,999.771911621094,,,6,,,,26.0463790893555,,,10,,,,,,,,,,,,,,,,,,,,,,69.4819717407227,69.8120498657227,999.771911621094,999.771911621094,,,6.49941158294678,-99999999,1,0,0,0,0.019989013671875,33.2355842590332,2,1,1,69.8274917602539,0,1816138912,69.648024819114,,,0.000706679360176044,3.51114269102582E-5,0.00070889495324025,3.51162263359809E-5,0.915497303009033,0.965672612190247,26.3366012573242,0.188062384724617,30,4,200,-4.25219222961459E-5,-0.322466969490051,0.0162870213389397,1,,,,,,,,,,,,,,,,
,3826053584.47562,72.9445991516113,999.771911621094,,,6,,,,26.0463790893555,,,10,,,,,,,,,,,,,,,,,,,,,,72.7697067260742,73.1003646850586,999.771911621094,999.771911621094,,,6.51964235305786,-99999999,1,0,0,0,0.0191497802734375,32.7468223571777,2,1,1,73.1194915771484,0,1816138880,72.9311121160334,,,0.000674431339248769,3.35247266552573E-5,0.000676842745041379,3.3529981174275E-5,0.910215079784393,0.964384436607361,26.3561134338379,0.188146263360977,30,4,200,-4.16304028476588E-5,-0.318806618452072,0.00490861339494586,1,,,,,,,,,,,,,,,,
,3826053683.42546,76.2101020812988,999.771911621094,,,6,,,,26.0463790893555,,,10,,,,,,,,,,,,,,,,,,,,,,76.0530776977539,76.368408203125,999.771911621094,999.771911621094,,,6.54009962081909,-99999999,1,0,0,0,0.019073486328125,33.7243423461914,2,1,1,76.3866577148438,0,1816138976,76.2158111572266,,,0.000645059598948486,3.20808615275919E-5,0.000647672886140174,3.20865474315729E-5,0.904819905757904,0.963014364242554,26.3759460449219,0.188249811530113,30,4,200,-2.91197320620995E-5,-0.314075648784637,-0.00411003036424518,1,,,,,,,,,,,,,,,,
,3826053782.40148,79.4748573303223,999.771911621094,,,6,,,,26.0463790893555,,,10,,,,,,,,,,,,,,,,,,,,,,79.2967834472656,79.6309585571289,999.771911621094,999.771911621094,,,6.5589656829834,-99999999,1,0,0,0,0.0193023681640625,32.7468223571777,2,1,1,79.6529312133789,0,1816139008,79.4726371765137,,,0.000617992328702425,3.07513624320835E-5,0.000620818650255946,3.07576759118156E-5,0.899340510368347,0.961691081523895,26.3961277008057,0.188335165381432,30,4,200,-9.69887696555816E-6,-0.31013411283493,0.0925159528851509,1,,,,,,,,,,,,,,,,
,3826053882.10311,82.7714691162109,999.771911621094,,,6,,,,26.0463790893555,,,10,,,,,,,,,,,,,,,,,,,,,,82.5983734130859,82.9310684204102,999.771911621094,999.771911621094,,,6.57583856582642,-99999999,1,0,0,0,0.020751953125,33.2355842590332,2,1,1,82.9445648193359,0,1816139008,82.7613388061523,,,0.000592783444698942,2.95139743975155E-5,0.000595819965217467,2.95207233261018E-5,0.893826365470886,0.960325121879578,26.4163780212402,0.188444331288338,30,4,200,-8.17133786767954E-6,-0.201842620968819,0.0838913545012474,1,,,,,,,,,,,,,,,,
,3826053981.53299,86.0697708129883,999.771911621094,,,6,,,,26.0463790893555,,,10,,,,,,,,,,,,,,,,,,,,,,85.8949813842773,86.2197341918945,999.771911621094,999.771911621094,,,6.59254217147827,-99999999,1,0,0,0,0.0191497802734375,33.2355842590332,2,1,1,86.2445602416992,0,1816139040,86.0670692443848,,,0.00056942668113252,2.83684451346186E-5,0.000572676114859411,2.83755924819776E-5,0.888270378112793,0.958964347839356,26.4367656707764,0.188550680875778,30,4,200,-2.73183904937468E-5,-0.199721410870552,0.0752013847231865,1,,,,,,,,,,,,,,,,
,3826054080.71199,89.3670349121094,999.771911621094,,,6,,,,26.0463790893555,,,10,,,,,,,,,,,,,,,,,,,,,,89.1888198852539,89.5263900756836,999.771911621094,999.771911621094,,,6.6059718132019,-99999999,1,0,0,0,0.02105712890625,32.7468223571777,2,1,1,89.5452499389648,0,1816139040,89.3626369129528,,,0.000547792750483183,2.73086346641904E-5,0.000551262365274773,2.73161142687206E-5,0.882600843906403,0.957610726356506,26.4576511383057,0.188685297966003,30,4,200,1.9491364582791E-5,-0.197175100445747,0.0677023008465767,1,,,,,,,,,,,,,,,,
,3826054180.36998,92.6801834106445,999.771911621094,,,6,,,,26.0463790893555,,,10,,,,,,,,,,,,,,,,,,,,,,92.5046005249023,92.8358383178711,999.771911621094,999.771911621094,,,6.62125730514526,-99999999,1,0,0,0,0.0186920166015625,33.2355842590332,2,1,1,92.8557662963867,0,1816139040,92.6722148548473,,,0.000527515379504076,2.63161458348222E-5,0.000531216852462174,2.63244607916534E-5,0.876873970031738,0.956165254116058,26.4786071777344,0.188821628689766,30,4,200,-3.58937868440989E-5,-0.196427568793297,0.059113897383213,1,,,,,,,,,,,,,,,,
,3826054279.80529,95.9782371520996,999.771911621094,,,6,,,,26.0463790893555,,,10,,,,,,,,,,,,,,,,,,,,,,95.7991256713867,96.1436309814453,999.771911621094,999.771911621094,,,6.6335391998291,-99999999,1,0,0,0,0.015869140625,33.7243423461914,2,1,1,96.1573486328125,0,1816138976,95.9762032248757,,,0.000508577819978966,2.53897066601804E-5,0.000512497004587064,2.5398197935377E-5,0.871238112449646,0.954921662807465,26.4994792938232,0.188969880342484,30,4,200,-3.19445352943148E-5,-0.196584448218346,0.0501598678529263,1,,,,,,,,,,,,,,,,
,3826054379.69899,99.3039054870605,999.771911621094,,,6,,,,26.0463790893555,,,10,,,,,,,,,,,,,,,,,,,,,,99.1228103637695,99.4690246582031,999.771911621094,999.771911621094,,,6.64704751968384,-99999999,1,0,0,0,0.02105712890625,33.2355842590332,2,1,1,99.4850006103516,0,1816138944,99.296855579723,,,0.000490869948080105,2.45250762820597E-5,0.000495029541160656,2.45342122982902E-5,0.865336894989014,0.953452169895172,26.5210361480713,0.189103871583939,30,4,200,-3.46650267601945E-5,-0.19525808095932,0.0432787500321865,1,,,,,,,,,,,,,,,,
,3826054478.77475,102.589042663574,999.771911621094,,,6,,,,26.0463790893555,,,10,,,,,,,,,,,,,,,,,,,,,,102.407730102539,102.745712280273,999.771911621094,999.771911621094,,,6.65927362442017,-99999999,1,0,0,0,0.019073486328125,33.7243423461914,2,1,1,102.770355224609,0,1816139040,102.578373302113,,,0.000474315410808817,2.37169775069104E-5,0.000478700479308997,2.37264327509939E-5,0.859616994857788,0.952108860015869,26.542064666748,0.189254581928253,30,4,200,-1.53877517732326E-5,-0.193984106183052,0.0369244329631329,1,,,,,,,,,,,,,,,,
,3826054577.72851,105.870433807373,999.771911621094,,,6,,,,26.0463790893555,,,10,,,,,,,,,,,,,,,,,,,,,,105.692840576172,106.029914855957,999.771911621094,999.771911621094,,,6.6704249382019,-99999999,1,0,0,0,0.019378662109375,33.2355842590332,2,1,1,106.048027038574,0,1816138848,105.860798228871,,,0.000458686244547443,2.2954890619856E-5,0.000463310525047609,2.29651078650535E-5,0.853833019733429,0.950794398784637,26.563383102417,0.1894171833992,30,4,200,2.10761154448846E-5,-0.192858636379242,0.0307447612285614,1,,,,,,,,,,,,,,,,
,3826054676.48629,109.162845611572,999.771911621094,,,6,,,,26.0463790893555,,,10,,,,,,,,,,,,,,,,,,,,,,108.975372314453,109.327003479004,999.771911621094,999.771911621094,,,6.68136882781982,-99999999,1,0,0,0,0.0164794921875,33.7243423461914,2,1,1,109.350318908691,0,1816138944,109.162769664418,,,0.000444152608879572,2.22480301077822E-5,0.000449021686081401,2.22585846979946E-5,0.847798943519592,0.949235737323761,26.5853271484375,0.189575508236885,30,4,200,5.34993569090148E-6,-0.190592259168625,0.0263799112290144,1,,,,,,,,,,,,,,,,
,3826054775.89872,112.458751678467,999.771911621094,,,6,,,,26.0463790893555,,,10,,,,,,,,,,,,,,,,,,,,,,112.274612426758,112.627479553223,999.771911621094,999.771911621094,,,6.69111728668213,-99999999,1,0,0,0,0.0177764892578125,33.2355842590332,2,1,1,112.642890930176,0,1816138976,112.45137162642,,,0.000430154600225433,2.15671150600232E-5,0.000435266240691942,2.15781813973615E-5,0.84188723564148,0.947910726070404,26.607177734375,0.18977090716362,30,4,200,-2.13172224903246E-5,-0.190520763397217,0.0200529973953962,1,,,,,,,,,,,,,,,,
,3826054875.61753,115.766136169434,999.771911621094,,,6,,,,26.0463790893555,,,10,,,,,,,,,,,,,,,,,,,,,,115.583351135254,115.935836791992,999.771911621094,999.771911621094,,,6.70140314102173,-99999999,1,0,0,0,0.0145721435546875,32.7468223571777,2,1,1,115.948921203613,0,1816138976,115.759049155495,,,0.000416955431522432,2.09267774371529E-5,0.000422327957074614,2.09384873566734E-5,0.835692942142487,0.946362853050232,26.6298313140869,0.189963936805725,30,4,200,-4.24053396272939E-5,-0.192109018564224,0.0124248787760735,1,,,,,,,,,,,,,,,,
,3826054975.36672,119.084957122803,999.771911621094,,,6,,,,26.0463790893555,,,10,,,,,,,,,,,,,,,,,,,,,,118.906936645508,119.24821472168,999.771911621094,999.771911621094,,,6.71132183074951,-99999999,1,0,0,0,0.019989013671875,33.2355842590332,2,1,1,119.262977600098,0,1816138944,119.078459306197,,,0.000404473354823275,2.03215533572118E-5,0.000410091639259674,2.03334451639485E-5,0.829619646072388,0.944909155368805,26.6521263122559,0.190165549516678,30,4,200,-2.48123888013652E-5,-0.194158524274826,0.00460742227733135,1,,,,,,,,,,,,,,,,
,3826055074.27811,122.366138458252,999.771911621094,,,6,,,,26.0463790893555,,,10,,,,,,,,,,,,,,,,,,,,,,122.187683105469,122.527656555176,999.771911621094,999.771911621094,,,6.71996307373047,-99999999,1,0,0,0,0.019989013671875,33.2355842590332,2,1,1,122.544593811035,0,1816139104,122.357075084339,,,0.000392647250609248,1.97484820654334E-5,0.000398515356231526,1.97609487289724E-5,0.823639988899231,0.943563520908356,26.6741886138916,0.190375298261642,30,4,200,-1.24397693070932E-5,-0.193983286619186,-0.000644956366159022,1,,,,,,,,,,,,,,,,
,3826055173.78852,125.689434051514,999.771911621094,,,6,,,,26.0463790893555,,,10,,,,,,,,,,,,,,,,,,,,,,125.51244354248,125.850456237793,999.771911621094,999.771911621094,,,6.72870111465454,-99999999,1,0,0,0,0.0182342529296875,33.2355842590332,2,1,1,125.866424560547,0,1816138976,125.680714693936,,,0.000381440274072966,1.92071101157723E-5,0.00038758055945787,1.92204588742798E-5,0.817377150058746,0.941992402076721,26.6971054077148,0.190597772598267,30,4,200,-2.24299037654418E-5,-0.194988667964935,-0.00673178350552916,1,,,,,,,,,,,,,,,,
,3826055273.03699,128.99095916748,999.771911621094,,,6,,,,26.0463790893555,,,10,,,,,,,,,,,,,,,,,,,,,,128.811370849609,129.153839111328,999.771911621094,999.771911621094,,,6.73753929138184,-99999999,1,0,0,0,0.000152587890625,33.7243423461914,2,1,1,129.170547485352,0,1816139328,128.98616027832,,,0.000370759341820003,1.86914966700326E-5,0.000377162238721649,1.87054174722192E-5,0.811195254325867,0.94053316116333,26.7198829650879,0.190836772322655,30,4,200,-4.41654556198046E-5,-0.196787506341934,-0.0132886515930295,1,,,,,,,,,,,,,,,,
,3826055373.2863,132.306465148926,999.771911621094,,,6,,,,26.0463790893555,,,10,,,,,,,,,,,,,,,,,,,,,,132.120452880859,132.47868347168,999.771911621094,999.771911621094,,,6.74534702301025,-99999999,1,0,0,0,0.0188446044921875,33.7243423461914,2,1,1,132.492477416992,0,1816139040,132.301803588867,,,0.000360492447232964,1.81971080858872E-5,0.000367171766387901,1.82116588116486E-5,0.804792881011963,0.93896758556366,26.7433300018311,0.191073358058929,30,4,200,-3.09114184346981E-5,-0.198531478643417,-0.0197939369827509,1,,,,,,,,,,,,,,,,
,3826055484.18113,136.015075683594,999.771911621094,,,6,,,,26.0463790893555,,,1,,,,,,,,,,,,,,,,,,,,,,135.840270996094,136.175079345703,999.771911621094,999.771911621094,,,6.75416660308838,-99999999,1,0,0,0,0.0188446044921875,33.2355842590332,2,1,1,136.189880371094,0,1816138976,136.004978526722,,,0.000349811969812805,1.76834496518103E-5,0.000356793147143264,1.76986507542236E-5,0.797822952270508,0.937354922294617,26.7690467834473,0.191351518034935,30,4,200,-3.56569689756725E-5,-1.99761700630188,0.794456899166107,1,,,,,,,,,,,,,,,,
,3826055583.95501,139.331985473633,999.771911621094,,,6,,,,26.0463790893555,,,1,,,,,,,,,,,,,,,,,,,,,,139.160583496094,139.492980957031,999.771911621094,999.771911621094,,,6.76155090332031,-99999999,1,0,0,0,0.020294189453125,33.7243423461914,2,1,1,139.507553100586,0,1816137728,139.324949784712,,,0.000340566245661104,1.72396949048423E-5,0.000347818153801704,1.7255260394514E-5,0.79142701625824,0.935708343982697,26.792444229126,0.191622346639633,30,4,200,-0.0001013524888549,-0.943668484687805,0.752581357955933,1,,,,,,,,,,,,,,,,
,3826055682.53108,142.597602844238,999.771911621094,,,6,,,,26.0463790893555,,,1,,,,,,,,,,,,,,,,,,,,,,142.41325378418,142.765472412109,999.771911621094,999.771911621094,,,6.76874828338623,-99999999,1,0,0,0,0.0217437744140625,33.7243423461914,2,1,1,142.781951904297,0,1816139168,142.596084594727,,,0.000331835146715279,1.68214146094402E-5,0.000339361206588174,1.68373016089162E-5,0.785069763660431,0.934264242649078,26.8159770965576,0.19189889729023,30,4,200,5.27081356267445E-5,-0.944050490856171,0.713494777679443,1,,,,,,,,,,,,,,,,
,3826055781.61841,145.91690826416,999.771911621094,,,6,,,,26.0463790893555,,,1,,,,,,,,,,,,,,,,,,,,,,145.735214233398,146.081100463867,999.771911621094,999.771911621094,,,6.77620077133179,-99999999,1,0,0,0,0.0202178955078125,33.7243423461914,2,1,1,146.098602294922,0,1816138944,145.916218150746,,,0.000323408859779951,1.64185298673508E-5,0.000331223608766819,1.64352817759592E-5,0.778613686561585,0.932692587375641,26.839822769165,0.192206397652626,30,4,200,-0.000139964642585255,-0.946838259696961,0.672274708747864,1,,,,,,,,,,,,,,,,
,3826055880.46107,149.190498352051,999.771911621094,,,6,,,,26.0463790893555,,,1,,,,,,,,,,,,,,,,,,,,,,149.010330200195,149.350433349609,999.771911621094,999.771911621094,,,6.78320550918579,-99999999,1,0,0,0,0.02044677734375,33.7243423461914,2,1,1,149.370666503906,0,1816139072,149.193241882324,,,0.000315413675788739,1.60366020923748E-5,0.000323506577674191,1.60539864448622E-5,0.772290527820587,0.931216895580292,26.8630657196045,0.192470341920853,30,4,200,-1.45106344007218E-6,-0.940604507923126,0.642336666584015,1,,,,,,,,,,,,,,,,
,3826055979.88757,152.508598327637,999.771911621094,,,6,,,,26.0463790893555,,,1,,,,,,,,,,,,,,,,,,,,,,152.332580566406,152.66389465332,999.771911621094,999.771911621094,,,6.79010534286499,-99999999,1,0,0,0,0.01495361328125,33.2355842590332,2,1,1,152.684616088867,0,1816138880,152.496662486683,,,0.000307609373312072,1.56644801114489E-5,0.000315991053549358,1.56827057236436E-5,0.765827178955078,0.92968088388443,26.8869781494141,0.192787364125252,30,4,200,0.000183149459189735,-0.936480700969696,0.610769212245941,1,,,,,,,,,,,,,,,,
,3826056079.45856,155.818969726562,999.771911621094,,,6,,,,26.0463790893555,,,1,,,,,,,,,,,,,,,,,,,,,,155.636566162109,155.98616027832,999.771911621094,999.771911621094,,,6.79718637466431,-99999999,1,0,0,0,0.0183868408203125,33.2355842590332,2,1,1,156.001373291016,0,1816139008,155.826361083984,,,0.000300232153400955,1.53141785453865E-5,0.000308906049014087,1.53328574366997E-5,0.759239673614502,0.928058445453644,26.9113121032715,0.193120166659355,30,4,200,0.000129993990412913,-0.915696382522583,0.598978996276855,1,,,,,,,,,,,,,,,,
,3826056178.33572,159.111862182617,999.771911621094,,,6,,,,26.0463790893555,,,1,,,,,,,,,,,,,,,,,,,,,,158.930587768555,159.273956298828,999.771911621094,999.771911621094,,,6.80396795272827,-99999999,1,0,0,0,0.0201416015625,33.7243423461914,2,1,1,159.29313659668,0,1816138944,159.110150146484,,,0.000293190678322405,1.49797704426913E-5,0.000302150432730657,1.4999147168585E-5,0.752861618995667,0.926587879657745,26.9349613189697,0.193441703915596,30,4,200,0.000233403785387054,-0.892453193664551,0.590245246887207,1,,,,,,,,,,,,,,,,
,3826056277.55566,162.422798156738,999.771911621094,,,6,,,,26.0463790893555,,,1,,,,,,,,,,,,,,,,,,,,,,162.243392944336,162.595718383789,999.771911621094,999.771911621094,,,6.81163549423218,-99999999,1,0,0,0,0.0186920166015625,33.7243423461914,2,1,1,162.602203369141,0,1816138944,162.424541126598,,,0.000286382305467559,1.46577409985485E-5,0.000295640297118658,1.46776876101643E-5,0.746261298656464,0.925022304058075,26.9593276977539,0.193767383694649,30,4,200,0.000200637936359271,-0.864068031311035,0.587928831577301,1,,,,,,,,,,,,,,,,
,3826056376.66022,165.725326538086,999.771911621094,,,6,,,,26.0463790893555,,,1,,,,,,,,,,,,,,,,,,,,,,165.541091918945,165.895385742187,999.771911621094,999.771911621094,,,6.81937646865845,-99999999,1,0,0,0,0.0211334228515625,33.2355842590332,2,1,1,165.909561157227,0,1816138976,165.733065795898,,,0.000279861255955399,1.4349841139324E-5,0.000289418641908457,1.43705700474765E-5,0.739705502986908,0.923404276371002,26.9837036132813,0.194149270653725,30,4,200,8.80495208548382E-5,-0.842298209667206,0.581088244915009,1,,,,,,,,,,,,,,,,
,3826056475.69657,169.004913330078,999.771911621094,,,6,,,,26.0463790893555,,,1,,,,,,,,,,,,,,,,,,,,,,168.825119018555,169.164047241211,999.771911621094,999.771911621094,,,6.82525110244751,-99999999,1,0,0,0,0.01983642578125,33.2355842590332,2,1,1,169.184707641602,0,1816138976,169.005963134766,,,0.000273584478810238,1.40542694248992E-5,0.000283445779809437,1.4075722286785E-5,0.733101844787598,0.92183268070221,27.0081062316895,0.194488316774368,30,4,200,0.000140321237267926,-0.830153524875641,0.5656378865242,1,,,,,,,,,,,,,,,,
,3826056574.70057,172.300735473633,999.771911621094,,,6,,,,26.0463790893555,,,1,,,,,,,,,,,,,,,,,,,,,,172.122268676758,172.464172363281,999.771911621094,999.771911621094,,,6.83121919631958,-99999999,1,0,0,0,0.0177001953125,33.2355842590332,2,1,1,172.479202270508,0,1816139008,172.297556096857,,,0.000267511269030044,1.37687034985971E-5,0.000277673235482173,1.37907572059037E-5,0.726512372493744,0.920285224914551,27.0325584411621,0.194859623908997,30,4,200,5.81364729441702E-5,-0.821525990962982,0.546815872192383,1,,,,,,,,,,,,,,,,
,3826056673.11729,175.577919006348,999.771911621094,,,6,,,,26.0463790893555,,,1,,,,,,,,,,,,,,,,,,,,,,175.404418945313,175.728973388672,999.771911621094,999.771911621094,,,6.83696126937866,-99999999,1,0,0,0,0.0191497802734375,33.2355842590332,2,1,1,175.751419067383,0,1816139008,175.567495172674,,,0.000261728888298731,1.34973962790521E-5,0.00027219206647802,1.35202000649687E-5,0.720003187656403,0.918766915798187,27.0568084716797,0.19524148106575,30,4,200,-1.8584321878734E-5,-0.805667400360107,0.537799179553986,1,,,,,,,,,,,,,,,,
,3826056772.4993,178.90323638916,999.771911621094,,,6,,,,26.0463790893555,,,1,,,,,,,,,,,,,,,,,,,,,,178.727203369141,179.06330871582,999.771911621094,999.771911621094,,,6.84366941452026,-99999999,1,0,0,0,0.021514892578125,33.2355842590332,2,1,1,179.07926940918,0,1816138976,178.893735018643,,,0.0002560448411881,1.32319832716055E-5,0.00026681276311172,1.32550779416671E-5,0.713198959827423,0.91687285900116,27.0819396972656,0.195670664310455,30,4,200,0.000114269918412901,-0.802649796009064,0.515203773975372,1,,,,,,,,,,,,,,,,
,3826056871.55695,182.18367767334,999.771911621094,,,6,,,,26.0463790893555,,,1,,,,,,,,,,,,,,,,,,,,,,182.003173828125,182.338088989258,999.771911621094,999.771911621094,,,6.84913539886475,-99999999,1,0,0,0,0.01739501953125,33.2355842590332,2,1,1,182.364181518555,0,1816139008,182.17908782959,,,0.000250642900247614,1.29798731731135E-5,0.000261722975801636,1.30038737747029E-5,0.706611394882202,0.915365517139435,27.1065654754639,0.19608148932457,30,4,200,-6.51103764539585E-5,-0.803640604019165,0.491055071353912,1,,,,,,,,,,,,,,,,
,3826056970.80296,185.486679077148,999.771911621094,,,6,,,,26.0463790893555,,,1,,,,,,,,,,,,,,,,,,,,,,185.315185546875,185.641067504883,999.771911621094,999.771911621094,,,6.85482120513916,-99999999,1,0,0,0,0.019378662109375,33.7243423461914,2,1,1,185.658172607422,0,1816138944,185.477734652433,,,0.000245370054693084,1.27353445588113E-5,0.000256779523531033,1.27600683449198E-5,0.699721157550812,0.913715243339539,27.1322116851807,0.19650824368,30,4,200,-3.40371552738361E-5,-0.807473182678223,0.464279115200043,1,,,,,,,,,,,,,,,,
,3826057069.74086,188.770736694336,999.771911621094,,,6,,,,26.0463790893555,,,1,,,,,,,,,,,,,,,,,,,,,,188.591598510742,188.939743041992,999.771911621094,999.771911621094,,,6.86058568954468,-99999999,1,0,0,0,0.019989013671875,33.2355842590332,2,1,1,188.94987487793,0,1816138880,188.770148537376,,,0.000240283373117302,1.24992080242711E-5,0.000252007577706173,1.25245591045928E-5,0.693045854568481,0.912239849567413,27.1574687957764,0.19697430729866,30,4,200,-3.51960225088988E-5,-0.804275274276733,0.444826364517212,1,,,,,,,,,,,,,,,,
,3826057168.79706,192.086685180664,999.771911621094,,,6,,,,26.0463790893555,,,1,,,,,,,,,,,,,,,,,,,,,,191.900650024414,192.260345458984,999.771911621094,999.771911621094,,,6.86612701416016,-99999999,1,0,0,0,0.020904541015625,33.7243423461914,2,1,1,192.272720336914,0,1816138944,192.080354309082,,,0.000235369019634569,1.22730637129025E-5,0.000247436684360314,1.22993153258727E-5,0.686042666435242,0.910485863685608,27.183708190918,0.197464525699615,30,4,200,-0.000143516721436754,-0.803452670574188,0.425012737512588,1,,,,,,,,,,,,,,,,
,3826057267.68746,195.385063171387,999.771911621094,,,6,,,,26.0463790893555,,,1,,,,,,,,,,,,,,,,,,,,,,195.206726074219,195.542861938477,999.771911621094,999.771911621094,,,6.87086057662964,-99999999,1,0,0,0,0.0185394287109375,33.7243423461914,2,1,1,195.563400268555,0,1816138912,195.381917780096,,,0.000230656844843674,1.20560954444025E-5,0.000243054216209776,1.20831600305072E-5,0.679279148578644,0.908957362174988,27.2090835571289,0.197919324040413,30,4,200,4.30807085649576E-5,-0.803306877613068,0.404816448688507,1,,,,,,,,,,,,,,,,
,3826057366.94015,198.651245117187,999.771911621094,,,6,,,,26.0463790893555,,,1,,,,,,,,,,,,,,,,,,,,,,198.474517822266,198.809951782227,999.771911621094,999.771911621094,,,6.87656831741333,-99999999,1,0,0,0,0.019378662109375,33.7243423461914,2,1,1,198.827972412109,0,1816138944,198.64797668457,,,0.000226088727309103,1.18469297087444E-5,0.000238821102778504,1.18746740993957E-5,0.672371685504913,0.907175481319427,27.2348804473877,0.198412820696831,30,4,200,-9.91821871139109E-5,-0.804399251937866,0.383781284093857,1,,,,,,,,,,,,,,,,
,3826057465.89466,201.951469421387,999.771911621094,,,6,,,,26.0463790893555,,,1,,,,,,,,,,,,,,,,,,,,,,201.773590087891,202.108688354492,999.771911621094,999.771911621094,,,6.88199186325073,-99999999,1,0,0,0,0.0189208984375,33.2355842590332,2,1,1,202.129348754883,0,1816139232,201.946484652433,,,0.000221571711953441,1.16405108182523E-5,0.000234647826600433,1.16690544785021E-5,0.665370285511017,0.905465722084045,27.2612056732178,0.198931068181992,30,4,200,0.000119063348392956,-0.803908348083496,0.365522533655167,1,,,,,,,,,,,,,,,,
,3826057565.14181,205.256721496582,999.771911621094,,,6,,,,26.0463790893555,,,1,,,,,,,,,,,,,,,,,,,,,,205.065628051758,205.43310546875,999.771911621094,999.771911621094,,,6.88776779174805,-99999999,1,0,0,0,0.002288818359375,33.7243423461914,2,1,1,205.447814941406,0,1816139008,205.255043723366,,,0.000217236395548939,1.14422951979886E-5,0.000230637738734305,1.14713819750745E-5,0.658596038818359,0.903882384300232,27.2869205474854,0.199468314647675,30,4,200,-5.87350659770891E-5,-0.807184994220734,0.342968553304672,1,,,,,,,,,,,,,,,,
,3826057664.10626,208.543060302734,999.771911621094,,,6,,,,26.0463790893555,,,1,,,,,,,,,,,,,,,,,,,,,,208.366516113281,208.706420898438,999.771911621094,999.771911621094,,,6.89391660690308,-99999999,1,0,0,0,0.0209808349609375,33.7243423461914,2,1,1,208.719604492187,0,1816139008,208.538489601829,,,0.000213055136306831,1.12528970772705E-5,0.000226806738389201,1.12828157647267E-5,0.651587009429932,0.902093887329102,27.3132648468018,0.200008645653725,30,4,200,-8.90354131115601E-5,-0.813162684440613,0.319389194250107,1,,,,,,,,,,,,,,,,
,3826057762.8316,211.830192565918,999.771911621094,,,6,,,,26.0463790893555,,,1,,,,,,,,,,,,,,,,,,,,,,211.650604248047,211.988555908203,999.771911621094,999.771911621094,,,6.90094947814941,-99999999,1,0,0,0,0.018463134765625,33.7243423461914,2,1,1,212.009780883789,0,1816138976,211.821512395685,,,0.000208981648551829,1.1068352372605E-5,0.000223077648101711,1.10991260291851E-5,0.644691169261932,0.900445580482483,27.3392772674561,0.200548648834229,30,4,200,-0.000103016747743823,-0.818054378032684,0.297310054302216,1,,,,,,,,,,,,,,,,
,3826057862.02072,215.123901367187,999.771911621094,,,6,,,,26.0463790893555,,,1,,,,,,,,,,,,,,,,,,,,,,214.941192626953,215.284790039062,999.771911621094,999.771911621094,,,6.90691423416138,-99999999,1,0,0,0,0.0182342529296875,33.2355842590332,2,1,1,215.306610107422,0,1816139008,215.123248291016,,,0.0002050476834869,1.08904843884401E-5,0.000219481088664992,1.092203925014E-5,0.637882173061371,0.898769319057465,27.3654003143311,0.201168358325958,30,4,200,-2.45983210334089E-5,-0.83337539434433,0.264890819787979,1,,,,,,,,,,,,,,,,
,3826057961.20564,218.420783996582,999.771911621094,,,6,,,,26.0463790893555,,,1,,,,,,,,,,,,,,,,,,,,,,218.240310668945,218.588043212891,999.771911621094,999.771911621094,,,6.91391324996948,-99999999,1,0,0,0,0.017242431640625,33.7243423461914,2,1,1,218.601257324219,0,1816139008,218.412422873757,,,0.00020120276309331,1.07181686634796E-5,0.000215993627655823,1.0750427783284E-5,0.630821585655212,0.897025585174561,27.3920440673828,0.201741054654121,30,4,200,-0.000124627229524776,-0.839532792568207,0.243396759033203,1,,,,,,,,,,,,,,,,
,3826058060.15839,221.720611572266,999.771911621094,,,6,,,,26.0463790893555,,,1,,,,,,,,,,,,,,,,,,,,,,221.538223266602,221.894790649414,999.771911621094,999.771911621094,,,6.92138385772705,-99999999,1,0,0,0,0.0196075439453125,33.2355842590332,2,1,1,221.90299987793,0,1816138976,221.726312810724,,,0.000197464457392441,1.05513476454677E-5,0.000212618745226215,1.05845621871638E-5,0.623733639717102,0.895126402378082,27.4189319610596,0.202376767992973,30,4,200,-5.29711587660131E-6,-0.843710243701935,0.222258642315865,1,,,,,,,,,,,,,,,,
,3826058159.09985,225.020133972168,999.771911621094,,,6,,,,26.0463790893555,,,1,,,,,,,,,,,,,,,,,,,,,,224.847045898438,225.169891357422,999.771911621094,999.771911621094,,,6.9300651550293,-99999999,1,0,0,0,0.0203704833984375,33.2355842590332,2,1,1,225.193222045898,0,1816138976,225.010346846147,,,0.000193845272491448,1.0390157720716E-5,0.000209358527947625,1.04241242857442E-5,0.616740167140961,0.893457531929016,27.4456405639648,0.203000828623772,30,4,200,0.000126965634990484,-0.845542669296265,0.205503776669502,1,,,,,,,,,,,,,,,,
,3826058257.84768,228.293441772461,999.771911621094,,,6,,,,26.0463790893555,,,1,,,,,,,,,,,,,,,,,,,,,,228.118026733398,228.454467773438,999.771911621094,999.771911621094,,,6.93981981277466,-99999999,1,0,0,0,0.0203704833984375,33.2355842590332,2,1,1,228.468856811523,0,1816138944,228.288477117365,,,0.000190336740483098,1.02354805766541E-5,0.00020622518098509,1.02701493098504E-5,0.609560668468475,0.891636669635773,27.4731216430664,0.203668415546417,30,4,200,1.04060709418263E-5,-0.834911823272705,0.20186248421669,1,,,,,,,,,,,,,,,,
,3826058357.02406,231.602905273438,999.771911621094,,,6,,,,26.0463790893555,,,1,,,,,,,,,,,,,,,,,,,,,,231.433090209961,231.753936767578,999.771911621094,999.771911621094,,,6.95012712478638,-99999999,1,0,0,0,0.018768310546875,33.2355842590332,2,1,1,231.772720336914,0,1816139008,231.594435258345,,,0.000186878538497382,1.0081652397515E-5,0.000203117799687869,1.01171426435451E-5,0.602711081504822,0.890074491500855,27.4994087219238,0.204308032989502,30,4,200,-7.59320391807705E-5,-0.827375888824463,0.19514425098896,1,,,,,,,,,,,,,,,,
,3826058455.92091,234.883293151855,999.771911621094,,,6,,,,26.0463790893555,,,1,,,,,,,,,,,,,,,,,,,,,,234.704010009766,235.042907714844,999.771911621094,999.771911621094,,,6.96039009094238,-99999999,1,0,0,0,0.0180816650390625,32.7468223571777,2,1,1,235.062576293945,0,1816138944,234.877942171964,,,0.000183496469298799,9.93322557429556E-6,0.000200112336046619,9.96959413728274E-6,0.595526337623596,0.888149857521057,27.5269775390625,0.205024018883705,30,4,200,-5.6439995432811E-7,-0.832251310348511,0.176284372806549,1,,,,,,,,,,,,,,,,
,3826058555.09129,238.19889831543,999.771911621094,,,6,,,,26.0463790893555,,,1,,,,,,,,,,,,,,,,,,,,,,238.021789550781,238.36213684082,999.771911621094,999.771911621094,,,6.97365427017212,-99999999,1,0,0,0,0.0177001953125,33.2355842590332,2,1,1,238.376007080078,0,1816139040,238.196842540394,,,0.000180225367615586,9.78960879623191E-6,0.000197209366427381,9.82690840515407E-6,0.58853155374527,0.886420428752899,27.5540809631348,0.205755889415741,30,4,200,4.28493649451411E-6,-0.833742558956146,0.161423906683922,1,,,,,,,,,,,,,,,,
,3826058654.22055,241.489486694336,999.771911621094,,,6,,,,26.0463790893555,,,1,,,,,,,,,,,,,,,,,,,,,,241.303512573242,241.657012939453,999.771911621094,999.771911621094,,,6.98793983459473,-99999999,1,0,0,0,0.0177764892578125,33.2355842590332,2,1,1,241.67546081543,0,1816138976,241.489901455966,,,0.000177066316095767,9.65166192709798E-6,0.000194414510175227,9.68942006045927E-6,0.581564724445343,0.884837210178375,27.5811195373535,0.206467732787132,30,4,200,0.000132040193420835,-0.837016999721527,0.145023509860039,1,,,,,,,,,,,,,,,,
,3826058753.32671,244.763412475586,999.771911621094,,,6,,,,26.0463790893555,,,1,,,,,,,,,,,,,,,,,,,,,,244.586242675781,244.923767089844,999.771911621094,999.771911621094,,,7.00643682479858,-99999999,1,0,0,0,0.0189971923828125,33.2355842590332,2,1,1,244.940582275391,0,1816139040,244.75515053489,,,0.00017393799742769,9.51602251650677E-6,0.000191671968276237,9.55470160986865E-6,0.574413061141968,0.883088111877441,27.6090393066406,0.207249119877815,30,4,200,0.000115158894914202,-0.837854087352753,0.131922274827957,1,,,,,,,,,,,,,,,,
,3826058852.20392,248.049728393555,999.771911621094,,,6,,,,26.0463790893555,,,1,,,,,,,,,,,,,,,,,,,,,,247.865158081055,248.219131469727,999.771911621094,999.771911621094,,,7.03090047836304,-99999999,1,0,0,0,0.01922607421875,33.2355842590332,2,1,1,248.234298706055,0,1816138912,248.041458129883,,,0.000170896132121726,9.38428538640955E-6,0.000189006328055426,9.42353356728299E-6,0.567373275756836,0.881564199924469,27.6365871429443,0.207998499274254,30,4,200,0.000195708053070121,-0.833686470985413,0.12252501398325,1,,,,,,,,,,,,,,,,
,3826058951.08981,251.34553527832,999.771911621094,,,6,,,,26.0463790893555,,,1,,,,,,,,,,,,,,,,,,,,,,251.159393310547,251.51155090332,999.771911621094,999.771911621094,,,7.06078720092773,-99999999,1,0,0,0,0.0138092041015625,32.7468223571777,2,1,1,251.531677246094,0,1816138912,251.334671020508,,,0.000167865201681509,9.25299828316123E-6,0.000186363751903821,9.29374721354607E-6,0.560307741165161,0.879814565181732,27.6641616821289,0.208803430199623,30,4,200,-7.52441119402647E-5,-0.827501595020294,0.11749405413866,1,,,,,,,,,,,,,,,,
,3826059050.46675,254.643577575684,999.771911621094,,,6,,,,26.0463790893555,,,1,,,,,,,,,,,,,,,,,,,,,,254.467910766602,254.799606323242,999.771911621094,999.771911621094,,,7.09939527511597,-99999999,1,0,0,0,0.01861572265625,33.2355842590332,2,1,1,254.819244384766,0,1816138880,254.635482788086,,,0.000164997617574471,9.13039581514863E-6,0.000183884270924617,9.17198643502319E-6,0.55325186252594,0.878136515617371,27.6919574737549,0.209619373083115,30,4,200,3.60021331289317E-5,-0.831472396850586,0.101025469601154,1,,,,,,,,,,,,,,,,
,3826059149.61113,257.936645507813,999.771911621094,,,6,,,,26.0463790893555,,,1,,,,,,,,,,,,,,,,,,,,,,257.757598876953,258.102416992187,999.771911621094,999.771911621094,,,7.14392375946045,-99999999,1,0,0,0,0.01739501953125,33.2355842590332,2,1,1,258.115692138672,0,1816138944,257.931232799183,,,0.000162178382150104,9.00768685037731E-6,0.000181399722913466,9.04952509110585E-6,0.546689808368683,0.876836359500885,27.7181377410889,0.210409834980965,30,4,200,-1.67849630088313E-5,-0.832884728908539,0.0881222411990166,1,,,,,,,,,,,,,,,,
,3826059248.91958,261.256103515625,999.771911621094,,,6,,,,26.0463790893555,,,1,,,,,,,,,,,,,,,,,,,,,,261.073760986328,261.421661376953,999.771911621094,999.771911621094,,,7.19413185119629,-99999999,1,0,0,0,0.018157958984375,33.2355842590332,2,1,1,261.438446044922,0,1816138976,261.245838512074,,,0.000159470156426718,8.88904895724231E-6,0.000179013955605956,8.93165385323938E-6,0.540477275848389,0.875814080238342,27.7432918548584,0.211175605654716,30,4,200,-7.78497633291408E-5,-0.838547050952911,0.071097731590271,1,,,,,,,,,,,,,,,,
,3826059348.45095,264.569641113281,999.771911621094,,,6,,,,26.0463790893555,,,1,,,,,,,,,,,,,,,,,,,,,,264.391418457031,264.742431640625,999.771911621094,999.771911621094,,,7.24034690856934,-99999999,1,0,0,0,0.0183868408203125,34.2131004333496,2,1,1,264.747863769531,0,1816139200,264.568195689808,,,0.000156796547917976,8.77181862771698E-6,0.000176662919294994,8.81510356796729E-6,0.534306168556213,0.875137388706207,27.7686347961426,0.211924016475678,30,4,200,-4.29173196607735E-5,-0.845414757728577,0.0525073520839214,1,,,,,,,,,,,,,,,,
,3826059447.88221,267.870574951172,999.771911621094,,,6,,,,26.0463790893555,,,1,,,,,,,,,,,,,,,,,,,,,,267.682830810547,268.032867431641,999.771911621094,999.771911621094,,,7.2388162612915,-99999999,1,0,0,0,0.0176239013671875,33.2355842590332,2,1,1,268.058319091797,0,1816138976,267.874978637695,,,0.000154184538317125,8.65825609303748E-6,0.000174383808943169,8.70236305301798E-6,0.528036296367645,0.874253749847412,27.7944583892822,0.212756246328354,30,4,200,-0.000107252235466149,-0.852696418762207,0.0349384061992168,1,,,,,,,,,,,,,,,,
,3826059547.32353,271.174255371094,999.771911621094,,,6,,,,26.0463790893555,,,1,,,,,,,,,,,,,,,,,,,,,,270.997253417969,271.323791503906,999.771911621094,999.771911621094,,,7.26025485992432,-99999999,1,0,0,0,0.0167083740234375,33.2355842590332,2,1,1,271.351257324219,0,1816138944,271.172979736328,,,0.000151595707669403,8.54940846116126E-6,0.00017219792368804,8.59443031925575E-6,0.521066248416901,0.873209476470947,27.8230018615723,0.213683411478996,30,4,200,-7.03710175002925E-5,-0.866383910179138,0.0100644323974848,1,,,,,,,,,,,,,,,,
,3826059645.97737,274.456298828125,999.771911621094,,,6,,,,26.0463790893555,,,1,,,,,,,,,,,,,,,,,,,,,,274.272521972656,274.617980957031,999.771911621094,999.771911621094,,,7.30718803405762,-99999999,1,0,0,0,0.01800537109375,32.7468223571777,2,1,1,274.640075683594,0,1816138784,274.462463378906,,,0.000149145105230912,8.4505489793042E-6,0.000170205499709959,8.49650521979048E-6,0.513649344444275,0.8718301653862,27.8532543182373,0.214679270982742,30,4,200,-7.58367532398552E-5,-0.873658239841461,-0.00614220788702369,1,,,,,,,,,,,,,,,,
,3826059744.9505,277.743301391602,999.771911621094,,,6,,,,26.0463790893555,,,1,,,,,,,,,,,,,,,,,,,,,,277.563781738281,277.907470703125,999.771911621094,999.771911621094,,,7.37833833694458,-99999999,1,0,0,0,0.019378662109375,33.2355842590332,2,1,1,277.928833007813,0,1816139104,277.746478271484,,,0.000146630480131482,8.35092599294227E-6,0.000168203020299973,8.39815962441493E-6,0.505679607391357,0.870362222194672,27.8856773376465,0.215772062540054,30,4,200,-0.000159904273459688,-0.881427228450775,-0.0233137626200914,1,,,,,,,,,,,,,,,,
,3826059844.24877,281.054000854492,999.771911621094,,,6,,,,26.0463790893555,,,1,,,,,,,,,,,,,,,,,,,,,,280.880950927734,281.213409423828,999.771911621094,999.771911621094,,,7.47677421569824,-99999999,1,0,0,0,0.020751953125,33.7243423461914,2,1,1,281.22705078125,0,1816139168,281.049546675249,,,0.000144073732773547,8.2514031583851E-6,0.000166202044048056,8.3000811371564E-6,0.497236877679825,0.868702471256256,27.9203090667725,0.217007532715797,30,4,200,-0.000154455075971782,-0.89873343706131,-0.0500492230057716,1,,,,,,,,,,,,,,,,
,3826059943.55823,284.369888305664,999.771911621094,,,6,,,,26.0463790893555,,,1,,,,,,,,,,,,,,,,,,,,,,284.176483154297,284.541687011719,999.771911621094,999.771911621094,,,7.59386205673218,-99999999,1,0,0,0,0.017242431640625,33.2355842590332,2,1,1,284.563293457031,0,1816138944,284.367894952947,,,0.000141551208740452,8.15513398123675E-6,0.000164262318008604,8.20494704368899E-6,0.488553315401077,0.867128908634186,27.9561862945557,0.218307748436928,30,4,200,-0.000201844843104482,-0.913469433784485,-0.0730729177594185,1,,,,,,,,,,,,,,,,
,3826060042.73766,287.662796020508,999.771911621094,,,6,,,,26.0463790893555,,,1,,,,,,,,,,,,,,,,,,,,,,287.491638183594,287.814758300781,999.771911621094,999.771911621094,,,7.72029113769531,-99999999,1,0,0,0,0.01953125,33.2355842590332,2,1,1,287.833953857422,0,1816139104,287.662777709961,,,0.000139077561683144,8.06273943007007E-6,0.000162402785283977,8.11379801068052E-6,0.479683220386505,0.865556478500366,27.9932498931885,0.219692930579185,30,4,200,-4.84611482534092E-5,-0.91893482208252,-0.0883771628141403,1,,,,,,,,,,,,,,,,
,3826060141.27257,290.918243408203,999.771911621094,,,6,,,,26.0463790893555,,,1,,,,,,,,,,,,,,,,,,,,,,290.744964599609,291.082458496094,999.771911621094,999.771911621094,,,7.85967826843262,-99999999,1,0,0,0,0.0167083740234375,32.7468223571777,2,1,1,291.100402832031,0,1816138880,290.927389526367,,,0.000136574868338846,7.96954201176215E-6,0.00016053401761232,8.02217835105445E-6,0.470665514469147,0.863978862762451,28.0307865142822,0.221124395728111,30,4,200,-0.00011186464689672,-0.924031913280487,-0.101509600877762,1,,,,,,,,,,,,,,,,
,3826060240.64695,294.236663818359,999.771911621094,,,6,,,,26.0463790893555,,,1,,,,,,,,,,,,,,,,,,,,,,294.056549072266,294.395568847656,999.771911621094,999.771911621094,,,8.00223445892334,-99999999,1,0,0,0,0.01861572265625,32.7468223571777,2,1,1,294.416778564453,0,1816138816,294.238555908203,,,0.00013404474575888,7.87826572292737E-6,0.000158702329644192,7.9324682177311E-6,0.461058408021927,0.862328827381134,28.0712966918945,0.222723960876465,30,4,200,-2.15589425351936E-5,-0.931550920009613,-0.117584131658077,1,,,,,,,,,,,,,,,,
,3826060339.91466,297.554718017578,999.771911621094,,,6,,,,26.0463790893555,,,1,,,,,,,,,,,,,,,,,,,,,,297.379272460937,297.70947265625,999.771911621094,999.771911621094,,,8.04250049591064,-99999999,1,0,0,0,0.0138092041015625,33.2355842590332,2,1,1,297.730163574219,0,1816138976,297.546078768643,,,0.000131418731045585,7.78055822476576E-6,0.000156731416078988,7.83557293435774E-6,0.451593816280365,0.860866665840149,28.1118335723877,0.224390640854836,30,4,200,-4.3845077016158E-5,-0.944510459899902,-0.140522718429565,1,,,,,,,,,,,,,,,,
,3826060438.8468,299.778427124023,999.771911621094,,,6,,,,26.0463790893555,,,1,,,,,,,,,,,,,,,,,,,,,,299.752105712891,299.801696777344,999.771911621094,999.771911621094,,,8.01223945617676,-99999999,1,0,0,0,0.018157958984375,33.2355842590332,5,1,1,299.804748535156,0,1816138976,299.781649780273,,,0.000129631754613924,7.71627264191813E-6,0.000155451601943263,7.77328018273331E-6,0.444794774055481,0.859341859817505,28.1403617858887,0.225595280528069,30,4,200,-7.91843194747344E-5,-0.955670595169067,-0.156812489032745,1,,,,,,,,,,,,,,,,
,3826060472.21024,299.891128540039,999.771911621094,,,6,,,,26.0463790893555,,,1,,,,,,,,,,,,,,,,,,,,,,299.879089355469,299.901397705078,999.771911621094,999.771911621094,,,7.99930286407471,-99999999,1,0,0,0,0.0180816650390625,32.7468223571777,1,1,1,299.903167724609,0,1816138944,299.893857088956,,,0.000129521715547109,7.7133640964662E-6,0.000155399454541349,7.77059960242225E-6,0.444207400083542,0.85940945148468,28.1431770324707,0.225696876645088,30,4,200,-0.000170919942320324,-0.96405041217804,-0.164450585842133,1,,,,,,,,,,,,,,,,