File: data/AP424/MH_1_8K.csv
[Data]

Comment,Time Stamp (sec),Temperature (K),Magnetic Field (Oe),Moment (emu),M. Std. Err. (emu),Transport Action,Averaging Time (sec),Frequency (Hz),Peak Amplitude (mm),Center Position (mm),Lockin Signal' (V),Lockin Signal (V),Range,M. Quad. Signal (emu),AC Moment (emu),AC M. Std Err. (emu),AC Phase (deg),AC Phase Std. Err. (deg),AC Susceptibility (emu/Oe),AC Suscept. Std Err. (emu/Oe),AC X' (emu/Oe),AC X' Std Err. (emu/Oe),AC X'' (emu/Oe),AC X'' Std Err. (emu/Oe),AC Drive (Oe),AC Frequency (Hz),AC Averaging Time (sec),AC Cycles,AC Range,AC Measure Type,AC Signal' (V),AC Signal'' (V),AC Trim Coil Ratio,AC Trim Coil Phase,Min. Temperature (K),Max. Temperature (K),Min. Field (Oe),Max. Field (Oe),Mass (grams),Motor Lag (deg),Pressure (Torr),Measure Count,Measurement Number,SQUID Status (code),Motor Status (code),Measure Status (code),Motor Current (amps),Motor Temp. (C),Temp. Status (code),Field Status (code),Chamber Status (code),Chamber Temp (K),Redirection State,Evercool Status,Average Temp (K),Rotation Angle (deg),Rotator state,DC Moment Fixed Ctr (emu),DC Moment Err Fixed Ctr (emu),DC Moment Free Ctr (emu),DC Moment Err Free Ctr (emu),DC Fixed Fit,DC Free Fit,DC Calculated Center (mm),DC Calculated Center Err (mm),DC Scan Length (mm),DC Scan Time (s),DC Number of Points,DC Squid Drift,DC Min V (V),DC Max V (V),DC Scans per Measure,Map 01,Map 02,Map 03,Map 04,Map 05,Map 06,Map 07,Map 08,Map 09,Map 10,Map 11,Map 12,Map 13,Map 14,Map 15,Map 16

,3825559857.17477,1.80160892009735,-0.252101629972458,,,6,,,,25.9127864837646,,,1,,,,,,,,,,,,,,,,,,,,,,1.79836714267731,1.80164587497711,-0.252101629972458,-0.252101629972458,,,2.32953238487244,-99999999,1,0,0,0,0.0145721435546875,33.2355842590332,1,1,1,1.80157196521759,0,1816138976,1.80005590120951,,,-1.76176791680298E-5,8.73962167706476E-7,-1.76518684560506E-5,8.74033927950416E-7,0.936617732048035,0.982334315776825,25.6828517913818,0.187766671180725,30,4,200,-0.00025571949663572,0.000774145184550434,0.162931337952614,1,,,,,,,,,,,,,,,,

,3825559886.52727,1.80158925056458,28.0841197967529,,,6,,,,25.9127864837646,,,1,,,,,,,,,,,,,,,,,,,,,,1.79879534244537,1.80180609226227,28.0841197967529,28.0841197967529,,,2.33067226409912,-99999999,1,0,0,0,0.0138092041015625,32.7468223571777,1,1,1,1.80137240886688,0,1816139104,1.8001392212781,,,0.000756265657595014,3.74629304084748E-5,0.000756270498601397,3.74629425051573E-5,0.965565741062164,0.965742528438568,25.8997268676758,0.187498673796654,30,4,200,0.000789952289778739,-3.16774010658264,0.412855297327042,1,,,,,,,,,,,,,,,,

,3825559914.93314,1.80165410041809,111.693618774414,,,6,,,,25.9127864837646,,,10,,,,,,,,,,,,,,,,,,,,,,1.79827165603638,1.80204439163208,111.693618774414,111.693618774414,,,2.33581471443176,-99999999,1,0,0,0,0.0145721435546875,33.2355842590332,1,1,1,1.8012638092041,0,1816139040,1.80006991113935,,,0.00303459136001663,0.000150323298142823,0.00303462300276911,0.000150323348099193,0.965663969516754,0.965958893299103,25.8959541320801,0.187495738267899,30,4,200,0.000297321734251454,-4.76689100265503,4.77245187759399,1,,,,,,,,,,,,,,,,

,3825559944.4504,1.80160766839981,251.862106323242,,,6,,,,25.9127864837646,,,10,,,,,,,,,,,,,,,,,,,,,,1.79847896099091,1.80200231075287,251.862106323242,251.862106323242,,,2.3341691493988,-99999999,1,0,0,0,0.0145721435546875,33.7243423461914,1,1,1,1.80121302604675,0,1816138976,1.80020306110382,,,0.00684362475606584,0.000339007849181558,0.00684370494120454,0.000339008059691669,0.96583765745163,0.966163635253906,25.8951377868652,0.18750387430191,30,4,200,0.000936070515308529,-2.83504843711853,0.404993027448654,1,,,,,,,,,,,,,,,,

,3825559968.06203,1.80170196294785,447.858489990234,,,6,,,,25.9127864837646,,,10,,,,,,,,,,,,,,,,,,,,,,1.79822170734406,1.8019152879715,447.858489990234,447.858489990234,,,2.33547472953796,-99999999,1,0,0,0,0.0145721435546875,33.2355842590332,1,1,1,1.80148863792419,0,1816139040,1.80013103918596,,,0.0119138483669329,0.000590167289038874,0.011913991994508,0.000590167456795831,0.965869963169098,0.966216206550598,25.8946094512939,0.187488198280334,30,4,200,0.00225397944450378,-4.90557050704956,0.738434374332428,1,,,,,,,,,,,,,,,,

,3825559997.40211,1.80169945955276,699.922302246094,,,6,,,,25.9127864837646,,,100,,,,,,,,,,,,,,,,,,,,,,1.79822993278503,1.80221486091614,699.922302246094,699.922302246094,,,2.33754563331604,-99999999,1,0,0,0,0.0145721435546875,33.2355842590332,1,1,1,1.80118405818939,0,1816138912,1.80009273886681,,,0.0175289449059189,0.000868319524300539,0.0175292213933488,0.000868319843805707,0.965817093849182,0.966270267963409,25.8919887542725,0.187493830919266,30,4,200,0.00035145744914189,-4.73506259918213,4.74841928482056,1,,,,,,,,,,,,,,,,

,3825560027.05324,1.80161064863205,1007.72576904297,,,6,,,,25.9127864837646,,,100,,,,,,,,,,,,,,,,,,,,,,1.79838252067566,1.80184066295624,1007.72576904297,1007.72576904297,,,2.33818125724792,-99999999,1,0,0,0,0.0138092041015625,33.2355842590332,1,1,1,1.80138063430786,0,1816139008,1.80013480186462,,,0.0230151127057516,0.00114020681650931,0.0230157121465281,0.00114020766019745,0.962805449962616,0.963491201400757,25.8861331939697,0.187513083219528,30,4,200,0.000903994834516198,-0.952217400074005,0.151759222149849,1,,,,,,,,,,,,,,,,

,3825560051.64016,1.80164086818695,1371.84875488281,,,6,,,,25.9127864837646,,,100,,,,,,,,,,,,,,,,,,,,,,1.7986181974411,1.80179250240326,1371.84875488281,1371.84875488281,,,2.33936905860901,-99999999,1,0,0,0,0.0145721435546875,33.2355842590332,1,1,1,1.80148923397064,0,1816138912,1.80015217065811,,,0.0306969407693159,0.00152086815979924,0.0306976902727855,0.00152086930951702,0.961237907409668,0.961852252483368,25.8870124816895,0.187530517578125,30,4,200,0.000874483957886696,-1.27785158157349,0.200169667601585,1,,,,,,,,,,,,,,,,

,3825560076.45701,1.80170470476151,1791.67346191406,,,6,,,,25.9127864837646,,,100,,,,,,,,,,,,,,,,,,,,,,1.79831719398499,1.80194664001465,1791.67346191406,1791.67346191406,,,2.33967876434326,-99999999,1,0,0,0,0.0145721435546875,33.2355842590332,1,1,1,1.80146276950836,0,1816138880,1.80011808872223,,,0.0410937158421114,0.00203589990622747,0.041094570031407,0.00203590214317002,0.962162733078003,0.962685883045197,25.8892784118652,0.187521651387215,30,4,200,0.0022363483440131,-1.69833743572235,0.277240842580795,1,,,,,,,,,,,,,,,,

,3825560101.66059,1.80184042453766,2267.90600585938,,,6,,,,25.9127864837646,,,100,,,,,,,,,,,,,,,,,,,,,,1.79837048053741,1.80205357074738,2267.90600585938,2267.90600585938,,,2.3373019695282,-99999999,1,0,0,0,0.0145721435546875,33.2355842590332,1,1,1,1.80162727832794,0,1816139008,1.80016263723373,,,0.053002819421179,0.00262566620468565,0.0530037072899342,0.00262566853274822,0.964713037014008,0.965164959430695,25.8916835784912,0.187509849667549,30,4,200,0.00203459104523063,-2.18291282653809,0.344945460557938,1,,,,,,,,,,,,,,,,

,3825560127.13773,1.80170035362244,2799.802734375,,,6,,,,25.9127864837646,,,100,,,,,,,,,,,,,,,,,,,,,,1.79838478565216,1.80174839496613,2799.802734375,2799.802734375,,,2.34123635292053,-99999999,1,0,0,0,0.0145721435546875,33.2355842590332,1,1,1,1.80137062072754,0,1816138944,1.80010307918895,,,0.0636754936966494,0.00315426932806026,0.0636766465673896,0.00315427096764454,0.965637505054474,0.966152548789978,25.8905696868896,0.187494784593582,30,4,200,0.00133528001606464,-2.60036849975586,0.419916123151779,1,,,,,,,,,,,,,,,,

,3825560152.77105,1.8017281293869,3387.95556640625,,,6,,,,25.9127864837646,,,100,,,,,,,,,,,,,,,,,,,,,,1.79824268817902,1.80202424526215,3387.95556640625,3387.95556640625,,,2.34127116203308,-99999999,1,0,0,0,0.0145721435546875,33.2355842590332,1,1,1,1.80143201351166,0,1816139104,1.80014444481243,,,0.0724926315182874,0.00359105825082605,0.072494273375947,0.00359105979667527,0.965499818325043,0.966149151325226,25.8878135681152,0.187496483325958,30,4,200,0.000999496667645872,-2.96964621543884,0.470202147960663,1,,,,,,,,,,,,,,,,

,3825560178.80036,1.80154395103455,4032.27709960937,,,6,,,,25.9127864837646,,,100,,,,,,,,,,,,,,,,,,,,,,1.79837954044342,1.80158519744873,4032.27709960937,4032.27709960937,,,2.34237718582153,-99999999,1,0,0,0,0.0145721435546875,32.7468223571777,1,1,1,1.80150270462036,0,1816138784,1.80013256072998,,,0.0800863617820168,0.00396725412115847,0.0800887216266565,0.00396725749801215,0.965299010276794,0.966132640838623,25.8844451904297,0.187502682209015,30,4,200,0.000912510440684855,-3.28054714202881,0.520041227340698,1,,,,,,,,,,,,,,,,

,3825560205.39153,1.80149799585342,4732.17431640625,,,6,,,,25.9127864837646,,,100,,,,,,,,,,,,,,,,,,,,,,1.79868912696838,1.80175745487213,4732.17431640625,4732.17431640625,,,2.33972477912903,-99999999,1,0,0,0,0.0145721435546875,33.2355842590332,1,1,1,1.80123853683472,0,1816138944,1.80013244802302,,,0.0864547475805484,0.00428276294796014,0.0864579726599535,0.00428276344192075,0.96504807472229,0.966127455234528,25.8804817199707,0.187481626868248,30,4,200,0.00103577075060457,-3.54174900054932,0.558121025562286,1,,,,,,,,,,,,,,,,

,3825560232.24087,1.80179965496063,5488.26416015625,,,6,,,,25.9127864837646,,,100,,,,,,,,,,,,,,,,,,,,,,1.79877471923828,1.80212986469269,5488.26416015625,5488.26416015625,,,2.34334444999695,-99999999,1,0,0,0,0.0145721435546875,33.7243423461914,1,1,1,1.80146944522858,0,1816138944,1.8004106499932,,,0.091671674653471,0.00454125257119348,0.0916760845944562,0.00454125949446624,0.964715242385864,0.966059327125549,25.8766288757324,0.187504336237907,30,4,200,0.00112098781391978,-3.74823904037476,0.597320914268494,1,,,,,,,,,,,,,,,,

,3825560259.67381,1.80158686637878,6300.359375,,,6,,,,25.9127864837646,,,100,,,,,,,,,,,,,,,,,,,,,,1.79855740070343,1.801882147789,6300.359375,6300.359375,,,2.34200739860535,-99999999,1,0,0,0,0.0145721435546875,32.7468223571777,1,1,1,1.80129158496857,0,1816138912,1.80011967095462,,,0.0958393612661526,0.0047477833834069,0.0958451223291944,0.00474779370399893,0.964286625385284,0.965945422649384,25.8724613189697,0.187511324882507,30,4,200,0.00122557487338781,-3.92020797729492,0.623451054096222,1,,,,,,,,,,,,,,,,

,3825560286.94446,1.80166834592819,7168.43359375,,,6,,,,25.9127864837646,,,100,,,,,,,,,,,,,,,,,,,,,,1.79816555976868,1.80198788642883,7168.43359375,7168.43359375,,,2.34402418136597,-99999999,1,0,0,0,0.0145721435546875,33.2355842590332,1,1,1,1.80134880542755,0,1816138752,1.80012176253579,,,0.0990907352343659,0.00490891981547774,0.0990979611363556,0.00490893214244681,0.963911294937134,0.965915501117706,25.8683338165283,0.187510520219803,30,4,200,0.00124012271407992,-4.04638385772705,0.649499297142029,1,,,,,,,,,,,,,,,,

,3825560314.89421,1.80197381973267,8092.310546875,,,6,,,,25.9127864837646,,,100,,,,,,,,,,,,,,,,,,,,,,1.79811906814575,1.8020966053009,8092.310546875,8092.310546875,,,2.3439404964447,-99999999,1,0,0,0,0.0145721435546875,33.7243423461914,1,1,1,1.80185103416443,0,1816138912,1.80018280852925,,,0.101606106047665,0.00503362058631728,0.101615040807591,0.00503363724711893,0.963419377803802,0.965807735919952,25.8640594482422,0.187495723366737,30,4,200,0.00135504512581974,-4.15048742294312,0.665976881980896,1,,,,,,,,,,,,,,,,

,3825560343.26838,1.80183446407318,9072.4052734375,,,6,,,,25.9127864837646,,,100,,,,,,,,,,,,,,,,,,,,,,1.79827046394348,1.80203664302826,9072.4052734375,9072.4052734375,,,2.34536647796631,-99999999,1,0,0,0,0.0145721435546875,33.2355842590332,1,1,1,1.8016322851181,0,1816138976,1.80014820532365,,,0.103543830842904,0.00512971755484563,0.103554467564305,0.00512973587964364,0.962896108627319,0.965668499469757,25.8600425720215,0.18751235306263,30,4,200,0.00141620787326246,-4.23083209991455,0.675754129886627,1,,,,,,,,,,,,,,,,

,3825560371.81698,1.80165803432465,10108.341796875,,,6,,,,25.9127864837646,,,100,,,,,,,,,,,,,,,,,,,,,,1.79817819595337,1.80211472511291,10108.341796875,10108.341796875,,,2.34547567367554,-99999999,1,0,0,0,0.0145721435546875,33.7243423461914,1,1,1,1.80120134353638,0,1816139008,1.80014886639335,,,0.105030759847984,0.00520347381015233,0.105043106138002,0.00520349519910215,0.962418913841248,0.965565025806427,25.856372833252,0.187518179416656,30,4,200,0.00139011919964105,-4.29363441467285,0.69508820772171,1,,,,,,,,,,,,,,,,

,3825560401.44968,1.80153775215149,11200.49609375,,,6,,,,25.9127864837646,,,100,,,,,,,,,,,,,,,,,,,,,,1.79825496673584,1.80176866054535,11200.49609375,11200.49609375,,,2.34466814994812,-99999999,1,0,0,0,0.0145721435546875,33.2355842590332,1,1,1,1.80130684375763,0,1816139136,1.80022184848785,,,0.106180248057097,0.00526051845554062,0.106194262577502,0.00526054786106238,0.961929261684418,0.965403199195862,25.8532428741455,0.187514528632164,30,4,200,0.0013153413310647,-4.33706331253052,0.694978296756744,1,,,,,,,,,,,,,,,,

,3825560430.73482,1.80157482624054,12348.478515625,,,6,,,,25.9127864837646,,,100,,,,,,,,,,,,,,,,,,,,,,1.79816794395447,1.80198228359222,12348.478515625,12348.478515625,,,2.3447949886322,-99999999,1,0,0,0,0.0146484375,32.7468223571777,1,1,1,1.80116736888886,0,1816139104,1.80016538229856,,,0.107074285773641,0.00530490062797597,0.10708957019445,0.00530492789567725,0.961499571800232,0.965251505374908,25.850658416748,0.18752883374691,30,4,200,0.00132075359579176,-4.37941551208496,0.706039130687714,1,,,,,,,,,,,,,,,,

,3825560460.26226,1.80197495222092,13552.2763671875,,,6,,,,25.9127864837646,,,100,,,,,,,,,,,,,,,,,,,,,,1.79799699783325,1.80238008499146,13552.2763671875,13552.2763671875,,,2.34657168388367,-99999999,1,0,0,0,0.0145721435546875,33.2355842590332,1,1,1,1.80156981945038,0,1816138944,1.80012411420996,,,0.10778773223816,0.00534034279619793,0.107804384939599,0.0053403742143156,0.961037576198578,0.965053260326386,25.8482246398926,0.187535181641579,30,4,200,0.00124461739324033,-4.40954494476318,0.711671531200409,1,,,,,,,,,,,,,,,,

,3825560489.9406,1.8018770813942,14812.29296875,,,6,,,,25.9127864837646,,,100,,,,,,,,,,,,,,,,,,,,,,1.79801869392395,1.80226171016693,14812.29296875,14812.29296875,,,2.34582948684692,-99999999,1,0,0,0,0.0145721435546875,33.2355842590332,1,1,1,1.80149245262146,0,1816139168,1.80022710561752,,,0.108352733564556,0.00536841185186605,0.10837040410637,0.00536844395416231,0.96068274974823,0.964898705482483,25.8464088439941,0.187536850571632,30,4,200,0.00116670376155525,-4.43351984024048,0.714538812637329,1,,,,,,,,,,,,,,,,

,3825560520.21539,1.80165213346481,16128.3134765625,,,6,,,,25.9127864837646,,,100,,,,,,,,,,,,,,,,,,,,,,1.79811942577362,1.80211412906647,16128.3134765625,16128.3134765625,,,2.34792304039001,-99999999,1,0,0,0,0.0138092041015625,32.7468223571777,1,1,1,1.80119013786316,0,1816138752,1.80016798973083,,,0.108804809455552,0.00539085877747257,0.108823018468556,0.00539089064258263,0.960446774959564,0.964757263660431,25.8455028533936,0.187532216310501,30,4,200,0.00103064253926277,-4.4477801322937,0.720621645450592,1,,,,,,,,,,,,,,,,

,3825560550.8083,1.801662504673,17500.337890625,,,6,,,,25.9127864837646,,,100,,,,,,,,,,,,,,,,,,,,,,1.79855823516846,1.80194199085236,17500.337890625,17500.337890625,,,2.34708833694458,-99999999,1,0,0,0,0.0138092041015625,33.2355842590332,1,1,1,1.80138301849365,0,1816139040,1.80014176802202,,,0.109185267287017,0.00540976377670079,0.109203760807641,0.00540978916000824,0.960189580917358,0.964559972286224,25.8448429107666,0.187514171004295,30,4,200,0.000931883172597736,-4.46919918060303,0.729031145572662,1,,,,,,,,,,,,,,,,

,3825560582.11807,1.80155450105667,18928.2421875,,,6,,,,25.9127864837646,,,100,,,,,,,,,,,,,,,,,,,,,,1.79788589477539,1.80214071273804,18928.2421875,18928.2421875,,,2.34895205497742,-99999999,1,0,0,0,0.0138092041015625,33.2355842590332,1,1,1,1.80096828937531,0,1816138784,1.80012467774478,,,0.109491108177824,0.00542496129973993,0.109509997263269,0.00542499794751391,0.959992527961731,0.96436882019043,25.8446197509766,0.187530070543289,30,4,200,0.000765065487939864,-4.47763061523438,0.722567081451416,1,,,,,,,,,,,,,,,,

,3825560613.05022,1.80185461044312,20412.515625,,,6,,,,25.9127864837646,,,100,,,,,,,,,,,,,,,,,,,,,,1.79799950122833,1.80226719379425,20412.515625,20412.515625,,,2.34979033470154,-99999999,1,0,0,0,0.0146484375,33.2355842590332,1,1,1,1.80144202709198,0,1816137888,1.80015276670456,,,0.109767743552375,0.0054387068994338,0.10978640069272,0.00543873913564766,0.959809482097626,0.964115500450134,25.8449764251709,0.187538459897041,30,4,200,0.000718150287866592,-4.48938512802124,0.727693736553192,1,,,,,,,,,,,,,,,,

,3825560644.40194,1.80187296867371,21952.515625,,,6,,,,25.9127864837646,,,100,,,,,,,,,,,,,,,,,,,,,,1.79786205291748,1.80224883556366,21952.515625,21952.515625,,,2.34917259216309,-99999999,1,0,0,0,0.0146484375,33.2355842590332,1,1,1,1.8012421131134,0,1816138816,1.80013986067338,,,0.110001571248909,0.00545031804978874,0.110019820940693,0.00545034791448305,0.959692120552063,0.963883876800537,25.8457317352295,0.187542200088501,30,4,200,0.000643211416900158,-4.50333213806152,0.735698044300079,1,,,,,,,,,,,,,,,,

,3825560675.69064,1.80180794000626,23548.357421875,,,6,,,,25.9127864837646,,,100,,,,,,,,,,,,,,,,,,,,,,1.79766154289246,1.80197703838348,23548.357421875,23548.357421875,,,2.34984803199768,-99999999,1,0,0,0,0.0145721435546875,33.2355842590332,1,1,1,1.80163884162903,0,1816139040,1.80015245350924,,,0.110219093465121,0.00546112660964034,0.110236776263377,0.00546115675979759,0.959560036659241,0.963585019111633,25.8469009399414,0.187533840537071,30,4,200,0.000599271152168512,-4.50641345977783,0.7310351729393,1,,,,,,,,,,,,,,,,

,3825560707.94306,1.80187433958054,25200.166015625,,,6,,,,25.9127864837646,,,100,,,,,,,,,,,,,,,,,,,,,,1.79776906967163,1.80222725868225,25200.166015625,25200.166015625,,,2.3477635383606,-99999999,1,0,0,0,0.0145721435546875,33.2355842590332,1,1,1,1.80152142047882,0,1816138976,1.80011001500216,,,0.110381347715971,0.00546916195018204,0.110398114710127,0.00546918519628016,0.959571182727814,0.96339875459671,25.8484687805176,0.1875329464674,30,4,200,0.000437053007772192,-4.50849056243897,0.739303231239319,1,,,,,,,,,,,,,,,,

,3825560740.50929,1.80162304639816,26908.35546875,,,6,,,,25.9127864837646,,,100,,,,,,,,,,,,,,,,,,,,,,1.79812276363373,1.80203592777252,26908.35546875,26908.35546875,,,2.35143685340881,-99999999,1,0,0,0,0.0145721435546875,32.7468223571777,1,1,1,1.8012101650238,0,1816139040,1.80019944906235,,,0.110544069888903,0.00547722032542821,0.110559941389381,0.00547724585146115,0.959585428237915,0.963176906108856,25.8504028320313,0.187534347176552,30,4,200,0.000381212099455297,-4.519615650177,0.736416637897491,1,,,,,,,,,,,,,,,,

,3825560772.6849,1.80155265331268,28672.462890625,,,6,,,,25.9127864837646,,,100,,,,,,,,,,,,,,,,,,,,,,1.79798257350922,1.80183851718903,28672.462890625,28672.462890625,,,2.35002899169922,-99999999,1,0,0,0,0.0145721435546875,33.2355842590332,1,1,1,1.80126678943634,0,1816138976,1.80016394853592,,,0.110694234203433,0.00548467039838324,0.110708893201206,0.00548469374792971,0.95955091714859,0.962849080562592,25.8528690338135,0.187532782554626,30,4,200,0.000444154167780653,-4.52942705154419,0.744474947452545,1,,,,,,,,,,,,,,,,

,3825560805.80492,1.80168038606644,30492.3203125,,,6,,,,25.9127864837646,,,100,,,,,,,,,,,,,,,,,,,,,,1.7980968952179,1.80231869220734,30492.3203125,30492.3203125,,,2.34979152679443,-99999999,1,0,0,0,0.0145721435546875,33.2355842590332,1,1,1,1.80104207992554,0,1816139040,1.8002182895487,,,0.110817178171245,0.00549075868879721,0.110830697218464,0.00549077837050177,0.959562599658966,0.962600290775299,25.8552017211914,0.187528699636459,30,4,200,0.000229505923925899,-4.52982759475708,0.740525424480438,1,,,,,,,,,,,,,,,,

,3825560839.14713,1.8017646074295,32368.333984375,,,6,,,,25.9127864837646,,,100,,,,,,,,,,,,,,,,,,,,,,1.79774010181427,1.80235207080841,32368.333984375,32368.333984375,,,2.34909582138062,-99999999,1,0,0,0,0.0145721435546875,32.7468223571777,1,1,1,1.8011771440506,0,1816138944,1.80018827048215,,,0.110935299097053,0.00549659930032253,0.110947497854234,0.00549661874125932,0.959619581699371,0.962342798709869,25.8581924438477,0.187540426850319,30,4,200,0.000211070830118842,-4.53625965118408,0.741191864013672,1,,,,,,,,,,,,,,,,

,3825560873.01463,1.80186688899994,34300.2890625,,,6,,,,25.9127864837646,,,100,,,,,,,,,,,,,,,,,,,,,,1.79805040359497,1.80210113525391,34300.2890625,34300.2890625,,,2.35111784934998,-99999999,1,0,0,0,0.0145721435546875,32.7468223571777,1,1,1,1.80163264274597,0,1816138848,1.80015893415971,,,0.111060627753681,0.00550281474106298,0.111071371593257,0.00550282960835458,0.959590673446655,0.961985051631928,25.8614768981934,0.187530621886253,30,4,200,0.00010644751455402,-4.5364818572998,0.747374832630157,1,,,,,,,,,,,,,,,,

,3825560906.57345,1.80215591192245,36288.3515625,,,6,,,,25.9127864837646,,,100,,,,,,,,,,,,,,,,,,,,,,1.79779458045959,1.80218613147736,36288.3515625,36288.3515625,,,2.35019850730896,-99999999,1,0,0,0,0.0138092041015625,33.7243423461914,1,1,1,1.80212569236755,0,1816138944,1.80014042420821,,,0.111143614336856,0.00550691983079988,0.111152987150343,0.00550693200978336,0.959620654582977,0.961704909801483,25.8648414611816,0.187530353665352,30,4,200,0.000108542859379668,-4.53592205047607,0.751413643360138,1,,,,,,,,,,,,,,,,

,3825560940.93288,1.80182558298111,38332.37890625,,,6,,,,25.9127864837646,,,100,,,,,,,,,,,,,,,,,,,,,,1.79844057559967,1.80211758613586,38332.37890625,38332.37890625,,,2.3498203754425,-99999999,1,0,0,0,0.0145721435546875,33.2355842590332,1,1,1,1.80153357982635,0,1816139008,1.80016057057814,,,0.111248321024549,0.00551211358542301,0.111256309888007,0.00551212650725528,0.959598779678345,0.961353540420532,25.868688583374,0.187545970082283,30,4,200,4.88947771373205E-5,-4.53564071655273,0.748604118824005,1,,,,,,,,,,,,,,,,

,3825560975.37885,1.80145287513733,40432.39453125,,,6,,,,25.9127864837646,,,100,,,,,,,,,,,,,,,,,,,,,,1.79820120334625,1.80188643932343,40432.39453125,40432.39453125,,,2.34943866729736,-99999999,1,0,0,0,0.0145721435546875,34.2131004333496,1,1,1,1.80101931095123,0,1816138752,1.80010908300226,,,0.11134735747931,0.00551703837274524,0.11135397444879,0.00551704730399036,0.959517896175385,0.960969626903534,25.8725662231445,0.18753719329834,30,4,200,9.11296592676081E-5,-4.54698991775513,0.754534363746643,1,,,,,,,,,,,,,,,,

,3825561009.78802,1.8016431927681,42588.43359375,,,6,,,,25.9127864837646,,,100,,,,,,,,,,,,,,,,,,,,,,1.7979416847229,1.80197954177856,42588.43359375,42588.43359375,,,2.35039663314819,-99999999,1,0,0,0,0.0145721435546875,33.2355842590332,1,1,1,1.80130684375763,0,1816138912,1.80013582923196,,,0.111433659030177,0.00552132830930859,0.111439060442368,0.00552133644392518,0.959448575973511,0.960622668266296,25.876522064209,0.187545195221901,30,4,200,0.000117094066808932,-4.54370880126953,0.761129677295685,1,,,,,,,,,,,,,,,,

,3825561044.97935,1.80173242092133,44800.1328125,,,6,,,,25.9127864837646,,,100,,,,,,,,,,,,,,,,,,,,,,1.79813933372498,1.80194318294525,44800.1328125,44800.1328125,,,2.35040760040283,-99999999,1,0,0,0,0.0145721435546875,33.7243423461914,1,1,1,1.8015216588974,0,1816138976,1.80017181634903,,,0.111531343858938,0.00552621573715465,0.111535536035927,0.00552622151901488,0.959252238273621,0.960157573223114,25.8808155059814,0.18754006922245,30,4,200,9.31997201405466E-5,-4.54725027084351,0.755585670471191,1,,,,,,,,,,,,,,,,

,3825561079.87607,1.80176067352295,47068.375,,,6,,,,25.9127864837646,,,100,,,,,,,,,,,,,,,,,,,,,,1.79806208610535,1.80213856697083,47068.375,47068.375,,,2.34792137145996,-99999999,1,0,0,0,0.0138092041015625,33.2355842590332,1,1,1,1.80138278007507,0,1816139008,1.80015381899747,,,0.111621430669586,0.00553071568274531,0.111624554424475,0.00553071876762653,0.959078907966614,0.959753632545471,25.8850898742676,0.187544420361519,30,4,200,2.16734879359137E-5,-4.55148077011108,0.757574796676636,1,,,,,,,,,,,,,,,,

,3825561115.11565,1.80156648159027,49392.42578125,,,6,,,,25.9127864837646,,,100,,,,,,,,,,,,,,,,,,,,,,1.79784619808197,1.80206108093262,49392.42578125,49392.42578125,,,2.35033869743347,-99999999,1,0,0,0,0.0138092041015625,33.2355842590332,1,1,1,1.80107188224792,0,1816139104,1.80012206597762,,,0.111716936336419,0.00553550885457694,0.111719091323429,0.00553551038129734,0.958821356296539,0.959284901618958,25.8897285461426,0.187545955181122,30,4,200,-4.11571891163476E-5,-4.55767345428467,0.770963549613953,1,,,,,,,,,,,,,,,,

,3825561152.03987,1.80159264802933,51772.31640625,,,6,,,,25.9127864837646,,,100,,,,,,,,,,,,,,,,,,,,,,1.79802167415619,1.80195713043213,51772.31640625,51772.31640625,,,2.34925103187561,-99999999,1,0,0,0,0.0145721435546875,33.7243423461914,1,1,1,1.80122816562653,0,1816138912,1.80020749568939,,,0.111796598309095,0.00553951559444203,0.111797934109641,0.00553951637456499,0.95856237411499,0.95884782075882,25.8946170806885,0.187549293041229,30,4,200,-5.90458912483882E-5,-4.5587477684021,0.763328611850739,1,,,,,,,,,,,,,,,,

,3825561188.25673,1.80183696746826,54208.3984375,,,6,,,,25.9127864837646,,,100,,,,,,,,,,,,,,,,,,,,,,1.79792559146881,1.80226385593414,54208.3984375,54208.3984375,,,2.35033845901489,-99999999,1,0,0,0,0.0145721435546875,33.2355842590332,1,1,1,1.80141007900238,0,1816139040,1.80024448633194,,,0.111877917920323,0.00554361977050777,0.111878612554641,0.00554362016494757,0.958224236965179,0.958371162414551,25.8996887207031,0.187554866075516,30,4,200,-6.20013406660291E-6,-4.55461359024048,0.774152517318726,1,,,,,,,,,,,,,,,,

,3825561224.63878,1.80163741111755,56700.48828125,,,6,,,,25.9127864837646,,,100,,,,,,,,,,,,,,,,,,,,,,1.79843187332153,1.80197501182556,56700.48828125,56700.48828125,,,2.34944343566895,-99999999,1,0,0,0,0.0138092041015625,32.7468223571777,1,1,1,1.80129981040955,0,1816138944,1.80012170834975,,,0.111952153070353,0.00554737987668623,0.111952406122756,0.00554737918978814,0.957886397838593,0.957942962646484,25.9046249389648,0.187555909156799,30,4,200,-0.000106185070762876,-4.56401681900024,0.769301176071167,1,,,,,,,,,,,,,,,,

,3825561261.60274,1.80188482999802,59248.2265625,,,6,,,,25.9127864837646,,,100,,,,,,,,,,,,,,,,,,,,,,1.79811143875122,1.80224943161011,59248.2265625,59248.2265625,,,2.35027480125427,-99999999,1,0,0,0,0.0145721435546875,33.2355842590332,1,1,1,1.80152022838593,0,1816138944,1.80024658441544,,,0.112025010203339,0.00555108196811606,0.112025036312711,0.0055510816826112,0.95748382806778,0.957490503787994,25.9099655151367,0.187551766633987,30,4,200,4.9089238018496E-5,-4.56209564208984,0.779853224754333,1,,,,,,,,,,,,,,,,

,3825561298.55082,1.80168634653091,61852.30078125,,,6,,,,25.9127864837646,,,100,,,,,,,,,,,,,,,,,,,,,,1.79787635803223,1.80198800563812,61852.30078125,61852.30078125,,,2.34807181358337,-99999999,1,0,0,0,0.0145721435546875,33.7243423461914,1,1,1,1.80138468742371,0,1816139136,1.80016049471768,,,0.112111458347026,0.00555549271046791,0.112111496648307,0.00555549305509767,0.956954717636108,0.956961154937744,25.9155807495117,0.18755678832531,30,4,200,0.000179660215508193,-4.57060050964355,0.777716815471649,1,,,,,,,,,,,,,,,,

,3825561335.4658,1.80181020498276,64512.4765625,,,6,,,,25.9127864837646,,,100,,,,,,,,,,,,,,,,,,,,,,1.79816734790802,1.80207920074463,64512.4765625,64512.4765625,,,2.34972071647644,-99999999,1,0,0,0,0.0138092041015625,32.7468223571777,1,1,1,1.80154120922089,0,1816139008,1.80015850067139,,,0.112183516876043,0.00555919354290175,0.112183859256218,0.00555919625181904,0.956419885158539,0.956478714942932,25.9212493896484,0.18756540119648,30,4,200,0.00032497791107744,-4.5691933631897,0.782319128513336,1,,,,,,,,,,,,,,,,

,3825561373.40042,1.80164784193039,67228.515625,,,6,,,,25.9127864837646,,,100,,,,,,,,,,,,,,,,,,,,,,1.79790377616882,1.80176174640656,67228.515625,67228.515625,,,2.35154128074646,-99999999,1,0,0,0,0.0145721435546875,33.2355842590332,1,1,1,1.80153393745422,0,1816139008,1.80010937560688,,,0.112255636771118,0.00556290573673322,0.112256557986361,0.00556291063481332,0.955852210521698,0.956018149852753,25.9270858764648,0.187562450766563,30,4,200,0.000468513695523143,-4.57277011871338,0.78575849533081,1,,,,,,,,,,,,,,,,

,3825561411.30717,1.80162680149078,70000.2734375,,,6,,,,25.9127864837646,,,100,,,,,,,,,,,,,,,,,,,,,,1.7979724407196,1.8018616437912,70000.2734375,70000.2734375,,,2.35123634338379,-99999999,1,0,0,0,0.0145721435546875,33.2355842590332,1,1,1,1.80117762088776,0,1816139136,1.80014636299827,,,0.1123284748641,0.0055666835701233,0.112330333096648,0.00556669101305706,0.955178737640381,0.95551860332489,25.933385848999,0.187572926282883,30,4,200,0.00053318205755204,-4.57630157470703,0.796505570411682,1,,,,,,,,,,,,,,,,

,3825561449.18854,1.80165976285934,67228.3515625,,,6,,,,25.9127864837646,,,100,,,,,,,,,,,,,,,,,,,,,,1.79812753200531,1.80188691616058,67228.3515625,67228.3515625,,,2.35143542289734,-99999999,1,0,0,0,0.0145721435546875,33.2355842590332,1,1,1,1.80143260955811,0,1816138656,1.80013089830225,,,0.112271788912287,0.00556371424819481,0.112272722086562,0.00556371828422928,0.955821216106415,0.955992937088013,25.927339553833,0.187564626336098,30,4,200,6.49843786959536E-5,-4.56791687011719,0.791755676269531,1,,,,,,,,,,,,,,,,

,3825561486.11869,1.8016272187233,64512.5,,,6,,,,25.9127864837646,,,100,,,,,,,,,,,,,,,,,,,,,,1.79805219173431,1.80176138877869,64512.5,64512.5,,,2.35116815567017,-99999999,1,0,0,0,0.0145721435546875,33.2355842590332,1,1,1,1.80149304866791,0,1816138848,1.80016105175018,,,0.112184573218342,0.00555921548438446,0.112184871324275,0.00555921733687166,0.956548810005188,0.956602215766907,25.9208431243896,0.187561318278313,30,4,200,0.000100156510598026,-4.56741237640381,0.787781834602356,1,,,,,,,,,,,,,,,,

,3825561523.7202,1.80158078670502,61852.484375,,,6,,,,25.9127864837646,,,100,,,,,,,,,,,,,,,,,,,,,,1.7982519865036,1.80201590061188,61852.484375,61852.484375,,,2.35034966468811,-99999999,1,0,0,0,0.0145721435546875,33.2355842590332,1,1,1,1.80114567279816,0,1816138752,1.80022637844086,,,0.112121406593693,0.00555597178864229,0.112121429004107,0.00555597211741544,0.957018136978149,0.957021415233612,25.9147682189941,0.187559679150581,30,4,200,0.000412497349316254,-4.56767272949219,0.784024834632873,1,,,,,,,,,,,,,,,,

,3825561560.68948,1.80159664154053,59248.4375,,,6,,,,25.9127864837646,,,100,,,,,,,,,,,,,,,,,,,,,,1.79816436767578,1.80176341533661,59248.4375,59248.4375,,,2.35156106948853,-99999999,1,0,0,0,0.0145721435546875,33.7243423461914,1,1,1,1.80142986774445,0,1816139136,1.80015306472778,,,0.11204210113161,0.00555192686202356,0.112042145232842,0.0055519262175536,0.957501649856567,0.957513630390167,25.9090137481689,0.187549322843552,30,4,200,0.000850444892421365,-4.56548309326172,0.784217894077301,1,,,,,,,,,,,,,,,,

,3825561596.86434,1.80156296491623,56700.4609375,,,6,,,,25.9127864837646,,,100,,,,,,,,,,,,,,,,,,,,,,1.79798531532288,1.80208873748779,56700.4609375,56700.4609375,,,2.35053491592407,-99999999,1,0,0,0,0.0145721435546875,33.7243423461914,1,1,1,1.80103719234467,0,1816139008,1.80013244802302,,,0.111967573137214,0.00554812308857889,0.111967946075145,0.00554812289186593,0.957973718643188,0.958053708076477,25.9030876159668,0.187546908855438,30,4,200,0.00106588075868785,-4.56192255020142,0.783468306064606,1,,,,,,,,,,,,,,,,

,3825561632.86553,1.80163133144379,54208.4609375,,,6,,,,25.9127864837646,,,100,,,,,,,,,,,,,,,,,,,,,,1.79783654212952,1.80211532115936,54208.4609375,54208.4609375,,,2.35104298591614,-99999999,1,0,0,0,0.0145721435546875,33.2355842590332,1,1,1,1.80114734172821,0,1816138976,1.80009683695706,,,0.111899167729482,0.00554466842411442,0.111900045160711,0.0055446676582159,0.958239853382111,0.958431005477905,25.8978519439697,0.187553137540817,30,4,200,0.00127347349189222,-4.551100730896,0.776828527450562,1,,,,,,,,,,,,,,,,

,3825561669.03914,1.80168634653091,51772.4453125,,,6,,,,25.9127864837646,,,100,,,,,,,,,,,,,,,,,,,,,,1.79792320728302,1.80239295959473,51772.4453125,51772.4453125,,,2.34951877593994,-99999999,1,0,0,0,0.0138092041015625,33.2355842590332,1,1,1,1.8009797334671,0,1816138880,1.80015389919281,,,0.111817071404292,0.00554052389087189,0.111818703887435,0.00554052545477057,0.958581447601318,0.958927989006042,25.8927803039551,0.187544018030167,30,4,200,0.00139899482019246,-4.54834890365601,0.774876058101654,1,,,,,,,,,,,,,,,,

,3825561705.32731,1.80159342288971,49392.15234375,,,6,,,,25.9127864837646,,,100,,,,,,,,,,,,,,,,,,,,,,1.79797971248627,1.80221319198608,49392.15234375,49392.15234375,,,2.35032773017883,-99999999,1,0,0,0,0.0138092041015625,33.2355842590332,1,1,1,1.80097365379334,0,1816139040,1.80015316009521,,,0.111737338151858,0.0055365188677345,0.111739857950768,0.00553652080801234,0.958816051483154,0.959357798099518,25.8878707885742,0.187536805868149,30,4,200,0.00145990087185055,-4.55784273147583,0.771248698234558,1,,,,,,,,,,,,,,,,

,3825561740.0341,1.80163842439651,47068.25390625,,,6,,,,25.9127864837646,,,100,,,,,,,,,,,,,,,,,,,,,,1.79812347888947,1.80198633670807,47068.25390625,47068.25390625,,,2.34869456291199,-99999999,1,0,0,0,0.0145721435546875,33.7243423461914,1,1,1,1.80129051208496,0,1816139008,1.80026800632477,,,0.111653584279549,0.00553233262666434,0.111657133651567,0.00553233594634726,0.958979845046997,0.959746062755585,25.8832530975342,0.187531933188438,30,4,200,0.00150712195318192,-4.54913425445557,0.763895928859711,1,,,,,,,,,,,,,,,,

,3825561775.09194,1.80172950029373,44800.30859375,,,6,,,,25.9127864837646,,,100,,,,,,,,,,,,,,,,,,,,,,1.79798471927643,1.80216896533966,44800.30859375,44800.30859375,,,2.34946775436401,-99999999,1,0,0,0,0.0145721435546875,33.7243423461914,1,1,1,1.8012900352478,0,1816138976,1.80019298791885,,,0.111569628655,0.00552814610952565,0.111574567390977,0.00552815678226935,0.959102511405945,0.960149347782135,25.8783721923828,0.18754506111145,30,4,200,0.00141661113593727,-4.54356288909912,0.772012889385223,1,,,,,,,,,,,,,,,,

,3825561810.44888,1.80202376842499,42588.20703125,,,6,,,,25.9127864837646,,,100,,,,,,,,,,,,,,,,,,,,,,1.79782402515411,1.80141484737396,42588.20703125,42588.20703125,,,2.35009503364563,-99999999,1,0,0,0,0.0145721435546875,33.2355842590332,1,1,1,1.80147898197174,0,1816139008,1.79998271465302,,,0.111486598538708,0.00552400448948693,0.111492666287911,0.00552401183284895,0.959217131137848,0.960538327693939,25.8742427825928,0.187540575861931,30,4,200,0.00143981701694429,-4.54350185394287,0.767584621906281,1,,,,,,,,,,,,,,,,

,3825561845.25061,1.80177962779999,40432.484375,,,6,,,,25.9127864837646,,,100,,,,,,,,,,,,,,,,,,,,,,1.79771995544434,1.8022164106369,40432.484375,40432.484375,,,2.35010766983032,-99999999,1,0,0,0,0.0138092041015625,33.2355842590332,1,1,1,1.80134284496307,0,1816139072,1.80020948648453,,,0.111399191894739,0.00551965108765316,0.111406630044643,0.00551966054417073,0.959320545196533,0.960949838161469,25.8701171875,0.18754318356514,30,4,200,0.00129632325842977,-4.54575300216675,0.761067390441895,1,,,,,,,,,,,,,,,,

,3825561879.53372,1.80176568031311,38332.30078125,,,6,,,,25.9127864837646,,,100,,,,,,,,,,,,,,,,,,,,,,1.79800546169281,1.80236291885376,38332.30078125,38332.30078125,,,2.34982585906982,-99999999,1,0,0,0,0.0145721435546875,33.2355842590332,1,1,1,1.80116844177246,0,1816138848,1.80016861178658,,,0.111306057639298,0.00551502944861623,0.111314762465452,0.00551503687366242,0.959350109100342,0.96128386259079,25.8664054870605,0.187533631920815,30,4,200,0.00135337840765715,-4.53781747817993,0.759777903556824,1,,,,,,,,,,,,,,,,

,3825561913.30323,1.8021057844162,36288.4375,,,6,,,,25.9127864837646,,,100,,,,,,,,,,,,,,,,,,,,,,1.79791665077209,1.80244386196136,36288.4375,36288.4375,,,2.35008597373962,-99999999,1,0,0,0,0.0145721435546875,33.7243423461914,1,1,1,1.80176770687103,0,1816138880,1.80016034299677,,,0.111199932599814,0.00550977246627483,0.111210209084165,0.00550978253290827,0.959351181983948,0.96164059638977,25.8624267578125,0.187544971704483,30,4,200,0.00134992599487305,-4.53831195831299,0.751177251338959,1,,,,,,,,,,,,,,,,

,3825561946.41893,1.80148065090179,34300.27734375,,,6,,,,25.9127864837646,,,100,,,,,,,,,,,,,,,,,,,,,,1.79793441295624,1.80202007293701,34300.27734375,34300.27734375,,,2.35067486763,-99999999,1,0,0,0,0.0145721435546875,32.7468223571777,1,1,1,1.80094122886658,0,1816138912,1.80017131567001,,,0.111098003749002,0.00550472072023795,0.111109947428981,0.00550474138869809,0.959355592727661,0.961989462375641,25.85888671875,0.187543615698814,30,4,200,0.00115705712232739,-4.54221534729004,0.75281023979187,1,,,,,,,,,,,,,,,,

,3825561979.2004,1.801549077034,32368.232421875,,,6,,,,25.9127864837646,,,100,,,,,,,,,,,,,,,,,,,,,,1.79798007011414,1.80190896987915,32368.232421875,32368.232421875,,,2.35051560401917,-99999999,1,0,0,0,0.0145721435546875,33.7243423461914,1,1,1,1.80118918418884,0,1816138880,1.8002211689949,,,0.110977208712128,0.00549872456777956,0.110990583188289,0.00549874929814407,0.959403276443481,0.962364554405212,25.8557720184326,0.187585040926933,30,4,200,0.00118212751112878,-4.53073644638062,0.754889786243439,1,,,,,,,,,,,,,,,,

,3825562011.68163,1.80190235376358,30492.255859375,,,6,,,,25.9127864837646,,,100,,,,,,,,,,,,,,,,,,,,,,1.79798710346222,1.80216503143311,30492.255859375,30492.255859375,,,2.35063600540161,-99999999,1,0,0,0,0.0145721435546875,33.7243423461914,1,1,1,1.8013551235199,0,1816139040,1.8001472083005,,,0.110847614764488,0.00549230157514166,0.11086226840983,0.00549232398674469,0.959411919116974,0.962696254253387,25.8528823852539,0.187537476420403,30,4,200,0.00111856870353222,-4.53066158294678,0.747453987598419,1,,,,,,,,,,,,,,,,

,3825562043.31989,1.80207496881485,28672.158203125,,,6,,,,25.9127864837646,,,100,,,,,,,,,,,,,,,,,,,,,,1.79761826992035,1.80251801013947,28672.158203125,28672.158203125,,,2.35204100608826,-99999999,1,0,0,0,0.0145721435546875,33.2355842590332,1,1,1,1.80163192749023,0,1816138784,1.8002229495482,,,0.110717764451802,0.0054858652481241,0.110733765553236,0.00548589311834187,0.959414422512054,0.963003396987915,25.850284576416,0.187542915344238,30,4,200,0.00102050183340907,-4.53216886520386,0.750830471515656,1,,,,,,,,,,,,,,,,

,3825562075.2032,1.80168795585632,26908.40625,,,6,,,,25.9127864837646,,,100,,,,,,,,,,,,,,,,,,,,,,1.7980375289917,1.80216836929321,26908.40625,26908.40625,,,2.35178351402283,-99999999,1,0,0,0,0.0138092041015625,33.2355842590332,1,1,1,1.80120754241943,0,1816138752,1.80016312815926,,,0.110590481157806,0.00547958437374312,0.110607622793982,0.00547960919246584,0.959304690361023,0.963180959224701,25.8478546142578,0.187551558017731,30,4,200,0.000979714328423142,-4.5215892791748,0.741231441497803,1,,,,,,,,,,,,,,,,

,3825562107.32144,1.80161905288696,25200.3671875,,,6,,,,25.9127864837646,,,100,,,,,,,,,,,,,,,,,,,,,,1.7980043888092,1.80225133895874,25200.3671875,25200.3671875,,,2.35138559341431,-99999999,1,0,0,0,0.0145721435546875,33.7243423461914,1,1,1,1.80098676681519,0,1816139072,1.80021466016769,,,0.110419915734009,0.00547110891940822,0.110438105619592,0.00547114038701183,0.959411919116974,0.963531851768494,25.8460388183594,0.187543049454689,30,4,200,0.000865280802827328,-4.5148344039917,0.739733636379242,1,,,,,,,,,,,,,,,,

,3825562139.27675,1.80195879936218,23548.255859375,,,6,,,,25.9127864837646,,,100,,,,,,,,,,,,,,,,,,,,,,1.79788255691528,1.80236124992371,23548.255859375,23548.255859375,,,2.3513126373291,-99999999,1,0,0,0,0.0138092041015625,33.2355842590332,1,1,1,1.80155634880066,0,1816138816,1.8001881480217,,,0.110225382860838,0.00546144949033154,0.1102445179529,0.00546148391400057,0.959504902362823,0.963864386081696,25.8443088531494,0.187542468309402,30,4,200,0.000849970732815564,-4.50446128845215,0.736790597438812,1,,,,,,,,,,,,,,,,

,3825562171.34819,1.80185550451279,21952.212890625,,,6,,,,25.9127864837646,,,100,,,,,,,,,,,,,,,,,,,,,,1.79808223247528,1.80208718776703,21952.212890625,21952.212890625,,,2.34869265556335,-99999999,1,0,0,0,0.0145721435546875,33.2355842590332,1,1,1,1.80162382125854,0,1816138976,1.80013137513941,,,0.110034230091876,0.00545197062921348,0.110054031967877,0.00545200828415185,0.959540128707886,0.964063465595245,25.843132019043,0.187557324767113,30,4,200,0.00074743281584233,-4.49951219558716,0.732373416423798,1,,,,,,,,,,,,,,,,

[...]

,3825566314.96531,1.8016881942749,4731.84619140625,,,6,,,,25.9127864837646,,,100,,,,,,,,,,,,,,,,,,,,,,1.79851198196411,1.80189836025238,4731.84619140625,4731.84619140625,,,2.35592651367187,-99999999,1,0,0,0,0.0138092041015625,33.7243423461914,1,1,1,1.80147802829742,0,1816138752,1.80014565857974,,,0.086491988498178,0.0042846007582219,0.0864954002632936,0.00428460850420929,0.965116560459137,0.966211438179016,25.8802833557129,0.18749888241291,30,4,200,0.000900955230463296,-3.54260325431824,0.559522211551666,1,,,,,,,,,,,,,,,,

,3825566341.40222,1.80164217948914,5487.87353515625,,,6,,,,25.9127864837646,,,100,,,,,,,,,,,,,,,,,,,,,,1.79806613922119,1.80207765102386,5487.87353515625,5487.87353515625,,,2.35606145858765,-99999999,1,0,0,0,0.0138092041015625,33.7243423461914,1,1,1,1.80120670795441,0,1816138912,1.80010646039789,,,0.0916886083800421,0.00454207989636292,0.0916932011640994,0.00454208944924057,0.964785814285278,0.966174244880676,25.8760871887207,0.187494575977325,30,4,200,0.00101053866092116,-3.75517749786377,0.591967225074768,1,,,,,,,,,,,,,,,,

,3825566368.26569,1.80163949728012,6300.33447265625,,,6,,,,25.9127864837646,,,100,,,,,,,,,,,,,,,,,,,,,,1.7979793548584,1.80208206176758,6300.33447265625,6300.33447265625,,,2.35666418075562,-99999999,1,0,0,0,0.0138092041015625,33.2355842590332,1,1,1,1.80119693279266,0,1816138688,1.80016760392622,,,0.0958395803224378,0.00474777738000406,0.0958452655292349,0.00474778023432023,0.964385211467743,0.966071844100952,25.8721961975098,0.187480911612511,30,4,200,0.0010854055872187,-3.92664051055908,0.627856254577637,1,,,,,,,,,,,,,,,,

,3825566395.2484,1.80192452669144,7168.33251953125,,,6,,,,25.9127864837646,,,100,,,,,,,,,,,,,,,,,,,,,,1.79818546772003,1.8022243976593,7168.33251953125,7168.33251953125,,,2.35732650756836,-99999999,1,0,0,0,0.0145721435546875,33.2355842590332,1,1,1,1.80139827728271,0,1816139008,1.80014568025416,,,0.09908356674735,0.00490855635795212,0.0990908403813986,0.00490856585447179,0.963959276676178,0.965997576713562,25.8679981231689,0.187509581446648,30,4,200,0.00107545882929116,-4.05069875717163,0.645579874515533,1,,,,,,,,,,,,,,,,

,3825566424.22275,1.80175507068634,8092.2099609375,,,6,,,,25.9127864837646,,,100,,,,,,,,,,,,,,,,,,,,,,1.79830861091614,1.80213117599487,8092.2099609375,8092.2099609375,,,2.35662460327148,-99999999,1,0,0,0,0.0145721435546875,33.2355842590332,1,1,1,1.80137896537781,0,1816138560,1.80007206201553,,,0.101595372277286,0.00503307644316855,0.10160444066608,0.00503309480730651,0.963489949703217,0.965912163257599,25.8637657165527,0.187534138560295,30,4,200,0.00121633429080248,-4.15765714645386,0.667848408222199,1,,,,,,,,,,,,,,,,

,3825566452.13562,1.8016728758812,9072.4560546875,,,6,,,,25.9127864837646,,,100,,,,,,,,,,,,,,,,,,,,,,1.79818749427795,1.80205595493317,9072.4560546875,9072.4560546875,,,2.35719680786133,-99999999,1,0,0,0,0.0145721435546875,33.2355842590332,1,1,1,1.80128979682922,0,1816138944,1.80014558271928,,,0.103526408430641,0.00512883151980123,0.103537257004136,0.00512885509158649,0.963004887104034,0.965816497802734,25.8597621917725,0.18751522898674,30,4,200,0.0012242472730577,-4.23122310638428,0.674466669559479,1,,,,,,,,,,,,,,,,

,3825566480.62104,1.80178761482239,10108.2783203125,,,6,,,,25.9127864837646,,,100,,,,,,,,,,,,,,,,,,,,,,1.79830980300903,1.80189538002014,10108.2783203125,10108.2783203125,,,2.35633111000061,-99999999,1,0,0,0,0.0145721435546875,33.7243423461914,1,1,1,1.80167984962463,0,1816138784,1.80012678016316,,,0.105016981294013,0.00520277267734831,0.105029413130064,0.00520279452988005,0.962518632411957,0.965695440769196,25.8561916351318,0.187497392296791,30,4,200,0.00123708334285766,-4.29489469528198,0.692182779312134,1,,,,,,,,,,,,,,,,

,3825566510.23549,1.80158680677414,11200.5087890625,,,6,,,,25.9127864837646,,,100,,,,,,,,,,,,,,,,,,,,,,1.79809141159058,1.80183780193329,11200.5087890625,11200.5087890625,,,2.354416847229,-99999999,1,0,0,0,0.0145721435546875,33.7243423461914,1,1,1,1.80133581161499,0,1816138784,1.80017005205154,,,0.106168347439053,0.0052599148418692,0.106182309424363,0.00525993821526796,0.962002575397491,0.965503215789795,25.8530826568604,0.187518671154976,30,4,200,0.00124835828319192,-4.33385467529297,0.696298003196716,1,,,,,,,,,,,,,,,,

,3825566539.21433,1.80172175168991,12348.125,,,6,,,,25.9127864837646,,,100,,,,,,,,,,,,,,,,,,,,,,1.79817759990692,1.80222856998444,12348.125,12348.125,,,2.35708427429199,-99999999,1,0,0,0,0.0145721435546875,33.7243423461914,1,1,1,1.80121493339539,0,1816138976,1.8001828843897,,,0.10705892839896,0.00530411987621758,0.107074300230468,0.00530414392846111,0.961597204208374,0.965401351451874,25.8503322601318,0.187519520521164,30,4,200,0.00117181497626007,-4.37390613555908,0.701290428638458,1,,,,,,,,,,,,,,,,

,3825566568.50278,1.80177211761475,13552.4150390625,,,6,,,,25.9127864837646,,,100,,,,,,,,,,,,,,,,,,,,,,1.79799365997314,1.80223023891449,13552.4150390625,13552.4150390625,,,2.3568229675293,-99999999,1,0,0,0,0.0145721435546875,33.2355842590332,1,1,1,1.801313996315,0,1816138944,1.80016738718206,,,0.107762992194985,0.00533908735463996,0.107779639526009,0.005339111645553,0.961177885532379,0.965247631072998,25.8479385375977,0.187523603439331,30,4,200,0.00114316656254232,-4.4077296257019,0.711022794246674,1,,,,,,,,,,,,,,,,

,3825566599.05764,1.80193716287613,14812.34375,,,6,,,,25.9127864837646,,,100,,,,,,,,,,,,,,,,,,,,,,1.79845798015594,1.80222821235657,14812.34375,14812.34375,,,2.35526609420776,-99999999,1,0,0,0,0.014495849609375,33.2355842590332,1,1,1,1.80164611339569,0,1816139008,1.80014724081213,,,0.108317776976549,0.00536664381336135,0.108335639029666,0.00536667714656982,0.960841834545135,0.965122520923614,25.8460693359375,0.187535524368286,30,4,200,0.00106066616717726,-4.4317045211792,0.71258407831192,1,,,,,,,,,,,,,,,,

,3825566629.199,1.80188685655594,16128.3896484375,,,6,,,,25.9127864837646,,,100,,,,,,,,,,,,,,,,,,,,,,1.79785811901093,1.80246078968048,16128.3896484375,16128.3896484375,,,2.35547232627869,-99999999,1,0,0,0,0.0145721435546875,33.7243423461914,1,1,1,1.80153679847717,0,1816138784,1.80017851699482,,,0.108779088311755,0.00538956786278609,0.108797657101979,0.00538960410278199,0.960525155067444,0.964917302131653,25.8449726104736,0.187534287571907,30,4,200,0.00105194433126599,-4.44690990447998,0.718775928020477,1,,,,,,,,,,,,,,,,

,3825566659.51361,1.80169904232025,17500.2890625,,,6,,,,25.9127864837646,,,100,,,,,,,,,,,,,,,,,,,,,,1.79773640632629,1.80227482318878,17500.2890625,17500.2890625,,,2.35715532302856,-99999999,1,0,0,0,0.0138092041015625,33.2355842590332,1,1,1,1.80112326145172,0,1816139008,1.80019311471419,,,0.10915548232905,0.00540827309263127,0.109174252111035,0.00540829823542698,0.960262715816498,0.96471631526947,25.8442974090576,0.187520056962967,30,4,200,0.000970500172115862,-4.45708656311035,0.717156708240509,1,,,,,,,,,,,,,,,,

,3825566690.05347,1.80172592401505,18928.279296875,,,6,,,,25.9127864837646,,,100,,,,,,,,,,,,,,,,,,,,,,1.79813182353973,1.80188512802124,18928.279296875,18928.279296875,,,2.35727167129517,-99999999,1,0,0,0,0.0145721435546875,33.7243423461914,1,1,1,1.80156672000885,0,1816139072,1.80014639550989,,,0.109471502181393,0.00542396844351235,0.109490625328279,0.00542400740377731,0.960080444812775,0.964516580104828,25.8442630767822,0.187519863247871,30,4,200,0.00082437990931794,-4.47621202468872,0.72385436296463,1,,,,,,,,,,,,,,,,

,3825566720.91956,1.80189490318298,20412.453125,,,6,,,,25.9127864837646,,,100,,,,,,,,,,,,,,,,,,,,,,1.79803729057312,1.80231845378876,20412.453125,20412.453125,,,2.35505056381226,-99999999,1,0,0,0,0.0145721435546875,33.7243423461914,1,1,1,1.80147135257721,0,1816139072,1.80011562867598,,,0.109738016078697,0.00543720770715124,0.109756866555833,0.00543724055410267,0.959939658641815,0.964308738708496,25.8446235656738,0.187534108757973,30,4,200,0.000777143752202392,-4.48178339004517,0.731979787349701,1,,,,,,,,,,,,,,,,

,3825566752.10526,1.80190080404282,21952.2265625,,,6,,,,25.9127864837646,,,100,,,,,,,,,,,,,,,,,,,,,,1.79795670509338,1.80206966400146,21952.2265625,21952.2265625,,,2.35508823394775,-99999999,1,0,0,0,0.0145721435546875,33.7243423461914,1,1,1,1.80173194408417,0,1816138752,1.80011982267553,,,0.109968119670078,0.00544863705064078,0.109986471761627,0.00544866571792597,0.959794521331787,0.964031517505646,25.8454780578613,0.187539085745811,30,4,200,0.000587381247896701,-4.49801301956177,0.737866878509522,1,,,,,,,,,,,,,,,,

,3825566783.67603,1.80171418190002,23548.4453125,,,6,,,,25.9127864837646,,,100,,,,,,,,,,,,,,,,,,,,,,1.79797542095184,1.80216872692108,23548.4453125,23548.4453125,,,2.35773968696594,-99999999,1,0,0,0,0.0146484375,33.7243423461914,1,1,1,1.80125963687897,0,1816138784,1.80011476169933,,,0.110165589734219,0.00545843456787053,0.110183314670391,0.00545846152147341,0.959734082221985,0.963807284832001,25.8466758728027,0.187534391880035,30,4,200,0.000602924556005746,-4.50435400009155,0.730948746204376,1,,,,,,,,,,,,,,,,

,3825566815.45184,1.80160355567932,25200.443359375,,,6,,,,25.9127864837646,,,100,,,,,,,,,,,,,,,,,,,,,,1.79795670509338,1.80208969116211,25200.443359375,25200.443359375,,,2.35745692253113,-99999999,1,0,0,0,0.0145721435546875,33.2355842590332,1,1,1,1.80111742019653,0,1816139008,1.80014843290502,,,0.110352398628291,0.00546769740186506,0.110369484472855,0.00546773414052651,0.959712862968445,0.963567912578583,25.8483657836914,0.187527999281883,30,4,200,0.000431401131208986,-4.50827503204346,0.734603404998779,1,,,,,,,,,,,,,,,,

,3825566847.33472,1.80164647102356,26908.4296875,,,6,,,,25.9127864837646,,,100,,,,,,,,,,,,,,,,,,,,,,1.79768848419189,1.80187237262726,26908.4296875,26908.4296875,,,2.35798072814941,-99999999,1,0,0,0,0.0146484375,33.2355842590332,1,1,1,1.80142056941986,0,1816138784,1.80017304420471,,,0.110512095478502,0.00547561903518498,0.110528110100246,0.00547564988060294,0.959673345088959,0.963283360004425,25.8503112792969,0.187557712197304,30,4,200,0.00051175570115447,-4.51363468170166,0.737847149372101,1,,,,,,,,,,,,,,,,

,3825566880.19131,1.80191522836685,28672.51171875,,,6,,,,25.9127864837646,,,100,,,,,,,,,,,,,,,,,,,,,,1.79808497428894,1.80227875709534,28672.51171875,28672.51171875,,,2.35435652732849,-99999999,1,0,0,0,0.0145721435546875,33.2355842590332,1,1,1,1.80155169963837,0,1816139072,1.80013822425495,,,0.110655312662913,0.00548272270604702,0.110670076556931,0.00548274578256154,0.959631383419037,0.962964832782745,25.8526248931885,0.187524721026421,30,4,200,0.000364019710104913,-4.525465965271,0.734739363193512,1,,,,,,,,,,,,,,,,

,3825566913.15465,1.80197101831436,30492.509765625,,,6,,,,25.9127864837646,,,100,,,,,,,,,,,,,,,,,,,,,,1.79791986942291,1.80231869220734,30492.509765625,30492.509765625,,,2.35625147819519,-99999999,1,0,0,0,0.0145721435546875,33.7243423461914,1,1,1,1.80162334442139,0,1816138976,1.80013566667383,,,0.110789672688228,0.00548936606895287,0.110803062276319,0.00548938203380313,0.959687650203705,0.962723195552826,25.8553047180176,0.187548741698265,30,4,200,0.000338129815645516,-4.51939392089844,0.748024880886078,1,,,,,,,,,,,,,,,,

,3825566946.76097,1.80151033401489,32368.255859375,,,6,,,,25.9127864837646,,,100,,,,,,,,,,,,,,,,,,,,,,1.79768049716949,1.80189001560211,32368.255859375,32368.255859375,,,2.35630583763123,-99999999,1,0,0,0,0.0145721435546875,33.2355842590332,1,1,1,1.80113065242767,0,1816139072,1.80011157556014,,,0.110908982762917,0.00549527898866901,0.110921172264562,0.00549529746032758,0.959689617156982,0.96242105960846,25.8581619262695,0.187534332275391,30,4,200,0.000261445326032117,-4.53300714492798,0.741362690925598,1,,,,,,,,,,,,,,,,

,3825566980.45517,1.80155277252197,34300.4296875,,,6,,,,25.9127864837646,,,100,,,,,,,,,,,,,,,,,,,,,,1.79805934429169,1.80182564258575,34300.4296875,34300.4296875,,,2.35276651382446,-99999999,1,0,0,0,0.0145721435546875,33.2355842590332,1,1,1,1.80127990245819,0,1816139008,1.80010517077013,,,0.111021283610319,0.00550083974331019,0.111032115509626,0.00550085800706613,0.959711790084839,0.962119340896606,25.8614063262939,0.187568083405495,30,4,200,0.000223924522288144,-4.53383636474609,0.745427787303925,1,,,,,,,,,,,,,,,,

,3825567013.91299,1.80170297622681,36288.36328125,,,6,,,,25.9127864837646,,,100,,,,,,,,,,,,,,,,,,,,,,1.79784214496613,1.80230510234833,36288.36328125,36288.36328125,,,2.35484385490417,-99999999,1,0,0,0,0.0145721435546875,33.7243423461914,1,1,1,1.80110085010529,0,1816139008,1.80022225596688,,,0.11111899415427,0.00550568799129522,0.111128511627596,0.00550570512674142,0.959683835506439,0.961782515048981,25.8647193908691,0.187524542212486,30,4,200,0.000231367841479369,-4.53226041793823,0.754750311374664,1,,,,,,,,,,,,,,,,

,3825567047.54662,1.80167365074158,38332.4375,,,6,,,,25.9127864837646,,,100,,,,,,,,,,,,,,,,,,,,,,1.7979154586792,1.80182290077209,38332.4375,38332.4375,,,2.35578393936157,-99999999,1,0,0,0,0.0145721435546875,32.7468223571777,1,1,1,1.80152440071106,0,1816138944,1.80013585090637,,,0.111225871945351,0.00551099601994109,0.111234062336551,0.00551100893855439,0.959615111351013,0.961417853832245,25.8681125640869,0.187540620565414,30,4,200,6.78701180731878E-5,-4.54302549362183,0.750783264636993,1,,,,,,,,,,,,,,,,

,3825567081.50174,1.80179196596146,40432.28515625,,,6,,,,25.9127864837646,,,100,,,,,,,,,,,,,,,,,,,,,,1.79792964458466,1.80232965946198,40432.28515625,40432.28515625,,,2.35463976860046,-99999999,1,0,0,0,0.0145721435546875,32.7468223571777,1,1,1,1.80125427246094,0,1816139008,1.80017325011167,,,0.111323425759735,0.00551585717325198,0.111330046986064,0.00551586616482132,0.959499835968018,0.960951864719391,25.8725509643555,0.18753382563591,30,4,200,5.56912018510047E-5,-4.54453945159912,0.756273448467255,1,,,,,,,,,,,,,,,,

,3825567115.72898,1.80171513557434,42588.359375,,,6,,,,25.9127864837646,,,100,,,,,,,,,,,,,,,,,,,,,,1.79787707328796,1.8020852804184,42588.359375,42588.359375,,,2.35323882102966,-99999999,1,0,0,0,0.0138092041015625,33.2355842590332,1,1,1,1.80134499073029,0,1816138656,1.80016436360099,,,0.111414331989985,0.0055203650496809,0.111419841535997,0.00552037101844289,0.959476470947266,0.960686266422272,25.8760013580322,0.187517806887627,30,4,200,0.000202778013772331,-4.54466009140015,0.751588523387909,1,,,,,,,,,,,,,,,,

,3825567150.46052,1.8018416762352,44800.4609375,,,6,,,,25.9127864837646,,,100,,,,,,,,,,,,,,,,,,,,,,1.79789412021637,1.80217313766479,44800.4609375,44800.4609375,,,2.35479950904846,-99999999,1,0,0,0,0.0145721435546875,33.2355842590332,1,1,1,1.8015102148056,0,1816138880,1.80015206336975,,,0.111504799351808,0.00552487231002477,0.111509132726445,0.00552487782039255,0.959362089633942,0.960303246974945,25.8802394866943,0.187533870339394,30,4,200,-8.57724662637338E-5,-4.54606914520264,0.75505805015564,1,,,,,,,,,,,,,,,,

,3825567185.34949,1.80196094512939,47068.375,,,6,,,,25.9127864837646,,,100,,,,,,,,,,,,,,,,,,,,,,1.79798269271851,1.80245292186737,47068.375,47068.375,,,2.35226440429687,-99999999,1,0,0,0,0.0145721435546875,33.2355842590332,1,1,1,1.80146896839142,0,1816138720,1.80017274076288,,,0.111579418870706,0.00552864180985069,0.111582738949043,0.00552864464880972,0.959053695201874,0.959772944450378,25.8841876983643,0.18755054473877,30,4,200,-0.000168621554621495,-4.54648590087891,0.760068953037262,1,,,,,,,,,,,,,,,,

,3825567220.48663,1.80190932750702,49392.42578125,,,6,,,,25.9127864837646,,,100,,,,,,,,,,,,,,,,,,,,,,1.79791212081909,1.80222046375275,49392.42578125,49392.42578125,,,2.3522584438324,-99999999,1,0,0,0,0.0145721435546875,32.7468223571777,1,1,1,1.80159819126129,0,1816139136,1.80012878504666,,,0.111671583814038,0.00553320706404716,0.11167383239977,0.00553320895922722,0.959052979946136,0.959538459777832,25.8892612457275,0.187524974346161,30,4,200,2.37300282606157E-5,-4.55579376220703,0.757260382175446,1,,,,,,,,,,,,,,,,

,3825567256.30519,1.80168402194977,51772.23046875,,,6,,,,25.9127864837646,,,100,,,,,,,,,,,,,,,,,,,,,,1.79736375808716,1.80236089229584,51772.23046875,51772.23046875,,,2.35528349876404,-99999999,1,0,0,0,0.0138092041015625,33.2355842590332,1,1,1,1.8010071516037,0,1816138912,1.80007484826175,,,0.111768998050497,0.00553812416210948,0.111770403923066,0.00553812490984438,0.958661556243896,0.95896315574646,25.894136428833,0.187535151839256,30,4,200,5.73013930988964E-5,-4.55661392211914,0.766677796840668,1,,,,,,,,,,,,,,,,

,3825567292.63787,1.80178689956665,54208.2109375,,,6,,,,25.9127864837646,,,100,,,,,,,,,,,,,,,,,,,,,,1.79781770706177,1.80219638347626,54208.2109375,54208.2109375,,,2.35316467285156,-99999999,1,0,0,0,0.0145721435546875,33.2355842590332,1,1,1,1.80137741565704,0,1816139104,1.80013378099962,,,0.111851835924246,0.00554228758872524,0.111852596393726,0.00554228696177148,0.958404183387756,0.958570420742035,25.8988876342773,0.187544211745262,30,4,200,0.000126536237075925,-4.55610418319702,0.771063983440399,1,,,,,,,,,,,,,,,,

,3825567329.61815,1.80156874656677,56700.20703125,,,6,,,,25.9127864837646,,,100,,,,,,,,,,,,,,,,,,,,,,1.79807937145233,1.80219340324402,56700.20703125,56700.20703125,,,2.35392284393311,-99999999,1,0,0,0,0.0145721435546875,33.2355842590332,1,1,1,1.8012238740921,0,1816139104,1.80014837871898,,,0.111931535532351,0.00554632726907985,0.111931829414075,0.00554632689381357,0.958013117313385,0.958077192306519,25.9041118621826,0.187553882598877,30,4,200,-0.000154548761202022,-4.56022834777832,0.770768225193024,1,,,,,,,,,,,,,,,,

,3825567366.50717,1.80167758464813,59248.5,,,6,,,,25.9127864837646,,,100,,,,,,,,,,,,,,,,,,,,,,1.79780519008636,1.80222117900848,59248.5,59248.5,,,2.35522150993347,-99999999,1,0,0,0,0.0145721435546875,32.7468223571777,1,1,1,1.80113399028778,0,1816138912,1.80013769323176,,,0.111991576229295,0.00554938146796703,0.111991619386736,0.00554938127249424,0.957678973674774,0.957688927650452,25.9093570709229,0.187550619244575,30,4,200,0.000325393310049549,-4.56333494186401,0.773642420768738,1,,,,,,,,,,,,,,,,

,3825567403.64457,1.80177336931229,61852.2734375,,,6,,,,25.9127864837646,,,100,,,,,,,,,,,,,,,,,,,,,,1.7986968755722,1.80229997634888,61852.2734375,61852.2734375,,,2.35450291633606,-99999999,1,0,0,0,0.0138092041015625,33.2355842590332,1,1,1,1.8012467622757,0,1816139072,1.8002752607519,,,0.112054851231389,0.00555262348683066,0.11205487766753,0.00555262394868811,0.957224130630493,0.95722770690918,25.914852142334,0.187548205256462,30,4,200,0.000250850629527122,-4.55795526504517,0.784570753574371,1,,,,,,,,,,,,,,,,

,3825567440.80078,1.80150300264359,64512.48828125,,,6,,,,25.9127864837646,,,100,,,,,,,,,,,,,,,,,,,,,,1.79810190200806,1.8019517660141,64512.48828125,64512.48828125,,,2.35485315322876,-99999999,1,0,0,0,0.0145721435546875,33.2355842590332,1,1,1,1.80105423927307,0,1816139040,1.80022804303603,,,0.112139688610929,0.00555697466105658,0.112139955953926,0.00555697603736128,0.956618547439575,0.956667721271515,25.9205112457275,0.18756391108036,30,4,200,0.000494590844027698,-4.56964635848999,0.780253231525421,1,,,,,,,,,,,,,,,,

,3825567478.46041,1.80167549848557,67228.3203125,,,6,,,,25.9127864837646,,,100,,,,,,,,,,,,,,,,,,,,,,1.7981231212616,1.80223608016968,67228.3203125,67228.3203125,,,2.35477375984192,-99999999,1,0,0,0,0.0138092041015625,33.2355842590332,1,1,1,1.80111491680145,0,1816139040,1.80011391639709,,,0.112216237784323,0.0055609010311167,0.112217037242288,0.00556090440978901,0.956069827079773,0.956218123435974,25.9262752532959,0.187564447522163,30,4,200,0.000374057475710288,-4.5660343170166,0.787139594554901,1,,,,,,,,,,,,,,,,

,3825567516.4054,1.8017275929451,70000.28125,,,6,,,,25.9127864837646,,,100,,,,,,,,,,,,,,,,,,,,,,1.79786491394043,1.80228531360626,70000.28125,70000.28125,,,2.35211229324341,-99999999,1,0,0,0,0.0145721435546875,33.2355842590332,1,1,1,1.80116987228394,0,1816138880,1.80013919960369,,,0.112284981741475,0.00556447768451555,0.112286722120118,0.00556448317102911,0.955378174781799,0.955703973770142,25.9329128265381,0.187569558620453,30,4,200,0.000595268851611763,-4.57210493087769,0.800304114818573,1,,,,,,,,,,,,,,,,