File: data/AP424/MH_hyst2_5.dat
[Header]
; MPMS3 Data File (default extension .dat)
; Copyright (c) 2007, Quantum Design, Inc. All rights reserved.
TITLE,
FILEOPENTIME,3826047547.4247,03/27/2021,10:59 pm
BYAPP,SQUID AC,0.9.1.0
INFO,MPMS3 Measurement Release 1.1.16 Build 347, MultiVu Release 2.3.3.2,APPNAME
INFO,0,MOMENT_UNITS
INFO,SC_AP424,SAMPLE_MATERIAL
INFO,capsule nujol,SAMPLE_COMMENT
INFO,1,SAMPLE_MASS
INFO,,SAMPLE_VOLUME
INFO,,SAMPLE_MOLECULAR_WEIGHT
INFO,,SAMPLE_SIZE
INFO,,SAMPLE_SHAPE
INFO,Standard,SAMPLE_HOLDER
INFO,Standard,SAMPLE_HOLDER_DETAIL
INFO,68.35,SAMPLE_OFFSET
DATATYPE,COMMENT,1
DATATYPE,TIME,2
STARTUPAXIS,X,2
STARTUPAXIS,Y1,5
FIELDGROUP, VSM,2,3,4,5,6,8,9,10,11,14,15
FIELDGROUP, DC, 2,3,4,14,56,57,58,59,60,61,62,63,64,65,66,67,68,69
FIELDGROUP, AC, 2,3,4,11,16,17,18,19,20,21,22,23,24,25,26,27,28,29,30
STARTUPGROUP, All
[Data]
Comment,Time Stamp (sec),Temperature (K),Magnetic Field (Oe),Moment (emu),M. Std. Err. (emu),Transport Action,Averaging Time (sec),Frequency (Hz),Peak Amplitude (mm),Center Position (mm),Lockin Signal' (V),Lockin Signal (V),Range,M. Quad. Signal (emu),AC Moment (emu),AC M. Std Err. (emu),AC Phase (deg),AC Phase Std. Err. (deg),AC Susceptibility (emu/Oe),AC Suscept. Std Err. (emu/Oe),AC X' (emu/Oe),AC X' Std Err. (emu/Oe),AC X'' (emu/Oe),AC X'' Std Err. (emu/Oe),AC Drive (Oe),AC Frequency (Hz),AC Averaging Time (sec),AC Cycles,AC Range,AC Measure Type,AC Signal' (V),AC Signal'' (V),AC Trim Coil Ratio,AC Trim Coil Phase,Min. Temperature (K),Max. Temperature (K),Min. Field (Oe),Max. Field (Oe),Mass (grams),Motor Lag (deg),Pressure (Torr),Measure Count,Measurement Number,SQUID Status (code),Motor Status (code),Measure Status (code),Motor Current (amps),Motor Temp. (C),Temp. Status (code),Field Status (code),Chamber Status (code),Chamber Temp (K),Redirection State,Evercool Status,Average Temp (K),Rotation Angle (deg),Rotator state,DC Moment Fixed Ctr (emu),DC Moment Err Fixed Ctr (emu),DC Moment Free Ctr (emu),DC Moment Err Free Ctr (emu),DC Fixed Fit,DC Free Fit,DC Calculated Center (mm),DC Calculated Center Err (mm),DC Scan Length (mm),DC Scan Time (s),DC Number of Points,DC Squid Drift,DC Min V (V),DC Max V (V),DC Scans per Measure,Map 01,Map 02,Map 03,Map 04,Map 05,Map 06,Map 07,Map 08,Map 09,Map 10,Map 11,Map 12,Map 13,Map 14,Map 15,Map 16
,3826048067.85423,2.50185668468475,-0.403362572193146,,,6,,,,26.0463790893555,,,1,,,,,,,,,,,,,,,,,,,,,,2.49832057952881,2.50265026092529,-0.403362572193146,-0.403362572193146,,,2.76058197021484,-99999999,1,0,0,0,0.018463134765625,33.7243423461914,1,1,1,2.50106310844421,0,1816139168,2.50017174084981,,,3.29223456003507E-5,1.63052277762976E-6,3.29270149751327E-5,1.63053307398348E-6,0.972345530986786,0.977775454521179,25.9842128753662,0.187446519732475,30,4,200,2.79570303973742E-5,0.0016453267307952,0.32334578037262,1,,,,,,,,,,,,,,,,
,3826048119.53899,2.50211584568024,49.9035148620605,,,6,,,,26.0463790893555,,,1,,,,,,,,,,,,,,,,,,,,,,2.49843215942383,2.50232338905334,49.9035148620605,49.9035148620605,,,2.76363325119019,-99999999,1,0,0,0,0.017242431640625,33.7243423461914,1,1,1,2.50138711929321,0,1816139136,2.50022348490628,,,0.000986592729820054,4.88474963079517E-5,0.000986615403006085,4.88475641913539E-5,0.987422227859497,0.989275097846985,26.0215854644775,0.187388673424721,30,4,200,0.00166310160420835,-3.83053421974182,0.803193926811218,1,,,,,,,,,,,,,,,,
,3826048178.58395,2.50185668468475,199.866149902344,,,6,,,,26.0463790893555,,,10,,,,,,,,,,,,,,,,,,,,,,2.49836492538452,2.50216364860535,199.866149902344,199.866149902344,,,2.76806402206421,-99999999,1,0,0,0,0.018463134765625,33.2355842590332,1,1,1,2.50154972076416,0,1816139168,2.50027585029602,,,0.00381870759834723,0.000189068828891095,0.00381878774928908,0.000189069030038222,0.987578749656677,0.989302158355713,26.0225639343262,0.187375262379646,30,4,200,0.000497347326017916,-1.5753265619278,0.217635557055473,1,,,,,,,,,,,,,,,,
,3826048226.99343,2.50150668621063,449.799682617188,,,6,,,,26.0463790893555,,,10,,,,,,,,,,,,,,,,,,,,,,2.49844646453857,2.50222659111023,449.799682617188,449.799682617188,,,2.7695906162262,-99999999,1,0,0,0,0.0138092041015625,33.2355842590332,1,1,1,2.50078678131104,0,1816138944,2.50022519718517,,,0.00847023645644136,0.000419370266219867,0.00847040785379762,0.000419370636295432,0.987817943096161,0.989526093006134,26.0229091644287,0.187371954321861,30,4,200,0.000307129521388561,-3.49640846252441,0.47792711853981,1,,,,,,,,,,,,,,,,
,3826048280.81387,2.50185751914978,799.792358398438,,,6,,,,26.0463790893555,,,100,,,,,,,,,,,,,,,,,,,,,,2.49840259552002,2.50249791145325,799.792358398438,799.792358398438,,,2.7733678817749,-99999999,1,0,0,0,0.01983642578125,32.7468223571777,1,1,1,2.50121712684631,0,1816139008,2.50019124576024,,,0.0147124839818676,0.000728432619600781,0.0147127719158318,0.000728433109539375,0.987577319145203,0.989205002784729,26.0231857299805,0.187376126646996,30,4,200,-0.00047835340956226,-4.86666059494019,4.89960432052612,1,,,,,,,,,,,,,,,,
,3826048335.20835,2.50131392478943,1249.55419921875,,,6,,,,26.0463790893555,,,100,,,,,,,,,,,,,,,,,,,,,,2.49835538864136,2.50204730033874,1249.55419921875,1249.55419921875,,,2.77506351470947,-99999999,1,0,0,0,0.01922607421875,33.2355842590332,1,1,1,2.50058054924011,0,1816138880,2.50019188360734,,,0.0220994971279772,0.00109421871853232,0.0220998985289455,0.00109421927355426,0.98455947637558,0.985748469829559,26.0239601135254,0.187392592430115,30,4,200,-0.00154463003855199,-0.913227021694183,0.133031100034714,1,,,,,,,,,,,,,,,,
,3826048384.97271,2.50227475166321,1799.63989257813,,,6,,,,26.0463790893555,,,100,,,,,,,,,,,,,,,,,,,,,,2.49865818023682,2.5028235912323,1799.63989257813,1799.63989257813,,,2.77569675445557,-99999999,1,0,0,0,0.0202178955078125,33.2355842590332,1,1,1,2.50172591209412,0,1816137728,2.5002911307595,,,0.0318814899430432,0.00157850882290046,0.0318820955664992,0.00157851041735825,0.986693680286407,0.988121747970581,26.0237522125244,0.187386050820351,30,4,200,-1.6878375390661E-5,-1.30818545818329,0.193099170923233,1,,,,,,,,,,,,,,,,
,3826048434.4731,2.50149464607239,2450.30151367187,,,6,,,,26.0463790893555,,,100,,,,,,,,,,,,,,,,,,,,,,2.49866437911987,2.50226879119873,2450.30151367187,2450.30151367187,,,2.77561855316162,-99999999,1,0,0,0,0.0183868408203125,33.7243423461914,1,1,1,2.50072050094604,0,1816138912,2.50021028518677,,,0.042695286934758,0.00211389026636109,0.0426961353747722,0.00211389173724679,0.987751424312592,0.989432096481323,26.0230178833008,0.187371492385864,30,4,200,0.000420390046201646,-1.74454367160797,0.256085485219955,1,,,,,,,,,,,,,,,,
,3826048484.14517,2.50196182727814,3199.87524414063,,,6,,,,26.0463790893555,,,100,,,,,,,,,,,,,,,,,,,,,,2.49828791618347,2.50269341468811,3199.87524414063,3199.87524414063,,,2.7784526348114,-99999999,1,0,0,0,0.0185394287109375,33.2355842590332,1,1,1,2.50123023986816,0,1816139168,2.50031488591974,,,0.0532545191828466,0.00263670439886704,0.0532557645096989,0.00263670608636987,0.987306535243988,0.989246308803558,26.0209350585938,0.187380015850067,30,4,200,0.000590442214161158,-2.18329119682312,0.316273480653763,1,,,,,,,,,,,,,,,,
,3826048535.91973,2.50177812576294,4050.16357421875,,,6,,,,26.0463790893555,,,100,,,,,,,,,,,,,,,,,,,,,,2.49858832359314,2.50292706489563,4050.16357421875,4050.16357421875,,,2.77839803695679,-99999999,1,0,0,0,0.019073486328125,33.2355842590332,1,1,1,2.50062918663025,0,1816138816,2.50027017159895,,,0.0632765741302038,0.00313292743896941,0.0632784100460559,0.00313293236416875,0.986862778663635,0.989150524139404,26.0184326171875,0.18737967312336,30,4,200,0.000842790759634227,-2.59158205986023,0.378288477659225,1,,,,,,,,,,,,,,,,
,3826048587.19607,2.501953125,4999.994140625,,,6,,,,26.0463790893555,,,100,,,,,,,,,,,,,,,,,,,,,,2.49789905548096,2.5023250579834,4999.994140625,4999.994140625,,,2.77954339981079,-99999999,1,0,0,0,0.0183868408203125,33.2355842590332,1,1,1,2.5015811920166,0,1816138944,2.5001569444483,,,0.0723206119898241,0.00358073315928099,0.0723231014965974,0.00358073967287388,0.98643958568573,0.989105582237244,26.0159187316895,0.187381565570831,30,4,200,0.00087994965724647,-2.97008681297302,0.433055192232132,1,,,,,,,,,,,,,,,,
,3826048639.22462,2.50152444839478,4050.31494140625,,,6,,,,26.0463790893555,,,100,,,,,,,,,,,,,,,,,,,,,,2.49852299690247,2.50191164016724,4050.31494140625,4050.31494140625,,,2.780606508255,-99999999,1,0,0,0,0.0177764892578125,33.2355842590332,1,1,1,2.501225233078,0,1816139008,2.50022415681319,,,0.0631584003326842,0.00312706957068457,0.0631600836430427,0.00312707197115026,0.987010776996613,0.989185214042664,26.0192356109619,0.187379509210587,30,4,200,-0.00122466601897031,-2.59900450706482,0.374833136796951,1,,,,,,,,,,,,,,,,
,3826048690.31332,2.50187706947327,3200.07690429687,,,6,,,,26.0463790893555,,,100,,,,,,,,,,,,,,,,,,,,,,2.49865174293518,2.50249099731445,3200.07690429687,3200.07690429687,,,2.78234672546387,-99999999,1,0,0,0,0.0203704833984375,33.2355842590332,1,1,1,2.50126314163208,0,1816138912,2.50029706954956,,,0.0530028747371408,0.00262424352888639,0.053004081291487,0.0026242449296589,0.987330257892609,0.989226520061493,26.0212249755859,0.187370523810387,30,4,200,-2.61689965554979E-5,-2.178546667099,0.31670406460762,1,,,,,,,,,,,,,,,,
,3826048739.52003,2.50158941745758,2450.41479492187,,,6,,,,26.0463790893555,,,100,,,,,,,,,,,,,,,,,,,,,,2.49838352203369,2.50222063064575,2450.41479492187,2450.41479492187,,,2.78122520446777,-99999999,1,0,0,0,0.0188446044921875,33.2355842590332,1,1,1,2.50095820426941,0,1816139200,2.5002273646268,,,0.0425917472514597,0.00210877561910003,0.0425925921223546,0.00210877671828201,0.987296462059021,0.988920509815216,26.0229301452637,0.187385305762291,30,4,200,4.9934158596443E-5,-1.75002753734589,0.254006206989288,1,,,,,,,,,,,,,,,,
,3826048789.02741,2.50185108184814,1800.24499511719,,,6,,,,26.0463790893555,,,100,,,,,,,,,,,,,,,,,,,,,,2.49800586700439,2.50224471092224,1800.24499511719,1800.24499511719,,,2.78113532066345,-99999999,1,0,0,0,0.0182342529296875,33.2355842590332,1,1,1,2.50145745277405,0,1816139072,2.50031458247792,,,0.0327373041474656,0.00162089404993006,0.032737875259221,0.00162089526006092,0.986105263233185,0.987363874912262,26.0245761871338,0.187386333942413,30,4,200,-1.662848808337E-5,-1.35431027412415,0.197154462337494,1,,,,,,,,,,,,,,,,
,3826048837.07722,2.50199866294861,1250.033203125,,,6,,,,26.0463790893555,,,100,,,,,,,,,,,,,,,,,,,,,,2.49858069419861,2.50256276130676,1250.033203125,1250.033203125,,,2.78296732902527,-99999999,1,0,0,0,0.0185394287109375,33.2355842590332,1,1,1,2.50143456459045,0,1816138976,2.50042202255943,,,0.0237697739995383,0.0011769386887744,0.0237701206397094,0.00117693944468528,0.983534336090088,0.984403789043427,26.0264568328857,0.187398970127106,30,4,200,-6.14528762525879E-5,-0.981950283050537,0.145701080560684,1,,,,,,,,,,,,,,,,
,3826048884.95127,2.50203287601471,800.372192382813,,,6,,,,26.0463790893555,,,100,,,,,,,,,,,,,,,,,,,,,,2.49846243858337,2.5029125213623,800.372192382813,800.372192382813,,,2.78571915626526,-99999999,1,0,0,0,0.0191497802734375,33.2355842590332,1,1,1,2.50115323066711,0,1816139040,2.50034882805564,,,0.0153601616100888,0.000760550448626596,0.0153603922773006,0.000760551031290617,0.983062267303467,0.983925402164459,26.026237487793,0.187391698360443,30,4,200,0.000777735665906221,-0.63446706533432,0.0964318439364433,1,,,,,,,,,,,,,,,,
,3826048933.86387,2.50234019756317,450.102203369141,,,6,,,,26.0463790893555,,,100,,,,,,,,,,,,,,,,,,,,,,2.4982054233551,2.50275874137878,450.102203369141,450.102203369141,,,2.78683710098267,-99999999,1,0,0,0,0.0200653076171875,33.7243423461914,1,1,1,2.50192165374756,0,1816138848,2.50032353401184,,,0.00807155498782688,0.000399636118944038,0.0080717461385514,0.000399636603750102,0.986842393875122,0.988677799701691,26.0210876464844,0.187401801347733,30,4,200,0.00214685103856027,-0.331421315670013,0.0510832779109478,1,,,,,,,,,,,,,,,,
,3826048981.86192,2.50199961662292,200.168670654297,,,6,,,,26.0463790893555,,,100,,,,,,,,,,,,,,,,,,,,,,2.49841618537903,2.50252389907837,200.168670654297,200.168670654297,,,2.78729224205017,-99999999,1,0,0,0,0.0182342529296875,33.2355842590332,1,1,1,2.50154066085815,0,1816138880,2.50035992535678,,,0.00335426477281365,0.000166091363739552,0.00335443514089456,0.000166091683313367,0.980833232402802,0.983578562736511,26.0091018676758,0.187394872307777,30,4,200,0.00377766834571958,-0.134970411658287,0.0296819247305393,1,,,,,,,,,,,,,,,,
,3826049040.1929,2.50193166732788,50.2186393737793,,,6,,,,26.0463790893555,,,10,,,,,,,,,,,,,,,,,,,,,,2.49858379364014,2.50286340713501,50.2186393737793,50.2186393737793,,,2.79015254974365,-99999999,1,0,0,0,0.019073486328125,33.2355842590332,1,1,1,2.50099992752075,0,1816138784,2.50036332824013,,,0.000554533201731788,2.76977262342591E-5,0.000555040118112207,2.76989267328192E-5,0.867490112781525,0.874114334583282,25.8896255493164,0.189042136073112,30,4,200,0.0518854819238186,-0.145752653479576,0.251241207122803,1,,,,,,,,,,,,,,,,
,3826049088.2474,2.50207281112671,0.100840643048286,,,6,,,,26.0463790893555,,,10,,,,,,,,,,,,,,,,,,,,,,2.49823832511902,2.50230169296265,0.100840643048286,0.100840643048286,,,2.78707194328308,-99999999,1,0,0,0,0.0194549560546875,33.2355842590332,1,1,1,2.50131845474243,0,1816139040,2.50027756257491,,,-0.000405775615948659,2.02923957835517E-5,-0.000405979698943432,2.02928988752774E-5,0.858730435371399,0.862088203430176,26.1637687683105,0.189249411225319,30,4,200,0.0484358966350555,-0.0465530008077621,0.265782564878464,1,,,,,,,,,,,,,,,,
,3826049135.43041,2.5016907453537,-49.701831817627,,,6,,,,26.0463790893555,,,10,,,,,,,,,,,,,,,,,,,,,,2.49865627288818,2.50194954872131,-49.701831817627,-49.701831817627,,,2.78978991508484,-99999999,1,0,0,0,0.018768310546875,33.2355842590332,1,1,1,2.50161862373352,0,1816138976,2.50019699876959,,,-0.00132314737731636,6.56507620429987E-5,-0.00132323173793523,6.56509935489817E-5,0.933531284332275,0.934439659118652,26.0879020690918,0.187762901186943,30,4,200,0.0598274208605289,-0.02698028460145,0.699211418628693,1,,,,,,,,,,,,,,,,
,3826049183.73065,2.50160801410675,-200.055221557617,,,6,,,,26.0463790893555,,,10,,,,,,,,,,,,,,,,,,,,,,2.49847531318665,2.50208830833435,-200.055221557617,-200.055221557617,,,2.78953242301941,-99999999,1,0,0,0,0.01922607421875,33.2355842590332,1,1,1,2.50153541564941,0,1816139008,2.50023831020702,,,-0.0041484291628294,0.000205399782966537,-0.00414845534739118,0.000205399837263647,0.985393464565277,0.985813438892365,26.0332508087158,0.18739365041256,30,4,200,0.0375074818730354,-0.264818698167801,1.83914577960968,1,,,,,,,,,,,,,,,,
,3826049231.67677,2.50139176845551,-450.203063964844,,,6,,,,26.0463790893555,,,10,,,,,,,,,,,,,,,,,,,,,,2.49863314628601,2.50206542015076,-450.203063964844,-450.203063964844,,,2.79084658622742,-99999999,1,0,0,0,0.015106201171875,33.2355842590332,1,1,1,2.50071811676025,0,1816138880,2.50018748370084,,,-0.00875993591061342,0.000433711553662676,-0.0087600717790415,0.000433711809316593,0.988225698471069,0.989569425582886,26.0257682800293,0.187382161617279,30,4,200,0.0148080745711923,-0.472114622592926,3.66661596298218,1,,,,,,,,,,,,,,,,
,3826049285.2737,2.50242781639099,-800.170471191406,,,6,,,,26.0463790893555,,,100,,,,,,,,,,,,,,,,,,,,,,2.49798274040222,2.50281715393066,-800.170471191406,-800.170471191406,,,2.79489183425903,-99999999,1,0,0,0,0.0201416015625,33.7243423461914,1,1,1,2.50203847885132,0,1816138944,2.500161193666,,,-0.0149630313957549,0.000740838367385266,-0.0149633347782937,0.000740838853712079,0.98749166727066,0.98917293548584,26.0227489471436,0.187370762228966,30,4,200,-3.83702717954293E-5,-4.87897872924805,4.85515117645264,1,,,,,,,,,,,,,,,,
,3826049339.49639,2.50164747238159,-1249.84411621094,,,6,,,,26.0463790893555,,,100,,,,,,,,,,,,,,,,,,,,,,2.49831914901733,2.50213766098022,-1249.84411621094,-1249.84411621094,,,2.79289293289185,-99999999,1,0,0,0,0.0182342529296875,33.2355842590332,1,1,1,2.50147008895874,0,1816138944,2.50026379932057,,,-0.0223034434264144,0.00110431931202607,-0.0223038841076379,0.00110432047579325,0.984412252902985,0.985662043094635,26.0233039855957,0.187394708395004,30,4,200,-0.000709892483428121,-0.139857262372971,0.915795564651489,1,,,,,,,,,,,,,,,,
,3826049387.92349,2.50182783603668,-1799.9423828125,,,6,,,,26.0463790893555,,,100,,,,,,,,,,,,,,,,,,,,,,2.4982750415802,2.50276565551758,-1799.9423828125,-1799.9423828125,,,2.793217420578,-99999999,1,0,0,0,0.018310546875,33.2355842590332,1,1,1,2.50089001655579,0,1816138912,2.50031609535217,,,-0.0319539207949436,0.00158209856631217,-0.0319544950598643,0.00158209961890086,0.986508131027222,0.987858176231384,26.0241832733154,0.187383472919464,30,4,200,-0.000930193695239723,-0.194714084267616,1.31177198886871,1,,,,,,,,,,,,,,,,
,3826049437.95453,2.5019416809082,-2450.5283203125,,,6,,,,26.0463790893555,,,100,,,,,,,,,,,,,,,,,,,,,,2.49846529960632,2.50229740142822,-2450.5283203125,-2450.5283203125,,,2.79329061508179,-99999999,1,0,0,0,0.0152587890625,33.2355842590332,1,1,1,2.50196194648743,0,1816138976,2.50028798796914,,,-0.0427313117977663,0.00211567247628143,-0.0427321381876462,0.00211567428970388,0.987818360328674,0.989443778991699,26.0234413146973,0.187385931611061,30,4,200,-0.00065273605287075,-0.258671164512634,1.74385261535645,1,,,,,,,,,,,,,,,,
,3826049488.23471,2.50163900852203,-3200.14013671875,,,6,,,,26.0463790893555,,,100,,,,,,,,,,,,,,,,,,,,,,2.49832367897034,2.50270390510559,-3200.14013671875,-3200.14013671875,,,2.78979134559631,-99999999,1,0,0,0,0.0177001953125,33.2355842590332,1,1,1,2.50113272666931,0,1816138816,2.50030088424683,,,-0.0532482548034847,0.00263639189375507,-0.0532494848814717,0.00263639457883988,0.987359404563904,0.989247024059296,26.0213069915771,0.187398910522461,30,4,200,-0.00061729020671919,-0.319619417190552,2.17955350875854,1,,,,,,,,,,,,,,,,
,3826049538.78093,2.50198340415955,-4050.3525390625,,,6,,,,26.0463790893555,,,100,,,,,,,,,,,,,,,,,,,,,,2.49840378761291,2.50236177444458,-4050.3525390625,-4050.3525390625,,,2.79287338256836,-99999999,1,0,0,0,0.018768310546875,33.2355842590332,1,1,1,2.50160503387451,0,1816138944,2.50010332194242,,,-0.0632658311343598,0.00313239196116775,-0.0632675706444013,0.00313239508049854,0.986945450305939,0.989163458347321,26.0189170837402,0.187370464205742,30,4,200,-0.00069218227872625,-0.384794920682907,2.59366488456726,1,,,,,,,,,,,,,,,,
,3826049589.59347,2.50185918807983,-5000.0947265625,,,6,,,,26.0463790893555,,,100,,,,,,,,,,,,,,,,,,,,,,2.49853801727295,2.50250792503357,-5000.0947265625,-5000.0947265625,,,2.79222679138184,-99999999,1,0,0,0,0.01983642578125,33.2355842590332,1,1,1,2.50171065330505,0,1816139104,2.50040041316639,,,-0.0722971956300556,0.00357957085356693,-0.0722996546578858,0.00357957820030069,0.986508190631866,0.9891317486763,26.0162200927734,0.187376484274864,30,4,200,-0.00083755305968225,-0.443129062652588,2.95866918563843,1,,,,,,,,,,,,,,,,
,3826049641.87776,2.50218784809113,-4050.41552734375,,,6,,,,26.0463790893555,,,100,,,,,,,,,,,,,,,,,,,,,,2.49838352203369,2.50259256362915,-4050.41552734375,-4050.41552734375,,,2.79375886917114,-99999999,1,0,0,0,0.0193023681640625,33.2355842590332,1,1,1,2.5017831325531,0,1816138720,2.50037381865761,,,-0.0631355976684273,0.00312593989842474,-0.0631372225452367,0.0031259418447852,0.987063765525818,0.989177525043487,26.0196437835693,0.18737505376339,30,4,200,0.00115545943845063,-0.380255967378616,2.59287047386169,1,,,,,,,,,,,,,,,,
,3826049691.41695,2.50157642364502,-3200.21557617188,,,6,,,,26.0463790893555,,,100,,,,,,,,,,,,,,,,,,,,,,2.4985020160675,2.50214982032776,-3200.21557617188,-3200.21557617188,,,2.79334425926209,-99999999,1,0,0,0,0.0202178955078125,33.2355842590332,1,1,1,2.50103735923767,0,1816139008,2.50034598870711,,,-0.0529817578635645,0.00262319626339929,-0.0529829833648457,0.00262320030375555,0.987388849258423,0.989235877990723,26.0215892791748,0.187374353408813,30,4,200,5.75869889871683E-5,-0.319866418838501,2.17429518699646,1,,,,,,,,,,,,,,,,
,3826049742.4053,2.50159132480621,-2450.31420898438,,,6,,,,26.0463790893555,,,100,,,,,,,,,,,,,,,,,,,,,,2.49841976165771,2.50208950042725,-2450.31420898438,-2450.31420898438,,,2.79311990737915,-99999999,1,0,0,0,0.0191497802734375,33.2355842590332,1,1,1,2.50121974945068,0,1816139040,2.50021050193093,,,-0.0425507369048335,0.00210674375266669,-0.0425515556575536,0.0021067448674563,0.987361669540405,0.988940715789795,26.0233001708984,0.187373369932175,30,4,200,-3.13316995743662E-5,-0.260895431041718,1.74694442749023,1,,,,,,,,,,,,,,,,
,3826049791.75699,2.50189614295959,-1800.09362792969,,,6,,,,26.0463790893555,,,100,,,,,,,,,,,,,,,,,,,,,,2.49839162826538,2.50213742256165,-1800.09362792969,-1800.09362792969,,,2.79383444786072,-99999999,1,0,0,0,0.0194549560546875,33.2355842590332,1,1,1,2.5016655921936,0,1816138976,2.50033025308089,,,-0.0327623480623618,0.00162214374915847,-0.0327629004721296,0.00162214446540675,0.985693216323853,0.98689079284668,26.0247573852539,0.187390774488449,30,4,200,4.01491306547541E-5,-0.199285179376602,1.35413873195648,1,,,,,,,,,,,,,,,,
,3826049840.61808,2.50169944763184,-1249.81884765625,,,6,,,,26.0463790893555,,,100,,,,,,,,,,,,,,,,,,,,,,2.49832439422607,2.50235152244568,-1249.81884765625,-1249.81884765625,,,2.79341340065002,-99999999,1,0,0,0,0.0197601318359375,33.2355842590332,1,1,1,2.50128841400146,0,1816139008,2.50019894946705,,,-0.0237280176154451,0.00117486907409334,-0.023728350881658,0.00117486969382596,0.983640074729919,0.984488129615784,26.026762008667,0.187395885586739,30,4,200,7.87736062193289E-5,-0.148672729730606,0.976943969726563,1,,,,,,,,,,,,,,,,
,3826049888.46152,2.50146269798279,-800.473022460937,,,6,,,,26.0463790893555,,,100,,,,,,,,,,,,,,,,,,,,,,2.49857831001282,2.5021288394928,-800.473022460937,-800.473022460937,,,2.79480123519897,-99999999,1,0,0,0,0.0189971923828125,33.2355842590332,1,1,1,2.50130581855774,0,1816138912,2.50024628639221,,,-0.0153268069953039,0.000758898522079424,-0.0153270254021649,0.000758898766134804,0.983105480670929,0.983950853347778,26.0264663696289,0.187380716204643,30,4,200,-0.00082528725033626,-0.100066497921944,0.629400372505188,1,,,,,,,,,,,,,,,,
,3826049936.61344,2.50174474716187,-450.278686523438,,,6,,,,26.0463790893555,,,100,,,,,,,,,,,,,,,,,,,,,,2.49869513511658,2.50220775604248,-450.278686523438,-450.278686523438,,,2.79529476165771,-99999999,1,0,0,0,0.01922607421875,33.7243423461914,1,1,1,2.50128173828125,0,1816138944,2.50031111457131,,,-0.00804611326670306,0.00039837613513372,-0.00804630057464303,0.00039837645949486,0.986896991729736,0.988740980625153,26.021089553833,0.187386780977249,30,4,200,-0.00211709085851908,-0.0553119592368603,0.325977891683578,1,,,,,,,,,,,,,,,,
,3826049984.53938,2.5020397901535,-199.979598999023,,,6,,,,26.0463790893555,,,100,,,,,,,,,,,,,,,,,,,,,,2.49827647209167,2.5026159286499,-199.979598999023,-199.979598999023,,,2.79503011703491,-99999999,1,0,0,0,0.0193023681640625,33.2355842590332,1,1,1,2.50212931632996,0,1816139072,2.50032678517428,,,-0.00332080971277162,0.000164433496177296,-0.00332098125993015,0.000164433918457036,0.981258273124695,0.984090745449066,26.00901222229,0.187408193945885,30,4,200,-0.00379095715470612,-0.0338030233979225,0.129044458270073,1,,,,,,,,,,,,,,,,
,3826050042.8041,2.5017226934433,-49.9161186218262,,,6,,,,26.0463790893555,,,10,,,,,,,,,,,,,,,,,,,,,,2.49837732315063,2.50237536430359,-49.9161186218262,-49.9161186218262,,,2.79773831367493,-99999999,1,0,0,0,0.02044677734375,33.2355842590332,1,1,1,2.50107002258301,0,1816138912,2.50019032304937,,,-0.000517434696381097,2.58722584510805E-5,-0.000517944546717209,2.58733479712366E-5,0.859828948974609,0.86659187078476,25.883358001709,0.189241155982018,30,4,200,-0.0524435453116894,-0.308746844530106,0.0680942609906197,1,,,,,,,,,,,,,,,,
,3826050091.09009,2.50128531455994,0.126050814986229,,,6,,,,26.0463790893555,,,10,,,,,,,,,,,,,,,,,,,,,,2.49826502799988,2.50214242935181,0.126050814986229,0.126050814986229,,,2.79500222206116,-99999999,1,0,0,0,0.021209716796875,32.7468223571777,1,1,1,2.50080466270447,0,1816139008,2.50027556852861,,,0.000441280427321148,2.20527704504813E-5,0.000441490708033424,2.20532337304694E-5,0.863592028617859,0.866910338401794,26.1608562469482,0.189143389463425,30,4,200,-0.0489459447562695,-0.344226032495499,-0.0243900697678328,1,,,,,,,,,,,,,,,,
,3826050139.46242,2.50135946273804,50.0043525695801,,,6,,,,26.0463790893555,,,10,,,,,,,,,,,,,,,,,,,,,,2.49848461151123,2.5022189617157,50.0043525695801,50.0043525695801,,,2.79697322845459,-99999999,1,0,0,0,0.0214385986328125,32.7468223571777,1,1,1,2.50089716911316,0,1816138912,2.50023187290538,,,0.00136145844494945,6.75583546848641E-5,0.00136156151085573,6.75586384065626E-5,0.932058393955231,0.933114171028137,26.0916194915771,0.187794610857964,30,4,200,-0.0610044002532959,-0.771615028381348,0.0322330705821514,1,,,,,,,,,,,,,,,,
,3826050187.47332,2.50196981430054,199.941787719727,,,6,,,,26.0463790893555,,,10,,,,,,,,,,,,,,,,,,,,,,2.498455286026,2.5025269985199,199.941787719727,199.941787719727,,,2.79776501655579,-99999999,1,0,0,0,0.01861572265625,33.2355842590332,1,1,1,2.50141263008118,0,1816138976,2.50027894973755,,,0.00417512368427443,0.000206724702801259,0.00417514474924939,0.000206724707596432,0.984375834465027,0.984700620174408,26.0344181060791,0.187374651432037,30,4,200,-0.0378128625452518,-1.82959043979645,0.1937485486269,1,,,,,,,,,,,,,,,,
,3826050235.39313,2.50189626216888,449.799682617188,,,6,,,,26.0463790893555,,,10,,,,,,,,,,,,,,,,,,,,,,2.49860763549805,2.50253534317017,449.799682617188,449.799682617188,,,2.7970986366272,-99999999,1,0,0,0,0.0205230712890625,33.2355842590332,1,1,1,2.5012571811676,0,1816139040,2.50027678229592,,,0.00877784631685676,0.000434598783009874,0.00877798890753416,0.000434599209150993,0.988110721111298,0.989472329616547,26.0255336761475,0.187380656599998,30,4,200,-0.0138269849121571,-3.64876675605774,0.501331210136414,1,,,,,,,,,,,,,,,,
,3826050289.0445,2.5017671585083,799.893188476563,,,6,,,,26.0463790893555,,,100,,,,,,,,,,,,,,,,,,,,,,2.49842691421509,2.50225186347961,799.893188476563,799.893188476563,,,2.80101871490479,-99999999,1,0,0,0,0.0206756591796875,33.7243423461914,1,1,1,2.50143647193909,0,1816139200,2.50015620958237,,,0.0149903483497455,0.000742189278851044,0.0149906275705823,0.000742189698389154,0.987691283226013,0.989258170127869,26.0237045288086,0.187373906373978,30,4,200,0.000135024369228631,-4.84161901473999,4.89508056640625,1,,,,,,,,,,,,,,,,
,3826050343.01315,2.5019416809082,1249.6171875,,,6,,,,26.0463790893555,,,100,,,,,,,,,,,,,,,,,,,,,,2.49866461753845,2.50245070457458,1249.6171875,1249.6171875,,,2.79898500442505,-99999999,1,0,0,0,0.0214385986328125,32.7468223571777,1,1,1,2.50143265724182,0,1816138880,2.50030569596724,,,0.0223177058897339,0.00110501947173956,0.0223181340518273,0.00110502018839607,0.984764575958252,0.986033797264099,26.0234088897705,0.187373459339142,30,4,200,0.000647496490273625,-0.917234122753143,0.138552069664001,1,,,,,,,,,,,,,,,,
,3826050391.83965,2.50163578987122,1799.58947753906,,,6,,,,26.0463790893555,,,100,,,,,,,,,,,,,,,,,,,,,,2.49837636947632,2.50235557556152,1799.58947753906,1799.58947753906,,,2.79816079139709,-99999999,1,0,0,0,0.0138092041015625,33.2355842590332,1,1,1,2.50091600418091,0,1816138944,2.50018447095698,,,0.0320238881254642,0.00158555747022968,0.0320244618879943,0.00158555856906055,0.986778020858765,0.988151848316193,26.0242366790771,0.187381684780121,30,4,200,0.000913540832698345,-1.31790709495544,0.190922051668167,1,,,,,,,,,,,,,,,,
,3826050441.50728,2.50178527832031,2450.35205078125,,,6,,,,26.0463790893555,,,100,,,,,,,,,,,,,,,,,,,,,,2.49845623970032,2.50244164466858,2450.35205078125,2450.35205078125,,,2.79816937446594,-99999999,1,0,0,0,0.018310546875,33.2355842590332,1,1,1,2.50112891197205,0,1816138848,2.50027663057501,,,0.0427493572648101,0.00211656522554792,0.0427501994309306,0.00211656856175163,0.987837433815002,0.989431858062744,26.0236663818359,0.187373161315918,30,4,200,0.00063429307192564,-1.74590539932251,0.257342875003815,1,,,,,,,,,,,,,,,,
,3826050491.67026,2.50208032131195,3199.97607421875,,,6,,,,26.0463790893555,,,100,,,,,,,,,,,,,,,,,,,,,,2.49822759628296,2.50246167182922,3199.97607421875,3199.97607421875,,,2.79582500457764,-99999999,1,0,0,0,0.0205230712890625,33.7243423461914,1,1,1,2.50169897079468,0,1816138816,2.5003512989391,,,0.0532669152216966,0.00263731464758556,0.0532681304136701,0.00263731788763323,0.987387657165527,0.98923397064209,26.0215930938721,0.187372758984566,30,4,200,0.000640369195025414,-2.18829154968262,0.321332991123199,1,,,,,,,,,,,,,,,,
,3826050542.23362,2.50177800655365,4050.17602539063,,,6,,,,26.0463790893555,,,100,,,,,,,,,,,,,,,,,,,,,,2.49817800521851,2.50221252441406,4050.17602539063,4050.17602539063,,,2.79853773117065,-99999999,1,0,0,0,0.02044677734375,33.7243423461914,1,1,1,2.50134348869324,0,1816138816,2.50023705309088,,,0.0632828207247392,0.00313323066913052,0.0632845480217196,0.0031332346491011,0.986995339393616,0.9891796708107,26.0191631317139,0.187379583716393,30,4,200,0.000651757116429508,-2.59278154373169,0.37772125005722,1,,,,,,,,,,,,,,,,
,3826050593.51245,2.5016028881073,5000.1708984375,,,6,,,,26.0463790893555,,,100,,,,,,,,,,,,,,,,,,,,,,2.498539686203,2.50279259681702,5000.1708984375,5000.1708984375,,,2.79729604721069,-99999999,1,0,0,0,0.0208282470703125,33.2355842590332,1,1,1,2.50100588798523,0,1816138592,2.50035413828763,,,0.0723112270453259,0.00358026466181091,0.0723136463343987,0.00358027113663206,0.986532628536224,0.989133358001709,26.0163688659668,0.187372639775276,30,4,200,0.000760900089517236,-2.96824193000793,0.434288710355759,1,,,,,,,,,,,,,,,,