File: data/AP424/MH_hyst3.dat
[Header]
; MPMS3 Data File (default extension .dat)
; Copyright (c) 2007, Quantum Design, Inc. All rights reserved.
TITLE,
FILEOPENTIME,3826043691.08919,03/27/2021,9:55 pm
BYAPP,SQUID AC,0.9.1.0
INFO,MPMS3 Measurement Release 1.1.16 Build 347, MultiVu Release 2.3.3.2,APPNAME
INFO,0,MOMENT_UNITS
INFO,SC_AP424,SAMPLE_MATERIAL
INFO,capsule nujol,SAMPLE_COMMENT
INFO,1,SAMPLE_MASS
INFO,,SAMPLE_VOLUME
INFO,,SAMPLE_MOLECULAR_WEIGHT
INFO,,SAMPLE_SIZE
INFO,,SAMPLE_SHAPE
INFO,Standard,SAMPLE_HOLDER
INFO,Standard,SAMPLE_HOLDER_DETAIL
INFO,68.35,SAMPLE_OFFSET
DATATYPE,COMMENT,1
DATATYPE,TIME,2
STARTUPAXIS,X,2
STARTUPAXIS,Y1,5
FIELDGROUP, VSM,2,3,4,5,6,8,9,10,11,14,15
FIELDGROUP, DC, 2,3,4,14,56,57,58,59,60,61,62,63,64,65,66,67,68,69
FIELDGROUP, AC, 2,3,4,11,16,17,18,19,20,21,22,23,24,25,26,27,28,29,30
STARTUPGROUP, All
[Data]
Comment,Time Stamp (sec),Temperature (K),Magnetic Field (Oe),Moment (emu),M. Std. Err. (emu),Transport Action,Averaging Time (sec),Frequency (Hz),Peak Amplitude (mm),Center Position (mm),Lockin Signal' (V),Lockin Signal (V),Range,M. Quad. Signal (emu),AC Moment (emu),AC M. Std Err. (emu),AC Phase (deg),AC Phase Std. Err. (deg),AC Susceptibility (emu/Oe),AC Suscept. Std Err. (emu/Oe),AC X' (emu/Oe),AC X' Std Err. (emu/Oe),AC X'' (emu/Oe),AC X'' Std Err. (emu/Oe),AC Drive (Oe),AC Frequency (Hz),AC Averaging Time (sec),AC Cycles,AC Range,AC Measure Type,AC Signal' (V),AC Signal'' (V),AC Trim Coil Ratio,AC Trim Coil Phase,Min. Temperature (K),Max. Temperature (K),Min. Field (Oe),Max. Field (Oe),Mass (grams),Motor Lag (deg),Pressure (Torr),Measure Count,Measurement Number,SQUID Status (code),Motor Status (code),Measure Status (code),Motor Current (amps),Motor Temp. (C),Temp. Status (code),Field Status (code),Chamber Status (code),Chamber Temp (K),Redirection State,Evercool Status,Average Temp (K),Rotation Angle (deg),Rotator state,DC Moment Fixed Ctr (emu),DC Moment Err Fixed Ctr (emu),DC Moment Free Ctr (emu),DC Moment Err Free Ctr (emu),DC Fixed Fit,DC Free Fit,DC Calculated Center (mm),DC Calculated Center Err (mm),DC Scan Length (mm),DC Scan Time (s),DC Number of Points,DC Squid Drift,DC Min V (V),DC Max V (V),DC Scans per Measure,Map 01,Map 02,Map 03,Map 04,Map 05,Map 06,Map 07,Map 08,Map 09,Map 10,Map 11,Map 12,Map 13,Map 14,Map 15,Map 16
,3826044250.29775,3.00211334228516,-0.226891458034515,,,6,,,,26.0463790893555,,,1,,,,,,,,,,,,,,,,,,,,,,2.99835133552551,3.0025737285614,-0.226891458034515,-0.226891458034515,,,3.02623867988586,-99999999,1,0,0,0,0.0202178955078125,33.2355842590332,1,1,1,3.00165295600891,0,1816139040,3.00011529241289,,,3.19375983862285E-5,1.5816374179674E-6,3.19412974949606E-5,1.58164492103507E-6,0.975098013877869,0.98004812002182,25.9901027679443,0.187422573566437,30,4,200,-1.18914349513943E-5,-0.0576202608644962,0.0937333032488823,1,,,,,,,,,,,,,,,,
,3826044302.08831,3.00197684764862,49.8909072875977,,,6,,,,26.0463790893555,,,1,,,,,,,,,,,,,,,,,,,,,,2.99851489067078,3.00261855125427,49.8909072875977,49.8909072875977,,,3.027498960495,-99999999,1,0,0,0,0.018157958984375,33.2355842590332,1,1,1,3.00133514404297,0,1816139168,3.00039692358537,,,0.000825764830666786,4.08846266117368E-5,0.000825781846797852,4.08846680171671E-5,0.98753696680069,0.989222884178162,26.022762298584,0.187380209565163,30,4,200,0.00153677118942142,-3.4652578830719,0.413800477981567,1,,,,,,,,,,,,,,,,
,3826044360.99583,3.00178813934326,199.866149902344,,,6,,,,26.0463790893555,,,10,,,,,,,,,,,,,,,,,,,,,,2.99847674369812,3.00200057029724,199.866149902344,199.866149902344,,,3.03401231765747,-99999999,1,0,0,0,0.020599365234375,33.2355842590332,1,1,1,3.00132322311401,0,1816138976,3.00024583122947,,,0.00319607410778839,0.000158241270386817,0.00319613483079886,0.000158241395467559,0.987664699554443,0.989241421222687,26.0236110687256,0.187397107481956,30,4,200,0.000439383060438558,-1.28225076198578,0.218183219432831,1,,,,,,,,,,,,,,,,
,3826044409.20456,3.00190830230713,449.85009765625,,,6,,,,26.0463790893555,,,10,,,,,,,,,,,,,,,,,,,,,,2.99850296974182,3.00264072418213,449.85009765625,449.85009765625,,,3.03572630882263,-99999999,1,0,0,0,0.01800537109375,33.2355842590332,1,1,1,3.00117588043213,0,1816139104,3.00034286759116,,,0.00713349510508788,0.000353187075261572,0.00713362239123399,0.000353187365155991,0.987784683704376,0.989268064498901,26.0243663787842,0.187388002872467,30,4,200,-0.000454468128737062,-2.93121910095215,0.41929966211319,1,,,,,,,,,,,,,,,,
,3826044462.68129,3.00205457210541,799.804931640625,,,6,,,,26.0463790893555,,,100,,,,,,,,,,,,,,,,,,,,,,2.99819135665894,3.00258231163025,799.804931640625,799.804931640625,,,3.03799247741699,-99999999,1,0,0,0,0.019989013671875,33.2355842590332,1,1,1,3.00127387046814,0,1816138880,3.00018811225891,,,0.0125959336444287,0.000623636372442475,0.0125961206019921,0.00062363653950894,0.988007307052612,0.989291131496429,26.0260124206543,0.187365114688873,30,4,200,-0.000673642556648701,-4.90350294113159,4.8821234703064,1,,,,,,,,,,,,,,,,
,3826044516.66645,3.00225973129272,1249.54162597656,,,6,,,,26.0463790893555,,,100,,,,,,,,,,,,,,,,,,,,,,2.99836754798889,3.00268507003784,1249.54162597656,1249.54162597656,,,3.03973388671875,-99999999,1,0,0,0,0.0180816650390625,33.2355842590332,1,1,1,3.00132822990417,0,1816138944,3.00029037215493,,,0.0194155797694742,0.000961277680823476,0.0194158473659681,0.00096127834430067,0.98852550983429,0.989729523658752,26.0270729064941,0.187366336584091,30,4,200,-0.00183661992195994,-0.803453743457794,0.108768455684185,1,,,,,,,,,,,,,,,,
,3826044565.07474,3.00172829627991,1799.6904296875,,,6,,,,26.0463790893555,,,100,,,,,,,,,,,,,,,,,,,,,,2.99855780601501,3.00239729881287,1799.6904296875,1799.6904296875,,,3.04210042953491,-99999999,1,0,0,0,0.0186920166015625,33.2355842590332,1,1,1,3.00105929374695,0,1816138912,3.00030662796714,,,0.0275383905136062,0.00136345080795773,0.0275388121767401,0.00136345154517298,0.988044142723084,0.989350855350494,26.0258750915527,0.187367022037506,30,4,200,-0.00063382217194885,-1.13601219654083,0.160903468728066,1,,,,,,,,,,,,,,,,
,3826044614.70069,3.00175046920776,2450.32690429687,,,6,,,,26.0463790893555,,,100,,,,,,,,,,,,,,,,,,,,,,2.99854755401611,3.00221252441406,2450.32690429687,2450.32690429687,,,3.04275321960449,-99999999,1,0,0,0,0.0182342529296875,33.2355842590332,1,1,1,3.00128841400146,0,1816138944,3.00030062415383,,,0.0366153244159155,0.00181286389296615,0.0366159426535288,0.00181286484678481,0.987768590450287,0.989188194274902,26.0248031616211,0.187358930706978,30,4,200,0.000176999979885295,-1.50085258483887,0.218220680952072,1,,,,,,,,,,,,,,,,
,3826044664.50138,3.00203251838684,3199.92578125,,,6,,,,26.0463790893555,,,100,,,,,,,,,,,,,,,,,,,,,,2.99870252609253,3.00250387191772,3199.92578125,3199.92578125,,,3.03976917266846,-99999999,1,0,0,0,0.019989013671875,33.2355842590332,1,1,1,3.00156116485596,0,1816139008,3.00035840814764,,,0.0460844639308837,0.00228169957704559,0.0460853591794805,0.00228170205655888,0.987500905990601,0.989065885543823,26.0235328674316,0.187376633286476,30,4,200,0.000558294937945902,-1.89125955104828,0.272577464580536,1,,,,,,,,,,,,,,,,
,3826044714.96504,3.00193440914154,4050.27709960937,,,6,,,,26.0463790893555,,,100,,,,,,,,,,,,,,,,,,,,,,2.99852108955383,3.00250864028931,4050.27709960937,4050.27709960937,,,3.04454803466797,-99999999,1,0,0,0,0.0189208984375,33.2355842590332,1,1,1,3.00136017799377,0,1816138912,3.0004094730724,,,0.055582265034486,0.00275195478840503,0.0555834727579209,0.00275195702838437,0.987261652946472,0.989025354385376,26.0219821929932,0.187382325530052,30,4,200,0.00064943777397275,-2.2793345451355,0.339622139930725,1,,,,,,,,,,,,,,,,
,3826044766.13568,3.00185585021973,5000.1201171875,,,6,,,,26.0463790893555,,,100,,,,,,,,,,,,,,,,,,,,,,2.99853873252869,3.00336074829102,5000.1201171875,5000.1201171875,,,3.04491424560547,-99999999,1,0,0,0,0.0177764892578125,33.2355842590332,1,1,1,3.00091576576233,0,1816793088,3.00040695884011,,,0.0646265416531337,0.00319976244706318,0.0646281847411795,0.00319976575145257,0.986958801746368,0.988986492156982,26.0200328826904,0.187378063797951,30,4,200,0.000845832342747599,-2.64531970024109,0.387815356254578,1,,,,,,,,,,,,,,,,
,3826044818.73534,3.00201416015625,4050.28930664063,,,6,,,,26.0463790893555,,,100,,,,,,,,,,,,,,,,,,,,,,2.99842572212219,3.00283145904541,4050.28930664063,4050.28930664063,,,3.04630446434021,-99999999,1,0,0,0,0.0193023681640625,33.7243423461914,1,1,1,3.00119686126709,0,1816139104,3.00034605373036,,,0.0554671661673121,0.00274625306585386,0.0554682945320472,0.00274625558973987,0.987362325191498,0.989005923271179,26.0228652954102,0.18738779425621,30,4,200,-0.00118628598283976,-2.28572750091553,0.328148752450943,1,,,,,,,,,,,,,,,,
,3826044869.20738,3.00236439704895,3200.27856445313,,,6,,,,26.0463790893555,,,100,,,,,,,,,,,,,,,,,,,,,,2.99857044219971,3.00273489952087,3200.27856445313,3200.27856445313,,,3.04572486877441,-99999999,1,0,0,0,0.0199127197265625,33.2355842590332,1,1,1,3.00199389457703,0,1816139168,3.00023930723017,,,0.045824358287535,0.00226881854115129,0.04582520632814,0.00226882092016246,0.987601161003113,0.989099502563477,26.0240879058838,0.187380507588387,30,4,200,-1.72431718965527E-5,-1.88403451442718,0.274998188018799,1,,,,,,,,,,,,,,,,
,3826044920.5479,3.00186622142792,2450.44018554687,,,6,,,,26.0463790893555,,,100,,,,,,,,,,,,,,,,,,,,,,2.99843192100525,3.0025908946991,2450.44018554687,2450.44018554687,,,3.04687976837158,-99999999,1,0,0,0,0.0186920166015625,33.2355842590332,1,1,1,3.00114154815674,0,1816138944,3.00034596703269,,,0.0362287671772172,0.00179372537677674,0.0362293762989184,0.00179372670001367,0.987770080566406,0.989163756370544,26.0249862670898,0.187392622232437,30,4,200,0.000535922008566558,-1.4846293926239,0.217704266309738,1,,,,,,,,,,,,,,,,
,3826044969.57004,3.001917719841,1800.38366699219,,,6,,,,26.0463790893555,,,100,,,,,,,,,,,,,,,,,,,,,,2.9986400604248,3.00247573852539,1800.38366699219,1800.38366699219,,,3.05013036727905,-99999999,1,0,0,0,0.021514892578125,32.7468223571777,1,1,1,3.00135970115662,0,1816138848,3.00038194656372,,,0.0272105203483648,0.0013472235065396,0.0272109499736253,0.00134722434445875,0.987699270248413,0.989000976085663,26.0256004333496,0.187375441193581,30,4,200,0.000552033015992492,-1.11677646636963,0.163777843117714,1,,,,,,,,,,,,,,,,
,3826045018.24258,3.00190365314484,1249.71801757812,,,6,,,,26.0463790893555,,,100,,,,,,,,,,,,,,,,,,,,,,2.99838089942932,3.00257420539856,1249.71801757812,1249.71801757812,,,3.0508439540863,-99999999,1,0,0,0,0.0180816650390625,33.2355842590332,1,1,1,3.00123310089111,0,1816138912,3.00029199773615,,,0.0191203664102466,0.00094667587594583,0.019120664875442,0.00094667629343986,0.987272500991821,0.988525807857513,26.025598526001,0.187382236123085,30,4,200,0.000569277792237699,-0.78984671831131,0.112250253558159,1,,,,,,,,,,,,,,,,
,3826045067.4686,3.00210273265839,800.18310546875,,,6,,,,26.0463790893555,,,100,,,,,,,,,,,,,,,,,,,,,,2.99856448173523,3.00293016433716,800.18310546875,800.18310546875,,,3.05132412910461,-99999999,1,0,0,0,0.018463134765625,33.2355842590332,1,1,1,3.00127530097961,0,1816138944,3.00038118795915,,,0.0122047038475866,0.000604271136655534,0.0122049378713607,0.000604272065401955,0.987350940704346,0.98883181810379,26.0239715576172,0.187371373176575,30,4,200,0.0013002083869651,-0.499751508235931,0.0755974128842354,1,,,,,,,,,,,,,,,,
,3826045115.57859,3.00196135044098,450.228271484375,,,6,,,,26.0463790893555,,,100,,,,,,,,,,,,,,,,,,,,,,2.9986355304718,3.0024139881134,450.228271484375,450.228271484375,,,3.05263781547546,-99999999,1,0,0,0,0.019378662109375,33.2355842590332,1,1,1,3.00150871276855,0,1816139008,3.00032524629073,,,0.00671575084442055,0.000332506753845604,0.00671591214707997,0.000332507176702214,0.987116098403931,0.989022374153137,26.0209369659424,0.187370821833611,30,4,200,0.00222821976058185,-0.276222854852676,0.0423055924475193,1,,,,,,,,,,,,,,,,
,3826045163.93932,3.00193822383881,200.143463134766,,,6,,,,26.0463790893555,,,100,,,,,,,,,,,,,,,,,,,,,,2.99846744537354,3.00256681442261,200.143463134766,200.143463134766,,,3.04982709884644,-99999999,1,0,0,0,0.0176239013671875,33.2355842590332,1,1,1,3.001309633255,0,1816138976,3.00029717792164,,,0.00280581858147917,0.00013893749327578,0.00280595890842779,0.000138937748430525,0.979655265808105,0.982178866863251,26.0093669891357,0.187407478690147,30,4,200,0.00370947504416108,-0.112370267510414,0.0264972802251577,1,,,,,,,,,,,,,,,,
,3826045222.08924,3.0022246837616,50.2312431335449,,,6,,,,26.0463790893555,,,10,,,,,,,,,,,,,,,,,,,,,,2.99858856201172,3.00298500061035,50.2312431335449,50.2312431335449,,,3.05576872825623,-99999999,1,0,0,0,0.020294189453125,33.7243423461914,1,1,1,3.00146436691284,0,1816138944,3.00033690712669,,,0.000463443509663067,2.31939701082967E-5,0.000463880943594145,2.31949391900907E-5,0.853543758392334,0.859703063964844,25.8869285583496,0.189412280917168,30,4,200,0.0516681596636772,-0.152948498725891,0.203659072518349,1,,,,,,,,,,,,,,,,
,3826045270.07293,3.00195395946503,0.113445729017258,,,6,,,,26.0463790893555,,,10,,,,,,,,,,,,,,,,,,,,,,2.99852085113525,3.00238442420959,0.113445729017258,0.113445729017258,,,3.05626893043518,-99999999,1,0,0,0,0.01922607421875,33.2355842590332,1,1,1,3.00152349472046,0,1816138880,3.00035810470581,,,-0.000340785210040266,1.71436303892592E-5,-0.000341128167190157,1.71444252043694E-5,0.822494089603424,0.827814042568207,26.2128505706787,0.190395995974541,30,4,200,0.0493991412222385,-0.015527437441051,0.266909897327423,1,,,,,,,,,,,,,,,,
,3826045316.92195,3.00234460830688,-49.8404884338379,,,6,,,,26.0463790893555,,,10,,,,,,,,,,,,,,,,,,,,,,2.998459815979,3.00287628173828,-49.8404884338379,-49.8404884338379,,,3.05560374259949,-99999999,1,0,0,0,0.019989013671875,33.2355842590332,1,1,1,3.00181293487549,0,1816138912,3.00032895261591,,,-0.00111063649725178,5.51786905690428E-5,-0.00111078290516557,5.51789811536548E-5,0.916217803955078,0.917731523513794,26.1066207885742,0.188027456402779,30,4,200,0.0614621341228485,-0.0501426309347153,0.63998955488205,1,,,,,,,,,,,,,,,,
,3826045364.8722,3.00217533111572,-200.042617797852,,,6,,,,26.0463790893555,,,10,,,,,,,,,,,,,,,,,,,,,,2.99839925765991,3.00273776054382,-200.042617797852,-200.042617797852,,,3.05303764343262,-99999999,1,0,0,0,0.0200653076171875,33.2355842590332,1,1,1,3.00161290168762,0,1816138912,3.00033734061501,,,-0.0034696833378442,0.000171795471192242,-0.00346969786908899,0.000171795509405018,0.98454087972641,0.98479950428009,26.0357494354248,0.187383711338043,30,4,200,0.0377446338534355,-0.223918780684471,1.55869770050049,1,,,,,,,,,,,,,,,,
,3826045413.14482,3.00171864032745,-450.177825927734,,,6,,,,26.0463790893555,,,10,,,,,,,,,,,,,,,,,,,,,,2.99837064743042,3.00197100639343,-450.177825927734,-450.177825927734,,,3.05725622177124,-99999999,1,0,0,0,0.0208282470703125,32.7468223571777,1,1,1,3.00146627426147,0,1816138816,3.00021958351135,,,-0.00738867101421984,0.000365819868796271,-0.00738877084070078,0.0003658201739227,0.988042056560516,0.989153683185577,26.0273818969727,0.187379971146584,30,4,200,0.0150320176035166,-0.408562809228897,3.09334015846252,1,,,,,,,,,,,,,,,,
,3826045467.05319,3.00216794013977,-800.1201171875,,,6,,,,26.0463790893555,,,100,,,,,,,,,,,,,,,,,,,,,,2.99827527999878,3.00248169898987,-800.1201171875,-800.1201171875,,,3.0573902130127,-99999999,1,0,0,0,0.0183868408203125,33.7243423461914,1,1,1,3.00185418128967,0,1816139104,3.00022884777614,,,-0.0128132068120287,0.000634393588247459,-0.0128134169344097,0.000634394306214172,0.988042831420898,0.989396095275879,26.0255317687988,0.187378630042076,30,4,200,-2.75441470876103E-5,-4.87631416320801,4.85770797729492,1,,,,,,,,,,,,,,,,
,3826045520.78519,3.00226402282715,-1249.80627441406,,,6,,,,26.0463790893555,,,100,,,,,,,,,,,,,,,,,,,,,,2.9985682964325,3.00270867347717,-1249.80627441406,-1249.80627441406,,,3.05853796005249,-99999999,1,0,0,0,0.0199127197265625,33.2355842590332,1,1,1,3.00181937217712,0,1816138848,3.00037481568076,,,-0.0195706727792261,0.000968959789840499,-0.0195709326265983,0.000968960042260936,0.988229513168335,0.989392757415772,26.0271301269531,0.187370151281357,30,4,200,6.71472953399643E-5,-0.122550487518311,0.802485048770905,1,,,,,,,,,,,,,,,,
,3826045569.86708,3.00226640701294,-1800.03076171875,,,6,,,,26.0463790893555,,,100,,,,,,,,,,,,,,,,,,,,,,2.99853134155273,3.00261569023132,-1800.03076171875,-1800.03076171875,,,3.05945730209351,-99999999,1,0,0,0,0.0188446044921875,33.2355842590332,1,1,1,3.00191712379456,0,1816138944,3.0003035068512,,,-0.0276434968470163,0.00136865402231598,-0.027643905172548,0.00136865480858006,0.988127529621124,0.989390313625336,26.0262794494629,0.187360346317291,30,4,200,-0.000310366769554094,-0.169625163078308,1.12628829479218,1,,,,,,,,,,,,,,,,
,3826045619.90139,3.00192391872406,-2450.47802734375,,,6,,,,26.0463790893555,,,100,,,,,,,,,,,,,,,,,,,,,,2.99862766265869,3.0026478767395,-2450.47802734375,-2450.47802734375,,,3.05945062637329,-99999999,1,0,0,0,0.019683837890625,33.2355842590332,1,1,1,3.00119996070862,0,1816138880,3.00031115792014,,,-0.0366390723941829,0.00181403880253202,-0.0366396699032807,0.00181403996692721,0.987828433513641,0.989191710948944,26.025260925293,0.187394306063652,30,4,200,-0.000378254015231505,-0.2212965041399,1.49864614009857,1,,,,,,,,,,,,,,,,
,3826045669.79432,3.00209033489227,-3200.12719726562,,,6,,,,26.0463790893555,,,100,,,,,,,,,,,,,,,,,,,,,,2.99853253364563,3.00243163108826,-3200.12719726562,-3200.12719726562,,,3.05837988853455,-99999999,1,0,0,0,0.0193023681640625,33.2355842590332,1,1,1,3.00174903869629,0,1816138912,3.00023226304488,,,-0.0460770453054973,0.00228133033549617,-0.0460778860830503,0.00228133159658771,0.987550914287567,0.98906397819519,26.0239372253418,0.18738055229187,30,4,200,-0.000590361072681844,-0.277675777673721,1.8857616186142,1,,,,,,,,,,,,,,,,
,3826045720.66216,3.00231182575226,-4050.4912109375,,,6,,,,26.0463790893555,,,100,,,,,,,,,,,,,,,,,,,,,,2.99859380722046,3.002774477005,-4050.4912109375,-4050.4912109375,,,3.05945324897766,-99999999,1,0,0,0,0.0200653076171875,33.2355842590332,1,1,1,3.00184917449951,0,1816138848,3.00029982220043,,,-0.0555760691761559,0.00275164775312457,-0.0555772408032863,0.00275164974741229,0.987298011779785,0.989016711711884,26.022310256958,0.187377586960793,30,4,200,-0.000687629508320242,-0.341145992279053,2.27738571166992,1,,,,,,,,,,,,,,,,
,3826045772.0933,3.00222718715668,-4999.93115234375,,,6,,,,26.0463790893555,,,100,,,,,,,,,,,,,,,,,,,,,,2.99858975410461,3.00276947021484,-4999.93115234375,-4999.93115234375,,,3.05911183357239,-99999999,1,0,0,0,0.0189208984375,33.2355842590332,1,1,1,3.00168490409851,0,1816138816,3.00038203326139,,,-0.0645967532623341,0.00319828539374646,-0.0645983366059905,0.00319828840368954,0.987014889717102,0.988978207111359,26.0204792022705,0.187386080622673,30,4,200,-0.000781697570346296,-0.391281634569168,2.64039301872253,1,,,,,,,,,,,,,,,,
,3826045824.98164,3.00186502933502,-4050.47875976562,,,6,,,,26.0463790893555,,,100,,,,,,,,,,,,,,,,,,,,,,2.99847102165222,3.00209093093872,-4050.47875976562,-4050.47875976562,,,3.05854511260986,-99999999,1,0,0,0,0.020294189453125,32.7468223571777,1,1,1,3.00163912773132,0,1816139104,3.00018425421281,,,-0.0554420904601443,0.0027450096985377,-0.0554431980757283,0.00274501176405561,0.987422168254852,0.989056646823883,26.0229873657227,0.187382638454437,30,4,200,0.000763592834118754,-0.337141841650009,2.27834033966064,1,,,,,,,,,,,,,,,,
,3826045876.48795,3.00204062461853,-3200.26611328125,,,6,,,,26.0463790893555,,,100,,,,,,,,,,,,,,,,,,,,,,2.99847793579102,3.0027916431427,-3200.26611328125,-3200.26611328125,,,3.05913281440735,-99999999,1,0,0,0,0.0188446044921875,33.2355842590332,1,1,1,3.00128960609436,0,1816138880,3.00028976527127,,,-0.0457989688475027,0.00226755941059648,-0.045799787217287,0.00226756189778269,0.987658202648163,0.98910129070282,26.0245304107666,0.187383264303207,30,4,200,8.39135100250132E-5,-0.28119769692421,1.87618732452393,1,,,,,,,,,,,,,,,,
,3826045925.18668,3.00204658508301,-2450.263671875,,,6,,,,26.0463790893555,,,100,,,,,,,,,,,,,,,,,,,,,,2.99841237068176,3.00256943702698,-2450.263671875,-2450.263671875,,,3.05954027175903,-99999999,1,0,0,0,0.01495361328125,33.2355842590332,1,1,1,3.00152373313904,0,1816138944,3.00027073513378,,,-0.0362017029255255,0.00179238466763565,-0.0362022933047918,0.00179238570185313,0.987816870212555,0.989184677600861,26.025218963623,0.187371209263802,30,4,200,-0.000629131041932851,-0.218286842107773,1.48316895961761,1,,,,,,,,,,,,,,,,
,3826045974.67482,3.0019965171814,-1800.232421875,,,6,,,,26.0463790893555,,,100,,,,,,,,,,,,,,,,,,,,,,2.99852228164673,3.00280499458313,-1800.232421875,-1800.232421875,,,3.0605034828186,-99999999,1,0,0,0,0.017852783203125,33.2355842590332,1,1,1,3.00118803977966,0,1816138912,3.00036044554277,,,-0.0271834881439535,0.00134588473432633,-0.0271839039923103,0.00134588539464884,0.987708449363709,0.988978564739227,26.0258502960205,0.187366262078285,30,4,200,-0.000553664227481931,-0.161779001355171,1.1174613237381,1,,,,,,,,,,,,,,,,
,3826046024.30782,3.00201952457428,-1250.1591796875,,,6,,,,26.0463790893555,,,100,,,,,,,,,,,,,,,,,,,,,,2.99842262268066,3.00247812271118,-1250.1591796875,-1250.1591796875,,,3.05891609191895,-99999999,1,0,0,0,0.0212860107421875,33.2355842590332,1,1,1,3.00156092643738,0,1816139232,3.00030021233992,,,-0.0190910674301532,0.000945223799979635,-0.0190913708896463,0.000945224675073251,0.987406551837921,0.988657116889954,26.0257358551025,0.187374100089073,30,4,200,-0.00060265907086432,-0.122792683541775,0.777922093868256,1,,,,,,,,,,,,,,,,
,3826046072.41137,3.00244188308716,-800.536071777344,,,6,,,,26.0463790893555,,,100,,,,,,,,,,,,,,,,,,,,,,2.99853157997131,3.0029559135437,-800.536071777344,-800.536071777344,,,3.0598464012146,-99999999,1,0,0,0,0.018310546875,33.2355842590332,1,1,1,3.00192785263062,0,1816138944,3.00039061633023,,,-0.0121800862438209,0.00060305245417416,-0.0121802998574008,0.000603052797536126,0.987331390380859,0.988749980926514,26.0244007110596,0.187378197908402,30,4,200,-0.00125459325499833,-0.0829503834247589,0.497202396392822,1,,,,,,,,,,,,,,,,
,3826046121.33653,3.00212180614471,-450.1904296875,,,6,,,,26.0463790893555,,,100,,,,,,,,,,,,,,,,,,,,,,2.99856066703796,3.00257754325867,-450.1904296875,-450.1904296875,,,3.05713105201721,-99999999,1,0,0,0,0.020751953125,33.2355842590332,1,1,1,3.00166606903076,0,1816138848,3.00031161308289,,,-0.00668909354629356,0.000331186141852457,-0.00668924261080497,0.00033118641208799,0.987318336963654,0.989142119884491,26.0216598510742,0.187378942966461,30,4,200,-0.00221259309910238,-0.0474116317927837,0.269870758056641,1,,,,,,,,,,,,,,,,
,3826046169.65119,3.00194239616394,-200.382965087891,,,6,,,,26.0463790893555,,,100,,,,,,,,,,,,,,,,,,,,,,2.99845933914185,3.00270175933838,-200.382965087891,-200.382965087891,,,3.06114387512207,-99999999,1,0,0,0,0.020294189453125,33.2355842590332,1,1,1,3.0011830329895,0,1816138944,3.00033203038302,,,-0.00278346505301802,0.000137833717536031,-0.00278362601154535,0.000137833998963326,0.978558719158173,0.981339693069458,26.0065593719482,0.187395676970482,30,4,200,-0.00375751731917262,-0.0351827852427959,0.102729417383671,1,,,,,,,,,,,,,,,,
,3826046228.58314,3.00190937519073,-50.4203186035156,,,6,,,,26.0463790893555,,,10,,,,,,,,,,,,,,,,,,,,,,2.99861407279968,3.00261640548706,-50.4203186035156,-50.4203186035156,,,3.06094789505005,-99999999,1,0,0,0,0.0194549560546875,34.2131004333496,1,1,1,3.00120234489441,0,1816139168,3.00049909678372,,,-0.000437698248924065,2.19657789192254E-5,-0.000438290595089206,2.1967006991487E-5,0.836250782012939,0.844156980514526,25.8551998138428,0.189917206764221,30,4,200,-0.0522896684706211,-0.289835035800934,0.0532363839447498,1,,,,,,,,,,,,,,,,
,3826046276.50753,3.00190138816833,-0.277311772108078,,,6,,,,26.0463790893555,,,10,,,,,,,,,,,,,,,,,,,,,,2.99854707717895,3.00245881080627,-0.277311772108078,-0.277311772108078,,,3.06334900856018,-99999999,1,0,0,0,0.01861572265625,33.7243423461914,1,1,1,3.0013439655304,0,1816138944,3.0003278688951,,,0.000363742468816233,1.82290338779196E-5,0.000364011216586021,1.82296581513662E-5,0.844724595546722,0.84921932220459,26.1888999938965,0.189658910036087,30,4,200,-0.0488015562295914,-0.284372746944427,0.0110867712646723,1,,,,,,,,,,,,,,,,
,3826046324.09722,3.00191056728363,50.0547752380371,,,6,,,,26.0463790893555,,,10,,,,,,,,,,,,,,,,,,,,,,2.9983549118042,3.00249314308167,50.0547752380371,50.0547752380371,,,3.06170034408569,-99999999,1,0,0,0,0.020294189453125,33.2355842590332,1,1,1,3.0013279914856,0,1816138976,3.00030888210643,,,0.00114049249607037,5.6630394457463E-5,0.00114061996336963,5.66307020739184E-5,0.923122704029083,0.92451024055481,26.1015682220459,0.187917992472649,30,4,200,-0.0610053986310959,-0.671262204647064,0.0364116616547108,1,,,,,,,,,,,,,,,,
,3826046371.89372,3.00184059143066,199.992202758789,,,6,,,,26.0463790893555,,,10,,,,,,,,,,,,,,,,,,,,,,2.99832081794739,3.00218486785889,199.992202758789,199.992202758789,,,3.06293201446533,-99999999,1,0,0,0,0.017852783203125,33.2355842590332,1,1,1,3.0009548664093,0,1816139008,3.00028183243491,,,0.00349670443885799,0.000173133744325116,0.00349672323387058,0.000173133778505101,0.984403848648071,0.984739303588867,26.0342330932617,0.187389522790909,30,4,200,-0.0380211770534515,-1.54243469238281,0.160186991095543,1,,,,,,,,,,,,,,,,
,3826046420.16057,3.00173234939575,449.963531494141,,,6,,,,26.0463790893555,,,10,,,,,,,,,,,,,,,,,,,,,,2.99836826324463,3.00200343132019,449.963531494141,449.963531494141,,,3.06339716911316,-99999999,1,0,0,0,0.0182342529296875,33.2355842590332,1,1,1,3.00155115127563,0,1816138944,3.00025476108898,,,0.00741062305063943,0.000366906820763749,0.00741073184747123,0.000366907096085539,0.988012373447418,0.989236831665039,26.0264625549316,0.187388375401497,30,4,200,-0.0155482590198517,-3.10736608505249,0.408454984426498,1,,,,,,,,,,,,,,,,
,3826046473.81759,3.00219082832336,799.956237792969,,,6,,,,26.0463790893555,,,100,,,,,,,,,,,,,,,,,,,,,,2.99827671051025,3.00253415107727,799.956237792969,799.956237792969,,,3.06681632995605,-99999999,1,0,0,0,0.01922607421875,33.7243423461914,1,1,1,3.0015652179718,0,1816139040,3.00013620512826,,,0.0128367323339176,0.000635558249218415,0.0128369334577465,0.000635558742142076,0.98805969953537,0.989379703998566,26.0257892608643,0.187381505966187,30,4,200,-0.000128882442368194,-4.87096309661865,4.86745500564575,1,,,,,,,,,,,,,,,,
,3826046527.84695,3.00219309329987,1249.73071289062,,,6,,,,26.0463790893555,,,100,,,,,,,,,,,,,,,,,,,,,,2.9984016418457,3.00265955924988,1249.73071289062,1249.73071289062,,,3.06123328208923,-99999999,1,0,0,0,0.0200653076171875,33.2355842590332,1,1,1,3.00172662734985,0,1816138976,3.00031434405934,,,0.0195856627504936,0.000969702562365092,0.0195859647603143,0.000969703056232995,0.988162457942963,0.989497184753418,26.0257778167725,0.187368348240852,30,4,200,-0.000166005702340044,-0.80754953622818,0.112594343721867,1,,,,,,,,,,,,,,,,
,3826046576.88947,3.00196290016174,1799.70300292969,,,6,,,,26.0463790893555,,,100,,,,,,,,,,,,,,,,,,,,,,2.99856066703796,3.00250434875488,1799.70300292969,1799.70300292969,,,3.06443405151367,-99999999,1,0,0,0,0.0179290771484375,33.2355842590332,1,1,1,3.0014214515686,0,1816139008,3.0002983266657,,,0.0276580493672401,0.0013693742608861,0.0276584640064245,0.00136937531578992,0.988141536712647,0.989408314228058,26.0262603759766,0.187373384833336,30,4,200,0.000313789321808144,-1.12950325012207,0.167012810707092,1,,,,,,,,,,,,,,,,
,3826046626.15592,3.00224947929382,2450.30151367187,,,6,,,,26.0463790893555,,,100,,,,,,,,,,,,,,,,,,,,,,2.99832320213318,3.00303888320923,2450.30151367187,2450.30151367187,,,3.06323003768921,-99999999,1,0,0,0,0.0159454345703125,33.2355842590332,1,1,1,3.00146007537842,0,1816138720,3.00042902339589,,,0.0366545600972216,0.0018148044589543,0.0366551773131606,0.00181480702395016,0.987868905067444,0.989214956760407,26.0254287719727,0.187351107597351,30,4,200,0.000380633602617308,-1.50366258621216,0.216844007372856,1,,,,,,,,,,,,,,,,
,3826046676.03486,3.00215065479279,3200.07690429687,,,6,,,,26.0463790893555,,,100,,,,,,,,,,,,,,,,,,,,,,2.99852514266968,3.00253701210022,3200.07690429687,3200.07690429687,,,3.06094026565552,-99999999,1,0,0,0,0.0196075439453125,33.7243423461914,1,1,1,3.00097155570984,0,1816138912,3.00026345252991,,,0.0460932559683352,0.00228213293362274,0.0460941030098179,0.00228213429193297,0.987544357776642,0.989064455032349,26.0238819122314,0.187382489442825,30,4,200,0.000574706878978759,-1.88588666915894,0.278322637081146,1,,,,,,,,,,,,,,,,
,3826046726.66121,3.00197553634644,4050.251953125,,,6,,,,26.0463790893555,,,100,,,,,,,,,,,,,,,,,,,,,,2.99844765663147,3.00251030921936,4050.251953125,4050.251953125,,,3.06299877166748,-99999999,1,0,0,0,0.01861572265625,33.2355842590332,1,1,1,3.00106739997864,0,1816138944,3.0003616809845,,,0.0555898823514231,0.00275233040099839,0.0555910575370613,0.00275233301229032,0.987317144870758,0.989023745059967,26.0224056243896,0.187397792935371,30,4,200,0.000631672504823655,-2.2779700756073,0.33179435133934,1,,,,,,,,,,,,,,,,
,3826046777.89935,3.00215351581574,4999.94384765625,,,6,,,,26.0463790893555,,,100,,,,,,,,,,,,,,,,,,,,,,2.99853873252869,3.00268888473511,4999.94384765625,4999.94384765625,,,3.06314134597778,-99999999,1,0,0,0,0.019683837890625,33.7243423461914,1,1,1,3.00161814689636,0,1816139008,3.00031052936207,,,0.0646118780407705,0.00319903349623951,0.064613486546865,0.00319903791275742,0.987045586109161,0.989009320735931,26.0205116271973,0.187373697757721,30,4,200,0.000764690164942294,-2.65362000465393,0.388306736946106,1,,,,,,,,,,,,,,,,