File: data/AP424/MH_hyst2.dat
[Header]
; MPMS3 Data File (default extension .dat)
; Copyright (c) 2007, Quantum Design, Inc. All rights reserved.
TITLE,
FILEOPENTIME,3826040400.19709,03/27/2021,9:00 pm
BYAPP,SQUID AC,0.9.1.0
INFO,MPMS3 Measurement Release 1.1.16 Build 347, MultiVu Release 2.3.3.2,APPNAME
INFO,0,MOMENT_UNITS
INFO,SC_AP424,SAMPLE_MATERIAL
INFO,capsule nujol,SAMPLE_COMMENT
INFO,1,SAMPLE_MASS
INFO,,SAMPLE_VOLUME
INFO,,SAMPLE_MOLECULAR_WEIGHT
INFO,,SAMPLE_SIZE
INFO,,SAMPLE_SHAPE
INFO,Standard,SAMPLE_HOLDER
INFO,Standard,SAMPLE_HOLDER_DETAIL
INFO,68.35,SAMPLE_OFFSET
DATATYPE,COMMENT,1
DATATYPE,TIME,2
STARTUPAXIS,X,2
STARTUPAXIS,Y1,5
FIELDGROUP, VSM,2,3,4,5,6,8,9,10,11,14,15
FIELDGROUP, DC, 2,3,4,14,56,57,58,59,60,61,62,63,64,65,66,67,68,69
FIELDGROUP, AC, 2,3,4,11,16,17,18,19,20,21,22,23,24,25,26,27,28,29,30
STARTUPGROUP, All
[Data]
Comment,Time Stamp (sec),Temperature (K),Magnetic Field (Oe),Moment (emu),M. Std. Err. (emu),Transport Action,Averaging Time (sec),Frequency (Hz),Peak Amplitude (mm),Center Position (mm),Lockin Signal' (V),Lockin Signal (V),Range,M. Quad. Signal (emu),AC Moment (emu),AC M. Std Err. (emu),AC Phase (deg),AC Phase Std. Err. (deg),AC Susceptibility (emu/Oe),AC Suscept. Std Err. (emu/Oe),AC X' (emu/Oe),AC X' Std Err. (emu/Oe),AC X'' (emu/Oe),AC X'' Std Err. (emu/Oe),AC Drive (Oe),AC Frequency (Hz),AC Averaging Time (sec),AC Cycles,AC Range,AC Measure Type,AC Signal' (V),AC Signal'' (V),AC Trim Coil Ratio,AC Trim Coil Phase,Min. Temperature (K),Max. Temperature (K),Min. Field (Oe),Max. Field (Oe),Mass (grams),Motor Lag (deg),Pressure (Torr),Measure Count,Measurement Number,SQUID Status (code),Motor Status (code),Measure Status (code),Motor Current (amps),Motor Temp. (C),Temp. Status (code),Field Status (code),Chamber Status (code),Chamber Temp (K),Redirection State,Evercool Status,Average Temp (K),Rotation Angle (deg),Rotator state,DC Moment Fixed Ctr (emu),DC Moment Err Fixed Ctr (emu),DC Moment Free Ctr (emu),DC Moment Err Free Ctr (emu),DC Fixed Fit,DC Free Fit,DC Calculated Center (mm),DC Calculated Center Err (mm),DC Scan Length (mm),DC Scan Time (s),DC Number of Points,DC Squid Drift,DC Min V (V),DC Max V (V),DC Scans per Measure,Map 01,Map 02,Map 03,Map 04,Map 05,Map 06,Map 07,Map 08,Map 09,Map 10,Map 11,Map 12,Map 13,Map 14,Map 15,Map 16
,3826040897.64936,2.00138998031616,-0.0504203215241432,,,6,,,,26.0463790893555,,,1,,,,,,,,,,,,,,,,,,,,,,1.99804985523224,2.0022189617157,-0.0504203215241432,-0.0504203215241432,,,2.45700573921204,-99999999,1,0,0,0,0.0154876708984375,33.2355842590332,1,1,1,2.00112819671631,0,1816139008,2.00008786292303,,,5.24910005113354E-5,2.59951071188525E-6,5.24974687025556E-5,2.59952511637413E-6,0.974899291992188,0.980130016803741,25.9884452819824,0.187436953186989,30,4,200,2.09779136639554E-5,-0.500779926776886,-0.0025470769032836,1,,,,,,,,,,,,,,,,
,3826040950.85257,2.00189673900604,50.0673789978027,,,6,,,,26.0463790893555,,,1,,,,,,,,,,,,,,,,,,,,,,1.99851286411285,2.00235199928284,50.0673789978027,50.0673789978027,,,2.45967054367065,-99999999,1,0,0,0,0.018157958984375,33.2355842590332,1,1,1,2.00144147872925,0,1816139040,2.00028506192294,,,0.00122907549240639,6.08531081987565E-5,0.0012291050531771,6.08531785011705E-5,0.987427175045013,0.989403247833252,26.0208473205566,0.187388226389885,30,4,200,0.00176059838850051,-4.81694936752319,0.955549597740173,1,,,,,,,,,,,,,,,,
,3826041009.58597,2.00176346302032,200.01741027832,,,6,,,,26.0463790893555,,,10,,,,,,,,,,,,,,,,,,,,,,1.99776113033295,2.00199007987976,200.01741027832,200.01741027832,,,2.46354126930237,-99999999,1,0,0,0,0.018463134765625,33.7243423461914,1,1,1,2.00160217285156,0,1816138944,2.00018599900332,,,0.00473739001658026,0.000234553841183155,0.00473748923355426,0.000234554061181085,0.987576544284821,0.989307105541229,26.0225143432617,0.187383115291595,30,4,200,0.000577246421016753,-1.91791749000549,0.307183116674423,1,,,,,,,,,,,,,,,,
,3826041057.95413,2.0014853477478,449.976165771484,,,6,,,,26.0463790893555,,,10,,,,,,,,,,,,,,,,,,,,,,1.99853038787842,2.00210666656494,449.976165771484,449.976165771484,,,2.46218800544739,-99999999,1,0,0,0,0.018310546875,33.2355842590332,1,1,1,2.00122165679932,0,1816138688,2.00024862722917,,,0.0104276448141903,0.000516283993107849,0.0104278725948876,0.000516284474127945,0.987775146961212,0.989625573158264,26.0219802856445,0.187381699681282,30,4,200,0.000740499119274318,-4.28329706192017,0.607846319675446,1,,,,,,,,,,,,,,,,
,3826041117.24946,2.00128388404846,800.04443359375,,,6,,,,26.0463790893555,,,100,,,,,,,,,,,,,,,,,,,,,,1.99827110767365,2.00190329551697,800.04443359375,800.04443359375,,,2.4688127040863,-99999999,1,0,0,0,0.0202178955078125,33.7243423461914,1,1,1,2.00085997581482,0,1816139040,2.00023331425407,,,0.0170617026467381,0.000844768998195316,0.0170621643082618,0.000844770518455293,0.985494196414947,0.987354397773743,26.0195579528809,0.187399864196777,30,4,200,-0.00109121995046735,-0.709872782230377,0.0960092917084694,1,,,,,,,,,,,,,,,,
,3826041165.57909,2.00132119655609,1249.70544433594,,,6,,,,26.0463790893555,,,100,,,,,,,,,,,,,,,,,,,,,,1.99807274341583,2.00264120101929,1249.70544433594,1249.70544433594,,,2.46881318092346,-99999999,1,0,0,0,0.018463134765625,33.2355842590332,1,1,1,2.00051975250244,0,1816793088,2.0001988736066,,,0.0256371508124227,0.00126941825804392,0.0256378963323525,0.00126941970816634,0.982695877552033,0.984393119812012,26.0181770324707,0.187378570437431,30,4,200,-0.00131080334540457,-1.06830608844757,0.147505536675453,1,,,,,,,,,,,,,,,,
,3826041214.15312,2.00163781642914,1799.6904296875,,,6,,,,26.0463790893555,,,100,,,,,,,,,,,,,,,,,,,,,,1.99821794033051,2.00226998329163,1799.6904296875,1799.6904296875,,,2.46740245819092,-99999999,1,0,0,0,0.0200653076171875,33.7243423461914,1,1,1,2.00133442878723,0,1816139040,2.00027733499354,,,0.037575192088748,0.00186046574298931,0.0375760774170156,0.00186046700076358,0.984743297100067,0.986324965953827,26.0208549499512,0.187382757663727,30,4,200,0.000492242688778788,-1.54538285732269,0.230476051568985,1,,,,,,,,,,,,,,,,
,3826041263.86537,2.00169694423676,2450.51586914062,,,6,,,,26.0463790893555,,,100,,,,,,,,,,,,,,,,,,,,,,1.99761569499969,2.00262928009033,2450.51586914062,2450.51586914062,,,2.4717812538147,-99999999,1,0,0,0,0.0160980224609375,32.7468223571777,1,1,1,2.00141668319702,0,1816139040,2.00015931779688,,,0.0507892138868091,0.00251463993940972,0.0507903953391742,0.00251464160432353,0.987427175045013,0.989375352859497,26.021017074585,0.187370538711548,30,4,200,0.000473218242404982,-2.07777738571167,0.307620376348495,1,,,,,,,,,,,,,,,,
,3826041313.36113,2.00187528133392,3199.82495117188,,,6,,,,26.0463790893555,,,100,,,,,,,,,,,,,,,,,,,,,,1.99814605712891,2.00259399414062,3199.82495117188,3199.82495117188,,,2.47280263900757,-99999999,1,0,0,0,0.0186920166015625,33.2355842590332,1,1,1,2.00147318840027,0,1816138848,2.00022628090598,,,0.0624328185956914,0.00309114496205351,0.062434700501679,0.00309115065146388,0.987011015415192,0.989411413669586,26.017993927002,0.187389329075813,30,4,200,0.000733090448193252,-2.56199216842651,0.37603822350502,1,,,,,,,,,,,,,,,,
,3826041363.76843,2.00206923484802,4050.16357421875,,,6,,,,26.0463790893555,,,100,,,,,,,,,,,,,,,,,,,,,,1.99868655204773,2.00248050689697,4050.16357421875,4050.16357421875,,,2.46984958648682,-99999999,1,0,0,0,0.02044677734375,33.2355842590332,1,1,1,2.00165796279907,0,1816139104,2.00022334402258,,,0.0725701405281433,0.0035930903752313,0.0725728699867302,0.00359309673093743,0.986378192901611,0.989328503608704,26.0144367218018,0.18739053606987,30,4,200,0.000766554498113692,-2.97566246986389,0.43842476606369,1,,,,,,,,,,,,,,,,
,3826041414.5692,2.00165319442749,4999.994140625,,,6,,,,26.0463790893555,,,100,,,,,,,,,,,,,,,,,,,,,,1.99812018871307,2.00225377082825,4999.994140625,4999.994140625,,,2.47565507888794,-99999999,1,0,0,0,0.018463134765625,32.7468223571777,1,1,1,2.00138378143311,0,1816139072,2.00024650313637,,,0.0810133330876476,0.0040111691803383,0.0810172005206817,0.00401118021106688,0.985659062862396,0.989243447780609,26.0105972290039,0.187374517321587,30,4,200,0.000957204145379364,-3.32203245162964,0.487961620092392,1,,,,,,,,,,,,,,,,
,3826041466.65394,2.00215458869934,4050.31494140625,,,6,,,,26.0463790893555,,,100,,,,,,,,,,,,,,,,,,,,,,1.99789297580719,2.00238466262817,4050.31494140625,4050.31494140625,,,2.47526621818542,-99999999,1,0,0,0,0.0180816650390625,33.2355842590332,1,1,1,2.00219106674194,0,1816138976,2.00023257732391,,,0.0724576250745589,0.00358751413828209,0.0724602519848216,0.00358752101117647,0.986497104167938,0.989338755607605,26.0151119232178,0.187399223446846,30,4,200,-0.00123634783085436,-2.98080229759216,0.428654611110687,1,,,,,,,,,,,,,,,,
,3826041519.79641,2.0019770860672,3200.3037109375,,,6,,,,26.0463790893555,,,100,,,,,,,,,,,,,,,,,,,,,,1.99809443950653,2.00242304801941,3200.3037109375,3200.3037109375,,,2.47273683547974,-99999999,1,0,0,0,0.0208282470703125,33.2355842590332,1,1,1,2.00165319442749,0,1816139232,2.00026512145996,,,0.0622352995736835,0.00308136715105447,0.0622371414517961,0.00308137186057029,0.986988961696625,0.989362239837646,26.0181159973145,0.187365815043449,30,4,200,-0.000156209047418088,-2.55874013900757,0.368125110864639,1,,,,,,,,,,,,,,,,
,3826041571.75769,2.00166285037994,2450.32690429687,,,6,,,,26.0463790893555,,,100,,,,,,,,,,,,,,,,,,,,,,1.99789071083069,2.00230050086975,2450.32690429687,2450.32690429687,,,2.47436547279358,-99999999,1,0,0,0,0.0185394287109375,33.2355842590332,1,1,1,2.00129771232605,0,1816139008,2.000178380446,,,0.0511649670267163,0.00253325831849429,0.0511662276466831,0.00253326236326099,0.986965835094452,0.988872826099396,26.0207653045654,0.18739777803421,30,4,200,-0.000282334571238607,-2.10927438735962,0.30282399058342,1,,,,,,,,,,,,,,,,
,3826041622.07488,2.00192630290985,1800.24499511719,,,6,,,,26.0463790893555,,,100,,,,,,,,,,,,,,,,,,,,,,1.9985579252243,2.00201606750488,1800.24499511719,1800.24499511719,,,2.47659301757813,-99999999,1,0,0,0,0.01617431640625,33.2355842590332,1,1,1,2.00116562843323,0,1816138912,2.00026591257616,,,0.0404968243515031,0.00200509864098542,0.0404975796056819,0.00200510071578906,0.985637605190277,0.98692113161087,26.0239849090576,0.187381491065025,30,4,200,-0.000307989190332592,-1.67911469936371,0.238098576664925,1,,,,,,,,,,,,,,,,
,3826041670.01862,2.00229609012604,1250.171875,,,6,,,,26.0463790893555,,,100,,,,,,,,,,,,,,,,,,,,,,1.99769985675812,2.00259041786194,1250.171875,1250.171875,,,2.47415566444397,-99999999,1,0,0,0,0.02044677734375,33.2355842590332,1,1,1,2.00200176239014,0,1816139040,2.00026664950631,,,0.0305849646441298,0.00151437609930684,0.0305853145664711,0.00151437683751208,0.983965456485748,0.984663605690002,26.0287189483643,0.187390521168709,30,4,200,-0.000312599557219073,-1.27027356624603,0.184111446142197,1,,,,,,,,,,,,,,,,
,3826041719.11276,2.00159883499146,800.447814941406,,,6,,,,26.0463790893555,,,100,,,,,,,,,,,,,,,,,,,,,,1.99831056594849,2.002121925354,800.447814941406,800.447814941406,,,2.4784300327301,-99999999,1,0,0,0,0.017242431640625,33.2355842590332,1,1,1,2.00107574462891,0,1816139232,2.00018032030626,,,0.0203783565846999,0.00100902041177653,0.0203785481201195,0.00100902138159395,0.983252227306366,0.983763754367828,26.0308799743652,0.187393128871918,30,4,200,0.000552074867300689,-0.842567682266235,0.124016351997852,1,,,,,,,,,,,,,,,,
,3826041767.96324,2.00205600261688,450.140045166016,,,6,,,,26.0463790893555,,,100,,,,,,,,,,,,,,,,,,,,,,1.99813115596771,2.00237107276917,450.140045166016,450.140045166016,,,2.47931051254272,-99999999,1,0,0,0,0.0168609619140625,32.7468223571777,1,1,1,2.00132465362549,0,1816138976,2.00027663057501,,,0.0101818856902478,0.000504130928470074,0.010182099043727,0.000504131452869407,0.985568821430206,0.987021565437317,26.0225677490234,0.187387302517891,30,4,200,0.00199280912056565,-0.420065075159073,0.063077911734581,1,,,,,,,,,,,,,,,,
,3826041816.16365,2.00159585475922,200.130859375,,,6,,,,26.0463790893555,,,100,,,,,,,,,,,,,,,,,,,,,,1.99807024002075,2.00231623649597,200.130859375,200.130859375,,,2.4795253276825,-99999999,1,0,0,0,0.01953125,33.7243423461914,1,1,1,2.00098299980164,0,1816138848,2.00014229254289,,,0.00415843311563524,0.000205903324945442,0.00415861447060329,0.000205903752122781,0.982874929904938,0.985501110553741,26.0120067596436,0.18739578127861,30,4,200,0.00370938889682293,-0.159177333116531,0.0427376218140125,1,,,,,,,,,,,,,,,,
,3826041874.24677,2.00143301486969,50.1808242797852,,,6,,,,26.0463790893555,,,10,,,,,,,,,,,,,,,,,,,,,,1.99830770492554,2.00240588188171,50.1808242797852,50.1808242797852,,,2.48220062255859,-99999999,1,0,0,0,0.01922607421875,32.7468223571777,1,1,1,2.00091028213501,0,1816138848,2.00035839080811,,,0.000683259738974334,3.40525084849703E-5,0.000683693587499372,3.40536045006893E-5,0.884954214096069,0.890247523784637,25.9160079956055,0.188627898693085,30,4,200,0.0539760701358318,-0.137813225388527,0.31084331870079,1,,,,,,,,,,,,,,,,
,3826041922.511,2.00164115428925,0.0756304785609245,,,6,,,,26.0463790893555,,,10,,,,,,,,,,,,,,,,,,,,,,1.99855995178223,2.00253009796143,0.0756304785609245,0.0756304785609245,,,2.48199033737183,-99999999,1,0,0,0,0.020294189453125,32.7468223571777,1,1,1,2.00142025947571,0,1816139040,2.00017497756264,,,-0.000502613276185944,2.5030601806718E-5,-0.000502732290966304,2.50308365673325E-5,0.891580522060394,0.893673837184906,26.1272392272949,0.188489750027657,30,4,200,0.0482037775218487,-0.0492451041936874,0.306132167577744,1,,,,,,,,,,,,,,,,
,3826041970.03483,2.00202417373657,-49.7396469116211,,,6,,,,26.0463790893555,,,10,,,,,,,,,,,,,,,,,,,,,,1.99852705001831,2.00229692459106,-49.7396469116211,-49.7396469116211,,,2.48265790939331,-99999999,1,0,0,0,0.0194549560546875,33.2355842590332,1,1,1,2.00175142288208,0,1816138976,2.00029996308413,,,-0.00163728901960137,8.1187888077145E-5,-0.00163734117778041,8.11879986316444E-5,0.943433821201324,0.943973779678345,26.0759162902832,0.187665745615959,30,4,200,0.0601879395544529,-0.0490047633647919,0.826309502124786,1,,,,,,,,,,,,,,,,
,3826042018.11488,2.00198817253113,-199.954391479492,,,6,,,,26.0463790893555,,,10,,,,,,,,,,,,,,,,,,,,,,1.99780344963074,2.00247621536255,-199.954391479492,-199.954391479492,,,2.48353219032288,-99999999,1,0,0,0,0.018157958984375,33.2355842590332,1,1,1,2.00195503234863,0,1816138848,2.00018040700392,,,-0.00513676273489473,0.000254331949110466,-0.00513680642012605,0.000254332139742056,0.986172020435333,0.986744582653046,26.0315132141113,0.187378197908402,30,4,200,0.0378972366452217,-0.250236690044403,2.22508955001831,1,,,,,,,,,,,,,,,,
,3826042065.84696,2.00187802314758,-450.102203369141,,,6,,,,26.0463790893555,,,10,,,,,,,,,,,,,,,,,,,,,,1.99853026866913,2.00260424613953,-450.102203369141,-450.102203369141,,,2.48356771469116,-99999999,1,0,0,0,0.01800537109375,33.2355842590332,1,1,1,2.00162744522095,0,1816139104,2.0002586516467,,,-0.0107553930287465,0.000532508461111674,-0.0107556070070983,0.000532509208922957,0.988190591335297,0.989876508712769,26.0234336853027,0.187378391623497,30,4,200,0.0134688075631857,-0.670142650604248,4.47019195556641,1,,,,,,,,,,,,,,,,
,3826042124.78066,2.00176656246185,-800.069641113281,,,6,,,,26.0463790893555,,,100,,,,,,,,,,,,,,,,,,,,,,1.99781167507172,2.00261902809143,-800.069641113281,-800.069641113281,,,2.48557066917419,-99999999,1,0,0,0,0.0183868408203125,33.7243423461914,1,1,1,2.00222873687744,0,1816139040,2.00012999231165,,,-0.0173262932794245,0.000857872209462392,-0.0173267000275442,0.000857872836420512,0.985278069972992,0.986913561820984,26.0209312438965,0.187390640377998,30,4,200,-2.64119462372037E-5,-0.106153957545757,0.712100028991699,1,,,,,,,,,,,,,,,,
,3826042173.41681,2.00140416622162,-1249.64245605469,,,6,,,,26.0463790893555,,,100,,,,,,,,,,,,,,,,,,,,,,1.99792909622192,2.00266575813293,-1249.64245605469,-1249.64245605469,,,2.48175716400146,-99999999,1,0,0,0,0.0197601318359375,33.2355842590332,1,1,1,2.00056290626526,0,1816139168,2.00025654922832,,,-0.0258735957245011,0.00128113232363471,-0.0258743464018464,0.00128113386372244,0.982405841350555,0.984064221382141,26.0182437896729,0.187379866838455,30,4,200,-0.00111751025542617,-0.166368022561073,1.06133437156677,1,,,,,,,,,,,,,,,,
,3826042222.1978,2.00181841850281,-1799.9423828125,,,6,,,,26.0463790893555,,,100,,,,,,,,,,,,,,,,,,,,,,1.99807727336884,2.00250148773193,-1799.9423828125,-1799.9423828125,,,2.48265504837036,-99999999,1,0,0,0,0.017852783203125,33.2355842590332,1,1,1,2.00113534927368,0,1816138816,2.00029944289814,,,-0.0377463434189378,0.00186893881986529,-0.0377472472277457,0.00186894168236039,0.984789848327637,0.986342251300812,26.0211200714111,0.187392264604568,30,4,200,-0.0013949420535937,-0.238869607448578,1.54599905014038,1,,,,,,,,,,,,,,,,
,3826042272.27978,2.0015264749527,-2450.33935546875,,,6,,,,26.0463790893555,,,100,,,,,,,,,,,,,,,,,,,,,,1.99852156639099,2.00312066078186,-2450.33935546875,-2450.33935546875,,,2.48235249519348,-99999999,1,0,0,0,0.0179290771484375,33.7243423461914,1,1,1,2.00158452987671,0,1816138944,2.00013819607821,,,-0.0508259376814575,0.00251645601670859,-0.0508270927664992,0.00251645755405299,0.987470328807831,0.989380717277527,26.0212879180908,0.187383964657784,30,4,200,-0.000999682466499507,-0.313558429479599,2.07686734199524,1,,,,,,,,,,,,,,,,
,3826042322.07471,2.00123643875122,-3199.98876953125,,,6,,,,26.0463790893555,,,100,,,,,,,,,,,,,,,,,,,,,,1.99798917770386,2.00265169143677,-3199.98876953125,-3199.98876953125,,,2.4854052066803,-99999999,1,0,0,0,0.019989013671875,33.2355842590332,1,1,1,2.00113129615784,0,1816138912,2.00011811473153,,,-0.0624147814855149,0.0030902494738208,-0.0624165704487655,0.00309025413398774,0.987104713916779,0.989417612552643,26.018575668335,0.187388956546783,30,4,200,-0.000771088234614581,-0.373989671468735,2.55345344543457,1,,,,,,,,,,,,,,,,
,3826042372.37182,2.00167429447174,-4050.31494140625,,,6,,,,26.0463790893555,,,100,,,,,,,,,,,,,,,,,,,,,,1.99848520755768,2.00218200683594,-4050.31494140625,-4050.31494140625,,,2.48434686660767,-99999999,1,0,0,0,0.02044677734375,33.2355842590332,1,1,1,2.00150799751282,0,1816138848,2.00013021989302,,,-0.0725571917727414,0.0035924467830495,-0.0725597989524131,0.00359245106093024,0.986433744430542,0.98929625749588,26.0149326324463,0.187384247779846,30,4,200,-0.000771183636970818,-0.442722290754318,2.97070956230164,1,,,,,,,,,,,,,,,,
,3826042423.32398,2.00141310691834,-5000.08251953125,,,6,,,,26.0463790893555,,,100,,,,,,,,,,,,,,,,,,,,,,1.99778175354004,2.00238037109375,-5000.08251953125,-5000.08251953125,,,2.48691320419312,-99999999,1,0,0,0,0.019073486328125,33.2355842590332,1,1,1,2.00090265274048,0,1816138880,2.00025245276364,,,-0.0809988802733077,0.00401045168468056,-0.0810025671883646,0.00401045768518959,0.985722601413727,0.989238202571869,26.0109825134277,0.187387242913246,30,4,200,-0.000906755798496306,-0.485710024833679,3.32324767112732,1,,,,,,,,,,,,,,,,
,3826042475.71714,2.00178980827332,-4050.47875976562,,,6,,,,26.0463790893555,,,100,,,,,,,,,,,,,,,,,,,,,,1.99835121631622,2.0023832321167,-4050.47875976562,-4050.47875976562,,,2.48507332801819,-99999999,1,0,0,0,0.018157958984375,33.2355842590332,1,1,1,2.00123000144958,0,1816138848,2.00036068396135,,,-0.0724360628518445,0.00358644160113699,-0.0724386026018474,0.00358644751204389,0.986558258533478,0.989329278469086,26.0155372619629,0.1873949021101,30,4,200,0.00116761156823486,-0.43202206492424,2.97682166099548,1,,,,,,,,,,,,,,,,
,3826042527.936,2.00230693817139,-3200.31640625,,,6,,,,26.0463790893555,,,100,,,,,,,,,,,,,,,,,,,,,,1.9985853433609,2.00297832489014,-3200.31640625,-3200.31640625,,,2.48298048973083,-99999999,1,0,0,0,0.0164794921875,33.2355842590332,1,1,1,2.00163555145264,0,1816138912,2.0004138621417,,,-0.0622055873881161,0.00307989301146156,-0.0622074132109081,0.00307989950614433,0.987080097198486,0.989395916461945,26.0185317993164,0.187376722693443,30,4,200,0.00018209773406852,-0.377871483564377,2.55783343315125,1,,,,,,,,,,,,,,,,
,3826042578.95739,2.00147080421448,-2450.32690429687,,,6,,,,26.0463790893555,,,100,,,,,,,,,,,,,,,,,,,,,,1.99856269359589,2.00229501724243,-2450.32690429687,-2450.32690429687,,,2.48609614372253,-99999999,1,0,0,0,0.0159454345703125,33.2355842590332,1,1,1,2.00122737884521,0,1816138944,2.00017376379533,,,-0.0511320403827519,0.00253162662787543,-0.0511332479361711,0.00253162994533868,0.986998498439789,0.988844990730286,26.0211753845215,0.187405496835709,30,4,200,0.000225678042625077,-0.309575647115707,2.10100054740906,1,,,,,,,,,,,,,,,,
,3826042629.40582,2.00161159038544,-1800.40881347656,,,6,,,,26.0463790893555,,,100,,,,,,,,,,,,,,,,,,,,,,1.99817776679993,2.00190448760986,-1800.40881347656,-1800.40881347656,,,2.48696899414062,-99999999,1,0,0,0,0.01861572265625,33.2355842590332,1,1,1,2.0016188621521,0,1816139136,2.00011031194167,,,-0.0404511400129018,0.00200283447345763,-0.0404518680001019,0.00200283630715385,0.985706627368927,0.986956059932709,26.0243301391602,0.187363833189011,30,4,200,0.00033043185248971,-0.240728765726089,1.67406272888184,1,,,,,,,,,,,,,,,,
,3826042677.53098,2.00194013118744,-1249.95764160156,,,6,,,,26.0463790893555,,,100,,,,,,,,,,,,,,,,,,,,,,1.99834680557251,2.00259232521057,-1249.95764160156,-1249.95764160156,,,2.4874107837677,-99999999,1,0,0,0,0.017852783203125,33.2355842590332,1,1,1,2.00128793716431,0,1816138848,2.0002859397368,,,-0.0305382660927554,0.0015120661437925,-0.030538605249453,0.00151206694810642,0.983870923519134,0.984540224075317,26.0290298461914,0.187365725636482,30,4,200,0.000332161172991618,-0.187763527035713,1.26449739933014,1,,,,,,,,,,,,,,,,
,3826042725.51367,2.00132238864899,-800.510864257812,,,6,,,,26.0463790893555,,,100,,,,,,,,,,,,,,,,,,,,,,1.99864292144775,2.00229978561401,-800.510864257812,-800.510864257812,,,2.48553037643433,-99999999,1,0,0,0,0.01861572265625,33.2355842590332,1,1,1,2.00158190727234,0,1816138880,2.00021114132621,,,-0.0204094360725574,0.0010105661608107,-0.020409604681014,0.00101056650757167,0.982863962650299,0.983332335948944,26.031364440918,0.187385335564613,30,4,200,-0.000573278754018247,-0.121522128582001,0.847051620483398,1,,,,,,,,,,,,,,,,
,3826042773.03375,2.00210821628571,-450.291290283203,,,6,,,,26.0463790893555,,,100,,,,,,,,,,,,,,,,,,,,,,1.99809050559998,2.00232172012329,-450.291290283203,-450.291290283203,,,2.48811173439026,-99999999,1,0,0,0,0.0206756591796875,33.2355842590332,1,1,1,2.00189471244812,0,1816139072,2.00026007890701,,,-0.0101546683553958,0.000502784625334194,-0.0101548873848731,0.000502785490300786,0.985392570495606,0.986820995807648,26.0226097106934,0.18737381696701,30,4,200,-0.00206896080635488,-0.0666857287287712,0.415448129177094,1,,,,,,,,,,,,,,,,
,3826042821.5461,2.00176823139191,-199.992202758789,,,6,,,,26.0463790893555,,,100,,,,,,,,,,,,,,,,,,,,,,1.99847567081451,2.00265908241272,-199.992202758789,-199.992202758789,,,2.48770213127136,-99999999,1,0,0,0,0.01861572265625,33.2355842590332,1,1,1,2.00087738037109,0,1816139040,2.00039317391135,,,-0.00411770289188014,0.000203886003939238,-0.00411789524788854,0.00020388649862525,0.983044445514679,0.985895454883575,26.0108833312988,0.187387749552727,30,4,200,-0.00370411318726838,-0.0455312766134739,0.15445214509964,1,,,,,,,,,,,,,,,,
,3826042880.19001,2.00185108184814,-50.0295639038086,,,6,,,,26.0463790893555,,,10,,,,,,,,,,,,,,,,,,,,,,1.99801766872406,2.00202894210815,-50.0295639038086,-50.0295639038086,,,2.48936414718628,-99999999,1,0,0,0,0.0205230712890625,33.7243423461914,1,1,1,2.00186371803284,0,1816138944,2.00016803091223,,,-0.000644761857387785,3.21172521498599E-5,-0.000645148922969466,3.21182324095626E-5,0.889469981193543,0.894686579704285,25.9195156097412,0.188510730862618,30,4,200,-0.0519947186112404,-0.29056853055954,0.145355314016342,1,,,,,,,,,,,,,,,,
,3826042928.02695,2.00138103961945,0.264706671237946,,,6,,,,26.0463790893555,,,10,,,,,,,,,,,,,,,,,,,,,,1.99837648868561,2.00201177597046,0.264706671237946,0.264706671237946,,,2.48915076255798,-99999999,1,0,0,0,0.0182342529296875,33.2355842590332,1,1,1,2.00126266479492,0,1816139008,2.0002047365362,,,0.000551924005260249,2.74679101380231E-5,0.000552039348618816,2.74681907948195E-5,0.897879302501678,0.89982408285141,26.1220016479492,0.188352540135384,30,4,200,-0.0487824343144894,-0.372624516487122,0.00907860603183508,1,,,,,,,,,,,,,,,,
,3826042975.6627,2.00125050544739,49.9665374755859,,,6,,,,26.0463790893555,,,10,,,,,,,,,,,,,,,,,,,,,,1.99832832813263,2.00232005119324,49.9665374755859,49.9665374755859,,,2.48877143859863,-99999999,1,0,0,0,0.0170135498046875,33.2355842590332,1,1,1,2.00069332122803,0,1816139072,2.00025285374035,,,0.0016854379989004,8.35715064242142E-5,0.00168549602724618,8.35716417846754E-5,0.944267988204956,0.944858014583588,26.0770130157471,0.187665611505508,30,4,200,-0.0609960369765758,-0.920237600803375,0.0401870384812355,1,,,,,,,,,,,,,,,,
,3826043023.74413,2.00114989280701,199.891372680664,,,6,,,,26.0463790893555,,,10,,,,,,,,,,,,,,,,,,,,,,1.99839234352112,2.00241041183472,199.891372680664,199.891372680664,,,2.48895025253296,-99999999,1,0,0,0,0.018157958984375,33.2355842590332,1,1,1,2.00107169151306,0,1816138784,2.00018846988678,,,0.00517213456311226,0.000256084741285583,0.00517217509150276,0.000256084796908185,0.985768854618072,0.986314594745636,26.0316467285156,0.187382370233536,30,4,200,-0.0367157272994518,-2.26384282112122,0.326393783092499,1,,,,,,,,,,,,,,,,
,3826043071.76449,2.00165486335754,449.875305175781,,,6,,,,26.0463790893555,,,10,,,,,,,,,,,,,,,,,,,,,,1.99848854541779,2.00218629837036,449.875305175781,449.875305175781,,,2.49002313613892,-99999999,1,0,0,0,0.020904541015625,32.7468223571777,1,1,1,2.00175833702087,0,1816138976,2.0001916885376,,,0.0107835288499367,0.000533901087754766,0.0107837177783412,0.000533901409666731,0.988257050514221,0.989798665046692,26.0244331359863,0.187371149659157,30,4,200,-0.0142031675204635,-4.4341459274292,0.656532227993011,1,,,,,,,,,,,,,,,,
,3826043130.67996,2.00126314163208,799.893188476563,,,6,,,,26.0463790893555,,,100,,,,,,,,,,,,,,,,,,,,,,1.99853098392487,2.00177669525146,799.893188476563,799.893188476563,,,2.4899206161499,-99999999,1,0,0,0,0.0185394287109375,33.2355842590332,1,1,1,2.00086069107056,0,1816138976,2.00013047998602,,,0.0173556336394462,0.000859324969726596,0.0173560465478836,0.000859325947567685,0.985276281833649,0.986904561519623,26.0209808349609,0.18739578127861,30,4,200,0.00022031128173694,-0.717749178409576,0.102369643747807,1,,,,,,,,,,,,,,,,
,3826043178.82963,2.00159358978271,1249.56689453125,,,6,,,,26.0463790893555,,,100,,,,,,,,,,,,,,,,,,,,,,1.99850583076477,2.00220155715942,1249.56689453125,1249.56689453125,,,2.48981904983521,-99999999,1,0,0,0,0.019683837890625,33.2355842590332,1,1,1,2.00098562240601,0,1816139040,2.00024149634621,,,0.0258780629984391,0.00128135075203356,0.0258788447839276,0.00128135317003818,0.982512593269348,0.984214603900909,26.0179862976074,0.187382623553276,30,4,200,0.00110396591480821,-1.05482459068298,0.172725006937981,1,,,,,,,,,,,,,,,,
,3826043227.70779,2.00159955024719,1799.57690429687,,,6,,,,26.0463790893555,,,100,,,,,,,,,,,,,,,,,,,,,,1.99857831001282,2.00212430953979,1799.57690429687,1799.57690429687,,,2.4880166053772,-99999999,1,0,0,0,0.0194549560546875,33.7243423461914,1,1,1,2.00131821632385,0,1816138976,2.00021812048825,,,0.0377744796232222,0.00187033051218368,0.0377753659372223,0.00187033256211797,0.984829902648926,0.986383557319641,26.0211448669434,0.187389075756073,30,4,200,0.00145230744965374,-1.56042087078094,0.22892764210701,1,,,,,,,,,,,,,,,,
,3826043277.30317,2.00165176391602,2450.32690429687,,,6,,,,26.0463790893555,,,100,,,,,,,,,,,,,,,,,,,,,,1.99803304672241,2.00220012664795,2450.32690429687,2450.32690429687,,,2.49063682556152,-99999999,1,0,0,0,0.0182342529296875,33.2355842590332,1,1,1,2.00145554542542,0,1816138912,2.00020720741966,,,0.0508429513137455,0.00251729824660975,0.050844095879994,0.00251730018179245,0.987478733062744,0.989355623722076,26.0215015411377,0.187377452850342,30,4,200,0.000971920206211507,-2.07876229286194,0.307328373193741,1,,,,,,,,,,,,,,,,
,3826043327.44171,2.00134217739105,3199.69897460937,,,6,,,,26.0463790893555,,,100,,,,,,,,,,,,,,,,,,,,,,1.99825417995453,2.00250601768494,3199.69897460937,3199.69897460937,,,2.48955392837524,-99999999,1,0,0,0,0.0186920166015625,33.2355842590332,1,1,1,2.00111269950867,0,1816138848,2.00021373141896,,,0.0624391621653473,0.00309145675557995,0.0624409207499955,0.00309145975919666,0.98708164691925,0.98939311504364,26.0185565948486,0.187387570738792,30,4,200,0.000810782250482589,-2.56020355224609,0.378433465957642,1,,,,,,,,,,,,,,,,
,3826043378.04819,2.00179493427277,4050.08813476562,,,6,,,,26.0463790893555,,,100,,,,,,,,,,,,,,,,,,,,,,1.99837791919708,2.00221300125122,4050.08813476562,4050.08813476562,,,2.49102520942688,-99999999,1,0,0,0,0.019989013671875,33.2355842590332,1,1,1,2.00137686729431,0,1816138816,2.00008917938579,,,0.0725751075370358,0.00359333276311318,0.0725777057780044,0.00359333767650881,0.986456096172333,0.989295661449432,26.0150718688965,0.1873859167099,30,4,200,0.000762590614613146,-2.97852969169617,0.435434967279434,1,,,,,,,,,,,,,,,,
,3826043428.95834,2.0014580488205,4999.89306640625,,,6,,,,26.0463790893555,,,100,,,,,,,,,,,,,,,,,,,,,,1.99814200401306,2.00253105163574,4999.89306640625,4999.89306640625,,,2.49021697044373,-99999999,1,0,0,0,0.019683837890625,33.2355842590332,1,1,1,2.00129795074463,0,1816138880,2.00017589872534,,,0.0810089195695343,0.0040109471580916,0.0810126433577428,0.0040109555567826,0.985749423503876,0.989260017871857,26.011043548584,0.187376290559769,30,4,200,0.000843673129566014,-3.31735014915466,0.491867184638977,1,,,,,,,,,,,,,,,,