File: data/AP424/MH_hyst1_8.dat
[Header]
; MPMS3 Data File (default extension .dat)
; Copyright (c) 2007, Quantum Design, Inc. All rights reserved.
TITLE,
FILEOPENTIME,3826036234.35486,03/27/2021,7:50 pm
BYAPP,SQUID AC,0.9.1.0
INFO,MPMS3 Measurement Release 1.1.16 Build 347, MultiVu Release 2.3.3.2,APPNAME
INFO,0,MOMENT_UNITS
INFO,SC_AP424,SAMPLE_MATERIAL
INFO,capsule nujol,SAMPLE_COMMENT
INFO,1,SAMPLE_MASS
INFO,,SAMPLE_VOLUME
INFO,,SAMPLE_MOLECULAR_WEIGHT
INFO,,SAMPLE_SIZE
INFO,,SAMPLE_SHAPE
INFO,Standard,SAMPLE_HOLDER
INFO,Standard,SAMPLE_HOLDER_DETAIL
INFO,68.35,SAMPLE_OFFSET
DATATYPE,COMMENT,1
DATATYPE,TIME,2
STARTUPAXIS,X,2
STARTUPAXIS,Y1,5
FIELDGROUP, VSM,2,3,4,5,6,8,9,10,11,14,15
FIELDGROUP, DC, 2,3,4,14,56,57,58,59,60,61,62,63,64,65,66,67,68,69
FIELDGROUP, AC, 2,3,4,11,16,17,18,19,20,21,22,23,24,25,26,27,28,29,30
STARTUPGROUP, All
[Data]
Comment,Time Stamp (sec),Temperature (K),Magnetic Field (Oe),Moment (emu),M. Std. Err. (emu),Transport Action,Averaging Time (sec),Frequency (Hz),Peak Amplitude (mm),Center Position (mm),Lockin Signal' (V),Lockin Signal (V),Range,M. Quad. Signal (emu),AC Moment (emu),AC M. Std Err. (emu),AC Phase (deg),AC Phase Std. Err. (deg),AC Susceptibility (emu/Oe),AC Suscept. Std Err. (emu/Oe),AC X' (emu/Oe),AC X' Std Err. (emu/Oe),AC X'' (emu/Oe),AC X'' Std Err. (emu/Oe),AC Drive (Oe),AC Frequency (Hz),AC Averaging Time (sec),AC Cycles,AC Range,AC Measure Type,AC Signal' (V),AC Signal'' (V),AC Trim Coil Ratio,AC Trim Coil Phase,Min. Temperature (K),Max. Temperature (K),Min. Field (Oe),Max. Field (Oe),Mass (grams),Motor Lag (deg),Pressure (Torr),Measure Count,Measurement Number,SQUID Status (code),Motor Status (code),Measure Status (code),Motor Current (amps),Motor Temp. (C),Temp. Status (code),Field Status (code),Chamber Status (code),Chamber Temp (K),Redirection State,Evercool Status,Average Temp (K),Rotation Angle (deg),Rotator state,DC Moment Fixed Ctr (emu),DC Moment Err Fixed Ctr (emu),DC Moment Free Ctr (emu),DC Moment Err Free Ctr (emu),DC Fixed Fit,DC Free Fit,DC Calculated Center (mm),DC Calculated Center Err (mm),DC Scan Length (mm),DC Scan Time (s),DC Number of Points,DC Squid Drift,DC Min V (V),DC Max V (V),DC Scans per Measure,Map 01,Map 02,Map 03,Map 04,Map 05,Map 06,Map 07,Map 08,Map 09,Map 10,Map 11,Map 12,Map 13,Map 14,Map 15,Map 16
,3826037257.792,1.80218118429184,-0.0882355645298958,,,6,,,,26.0463790893555,,,1,,,,,,,,,,,,,,,,,,,,,,1.79834449291229,1.80242264270782,-0.0882355645298958,-0.0882355645298958,,,2.30850005149841,-99999999,1,0,0,0,0.0189208984375,33.2355842590332,1,1,1,1.80193972587585,0,1816138944,1.80008728163583,,,5.37607269867048E-5,2.66180647903958E-6,5.37623970007188E-5,2.6618123482092E-6,0.98617696762085,0.988451421260834,26.0177040100098,0.187378644943237,30,4,200,5.18280212418176E-5,-0.00105948117561638,0.281864792108536,1,,,,,,,,,,,,,,,,
,3826037315.88143,1.80213922262192,49.8909072875977,,,6,,,,26.0463790893555,,,10,,,,,,,,,,,,,,,,,,,,,,1.7981344461441,1.80270636081696,49.8909072875977,49.8909072875977,,,2.31307601928711,-99999999,1,0,0,0,0.0211334228515625,32.7468223571777,1,1,1,1.80157208442688,0,1816138944,1.8001031989143,,,0.00136611064622955,6.76376523230773E-5,0.00136613964282806,6.76377540345225E-5,0.987736165523529,0.98946613073349,26.0226821899414,0.187386497855186,30,4,200,0.000158108610776253,-4.87958002090454,4.83764410018921,1,,,,,,,,,,,,,,,,
,3826037369.51868,1.80200898647308,199.664474487305,,,6,,,,26.0463790893555,,,10,,,,,,,,,,,,,,,,,,,,,,1.79786062240601,1.80245101451874,199.664474487305,199.664474487305,,,2.31392121315002,-99999999,1,0,0,0,0.01861572265625,31.7693061828613,1,1,1,1.80156695842743,0,1816139008,1.80017478899522,,,0.0052904768305384,0.000261937334820508,0.00529058518236407,0.000261937597907444,0.987744212150574,0.989452123641968,26.0228328704834,0.187369614839554,30,4,200,0.000684476341120899,-2.12278127670288,0.361835330724716,1,,,,,,,,,,,,,,,,
,3826037418.30145,1.80226677656174,449.6484375,,,6,,,,26.0463790893555,,,10,,,,,,,,,,,,,,,,,,,,,,1.79819989204407,1.80282509326935,449.6484375,449.6484375,,,2.31534957885742,-99999999,1,0,0,0,0.019073486328125,32.7468223571777,1,1,1,1.80170845985413,0,1816139072,1.80031021074815,,,0.0116366770354403,0.000576143156075042,0.011636928912889,0.000576143958681098,0.987937390804291,0.989752650260925,26.0223655700684,0.187384396791458,30,4,200,0.00195467169396579,-4.8094162940979,0.646066963672638,1,,,,,,,,,,,,,,,,
,3826037477.29398,1.8023527264595,799.754516601562,,,6,,,,26.0463790893555,,,100,,,,,,,,,,,,,,,,,,,,,,1.79868566989899,1.80297696590424,799.754516601562,799.754516601562,,,2.31619763374329,-99999999,1,0,0,0,0.019683837890625,33.2355842590332,1,1,1,1.80172848701477,0,1816138976,1.80031740665436,,,0.0188759903501123,0.000934599597107922,0.0188766004040499,0.000934601140184109,0.985474646091461,0.987766325473785,26.01682472229,0.187400966882706,30,4,200,0.000267705821897835,-0.775726079940796,0.114677399396896,1,,,,,,,,,,,,,,,,
,3826037527.02348,1.80180436372757,1249.52905273438,,,6,,,,26.0463790893555,,,100,,,,,,,,,,,,,,,,,,,,,,1.79789698123932,1.80249547958374,1249.52905273438,1249.52905273438,,,2.31872940063477,-99999999,1,0,0,0,0.017242431640625,33.2355842590332,1,1,1,1.80158472061157,0,1816138976,1.80012838406996,,,0.0282257682421226,0.00139758905058925,0.0282266734572519,0.00139759189448165,0.98287171125412,0.984725058078766,26.0171337127686,0.187402725219727,30,4,200,-0.00015935990086291,-1.16571307182312,0.171257212758064,1,,,,,,,,,,,,,,,,
,3826037575.8227,1.80166441202164,1799.70300292969,,,6,,,,26.0463790893555,,,100,,,,,,,,,,,,,,,,,,,,,,1.7976815700531,1.80284869670868,1799.70300292969,1799.70300292969,,,2.3196976184845,-99999999,1,0,0,0,0.0202178955078125,33.2355842590332,1,1,1,1.80105602741241,0,1816137728,1.8000538891012,,,0.0410502119202676,0.00203254723254933,0.0410513319512086,0.00203255119865807,0.984023809432983,0.98569667339325,26.0195217132568,0.187400221824646,30,4,200,0.000131669541588053,-1.69734179973602,0.244284391403198,1,,,,,,,,,,,,,,,,
,3826037625.70451,1.80190706253052,2450.23852539062,,,6,,,,26.0463790893555,,,100,,,,,,,,,,,,,,,,,,,,,,1.79786145687103,1.80281388759613,2450.23852539062,2450.23852539062,,,2.32144260406494,-99999999,1,0,0,0,0.01861572265625,32.7468223571777,1,1,1,1.8011771440506,0,1816139104,1.80019076304002,,,0.0553553409546484,0.00274072316099138,0.0553568188333011,0.00274072750953887,0.987169682979584,0.98930412530899,26.019645690918,0.187362805008888,30,4,200,0.00102138111833483,-2.26495981216431,0.334499329328537,1,,,,,,,,,,,,,,,,
,3826037675.53182,1.80234533548355,3199.85009765625,,,6,,,,26.0463790893555,,,100,,,,,,,,,,,,,,,,,,,,,,1.7982702255249,1.80256938934326,3199.85009765625,3199.85009765625,,,2.32261061668396,-99999999,1,0,0,0,0.020751953125,32.7468223571777,1,1,1,1.80171501636505,0,1816139072,1.80012534965168,,,0.0673756087905736,0.00333587918090264,0.0673778900820558,0.00333588567488763,0.986827433109283,0.989526212215424,26.0162391662598,0.187382012605667,30,4,200,0.000797164859250188,-2.75767636299133,0.401965379714966,1,,,,,,,,,,,,,,,,
,3826037725.56745,1.80232286453247,4049.87353515625,,,6,,,,26.0463790893555,,,100,,,,,,,,,,,,,,,,,,,,,,1.79820716381073,1.80239152908325,4049.87353515625,4049.87353515625,,,2.32068061828613,-99999999,1,0,0,0,0.01922607421875,32.7468223571777,1,1,1,1.80201089382172,0,1816138816,1.80021843043241,,,0.0772826444402887,0.00382643406630494,0.0772860619220172,0.00382644418958117,0.986013889312744,0.98939448595047,26.0119800567627,0.187377437949181,30,4,200,0.000740420480724424,-3.17360687255859,0.460694134235382,1,,,,,,,,,,,,,,,,
,3826037776.51272,1.80192488431931,4999.9189453125,,,6,,,,26.0463790893555,,,100,,,,,,,,,,,,,,,,,,,,,,1.79850995540619,1.80225837230682,4999.9189453125,4999.9189453125,,,2.32422256469727,-99999999,1,0,0,0,0.018768310546875,33.2355842590332,1,1,1,1.80159139633179,0,1816138880,1.80020062489943,,,0.0851513485595493,0.00421608560134744,0.0851561776071358,0.00421609933549402,0.985152959823608,0.989344120025635,26.0073738098145,0.18738380074501,30,4,200,0.000935374991968274,-3.49650716781616,0.517103254795074,1,,,,,,,,,,,,,,,,
,3826037828.02692,1.80204224586487,4050.39038085937,,,6,,,,26.0463790893555,,,100,,,,,,,,,,,,,,,,,,,,,,1.79835522174835,1.80285942554474,4050.39038085937,4050.39038085937,,,2.32502174377441,-99999999,1,0,0,0,0.0188446044921875,32.7468223571777,1,1,1,1.80180311203003,0,1816139072,1.80004995519465,,,0.0771769998207074,0.00382119922556867,0.0771803286844666,0.00382120944154965,0.986100018024445,0.989402592182159,26.0124397277832,0.187397703528404,30,4,200,-0.00115470832679421,-3.16797757148743,0.463434666395187,1,,,,,,,,,,,,,,,,
,3826037878.63712,1.80173623561859,3200.0517578125,,,6,,,,26.0463790893555,,,100,,,,,,,,,,,,,,,,,,,,,,1.79831898212433,1.80220305919647,3200.0517578125,3200.0517578125,,,2.32529377937317,-99999999,1,0,0,0,0.0186920166015625,32.7468223571777,1,1,1,1.80126941204071,0,1816138880,1.80021079020067,,,0.0672282838815144,0.00332858850694952,0.0672305654344489,0.00332859498390443,0.98673814535141,0.989421546459198,26.0162010192871,0.187384620308876,30,4,200,-0.000178210204467177,-2.76034998893738,0.400687515735626,1,,,,,,,,,,,,,,,,
,3826037927.20204,1.80191385746002,2450.35205078125,,,6,,,,26.0463790893555,,,100,,,,,,,,,,,,,,,,,,,,,,1.79824078083038,1.80237424373627,2450.35205078125,2450.35205078125,,,2.32537531852722,-99999999,1,0,0,0,0.0182342529296875,32.7468223571777,1,1,1,1.80145347118378,0,1816138944,1.80017104148865,,,0.0561011628396507,0.00277766944966249,0.0561026491511433,0.00277767328740061,0.986625254154205,0.988656759262085,26.0196418762207,0.187380433082581,30,4,200,-0.000354675459675491,-2.31621265411377,0.339139938354492,1,,,,,,,,,,,,,,,,
,3826037975.84533,1.80203300714493,1799.79125976562,,,6,,,,26.0463790893555,,,100,,,,,,,,,,,,,,,,,,,,,,1.79834628105164,1.80269336700439,1799.79125976562,1799.79125976562,,,2.32467770576477,-99999999,1,0,0,0,0.01922607421875,32.7468223571777,1,1,1,1.80137264728546,0,1816138944,1.80023832754655,,,0.0450086974574982,0.00222849888777361,0.045009565204234,0.00222850108583173,0.985435783863068,0.986750960350037,26.0235557556152,0.187400549650192,30,4,200,-0.000466065626824275,-1.85936760902405,0.270617008209229,1,,,,,,,,,,,,,,,,
,3826038024.68036,1.8021981716156,1249.76843261719,,,6,,,,26.0463790893555,,,100,,,,,,,,,,,,,,,,,,,,,,1.79784977436066,1.80216467380524,1249.76843261719,1249.76843261719,,,2.32439613342285,-99999999,1,0,0,0,0.0205230712890625,33.2355842590332,1,1,1,1.80223655700684,0,1816139040,1.80007325519215,,,0.0343518806201035,0.00170088303538753,0.0343522711270798,0.00170088440935274,0.984224021434784,0.984908044338226,26.0290393829346,0.187386885285378,30,4,200,-0.000368276028893888,-1.42050981521606,0.208282455801964,1,,,,,,,,,,,,,,,,
,3826038073.59307,1.80217814445496,800.057006835938,,,6,,,,26.0463790893555,,,100,,,,,,,,,,,,,,,,,,,,,,1.79810965061188,1.80256748199463,800.057006835938,800.057006835938,,,2.32819080352783,-99999999,1,0,0,0,0.019073486328125,32.7468223571777,1,1,1,1.80178880691528,0,1816139072,1.8001135262576,,,0.0232183557426019,0.00114964479009745,0.0232185350569427,0.00114964548735789,0.983055651187897,0.983480870723724,26.0321445465088,0.187389463186264,30,4,200,0.00048052507918328,-0.963340520858765,0.138499885797501,1,,,,,,,,,,,,,,,,
,3826038121.56539,1.80228072404861,449.824890136719,,,6,,,,26.0463790893555,,,100,,,,,,,,,,,,,,,,,,,,,,1.79820764064789,1.80233061313629,449.824890136719,449.824890136719,,,2.3265495300293,-99999999,1,0,0,0,0.0197601318359375,32.2580642700195,1,1,1,1.80223083496094,0,1816139040,1.80011425235055,,,0.0114799215239692,0.000568405415153421,0.0114801427233477,0.000568405993814764,0.984918773174286,0.986181497573853,26.0235843658447,0.187392577528954,30,4,200,0.00188318185973912,-0.475387364625931,0.0694596171379089,1,,,,,,,,,,,,,,,,
,3826038169.60256,1.80191320180893,199.853546142578,,,6,,,,26.0463790893555,,,100,,,,,,,,,,,,,,,,,,,,,,1.79830265045166,1.80267715454102,199.853546142578,199.853546142578,,,2.32842493057251,-99999999,1,0,0,0,0.0182342529296875,33.2355842590332,1,1,1,1.80148267745972,0,1816138944,1.80027810010043,,,0.00465228425585361,0.00023035485425147,0.00465248183076089,0.000230355435437466,0.983228147029877,0.985807597637177,26.0126724243164,0.187384679913521,30,4,200,0.00369189353659749,-0.183815225958824,0.0414209216833115,1,,,,,,,,,,,,,,,,
,3826038228.53234,1.80133634805679,49.9917488098145,,,6,,,,26.0463790893555,,,10,,,,,,,,,,,,,,,,,,,,,,1.79833650588989,1.80256819725037,49.9917488098145,49.9917488098145,,,2.32770109176636,-99999999,1,0,0,0,0.0183868408203125,32.2580642700195,1,1,1,1.80129849910736,0,1816139008,1.80019941329956,,,0.000765254899971914,3.81127137574117E-5,0.000765719049451702,3.81138329750043E-5,0.891030251979828,0.896397411823273,25.9187469482422,0.188493102788925,30,4,200,0.0542458966374397,-0.219924584031105,0.268519848585129,1,,,,,,,,,,,,,,,,
,3826038275.83985,1.80210024118423,-0.201681286096573,,,6,,,,26.0463790893555,,,10,,,,,,,,,,,,,,,,,,,,,,1.79837930202484,1.80275368690491,-0.201681286096573,-0.201681286096573,,,2.33040428161621,-99999999,1,0,0,0,0.0186920166015625,32.7468223571777,1,1,1,1.80144679546356,0,1816138752,1.80020429871299,,,-0.000565919587403237,2.81724075014368E-5,-0.000566055416417522,2.81726992053641E-5,0.895177781581879,0.897367775440216,26.1276760101318,0.18841227889061,30,4,200,0.0501504093408585,-0.0402079671621323,0.364699482917786,1,,,,,,,,,,,,,,,,
,3826038323.86848,1.80201798677444,-49.5127563476562,,,6,,,,26.0463790893555,,,10,,,,,,,,,,,,,,,,,,,,,,1.79836118221283,1.80264723300934,-49.5127563476562,-49.5127563476562,,,2.32826280593872,-99999999,1,0,0,0,0.0194549560546875,32.7468223571777,1,1,1,1.80138874053955,0,1816138944,1.80031755837527,,,-0.00182698005101594,9.05748387534564E-5,-0.0018270411298517,9.05749940413278E-5,0.947303891181946,0.947907567024231,26.0764980316162,0.187617167830467,30,4,200,0.061324629932642,-0.0753892734646797,0.952434539794922,1,,,,,,,,,,,,,,,,
,3826038371.42153,1.80179351568222,-200.030029296875,,,6,,,,26.0463790893555,,,10,,,,,,,,,,,,,,,,,,,,,,1.79821300506592,1.80223727226257,-200.030029296875,-200.030029296875,,,2.33208465576172,-99999999,1,0,0,0,0.0209808349609375,32.7468223571777,1,1,1,1.80134975910187,0,1816138848,1.80013065988367,,,-0.00574812353828031,0.000284600488389779,-0.00574817437232826,0.000284600709874545,0.986487805843353,0.987098395824432,26.0312194824219,0.187384143471718,30,4,200,0.0375833474099636,-0.284403115510941,2.4791693687439,1,,,,,,,,,,,,,,,,
,3826038425.03917,1.80211061239243,-450.215637207031,,,6,,,,26.0463790893555,,,100,,,,,,,,,,,,,,,,,,,,,,1.79841887950897,1.80249834060669,-450.215637207031,-450.215637207031,,,2.33366894721985,-99999999,1,0,0,0,0.0164794921875,32.7468223571777,1,1,1,1.80172288417816,0,1816138912,1.80011912754604,,,-0.0121064522863118,0.000599401120076478,-0.0121066965092536,0.000599402028274271,0.988103270530701,0.989791095256805,26.0233306884766,0.187380999326706,30,4,200,0.00101299048401415,-4.84411144256592,4.93465280532837,1,,,,,,,,,,,,,,,,
,3826038478.8451,1.80196934938431,-800.082275390625,,,6,,,,26.0463790893555,,,100,,,,,,,,,,,,,,,,,,,,,,1.79845368862152,1.80226874351501,-800.082275390625,-800.082275390625,,,2.33312153816223,-99999999,1,0,0,0,0.0193023681640625,32.7468223571777,1,1,1,1.80194163322449,0,1816138848,1.80014146458019,,,-0.0190953102275149,0.000945460248224422,-0.0190958280487245,0.000945461741329562,0.985341370105743,0.98720121383667,26.0194129943848,0.187392428517342,30,4,200,-0.000380440411390737,-0.117002584040165,0.78508472442627,1,,,,,,,,,,,,,,,,
,3826038527.33964,1.8025324344635,-1249.81884765625,,,6,,,,26.0463790893555,,,100,,,,,,,,,,,,,,,,,,,,,,1.79789292812347,1.80271172523499,-1249.81884765625,-1249.81884765625,,,2.33409953117371,-99999999,1,0,0,0,0.018463134765625,33.2355842590332,1,1,1,1.80235314369202,0,1816138976,1.80019368908622,,,-0.028291334759372,0.00140085399958104,-0.028292236018456,0.00140085585786459,0.982114136219025,0.983910739421844,26.0168972015381,0.187394261360168,30,4,200,-0.001297039212659,-0.180502146482468,1.16248750686646,1,,,,,,,,,,,,,,,,
,3826038575.95829,1.80214786529541,-1800.06848144531,,,6,,,,26.0463790893555,,,100,,,,,,,,,,,,,,,,,,,,,,1.79832077026367,1.80279064178467,-1800.06848144531,-1800.06848144531,,,2.33392906188965,-99999999,1,0,0,0,0.0203704833984375,32.7468223571777,1,1,1,1.80150508880615,0,1816138880,1.80021662061865,,,-0.041218487371386,0.00204088002346219,-0.0412195872550866,0.00204088359334126,0.984019815921783,0.985664427280426,26.0197372436523,0.187383338809013,30,4,200,-0.00171103212051094,-0.258376598358154,1.69282341003418,1,,,,,,,,,,,,,,,,
,3826038625.36931,1.80180531740189,-2450.41479492187,,,6,,,,26.0463790893555,,,100,,,,,,,,,,,,,,,,,,,,,,1.79839134216309,1.80247890949249,-2450.41479492187,-2450.41479492187,,,2.3345639705658,-99999999,1,0,0,0,0.0138092041015625,32.7468223571777,1,1,1,1.80113172531128,0,1816138944,1.80017368359999,,,-0.0553719765117297,0.00274154662908217,-0.0553733964141849,0.00274155080787342,0.987195134162903,0.989242017269134,26.0201778411865,0.187375456094742,30,4,200,-0.00120350462384522,-0.340664833784103,2.26148366928101,1,,,,,,,,,,,,,,,,
,3826038675.18787,1.80169522762299,-3200.20288085937,,,6,,,,26.0463790893555,,,100,,,,,,,,,,,,,,,,,,,,,,1.79841315746307,1.80212354660034,-3200.20288085937,-3200.20288085937,,,2.33467650413513,-99999999,1,0,0,0,0.0152587890625,33.2355842590332,1,1,1,1.80126690864563,0,1816138752,1.80020779913122,,,-0.0673513202060982,0.00333467383440213,-0.0673534863765726,0.00333467854585453,0.98689728975296,0.989502787590027,26.0167922973633,0.187387436628342,30,4,200,-0.000838304753415287,-0.410650789737701,2.75750303268433,1,,,,,,,,,,,,,,,,
,3826038726.13046,1.80279463529587,-4050.44091796875,,,6,,,,26.0463790893555,,,100,,,,,,,,,,,,,,,,,,,,,,1.79786729812622,1.80247032642365,-4050.44091796875,-4050.44091796875,,,2.33579707145691,-99999999,1,0,0,0,0.0177001953125,33.2355842590332,1,1,1,1.80254554748535,0,1816139040,1.80020532608032,,,-0.0772593615218643,0.0038252787832827,-0.0772626694819585,0.00382528782682119,0.986077606678009,0.989372551441193,26.0124454498291,0.187389761209488,30,4,200,-0.000775911670643836,-0.469477474689484,3.16429781913757,1,,,,,,,,,,,,,,,,
,3826038777.42429,1.8022677898407,-4999.93115234375,,,6,,,,26.0463790893555,,,100,,,,,,,,,,,,,,,,,,,,,,1.79813158512115,1.80246031284332,-4999.93115234375,-4999.93115234375,,,2.33317637443542,-99999999,1,0,0,0,0.0193023681640625,32.7468223571777,1,1,1,1.80207526683807,0,1816139136,1.80027644634247,,,-0.0851323983972123,0.00421514070669034,-0.0851370076624187,0.00421515085894216,0.985247194766998,0.989313662052154,26.0080051422119,0.187393113970757,30,4,200,-0.00085952109657228,-0.519650757312775,3.48248147964478,1,,,,,,,,,,,,,,,,
,3826038828.49156,1.80194413661957,-4050.44091796875,,,6,,,,26.0463790893555,,,100,,,,,,,,,,,,,,,,,,,,,,1.79838287830353,1.80281758308411,-4050.44091796875,-4050.44091796875,,,2.33470463752747,-99999999,1,0,0,0,0.01800537109375,32.7468223571777,1,1,1,1.80107069015503,0,1816138976,1.80015229095112,,,-0.0771516581498439,0.00381993895323659,-0.0771548120354584,0.00381994657497438,0.986227333545685,0.989420175552368,26.013111114502,0.187370806932449,30,4,200,0.0012914874823764,-0.459257781505585,3.17059183120728,1,,,,,,,,,,,,,,,,
,3826038879.61358,1.8022221326828,-3200.27856445313,,,6,,,,26.0463790893555,,,100,,,,,,,,,,,,,,,,,,,,,,1.79829061031342,1.80253672599792,-3200.27856445313,-3200.27856445313,,,2.33437633514404,-99999999,1,0,0,0,0.019378662109375,32.7468223571777,1,1,1,1.80190753936768,0,1816138912,1.80020469968969,,,-0.0671823638758073,0.00332631059048066,-0.0671845210032529,0.00332631440402159,0.986827611923218,0.989435970783234,26.0166893005371,0.18738380074501,30,4,200,0.000212527345865965,-0.402393311262131,2.75616264343262,1,,,,,,,,,,,,,,,,
,3826038929.86557,1.80170011520386,-2450.40234375,,,6,,,,26.0463790893555,,,100,,,,,,,,,,,,,,,,,,,,,,1.79837667942047,1.8022757768631,-2450.40234375,-2450.40234375,,,2.33425235748291,-99999999,1,0,0,0,0.020599365234375,32.7468223571777,1,1,1,1.80143332481384,0,1816139200,1.8001855395057,,,-0.055987086459177,0.0027720135284204,-0.0559885575506231,0.00277201896230937,0.986851692199707,0.988852977752686,26.0200710296631,0.18736532330513,30,4,200,0.000364200212061405,-0.335198283195496,2.30353426933289,1,,,,,,,,,,,,,,,,
,3826038979.8588,1.80209875106812,-1800.01818847656,,,6,,,,26.0463790893555,,,100,,,,,,,,,,,,,,,,,,,,,,1.79848897457123,1.80242800712585,-1800.01818847656,-1800.01818847656,,,2.33413457870483,-99999999,1,0,0,0,0.01861572265625,32.7468223571777,1,1,1,1.80176949501038,0,1816138880,1.80024235898798,,,-0.0450280052276534,0.00222946012964797,-0.0450288250139541,0.00222946164451011,0.985282719135284,0.986525893211365,26.0240421295166,0.187374383211136,30,4,200,0.000489715195726603,-0.270926475524902,1.86042261123657,1,,,,,,,,,,,,,,,,
,3826039028.18293,1.80217307806015,-1250.08361816406,,,6,,,,26.0463790893555,,,100,,,,,,,,,,,,,,,,,,,,,,1.79848897457123,1.80260133743286,-1250.08361816406,-1250.08361816406,,,2.33328127861023,-99999999,1,0,0,0,0.0185394287109375,32.7468223571777,1,1,1,1.80174481868744,0,1816138880,1.80027705972845,,,-0.0343327590421751,0.00169993768070106,-0.0343331219293029,0.00169993856435366,0.984173893928528,0.984822034835815,26.0294628143311,0.1873869150877,30,4,200,0.000405411701649427,-0.205367758870125,1.4255256652832,1,,,,,,,,,,,,,,,,
,3826039076.06203,1.80219006538391,-800.435180664062,,,6,,,,26.0463790893555,,,100,,,,,,,,,,,,,,,,,,,,,,1.79813015460968,1.8023464679718,-800.435180664062,-800.435180664062,,,2.33482718467712,-99999999,1,0,0,0,0.0189971923828125,32.7468223571777,1,1,1,1.80203366279602,0,1816138912,1.80021822452545,,,-0.0231993526156742,0.00114870472697429,-0.0231995135770414,0.00114870502221169,0.9830202460289,0.98341828584671,26.0325870513916,0.187403798103333,30,4,200,-0.000438860675785691,-0.137538924813271,0.963617503643036,1,,,,,,,,,,,,,,,,
,3826039124.86332,1.80222761631012,-450.518157958984,,,6,,,,26.0463790893555,,,100,,,,,,,,,,,,,,,,,,,,,,1.79830992221832,1.80277574062347,-450.518157958984,-450.518157958984,,,2.33513402938843,-99999999,1,0,0,0,0.0197601318359375,33.2355842590332,1,1,1,1.80167949199677,0,1816138944,1.80019308220256,,,-0.0114279266785859,0.000565830864378363,-0.0114281457595909,0.00056583130526997,0.984926104545593,0.986199736595154,26.023494720459,0.187398627400398,30,4,200,-0.00200421432964504,-0.0793829709291458,0.463245183229446,1,,,,,,,,,,,,,,,,
,3826039173.2023,1.80192279815674,-200.156066894531,,,6,,,,26.0463790893555,,,100,,,,,,,,,,,,,,,,,,,,,,1.79807949066162,1.80258691310883,-200.156066894531,-200.156066894531,,,2.33354234695435,-99999999,1,0,0,0,0.020294189453125,33.2355842590332,1,1,1,1.80125868320465,0,1816138976,1.80014135620811,,,-0.0046090914716605,0.000228216111697852,-0.00460928879170187,0.000228216773333921,0.983226597309113,0.985803365707398,26.0126876831055,0.187373012304306,30,4,200,-0.00372648588381708,-0.0444385372102261,0.178909778594971,1,,,,,,,,,,,,,,,,
,3826039231.33504,1.80251520872116,-50.3194808959961,,,6,,,,26.0463790893555,,,10,,,,,,,,,,,,,,,,,,,,,,1.79821026325226,1.80288302898407,-50.3194808959961,-50.3194808959961,,,2.33695888519287,-99999999,1,0,0,0,0.0205230712890625,33.2355842590332,1,1,1,1.80214738845825,0,1816138944,1.80024008317427,,,-0.00072736181134017,3.61941755051219E-5,-0.000727773317737015,3.6195176955078E-5,0.899188220500946,0.904619038105011,25.9230613708496,0.188317373394966,30,4,200,-0.0531948693096638,-0.312710672616959,0.156696528196335,1,,,,,,,,,,,,,,,,
,3826039279.23197,1.801966547966,-0.201681286096573,,,6,,,,26.0463790893555,,,10,,,,,,,,,,,,,,,,,,,,,,1.79848122596741,1.80263030529022,-0.201681286096573,-0.201681286096573,,,2.33695363998413,-99999999,1,0,0,0,0.019683837890625,32.7468223571777,1,1,1,1.80130279064178,0,1816138848,1.80033824443817,,,0.000605558947465702,3.01184319676458E-5,0.000605664065830666,3.01186325672952E-5,0.904106318950653,0.905847012996674,26.1156539916992,0.18823429942131,30,4,200,-0.0484313108026981,-0.407096892595291,-0.00398927135393023,1,,,,,,,,,,,,,,,,
,3826039326.48662,1.80200099945068,50.1682205200195,,,6,,,,26.0463790893555,,,10,,,,,,,,,,,,,,,,,,,,,,1.79837429523468,1.80239582061768,50.1682205200195,50.1682205200195,,,2.33661460876465,-99999999,1,0,0,0,0.0191497802734375,32.7468223571777,1,1,1,1.80160617828369,0,1816138880,1.8002603595907,,,0.00189231363435925,9.37929254788764E-5,0.00189235266973305,9.37930489104261E-5,0.951703906059265,0.952104508876801,26.0698795318604,0.187577456235886,30,4,200,-0.0609894581139088,-0.977253913879395,0.0838606730103493,1,,,,,,,,,,,,,,,,
,3826039374.41925,1.80222034454346,200.130859375,,,6,,,,26.0463790893555,,,10,,,,,,,,,,,,,,,,,,,,,,1.79812562465668,1.80296730995178,200.130859375,200.130859375,,,2.33667469024658,-99999999,1,0,0,0,0.0189971923828125,33.2355842590332,1,1,1,1.80147337913513,0,1816139200,1.80022686178034,,,0.00580266305416985,0.0002873015966152,0.00580271655969656,0.000287301736628827,0.986279845237732,0.98693174123764,26.0306034088135,0.187394484877586,30,4,200,-0.0381771922111511,-2.45406055450439,0.336366415023804,1,,,,,,,,,,,,,,,,
,3826039427.75393,1.80215299129486,449.887908935547,,,6,,,,26.0463790893555,,,100,,,,,,,,,,,,,,,,,,,,,,1.79825174808502,1.80269384384155,449.887908935547,449.887908935547,,,2.33646464347839,-99999999,1,0,0,0,0.0185394287109375,32.7468223571777,1,1,1,1.80161213874817,0,1816138944,1.80008548498154,,,0.0121395208627947,0.000601038215082919,0.0121397543648064,0.000601038805787106,0.988115668296814,0.989765822887421,26.0235824584961,0.187375098466873,30,4,200,-0.0010056730825454,-4.93856763839722,4.84279489517212,1,,,,,,,,,,,,,,,,
,3826039481.01671,1.8020686507225,800.069641113281,,,6,,,,26.0463790893555,,,100,,,,,,,,,,,,,,,,,,,,,,1.79843711853027,1.8022186756134,800.069641113281,800.069641113281,,,2.33428001403809,-99999999,1,0,0,0,0.01922607421875,32.7468223571777,1,1,1,1.80196893215179,0,1816139072,1.80020441792228,,,0.0191254018295501,0.000946952637212065,0.0191259747644646,0.000946954129434638,0.985163867473602,0.987218737602234,26.017951965332,0.187386736273766,30,4,200,4.73557229270227E-5,-0.79174417257309,0.110890448093414,1,,,,,,,,,,,,,,,,
,3826039528.81789,1.80213862657547,1249.78100585938,,,6,,,,26.0463790893555,,,100,,,,,,,,,,,,,,,,,,,,,,1.7983250617981,1.8027206659317,1249.78100585938,1249.78100585938,,,2.33794474601746,-99999999,1,0,0,0,0.02044677734375,33.2355842590332,1,1,1,1.80188512802124,0,1816139008,1.8001746264371,,,0.0283027867260103,0.00140141903488716,0.0283036422391268,0.00140142121057555,0.982191979885101,0.983881890773773,26.0178031921387,0.187413111329079,30,4,200,0.0010322832968086,-1.17393779754639,0.1696657538414,1,,,,,,,,,,,,,,,,
,3826039577.85698,1.80225163698196,1799.74072265625,,,6,,,,26.0463790893555,,,100,,,,,,,,,,,,,,,,,,,,,,1.79824841022491,1.80291545391083,1799.74072265625,1799.74072265625,,,2.33420062065125,-99999999,1,0,0,0,0.0206756591796875,33.2355842590332,1,1,1,1.8015878200531,0,1816138848,1.80022442340851,,,0.0413366063140511,0.00204671904966698,0.041337685328475,0.00204672201189251,0.98430722951889,0.985965609550476,26.0198841094971,0.187393054366112,30,4,200,0.00159307732246816,-1.7033429145813,0.252522379159927,1,,,,,,,,,,,,,,,,
,3826039627.77879,1.80230700969696,2450.3896484375,,,6,,,,26.0463790893555,,,100,,,,,,,,,,,,,,,,,,,,,,1.79798901081085,1.80276989936829,2450.3896484375,2450.3896484375,,,2.33584904670715,-99999999,1,0,0,0,0.01861572265625,32.7468223571777,1,1,1,1.80184412002563,0,1816138816,1.80024981498718,,,0.055452864952212,0.00274554695771863,0.0554542533380032,0.00274554957349374,0.987307012081146,0.989372193813324,26.0201950073242,0.187382623553276,30,4,200,0.0010760334553197,-2.26955389976501,0.33366659283638,1,,,,,,,,,,,,,,,,
,3826039677.81447,1.80207914113998,3199.85009765625,,,6,,,,26.0463790893555,,,100,,,,,,,,,,,,,,,,,,,,,,1.79831027984619,1.80270445346832,3199.85009765625,3199.85009765625,,,2.33750915527344,-99999999,1,0,0,0,0.0201416015625,33.2355842590332,1,1,1,1.80145382881165,0,1816138944,1.80028792944821,,,0.0673617407532206,0.00333519064845119,0.0673639003547921,0.00333519523636229,0.986890196800232,0.989487707614899,26.0168266296387,0.187373116612434,30,4,200,0.000805495714303106,-2.7588632106781,0.399951279163361,1,,,,,,,,,,,,,,,,
,3826039728.24944,1.80222749710083,4050.18872070313,,,6,,,,26.0463790893555,,,100,,,,,,,,,,,,,,,,,,,,,,1.79798913002014,1.80236566066742,4050.18872070313,4050.18872070313,,,2.33771276473999,-99999999,1,0,0,0,0.0185394287109375,32.7468223571777,1,1,1,1.80208933353424,0,1816139072,1.80017309839075,,,0.0772653331072865,0.00382557208032769,0.0772685807840977,0.00382557950774277,0.986118793487549,0.989392518997192,26.0125961303711,0.187394559383392,30,4,200,0.000763401680160314,-3.17475414276123,0.469203025102615,1,,,,,,,,,,,,,,,,
,3826039778.85117,1.80225318670273,4999.9814453125,,,6,,,,26.0463790893555,,,100,,,,,,,,,,,,,,,,,,,,,,1.79828381538391,1.8029180765152,4999.9814453125,4999.9814453125,,,2.33459186553955,-99999999,1,0,0,0,0.0199127197265625,32.7468223571777,1,1,1,1.80158829689026,0,1816138944,1.80015316876498,,,0.0851338088642233,0.00421520968423303,0.0851384793392919,0.00421522275403866,0.985260367393494,0.989334285259247,26.0079975128174,0.187381938099861,30,4,200,0.00090527260908857,-3.4947235584259,0.507508814334869,1,,,,,,,,,,,,,,,,