File: data/ac dwie rel do testu programu.zip/Yb1/ac_6000a.dat
[Header]
; MPMS3 Data File (default extension .dat)
; Copyright (c) 2007, Quantum Design, Inc. All rights reserved.
TITLE,
FILEOPENTIME,3818700606.10135,01/01/2021,10:11 pm
BYAPP,SQUID AC,0.9.1.0
INFO,MPMS3 Measurement Release 1.1.16 Build 347, MultiVu Release 2.3.3.2,APPNAME
INFO,0,MOMENT_UNITS
INFO,MLKS253,SAMPLE_MATERIAL
INFO,crystals in mother solution, glass tube,SAMPLE_COMMENT
INFO,1,SAMPLE_MASS
INFO,,SAMPLE_VOLUME
INFO,,SAMPLE_MOLECULAR_WEIGHT
INFO,,SAMPLE_SIZE
INFO,,SAMPLE_SHAPE
INFO,Standard,SAMPLE_HOLDER
INFO,Standard,SAMPLE_HOLDER_DETAIL
INFO,64.96,SAMPLE_OFFSET
DATATYPE,COMMENT,1
DATATYPE,TIME,2
STARTUPAXIS,X,2
STARTUPAXIS,Y1,5
FIELDGROUP, VSM,2,3,4,5,6,8,9,10,11,14,15
FIELDGROUP, DC, 2,3,4,14,56,57,58,59,60,61,62,63,64,65,66,67,68,69
FIELDGROUP, AC, 2,3,4,11,16,17,18,19,20,21,22,23,24,25,26,27,28,29,30
STARTUPGROUP, All
[Data]
Comment,Time Stamp (sec),Temperature (K),Magnetic Field (Oe),Moment (emu),M. Std. Err. (emu),Transport Action,Averaging Time (sec),Frequency (Hz),Peak Amplitude (mm),Center Position (mm),Lockin Signal' (V),Lockin Signal (V),Range,M. Quad. Signal (emu),AC Moment (emu),AC M. Std Err. (emu),AC Phase (deg),AC Phase Std. Err. (deg),AC Susceptibility (emu/Oe),AC Suscept. Std Err. (emu/Oe),AC X' (emu/Oe),AC X' Std Err. (emu/Oe),AC X'' (emu/Oe),AC X'' Std Err. (emu/Oe),AC Drive (Oe),AC Frequency (Hz),AC Averaging Time (sec),AC Cycles,AC Range,AC Measure Type,AC Signal' (V),AC Signal'' (V),AC Trim Coil Ratio,AC Trim Coil Phase,Min. Temperature (K),Max. Temperature (K),Min. Field (Oe),Max. Field (Oe),Mass (grams),Motor Lag (deg),Pressure (Torr),Measure Count,Measurement Number,SQUID Status (code),Motor Status (code),Measure Status (code),Motor Current (amps),Motor Temp. (C),Temp. Status (code),Field Status (code),Chamber Status (code),Chamber Temp (K),Redirection State,Evercool Status,Average Temp (K),Rotation Angle (deg),Rotator state,DC Moment Fixed Ctr (emu),DC Moment Err Fixed Ctr (emu),DC Moment Free Ctr (emu),DC Moment Err Free Ctr (emu),DC Fixed Fit,DC Free Fit,DC Calculated Center (mm),DC Calculated Center Err (mm),DC Scan Length (mm),DC Scan Time (s),DC Number of Points,DC Squid Drift,DC Min V (V),DC Max V (V),DC Scans per Measure,Map 01,Map 02,Map 03,Map 04,Map 05,Map 06,Map 07,Map 08,Map 09,Map 10,Map 11,Map 12,Map 13,Map 14,Map 15,Map 16
,3818701380.81491,1.80011230707169,6000.28271484375,,,5,,,,23.14000017941,,,,,5.73014239994276E-6,7.18786502499934E-7,8.76707030919542,0.061222558885875,5.73011744938252E-6,7.18783372712806E-7,5.66316758230335E-6,6.34491995436332E-7,8.73372153475543E-7,3.37741683266396E-7,1.00000435428426,0.400388091802597,79.9224568741094,32,1,3,0.0187538720043214,0.00312273585251326,0.0268117692321539,179.144744873047,1.79842710494995,1.80232286453247,6000.28271484375,6000.28271484375,,,2.45799469947815,0,1,,,,,,1,1,1,1.80008018016815,0,0,1.79999596058965,,,,,,,,,,,,,,,,,,,,,,,,,,,,,,,,,
,3818702317.04457,1.8000995516777,6000.28271484375,,,5,,,,23.14000017941,,,,,4.3121991472985E-6,5.77633365384341E-7,23.0285437426774,0.094878338436479,4.31221499384841E-6,5.77635488082213E-7,3.96857494280024E-6,4.77310357786562E-7,1.68689391383963E-6,3.25326880908481E-7,0.99999632519484,1.10092270374298,29.0665274602881,31,1,3,0.0130557685081057,0.00585222840898408,0.0267920885235071,178.035827636719,1.79830288887024,1.80162799358368,6000.28271484375,6000.28271484375,,,2.45577669143677,0,1,,,,,,1,1,1,1.80002176761627,0,0,1.79998967735856,,,,,,,,,,,,,,,,,,,,,,,,,,,,,,,,,
,3818702739.68003,1.80016249418259,6000.28271484375,,,5,,,,23.14000017941,,,,,2.87584843697821E-6,3.29417816222173E-7,23.4083594339242,0.0775229124098037,2.87584506247566E-6,3.2941742968537E-7,2.63915344353838E-6,3.1740159401695E-7,1.14252086406559E-6,8.81593505875285E-8,1.00000117339512,3.00962328910828,12,36,1,3,0.00859914394186664,0.00413402979998709,0.0266379602253437,174.94206237793,1.79792487621307,1.80267035961151,6000.28271484375,6000.28271484375,,,2.4560878276825,0,1,,,,,,1,1,1,1.80044674873352,0,0,1.79999328576601,,,,,,,,,,,,,,,,,,,,,,,,,,,,,,,,,
,3818703045.96871,1.79997229576111,6000.28271484375,,,5,,,,23.14000017941,,,,,2.33774145468044E-6,1.49970588063315E-7,15.0039312138592,0.0365261761334593,2.33786049522021E-6,1.4997822474175E-7,2.25815830895777E-6,1.34832426504681E-7,6.0523776055056E-7,6.5678646907093E-8,0.999949081418665,8.29281997680664,12,99,1,3,0.00727942029154987,0.00266858109245011,0.0255140084773302,166.56086730957,1.79841220378876,1.80405807495117,6000.28271484375,6000.28271484375,,,2.45696997642517,0,1,,,,,,1,1,1,1.79990744590759,0,0,1.80000962238563,,,,,,,,,,,,,,,,,,,,,,,,,,,,,,,,,
,3818703299.13324,1.79964780807495,6000.28271484375,,,5,,,,23.14000017941,,,,,2.12291492034915E-6,5.67829697696644E-8,9.49801759075863,0.0163609466081278,2.12250796624882E-6,5.67720847067939E-8,2.09341116574914E-6,4.73951617039559E-8,3.50242427336456E-7,3.12532918108036E-8,1.00019173266099,22.6896495819092,12,272,1,3,0.00666215006846679,0.0022499162274772,0.0213740989565849,149.40251159668,1.79829525947571,1.80221211910248,6000.28271484375,6000.28271484375,,,2.45759654045105,0,1,,,,,,1,1,1,1.79976665973663,0,0,1.80001382706529,,,,,,,,,,,,,,,,,,,,,,,,,,,,,,,,,
,3818703546.70484,1.7998114824295,6000.28271484375,,,5,,,,23.14000017941,,,,,1.99991383090373E-6,2.47411780009385E-8,8.28317012081585,0.00625347957655409,1.99939521372557E-6,2.47347621245538E-8,1.97853782098332E-6,2.23031869201197E-8,2.88043940410642E-7,1.06946860900384E-8,1.00025938702594,62.2807731628418,12,747,1,3,0.00633535366514318,0.00190579144442071,0.0126162674278021,131.629318237305,1.79801630973816,1.80324578285217,6000.28271484375,6000.28271484375,,,2.45803666114807,0,1,,,,,,1,1,1,1.79992806911469,0,0,1.80002237088753,,,,,,,,,,,,,,,,,,,,,,,,,,,,,,,,,
,3818703792.94112,1.79959899187088,6000.28271484375,,,5,,,,23.14000017941,,,,,1.88525061568984E-6,9.23942999407817E-9,9.97181959641165,0.00332677122925078,1.88496393342474E-6,9.23802499216656E-9,1.85648786086E-6,6.93990966128348E-9,3.26407494999009E-7,6.09743877780812E-9,1.00015208899227,171.026702880859,12,2052,1,3,0.00598959290916456,0.00173070151221558,0.00686538638547063,129.333648681641,1.79880356788635,1.80340576171875,6000.28271484375,6000.28271484375,,,2.45834875106812,0,1,,,,,,1,1,1,1.79981684684753,0,0,1.80002220533788,,,,,,,,,,,,,,,,,,,,,,,,,,,,,,,,,
,3818704034.14738,1.79950392246246,6000.28271484375,,,5,,,,23.14000017941,,,,,2.56381600124011E-6,4.3241009145693E-8,12.568712351143,0.0140305606212035,2.56376986182556E-6,4.32402309639336E-8,2.50233101029897E-6,2.31684382772828E-8,5.57902696983248E-7,3.65094650961372E-8,1.00001799670682,468.375305175781,12,5620,1,3,0.00790661777260996,0.0030786023629877,0.00571828661486506,120.248611450195,1.79834973812103,1.80221891403198,6000.28271484375,6000.28271484375,,,2.45951414108276,0,1,,,,,,1,1,1,1.80015826225281,0,0,1.7999944505045,,,,,,,,,,,,,,,,,,,,,,,,,,,,,,,,,
,3818704497.62178,2.19998264312744,6000.28271484375,,,5,,,,23.14000017941,,,,,5.28118189548743E-6,4.77177592190364E-7,1.130800970925,0.0750912887436348,5.28120037568399E-6,4.77179261955934E-7,5.28017184883465E-6,2.65246764627419E-7,1.04224061035579E-7,3.96666360932581E-7,0.999996500758305,0.400388091802597,79.9224568741094,32,1,3,0.0175136567043525,0.00055571374979263,0.0268313605338335,179.133682250977,2.19865560531616,2.20157837867737,6000.28271484375,6000.28271484375,,,2.74690747261047,0,1,,,,,,1,1,1,2.20005559921265,0,0,2.19999264826817,,,,,,,,,,,,,,,,,,,,,,,,,,,,,,,,,
,3818705432.62273,2.20006859302521,6000.28271484375,,,5,,,,23.14000017941,,,,,4.49654459063901E-6,3.36030247668115E-7,11.8880946189392,0.0468119839833873,4.49646493083624E-6,3.36024294629572E-7,4.40002390005715E-6,2.66247561015343E-7,9.26275635632272E-7,2.04998933740355E-7,1.00001771609564,1.10092270374298,29.0665274602881,31,1,3,0.0145364412289158,0.00335701309212647,0.0266952868551016,178.291534423828,2.1981828212738,2.20253705978394,6000.28271484375,6000.28271484375,,,2.74701619148254,0,1,,,,,,1,1,1,2.1999351978302,0,0,2.19998188699995,,,,,,,,,,,,,,,,,,,,,,,,,,,,,,,,,
,3818705853.76945,2.19999837875366,6000.28271484375,,,5,,,,23.14000017941,,,,,3.76191229244305E-6,1.21147471496754E-7,12.8970305911152,0.0202538396462213,3.76191342428963E-6,1.21147507946395E-7,3.66701074289005E-6,9.67019265871776E-8,8.39657563164561E-7,7.29757225106404E-8,0.999999699130083,3.00962328910828,12,36,1,3,0.0120463559149549,0.00326491758423989,0.026516554877162,174.931793212891,2.19874358177185,2.20413160324097,6000.28271484375,6000.28271484375,,,2.74815058708191,0,1,,,,,,1,1,1,2.20009255409241,0,0,2.20003991656833,,,,,,,,,,,,,,,,,,,,,,,,,,,,,,,,,
,3818706162.50609,2.20005035400391,6000.28271484375,,,5,,,,23.14000017941,,,,,3.27068256908788E-6,1.0847859495883E-7,7.57485318732632,0.015168639699891,3.26621605989601E-6,1.08330454431197E-7,3.23771339738349E-6,9.84819621612139E-8,4.30556972218583E-7,4.51308152612707E-8,1.00136748736457,8.29281997680664,12,99,1,3,0.0105817296722138,0.00238536750316193,0.0257708188146353,167.026626586914,2.19885492324829,2.2033839225769,6000.28271484375,6000.28271484375,,,2.74938297271729,0,1,,,,,,1,1,1,2.19979500770569,0,0,2.20005477587382,,,,,,,,,,,,,,,,,,,,,,,,,,,,,,,,,
,3818706415.11296,2.19956254959106,6000.28271484375,,,5,,,,23.14000017941,,,,,3.03475505118699E-6,4.13654590554419E-8,6.42968013074689,0.00890443704938631,3.03515610104074E-6,4.13709255959121E-8,3.01606510009644E-6,3.19974198346153E-8,3.39888025186347E-7,2.6224389575162E-8,0.999867865163965,22.6896495819092,12,272,1,3,0.00968220329088785,0.00270191153795269,0.0213645119220018,149.4326171875,2.19836091995239,2.20286703109741,6000.28271484375,6000.28271484375,,,2.75044751167297,0,1,,,,,,1,1,1,2.20006275177002,0,0,2.20005851984024,,,,,,,,,,,,,,,,,,,,,,,,,,,,,,,,,
,3818706658.61317,2.19968032836914,6000.28271484375,,,5,,,,23.14000017941,,,,,2.87860152934872E-6,2.02681901090965E-8,7.00333533186891,0.00384088374293637,2.87840062343939E-6,2.02667755336081E-8,2.85692503653544E-6,1.75088430920337E-8,3.50955103443783E-7,1.02069880037256E-8,1.00006979775772,62.2807731628418,12,747,1,3,0.00917787278923207,0.00253874295406248,0.0126245794817805,131.715347290039,2.19856953620911,2.20329880714417,6000.28271484375,6000.28271484375,,,2.75149989128113,0,1,,,,,,1,1,1,2.2000424861908,0,0,2.20002163433638,,,,,,,,,,,,,,,,,,,,,,,,,,,,,,,,,
,3818706895.83604,2.19947719573975,6000.28271484375,,,5,,,,23.14000017941,,,,,2.73907250454745E-6,9.61236002952567E-9,10.5191225992844,0.0019187893485989,2.73878111492607E-6,9.61133744179027E-9,2.69275324515895E-6,8.40918223166983E-9,5.00001956157807E-7,4.65440239069722E-9,1.00010639390632,171.026702880859,12,2052,1,3,0.0086778550921165,0.00259747714489439,0.00686072558164597,129.341064453125,2.19828295707703,2.20251154899597,6000.28271484375,6000.28271484375,,,2.75233721733093,0,1,,,,,,1,1,1,2.2000470161438,0,0,2.20000149986961,,,,,,,,,,,,,,,,,,,,,,,,,,,,,,,,,
,3818707137.06304,2.19941139221191,6000.28271484375,,,5,,,,23.14000017941,,,,,3.28450864889222E-6,3.87491871374643E-8,15.9149108242555,0.00984241104972889,3.28491158002698E-6,3.87539407416143E-8,3.15900085681562E-6,2.1112177880183E-8,9.00753948219778E-7,3.24983671614447E-8,0.999877338818735,468.375305175781,12,5620,1,3,0.009881782414421,0.00452831311017904,0.0057151336222887,120.378982543945,2.19830083847046,2.20293974876404,6000.28271484375,6000.28271484375,,,2.7521710395813,0,1,,,,,,1,1,1,2.1996648311615,0,0,2.20002381680375,,,,,,,,,,,,,,,,,,,,,,,,,,,,,,,,,
,3818707602.96158,2.59993362426758,6000.28271484375,,,5,,,,23.14000017941,,,,,4.36089677525735E-6,3.21854589473552E-7,0.355673471397806,0.0556237551035178,4.36088121217098E-6,3.21853440844949E-7,4.36079718871334E-6,2.11536040346353E-7,2.70707512947109E-8,2.42573990811709E-7,1.00000356879392,0.400388091802597,79.9224568741094,32,1,3,0.0144666564643201,0.00026319376589385,0.0268044900149107,179.143890380859,2.59855914115906,2.60180616378784,6000.28271484375,6000.28271484375,,,2.99164128303528,0,1,,,,,,1,1,1,2.5999219417572,0,0,2.59999958789626,,,,,,,,,,,,,,,,,,,,,,,,,,,,,,,,,
,3818708530.59831,2.59992861747742,6000.28271484375,,,5,,,,23.14000017941,,,,,4.40040937541184E-6,2.32992545198554E-7,3.7948307337431,0.0326067224253826,4.40040889731874E-6,2.32992519884517E-7,4.39076075223163E-6,1.83842646558737E-7,2.91236124586744E-7,1.43134187489978E-7,1.00000010864743,1.10092270374298,29.0665274602881,31,1,3,0.0145464827541234,0.00124976334980525,0.0267825312912464,178.152694702148,2.59860444068909,2.60214281082153,6000.28271484375,6000.28271484375,,,2.99169540405273,0,1,,,,,,1,1,1,2.60000443458557,0,0,2.59997679569103,,,,,,,,,,,,,,,,,,,,,,,,,,,,,,,,,
,3818708954.42026,2.5999516248703,6000.28271484375,,,5,,,,23.14000017941,,,,,3.8322645313865E-6,9.32162922806904E-8,5.96610429033201,0.0118902945987437,3.83226261206145E-6,9.32162455948828E-8,3.81150538967328E-6,8.19447515977895E-8,3.98325736421292E-7,4.44333897917104E-8,1.00000050083338,3.00962328910828,12,36,1,3,0.0125833148942739,0.00182081747208218,0.0265465043485165,174.952651977539,2.59812474250793,2.60182023048401,6000.28271484375,6000.28271484375,,,2.99217081069946,0,1,,,,,,1,1,1,2.59991455078125,0,0,2.59997697283582,,,,,,,,,,,,,,,,,,,,,,,,,,,,,,,,,
,3818709265.39143,2.59976267814636,6000.28271484375,,,5,,,,23.14000017941,,,,,3.59434316997149E-6,1.26665903750332E-7,5.0415808263804,0.0285342087526083,3.58432369163386E-6,1.26312813848025E-7,3.57045660599296E-6,7.34536666420545E-8,3.14985636385242E-7,1.0275935869323E-7,1.00279536091035,8.29281997680664,12,99,1,3,0.0117333793596383,0.00210486201385324,0.0255859717726707,166.453247070313,2.59831309318542,2.60277700424194,6000.28271484375,6000.28271484375,,,2.99331068992615,0,1,,,,,,1,1,1,2.5994827747345,0,0,2.59999421709462,,,,,,,,,,,,,,,,,,,,,,,,,,,,,,,,,
,3818709520.29033,2.59950911998749,6000.28271484375,,,5,,,,23.14000017941,,,,,3.50373003054636E-6,3.84342529642572E-8,4.20386704627625,0.00812109473260089,3.50296605878319E-6,3.84258725571633E-8,3.49354144038176E-6,2.59254444870163E-8,2.56786707838158E-7,2.83622814655308E-8,1.00021809282486,22.6896495819092,12,272,1,3,0.0112911615669852,0.00268293812822462,0.0213520806282759,149.395889282227,2.59845471382141,2.60172629356384,6000.28271484375,6000.28271484375,,,2.99456214904785,0,1,,,,,,1,1,1,2.59989619255066,0,0,2.59999976158142,,,,,,,,,,,,,,,,,,,,,,,,,,,,,,,,,
,3818709763.24682,2.59973776340485,6000.28271484375,,,5,,,,23.14000017941,,,,,3.3636652106131E-6,1.96923832591816E-8,5.4305246481009,0.00307485484240523,3.36294068971064E-6,1.96881415934993E-8,3.34784675791232E-6,1.71092169058606E-8,3.18264305330387E-7,9.74154075461832E-9,1.00021544266441,62.2807731628418,12,747,1,3,0.0108017957845575,0.00267103650804102,0.0126268193125725,131.638656616211,2.59897422790527,2.60402274131775,6000.28271484375,6000.28271484375,,,2.99539232254028,0,1,,,,,,1,1,1,2.60037875175476,0,0,2.60005008197222,,,,,,,,,,,,,,,,,,,,,,,,,,,,,,,,,
,3818710000.40213,2.59943854808807,6000.28271484375,,,5,,,,23.14000017941,,,,,3.23676408503475E-6,6.9716100828447E-9,9.64704295297909,0.00133684776276829,3.23686509666634E-6,6.97182765004787E-9,3.19109187044799E-6,5.62819248327412E-9,5.42428178082176E-7,4.11458748274826E-9,0.999968793376128,171.026702880859,12,2052,1,3,0.0103001770201077,0.00291293476619517,0.00686693610623479,129.356018066406,2.5987012386322,2.60194802284241,6000.28271484375,6000.28271484375,,,2.9965546131134,0,1,,,,,,1,1,1,2.59995698928833,0,0,2.59999714331193,,,,,,,,,,,,,,,,,,,,,,,,,,,,,,,,,
,3818710241.62862,2.59933733940125,6000.28271484375,,,5,,,,23.14000017941,,,,,3.82907572131775E-6,5.24726790907412E-8,15.2760564286683,0.0122308401611598,3.82961362351705E-6,5.24800503655709E-8,3.69430420317997E-6,1.63151622215294E-8,1.00898808704273E-6,4.98795666386351E-8,0.999859541391854,468.375305175781,12,5620,1,3,0.0115784047012602,0.00515009260189665,0.0057344944216311,120.279968261719,2.59833765029907,2.60285997390747,6000.28271484375,6000.28271484375,,,2.99644351005554,0,1,,,,,,1,1,1,2.59950375556946,0,0,2.60008259142859,,,,,,,,,,,,,,,,,,,,,,,,,,,,,,,,,
,3818710712.17628,2.99992287158966,6000.28271484375,,,5,,,,23.14000017941,,,,,4.23800267607158E-6,3.33722768281908E-7,1.54370447629831,0.0663122370836264,4.23802944804589E-6,3.33724876448906E-7,4.23649132611367E-6,1.79802294310914E-7,1.14170251238428E-7,2.81146630997722E-7,0.999993682919234,0.400388091802597,79.9224568741094,32,1,3,0.0140506474021781,0.000547214151067013,0.0268217697739601,179.12321472168,2.99884247779846,3.00276803970337,6000.28271484375,6000.28271484375,,,3.20966863632202,0,1,,,,,,1,1,1,3.00001692771912,0,0,2.9999933002318,,,,,,,,,,,,,,,,,,,,,,,,,,,,,,,,,
,3818711646.73407,2.99980473518372,6000.28271484375,,,5,,,,23.14000017941,,,,,4.02568450363916E-6,1.99631796694364E-7,2.08106074344338,0.0259228766038309,4.02570383688904E-6,1.99632755421111E-7,4.02304869136288E-6,1.70333424525443E-7,1.46186898409524E-7,1.04114175434762E-7,0.999995197547892,1.10092270374298,29.0665274602881,31,1,3,0.0133359912169177,0.000744837607712812,0.026720492169261,178.108123779297,2.99907231330872,3.00280237197876,6000.28271484375,6000.28271484375,,,3.20915818214417,0,1,,,,,,1,1,1,2.9997615814209,0,0,3.00002325773239,,,,,,,,,,,,,,,,,,,,,,,,,,,,,,,,,
,3818712067.04608,2.99996626377106,6000.28271484375,,,5,,,,23.14000017941,,,,,3.74342328795587E-6,1.25378654363556E-7,2.96574183478526,0.0152303326511113,3.74342242608106E-6,1.25378625496742E-7,3.73840866892563E-6,1.11965019068603E-7,1.93680366037176E-7,5.64237027889843E-8,1.00000023023712,3.00962328910828,12,36,1,3,0.0123678501163432,0.00113279634158091,0.0265393704175949,174.916534423828,2.99875473976135,3.00240898132324,6000.28271484375,6000.28271484375,,,3.21020483970642,0,1,,,,,,1,1,1,2.9999041557312,0,0,3.00000211927626,,,,,,,,,,,,,,,,,,,,,,,,,,,,,,,,,
,3818712379.8134,2.99998140335083,6000.28271484375,,,5,,,,23.14000017941,,,,,3.64583258329341E-6,8.12563860960906E-8,1.97137667311827,0.0131758830322915,3.64595139759755E-6,8.12590341663874E-8,3.64379349421363E-6,6.56850460738884E-8,1.25421549862711E-7,4.78383251789324E-8,0.99996741198903,8.29281997680664,12,99,1,3,0.0119987297113831,0.0014945090062362,0.0255129281431437,166.791427612305,2.99865293502808,3.00158667564392,6000.28271484375,6000.28271484375,,,3.21144270896912,0,1,,,,,,1,1,1,3.00004625320435,0,0,2.99996329307556,,,,,,,,,,,,,,,,,,,,,,,,,,,,,,,,,
,3818712633.29561,2.99953854084015,6000.28271484375,,,5,,,,23.14000017941,,,,,3.5763240789583E-6,4.2283324982636E-8,2.46977032278152,0.00816546459705595,3.57596937993412E-6,4.22791313318987E-8,3.57264764924668E-6,3.0715879358208E-8,1.54096659790535E-7,2.90527055785162E-8,1.00009918961448,22.6896495819092,12,272,1,3,0.0116026988687736,0.00238849867751343,0.021356176584959,149.412750244141,2.99881911277771,3.0024881362915,6000.28271484375,6000.28271484375,,,3.21280431747437,0,1,,,,,,1,1,1,2.99988150596619,0,0,3.00000267028809,,,,,,,,,,,,,,,,,,,,,,,,,,,,,,,,,
,3818712875.01514,2.99963593482971,6000.28271484375,,,5,,,,23.14000017941,,,,,3.47513276473839E-6,2.63555092399494E-8,4.21197163080351,0.00327767900609296,3.47503298542309E-6,2.63547525106834E-8,3.46564745212351E-6,2.41700694301193E-8,2.55229283916155E-7,1.05062230912249E-8,1.00002871319948,62.2807731628418,12,747,1,3,0.0112159212347911,0.00252157228140613,0.0126454401761293,131.653778076172,2.99908041954041,3.00218820571899,6000.28271484375,6000.28271484375,,,3.21386313438416,0,1,,,,,,1,1,1,3.00008654594421,0,0,3.0000239332517,,,,,,,,,,,,,,,,,,,,,,,,,,,,,,,,,
,3818713117.47466,2.99940860271454,6000.28271484375,,,5,,,,23.14000017941,,,,,3.38933366119342E-6,7.46354773548236E-9,8.01349873787951,0.00147295255988794,3.38990947143255E-6,7.46481570955513E-9,3.35680786117667E-6,5.63066148264779E-9,4.72575081495678E-7,4.90093101822987E-9,0.999830139936188,171.026702880859,12,2052,1,3,0.0108682789244367,0.00274145482065749,0.00686430744826794,129.381072998047,2.99844264984131,3.00210690498352,6000.28271484375,6000.28271484375,,,3.21423077583313,0,1,,,,,,1,1,1,2.99983644485474,0,0,2.99998428821564,,,,,,,,,,,,,,,,,,,,,,,,,,,,,,,,,
,3818713358.34824,2.99955642223358,6000.28271484375,,,5,,,,23.14000017941,,,,,3.9505625855571E-6,2.95011506401033E-8,15.523862351132,0.00483691938711768,3.95089504849025E-6,2.95036333343679E-8,3.80676272717786E-6,2.70853992060447E-8,1.05741629605097E-6,1.16980994087936E-8,0.999915851236475,468.375305175781,12,5620,1,3,0.0119227618895617,0.00536486467253448,0.00573650654405355,120.261993408203,2.9984884262085,3.00201821327209,6000.28271484375,6000.28271484375,,,3.21480083465576,0,1,,,,,,1,1,1,3.00009560585022,0,0,2.99996513128281,,,,,,,,,,,,,,,,,,,,,,,,,,,,,,,,,
,3818713810.86513,3.40014719963074,6000.28271484375,,,5,,,,23.14000017941,,,,,3.61994588434905E-6,2.28754695950052E-7,-0.908923232320734,0.0411844085083967,3.61992337103592E-6,2.28753273269641E-7,3.61946789092534E-6,1.7349607634505E-7,-5.74229808746797E-8,1.49087798040107E-7,1.00000621927892,0.400388091802597,79.9224568741094,32,1,3,0.0120105537750596,-4.66046314421548E-5,0.0268351752310991,179.187088012695,3.39912247657776,3.40167140960693,6000.28271484375,6000.28271484375,,,3.40587258338928,0,1,,,,,,1,1,1,3.40004849433899,0,0,3.39999540317693,,,,,,,,,,,,,,,,,,,,,,,,,,,,,,,,,
,3818714745.30405,3.40005397796631,6000.28271484375,,,5,,,,23.14000017941,,,,,3.70064723210104E-6,2.15569143607517E-7,0.473067036948153,0.0291976286376623,3.70061681528703E-6,2.15567371775149E-7,3.70049067849965E-6,1.86557652610669E-7,3.05540819260171E-8,1.08007101740776E-7,1.00000821939031,1.10092270374298,29.0665274602881,31,1,3,0.0122736175276292,0.000340421024882257,0.0267205182462931,177.943023681641,3.3990523815155,3.4012143611908,6000.28271484375,6000.28271484375,,,3.40458607673645,0,1,,,,,,1,1,1,3.40006875991821,0,0,3.39998295152788,,,,,,,,,,,,,,,,,,,,,,,,,,,,,,,,,
,3818715172.49743,3.40002679824829,6000.28271484375,,,5,,,,23.14000017941,,,,,3.46996957767721E-6,8.06338345062838E-8,0.772823359529914,0.0158052431881744,3.4699533393967E-6,8.06334571672916E-8,3.46963769195678E-6,5.91157459045113E-8,4.68023946304959E-8,5.48368762868811E-8,1.00000467968267,3.00962328910828,12,36,1,3,0.0114961732429357,0.000610599193843612,0.0265044141560793,175.092346191406,3.39884066581726,3.40269660949707,6000.28271484375,6000.28271484375,,,3.40589165687561,0,1,,,,,,1,1,1,3.40013933181763,0,0,3.39999403023138,,,,,,,,,,,,,,,,,,,,,,,,,,,,,,,,,
,3818715483.55839,3.40000903606415,6000.28271484375,,,5,,,,23.14000017941,,,,,3.52791090365831E-6,8.60844824870869E-8,0.81560899595525,0.0184428123953876,3.53479206523054E-6,8.62523895712034E-8,3.53443393144622E-6,5.6463181702568E-8,5.03162862145066E-8,6.5202636593664E-8,0.998053305132169,8.29281997680664,12,99,1,3,0.0116374483129663,0.00121167847139381,0.0256792437285185,166.82568359375,3.39910745620728,3.40259337425232,6000.28271484375,6000.28271484375,,,3.40735244750977,0,1,,,,,,1,1,1,3.40007853507996,0,0,3.40003660837809,,,,,,,,,,,,,,,,,,,,,,,,,,,,,,,,,
,3818715736.9193,3.39960622787476,6000.28271484375,,,5,,,,23.14000017941,,,,,3.44897323833674E-6,5.15377534321062E-8,1.67245058725764,0.00698671729904608,3.44866180677604E-6,5.15330997332E-8,3.44719270764827E-6,4.58599096104069E-8,1.00651347990668E-7,2.3505936667941E-8,1.00009030504531,22.6896495819092,12,272,1,3,0.0112205054952647,0.0021475046626655,0.0213864613324404,149.413528442383,3.39920997619629,3.40274262428284,6000.28271484375,6000.28271484375,,,3.40869927406311,0,1,,,,,,1,1,1,3.3999457359314,0,0,3.40004557270115,,,,,,,,,,,,,,,,,,,,,,,,,,,,,,,,,
,3818715980.54152,3.39990770816803,6000.28271484375,,,5,,,,23.14000017941,,,,,3.39998452555271E-6,2.63473019189215E-8,3.10667052233678,0.00374870389033839,3.39924751445832E-6,2.63415906418037E-8,3.39425187005388E-6,2.33037600253964E-8,1.84222439422707E-7,1.22806419302534E-8,1.00021681595449,62.2807731628418,12,747,1,3,0.0110189350570946,0.00225487963116915,0.0126306926831603,131.63850402832,3.3986325263977,3.40214252471924,6000.28271484375,6000.28271484375,,,3.40911459922791,0,1,,,,,,1,1,1,3.4000825881958,0,0,3.40003355604703,,,,,,,,,,,,,,,,,,,,,,,,,,,,,,,,,
,3818716223.9846,3.39940798282623,6000.28271484375,,,5,,,,23.14000017941,,,,,3.3614874369687E-6,1.04709589729829E-8,6.20291925724443,0.00217216533895421,3.36202196228115E-6,1.04726240075016E-8,3.34233887037165E-6,7.55217495774824E-9,3.63266500607367E-7,7.25537779926445E-9,0.999841010761248,171.026702880859,12,2052,1,3,0.0108595271539715,0.00237692780632947,0.00686659198254347,129.386596679688,3.39882779121399,3.40241622924805,6000.28271484375,6000.28271484375,,,3.40950012207031,0,1,,,,,,1,1,1,3.3999810218811,0,0,3.39999294671856,,,,,,,,,,,,,,,,,,,,,,,,,,,,,,,,,
,3818716463.5151,3.39941692352295,6000.28271484375,,,5,,,,23.14000017941,,,,,4.04309612721191E-6,3.28804950321781E-8,13.2474900080761,0.00568122748471877,4.04276563809292E-6,3.28778073281282E-8,3.93518480745577E-6,2.5674685597029E-8,9.26431074454074E-7,2.05368141199952E-8,1.00008174827546,468.375305175781,12,5620,1,3,0.012410570223739,0.00500127494788098,0.00571355642750859,120.316497802734,3.39847683906555,3.40223526954651,6000.28271484375,6000.28271484375,,,3.41049551963806,0,1,,,,,,1,1,1,3.3997974395752,0,0,3.39999853150319,,,,,,,,,,,,,,,,,,,,,,,,,,,,,,,,,
,3818716918.12832,3.79996025562286,6000.28271484375,,,5,,,,23.14000017941,,,,,3.25770633652385E-6,1.7335210903225E-7,0.212284790086931,0.0458834789667521,3.25771423309211E-6,1.73352529231808E-7,3.25769187292807E-6,8.77880754292983E-8,1.20700268985018E-8,1.49480276971527E-7,0.999997576040226,0.400388091802597,79.9224568741094,32,1,3,0.010807436880079,0.000169566026782021,0.0268158968538046,179.1357421875,3.79884934425354,3.80231475830078,6000.28271484375,6000.28271484375,,,3.58235907554626,0,1,,,,,,1,1,1,3.80001831054687,0,0,3.79999964335966,,,,,,,,,,,,,,,,,,,,,,,,,,,,,,,,,
,3818717851.1272,3.80012214183807,6000.28271484375,,,5,,,,23.14000017941,,,,,3.31502307117886E-6,1.02065864840699E-7,1.08124212962321,0.0186412995622957,3.31504304663165E-6,1.02066479862622E-7,3.3144527817549E-6,8.12516482375678E-8,6.25552438890903E-8,6.17716437390625E-8,0.999993974300634,1.10092270374298,29.0665274602881,31,1,3,0.0109907949130904,0.000421632172327243,0.0267255585640669,177.905960083008,3.79882478713989,3.80191969871521,6000.28271484375,6000.28271484375,,,3.58106088638306,0,1,,,,,,1,1,1,3.80003786087036,0,0,3.79998506916513,,,,,,,,,,,,,,,,,,,,,,,,,,,,,,,,,
,3818718282.5869,3.80006146430969,6000.28271484375,,,5,,,,23.14000017941,,,,,3.26223947865486E-6,7.19947550354282E-8,0.36324191800977,0.0151282469510845,3.26223601172252E-6,7.19946785232819E-8,3.26217045298482E-6,5.24198553185602E-8,2.06816791404951E-8,4.93496960887494E-8,1.00000106274724,3.00962328910828,12,36,1,3,0.0108117810749806,0.000496769027789892,0.0264745149761438,175.084899902344,3.79853439331055,3.80267453193665,6000.28271484375,6000.28271484375,,,3.58194279670715,0,1,,,,,,1,1,1,3.80002951622009,0,0,3.79999736797662,,,,,,,,,,,,,,,,,,,,,,,,,,,,,,,,,
,3818718592.64236,3.80012500286102,6000.28271484375,,,5,,,,23.14000017941,,,,,3.26712206363786E-6,6.37459919089833E-8,-0.0194099233378591,0.0128274111877959,3.26108857433046E-6,6.36282703322926E-8,3.2610883872041E-6,4.79505440236673E-8,-1.10474939957082E-9,4.1824659153586E-8,1.00185014579331,8.29281997680664,12,99,1,3,0.0107923981437531,0.000964926788978848,0.0256471913307905,166.914459228516,3.79907965660095,3.8019711971283,6000.28271484375,6000.28271484375,,,3.58355331420898,0,1,,,,,,1,1,1,3.80014109611511,0,0,3.80001211166382,,,,,,,,,,,,,,,,,,,,,,,,,,,,,,,,,
,3818718845.98725,3.79944837093353,6000.28271484375,,,5,,,,23.14000017941,,,,,3.25926174875855E-6,4.54219287332009E-8,1.19329943016327,0.0117320403203073,3.2586614539013E-6,4.54135628662264E-8,3.25795473427716E-6,2.44344195222612E-8,6.78632488403116E-8,3.82799011860642E-8,1.00018421516495,22.6896495819092,12,272,1,3,0.0106199214360065,0.00194062711524299,0.0213860254734755,149.40364074707,3.79854202270508,3.80164980888367,6000.28271484375,6000.28271484375,,,3.58498120307922,0,1,,,,,,1,1,1,3.79998826980591,0,0,3.80000235637029,,,,,,,,,,,,,,,,,,,,,,,,,,,,,,,,,
,3818719087.65873,3.79960894584656,6000.28271484375,,,5,,,,23.14000017941,,,,,3.20410689841826E-6,2.52133263206472E-8,2.24223228275589,0.0052786351877052,3.20359529202204E-6,2.5209300456522E-8,3.20114245800235E-6,1.87698032693722E-8,1.25338576026918E-7,1.68286456595968E-8,1.000159697574,62.2807731628418,12,747,1,3,0.0104150018287116,0.00196804028650889,0.0126414690166712,131.644165039062,3.79850554466248,3.80156993865967,6000.28271484375,6000.28271484375,,,3.58571696281433,0,1,,,,,,1,1,1,3.80005168914795,0,0,3.8000173886617,,,,,,,,,,,,,,,,,,,,,,,,,,,,,,,,,
,3818719325.10897,3.79962062835693,6000.28271484375,,,5,,,,23.1299996376038,,,,,3.17719293491738E-6,7.4039309359674E-9,4.86439802100925,0.00128210787782978,3.17738115142625E-6,7.40436954390253E-9,3.1659367948744E-6,6.24938115451273E-9,2.69434950032825E-7,3.97113630190307E-9,0.999940763635239,171.026702880859,12,2052,1,3,0.0103138431955056,0.00200615593337661,0.00687024369835854,129.359008789062,3.79848623275757,3.80196928977966,6000.28271484375,6000.28271484375,,,3.58705353736877,0,1,,,,,,1,1,1,3.80016851425171,0,0,3.80003082968972,,,,,,,,,,,,,,,,,,,,,,,,,,,,,,,,,
,3818719566.15347,3.79940986633301,6000.28271484375,,,5,,,,23.14000017941,,,,,3.84215600144884E-6,2.18203512690611E-8,11.3126217469687,0.00366201197360444,3.84236832339676E-6,2.1821557086702E-8,3.76771675351381E-6,1.78449916817299E-8,7.53727270260396E-7,1.25593242480312E-8,0.99994474190654,468.375305175781,12,5620,1,3,0.0119475921839997,0.00435155573236115,0.00572803616523743,120.257873535156,3.7983512878418,3.80187106132507,6000.28271484375,6000.28271484375,,,3.58678698539734,0,1,,,,,,1,1,1,3.79992985725403,0,0,3.79997538328171,,,,,,,,,,,,,,,,,,,,,,,,,,,,,,,,,
,3818720016.28808,4.20005488395691,6000.28271484375,,,5,,,,23.14000017941,,,,,3.0497596756484E-6,1.14381622056994E-7,-0.00684922933538956,0.0276030211539417,3.04975116303652E-6,1.1438130279041E-7,3.04975114124575E-6,7.74365459983139E-8,-3.64572142298696E-10,8.41823245811279E-8,1.00000279124802,0.400388091802597,79.9224568741094,32,1,3,0.0101181072108567,0.000120045224800182,0.0268269069492817,179.142868041992,4.19884157180786,4.20254278182983,6000.28271484375,6000.28271484375,,,3.74346327781677,0,1,,,,,,1,1,1,4.20005750656128,0,0,4.20000456050484,,,,,,,,,,,,,,,,,,,,,,,,,,,,,,,,,
,3818720971.51021,4.20000195503235,6000.28271484375,,,5,,,,23.14000017941,,,,,3.10235862604215E-6,7.75069425575833E-8,1.16665967486603,0.0179652823090415,3.10233942348057E-6,7.75064628155494E-8,3.10169631028643E-6,5.38582281995874E-8,6.31656333563344E-8,5.5736370830718E-8,1.00000618970363,1.10092270374298,29.0665274602881,31,1,3,0.0102851168090614,0.000409916916196441,0.0266912709921598,177.980438232422,4.19885110855103,4.20153141021729,6000.28271484375,6000.28271484375,,,3.74117112159729,0,1,,,,,,1,1,1,4.19996452331543,0,0,4.20001241139003,,,,,,,,,,,,,,,,,,,,,,,,,,,,,,,,,
,3818721398.13488,4.19997358322144,6000.28271484375,,,5,,,,23.14000017941,,,,,3.10692482316566E-6,5.36623506498754E-8,0.768927754572056,0.0126879226876404,3.10692462495033E-6,5.36623472263292E-8,3.10664484279417E-6,3.6406529267769E-8,4.1694674278001E-8,3.94234972638678E-8,1.00000006379792,3.00962328910828,12,36,1,3,0.0102934261023779,0.000546012787632828,0.026560066267848,174.953964233398,4.19865083694458,4.20173978805542,6000.28271484375,6000.28271484375,,,3.74226713180542,0,1,,,,,,1,1,1,4.19997930526733,0,0,4.19998166619278,,,,,,,,,,,,,,,,,,,,,,,,,,,,,,,,,
,3818721706.67896,4.2001268863678,6000.28271484375,,,5,,,,23.14000017941,,,,,3.06623262148768E-6,8.67791125568853E-8,-1.56272743593909,0.0248405945360066,3.06606922955092E-6,8.67744883130587E-8,3.06492885833504E-6,4.17855356396191E-8,-8.36158701687265E-8,7.60511724650138E-8,1.00005329036122,8.29281997680664,12,99,1,3,0.0101495091851021,0.000632467015096829,0.0255295131355524,166.620254516602,4.19893169403076,4.20156526565552,6000.28271484375,6000.28271484375,,,3.74418711662292,0,1,,,,,,1,1,1,4.20016813278198,0,0,4.19999851499285,,,,,,,,,,,,,,,,,,,,,,,,,,,,,,,,,
,3818721960.70551,4.19948410987854,6000.28271484375,,,5,,,,23.14000017941,,,,,3.04654254583823E-6,3.17058194970924E-8,0.871853100667106,0.00763469962836661,3.04634007310987E-6,3.17037123334201E-8,3.04598739266838E-6,2.15790219185373E-8,4.6353476033099E-8,2.32265190840027E-8,1.00006646425662,22.6896495819092,12,272,1,3,0.00993682330162031,0.0017582393700097,0.0213818959891796,149.415573120117,4.19868421554565,4.20146036148071,6000.28271484375,6000.28271484375,,,3.74570322036743,0,1,,,,,,1,1,1,4.19993734359741,0,0,4.20002668698629,,,,,,,,,,,,,,,,,,,,,,,,,,,,,,,,,
,3818722204.24335,4.19967532157898,6000.28271484375,,,5,,,,23.14000017941,,,,,3.02236982105608E-6,2.89144717913457E-8,1.53167735586257,0.00461228034538782,3.02175261118102E-6,2.8908567054805E-8,3.0206729378716E-6,2.54579688631362E-8,8.07703261690165E-8,1.36966079934318E-8,1.00020425559418,62.2807731628418,12,747,1,3,0.00984653344180844,0.00173441005665327,0.0126356678083539,131.61669921875,4.19906854629517,4.20180082321167,6000.28271484375,6000.28271484375,,,3.74627232551575,0,1,,,,,,1,1,1,4.20000076293945,0,0,4.1999975970534,,,,,,,,,,,,,,,,,,,,,,,,,,,,,,,,,
,3818722445.59796,4.19948530197144,6000.28271484375,,,5,,,,23.14000017941,,,,,2.99272797355399E-6,1.28004134178823E-8,3.35607564083915,0.00280568763224549,2.99315518249622E-6,1.28022406641689E-8,2.98802192228632E-6,9.69869937022E-9,1.75222539761189E-7,8.35659000725737E-9,0.999857271368778,171.026702880859,12,2052,1,3,0.00976141626685761,0.00163323022818109,0.00687600253149867,129.370162963867,4.19872236251831,4.20193433761597,6000.28271484375,6000.28271484375,,,3.74704670906067,0,1,,,,,,1,1,1,4.19994640350342,0,0,4.20002891222636,,,,,,,,,,,,,,,,,,,,,,,,,,,,,,,,,
,3818722689.54797,4.19967699050903,6000.28271484375,,,5,,,,23.14000017941,,,,,3.68431178762064E-6,4.0863094114286E-8,9.32652784744413,0.0101061999156602,3.68480763919054E-6,4.08685936568154E-8,3.63609738709348E-6,1.38964410683258E-8,5.971625653111E-7,3.84334603323775E-8,0.999865433526401,468.375305175781,12,5620,1,3,0.0115945600233749,0.00377297466473097,0.00573297357186675,120.272964477539,4.19905662536621,4.20256233215332,6000.28271484375,6000.28271484375,,,3.74705743789673,0,1,,,,,,1,1,1,4.20013618469238,0,0,4.20000152434072,,,,,,,,,,,,,,,,,,,,,,,,,,,,,,,,,
,3818723141.5,4.59997892379761,6000.28271484375,,,5,,,,23.14000017941,,,,,2.98714816643106E-6,1.1983925344919E-7,-1.3000803605412,0.0195213663294184,2.98711247579883E-6,1.19837821602331E-7,2.98634352584188E-6,1.04692576133737E-7,-6.77738056720592E-8,5.83143892094711E-8,1.000011948205,0.400388091802597,79.9224568741094,32,1,3,0.0099105120151056,-0.000106119085420825,0.0268012564629316,179.180953979492,4.59876918792725,4.60194158554077,6000.28271484375,6000.28271484375,,,3.89010453224182,0,1,,,,,,1,1,1,4.59976196289063,0,0,4.59999856184781,,,,,,,,,,,,,,,,,,,,,,,,,,,,,,,,,
,3818724075.96886,4.59997701644897,6000.28271484375,,,5,,,,23.14000017941,,,,,2.84092634889026E-6,5.69930421094645E-8,-0.652321213731654,0.0148024349756375,2.84094177515888E-6,5.69933515824564E-8,2.84075765328523E-6,3.84693387720543E-8,-3.23438579063539E-8,4.20517787857114E-8,0.999994570015918,1.10092270374298,29.0665274602881,31,1,3,0.00942557069965356,7.6226349976507E-5,0.0267304014414549,177.920806884766,4.59910821914673,4.60202264785767,6000.28271484375,6000.28271484375,,,3.8889639377594,0,1,,,,,,1,1,1,4.59997844696045,0,0,4.59999223407224,,,,,,,,,,,,,,,,,,,,,,,,,,,,,,,,,
,3818724503.42581,4.60005760192871,6000.28271484375,,,5,,,,23.14000017941,,,,,2.83858401020762E-6,6.30228465482219E-8,-0.1970417502225,0.0180776733164406,2.83858697472736E-6,6.30229123671202E-8,2.83857018888926E-6,3.65923502293168E-8,-9.76195887215891E-9,5.13116691204713E-8,0.999998955635406,3.00962328910828,12,36,1,3,0.00941147058116848,0.000340237737342554,0.0265203546732664,174.927810668945,4.59913682937622,4.60212230682373,6000.28271484375,6000.28271484375,,,3.88944625854492,0,1,,,,,,1,1,1,4.60009622573853,0,0,4.60000708045029,,,,,,,,,,,,,,,,,,,,,,,,,,,,,,,,,
,3818724810.52545,4.6000804901123,6000.28271484375,,,5,,,,23.14000017941,,,,,2.89633768899232E-6,6.02820388374366E-8,0.232294052048721,0.0143466329474326,2.89649063558676E-6,6.02852221446114E-8,2.89646683035287E-6,4.36833015419399E-8,1.17431983456229E-8,4.15460849590079E-8,0.999947195895418,8.29281997680664,12,99,1,3,0.00956372365191713,0.000897433043775808,0.0257682278752327,166.77587890625,4.59870147705078,4.60209989547729,6000.28271484375,6000.28271484375,,,3.89122438430786,0,1,,,,,,1,1,1,4.60006856918335,0,0,4.60001960118612,,,,,,,,,,,,,,,,,,,,,,,,,,,,,,,,,
,3818725064.41513,4.59952306747437,6000.28271484375,,,5,,,,23.14000017941,,,,,2.83926074536932E-6,4.88675427349414E-8,0.364763757285015,0.0134067926126521,2.8388388612768E-6,4.88602815353655E-8,2.83878133220387E-6,3.06705396574779E-8,1.8072858826886E-8,3.80347881397315E-8,1.00014861149686,22.6896495819092,12,272,1,3,0.00927487904099613,0.00155657790651663,0.021385733038187,149.407958984375,4.59867763519287,4.6014838218689,6000.28271484375,6000.28271484375,,,3.8924024105072,0,1,,,,,,1,1,1,4.59991598129272,0,0,4.59999356027377,,,,,,,,,,,,,,,,,,,,,,,,,,,,,,,,,
,3818725305.95338,4.59953856468201,6000.28271484375,,,5,,,,23.1299996376038,,,,,2.81476759709023E-6,2.90260096572922E-8,1.21626670231636,0.00810492290197992,2.81419547192034E-6,2.90201098768899E-8,2.81356142656528E-6,1.79342624211575E-8,5.97348568332004E-8,2.28151048359595E-8,1.00020329972654,62.2807731628418,12,747,1,3,0.00917894655658577,0.00156474420869693,0.0126414448022842,131.640045166016,4.59914875030518,4.60192966461182,6000.28271484375,6000.28271484375,,,3.89325976371765,0,1,,,,,,1,1,1,4.60006666183472,0,0,4.59999406337738,,,,,,,,,,,,,,,,,,,,,,,,,,,,,,,,,
,3818725552.09296,4.5995945930481,6000.28271484375,,,5,,,,23.14000017941,,,,,2.79760729930746E-6,1.21993062650043E-8,2.65425006886337,0.00142505698969451,2.79798279801968E-6,1.22009436727254E-8,2.79498103927172E-6,1.16083860709767E-8,1.29571324472668E-7,3.75611492531477E-9,0.999865796633033,171.026702880859,12,2052,1,3,0.00914301497439734,0.00141478990598911,0.00685602938756347,129.368713378906,4.59879684448242,4.60168361663818,6000.28271484375,6000.28271484375,,,3.89333963394165,0,1,,,,,,1,1,1,4.59989452362061,0,0,4.60000222176313,,,,,,,,,,,,,,,,,,,,,,,,,,,,,,,,,
,3818725784.97834,4.59954571723938,6000.28271484375,,,5,,,,23.14000017941,,,,,3.54420677660719E-6,4.26366473324555E-8,8.16360264502605,0.0109883141931006,3.54434162439298E-6,4.26382695452237E-8,3.50842552321833E-6,1.48065842330887E-8,5.0329702804094E-7,3.99848357900793E-8,0.999961954066487,468.375305175781,12,5620,1,3,0.0112250745480587,0.00340213942940837,0.00571726262569428,120.255630493164,4.59878158569336,4.60158348083496,6000.28271484375,6000.28271484375,,,3.89478397369385,0,1,,,,,,1,1,1,4.59989881515503,0,0,4.60000637830314,,,,,,,,,,,,,,,,,,,,,,,,,,,,,,,,,
,3818726228.28246,5.00004124641418,6000.28271484375,,,5,,,,23.14000017941,,,,,2.56556517613581E-6,6.80529166862894E-8,-0.619453083442073,0.0182916068892855,2.56551992493128E-6,6.8051716375153E-8,2.56536998657717E-6,4.92830123407774E-8,-2.77365677121472E-8,4.69278253941417E-8,1.00001763821988,0.400388091802597,79.9224568741094,32,1,3,0.0085123010995905,9.97512573155135E-6,0.0268031060695648,179.160766601562,4.99861478805542,5.00192403793335,6000.28271484375,6000.28271484375,,,4.02494478225708,0,1,,,,,,1,1,1,4.9999852180481,0,0,4.99999837675494,,,,,,,,,,,,,,,,,,,,,,,,,,,,,,,,,
,3818727162.06027,5.00007963180542,6000.28271484375,,,5,,,,23.14000017941,,,,,2.56429662616338E-6,4.58992029278118E-8,-0.499379428684913,0.0103906822100171,2.56428656634361E-6,4.58990228637332E-8,2.5641891683874E-6,3.73711127569627E-8,-2.23495649850856E-8,2.66480811908077E-8,1.00000392304819,1.10092270374298,29.0665274602881,31,1,3,0.00850755996921997,9.15133727111293E-5,0.0267125833779573,177.873489379883,4.99909496307373,5.00190353393555,6000.28271484375,6000.28271484375,,,4.02329444885254,0,1,,,,,,1,1,1,4.99999952316284,0,0,5.00001315470342,,,,,,,,,,,,,,,,,,,,,,,,,,,,,,,,,
,3818727594.70628,4.99998497962952,6000.28271484375,,,5,,,,23.14000017941,,,,,2.69450103031356E-6,5.21433766437E-8,-0.62601283028946,0.0140761869804049,2.69450283976684E-6,5.21434116598321E-8,2.69434201033293E-6,3.5784059859729E-8,-2.94395119975117E-8,3.7926724607881E-8,0.999999328464883,3.00962328910828,12,36,1,3,0.00893592375685782,0.000256071369860724,0.0265286229550838,174.931640625,4.99893760681152,5.00194787979126,6000.28271484375,6000.28271484375,,,4.02432155609131,0,1,,,,,,1,1,1,4.99998092651367,0,0,5.00000646637707,,,,,,,,,,,,,,,,,,,,,,,,,,,,,,,,,
,3818727903.93228,5.00006437301636,6000.28271484375,,,5,,,,23.14000017941,,,,,2.65804135833661E-6,5.10179943711181E-8,0.121589465067728,0.00648404331314728,2.6511423690216E-6,5.08855763419796E-8,2.65113639936262E-6,4.79090915910655E-8,5.62608176828926E-9,1.71482017300452E-8,1.00260227040072,8.29281997680664,12,99,1,3,0.00877844304475098,0.000806633491896663,0.0257484838366508,166.66780090332,4.99900054931641,5.00186538696289,6000.28271484375,6000.28271484375,,,4.02604818344116,0,1,,,,,,1,1,1,5.00003576278687,0,0,5.00000481229079,,,,,,,,,,,,,,,,,,,,,,,,,,,,,,,,,
,3818728157.57767,4.99963235855103,6000.28271484375,,,5,,,,23.1299996376038,,,,,2.6322886148934E-6,5.95287046281206E-8,0.447818824736306,0.01775711058689,2.63227219577409E-6,5.95283333128711E-8,2.63219179540976E-6,3.68936503243959E-8,2.05734008593972E-8,4.67170315061807E-8,1.00000623762213,22.6896495819092,12,272,1,3,0.00859667351851326,0.00145556294661543,0.0213747452944517,149.420486450195,4.99875259399414,5.00196218490601,6000.28271484375,6000.28271484375,,,4.0274338722229,0,1,,,,,,1,1,1,5.00001764297485,0,0,5.00000417232513,,,,,,,,,,,,,,,,,,,,,,,,,,,,,,,,,
,3818728401.30731,4.99966955184937,6000.28271484375,,,5,,,,23.14000017941,,,,,2.64986685244312E-6,2.58781616633256E-8,0.804711973328079,0.00587861460593661,2.64921315712157E-6,2.58717777828699E-8,2.64895187154879E-6,2.07097310549049E-8,3.72066403240654E-8,1.55066413281442E-8,1.00024675074551,62.2807731628418,12,747,1,3,0.00865156781718595,0.00141094294298253,0.0126439770683646,131.622695922852,4.99922132492065,5.00177526473999,6000.28271484375,6000.28271484375,,,4.02793741226196,0,1,,,,,,1,1,1,5.0000901222229,0,0,5.00001861228318,,,,,,,,,,,,,,,,,,,,,,,,,,,,,,,,,
,3818728638.26676,4.99954223632812,6000.28271484375,,,5,,,,23.1299996376038,,,,,2.64948980767055E-6,9.38776063847335E-9,1.79246527037336,0.00183861804882978,2.64989507246453E-6,9.38919658620566E-9,2.64859843222402E-6,8.05245754921216E-9,8.28869102589528E-8,4.82855464425454E-9,0.999847063833511,171.026702880859,12,2052,1,3,0.00867812536680182,0.00120943028756805,0.00686193723231554,129.372360229492,4.99892616271973,5.00212907791138,6000.28271484375,6000.28271484375,,,4.02942323684692,0,1,,,,,,1,1,1,4.99994564056396,0,0,4.99999407854947,,,,,,,,,,,,,,,,,,,,,,,,,,,,,,,,,
,3818728879.18563,4.99972677230835,6000.28271484375,,,5,,,,23.14000017941,,,,,3.33337247049348E-6,2.38502360985598E-8,7.02775170188897,0.00494058801199866,3.3330875946369E-6,2.38481978155601E-8,3.30804613005456E-6,1.75554100202796E-8,4.07803524939939E-7,1.61413790634491E-8,1.00008546905789,468.375305175781,12,5620,1,3,0.0106187365098619,0.00298961602213777,0.0056879511103034,120.349090576172,4.99890613555908,5.00132846832275,6000.28271484375,6000.28271484375,,,4.02957534790039,0,1,,,,,,1,1,1,5.00000333786011,0,0,5.00001363754272,,,,,,,,,,,,,,,,,,,,,,,,,,,,,,,,,
,3818729062.89918,4.99963450431824,6000.28271484375,,,5,,,,23.14000017941,,,,,2.45836416358365E-6,8.57954315940057E-9,7.82640283036295,0.00285230107085255,2.45839201045761E-6,8.57964034331683E-9,2.43549256907617E-6,5.1817089071999E-9,3.34764429198507E-7,6.83813726256756E-9,0.999988672728416,999.040954589844,12,11988,1,3,0.00743457704081585,0.00332901833769657,0.00739074079319835,89.1600646972656,4.99901390075684,5.00129222869873,6000.28271484375,6000.28271484375,,,4.02950191497803,0,1,,,,,,1,1,1,4.99997472763062,0,0,5.00000974439806,,,,,,,,,,,,,,,,,,,,,,,,,,,,,,,,,