File: data/ac dwie rel do testu programu.zip/Yb1/ac_800a.csv
[Data]

Comment,Time Stamp (sec),Temperature (K),Magnetic Field (Oe),Moment (emu),M. Std. Err. (emu),Transport Action,Averaging Time (sec),Frequency (Hz),Peak Amplitude (mm),Center Position (mm),Lockin Signal' (V),Lockin Signal (V),Range,M. Quad. Signal (emu),AC Moment (emu),AC M. Std Err. (emu),AC Phase (deg),AC Phase Std. Err. (deg),AC Susceptibility (emu/Oe),AC Suscept. Std Err. (emu/Oe),AC X' (emu/Oe),AC X' Std Err. (emu/Oe),AC X'' (emu/Oe),AC X'' Std Err. (emu/Oe),AC Drive (Oe),AC Frequency (Hz),AC Averaging Time (sec),AC Cycles,AC Range,AC Measure Type,AC Signal' (V),AC Signal'' (V),AC Trim Coil Ratio,AC Trim Coil Phase,Min. Temperature (K),Max. Temperature (K),Min. Field (Oe),Max. Field (Oe),Mass (grams),Motor Lag (deg),Pressure (Torr),Measure Count,Measurement Number,SQUID Status (code),Motor Status (code),Measure Status (code),Motor Current (amps),Motor Temp. (C),Temp. Status (code),Field Status (code),Chamber Status (code),Chamber Temp (K),Redirection State,Evercool Status,Average Temp (K),Rotation Angle (deg),Rotator state,DC Moment Fixed Ctr (emu),DC Moment Err Fixed Ctr (emu),DC Moment Free Ctr (emu),DC Moment Err Free Ctr (emu),DC Fixed Fit,DC Free Fit,DC Calculated Center (mm),DC Calculated Center Err (mm),DC Scan Length (mm),DC Scan Time (s),DC Number of Points,DC Squid Drift,DC Min V (V),DC Max V (V),DC Scans per Measure,Map 01,Map 02,Map 03,Map 04,Map 05,Map 06,Map 07,Map 08,Map 09,Map 10,Map 11,Map 12,Map 13,Map 14,Map 15,Map 16

,3818680525.68346,1.80053114891052,800.107482910156,,,5,,,,23.14000017941,,,,,7.4094593009995E-6,1.64318950715171E-7,1.24222244933883,0.0105954446041391,7.40934440188014E-6,1.64316402607142E-7,7.40760305113294E-6,1.44406412281901E-7,1.60628461109757E-7,7.84006904154682E-8,1.00001550732604,1.00057637691498,31.9815665633281,32,1,3,0.0245601331118334,0.000893207741688046,0.0262260288000107,178.077667236328,1.79851531982422,1.80138552188873,800.107482910156,800.107482910156,,,2.45377612113953,0,1,,,,,,1,1,1,1.80093479156494,0,0,1.79999127793819,,,,,,,,,,,,,,,,,,,,,,,,,,,,,,,,,

,3818680675.58151,1.79979598522186,800.107482910156,,,5,,,,23.14000017941,,,,,7.68112483573394E-6,1.47606076908809E-7,1.12997886397907,0.0110892385216817,7.68106064836041E-6,1.47604843437593E-7,7.67956691700527E-6,1.20582519657252E-7,1.51474918811878E-7,8.51295821635732E-8,1.00000835657684,1.30083453655243,24.5995928773607,32,1,3,0.0254593473292037,0.000957574951624086,0.0262118931859732,177.614929199219,1.79854035377502,1.80217444896698,800.107482910156,800.107482910156,,,2.45408535003662,0,1,,,,,,1,1,1,1.79973256587982,0,0,1.80002076830715,,,,,,,,,,,,,,,,,,,,,,,,,,,,,,,,,

,3818680797.75029,1.7999941110611,800.107482910156,,,5,,,,23.14000017941,,,,,7.55594647427476E-6,2.02859387358864E-7,1.92374045668937,0.0114623528993274,7.5558495169711E-6,2.02856784283355E-7,7.55159098220921E-6,1.83629915329639E-7,2.53644555488547E-7,8.62028371099986E-8,1.00001283208505,1.70109140872955,18.8114523627504,32,1,3,0.0250230888397534,0.00139522679228728,0.026161165907979,176.983215332031,1.79813694953918,1.80120050907135,800.107482910156,800.107482910156,,,2.45449781417847,0,1,,,,,,1,1,1,1.80018091201782,0,0,1.80000423136212,,,,,,,,,,,,,,,,,,,,,,,,,,,,,,,,,

,3818680903.56253,1.80005472898483,800.107482910156,,,5,,,,23.14000017941,,,,,7.57381109015759E-6,6.04110263922856E-8,1.96359565836785,0.00642761091602611,7.5737400096817E-6,6.04104594327385E-8,7.56929270635916E-6,3.57253969211491E-8,2.59510423126766E-7,4.87146756501662E-8,1.00000938512225,2.20184540748596,14.5332637301441,30,1,3,0.0250731100219487,0.00154856154572892,0.0261304769665003,176.193145751953,1.79890131950378,1.80187392234802,800.107482910156,800.107482910156,,,2.45430731773376,0,1,,,,,,1,1,1,1.80016851425171,0,0,1.79999569484166,,,,,,,,,,,,,,,,,,,,,,,,,,,,,,,,,

,3818680991.51195,1.79985231161118,800.107482910156,,,5,,,,23.14000017941,,,,,7.51425544820141E-6,5.55450275992417E-8,2.90519385538361,0.003733178948697,7.51424759223436E-6,5.55449695282977E-8,7.5045900320334E-6,4.8041218604295E-8,3.80848169885073E-7,2.78798306112835E-8,1.0000010454762,2.79977774620056,12,33,1,3,0.0248341906701564,0.00210032462664411,0.0260933246463537,175.134048461914,1.79864537715912,1.80194509029388,800.107482910156,800.107482910156,,,2.45437288284302,0,1,,,,,,1,1,1,1.79987180233002,0,0,1.80000880176638,,,,,,,,,,,,,,,,,,,,,,,,,,,,,,,,,

,3818681074.15292,1.79981303215027,800.107482910156,,,5,,,,23.14000017941,,,,,7.39932596186948E-6,4.01463640560482E-8,3.24867323179328,0.00374591320555919,7.39929832581314E-6,4.01462141116905E-8,7.38740752831626E-6,2.90588802071446E-8,4.19315781908283E-7,2.77001802992059E-8,1.00000373495636,3.59877109527588,12,43,1,3,0.0244216104824328,0.00241584536803005,0.0260099973529577,173.806976318359,1.79901432991028,1.80195832252502,800.107482910156,800.107482910156,,,2.45444512367249,0,1,,,,,,1,1,1,1.7998411655426,0,0,1.79999301637091,,,,,,,,,,,,,,,,,,,,,,,,,,,,,,,,,

,3818681154.67303,1.80028545856476,800.107482910156,,,5,,,,23.14000017941,,,,,7.34005274180735E-6,4.54079883202224E-8,3.70999844404213,0.00395435751599993,7.34005812961382E-6,4.5408021650971E-8,7.32467587673659E-6,3.49945774097597E-8,4.7494909923372E-7,2.8935583321706E-8,0.999999265972235,4.63792991638184,12,55,1,3,0.0241761489546828,0.00284388795234901,0.0259654335677624,172.365997314453,1.79909658432007,1.80148363113403,800.107482910156,800.107482910156,,,2.45469570159912,0,1,,,,,,1,1,1,1.80031490325928,0,0,1.79999873607974,,,,,,,,,,,,,,,,,,,,,,,,,,,,,,,,,

,3818681231.9776,1.79998737573624,800.107482910156,,,5,,,,23.14000017941,,,,,7.31205190982693E-6,5.78839989833876E-8,4.58106701592448,0.00673094226614944,7.31200138284604E-6,5.7883598999396E-8,7.28864191629984E-6,3.00648422586726E-8,5.84006197483767E-7,4.94632822716408E-8,1.00000691014378,5.99559497833252,12,71,1,3,0.0239919796309947,0.00351261912924094,0.0258061904460192,169.988739013672,1.7990996837616,1.80168795585632,800.107482910156,800.107482910156,,,2.45498871803284,0,1,,,,,,1,1,1,1.79988932609558,0,0,1.7999990613837,,,,,,,,,,,,,,,,,,,,,,,,,,,,,,,,,

,3818681313.81811,1.79989874362946,800.107482910156,,,5,,,,23.14000017941,,,,,7.29267735549735E-6,4.50315341464811E-8,5.31395495300899,0.00426519054120381,7.2925219244134E-6,4.50305743754912E-8,7.26117991134295E-6,3.26640282397399E-8,6.75383086225699E-7,3.09969980440062E-8,1.000021313763,7.74557828903198,12,92,1,3,0.0238154118297379,0.00418371570825102,0.0253861136734486,167.138702392578,1.79909121990204,1.80203354358673,800.107482910156,800.107482910156,,,2.4546582698822,0,1,,,,,,1,1,1,1.79957020282745,0,0,1.80000169924748,,,,,,,,,,,,,,,,,,,,,,,,,,,,,,,,,

,3818681390.98844,1.79969096183777,800.107482910156,,,5,,,,23.14000017941,,,,,7.25654997479803E-6,3.42077690171278E-8,6.63340501164894,0.00204194942659997,7.25647913753097E-6,3.42074350864199E-8,7.20790125661377E-6,3.14543826322065E-8,8.38241581125607E-7,1.34450893793377E-8,1.00000976193354,10.005763053894,12,120,1,3,0.0235010445167562,0.00513438091573974,0.0248135030269623,163.734161376953,1.79864048957825,1.80158185958862,800.107482910156,800.107482910156,,,2.454829454422,0,1,,,,,,1,1,1,1.8000705242157,0,0,1.79999937204754,,,,,,,,,,,,,,,,,,,,,,,,,,,,,,,,,

,3818681455.76682,1.80009663105011,800.107482910156,,,5,,,,23.14000017941,,,,,7.15602227835329E-6,1.55184197741427E-8,8.05842295184414,0.00107205911968572,7.15662285727958E-6,1.55197221786802E-8,7.08595580772903E-6,1.3924048943167E-8,1.00323527262938E-6,6.85438819528822E-9,0.999916080679635,12.9311771392822,12,155,1,3,0.0229206944890766,0.00608816905874721,0.023968867957592,159.634567260742,1.79856061935425,1.80119824409485,800.107482910156,800.107482910156,,,2.45568704605103,0,1,,,,,,1,1,1,1.80053818225861,0,0,1.80000099114009,,,,,,,,,,,,,,,,,,,,,,,,,,,,,,,,,

,3818681520.15678,1.79942113161087,800.107482910156,,,5,,,,23.14000017941,,,,,7.03844132406322E-6,1.12887382833508E-8,9.7408968447716,0.000765786427850236,7.03952004875269E-6,1.12904684165065E-8,6.93803095646023E-6,1.0503732931377E-8,1.19103692805493E-6,4.14080566682841E-9,0.999846761614145,16.6762714385986,12,200,1,3,0.0222207100961342,0.00706802195063844,0.022801473736763,154.929779052734,1.79895687103271,1.80151045322418,800.107482910156,800.107482910156,,,2.45543360710144,0,1,,,,,,1,1,1,1.79970622062683,0,0,1.80001067183912,,,,,,,,,,,,,,,,,,,,,,,,,,,,,,,,,

,3818681585.04191,1.79973459243774,800.107482910156,,,5,,,,23.14000017941,,,,,6.88885437986734E-6,1.49355266378358E-8,11.7182379614038,0.00111617607124817,6.88881523129944E-6,1.4935441760954E-8,6.74523999977329E-6,1.41285627615609E-8,1.39911137385181E-6,4.84263718313522E-9,1.00000568291739,21.5291557312012,12,258,1,3,0.0213654095555442,0.00799762311961445,0.0211982112377882,149.749481201172,1.79902839660645,1.80199694633484,800.107482910156,800.107482910156,,,2.45589256286621,0,1,,,,,,1,1,1,1.80012738704681,0,0,1.80000059945243,,,,,,,,,,,,,,,,,,,,,,,,,,,,,,,,,

,3818681649.50368,1.79959172010422,800.107482910156,,,5,,,,23.14000017941,,,,,6.69131191855988E-6,1.43067434211242E-8,13.9471318852548,0.00144527102218509,6.68970949509261E-6,1.43033172676766E-8,6.4924870921946E-6,1.20616399414288E-8,1.61239712429002E-6,7.68776474556451E-9,1.00023953558349,27.8064498901367,12,333,1,3,0.0203449224779069,0.00875855958577131,0.019269997254014,144.351928710938,1.79892289638519,1.80191373825073,800.107482910156,800.107482910156,,,2.4557774066925,0,1,,,,,,1,1,1,1.79989242553711,0,0,1.79999985581353,,,,,,,,,,,,,,,,,,,,,,,,,,,,,,,,,

,3818681713.75638,1.79969203472137,800.107482910156,,,5,,,,23.14000017941,,,,,6.42465945625834E-6,7.38125340039454E-9,16.2609870761258,0.000864844201007747,6.42300313047164E-6,7.37935045745592E-9,6.16605844715782E-6,5.89213121324536E-9,1.79852507357615E-6,4.4427022114761E-9,1.00025787404319,35.9030342102051,12,430,1,3,0.0191590934813712,0.00921386370748291,0.0170408617705107,139.191482543945,1.7987447977066,1.80147290229797,800.107482910156,800.107482910156,,,2.45597457885742,0,1,,,,,,1,1,1,1.79991793632507,0,0,1.80001906175462,,,,,,,,,,,,,,,,,,,,,,,,,,,,,,,,,

,3818681777.80624,1.7996569275856,800.107482910156,,,5,,,,23.14000017941,,,,,6.11025143451978E-6,8.56522394220023E-9,18.7957293735333,0.00112906824816524,6.10871724332213E-6,8.56307334474629E-9,5.78295937735985E-6,6.97823627954388E-9,1.96819897334261E-6,4.96290676261021E-9,1.0002511478493,46.4145660400391,12,556,1,3,0.0178720439447449,0.00944138522339518,0.0147001007571816,134.693099975586,1.79906952381134,1.80201816558838,800.107482910156,800.107482910156,,,2.45589780807495,0,1,,,,,,1,1,1,1.80007779598236,0,0,1.79999230778407,,,,,,,,,,,,,,,,,,,,,,,,,,,,,,,,,

,3818681842.01058,1.79983365535736,800.107482910156,,,5,,,,23.14000017941,,,,,5.74631882495875E-6,8.25130209837182E-9,21.2780595040334,0.00124583048846575,5.74622721065556E-6,8.25117054679677E-9,5.35450839847982E-6,6.4213481351377E-9,2.08527383503641E-6,5.18151556204264E-9,1.00001594338334,59.9854125976563,12,719,1,3,0.0165172208963582,0.00939839612451321,0.012463329359889,131.273040771484,1.7989102602005,1.8014475107193,800.107482910156,800.107482910156,,,2.45638155937195,0,1,,,,,,1,1,1,1.80016350746155,0,0,1.80000672832368,,,,,,,,,,,,,,,,,,,,,,,,,,,,,,,,,

,3818681907.88422,1.79961079359055,800.107482910156,,,5,,,,23.14000017941,,,,,5.37677978506569E-6,7.04035157839784E-9,23.4971009427209,0.00116099040194731,5.37666062540465E-6,7.04019555082348E-9,4.93082926596454E-6,3.8138709533116E-9,2.14368893048507E-6,5.91766353769128E-9,1.00002216239211,77.5049591064453,12,930,1,3,0.0152316917134234,0.00916905078694203,0.010449705645442,129.190032958984,1.7992650270462,1.80214381217957,800.107482910156,800.107482910156,,,2.45602226257324,0,1,,,,,,1,1,1,1.79983866214752,0,0,1.80000695265256,,,,,,,,,,,,,,,,,,,,,,,,,,,,,,,,,

,3818681968.01294,1.79954063892365,800.107482910156,,,5,,,,23.14000017941,,,,,4.9754662258955E-6,1.09736814874838E-8,25.4640817548539,0.00222992542017649,4.97538154155658E-6,1.0973494711226E-8,4.49204805585151E-6,9.88079401836836E-9,2.13914135764391E-6,4.77362501081534E-9,1.00001702067233,100.057640075684,12,1200,1,3,0.0139101692560163,0.0087806068145497,0.00883736647665501,128.364410400391,1.79886913299561,1.80174684524536,800.107482910156,800.107482910156,,,2.45681500434875,0,1,,,,,,1,1,1,1.79990315437317,0,0,1.79999806719311,,,,,,,,,,,,,,,,,,,,,,,,,,,,,,,,,

,3818682032.34428,1.79972779750824,800.107482910156,,,5,,,,23.14000017941,,,,,4.57966629877687E-6,5.82605771828546E-9,27.2703473558667,0.00132528036630014,4.58042920487908E-6,5.82702825515323E-9,4.07133502558223E-6,4.65187057893095E-9,2.09870503176995E-6,3.50918201340864E-9,0.999833442223844,129.174926757812,12,1550,1,3,0.0126244977026071,0.00835776239745294,0.00754499668255448,128.510299682617,1.79896950721741,1.80145347118378,800.107482910156,800.107482910156,,,2.45677328109741,0,1,,,,,,1,1,1,1.80001842975616,0,0,1.8000021725893,,,,,,,,,,,,,,,,,,,,,,,,,,,,,,,,,

,3818682096.81643,1.79949229955673,800.107482910156,,,5,,,,23.14000017941,,,,,4.20658592198026E-6,6.16948237991732E-9,28.7182730409656,0.00157298870966978,4.2065805739561E-6,6.16947453637354E-9,3.68914156565132E-6,4.55490842367645E-9,2.02127549675162E-6,4.1611567270271E-9,1.00000127134714,166.93376159668,12,2003,1,3,0.0114388230506993,0.00790960598334274,0.00660987151786685,129.023681640625,1.79882156848907,1.80170512199402,800.107482910156,800.107482910156,,,2.45662784576416,0,1,,,,,,1,1,1,1.79996848106384,0,0,1.80000240462167,,,,,,,,,,,,,,,,,,,,,,,,,,,,,,,,,

,3818682165.81424,1.79976159334183,800.107482910156,,,5,,,,23.14000017941,,,,,3.82881056435196E-6,5.76106911083335E-9,29.8937538825439,0.0016002303246389,3.82917173525935E-6,5.76161255128916E-9,3.31970459659316E-6,3.64763658269794E-9,1.90843327613709E-6,4.45992450067671E-9,0.999905679104423,215.576721191406,12,2586,1,3,0.0102581802850182,0.00741785705950412,0.00598155055195093,129.17643737793,1.79891729354858,1.80212330818176,800.107482910156,800.107482910156,,,2.45632195472717,0,1,,,,,,1,1,1,1.79994797706604,0,0,1.79999849375556,,,,,,,,,,,,,,,,,,,,,,,,,,,,,,,,,

,3818682232.52123,1.79971206188202,800.107482910156,,,5,,,,23.14000017941,,,,,3.48160083369283E-6,9.27893912567045E-9,30.7954891016897,0.00300361148723946,3.48180574748253E-6,9.27948524875332E-9,2.99087185927487E-6,5.84832085703792E-9,1.78259832396422E-6,7.20458115610934E-9,0.999941147265367,278.222930908203,12,3338,1,3,0.00917437726539481,0.00695531759682693,0.00559936696663499,128.193817138672,1.79902338981628,1.80228662490845,800.107482910156,800.107482910156,,,2.45639777183533,0,1,,,,,,1,1,1,1.79996049404144,0,0,1.79999786434752,,,,,,,,,,,,,,,,,,,,,,,,,,,,,,,,,

,3818682296.59726,1.79973870515823,800.107482910156,,,5,,,,23.14000017941,,,,,3.15512433800491E-6,7.11378781258819E-9,31.5450055183709,0.00247432508626713,3.15475364210815E-6,7.11295201289535E-9,2.68857406105027E-6,3.71682885125359E-9,1.65046661906331E-6,6.06459146424893E-9,1.00011750391277,359.691528320313,12,4316,1,3,0.00814176313474062,0.00652772439632898,0.00541729433462024,125.386566162109,1.79892563819885,1.8017590045929,800.107482910156,800.107482910156,,,2.45651125907898,0,1,,,,,,1,1,1,1.79992473125458,0,0,1.79999777438149,,,,,,,,,,,,,,,,,,,,,,,,,,,,,,,,,

,3818682363.22899,1.7992616891861,800.107482910156,,,5,,,,23.14000017941,,,,,2.84992638945816E-6,6.47285853826513E-9,32.2968654497809,0.00295176115196504,2.84966447445097E-6,6.47226366718464E-9,2.40879591970904E-6,3.77649484414646E-9,1.52259312823255E-6,5.2562613776042E-9,1.00009191082303,463.925201416016,12,5567,1,3,0.00714431125455984,0.00615304369466929,0.00540934037417173,120.318939208984,1.79849362373352,1.80175745487213,800.107482910156,800.107482910156,,,2.45667243003845,0,1,,,,,,1,1,1,1.79954349994659,0,0,1.79999568245628,,,,,,,,,,,,,,,,,,,,,,,,,,,,,,,,,

,3818682427.41714,1.79977053403854,800.107482910156,,,5,,,,23.14000017941,,,,,2.56530886138428E-6,5.97672565384382E-9,32.5747133612548,0.00401950465682398,2.56565320879982E-6,5.97752792372377E-9,2.162050542192E-6,4.17570302167703E-9,1.38134493911988E-6,4.27718883773615E-9,0.999865785674247,600.038391113281,12,7200,1,3,0.00622424094054803,0.0057742696836282,0.00564941857010126,112.598388671875,1.79879689216614,1.80136346817017,800.107482910156,800.107482910156,,,2.45682859420776,0,1,,,,,,1,1,1,1.80037772655487,0,0,1.79999843476311,,,,,,,,,,,,,,,,,,,,,,,,,,,,,,,,,

,3818682491.64012,1.80008798837662,800.107482910156,,,5,,,,23.14000017941,,,,,2.27148816223885E-6,4.62779496870083E-9,32.4488223761723,0.00385207537392546,2.27180933393488E-6,4.62844930482447E-9,1.91711409396533E-6,2.93882310559449E-9,1.21893035095248E-6,3.57573233357226E-9,0.999858627354316,775.049621582031,12,9300,1,3,0.00529618122286878,0.00534004921176404,0.00619446858763695,102.182312011719,1.79878377914429,1.80173349380493,800.107482910156,800.107482910156,,,2.45690870285034,0,1,,,,,,1,1,1,1.80039346218109,0,0,1.8000196805076,,,,,,,,,,,,,,,,,,,,,,,,,,,,,,,,,

,3818682555.72722,1.79960942268372,800.107482910156,,,5,,,,23.14000017941,,,,,1.92574506548265E-6,6.73635431283498E-9,31.8650608637022,0.00769383287297003,1.92574170000204E-6,6.7363425402124E-9,1.63552043426435E-6,4.02793865373367E-9,1.01663858092761E-6,5.39944636243694E-9,1.00000174762826,999.040954589844,12,11988,1,3,0.00427042196387769,0.00473911017924476,0.00721818814054131,89.2161865234375,1.79871845245361,1.80197250843048,800.107482910156,800.107482910156,,,2.45644593238831,0,1,,,,,,1,1,1,1.79967558383942,0,0,1.79999419242617,,,,,,,,,,,,,,,,,,,,,,,,,,,,,,,,,

,3818682776.28326,2.20009863376617,800.107482910156,,,5,,,,23.14000017941,,,,,6.26657006883913E-6,1.10186377585846E-7,0.139901944135688,0.00927852435540832,6.2666073845888E-6,1.10187033716271E-7,6.26658870340002E-6,9.35990238352904E-8,1.53014705884309E-8,5.8141251588449E-8,0.999994045302765,1.00057637691498,31.9815665633281,32,1,3,0.0207824872508302,0.000355685663673506,0.0262346994131804,178.119232177734,2.19874572753906,2.20274567604065,800.107482910156,800.107482910156,,,2.74529075622559,0,1,,,,,,1,1,1,2.20021200180054,0,0,2.2000088490449,,,,,,,,,,,,,,,,,,,,,,,,,,,,,,,,,

,3818682925.60951,2.19977486133575,800.107482910156,,,5,,,,23.14000017941,,,,,6.23480203390584E-6,1.58397599831367E-7,1.57975847384211,0.0088526184568624,6.2347759734587E-6,1.5839693775545E-7,6.23240624018484E-6,1.48582826842096E-7,1.71883380589446E-7,5.4888372702382E-8,1.00000417985301,1.30083453655243,24.5995928773607,32,1,3,0.020658723331584,0.000939467643820217,0.0262053888291121,177.609848022461,2.19909405708313,2.20184302330017,800.107482910156,800.107482910156,,,2.74681520462036,0,1,,,,,,1,1,1,2.19926834106445,0,0,2.20000859722495,,,,,,,,,,,,,,,,,,,,,,,,,,,,,,,,,

,3818683047.79174,2.20001077651978,800.107482910156,,,5,,,,23.14000017941,,,,,6.20499702687495E-6,6.75835304917558E-8,0.96965551238597,0.00830922992028601,6.20498779069151E-6,6.75834298931765E-8,6.20409922355549E-6,4.36859705299833E-8,1.05006223190933E-7,5.15660350907391E-8,1.00000148850953,1.70109140872955,18.8114523627504,32,1,3,0.0205653681839066,0.000803443003914085,0.0261623002588749,176.998733520508,2.19885635375977,2.2024130821228,800.107482910156,800.107482910156,,,2.74747443199158,0,1,,,,,,1,1,1,2.20009469985962,0,0,2.19998760223389,,,,,,,,,,,,,,,,,,,,,,,,,,,,,,,,,

,3818683153.71454,2.19996440410614,800.107482910156,,,5,,,,23.14000017941,,,,,6.16538445938177E-6,1.14071207716415E-7,1.00912439316784,0.00451723169122471,6.16529721047667E-6,1.14069593447582E-7,6.16434099242299E-6,1.10684757539503E-7,1.0858094973332E-7,2.75818164325386E-8,1.0000141516138,2.20184540748596,14.5332637301441,30,1,3,0.0204286789651961,0.000920417944281576,0.0261498764157295,176.207931518555,2.19870853424072,2.20155310630798,800.107482910156,800.107482910156,,,2.74727821350098,0,1,,,,,,1,1,1,2.19985294342041,0,0,2.20002232279096,,,,,,,,,,,,,,,,,,,,,,,,,,,,,,,,,

,3818683241.69507,2.19995212554932,800.107482910156,,,5,,,,23.14000017941,,,,,6.09606506359767E-6,5.52360992594055E-8,1.11793928140789,0.00684027890545761,6.09600317815464E-6,5.52355385189216E-8,6.09484281861059E-6,3.62150202212338E-8,1.18935968077104E-7,4.17065585471986E-8,1.00001015180623,2.79977774620056,12,33,1,3,0.0201904930662459,0.00107473434193342,0.0260830894112587,175.226150512695,2.19880127906799,2.20201349258423,800.107482910156,800.107482910156,,,2.74762606620789,0,1,,,,,,1,1,1,2.19985175132751,0,0,2.19999798332773,,,,,,,,,,,,,,,,,,,,,,,,,,,,,,,,,

,3818683324.22935,2.20006537437439,800.107482910156,,,5,,,,23.14000017941,,,,,6.11013342267868E-6,3.73333211412837E-8,1.72380399215317,0.00354491459769651,6.11012391536927E-6,3.73332630509916E-8,6.10735877130932E-6,3.04351317717256E-8,1.83801794546874E-7,2.16211767504045E-8,1.0000015559929,3.59877109527588,12,43,1,3,0.020212552327505,0.0014575700544603,0.0260177738964558,173.833023071289,2.19829845428467,2.20215487480164,800.107482910156,800.107482910156,,,2.74785542488098,0,1,,,,,,1,1,1,2.20001077651978,0,0,2.19997537426832,,,,,,,,,,,,,,,,,,,,,,,,,,,,,,,,,

,3818683405.45827,2.19968235492706,800.107482910156,,,5,,,,23.14000017941,,,,,6.14040741476982E-6,6.54960406335886E-8,2.02635519354378,0.00491452767548458,6.14033310159316E-6,6.54952479795334E-8,6.13649335511786E-6,5.82424559735948E-8,2.17117251997924E-7,2.99573668746846E-8,1.00001210246666,4.63792991638184,12,55,1,3,0.0202860103968015,0.00178383310499557,0.0259922407567501,172.094451904297,2.19895362854004,2.20187139511108,800.107482910156,800.107482910156,,,2.74791812896729,0,1,,,,,,1,1,1,2.19960641860962,0,0,2.19999739489978,,,,,,,,,,,,,,,,,,,,,,,,,,,,,,,,,

,3818683485.59715,2.199991106987,800.107482910156,,,5,,,,23.14000017941,,,,,6.15106114372838E-6,6.81259610624029E-8,2.30517536495138,0.00517548496048989,6.1509134959982E-6,6.8124325792767E-8,6.14593596795809E-6,6.03963383437057E-8,2.474023302473E-7,3.15151722094563E-8,1.00002400419552,5.99559497833252,12,71,1,3,0.020284011544282,0.00215107969369968,0.0257221907377243,170.008880615234,2.19911122322083,2.20248746871948,800.107482910156,800.107482910156,,,2.74829053878784,0,1,,,,,,1,1,1,2.20007514953613,0,0,2.20000643669804,,,,,,,,,,,,,,,,,,,,,,,,,,,,,,,,,

,3818683566.53612,2.20009243488312,800.107482910156,,,5,,,,23.14000017941,,,,,6.07924767634752E-6,2.74506300762444E-8,3.04410566519842,0.00244552541939959,6.07921733342244E-6,2.74504930638284E-8,6.07063926127903E-6,2.31714228788903E-8,3.22834859334452E-7,1.47178371785711E-8,1.00000499125519,7.74557828903198,12,92,1,3,0.0199753150680843,0.00269855564632494,0.0253162011504173,167.1845703125,2.19861793518066,2.2023594379425,800.107482910156,800.107482910156,,,2.74870276451111,0,1,,,,,,1,1,1,2.20035791397095,0,0,2.19999105632305,,,,,,,,,,,,,,,,,,,,,,,,,,,,,,,,,

,3818683643.69496,2.1998336315155,800.107482910156,,,5,,,,23.14000017941,,,,,6.09901190936345E-6,2.09786759120495E-8,3.83014518637913,0.00164487216640626,6.09860204473785E-6,2.09772661071047E-8,6.08498058117855E-6,1.85741958819618E-8,4.07379708332068E-7,9.74909947978761E-9,1.0000672063241,10.005763053894,12,120,1,3,0.01993965936162,0.00334417617320042,0.0247993599623442,163.748611450195,2.19917821884155,2.20158529281616,800.107482910156,800.107482910156,,,2.74812006950378,0,1,,,,,,1,1,1,2.19987678527832,0,0,2.1999806355739,,,,,,,,,,,,,,,,,,,,,,,,,,,,,,,,,

,3818683708.3204,2.19978260993958,800.107482910156,,,5,,,,23.14000017941,,,,,6.06839650238443E-6,2.08230075772102E-8,4.88083982143318,0.00122790229672004,6.06858744212636E-6,2.08236627650661E-8,6.04658155825878E-6,1.97672364035538E-8,5.16338069542257E-7,6.54838116783213E-9,0.999968536377905,12.9311771392822,12,155,1,3,0.0196933350841052,0.00407748368750976,0.0239744056016207,159.624496459961,2.19866371154785,2.20156407356262,800.107482910156,800.107482910156,,,2.74896907806396,0,1,,,,,,1,1,1,2.20014476776123,0,0,2.19997875652616,,,,,,,,,,,,,,,,,,,,,,,,,,,,,,,,,

,3818683772.77767,2.19989800453186,800.107482910156,,,5,,,,23.14000017941,,,,,6.01659940105928E-6,1.23352252843077E-8,6.05204225767249,0.00118773736436855,6.01746726499876E-6,1.23370045779744E-8,5.98392915798146E-6,1.02550658494778E-8,6.3443212213042E-7,6.85822909939848E-9,0.999855775876917,16.6762714385986,12,200,1,3,0.019344077342981,0.00480726943573866,0.0227929726243019,154.937866210938,2.19896578788757,2.20232486724854,800.107482910156,800.107482910156,,,2.74907350540161,0,1,,,,,,1,1,1,2.20014905929565,0,0,2.20001516491175,,,,,,,,,,,,,,,,,,,,,,,,,,,,,,,,,

,3818683837.33019,2.20006489753723,800.107482910156,,,5,,,,23.14000017941,,,,,5.96793674846849E-6,7.90080279932558E-9,7.48284096044937,0.000911470531477553,5.96790434398648E-6,7.90075989983905E-9,5.91708111631172E-6,5.85076481430096E-9,7.77195806705084E-7,5.30947813656319E-9,1.00000542979246,21.5291557312012,12,258,1,3,0.018970388601178,0.0055425576709818,0.0211980473250151,149.74951171875,2.19922804832458,2.20189118385315,800.107482910156,800.107482910156,,,2.74908804893494,0,1,,,,,,1,1,1,2.20033144950867,0,0,2.19999234638517,,,,,,,,,,,,,,,,,,,,,,,,,,,,,,,,,

,3818683901.4914,2.19974207878113,800.107482910156,,,5,,,,23.14000017941,,,,,5.88242239015984E-6,8.55784495248863E-9,9.24389765790619,0.000855028577930007,5.88104585113162E-6,8.55584234084444E-9,5.80467153746788E-6,7.31980819091278E-9,9.44716171780019E-7,4.4297681891531E-9,1.00023406364498,27.8064498901367,12,333,1,3,0.0184566182218225,0.00620730243323276,0.0192708354443312,144.353805541992,2.19878911972046,2.20198941230774,800.107482910156,800.107482910156,,,2.74941921234131,0,1,,,,,,1,1,1,2.20011973381042,0,0,2.19998728282868,,,,,,,,,,,,,,,,,,,,,,,,,,,,,,,,,

,3818683965.59251,2.19972097873688,800.107482910156,,,5,,,,23.14000017941,,,,,5.77461013393946E-6,8.18446641586264E-9,11.3627271973679,0.000912411289561588,5.77337497104451E-6,8.18271579564805E-9,5.66021422265989E-6,6.78514172801289E-9,1.13746802587234E-6,4.57369539028632E-9,1.00021394122175,35.9030342102051,12,430,1,3,0.01786482649577,0.00678092287859594,0.0170353502035141,139.184204101562,2.19912052154541,2.20198464393616,800.107482910156,800.107482910156,,,2.74951243400574,0,1,,,,,,1,1,1,2.19983005523682,0,0,2.19998970864311,,,,,,,,,,,,,,,,,,,,,,,,,,,,,,,,,

,3818684031.43571,2.19964647293091,800.107482910156,,,5,,,,23.14000017941,,,,,5.60195583453609E-6,7.8493174121366E-9,13.6593950648669,0.000930689113358138,5.60061335944006E-6,7.84743637032587E-9,5.4422096480392E-6,6.62181310211195E-9,1.32258237880578E-6,4.21115765876935E-9,1.00023970144159,46.4145660400391,12,556,1,3,0.0170944689631817,0.0071542799515682,0.0147154927253723,134.691070556641,2.1988160610199,2.20249915122986,800.107482910156,800.107482910156,,,2.74945330619812,0,1,,,,,,1,1,1,2.19968271255493,0,0,2.19999564977793,,,,,,,,,,,,,,,,,,,,,,,,,,,,,,,,,

,3818684095.39545,2.1999020576477,800.107482910156,,,5,,,,23.14000017941,,,,,5.38939455023264E-6,6.11990085850977E-9,16.3579019393449,0.000861401824550558,5.38854926064871E-6,6.11894099401995E-9,5.17042706905913E-6,4.55880412823442E-9,1.51761228842496E-6,4.08151244132499E-9,1.00015686774734,59.9854125976563,12,719,1,3,0.0161902215328051,0.00745346050360327,0.0124701205641031,131.283615112305,2.19903063774109,2.20215034484863,800.107482910156,800.107482910156,,,2.74995398521423,0,1,,,,,,1,1,1,2.19996643066406,0,0,2.20002152427794,,,,,,,,,,,,,,,,,,,,,,,,,,,,,,,,,

,3818684161.46733,2.19989991188049,800.107482910156,,,5,,,,23.14000017941,,,,,5.13819595858516E-6,7.92392660477973E-9,19.1280687459243,0.00117852401864648,5.13820404221039E-6,7.92393907103316E-9,4.8545160760198E-6,6.63821361111516E-9,1.68369072191199E-6,4.32700016809004E-9,0.999998426760564,77.5049591064453,12,930,1,3,0.0151810467531301,0.00762781757856954,0.0104530667886138,129.188232421875,2.19875383377075,2.20206809043884,800.107482910156,800.107482910156,,,2.74994301795959,0,1,,,,,,1,1,1,2.20033550262451,0,0,2.20003357300392,,,,,,,,,,,,,,,,,,,,,,,,,,,,,,,,,

,3818684225.8698,2.19995760917664,800.107482910156,,,5,,,,23.14000017941,,,,,4.84652451201923E-6,5.55551679110995E-9,21.9079735852179,0.000963657932787683,4.84646212995138E-6,5.55544528324395E-9,4.49647165864662E-6,4.17007222072349E-9,1.80829693359265E-6,3.67062255878587E-9,1.00001287167137,100.057640075684,12,1200,1,3,0.0140541333696935,0.00769609406602053,0.00883358716964722,128.364761352539,2.19893932342529,2.20201635360718,800.107482910156,800.107482910156,,,2.75000596046448,0,1,,,,,,1,1,1,2.20012736320496,0,0,2.19998300643194,,,,,,,,,,,,,,,,,,,,,,,,,,,,,,,,,

,3818684289.99232,2.19992911815643,800.107482910156,,,5,,,,23.14000017941,,,,,4.51904600635778E-6,1.00456322918416E-8,24.4809986219658,0.00196411320418288,4.51977882639818E-6,1.0047261317227E-8,4.11344505247422E-6,5.61279649591569E-9,1.8729576716607E-6,8.33330519494412E-9,0.999837863738792,129.174926757812,12,1550,1,3,0.0128440089116911,0.00763106421952603,0.00754506001248956,128.511276245117,2.19892859458923,2.20205307006836,800.107482910156,800.107482910156,,,2.75069117546082,0,1,,,,,,1,1,1,2.2004063129425,0,0,2.20001338777088,,,,,,,,,,,,,,,,,,,,,,,,,,,,,,,,,

,3818684356.75312,2.19993054866791,800.107482910156,,,5,,,,23.14000017941,,,,,4.16194270479563E-6,4.48329278559364E-9,26.7906576201693,0.00100166082725861,4.16241106814932E-6,4.4837973120116E-9,3.715615052608E-6,2.63615562806117E-9,1.87613184000614E-6,3.62699901293671E-9,0.999887477871354,166.93376159668,12,2003,1,3,0.011574303052333,0.00744047165081209,0.00664520915597677,129.036987304688,2.19874024391174,2.20147585868835,800.107482910156,800.107482910156,,,2.7503228187561,0,1,,,,,,1,1,1,2.20010805130005,0,0,2.20000293399348,,,,,,,,,,,,,,,,,,,,,,,,,,,,,,,,,

,3818684422.58988,2.19983518123627,800.107482910156,,,5,,,,23.14000017941,,,,,3.80034462830655E-6,5.80510275228066E-9,28.6065294236951,0.00158445365582722,3.80024509920989E-6,5.80495071958641E-9,3.33634316807839E-6,3.97917972985327E-9,1.81952660845767E-6,4.22653303954336E-9,1.00002619017828,215.576721191406,12,2586,1,3,0.0103448052065185,0.00713202552800051,0.00597711186856031,129.191421508789,2.19871783256531,2.20225763320923,800.107482910156,800.107482910156,,,2.75006437301636,0,1,,,,,,1,1,1,2.19993472099304,0,0,2.20001809780414,,,,,,,,,,,,,,,,,,,,,,,,,,,,,,,,,

,3818684488.61641,2.19964683055878,800.107482910156,,,5,,,,23.14000017941,,,,,3.44601932285626E-6,4.24782405141207E-9,30.2072659884162,0.00144091377411676,3.44606938150074E-6,4.24788575748336E-9,2.97813108113535E-6,3.03960712730491E-9,1.73381932325501E-6,2.96737626873761E-9,0.999985473698019,278.222930908203,12,3338,1,3,0.00915088824387376,0.00679054133818188,0.00556817092001438,128.199554443359,2.19887924194336,2.20253920555115,800.107482910156,800.107482910156,,,2.74999642372131,0,1,,,,,,1,1,1,2.19948792457581,0,0,2.19998815243061,,,,,,,,,,,,,,,,,,,,,,,,,,,,,,,,,

,3818684552.71205,2.19997549057007,800.107482910156,,,5,,,,23.14000017941,,,,,3.11903250790713E-6,4.52166733579827E-9,31.3765664173432,0.00184959048230559,3.11876054428828E-6,4.52127306962478E-9,2.66268490118262E-6,3.10102570171309E-9,1.62381539887494E-6,3.29022032201934E-9,1.00008720246873,359.691528320313,12,4316,1,3,0.00806765605688923,0.00642924042422826,0.0054011344909668,125.392684936523,2.19886922836304,2.20173001289368,800.107482910156,800.107482910156,,,2.75048303604126,0,1,,,,,,1,1,1,2.20011520385742,0,0,2.20002202760606,,,,,,,,,,,,,,,,,,,,,,,,,,,,,,,,,

,3818684616.98097,2.19998097419739,800.107482910156,,,5,,,,23.14000017941,,,,,2.82309953997745E-6,5.19469235898153E-9,32.2161907562241,0.00245949530936488,2.82273006034865E-6,5.19401249170184E-9,2.3881497413183E-6,3.17426807350073E-9,1.50484079112617E-6,4.11117841518812E-9,1.00013089442522,463.925201416016,12,5567,1,3,0.00708574653083367,0.00608501211072643,0.00541921006515622,120.336791992187,2.19896030426025,2.20200991630554,800.107482910156,800.107482910156,,,2.75053238868713,0,1,,,,,,1,1,1,2.19990372657776,0,0,2.19998011513362,,,,,,,,,,,,,,,,,,,,,,,,,,,,,,,,,

,3818684681.14318,2.19978511333466,800.107482910156,,,5,,,,23.14000017941,,,,,2.53792631945818E-6,5.34011599860119E-9,32.8697662700346,0.00307561909683313,2.53814796577409E-6,5.34058237031125E-9,2.13180664168236E-6,3.00082031502578E-9,1.3775324092892E-6,4.41779328296468E-9,0.999912673997381,600.038391113281,12,7200,1,3,0.00612843636647503,0.00574410889261999,0.00564270047470927,112.617263793945,2.19884538650513,2.20196270942688,800.107482910156,800.107482910156,,,2.7505087852478,0,1,,,,,,1,1,1,2.19985747337341,0,0,2.20005035400391,,,,,,,,,,,,,,,,,,,,,,,,,,,,,,,,,

,3818684741.28371,2.19968068599701,800.107482910156,,,5,,,,23.14000017941,,,,,2.25330184378295E-6,5.43811032120262E-9,33.2541545455001,0.00424450340614468,2.25349263065215E-6,5.43857076552587E-9,1.88447509222464E-6,3.01330977807698E-9,1.23571139963524E-6,4.52747348451411E-9,0.999915337256221,775.049621582031,12,9300,1,3,0.0051789640886881,0.00537043642175194,0.00619293423369527,102.200286865234,2.19867134094238,2.20151424407959,800.107482910156,800.107482910156,,,2.75100946426392,0,1,,,,,,1,1,1,2.19996380805969,0,0,2.20000205605717,,,,,,,,,,,,,,,,,,,,,,,,,,,,,,,,,

,3818684807.8925,2.19964325428009,800.107482910156,,,5,,,,23.14000017941,,,,,1.91630262609343E-6,7.57322964099405E-9,33.3859140756576,0.00793416198119812,1.91653969292778E-6,7.57416652932912E-9,1.6002783908912E-6,3.77325101488139E-9,1.05462479878599E-6,6.56738725770805E-9,0.999876304761529,999.040954589844,12,11988,1,3,0.00412300607202779,0.00482680738671227,0.00720764603465795,89.2417907714844,2.19863843917847,2.20108366012573,800.107482910156,800.107482910156,,,2.75028133392334,0,1,,,,,,1,1,1,2.19948267936707,0,0,2.19997636838393,,,,,,,,,,,,,,,,,,,,,,,,,,,,,,,,,

,3818685024.09112,2.60001754760742,800.107482910156,,,5,,,,23.14000017941,,,,,5.29295399786888E-6,8.32801526324595E-8,0.385713257666123,0.010241178588711,5.29295823661102E-6,8.32802193254805E-8,5.29283830029638E-6,6.32261896285171E-8,3.56317474187138E-8,5.42037256649294E-8,0.999999199173327,1.00057637691498,31.9815665633281,32,1,3,0.0175521311786385,0.000375728906932135,0.0262539219111204,178.09895324707,2.59936141967773,2.60240817070007,800.107482910156,800.107482910156,,,2.99031162261963,0,1,,,,,,1,1,1,2.60011744499207,0,0,2.60001583816179,,,,,,,,,,,,,,,,,,,,,,,,,,,,,,,,,

,3818685180.1132,2.6000280380249,800.107482910156,,,5,,,,23.14000017941,,,,,5.26247996100234E-6,5.87713282231519E-8,-0.396457705965858,0.00749384213637283,5.26240327741033E-6,5.87704718214956E-8,5.26227729762597E-6,4.35744402504473E-8,-3.64128684587366E-8,3.94364871024462E-8,1.00001457197177,1.30083453655243,24.5995928773607,32,1,3,0.0174539536859508,0.000191176389944042,0.0262359455227852,177.640029907227,2.59855675697327,2.60181546211243,800.107482910156,800.107482910156,,,2.99163889884949,0,1,,,,,,1,1,1,2.60005450248718,0,0,2.59999514693645,,,,,,,,,,,,,,,,,,,,,,,,,,,,,,,,,

,3818685301.80894,2.59994626045227,800.107482910156,,,5,,,,23.14000017941,,,,,5.24771516799579E-6,5.96537430339992E-8,0.348092601019527,0.00553831872578078,5.24764787416509E-6,5.96529780670077E-8,5.24755102906031E-6,5.20998111137802E-8,3.18811643063577E-8,2.90531835462367E-8,1.0000128236178,1.70109140872955,18.8114523627504,32,1,3,0.0173989741134969,0.000490772777651889,0.0261544790118933,176.983612060547,2.59904813766479,2.60232090950012,800.107482910156,800.107482910156,,,2.99212908744812,0,1,,,,,,1,1,1,2.59993839263916,0,0,2.60000120344616,,,,,,,,,,,,,,,,,,,,,,,,,,,,,,,,,

,3818685410.60899,2.59994840621948,800.107482910156,,,5,,,,23.14000017941,,,,,5.32425699130211E-6,6.77964450809728E-8,0.44856362892482,0.00830891826763474,5.32427280897683E-6,6.77966464953894E-8,5.3241096425006E-6,5.13775473701684E-8,4.16828387008216E-8,4.42349737452946E-8,0.999997029138947,2.20184540748596,14.5332637301441,30,1,3,0.0176485792017246,0.000622211418698278,0.0261145904660225,176.158676147461,2.59877943992615,2.60182690620422,800.107482910156,800.107482910156,,,2.99207448959351,0,1,,,,,,1,1,1,2.60010504722595,0,0,2.59998512521703,,,,,,,,,,,,,,,,,,,,,,,,,,,,,,,,,

,3818685498.49372,2.60010397434235,800.107482910156,,,5,,,,23.14000017941,,,,,5.28790346584991E-6,1.03670701252046E-7,1.71594166307215,0.0114758957468168,5.28791093745924E-6,1.0367084773486E-7,5.28553966504993E-6,8.4116255626269E-8,1.58343082213765E-7,6.05978564759564E-8,0.999998587039491,2.79977774620056,12,33,1,3,0.0175031350337165,0.00111499321739097,0.0260969642549753,175.253707885742,2.59885883331299,2.60211062431335,800.107482910156,800.107482910156,,,2.99225878715515,0,1,,,,,,1,1,1,2.59988117218018,0,0,2.60003663286751,,,,,,,,,,,,,,,,,,,,,,,,,,,,,,,,,

,3818685581.18582,2.59981286525726,800.107482910156,,,5,,,,23.14000017941,,,,,5.32542916268437E-6,9.14432279218637E-8,1.13438060944389,0.0157193508085679,5.32542505157512E-6,9.14431573297877E-8,5.32438133538939E-6,3.66405356437345E-8,1.05429480226955E-7,8.37813951315E-8,1.00000077197767,3.59877109527588,12,43,1,3,0.0176288575956726,0.001089082579055,0.0260066334158182,173.8662109375,2.59867095947266,2.60199546813965,800.107482910156,800.107482910156,,,2.99252319335937,0,1,,,,,,1,1,1,2.59981751441956,0,0,2.59999416804895,,,,,,,,,,,,,,,,,,,,,,,,,,,,,,,,,

,3818685662.56377,2.60001194477081,800.107482910156,,,5,,,,23.14000017941,,,,,5.24639583078255E-6,4.2354923961052E-8,1.42839238992943,0.00439452185999145,5.24635261334263E-6,4.23545750603131E-8,5.24472236120538E-6,3.5565913264369E-8,1.30778810972351E-7,2.29994748246799E-8,1.00000823761632,4.63792991638184,12,55,1,3,0.0173474345076171,0.00134314417433669,0.0258435904979706,172.301193237305,2.59815526008606,2.60187602043152,800.107482910156,800.107482910156,,,2.99277067184448,0,1,,,,,,1,1,1,2.59983897209167,0,0,2.60001797012136,,,,,,,,,,,,,,,,,,,,,,,,,,,,,,,,,

,3818685745.85976,2.59990239143372,800.107482910156,,,5,,,,23.14000017941,,,,,5.17119512443148E-6,4.88879554669065E-8,1.90989609886188,0.00521787455360263,5.17125726742398E-6,4.88885429604698E-8,5.16838450208212E-6,4.08393393553625E-8,1.723466405903E-7,2.68744859265297E-8,0.999987983001175,5.99559497833252,12,71,1,3,0.0170648325878346,0.00169071989352805,0.0257129389792681,169.96321105957,2.59913182258606,2.60173058509827,800.107482910156,800.107482910156,,,2.99280118942261,0,1,,,,,,1,1,1,2.5998055934906,0,0,2.59998962065069,,,,,,,,,,,,,,,,,,,,,,,,,,,,,,,,,

,3818685825.4228,2.60011339187622,800.107482910156,,,5,,,,23.14000017941,,,,,5.23806386397178E-6,4.73176801368451E-8,1.9620748516421,0.00602678683075402,5.23794251887001E-6,4.73165839744344E-8,5.23487155880651E-6,3.52835603381643E-8,1.793365377856E-7,3.15266472824629E-8,1.0000231665585,7.74557828903198,12,92,1,3,0.017252175839304,0.00199972026161081,0.0253156796097755,167.178466796875,2.59880447387695,2.60155606269836,800.107482910156,800.107482910156,,,2.99326324462891,0,1,,,,,,1,1,1,2.60020446777344,0,0,2.60000220628885,,,,,,,,,,,,,,,,,,,,,,,,,,,,,,,,,

,3818685901.19026,2.59979438781738,800.107482910156,,,5,,,,23.14000017941,,,,,5.26111773106909E-6,2.02498063684162E-8,2.23222524628897,0.00249359941289599,5.26072307135444E-6,2.02482873408613E-8,5.25673106450408E-6,1.54565472762069E-8,2.04904243388693E-7,1.30800721151095E-8,1.00007502005129,10.005763053894,12,120,1,3,0.0172740644339271,0.00240398101718794,0.0247944351285696,163.751770019531,2.59888768196106,2.60178756713867,800.107482910156,800.107482910156,,,2.99338412284851,0,1,,,,,,1,1,1,2.5998706817627,0,0,2.59999582660732,,,,,,,,,,,,,,,,,,,,,,,,,,,,,,,,,

,3818685965.94739,2.59982907772064,800.107482910156,,,5,,,,23.14000017941,,,,,5.22233425190431E-6,1.32548853980314E-8,3.06375980163652,0.00119334742889915,5.22284606769274E-6,1.32561844454101E-8,5.21538092853329E-6,1.17907774549381E-8,2.79146587127206E-7,6.05838204959499E-9,0.999902004427892,12.9311771392822,12,155,1,3,0.0170504147741607,0.00296983407416051,0.0239628385752439,159.638763427734,2.59903788566589,2.60213446617126,800.107482910156,800.107482910156,,,2.99372720718384,0,1,,,,,,1,1,1,2.59994840621948,0,0,2.59998126635476,,,,,,,,,,,,,,,,,,,,,,,,,,,,,,,,,

[...]

,3818744172.82704,4.39945650100708,800.1201171875,,,5,,,,23.14000017941,,,,,3.11992435056568E-6,5.3349813420581E-9,5.32193163198133,0.0012440518065723,3.12030863567156E-6,5.33563845859027E-9,3.10685782045044E-6,3.66649505864457E-9,2.89414003379992E-7,3.87631935548692E-9,0.999876843879646,215.576721191406,12,2586,1,3,0.0101155536155558,0.00202055577170766,0.00600390648469329,129.25993347168,4.39890480041504,4.40265083312988,800.1201171875,800.1201171875,,,3.82242298126221,0,1,,,,,,1,1,1,4.39990091323853,0,0,4.4000328407913,,,,,,,,,,,,,,,,,,,,,,,,,,,,,,,,,

,3818744234.85647,4.39962434768677,800.1201171875,,,5,,,,23.14000017941,,,,,3.09158638185041E-6,1.01357593301679E-8,6.75368070442295,0.00232402992067369,3.09199209009428E-6,1.01370894437764E-8,3.07053646093865E-6,7.19619547947676E-9,3.63621956504228E-7,7.13970258570205E-9,0.999868787425047,278.222930908203,12,3338,1,3,0.0099562661628429,0.00232062679499512,0.00561723066493869,128.277282714844,4.39845943450928,4.40116691589355,800.1201171875,800.1201171875,,,3.82252788543701,0,1,,,,,,1,1,1,4.4000415802002,0,0,4.39998006820679,,,,,,,,,,,,,,,,,,,,,,,,,,,,,,,,,

,3818744295.24456,4.39947605133057,800.1201171875,,,5,,,,23.14000017941,,,,,3.05612060353967E-6,5.33673342938733E-9,8.47291460333945,0.00130436960923327,3.05570956383524E-6,5.33601565361339E-9,3.02235840895033E-6,3.56857140537628E-9,4.50233924045435E-7,3.96716034215129E-9,1.00013451530515,359.691528320313,12,4316,1,3,0.00973359367818845,0.00272560001380584,0.00540891569107771,125.486175537109,4.39909839630127,4.40227270126343,800.1201171875,800.1201171875,,,3.82298517227173,0,1,,,,,,1,1,1,4.39998388290405,0,0,4.40004551612725,,,,,,,,,,,,,,,,,,,,,,,,,,,,,,,,,

,3818744355.53132,4.39958238601685,800.1201171875,,,5,,,,23.14000017941,,,,,3.00642584237612E-6,4.72122590606917E-9,10.5403462853047,0.0012614892120673,3.00602468732904E-6,4.72059594088796E-9,2.95530204278775E-6,2.78619913949839E-9,5.49885676051115E-7,3.81065878716348E-9,1.00013345035015,463.925201416016,12,5567,1,3,0.00940609000057175,0.00323376862474727,0.00540349073708057,120.442413330078,4.39867448806763,4.40150165557861,800.1201171875,800.1201171875,,,3.8228440284729,0,1,,,,,,1,1,1,4.40007829666138,0,0,4.39998558012106,,,,,,,,,,,,,,,,,,,,,,,,,,,,,,,,,

,3818744415.46954,4.39953374862671,800.1201171875,,,5,,,,23.14000017941,,,,,2.93756391262937E-6,4.61884577085796E-9,13.0776740112669,0.00124052320531246,2.93791882667901E-6,4.61940381599534E-9,2.86172158312372E-6,2.99345396945782E-9,6.64768089516083E-7,3.51825595259492E-9,0.999879195420098,600.038391113281,12,7200,1,3,0.00892618094254056,0.00385264584195634,0.00563645362854004,112.720108032227,4.39904642105103,4.40262746810913,800.1201171875,800.1201171875,,,3.8232274055481,0,1,,,,,,1,1,1,4.40002107620239,0,0,4.40002646688688,,,,,,,,,,,,,,,,,,,,,,,,,,,,,,,,,

,3818744475.64577,4.399489402771,800.1201171875,,,5,,,,23.14000017941,,,,,2.8204626405851E-6,1.03160366743738E-8,16.1807782836777,0.00311900199900642,2.82056925282145E-6,1.03164266159827E-8,2.7088386866521E-6,7.03020172189689E-9,7.86005012489533E-7,7.55016038719677E-9,0.999962201872462,775.049621582031,12,9300,1,3,0.00817116397454667,0.00452111489837701,0.00617407029494643,102.316375732422,4.39876651763916,4.40137910842895,800.1201171875,800.1201171875,,,3.82324075698853,0,1,,,,,,1,1,1,4.39997625350952,0,0,4.40001150713129,,,,,,,,,,,,,,,,,,,,,,,,,,,,,,,,,

,3818744535.86951,4.39947533607483,800.1201171875,,,5,,,,23.14000017941,,,,,2.5429706743394E-6,8.0248191487149E-9,19.3551169108335,0.00295716077387591,2.54307511304648E-6,8.02514872457076E-9,2.39934704206873E-6,3.98300376161013E-9,8.42831419865451E-7,6.96697158645557E-9,0.999958932118622,999.040954589844,12,11988,1,3,0.00686199761840853,0.00488593166612905,0.00721848988905549,89.3319396972656,4.39865875244141,4.40149593353271,800.1201171875,800.1201171875,,,3.82332801818848,0,1,,,,,,1,1,1,4.40007543563843,0,0,4.40002769534871,,,,,,,,,,,,,,,,,,,,,,,,,,,,,,,,,

,3818744744.36028,4.80009984970093,800.1201171875,,,5,,,,23.14000017941,,,,,2.93535371224141E-6,6.63359783455553E-8,-0.703440282238418,0.0178275055039114,2.93534710959149E-6,6.63358291324503E-8,2.93512588509376E-6,4.07706700946779E-8,-3.6037375593531E-8,5.23277621031186E-8,1.00000224935916,1.00057637691498,31.9815665633281,32,1,3,0.00973622084150394,2.33050197146718E-5,0.0262319352477789,178.094802856445,4.79855298995972,4.8016209602356,800.1201171875,800.1201171875,,,3.9584698677063,0,1,,,,,,1,1,1,4.79998874664307,0,0,4.79999299173231,,,,,,,,,,,,,,,,,,,,,,,,,,,,,,,,,

,3818744889.8264,4.80005598068237,800.1201171875,,,5,,,,23.14000017941,,,,,2.90360885759506E-6,5.58033597434893E-8,-1.38801586894067,0.0144124339226286,2.90356142210139E-6,5.58024480986889E-8,2.90270945391083E-6,3.69163624063961E-8,-7.03331933881761E-8,4.18460918185497E-8,1.00001633700369,1.30083453655243,24.5995928773607,32,1,3,0.00963072010844751,-6.11897434507586E-5,0.0262302719056606,177.637191772461,4.79875040054321,4.80214548110962,800.1201171875,800.1201171875,,,3.95968747138977,0,1,,,,,,1,1,1,4.80004072189331,0,0,4.79999676513672,,,,,,,,,,,,,,,,,,,,,,,,,,,,,,,,,

,3818745010.75211,4.80014872550964,800.1201171875,,,5,,,,23.14000017941,,,,,2.9625768341114E-6,6.62313518115767E-8,0.824428507751222,0.0172599329830833,2.96257737985737E-6,6.62313640122707E-8,2.96227069456409E-6,4.20858563046867E-8,4.26270309700756E-8,5.11407301280218E-8,0.999999815786763,1.70109140872955,18.8114523627504,32,1,3,0.00981987931721695,0.000358710154286503,0.0261955726891756,176.945938110352,4.79870414733887,4.80217599868774,800.1201171875,800.1201171875,,,3.95979452133179,0,1,,,,,,1,1,1,4.80016326904297,0,0,4.80000732512701,,,,,,,,,,,,,,,,,,,,,,,,,,,,,,,,,

,3818745115.73321,4.80005145072937,800.1201171875,,,5,,,,23.14000017941,,,,,2.79439900585817E-6,6.83595389994979E-8,-0.440060609869107,0.0166396499020355,2.79440424024496E-6,6.83596670485944E-8,2.79432181944435E-6,5.0108519620952E-8,-2.14622290605054E-8,4.64992509659172E-8,0.999998126832648,2.20184540748596,14.5332637301441,30,1,3,0.00926668392313514,0.000182865305596355,0.0261332001537085,176.174209594727,4.79903078079224,4.80178642272949,800.1201171875,800.1201171875,,,3.95918488502502,0,1,,,,,,1,1,1,4.79994440078735,0,0,4.8000090652042,,,,,,,,,,,,,,,,,,,,,,,,,,,,,,,,,

,3818745199.67274,4.8000795841217,800.1201171875,,,5,,,,23.14000017941,,,,,2.84527980771316E-6,4.55738157272243E-8,0.703716936990267,0.00964479890645416,2.84527515661633E-6,4.55737412290223E-8,2.84506055175317E-6,3.63934112695861E-8,3.49452960499343E-8,2.74314692601882E-8,1.00000163467383,2.79977774620056,12,33,1,3,0.00942709922508467,0.000433472788239659,0.0260876081883907,175.195343017578,4.79904079437256,4.80202674865723,800.1201171875,800.1201171875,,,3.95988440513611,0,1,,,,,,1,1,1,4.80005407333374,0,0,4.79999844844525,,,,,,,,,,,,,,,,,,,,,,,,,,,,,,,,,

,3818745278.32945,4.80002641677856,800.1201171875,,,5,,,,23.14000017941,,,,,2.88631967374615E-6,2.61127671631625E-8,-0.654453243114331,0.00633199466686583,2.88630744554391E-6,2.61126565336294E-8,2.88611915875208E-6,1.86506127496034E-8,-3.29677370526766E-8,1.82763638426145E-8,1.00000423662499,3.59877109527588,12,43,1,3,0.00956840226668025,0.000291716833366629,0.0260147619992495,173.916412353516,4.79888868331909,4.80148935317993,800.1201171875,800.1201171875,,,3.96027135848999,0,1,,,,,,1,1,1,4.79997396469116,0,0,4.79999993397639,,,,,,,,,,,,,,,,,,,,,,,,,,,,,,,,,

,3818745355.68072,4.80006146430969,800.1201171875,,,5,,,,23.14000017941,,,,,2.88493735071529E-6,4.26346047902372E-8,0.404264516730745,0.0110032258624132,2.88494104204643E-6,4.26346593420091E-8,2.88486923102108E-6,2.84594169895118E-8,2.03552448220743E-8,3.17454841170559E-8,0.999998720482988,4.63792991638184,12,55,1,3,0.00955084781579316,0.000567954156619399,0.0258262567222118,172.16259765625,4.7989706993103,4.80213451385498,800.1201171875,800.1201171875,,,3.96050310134888,0,1,,,,,,1,1,1,4.8000636100769,0,0,4.80000524520874,,,,,,,,,,,,,,,,,,,,,,,,,,,,,,,,,

,3818745434.96088,4.80000925064087,800.1201171875,,,5,,,,23.14000017941,,,,,2.84776284988323E-6,4.30693028928438E-8,0.146716172094626,0.0116523290223541,2.84775879741906E-6,4.30692416037491E-8,2.84774946092813E-6,2.74552740535589E-8,7.29219179408989E-9,3.31838439449997E-8,1.00000142303631,5.99559497833252,12,71,1,3,0.00942175537273138,0.000641472166022171,0.0257225818932056,169.926513671875,4.79882574081421,4.8023157119751,800.1201171875,800.1201171875,,,3.96044039726257,0,1,,,,,,1,1,1,4.80004167556763,0,0,4.79999462152139,,,,,,,,,,,,,,,,,,,,,,,,,,,,,,,,,

,3818745511.9584,4.80001068115234,800.1201171875,,,5,,,,23.14000017941,,,,,2.85717791122881E-6,7.40526142230353E-8,0.415120288445837,0.0230901945789236,2.85701742982123E-6,7.40484548503486E-8,2.85694244322365E-6,3.35786858288976E-8,2.06995267970924E-8,6.59973145190644E-8,1.00005617095853,7.74557828903198,12,92,1,3,0.009436468135162,0.00083631509157222,0.0253619570285082,167.160003662109,4.79891777038574,4.80156183242798,800.1201171875,800.1201171875,,,3.96070837974548,0,1,,,,,,1,1,1,4.7999005317688,0,0,4.79999661445618,,,,,,,,,,,,,,,,,,,,,,,,,,,,,,,,,

,3818745584.98986,4.79979205131531,800.1201171875,,,5,,,,23.14000017941,,,,,2.89477693843171E-6,1.92493151840682E-8,0.505667028802463,0.00335765567020556,2.89460921613079E-6,1.92481998858942E-8,2.89449648570814E-6,1.66290827267019E-8,2.5546199962755E-8,9.69364774044542E-9,1.00005794298587,10.005763053894,12,120,1,3,0.00954009173729072,0.00103572896480618,0.0247862990945578,163.74577331543,4.79891395568848,4.80148839950562,800.1201171875,800.1201171875,,,3.96085476875305,0,1,,,,,,1,1,1,4.7999792098999,0,0,4.80002728242141,,,,,,,,,,,,,,,,,,,,,,,,,,,,,,,,,

,3818745645.86335,4.79954671859741,800.1201171875,,,5,,,,23.14000017941,,,,,2.86599850708501E-6,1.04763353682438E-8,0.405430794043931,0.00174990781218396,2.86627234558567E-6,1.04773363541001E-8,2.86620058700422E-6,9.20934388484663E-9,2.02818669221972E-8,4.99625482612579E-9,0.999904461799983,12.9311771392822,12,155,1,3,0.00942273291743166,0.00119406414885338,0.0239674430340528,159.63801574707,4.79861545562744,4.80153656005859,800.1201171875,800.1201171875,,,3.96122789382935,0,1,,,,,,1,1,1,4.80003499984741,0,0,4.80000185966492,,,,,,,,,,,,,,,,,,,,,,,,,,,,,,,,,

,3818745706.39961,4.79940724372864,800.1201171875,,,5,,,,23.14000017941,,,,,2.87570417911065E-6,5.9741554119573E-9,0.265454224150805,0.00169488114446239,2.87610564928324E-6,5.97498944948514E-9,2.87607478131256E-6,3.45580179067486E-9,1.33250942538542E-8,4.87421100333451E-9,0.99986041188275,16.6762714385986,12,200,1,3,0.00943028267502487,0.00135375187538854,0.0228006429970264,154.939163208008,4.7985725402832,4.80201101303101,800.1201171875,800.1201171875,,,3.96181583404541,0,1,,,,,,1,1,1,4.79989624023438,0,0,4.80000289281209,,,,,,,,,,,,,,,,,,,,,,,,,,,,,,,,,

,3818745766.98304,4.79955744743347,800.1201171875,,,5,,,,23.14000017941,,,,,2.883684747638E-6,7.29556457110058E-9,0.460913412400934,0.00161305802041128,2.8836294800524E-6,7.29542474713412E-9,2.88353617599142E-6,5.63076597833496E-9,2.31969820462159E-8,4.63871714359935E-9,1.00001916598023,21.5291557312012,12,258,1,3,0.00942507775573401,0.00153741028144859,0.0212319120764732,149.748321533203,4.79880809783936,4.80179643630981,800.1201171875,800.1201171875,,,3.96217632293701,0,1,,,,,,1,1,1,4.80000448226929,0,0,4.80000344777511,,,,,,,,,,,,,,,,,,,,,,,,,,,,,,,,,

,3818745827.24912,4.79959654808044,800.1201171875,,,5,,,,23.14000017941,,,,,2.8727715546386E-6,6.30949022569266E-9,0.452817581594449,0.00173191202482281,2.87248903694681E-6,6.30886972991671E-9,2.87239932972217E-6,3.88321096304446E-9,2.27014975545532E-8,4.97217355746465E-9,1.00009835292255,27.8064498901367,12,333,1,3,0.00937099627586071,0.00161818243136296,0.0192713756114244,144.369186401367,4.79876899719238,4.80206632614136,800.1201171875,800.1201171875,,,3.96194291114807,0,1,,,,,,1,1,1,4.80010032653809,0,0,4.80000451405843,,,,,,,,,,,,,,,,,,,,,,,,,,,,,,,,,

,3818745887.66321,4.79947733879089,800.1201171875,,,5,,,,23.14000017941,,,,,2.88011279269475E-6,8.33458235164657E-9,0.5379483615963,0.00214976220002565,2.87938033755745E-6,8.33246274449918E-9,2.87925342582808E-6,5.58666319869367E-9,2.70340187493589E-8,6.18216221825573E-9,1.00025437943287,35.9030342102051,12,430,1,3,0.0093867960193224,0.00164835759070102,0.0170415453612804,139.190536499023,4.79909610748291,4.80200576782227,800.1201171875,800.1201171875,,,3.96204209327698,0,1,,,,,,1,1,1,4.80002880096436,0,0,4.799996715481,,,,,,,,,,,,,,,,,,,,,,,,,,,,,,,,,

,3818745949.77651,4.79952788352966,800.1201171875,,,5,,,,23.14000017941,,,,,2.87229217724056E-6,7.35637026278742E-9,0.722937845784424,0.0020292579184644,2.87153439161999E-6,7.35442946036875E-9,2.8713058133607E-6,4.48824526965902E-9,3.62310421796871E-8,5.82608677303413E-9,1.0002638957147,46.4145660400391,12,556,1,3,0.00936361539506294,0.0016127986191334,0.0146812815219164,134.697189331055,4.79878044128418,4.80150938034058,800.1201171875,800.1201171875,,,3.96212124824524,0,1,,,,,,1,1,1,4.79992723464966,0,0,4.80001301843612,,,,,,,,,,,,,,,,,,,,,,,,,,,,,,,,,

,3818746010.31469,4.79946970939636,800.1201171875,,,5,,,,23.14000017941,,,,,2.86992065739104E-6,8.62561582545771E-9,1.07539706567316,0.00163222243362743,2.86920839535644E-6,8.62347510471627E-9,2.8687030226573E-6,7.26529540582229E-9,5.38496404882095E-8,4.64540693026982E-9,1.00024824339555,59.9854125976563,12,719,1,3,0.0093628086437914,0.00155610600716358,0.0124584371224046,131.296096801758,4.79869794845581,4.80213594436646,800.1201171875,800.1201171875,,,3.96250820159912,0,1,,,,,,1,1,1,4.79999303817749,0,0,4.8000151828184,,,,,,,,,,,,,,,,,,,,,,,,,,,,,,,,,

,3818746072.27258,4.79971861839294,800.1201171875,,,5,,,,23.14000017941,,,,,2.8744475893035E-6,4.8285892122665E-9,1.10231931493224,0.00119342820324911,2.87397803787073E-6,4.8278004447164E-9,2.87344616281484E-6,3.4011253512743E-9,5.52893440720584E-8,3.4263688474715E-9,1.00016338031349,77.5049591064453,12,930,1,3,0.0093963453977003,0.00142954095620899,0.0104814656078815,129.202056884766,4.79914569854736,4.80180072784424,800.1201171875,800.1201171875,,,3.96248435974121,0,1,,,,,,1,1,1,4.80004930496216,0,0,4.8000138704894,,,,,,,,,,,,,,,,,,,,,,,,,,,,,,,,,

,3818746132.68497,4.79955196380615,800.1201171875,,,5,,,,23.14000017941,,,,,2.87841282525525E-6,6.01187189039893E-9,1.69063373537067,0.00131048796709007,2.87891614631529E-6,6.01292313006341E-9,2.8776629436622E-6,4.69350161526042E-9,8.49362124673544E-8,3.75849533132601E-9,0.999825169947836,100.057640075684,12,1200,1,3,0.0094122898701336,0.00140437507331393,0.00883852876722813,128.402954101562,4.79861974716186,4.80199480056763,800.1201171875,800.1201171875,,,3.96284556388855,0,1,,,,,,1,1,1,4.79991006851196,0,0,4.79999238353665,,,,,,,,,,,,,,,,,,,,,,,,,,,,,,,,,

,3818746193.01786,4.79953336715698,800.1201171875,,,5,,,,23.14000017941,,,,,2.88913394994106E-6,5.67777368170329E-9,2.13184406846377,0.00156790744650436,2.88860518124834E-6,5.67673453674869E-9,2.88660590092261E-6,3.4130602555244E-9,1.0745355226102E-7,4.53611449291959E-9,1.00018305329373,129.174926757812,12,1550,1,3,0.00944984584850851,0.00138948823901419,0.00753566389903426,128.557510375977,4.79876565933228,4.80149698257446,800.1201171875,800.1201171875,,,3.9630651473999,0,1,,,,,,1,1,1,4.79992246627808,0,0,4.79998645782471,,,,,,,,,,,,,,,,,,,,,,,,,,,,,,,,,

,3818746253.54381,4.79953241348267,800.1201171875,,,5,,,,23.14000017941,,,,,2.89379660499988E-6,5.42438047320663E-9,2.59898127695607,0.00162271336672446,2.89337477576161E-6,5.42358976031438E-9,2.89039858157593E-6,2.68551285818112E-9,1.31200734134282E-7,4.7120427180503E-9,1.0001457914273,166.93376159668,12,2003,1,3,0.00946091579999704,0.0014207458776432,0.00660975091159344,129.097763061523,4.7985668182373,4.80216121673584,800.1201171875,800.1201171875,,,3.96293115615845,0,1,,,,,,1,1,1,4.79997873306274,0,0,4.80000314874164,,,,,,,,,,,,,,,,,,,,,,,,,,,,,,,,,

,3818746315.54073,4.79962086677551,800.1201171875,,,5,,,,23.14000017941,,,,,2.87519512340266E-6,5.54951031331849E-9,3.45138775430992,0.00128483101957972,2.87557123390718E-6,5.55023625678812E-9,2.87035562462731E-6,4.15562240113758E-9,1.73114151486356E-7,3.67912013466929E-9,0.999869204942628,215.576721191406,12,2586,1,3,0.00937790805054337,0.0015566911675414,0.00597642548382282,129.261779785156,4.79868698120117,4.80189323425293,800.1201171875,800.1201171875,,,3.96290445327759,0,1,,,,,,1,1,1,4.80011892318726,0,0,4.80000875816971,,,,,,,,,,,,,,,,,,,,,,,,,,,,,,,,,

,3818746375.94013,4.79954600334167,800.1201171875,,,5,,,,23.14000017941,,,,,2.86234311008923E-6,6.44149409953275E-9,4.26994554719691,0.00140704459848941,2.86246987928066E-6,6.44177938433868E-9,2.85452459709878E-6,5.06189609882251E-9,2.13127038047944E-7,3.98418492557966E-9,0.999955713353578,278.222930908203,12,3338,1,3,0.00930247046357573,0.00174694365850802,0.005614441819489,128.305450439453,4.79874992370605,4.80197477340698,800.1201171875,800.1201171875,,,3.96313261985779,0,1,,,,,,1,1,1,4.79999446868897,0,0,4.80000640551249,,,,,,,,,,,,,,,,,,,,,,,,,,,,,,,,,

,3818746436.5652,4.79939937591553,800.1201171875,,,5,,,,23.14000017941,,,,,2.8459785757451E-6,7.27056592008343E-9,5.3933464325,0.0014130543284204,2.84566083856679E-6,7.26975420311553E-9,2.83306277469445E-6,6.14920607682242E-9,2.67471349481036E-7,3.87770432066269E-9,1.00011165672803,359.691528320313,12,4316,1,3,0.00918759828070095,0.00204740776237378,0.00540439784526825,125.497573852539,4.79912090301514,4.80148077011108,800.1201171875,800.1201171875,,,3.96312212944031,0,1,,,,,,1,1,1,4.7998423576355,0,0,4.79998514207743,,,,,,,,,,,,,,,,,,,,,,,,,,,,,,,,,

,3818746498.99818,4.79961585998535,800.1201171875,,,5,,,,23.14000017941,,,,,2.82308794725391E-6,4.72305783685554E-9,6.89409414617472,0.00121395713338508,2.82278854976125E-6,4.72255694148831E-9,2.80237899802938E-6,3.28242783444605E-9,3.3883203518416E-7,3.39532201377914E-9,1.00010606444209,463.925201416016,12,5567,1,3,0.00900776572856257,0.00246851365772766,0.00539490487426519,120.454086303711,4.79886627197266,4.80192041397095,800.1201171875,800.1201171875,,,3.96321582794189,0,1,,,,,,1,1,1,4.80002880096436,0,0,4.79999333812344,,,,,,,,,,,,,,,,,,,,,,,,,,,,,,,,,

,3818746559.42637,4.79954099655151,800.1201171875,,,5,,,,23.14000017941,,,,,2.79175311640024E-6,5.68510106661519E-9,8.76062885419453,0.00155548224750895,2.79143110945627E-6,5.6844453345557E-9,2.75886424554476E-6,3.73341268904599E-9,4.25153752770704E-7,4.28655438024789E-9,1.00011535550452,600.038391113281,12,7200,1,3,0.00873472943792228,0.00301221015278251,0.00562666775658727,112.756500244141,4.79917621612549,4.80199241638184,800.1201171875,800.1201171875,,,3.96339082717895,0,1,,,,,,1,1,1,4.79993772506714,0,0,4.8000360828335,,,,,,,,,,,,,,,,,,,,,,,,,,,,,,,,,

,3818746619.76633,4.79967617988586,800.1201171875,,,5,,,,23.14000017941,,,,,2.72319107358803E-6,1.14196868663071E-8,11.1312223662835,0.0034214413810267,2.72287986885646E-6,1.14183818309681E-8,2.67165598187807E-6,6.81545188787089E-9,5.25670138698139E-7,9.16128043462812E-9,1.00011429249418,775.049621582031,12,9300,1,3,0.00824305879416866,0.0036535464821193,0.00615440122783184,102.337463378906,4.79859638214111,4.80141067504883,800.1201171875,800.1201171875,,,3.9635796546936,0,1,,,,,,1,1,1,4.80004692077637,0,0,4.79999219765097,,,,,,,,,,,,,,,,,,,,,,,,,,,,,,,,,

,3818746679.91766,4.79954481124878,800.1201171875,,,5,,,,23.14000017941,,,,,2.5126748879495E-6,7.7707722744812E-9,13.6121717526061,0.00268877554582218,2.51272940100861E-6,7.77094086317144E-9,2.44214940950224E-6,4.99613234577036E-9,5.91367317630048E-7,5.95198987586965E-9,0.999978305240871,999.040954589844,12,11988,1,3,0.00722945995411011,0.00412467252011316,0.00722553487867117,89.3778991699219,4.79915189743042,4.80145168304443,800.1201171875,800.1201171875,,,3.96365690231323,0,1,,,,,,1,1,1,4.79988193511963,0,0,4.8000164840181,,,,,,,,,,,,,,,,,,,,,,,,,,,,,,,,,